{"event": "depthUpdate", "raw_payload": "{\"e\": \"depthUpdate\", \"E\": 1773246384232, \"T\": 1773246384230, \"s\": \"BTCUSDT\", \"U\": 10089703733613, \"u\": 10089703738660, \"pu\": 10089703733549, \"b\": [[\"1000.00\", \"26.792\"], [\"5000.00\", \"101.418\"], [\"19848.60\", \"0.070\"], [\"19948.60\", \"1.610\"], [\"20048.60\", \"0.510\"], [\"20148.60\", \"0.810\"], [\"66831.00\", \"0.002\"], [\"69223.00\", \"2.134\"], [\"69328.50\", \"4.204\"], [\"69398.90\", \"0.404\"], [\"70253.10\", \"0.076\"], [\"70260.20\", \"0.165\"], [\"70267.20\", \"0.172\"], [\"70284.80\", \"0.018\"], [\"70293.40\", \"0.007\"], [\"70296.90\", \"0.263\"], [\"70297.30\", \"0.196\"], [\"70304.60\", \"0.008\"], [\"70304.70\", \"0.000\"], [\"70304.80\", \"0.088\"], [\"70308.50\", \"0.002\"], [\"70336.30\", \"0.000\"], [\"70336.70\", \"0.006\"], [\"70338.00\", \"0.536\"], [\"70348.60\", \"2.004\"]], \"a\": [[\"70349.90\", \"0.002\"], [\"70351.60\", \"0.002\"], [\"70352.40\", \"0.004\"], [\"70354.90\", \"0.004\"], [\"70355.60\", \"0.513\"], [\"70356.80\", \"0.003\"], [\"70356.90\", \"0.117\"], [\"70366.90\", \"0.096\"], [\"70368.40\", \"0.194\"], [\"70429.20\", \"0.073\"], [\"70433.30\", \"0.087\"], [\"70436.20\", \"0.073\"], [\"70443.30\", \"9.673\"], [\"70478.10\", \"0.447\"], [\"70487.00\", \"0.000\"], [\"70487.60\", \"0.055\"], [\"70585.50\", \"3.069\"], [\"71052.20\", \"0.010\"], [\"71293.70\", \"0.703\"], [\"71368.80\", \"5.880\"], [\"71397.80\", \"0.973\"], [\"71439.10\", \"3.917\"], [\"71474.30\", \"1.956\"], [\"72459.10\", \"0.000\"], [\"73899.60\", \"0.002\"], [\"89523.20\", \"0.000\"]]}", "symbol": "BTCUSDT"}
{"event": "depthUpdate", "raw_payload": "{\"e\": \"depthUpdate\", \"E\": 1773246384334, \"T\": 1773246384333, \"s\": \"BTCUSDT\", \"U\": 10089703738780, \"u\": 10089703756526, \"pu\": 10089703738660, \"b\": [[\"5000.00\", \"101.418\"], [\"19848.60\", \"0.150\"], [\"19948.60\", \"1.620\"], [\"20048.60\", \"0.510\"], [\"20148.60\", \"0.720\"], [\"40000.00\", \"50.271\"], [\"56279.00\", \"0.045\"], [\"66806.40\", \"0.002\"], [\"66815.70\", \"0.000\"], [\"68939.80\", \"0.000\"], [\"69223.00\", \"3.144\"], [\"69258.20\", \"1.009\"], [\"69314.50\", \"1.295\"], [\"69328.50\", \"5.212\"], [\"69645.10\", \"0.000\"], [\"69674.10\", \"0.000\"], [\"69869.40\", \"0.000\"], [\"70226.80\", \"0.039\"], [\"70235.20\", \"0.008\"], [\"70252.00\", \"0.200\"], [\"70259.00\", \"2.367\"], [\"70263.00\", \"0.122\"], [\"70264.40\", \"0.000\"], [\"70266.10\", \"0.021\"], [\"70266.40\", \"1.302\"], [\"70278.90\", \"0.022\"], [\"70281.70\", \"0.003\"], [\"70281.80\", \"0.000\"], [\"70297.20\", \"0.004\"], [\"70297.30\", \"0.194\"], [\"70297.40\", \"0.100\"], [\"70304.80\", \"0.003\"], [\"70305.40\", \"0.001\"], [\"70305.60\", \"0.005\"], [\"70306.00\", \"0.445\"], [\"70306.10\", \"0.542\"], [\"70308.00\", \"0.014\"], [\"70309.00\", \"0.002\"], [\"70311.70\", \"0.245\"], [\"70314.40\", \"0.000\"], [\"70314.70\", \"0.005\"], [\"70316.30\", \"0.003\"], [\"70316.40\", \"0.001\"], [\"70317.00\", \"0.017\"], [\"70317.10\", \"0.068\"], [\"70317.70\", \"0.248\"], [\"70317.80\", \"0.002\"], [\"70318.40\", \"0.007\"], [\"70318.50\", \"0.923\"], [\"70318.80\", \"0.010\"], [\"70320.50\", \"0.002\"], [\"70320.60\", \"0.002\"], [\"70321.20\", \"0.002\"], [\"70321.30\", \"0.236\"], [\"70321.70\", \"0.002\"], [\"70322.00\", \"0.061\"], [\"70322.60\", \"0.000\"], [\"70323.70\", \"0.061\"], [\"70323.80\", \"0.000\"], [\"70326.30\", \"0.042\"], [\"70326.50\", \"0.511\"], [\"70326.90\", \"0.000\"], [\"70327.50\", \"0.221\"], [\"70327.60\", \"0.002\"], [\"70327.70\", \"0.003\"], [\"70327.80\", \"0.000\"], [\"70328.10\", \"0.074\"], [\"70328.20\", \"0.003\"], [\"70328.50\", \"0.071\"], [\"70329.10\", \"0.362\"], [\"70329.20\", \"0.512\"], [\"70330.00\", \"0.301\"], [\"70330.10\", \"2.199\"], [\"70330.20\", \"0.000\"], [\"70330.50\", \"0.500\"], [\"70330.80\", \"0.005\"], [\"70331.10\", \"0.028\"], [\"70331.40\", \"0.115\"], [\"70331.50\", \"0.278\"], [\"70331.60\", \"0.518\"], [\"70331.80\", \"0.069\"], [\"70331.90\", \"0.040\"], [\"70332.30\", \"0.037\"], [\"70332.60\", \"0.100\"], [\"70332.70\", \"0.000\"], [\"70333.00\", \"0.007\"], [\"70333.40\", \"0.383\"], [\"70333.50\", \"0.290\"], [\"70333.60\", \"0.029\"], [\"70333.70\", \"0.025\"], [\"70333.80\", \"0.151\"], [\"70333.90\", \"0.003\"], [\"70334.00\", \"0.008\"], [\"70334.40\", \"0.172\"], [\"70334.50\", \"1.480\"], [\"70334.60\", \"0.284\"], [\"70334.90\", \"0.345\"], [\"70335.20\", \"0.656\"], [\"70335.30\", \"0.021\"], [\"70335.40\", \"0.009\"], [\"70335.60\", \"0.091\"], [\"70335.70\", \"0.137\"], [\"70335.90\", \"0.003\"], [\"70336.00\", \"1.075\"], [\"70336.90\", \"0.003\"], [\"70337.20\", \"0.089\"], [\"70337.30\", \"0.051\"], [\"70337.40\", \"0.019\"], [\"70337.70\", \"0.016\"], [\"70337.90\", \"0.000\"], [\"70338.00\", \"0.089\"], [\"70338.10\", \"0.020\"], [\"70338.40\", \"0.108\"], [\"70338.50\", \"0.557\"], [\"70338.70\", \"0.018\"], [\"70339.00\", \"0.001\"], [\"70339.10\", \"0.000\"], [\"70339.60\", \"0.050\"], [\"70340.10\", \"1.002\"], [\"70340.40\", \"0.007\"], [\"70340.50\", \"0.065\"], [\"70340.60\", \"0.097\"], [\"70340.70\", \"0.014\"], [\"70340.90\", \"0.008\"], [\"70341.40\", \"0.205\"], [\"70341.50\", \"0.014\"], [\"70341.60\", \"0.051\"], [\"70341.80\", \"0.534\"], [\"70343.00\", \"0.398\"], [\"70344.30\", \"0.005\"], [\"70344.40\", \"0.003\"], [\"70345.00\", \"0.209\"], [\"70345.60\", \"0.431\"], [\"70345.70\", \"0.000\"], [\"70345.80\", \"0.355\"], [\"70348.60\", \"3.920\"]], \"a\": [[\"70348.70\", \"0.076\"], [\"70348.80\", \"0.004\"], [\"70349.90\", \"0.000\"], [\"70350.10\", \"0.000\"], [\"70350.20\", \"0.002\"], [\"70351.20\", \"0.000\"], [\"70352.40\", \"0.004\"], [\"70352.50\", \"0.000\"], [\"70352.90\", \"0.000\"], [\"70353.00\", \"0.005\"], [\"70353.90\", \"0.075\"], [\"70354.10\", \"0.000\"], [\"70354.20\", \"0.002\"], [\"70354.70\", \"0.005\"], [\"70355.30\", \"0.000\"], [\"70355.50\", \"0.001\"], [\"70355.60\", \"0.002\"], [\"70356.10\", \"0.005\"], [\"70356.20\", \"0.006\"], [\"70356.30\", \"0.007\"], [\"70356.90\", \"0.004\"], [\"70357.10\", \"0.044\"], [\"70357.40\", \"0.000\"], [\"70357.50\", \"0.106\"], [\"70357.70\", \"0.002\"], [\"70357.80\", \"0.003\"], [\"70357.90\", \"0.003\"], [\"70358.10\", \"0.000\"], [\"70358.40\", \"0.001\"], [\"70358.60\", \"0.011\"], [\"70358.70\", \"0.781\"], [\"70358.80\", \"0.003\"], [\"70359.20\", \"0.010\"], [\"70359.30\", \"0.084\"], [\"70359.40\", \"0.000\"], [\"70359.50\", \"0.004\"], [\"70359.60\", \"0.002\"], [\"70359.70\", \"0.004\"], [\"70359.90\", \"0.000\"], [\"70360.00\", \"0.015\"], [\"70360.10\", \"0.003\"], [\"70360.20\", \"0.000\"], [\"70360.30\", \"0.003\"], [\"70360.40\", \"0.513\"], [\"70360.50\", \"0.102\"], [\"70360.70\", \"0.014\"], [\"70360.90\", \"0.007\"], [\"70361.00\", \"0.199\"], [\"70361.20\", \"0.006\"], [\"70361.30\", \"1.068\"], [\"70361.50\", \"0.097\"], [\"70361.80\", \"0.000\"], [\"70362.40\", \"0.006\"], [\"70362.50\", \"0.136\"], [\"70362.60\", \"0.547\"], [\"70362.70\", \"0.165\"], [\"70362.80\", \"0.411\"], [\"70363.10\", \"0.003\"], [\"70363.20\", \"0.007\"], [\"70364.00\", \"0.007\"], [\"70364.20\", \"0.091\"], [\"70364.30\", \"0.001\"], [\"70364.40\", \"0.002\"], [\"70364.50\", \"0.049\"], [\"70364.70\", \"0.082\"], [\"70364.80\", \"0.514\"], [\"70365.10\", \"0.014\"], [\"70365.60\", \"0.003\"], [\"70366.00\", \"0.004\"], [\"70366.20\", \"0.005\"], [\"70366.80\", \"0.000\"], [\"70366.90\", \"0.642\"], [\"70367.00\", \"1.068\"], [\"70367.10\", \"0.515\"], [\"70367.40\", \"0.006\"], [\"70367.70\", \"0.007\"], [\"70367.90\", \"0.000\"], [\"70368.20\", \"0.000\"], [\"70368.30\", \"0.142\"], [\"70368.40\", \"0.108\"], [\"70368.60\", \"0.219\"], [\"70369.30\", \"0.002\"], [\"70369.40\", \"0.004\"], [\"70369.50\", \"0.002\"], [\"70369.60\", \"0.189\"], [\"70369.70\", \"0.380\"], [\"70369.80\", \"0.293\"], [\"70370.00\", \"0.009\"], [\"70370.60\", \"0.002\"], [\"70370.80\", \"0.010\"], [\"70371.00\", \"0.017\"], [\"70371.60\", \"0.155\"], [\"70371.80\", \"0.000\"], [\"70371.90\", \"0.000\"], [\"70372.20\", \"0.009\"], [\"70372.40\", \"0.002\"], [\"70372.90\", \"0.005\"], [\"70373.50\", \"0.000\"], [\"70373.70\", \"0.077\"], [\"70373.80\", \"0.002\"], [\"70373.90\", \"0.003\"], [\"70374.20\", \"0.002\"], [\"70374.80\", \"0.561\"], [\"70375.10\", \"1.003\"], [\"70375.60\", \"0.513\"], [\"70375.70\", \"0.014\"], [\"70375.80\", \"0.005\"], [\"70376.80\", \"0.195\"], [\"70377.20\", \"0.074\"], [\"70377.40\", \"0.214\"], [\"70377.80\", \"0.000\"], [\"70377.90\", \"0.117\"], [\"70378.70\", \"0.000\"], [\"70379.10\", \"0.189\"], [\"70379.30\", \"0.000\"], [\"70379.40\", \"0.005\"], [\"70379.70\", \"1.071\"], [\"70380.10\", \"0.004\"], [\"70380.20\", \"0.003\"], [\"70380.70\", \"0.002\"], [\"70380.80\", \"0.084\"], [\"70380.90\", \"0.016\"], [\"70381.30\", \"0.010\"], [\"70381.60\", \"0.000\"], [\"70382.20\", \"0.000\"], [\"70382.30\", \"0.294\"], [\"70382.90\", \"0.002\"], [\"70383.00\", \"0.007\"], [\"70383.90\", \"0.065\"], [\"70384.90\", \"0.020\"], [\"70385.30\", \"0.002\"], [\"70386.70\", \"0.020\"], [\"70387.10\", \"0.007\"], [\"70387.20\", \"0.000\"], [\"70387.80\", \"0.006\"], [\"70387.90\", \"0.006\"], [\"70390.20\", \"0.086\"], [\"70391.20\", \"0.190\"], [\"70391.30\", \"0.002\"], [\"70392.20\", \"0.002\"], [\"70393.20\", \"0.002\"], [\"70394.10\", \"0.086\"], [\"70394.30\", \"0.053\"], [\"70394.80\", \"0.191\"], [\"70395.10\", \"0.002\"], [\"70396.10\", \"0.006\"], [\"70397.00\", \"0.018\"], [\"70398.00\", \"0.000\"], [\"70399.00\", \"0.024\"], [\"70399.60\", \"0.002\"], [\"70399.90\", \"0.060\"], [\"70400.90\", \"0.010\"], [\"70401.30\", \"0.073\"], [\"70401.90\", \"0.004\"], [\"70402.30\", \"0.002\"], [\"70404.10\", \"0.405\"], [\"70405.40\", \"0.002\"], [\"70405.60\", \"0.217\"], [\"70407.70\", \"3.665\"], [\"70408.90\", \"0.041\"], [\"70409.00\", \"0.007\"], [\"70409.20\", \"0.900\"], [\"70409.40\", \"0.081\"], [\"70409.50\", \"0.917\"], [\"70410.30\", \"0.000\"], [\"70411.00\", \"0.084\"], [\"70411.30\", \"0.000\"], [\"70412.30\", \"0.082\"], [\"70413.20\", \"0.004\"], [\"70414.20\", \"0.005\"], [\"70415.20\", \"0.017\"], [\"70415.70\", \"0.078\"], [\"70416.20\", \"0.002\"], [\"70416.40\", \"0.249\"], [\"70416.80\", \"0.206\"], [\"70417.50\", \"0.005\"], [\"70417.60\", \"0.525\"], [\"70418.60\", \"0.015\"], [\"70420.70\", \"0.085\"], [\"70421.00\", \"0.000\"], [\"70421.70\", \"0.000\"], [\"70422.50\", \"0.081\"], [\"70422.70\", \"0.006\"], [\"70423.70\", \"0.423\"], [\"70423.80\", \"0.002\"], [\"70423.90\", \"0.167\"], [\"70424.60\", \"0.000\"], [\"70424.70\", \"0.000\"], [\"70425.30\", \"0.173\"], [\"70425.60\", \"0.001\"], [\"70426.40\", \"0.086\"], [\"70426.60\", \"0.002\"], [\"70426.90\", \"0.002\"], [\"70427.40\", \"0.088\"], [\"70427.50\", \"0.025\"], [\"70428.40\", \"0.290\"], [\"70428.50\", \"0.002\"], [\"70429.50\", \"0.086\"], [\"70430.50\", \"0.599\"], [\"70431.40\", \"0.887\"], [\"70432.40\", \"0.284\"], [\"70433.10\", \"0.002\"], [\"70433.40\", \"0.086\"], [\"70434.30\", \"0.001\"], [\"70435.30\", \"0.013\"], [\"70436.30\", \"1.502\"], [\"70436.60\", \"0.002\"], [\"70466.60\", \"0.130\"], [\"70481.00\", \"0.450\"], [\"70492.30\", \"0.187\"], [\"70583.60\", \"0.000\"], [\"70585.50\", \"2.662\"], [\"70827.90\", \"0.000\"], [\"70829.50\", \"0.006\"], [\"70851.20\", \"0.000\"], [\"71052.20\", \"0.010\"], [\"71368.80\", \"6.859\"], [\"100000.00\", \"15.487\"]]}", "symbol": "BTCUSDT"}
{"event": "depthUpdate", "raw_payload": "{\"e\": \"depthUpdate\", \"E\": 1773246384436, \"T\": 1773246384432, \"s\": \"BTCUSDT\", \"U\": 10089703756737, \"u\": 10089703766149, \"pu\": 10089703756526, \"b\": [[\"5000.00\", \"101.418\"], [\"19848.60\", \"0.240\"], [\"19948.60\", \"1.610\"], [\"20048.60\", \"0.510\"], [\"20148.60\", \"0.640\"], [\"66806.40\", \"0.000\"], [\"67675.30\", \"1.328\"], [\"68941.70\", \"0.006\"], [\"69474.70\", \"0.000\"], [\"69645.10\", \"0.000\"], [\"69850.00\", \"5.835\"], [\"69996.90\", \"0.000\"], [\"70223.90\", \"0.000\"], [\"70225.30\", \"0.103\"], [\"70253.10\", \"0.076\"], [\"70260.20\", \"0.165\"], [\"70267.20\", \"0.172\"], [\"70281.80\", \"0.218\"], [\"70292.80\", \"0.006\"], [\"70297.20\", \"0.002\"], [\"70298.70\", \"0.005\"], [\"70308.30\", \"0.089\"], [\"70315.80\", \"0.188\"], [\"70316.10\", \"0.270\"], [\"70317.10\", \"0.075\"], [\"70317.70\", \"0.000\"], [\"70318.40\", \"0.005\"], [\"70318.50\", \"0.921\"], [\"70319.10\", \"0.013\"], [\"70319.20\", \"0.007\"], [\"70321.20\", \"0.000\"], [\"70321.30\", \"0.234\"], [\"70321.90\", \"0.004\"], [\"70322.00\", \"0.063\"], [\"70325.70\", \"0.029\"], [\"70326.80\", \"0.000\"], [\"70332.30\", \"0.035\"], [\"70332.60\", \"0.098\"], [\"70333.50\", \"0.196\"], [\"70334.20\", \"0.002\"], [\"70334.50\", \"1.264\"], [\"70334.80\", \"0.115\"], [\"70335.20\", \"0.542\"], [\"70335.30\", \"0.007\"], [\"70335.60\", \"0.000\"], [\"70335.80\", \"0.003\"], [\"70336.30\", \"0.028\"], [\"70338.00\", \"0.143\"], [\"70338.60\", \"0.003\"], [\"70339.10\", \"0.094\"], [\"70340.10\", \"0.002\"], [\"70340.50\", \"0.063\"], [\"70340.70\", \"0.014\"], [\"70340.80\", \"0.034\"], [\"70341.50\", \"0.014\"], [\"70341.60\", \"1.000\"], [\"70344.50\", \"0.062\"], [\"70348.60\", \"3.885\"]], \"a\": [[\"70348.70\", \"0.081\"], [\"70351.10\", \"0.003\"], [\"70351.50\", \"0.003\"], [\"70352.00\", \"0.001\"], [\"70353.80\", \"0.002\"], [\"70353.90\", \"0.039\"], [\"70355.70\", \"0.077\"], [\"70355.80\", \"0.092\"], [\"70355.90\", \"0.019\"], [\"70356.50\", \"0.003\"], [\"70357.10\", \"0.002\"], [\"70357.20\", \"0.613\"], [\"70357.30\", \"0.034\"], [\"70357.40\", \"0.000\"], [\"70357.50\", \"0.356\"], [\"70358.50\", \"0.425\"], [\"70358.60\", \"0.407\"], [\"70358.70\", \"0.345\"], [\"70359.20\", \"0.010\"], [\"70359.30\", \"0.084\"], [\"70360.50\", \"0.008\"], [\"70360.70\", \"0.002\"], [\"70361.00\", \"0.244\"], [\"70362.30\", \"0.003\"], [\"70362.80\", \"0.309\"], [\"70363.10\", \"0.015\"], [\"70365.40\", \"0.096\"], [\"70367.70\", \"0.000\"], [\"70368.90\", \"0.007\"], [\"70369.60\", \"0.009\"], [\"70369.70\", \"0.378\"], [\"70370.00\", \"0.007\"], [\"70370.80\", \"0.005\"], [\"70371.00\", \"0.010\"], [\"70371.60\", \"0.157\"], [\"70371.90\", \"0.002\"], [\"70372.00\", \"0.004\"], [\"70372.60\", \"0.414\"], [\"70373.20\", \"0.005\"], [\"70373.70\", \"0.006\"], [\"70375.00\", \"0.005\"], [\"70376.10\", \"0.080\"], [\"70376.80\", \"0.008\"], [\"70377.90\", \"0.046\"], [\"70379.70\", \"1.142\"], [\"70380.80\", \"0.075\"], [\"70380.90\", \"0.007\"], [\"70381.50\", \"0.378\"], [\"70381.60\", \"0.009\"], [\"70385.30\", \"0.022\"], [\"70386.70\", \"0.000\"], [\"70387.80\", \"0.004\"], [\"70387.90\", \"0.004\"], [\"70388.50\", \"0.007\"], [\"70388.60\", \"0.005\"], [\"70391.70\", \"0.067\"], [\"70395.90\", \"0.437\"], [\"70396.60\", \"0.002\"], [\"70408.90\", \"0.085\"], [\"70409.60\", \"0.002\"], [\"70413.50\", \"0.000\"], [\"70415.30\", \"0.088\"], [\"70416.10\", \"0.002\"], [\"70417.20\", \"0.086\"], [\"70417.60\", \"0.522\"], [\"70428.60\", \"0.003\"], [\"70429.20\", \"0.073\"], [\"70432.40\", \"0.198\"], [\"70433.40\", \"0.000\"], [\"70436.20\", \"0.073\"], [\"70436.60\", \"0.104\"], [\"70443.30\", \"9.673\"], [\"70487.50\", \"0.152\"], [\"70487.60\", \"0.041\"], [\"70495.90\", \"0.272\"], [\"70499.50\", \"0.802\"], [\"70503.10\", \"0.271\"], [\"70559.80\", \"0.002\"], [\"70561.20\", \"0.019\"], [\"70585.50\", \"0.000\"], [\"70588.40\", \"3.113\"], [\"70609.00\", \"0.008\"], [\"70829.50\", \"0.000\"], [\"70847.40\", \"3.720\"], [\"71052.20\", \"0.010\"], [\"71670.30\", \"0.000\"], [\"72515.30\", \"0.000\"], [\"72517.80\", \"0.595\"], [\"89523.20\", \"0.000\"]]}", "symbol": "BTCUSDT"}
{"event": "depthUpdate", "raw_payload": "{\"e\": \"depthUpdate\", \"E\": 1773246384538, \"T\": 1773246384536, \"s\": \"BTCUSDT\", \"U\": 10089703766389, \"u\": 10089703773387, \"pu\": 10089703766149, \"b\": [[\"1000.00\", \"26.792\"], [\"5000.00\", \"101.418\"], [\"19848.60\", \"0.320\"], [\"19948.60\", \"1.620\"], [\"20048.60\", \"0.510\"], [\"20148.60\", \"0.550\"], [\"33000.00\", \"10.797\"], [\"65051.60\", \"0.000\"], [\"68407.50\", \"0.000\"], [\"69645.10\", \"0.000\"], [\"69850.00\", \"2.115\"], [\"69851.70\", \"3.843\"], [\"70105.30\", \"0.389\"], [\"70115.90\", \"0.008\"], [\"70148.20\", \"0.000\"], [\"70157.50\", \"0.000\"], [\"70157.70\", \"0.646\"], [\"70158.00\", \"0.000\"], [\"70158.20\", \"0.002\"], [\"70158.50\", \"0.000\"], [\"70158.90\", \"0.003\"], [\"70159.20\", \"0.000\"], [\"70159.60\", \"0.002\"], [\"70159.80\", \"7.606\"], [\"70159.90\", \"0.002\"], [\"70183.30\", \"0.047\"], [\"70183.40\", \"0.003\"], [\"70190.40\", \"0.000\"], [\"70211.10\", \"0.029\"], [\"70212.00\", \"0.015\"], [\"70218.20\", \"0.002\"], [\"70218.30\", \"0.082\"], [\"70218.40\", \"0.200\"], [\"70218.80\", \"0.087\"], [\"70218.90\", \"0.002\"], [\"70219.20\", \"0.005\"], [\"70219.50\", \"0.000\"], [\"70219.90\", \"0.046\"], [\"70220.20\", \"0.000\"], [\"70306.10\", \"0.457\"], [\"70306.70\", \"0.003\"], [\"70306.80\", \"0.098\"], [\"70318.40\", \"0.007\"], [\"70318.50\", \"0.923\"], [\"70319.10\", \"0.011\"], [\"70319.20\", \"0.005\"], [\"70321.20\", \"0.002\"], [\"70321.30\", \"0.236\"], [\"70321.90\", \"0.002\"], [\"70322.00\", \"0.061\"], [\"70328.80\", \"0.643\"], [\"70330.10\", \"1.560\"], [\"70332.20\", \"0.050\"], [\"70332.50\", \"0.027\"], [\"70333.40\", \"0.120\"], [\"70333.70\", \"0.000\"], [\"70333.80\", \"0.017\"], [\"70334.10\", \"0.205\"], [\"70334.40\", \"0.129\"], [\"70334.50\", \"1.210\"], [\"70334.60\", \"0.284\"], [\"70334.80\", \"0.080\"], [\"70335.20\", \"0.507\"], [\"70338.00\", \"0.140\"], [\"70340.70\", \"0.004\"], [\"70341.50\", \"0.004\"], [\"70341.60\", \"1.000\"], [\"70343.10\", \"0.005\"], [\"70345.90\", \"0.912\"], [\"70348.60\", \"3.271\"]], \"a\": [[\"70352.40\", \"0.002\"], [\"70355.70\", \"0.123\"], [\"70355.80\", \"0.097\"], [\"70357.00\", \"0.487\"], [\"70357.10\", \"0.297\"], [\"70357.20\", \"0.556\"], [\"70357.40\", \"0.000\"], [\"70357.50\", \"0.074\"], [\"70357.70\", \"0.005\"], [\"70358.40\", \"0.001\"], [\"70358.50\", \"0.000\"], [\"70358.60\", \"0.011\"], [\"70359.30\", \"0.105\"], [\"70360.80\", \"0.002\"], [\"70361.60\", \"0.003\"], [\"70361.90\", \"0.001\"], [\"70362.00\", \"0.002\"], [\"70362.20\", \"0.003\"], [\"70362.40\", \"0.036\"], [\"70362.50\", \"0.111\"], [\"70362.60\", \"0.511\"], [\"70362.70\", \"0.140\"], [\"70362.80\", \"0.411\"], [\"70363.00\", \"0.211\"], [\"70363.50\", \"0.002\"], [\"70363.90\", \"0.142\"], [\"70364.00\", \"0.032\"], [\"70364.20\", \"0.019\"], [\"70364.30\", \"0.037\"], [\"70370.00\", \"0.004\"], [\"70371.60\", \"0.127\"], [\"70373.70\", \"1.006\"], [\"70375.10\", \"0.003\"], [\"70380.80\", \"0.084\"], [\"70380.90\", \"0.016\"], [\"70381.50\", \"0.369\"], [\"70381.60\", \"0.000\"], [\"70381.70\", \"0.008\"], [\"70387.80\", \"0.006\"], [\"70387.90\", \"0.006\"], [\"70388.50\", \"0.005\"], [\"70388.60\", \"0.003\"], [\"70397.70\", \"0.088\"], [\"70411.00\", \"0.011\"], [\"70413.30\", \"0.050\"], [\"70413.50\", \"0.086\"], [\"70416.80\", \"0.234\"], [\"70417.30\", \"0.031\"], [\"70420.40\", \"0.143\"], [\"70424.80\", \"0.025\"], [\"70429.80\", \"0.000\"], [\"70430.50\", \"0.513\"], [\"70431.00\", \"0.002\"], [\"70431.20\", \"0.010\"], [\"70431.40\", \"0.801\"], [\"70431.50\", \"0.097\"], [\"70431.90\", \"0.000\"], [\"70432.00\", \"0.022\"], [\"70432.60\", \"0.002\"], [\"70432.70\", \"0.000\"], [\"70432.80\", \"0.142\"], [\"70432.90\", \"0.004\"], [\"70435.80\", \"0.018\"], [\"70436.60\", \"0.002\"], [\"70438.80\", \"0.036\"], [\"70446.80\", \"0.009\"], [\"70450.10\", \"0.000\"], [\"70485.30\", \"0.079\"], [\"70485.50\", \"17.327\"], [\"70490.10\", \"2.374\"], [\"70491.40\", \"10.444\"], [\"70491.80\", \"0.379\"], [\"70492.20\", \"2.000\"], [\"70492.80\", \"0.088\"], [\"70492.90\", \"0.004\"], [\"70493.20\", \"0.000\"], [\"70493.40\", \"0.337\"], [\"70493.50\", \"0.000\"], [\"70494.60\", \"0.084\"], [\"70499.60\", \"0.079\"], [\"70500.70\", \"0.014\"], [\"70501.60\", \"0.011\"], [\"70507.70\", \"0.011\"], [\"70508.60\", \"0.013\"], [\"70513.30\", \"0.038\"], [\"70514.70\", \"0.007\"], [\"70515.60\", \"0.000\"], [\"70521.30\", \"0.000\"], [\"70521.70\", \"0.013\"], [\"70522.60\", \"0.212\"], [\"70528.30\", \"0.000\"], [\"70528.70\", \"0.007\"], [\"70529.60\", \"1.634\"], [\"70535.70\", \"0.007\"], [\"70536.60\", \"0.000\"], [\"70542.70\", \"0.100\"], [\"70543.00\", \"0.163\"], [\"70543.60\", \"0.000\"], [\"70549.70\", \"0.009\"], [\"70588.00\", \"2.156\"], [\"70613.20\", \"0.002\"], [\"70617.60\", \"0.000\"], [\"70845.70\", \"3.720\"], [\"70847.40\", \"0.000\"], [\"70876.00\", \"0.071\"], [\"71052.20\", \"0.010\"], [\"71257.70\", \"0.486\"], [\"71266.40\", \"0.490\"], [\"71707.80\", \"0.677\"], [\"72459.10\", \"0.000\"], [\"73899.60\", \"0.000\"], [\"75257.70\", \"0.002\"]]}", "symbol": "BTCUSDT"}
{"event": "depthUpdate", "raw_payload": "{\"e\": \"depthUpdate\", \"E\": 1773246384642, \"T\": 1773246384641, \"s\": \"BTCUSDT\", \"U\": 10089703773604, \"u\": 10089703780988, \"pu\": 10089703773387, \"b\": [[\"5000.00\", \"101.418\"], [\"19848.60\", \"0.430\"], [\"19948.60\", \"1.570\"], [\"20048.60\", \"0.540\"], [\"20148.60\", \"0.460\"], [\"33000.00\", \"10.793\"], [\"40000.00\", \"50.522\"], [\"56279.00\", \"0.045\"], [\"66827.30\", \"0.004\"], [\"68941.80\", \"0.005\"], [\"69358.40\", \"0.000\"], [\"69359.80\", \"0.290\"], [\"69434.10\", \"3.152\"], [\"69645.10\", \"0.000\"], [\"69850.10\", \"0.007\"], [\"70075.80\", \"0.010\"], [\"70204.90\", \"0.128\"], [\"70211.20\", \"0.087\"], [\"70211.70\", \"0.083\"], [\"70212.10\", \"0.588\"], [\"70212.80\", \"0.148\"], [\"70298.70\", \"0.003\"], [\"70298.80\", \"0.004\"], [\"70306.00\", \"0.530\"], [\"70306.10\", \"0.457\"], [\"70306.20\", \"0.002\"], [\"70306.80\", \"0.013\"], [\"70308.00\", \"0.008\"], [\"70313.60\", \"0.315\"], [\"70316.10\", \"0.022\"], [\"70318.40\", \"0.005\"], [\"70318.50\", \"0.921\"], [\"70318.70\", \"0.366\"], [\"70319.10\", \"0.007\"], [\"70319.20\", \"0.007\"], [\"70320.50\", \"0.053\"], [\"70321.20\", \"0.002\"], [\"70321.30\", \"0.236\"], [\"70321.90\", \"0.002\"], [\"70322.00\", \"0.061\"], [\"70326.20\", \"0.189\"], [\"70326.50\", \"1.221\"], [\"70328.10\", \"0.003\"], [\"70328.50\", \"0.000\"], [\"70328.80\", \"0.004\"], [\"70329.30\", \"0.080\"], [\"70330.00\", \"0.273\"], [\"70330.10\", \"1.076\"], [\"70331.10\", \"0.009\"], [\"70331.40\", \"0.117\"], [\"70331.60\", \"0.007\"], [\"70331.70\", \"0.004\"], [\"70331.80\", \"0.038\"], [\"70331.90\", \"0.012\"], [\"70332.10\", \"0.006\"], [\"70332.20\", \"0.180\"], [\"70332.60\", \"0.192\"], [\"70333.30\", \"0.063\"], [\"70333.40\", \"0.088\"], [\"70333.50\", \"0.175\"], [\"70333.60\", \"0.003\"], [\"70333.80\", \"0.003\"], [\"70334.00\", \"0.006\"], [\"70334.20\", \"0.000\"], [\"70334.40\", \"0.157\"], [\"70334.50\", \"1.208\"], [\"70334.80\", \"0.000\"], [\"70334.90\", \"0.003\"], [\"70335.20\", \"0.346\"], [\"70335.70\", \"0.047\"], [\"70336.00\", \"0.009\"], [\"70336.30\", \"0.000\"], [\"70337.20\", \"0.018\"], [\"70337.30\", \"0.023\"], [\"70337.50\", \"0.144\"], [\"70338.00\", \"0.056\"], [\"70338.50\", \"0.167\"], [\"70339.60\", \"0.003\"], [\"70340.60\", \"0.000\"], [\"70341.70\", \"0.005\"], [\"70341.80\", \"0.532\"], [\"70341.90\", \"0.003\"], [\"70343.00\", \"0.002\"], [\"70344.50\", \"0.059\"], [\"70345.60\", \"0.002\"], [\"70345.80\", \"0.000\"], [\"70345.90\", \"0.000\"], [\"70346.00\", \"0.655\"], [\"70346.20\", \"0.002\"], [\"70348.60\", \"3.188\"]], \"a\": [[\"70348.70\", \"0.712\"], [\"70348.80\", \"0.004\"], [\"70352.00\", \"0.001\"], [\"70352.90\", \"0.342\"], [\"70353.90\", \"0.382\"], [\"70355.30\", \"1.068\"], [\"70355.40\", \"0.352\"], [\"70355.70\", \"0.225\"], [\"70355.80\", \"0.097\"], [\"70356.60\", \"0.063\"], [\"70356.70\", \"0.007\"], [\"70356.80\", \"0.429\"], [\"70356.90\", \"0.004\"], [\"70357.00\", \"0.004\"], [\"70357.10\", \"0.297\"], [\"70358.30\", \"0.024\"], [\"70358.40\", \"0.001\"], [\"70358.60\", \"0.004\"], [\"70359.00\", \"0.021\"], [\"70359.30\", \"0.084\"], [\"70362.40\", \"0.076\"], [\"70362.50\", \"0.111\"], [\"70362.80\", \"0.309\"], [\"70363.00\", \"0.214\"], [\"70363.10\", \"0.043\"], [\"70363.20\", \"0.007\"], [\"70363.30\", \"0.166\"], [\"70364.00\", \"0.104\"], [\"70364.10\", \"0.037\"], [\"70364.30\", \"0.109\"], [\"70364.40\", \"0.677\"], [\"70365.10\", \"0.156\"], [\"70366.90\", \"0.003\"], [\"70368.30\", \"0.000\"], [\"70368.50\", \"0.008\"], [\"70368.60\", \"0.218\"], [\"70368.80\", \"0.002\"], [\"70370.60\", \"0.002\"], [\"70371.00\", \"0.081\"], [\"70371.60\", \"0.085\"], [\"70371.90\", \"0.000\"], [\"70372.00\", \"0.000\"], [\"70372.10\", \"1.576\"], [\"70372.70\", \"0.108\"], [\"70373.70\", \"0.006\"], [\"70374.60\", \"0.086\"], [\"70375.00\", \"0.025\"], [\"70375.30\", \"0.020\"], [\"70376.10\", \"0.009\"], [\"70376.80\", \"0.195\"], [\"70377.20\", \"0.003\"], [\"70378.70\", \"0.086\"], [\"70380.80\", \"0.075\"], [\"70380.90\", \"0.007\"], [\"70381.50\", \"0.378\"], [\"70381.60\", \"0.009\"], [\"70383.80\", \"0.028\"], [\"70384.40\", \"0.089\"], [\"70384.90\", \"0.000\"], [\"70385.30\", \"0.002\"], [\"70387.80\", \"0.004\"], [\"70387.90\", \"0.004\"], [\"70388.50\", \"0.007\"], [\"70388.60\", \"0.005\"], [\"70393.90\", \"0.094\"], [\"70395.70\", \"0.086\"], [\"70409.50\", \"0.789\"], [\"70410.40\", \"0.128\"], [\"70410.90\", \"0.075\"], [\"70413.50\", \"0.114\"], [\"70417.20\", \"0.000\"], [\"70417.30\", \"0.003\"], [\"70423.60\", \"0.228\"], [\"70423.90\", \"0.081\"], [\"70424.20\", \"0.036\"], [\"70424.60\", \"0.072\"], [\"70424.90\", \"0.036\"], [\"70425.30\", \"0.087\"], [\"70426.40\", \"0.000\"], [\"70427.40\", \"0.002\"], [\"70427.80\", \"0.230\"], [\"70428.40\", \"0.204\"], [\"70429.50\", \"0.000\"], [\"70449.30\", \"0.000\"], [\"70467.70\", \"0.002\"], [\"70483.80\", \"0.036\"], [\"70484.50\", \"0.243\"], [\"70484.90\", \"0.077\"], [\"70485.40\", \"0.197\"], [\"70491.60\", \"0.038\"], [\"70587.50\", \"3.001\"], [\"70588.00\", \"1.497\"], [\"70588.40\", \"0.005\"], [\"71609.80\", \"0.000\"], [\"72459.70\", \"3.997\"], [\"73889.40\", \"0.004\"], [\"89523.20\", \"0.000\"]]}", "symbol": "BTCUSDT"}
{"event": "depthUpdate", "raw_payload": "{\"e\": \"depthUpdate\", \"E\": 1773246384744, \"T\": 1773246384741, \"s\": \"BTCUSDT\", \"U\": 10089703781053, \"u\": 10089703787750, \"pu\": 10089703780988, \"b\": [[\"5000.00\", \"101.418\"], [\"19848.60\", \"0.600\"], [\"19948.60\", \"1.400\"], [\"20048.60\", \"0.620\"], [\"20148.60\", \"0.380\"], [\"66802.20\", \"0.002\"], [\"66834.20\", \"0.004\"], [\"68941.70\", \"0.009\"], [\"68941.80\", \"0.002\"], [\"69645.10\", \"0.000\"], [\"69769.70\", \"45.740\"], [\"69850.10\", \"0.000\"], [\"69851.70\", \"0.123\"], [\"69853.20\", \"0.000\"], [\"69854.50\", \"3.720\"], [\"69962.00\", \"0.194\"], [\"69996.90\", \"0.000\"], [\"70114.80\", \"0.007\"], [\"70176.30\", \"0.040\"], [\"70211.40\", \"0.079\"], [\"70211.70\", \"0.126\"], [\"70211.80\", \"0.399\"], [\"70212.40\", \"0.060\"], [\"70213.10\", \"0.035\"], [\"70278.30\", \"0.304\"], [\"70298.40\", \"0.005\"], [\"70298.80\", \"0.002\"], [\"70315.80\", \"0.074\"], [\"70316.80\", \"0.049\"], [\"70320.50\", \"0.002\"], [\"70326.50\", \"0.582\"], [\"70329.40\", \"0.641\"], [\"70330.10\", \"1.083\"], [\"70331.10\", \"0.007\"], [\"70331.40\", \"0.115\"], [\"70331.50\", \"0.271\"], [\"70332.20\", \"0.266\"], [\"70332.60\", \"0.232\"], [\"70332.90\", \"0.065\"], [\"70333.20\", \"2.121\"], [\"70333.30\", \"1.271\"], [\"70334.00\", \"0.041\"], [\"70334.50\", \"0.051\"], [\"70335.30\", \"0.121\"], [\"70335.40\", \"0.372\"], [\"70336.30\", \"0.142\"], [\"70337.50\", \"0.002\"], [\"70338.00\", \"0.059\"], [\"70340.20\", \"1.000\"], [\"70340.30\", \"0.339\"], [\"70340.40\", \"0.406\"], [\"70341.60\", \"0.000\"], [\"70341.90\", \"0.003\"], [\"70342.00\", \"0.401\"], [\"70342.10\", \"0.003\"], [\"70343.00\", \"0.398\"], [\"70343.10\", \"0.660\"], [\"70346.00\", \"0.000\"], [\"70346.10\", \"0.005\"], [\"70346.20\", \"0.002\"], [\"70348.60\", \"2.776\"]], \"a\": [[\"70348.70\", \"0.166\"], [\"70348.80\", \"0.004\"], [\"70351.40\", \"0.002\"], [\"70352.70\", \"0.005\"], [\"70352.80\", \"0.061\"], [\"70353.80\", \"0.000\"], [\"70353.90\", \"0.198\"], [\"70355.20\", \"0.436\"], [\"70355.40\", \"0.003\"], [\"70355.70\", \"0.067\"], [\"70355.80\", \"0.097\"], [\"70356.60\", \"0.006\"], [\"70356.70\", \"0.000\"], [\"70356.80\", \"0.003\"], [\"70357.00\", \"0.006\"], [\"70358.10\", \"0.007\"], [\"70358.60\", \"0.429\"], [\"70359.10\", \"0.007\"], [\"70359.20\", \"0.006\"], [\"70359.30\", \"0.189\"], [\"70360.30\", \"0.060\"], [\"70360.60\", \"0.001\"], [\"70362.40\", \"0.036\"], [\"70362.60\", \"0.536\"], [\"70362.80\", \"0.309\"], [\"70363.30\", \"0.068\"], [\"70363.60\", \"0.037\"], [\"70364.00\", \"0.140\"], [\"70364.20\", \"0.019\"], [\"70364.30\", \"0.181\"], [\"70364.40\", \"0.038\"], [\"70365.10\", \"0.014\"], [\"70365.70\", \"0.647\"], [\"70367.30\", \"0.044\"], [\"70368.30\", \"0.142\"], [\"70368.50\", \"0.004\"], [\"70368.60\", \"0.216\"], [\"70368.80\", \"0.000\"], [\"70369.10\", \"0.000\"], [\"70369.60\", \"0.196\"], [\"70369.70\", \"0.003\"], [\"70370.20\", \"0.375\"], [\"70370.30\", \"0.003\"], [\"70370.40\", \"0.002\"], [\"70370.60\", \"0.004\"], [\"70370.70\", \"0.070\"], [\"70370.80\", \"0.009\"], [\"70371.10\", \"0.239\"], [\"70371.20\", \"0.005\"], [\"70371.50\", \"0.002\"], [\"70371.70\", \"0.000\"], [\"70372.10\", \"0.579\"], [\"70372.70\", \"1.037\"], [\"70373.20\", \"0.192\"], [\"70374.40\", \"0.075\"], [\"70374.60\", \"0.000\"], [\"70378.70\", \"0.000\"], [\"70380.80\", \"0.084\"], [\"70380.90\", \"0.016\"], [\"70381.50\", \"0.369\"], [\"70381.60\", \"0.000\"], [\"70383.20\", \"0.001\"], [\"70383.80\", \"0.000\"], [\"70385.40\", \"0.098\"], [\"70386.30\", \"0.088\"], [\"70387.30\", \"0.088\"], [\"70410.90\", \"0.078\"], [\"70413.50\", \"0.114\"], [\"70415.30\", \"0.002\"], [\"70417.30\", \"0.003\"], [\"70423.00\", \"0.044\"], [\"70423.90\", \"0.117\"], [\"70424.00\", \"0.031\"], [\"70424.60\", \"0.108\"], [\"70424.80\", \"0.061\"], [\"70428.60\", \"0.000\"], [\"70442.10\", \"0.043\"], [\"70483.40\", \"0.228\"], [\"70484.10\", \"0.039\"], [\"70484.80\", \"0.187\"], [\"70485.20\", \"0.036\"], [\"70486.30\", \"0.102\"], [\"70499.50\", \"0.615\"], [\"70503.10\", \"0.084\"], [\"70520.20\", \"0.036\"], [\"70520.80\", \"0.039\"], [\"70842.80\", \"3.720\"], [\"70844.20\", \"0.000\"], [\"70845.70\", \"0.000\"], [\"70923.30\", \"42.683\"], [\"71052.20\", \"0.010\"], [\"71755.70\", \"0.000\"]]}", "symbol": "BTCUSDT"}
{"event": "depthUpdate", "raw_payload": "{\"e\": \"depthUpdate\", \"E\": 1773246384846, \"T\": 1773246384844, \"s\": \"BTCUSDT\", \"U\": 10089703788056, \"u\": 10089703793684, \"pu\": 10089703787750, \"b\": [[\"1000.00\", \"26.792\"], [\"5000.00\", \"101.418\"], [\"19848.60\", \"0.770\"], [\"19948.60\", \"1.230\"], [\"20048.60\", \"0.710\"], [\"20148.60\", \"0.290\"], [\"40000.00\", \"50.271\"], [\"63313.70\", \"0.002\"], [\"68348.60\", \"0.005\"], [\"68601.70\", \"0.624\"], [\"69394.80\", \"0.000\"], [\"69434.20\", \"0.007\"], [\"69533.10\", \"0.000\"], [\"69645.10\", \"0.000\"], [\"69769.80\", \"3.243\"], [\"69854.50\", \"0.000\"], [\"70108.80\", \"0.047\"], [\"70114.80\", \"0.000\"], [\"70150.40\", \"0.044\"], [\"70150.70\", \"0.047\"], [\"70152.50\", \"0.054\"], [\"70213.10\", \"0.070\"], [\"70238.60\", \"2.510\"], [\"70250.90\", \"0.147\"], [\"70301.00\", \"0.570\"], [\"70312.10\", \"0.048\"], [\"70313.60\", \"0.067\"], [\"70315.20\", \"0.066\"], [\"70317.70\", \"0.248\"], [\"70320.30\", \"0.373\"], [\"70321.20\", \"0.002\"], [\"70321.30\", \"0.236\"], [\"70321.90\", \"0.002\"], [\"70322.00\", \"0.061\"], [\"70327.60\", \"0.294\"], [\"70329.00\", \"0.015\"], [\"70329.40\", \"1.125\"], [\"70330.50\", \"0.500\"], [\"70330.70\", \"0.027\"], [\"70330.80\", \"0.005\"], [\"70330.90\", \"0.028\"], [\"70331.00\", \"0.005\"], [\"70331.20\", \"0.035\"], [\"70331.60\", \"0.518\"], [\"70332.40\", \"0.206\"], [\"70332.70\", \"0.000\"], [\"70333.70\", \"0.035\"], [\"70333.90\", \"0.003\"], [\"70334.00\", \"0.073\"], [\"70334.10\", \"0.231\"], [\"70334.30\", \"0.017\"], [\"70334.40\", \"0.235\"], [\"70334.50\", \"0.051\"], [\"70334.60\", \"0.375\"], [\"70334.70\", \"0.090\"], [\"70334.90\", \"0.003\"], [\"70335.30\", \"0.510\"], [\"70335.40\", \"0.009\"], [\"70335.70\", \"0.047\"], [\"70336.20\", \"0.091\"], [\"70336.30\", \"0.000\"], [\"70336.60\", \"0.405\"], [\"70338.00\", \"0.056\"], [\"70338.40\", \"0.108\"], [\"70338.50\", \"0.214\"], [\"70338.80\", \"0.007\"], [\"70339.20\", \"0.144\"], [\"70339.60\", \"0.003\"], [\"70340.00\", \"0.116\"], [\"70343.10\", \"0.005\"], [\"70344.30\", \"0.401\"], [\"70345.60\", \"0.511\"], [\"70346.40\", \"0.003\"], [\"70348.60\", \"3.493\"]], \"a\": [[\"70348.70\", \"0.169\"], [\"70352.00\", \"0.001\"], [\"70352.60\", \"0.008\"], [\"70352.70\", \"0.058\"], [\"70352.80\", \"0.006\"], [\"70353.90\", \"0.039\"], [\"70355.20\", \"0.000\"], [\"70355.30\", \"0.002\"], [\"70355.80\", \"0.094\"], [\"70357.00\", \"0.442\"], [\"70357.10\", \"0.722\"], [\"70357.30\", \"0.048\"], [\"70357.70\", \"0.002\"], [\"70358.10\", \"0.000\"], [\"70358.30\", \"0.003\"], [\"70358.50\", \"0.213\"], [\"70358.80\", \"0.010\"], [\"70359.00\", \"0.000\"], [\"70359.30\", \"0.084\"], [\"70362.40\", \"0.006\"], [\"70362.50\", \"0.111\"], [\"70362.80\", \"0.411\"], [\"70362.90\", \"0.083\"], [\"70363.10\", \"0.015\"], [\"70363.40\", \"0.000\"], [\"70364.10\", \"0.009\"], [\"70365.70\", \"0.008\"], [\"70366.10\", \"0.307\"], [\"70367.20\", \"50.035\"], [\"70367.30\", \"0.004\"], [\"70367.70\", \"0.639\"], [\"70369.40\", \"0.044\"], [\"70370.80\", \"0.005\"], [\"70371.30\", \"0.188\"], [\"70372.00\", \"0.004\"], [\"70372.20\", \"0.002\"], [\"70372.70\", \"0.002\"], [\"70373.60\", \"1.443\"], [\"70374.10\", \"1.005\"], [\"70374.20\", \"0.009\"], [\"70374.40\", \"0.004\"], [\"70375.00\", \"0.005\"], [\"70375.70\", \"0.007\"], [\"70376.10\", \"0.009\"], [\"70377.30\", \"0.014\"], [\"70377.80\", \"0.071\"], [\"70378.40\", \"0.027\"], [\"70380.80\", \"0.084\"], [\"70380.90\", \"0.016\"], [\"70381.50\", \"0.369\"], [\"70381.60\", \"0.000\"], [\"70384.40\", \"0.003\"], [\"70385.10\", \"0.847\"], [\"70385.40\", \"0.012\"], [\"70385.60\", \"0.000\"], [\"70386.30\", \"0.002\"], [\"70386.70\", \"0.000\"], [\"70387.30\", \"0.002\"], [\"70392.30\", \"0.192\"], [\"70393.90\", \"0.008\"], [\"70395.70\", \"0.000\"], [\"70397.70\", \"0.002\"], [\"70398.60\", \"0.000\"], [\"70399.60\", \"0.088\"], [\"70400.60\", \"0.122\"], [\"70400.80\", \"0.019\"], [\"70401.50\", \"0.638\"], [\"70402.50\", \"0.096\"], [\"70403.50\", \"0.086\"], [\"70404.50\", \"0.086\"], [\"70405.40\", \"0.088\"], [\"70423.20\", \"0.077\"], [\"70483.40\", \"0.253\"], [\"70587.50\", \"0.007\"], [\"70841.60\", \"3.722\"], [\"70842.80\", \"0.000\"], [\"71052.20\", \"0.010\"], [\"73162.60\", \"0.002\"], [\"73893.30\", \"0.004\"], [\"77383.60\", \"0.004\"], [\"89523.20\", \"0.000\"]]}", "symbol": "BTCUSDT"}
{"event": "snapshot", "last_update_id": 10089703790539, "symbol": "BTCUSDT", "bids": [["70348.60", "2.834"], ["70348.50", "0.087"], ["70347.50", "0.002"], ["70347.40", "0.002"], ["70347.30", "0.086"], ["70347.10", "0.002"], ["70346.90", "0.003"], ["70346.40", "0.001"], ["70346.30", "0.087"], ["70346.20", "0.002"], ["70346.10", "0.005"], ["70345.60", "0.511"], ["70345.50", "0.136"], ["70345.40", "0.004"], ["70345.20", "0.001"], ["70345.10", "0.086"], ["70345.00", "0.209"], ["70344.90", "0.005"], ["70344.80", "0.006"], ["70344.50", "0.059"], ["70344.40", "0.003"], ["70344.30", "0.401"], ["70344.10", "0.003"], ["70343.90", "0.007"], ["70343.60", "0.003"], ["70343.40", "0.001"], ["70343.20", "0.002"], ["70343.10", "0.660"], ["70343.00", "0.398"], ["70342.80", "0.001"], ["70342.60", "0.005"], ["70342.50", "0.003"], ["70342.20", "0.001"], ["70342.10", "0.003"], ["70342.00", "0.401"], ["70341.90", "0.003"], ["70341.80", "0.532"], ["70341.70", "0.005"], ["70341.50", "0.004"], ["70341.40", "0.205"], ["70341.10", "0.003"], ["70340.90", "0.008"], ["70340.80", "0.034"], ["70340.70", "0.004"], ["70340.50", "0.063"], ["70340.40", "0.406"], ["70340.30", "0.339"], ["70340.20", "1.000"], ["70340.10", "0.002"], ["70340.00", "0.019"], ["70339.90", "0.001"], ["70339.80", "0.003"], ["70339.60", "0.100"], ["70339.50", "0.002"], ["70339.40", "0.002"], ["70339.30", "0.009"], ["70339.20", "0.002"], ["70339.10", "0.094"], ["70339.00", "0.001"], ["70338.90", "0.002"], ["70338.80", "0.007"], ["70338.70", "0.018"], ["70338.60", "0.003"], ["70338.50", "0.167"], ["70338.40", "0.155"], ["70338.20", "0.001"], ["70338.10", "0.020"], ["70338.00", "0.059"], ["70337.80", "0.206"], ["70337.70", "0.016"], ["70337.60", "0.016"], ["70337.50", "0.002"], ["70337.40", "0.019"], ["70337.30", "0.023"], ["70337.20", "0.018"], ["70336.90", "0.003"], ["70336.70", "0.006"], ["70336.60", "0.301"], ["70336.50", "0.004"], ["70336.40", "0.003"], ["70336.30", "0.142"], ["70336.20", "0.181"], ["70336.10", "0.005"], ["70336.00", "0.009"], ["70335.90", "0.003"], ["70335.80", "0.003"], ["70335.70", "0.047"], ["70335.50", "0.001"], ["70335.40", "0.372"], ["70335.30", "0.581"], ["70335.20", "0.346"], ["70335.10", "0.671"], ["70335.00", "0.059"], ["70334.90", "0.046"], ["70334.70", "0.090"], ["70334.60", "0.284"], ["70334.50", "0.051"], ["70334.40", "0.157"], ["70334.30", "0.017"], ["70334.10", "0.231"], ["70334.00", "0.105"], ["70333.90", "0.035"], ["70333.80", "0.003"], ["70333.70", "0.035"], ["70333.60", "0.003"], ["70333.50", "0.175"], ["70333.40", "0.088"], ["70333.30", "1.271"], ["70333.20", "2.121"], ["70333.10", "0.007"], ["70333.00", "0.007"], ["70332.90", "0.065"], ["70332.60", "0.232"], ["70332.50", "0.027"], ["70332.40", "0.175"], ["70332.30", "0.035"], ["70332.20", "0.266"], ["70332.10", "0.006"], ["70332.00", "0.003"], ["70331.90", "0.012"], ["70331.80", "0.038"], ["70331.70", "0.004"], ["70331.60", "0.007"], ["70331.50", "0.271"], ["70331.40", "0.115"], ["70331.30", "0.002"], ["70331.20", "0.007"], ["70331.10", "0.007"], ["70331.00", "0.005"], ["70330.80", "0.033"], ["70330.70", "0.006"], ["70330.60", "0.424"], ["70330.50", "0.528"], ["70330.40", "0.042"], ["70330.30", "0.003"], ["70330.10", "1.083"], ["70330.00", "0.273"], ["70329.90", "0.070"], ["70329.80", "0.003"], ["70329.70", "0.011"], ["70329.60", "0.005"], ["70329.50", "0.215"], ["70329.40", "0.641"], ["70329.30", "0.080"], ["70329.20", "0.512"], ["70329.10", "0.362"], ["70329.00", "0.015"], ["70328.90", "0.002"], ["70328.80", "0.004"], ["70328.70", "0.002"], ["70328.60", "0.201"], ["70328.40", "0.002"], ["70328.30", "0.005"], ["70328.20", "0.003"], ["70328.10", "0.003"], ["70328.00", "0.006"], ["70327.90", "0.002"], ["70327.70", "0.003"], ["70327.60", "0.294"], ["70327.50", "0.221"], ["70327.40", "0.006"], ["70327.30", "0.002"], ["70327.20", "0.049"], ["70327.00", "0.518"], ["70326.50", "0.582"], ["70326.40", "0.089"], ["70326.30", "0.042"], ["70326.20", "0.189"], ["70326.10", "0.004"], ["70326.00", "0.003"], ["70325.90", "0.002"], ["70325.80", "0.120"], ["70325.70", "0.029"], ["70325.60", "0.002"], ["70325.50", "0.100"], ["70325.40", "0.654"], ["70325.30", "0.073"], ["70325.00", "0.212"], ["70324.80", "0.005"], ["70324.70", "0.040"], ["70324.60", "0.010"], ["70324.50", "0.516"], ["70324.40", "0.002"], ["70324.30", "0.377"], ["70324.20", "0.380"], ["70324.10", "0.006"], ["70324.00", "0.003"], ["70323.90", "0.002"], ["70323.70", "0.061"], ["70323.60", "0.005"], ["70323.50", "0.003"], ["70323.40", "0.014"], ["70323.30", "0.002"], ["70323.20", "0.002"], ["70323.10", "1.423"], ["70323.00", "0.017"], ["70322.90", "0.007"], ["70322.80", "0.003"], ["70322.70", "0.007"], ["70322.50", "0.004"], ["70322.40", "0.002"], ["70322.30", "0.511"], ["70322.20", "0.007"], ["70322.10", "0.052"], ["70322.00", "0.061"], ["70321.90", "0.002"], ["70321.80", "0.307"], ["70321.70", "0.002"], ["70321.60", "0.035"], ["70321.50", "0.013"], ["70321.40", "0.205"], ["70321.30", "0.236"], ["70321.20", "0.002"], ["70321.10", "0.089"], ["70320.90", "0.001"], ["70320.80", "0.015"], ["70320.60", "0.002"], ["70320.50", "0.002"], ["70320.30", "0.259"], ["70320.20", "0.029"], ["70320.10", "0.436"], ["70320.00", "0.048"], ["70319.90", "0.002"], ["70319.80", "0.514"], ["70319.70", "0.022"], ["70319.50", "0.096"], ["70319.40", "0.193"], ["70319.20", "0.007"], ["70319.10", "0.007"], ["70319.00", "0.007"], ["70318.90", "0.049"], ["70318.80", "0.010"], ["70318.70", "0.366"], ["70318.50", "0.921"], ["70318.40", "0.005"], ["70318.30", "0.002"], ["70318.20", "0.383"], ["70318.10", "0.004"], ["70318.00", "0.055"], ["70317.90", "0.002"], ["70317.80", "0.002"], ["70317.60", "0.512"], ["70317.50", "0.203"], ["70317.40", "1.074"], ["70317.30", "0.009"], ["70317.20", "0.003"], ["70317.10", "0.075"], ["70317.00", "0.017"], ["70316.90", "0.140"], ["70316.80", "0.049"], ["70316.70", "0.007"], ["70316.60", "0.036"], ["70316.50", "0.004"], ["70316.40", "0.001"], ["70316.30", "0.003"], ["70316.10", "0.022"], ["70316.00", "0.359"], ["70315.90", "0.002"], ["70315.80", "0.074"], ["70315.70", "0.391"], ["70315.60", "0.194"], ["70315.40", "1.080"], ["70315.30", "1.105"], ["70315.20", "0.636"], ["70315.10", "0.040"], ["70315.00", "0.008"], ["70314.90", "0.006"], ["70314.70", "0.005"], ["70314.60", "0.002"], ["70314.50", "0.002"], ["70314.30", "0.437"], ["70314.20", "0.003"], ["70314.00", "0.002"], ["70313.80", "0.030"], ["70313.70", "0.003"], ["70313.60", "0.315"], ["70313.50", "0.379"], ["70313.40", "0.143"], ["70313.30", "0.002"], ["70313.10", "0.206"], ["70313.00", "0.511"], ["70312.90", "1.004"], ["70312.80", "0.005"], ["70312.60", "0.073"], ["70312.50", "0.006"], ["70312.40", "0.002"], ["70312.30", "0.010"], ["70312.10", "0.008"], ["70312.00", "0.037"], ["70311.90", "0.030"], ["70311.80", "0.027"], ["70311.70", "0.245"], ["70311.60", "0.003"], ["70311.50", "1.070"], ["70311.40", "1.969"], ["70311.30", "0.389"], ["70311.20", "0.383"], ["70311.10", "0.007"], ["70310.90", "0.215"], ["70310.80", "0.003"], ["70310.70", "0.117"], ["70310.60", "0.511"], ["70310.50", "0.202"], ["70310.40", "0.004"], ["70310.30", "10.226"], ["70310.20", "0.002"], ["70310.00", "0.084"], ["70309.90", "0.056"], ["70309.80", "0.040"], ["70309.60", "0.193"], ["70309.40", "0.001"], ["70309.20", "0.011"], ["70309.10", "0.213"], ["70309.00", "0.002"], ["70308.90", "0.540"], ["70308.80", "0.117"], ["70308.70", "0.006"], ["70308.60", "0.002"], ["70308.50", "0.002"], ["70308.40", "0.024"], ["70308.30", "0.089"], ["70308.10", "0.007"], ["70308.00", "0.008"], ["70307.90", "0.087"], ["70307.80", "0.001"], ["70307.70", "0.007"], ["70307.60", "0.006"], ["70307.50", "0.014"], ["70307.40", "0.002"], ["70307.20", "0.034"], ["70307.10", "0.025"], ["70307.00", "0.003"], ["70306.90", "0.003"], ["70306.80", "0.013"], ["70306.70", "0.003"], ["70306.50", "0.001"], ["70306.40", "0.003"], ["70306.20", "0.002"], ["70306.10", "0.457"], ["70306.00", "0.530"], ["70305.90", "0.817"], ["70305.80", "0.002"], ["70305.70", "0.005"], ["70305.60", "0.005"], ["70305.40", "0.001"], ["70305.30", "0.306"], ["70305.20", "0.101"], ["70305.00", "0.003"], ["70304.90", "0.002"], ["70304.80", "0.003"], ["70304.60", "0.008"], ["70304.50", "0.006"], ["70304.30", "0.536"], ["70304.20", "0.008"], ["70304.10", "0.002"], ["70303.90", "0.002"], ["70303.70", "0.664"], ["70303.60", "1.813"], ["70303.50", "0.003"], ["70303.40", "0.002"], ["70303.20", "0.002"], ["70303.10", "0.033"], ["70303.00", "0.347"], ["70302.90", "0.028"], ["70302.60", "0.004"], ["70302.50", "0.004"], ["70302.40", "0.003"], ["70302.20", "0.003"], ["70302.10", "0.002"], ["70302.00", "0.008"], ["70301.90", "0.004"], ["70301.80", "0.513"], ["70301.70", "0.587"], ["70301.60", "0.023"], ["70301.50", "0.759"], ["70301.40", "0.002"], ["70301.30", "0.004"], ["70301.00", "0.570"], ["70300.90", "0.002"], ["70300.80", "0.003"], ["70300.60", "0.023"], ["70300.50", "2.030"], ["70300.40", "0.007"], ["70300.30", "0.002"], ["70300.20", "0.001"], ["70300.10", "0.003"], ["70300.00", "1.547"], ["70299.80", "0.018"], ["70299.70", "0.010"], ["70299.60", "0.002"], ["70299.50", "0.020"], ["70299.40", "0.006"], ["70299.30", "0.084"], ["70299.20", "0.002"], ["70299.10", "0.002"], ["70299.00", "0.239"], ["70298.80", "0.002"], ["70298.70", "0.003"], ["70298.60", "0.002"], ["70298.50", "0.014"], ["70298.40", "0.005"], ["70298.30", "0.012"], ["70298.10", "0.002"], ["70297.60", "0.086"], ["70297.40", "0.100"], ["70297.30", "0.194"], ["70297.20", "0.002"], ["70297.00", "0.002"], ["70296.90", "0.263"], ["70296.80", "0.968"], ["70296.60", "0.004"], ["70296.50", "0.235"], ["70296.40", "0.002"], ["70296.30", "0.002"], ["70296.10", "0.279"], ["70296.00", "0.006"], ["70295.90", "0.005"], ["70295.80", "0.053"], ["70295.60", "0.003"], ["70295.50", "0.541"], ["70295.40", "0.016"], ["70295.30", "0.002"], ["70295.20", "0.003"], ["70295.00", "0.002"], ["70294.80", "0.344"], ["70294.50", "0.244"], ["70294.40", "0.030"], ["70294.30", "0.403"], ["70294.20", "0.865"], ["70294.10", "2.108"], ["70294.00", "2.832"], ["70293.90", "0.008"], ["70293.80", "0.004"], ["70293.70", "0.011"], ["70293.60", "0.009"], ["70293.50", "0.002"], ["70293.40", "0.007"], ["70293.30", "1.078"], ["70293.20", "0.007"], ["70293.10", "1.204"], ["70293.00", "0.468"], ["70292.80", "0.006"], ["70292.70", "0.003"], ["70292.60", "0.002"], ["70292.40", "0.004"], ["70292.20", "1.073"], ["70292.10", "0.002"], ["70292.00", "0.054"], ["70291.80", "0.012"], ["70291.70", "0.049"], ["70291.60", "0.182"], ["70291.50", "0.002"], ["70291.40", "0.039"], ["70291.30", "0.001"], ["70291.20", "0.310"], ["70291.10", "0.542"], ["70291.00", "0.851"], ["70290.90", "0.349"], ["70290.80", "0.204"], ["70290.60", "0.087"], ["70290.50", "0.405"], ["70290.40", "0.402"], ["70290.30", "0.002"], ["70290.20", "0.002"], ["70290.10", "0.002"], ["70290.00", "0.081"], ["70289.90", "0.002"], ["70289.80", "0.010"], ["70289.70", "0.004"], ["70289.50", "0.215"], ["70289.20", "0.851"], ["70289.10", "0.010"], ["70288.90", "0.008"], ["70288.80", "0.346"], ["70288.70", "0.003"], ["70288.50", "0.024"], ["70288.20", "0.004"], ["70288.10", "0.511"], ["70288.00", "0.010"], ["70287.90", "0.023"], ["70287.80", "0.002"], ["70287.70", "0.091"], ["70287.50", "0.104"], ["70287.40", "0.011"], ["70287.30", "0.207"], ["70287.20", "0.005"], ["70287.10", "0.003"], ["70287.00", "0.752"], ["70286.90", "0.060"], ["70286.80", "0.390"], ["70286.70", "0.002"], ["70286.60", "0.005"], ["70286.50", "0.002"], ["70286.40", "0.045"], ["70286.30", "0.248"], ["70286.20", "0.087"], ["70286.10", "0.002"], ["70286.00", "0.030"], ["70285.90", "0.004"], ["70285.80", "0.008"], ["70285.70", "1.293"], ["70285.60", "0.010"], ["70285.30", "0.011"], ["70285.00", "0.235"], ["70284.90", "0.002"], ["70284.80", "0.018"], ["70284.70", "0.070"], ["70284.40", "0.191"], ["70284.30", "0.002"], ["70284.20", "0.041"], ["70284.00", "0.072"], ["70283.90", "0.002"], ["70283.70", "1.580"], ["70283.60", "0.079"], ["70283.40", "0.012"], ["70283.30", "0.002"], ["70283.20", "0.005"], ["70283.10", "0.054"], ["70282.90", "0.002"], ["70282.60", "0.344"], ["70282.50", "0.039"], ["70282.40", "0.061"], ["70282.30", "0.002"], ["70282.20", "0.007"], ["70282.10", "0.002"], ["70282.00", "0.008"], ["70281.90", "0.833"], ["70281.80", "0.218"], ["70281.70", "0.003"], ["70281.60", "0.209"], ["70281.50", "0.008"], ["70281.40", "1.002"], ["70281.30", "3.367"], ["70281.20", "0.002"], ["70281.00", "0.005"], ["70280.90", "0.391"], ["70280.60", "0.006"], ["70280.50", "0.664"], ["70280.20", "0.008"], ["70280.10", "0.191"], ["70280.00", "1.428"], ["70279.90", "0.076"], ["70279.80", "0.002"], ["70279.70", "0.052"], ["70279.60", "0.121"], ["70279.40", "0.081"], ["70279.30", "0.002"], ["70279.10", "0.201"], ["70279.00", "0.002"], ["70278.90", "0.022"], ["70278.70", "0.002"], ["70278.60", "0.003"], ["70278.50", "0.058"], ["70278.30", "0.304"], ["70278.20", "0.091"], ["70278.00", "0.528"], ["70277.90", "6.303"], ["70277.80", "0.204"], ["70277.70", "0.089"], ["70277.60", "0.019"], ["70277.30", "0.002"], ["70277.10", "0.076"], ["70277.00", "0.064"], ["70276.90", "0.395"], ["70276.80", "0.003"], ["70276.70", "0.342"], ["70276.60", "0.189"], ["70276.40", "0.445"], ["70276.20", "0.008"], ["70276.10", "0.002"], ["70276.00", "0.002"], ["70275.80", "0.511"], ["70275.70", "0.006"], ["70275.60", "0.004"], ["70275.40", "0.168"], ["70275.30", "0.007"], ["70275.10", "2.049"], ["70275.00", "10.257"], ["70274.90", "0.349"], ["70274.70", "1.000"], ["70274.60", "0.002"], ["70274.30", "0.004"], ["70274.20", "0.003"], ["70274.00", "0.003"], ["70273.90", "1.067"], ["70273.60", "0.042"], ["70273.50", "0.004"], ["70273.40", "0.522"], ["70273.30", "0.225"], ["70273.00", "0.256"], ["70272.90", "0.195"], ["70272.70", "0.108"], ["70272.40", "0.205"], ["70272.30", "0.004"], ["70272.20", "0.001"], ["70272.10", "0.199"], ["70272.00", "0.014"], ["70271.90", "0.006"], ["70271.80", "0.020"], ["70271.70", "0.056"], ["70271.60", "0.003"], ["70271.50", "0.004"], ["70271.40", "0.134"], ["70271.30", "0.083"], ["70271.00", "0.003"], ["70270.90", "0.142"], ["70270.70", "0.007"], ["70270.60", "0.002"], ["70270.40", "0.002"], ["70270.20", "0.004"], ["70270.10", "0.004"], ["70270.00", "0.051"], ["70269.90", "0.078"], ["70269.70", "0.006"], ["70269.60", "0.019"], ["70269.50", "0.342"], ["70269.40", "0.081"], ["70269.30", "0.081"], ["70269.10", "0.003"], ["70269.00", "0.004"], ["70268.80", "0.045"], ["70268.70", "0.257"], ["70268.50", "0.004"], ["70268.40", "0.903"], ["70268.20", "0.081"], ["70268.00", "0.128"], ["70267.90", "0.041"], ["70267.80", "0.033"], ["70267.70", "0.188"], ["70267.60", "0.388"], ["70267.50", "0.047"], ["70267.40", "1.782"], ["70267.30", "0.065"], ["70267.20", "0.172"], ["70267.00", "0.022"], ["70266.60", "0.044"], ["70266.50", "0.511"], ["70266.40", "1.302"], ["70266.30", "0.081"], ["70266.20", "0.013"], ["70266.10", "0.021"], ["70266.00", "0.891"], ["70265.80", "0.565"], ["70265.50", "0.009"], ["70265.40", "0.018"], ["70265.10", "0.081"], ["70265.00", "0.039"], ["70264.90", "0.027"], ["70264.80", "0.002"], ["70264.70", "0.081"], ["70264.60", "0.002"], ["70264.30", "0.050"], ["70264.10", "0.018"], ["70264.00", "0.191"], ["70263.90", "0.399"], ["70263.80", "1.270"], ["70263.60", "0.618"], ["70263.50", "0.081"], ["70263.40", "0.096"], ["70263.20", "0.006"], ["70263.10", "0.135"], ["70263.00", "0.122"], ["70262.60", "0.344"], ["70262.50", "0.571"], ["70262.40", "0.005"], ["70262.30", "0.188"], ["70262.10", "0.008"], ["70262.00", "0.004"], ["70261.60", "0.003"], ["70261.50", "0.237"], ["70261.40", "0.103"], ["70261.30", "0.002"], ["70261.20", "0.012"], ["70261.10", "0.001"], ["70261.00", "0.008"], ["70260.90", "0.006"], ["70260.80", "0.027"], ["70260.60", "2.128"], ["70260.50", "0.077"], ["70260.40", "0.473"], ["70260.30", "0.052"], ["70260.20", "0.165"], ["70260.00", "0.172"], ["70259.70", "0.004"], ["70259.50", "0.117"], ["70259.30", "0.009"], ["70259.20", "0.011"], ["70259.10", "0.003"], ["70259.00", "2.367"], ["70258.90", "6.535"], ["70258.80", "0.210"], ["70258.70", "0.084"], ["70258.60", "7.320"], ["70258.50", "0.090"], ["70258.30", "0.043"], ["70258.20", "0.001"], ["70257.90", "0.006"], ["70257.80", "0.042"], ["70257.70", "0.006"], ["70257.60", "0.511"], ["70257.40", "0.002"], ["70257.10", "0.097"], ["70257.00", "0.081"], ["70256.80", "0.730"], ["70256.70", "0.002"], ["70256.20", "0.079"], ["70256.10", "0.039"], ["70256.00", "0.014"], ["70255.70", "0.119"], ["70255.50", "1.668"], ["70255.30", "0.089"], ["70255.10", "0.529"], ["70254.90", "0.020"], ["70254.80", "0.003"], ["70254.70", "0.116"], ["70254.60", "0.081"], ["70254.50", "0.100"], ["70254.30", "1.408"], ["70254.20", "4.062"], ["70254.10", "0.848"], ["70254.00", "0.039"], ["70253.80", "0.023"], ["70253.50", "0.198"], ["70253.30", "2.000"], ["70253.20", "0.380"], ["70253.10", "0.076"], ["70253.00", "0.092"], ["70252.90", "0.044"], ["70252.80", "0.564"], ["70252.60", "0.294"], ["70252.50", "0.012"], ["70252.40", "0.003"], ["70252.30", "0.079"], ["70252.20", "0.081"], ["70252.10", "0.371"], ["70252.00", "0.200"], ["70251.90", "2.818"], ["70251.70", "13.715"], ["70251.50", "0.097"], ["70251.30", "0.002"], ["70251.20", "0.025"], ["70250.90", "0.145"], ["70250.80", "0.042"], ["70250.70", "0.104"], ["70250.60", "0.084"], ["70250.50", "0.091"], ["70250.40", "0.083"], ["70250.30", "0.084"], ["70250.20", "0.083"], ["70250.10", "0.787"], ["70250.00", "1.629"], ["70249.90", "0.097"], ["70249.80", "0.001"], ["70249.60", "0.004"], ["70249.50", "0.048"], ["70249.40", "0.052"], ["70249.30", "0.270"], ["70249.00", "0.099"], ["70248.90", "0.039"], ["70248.80", "0.085"], ["70248.70", "0.081"], ["70248.60", "0.158"], ["70248.50", "2.364"], ["70248.40", "0.210"], ["70248.30", "4.066"], ["70248.20", "0.002"], ["70248.00", "0.430"], ["70247.90", "0.260"], ["70247.70", "0.003"], ["70247.50", "0.042"], ["70247.40", "0.081"], ["70247.30", "0.256"], ["70247.20", "0.002"], ["70247.10", "0.046"], ["70246.90", "0.004"], ["70246.70", "0.091"], ["70246.60", "0.082"], ["70246.50", "0.166"], ["70246.40", "0.089"], ["70246.30", "0.042"], ["70246.20", "0.002"], ["70246.10", "0.221"], ["70246.00", "0.099"], ["70245.80", "0.342"], ["70245.70", "0.009"], ["70245.60", "0.002"], ["70245.50", "0.042"], ["70245.30", "6.653"], ["70245.10", "0.100"], ["70245.00", "0.007"], ["70244.90", "2.395"], ["70244.80", "2.632"], ["70244.70", "6.537"], ["70244.30", "0.005"], ["70244.20", "0.186"], ["70244.10", "0.385"], ["70244.00", "0.122"], ["70243.90", "0.511"], ["70243.80", "0.019"], ["70243.70", "0.648"], ["70243.60", "4.207"], ["70243.50", "0.022"], ["70243.30", "0.002"], ["70243.20", "0.179"], ["70243.10", "0.016"], ["70243.00", "0.015"], ["70242.90", "0.004"], ["70242.80", "0.225"], ["70242.60", "0.099"], ["70242.40", "0.128"], ["70242.30", "0.277"], ["70242.20", "0.083"], ["70242.10", "0.008"], ["70242.00", "0.474"], ["70241.80", "0.082"], ["70241.60", "0.513"], ["70241.50", "0.096"], ["70241.30", "0.012"], ["70240.80", "1.116"], ["70240.60", "1.760"], ["70240.50", "1.388"], ["70240.30", "0.079"], ["70240.10", "0.041"], ["70240.00", "0.270"], ["70239.90", "0.007"], ["70239.80", "0.079"], ["70239.70", "0.098"], ["70239.60", "0.008"], ["70239.50", "3.642"], ["70239.40", "0.034"], ["70239.30", "0.593"], ["70239.20", "0.002"], ["70239.10", "0.043"], ["70238.80", "0.219"], ["70238.70", "1.066"], ["70238.60", "2.512"], ["70238.40", "0.185"], ["70238.30", "0.215"], ["70238.20", "0.083"], ["70238.10", "0.002"], ["70238.00", "4.094"], ["70237.80", "0.099"], ["70237.70", "0.098"], ["70237.50", "0.429"], ["70237.40", "11.671"], ["70237.30", "0.005"], ["70237.20", "0.079"], ["70236.90", "1.507"], ["70236.80", "0.088"], ["70236.70", "0.511"], ["70236.60", "0.194"], ["70236.50", "0.166"], ["70236.40", "0.003"], ["70236.30", "0.084"], ["70236.20", "0.008"], ["70236.10", "0.085"], ["70236.00", "0.059"], ["70235.90", "0.003"], ["70235.80", "0.039"], ["70235.70", "0.002"], ["70235.40", "0.309"], ["70235.30", "0.236"], ["70235.20", "0.008"], ["70235.00", "0.095"], ["70234.90", "0.018"], ["70234.80", "0.083"], ["70234.70", "0.005"], ["70234.60", "0.003"], ["70234.50", "0.176"], ["70234.40", "0.004"], ["70234.30", "0.002"], ["70234.10", "0.092"], ["70234.00", "2.552"], ["70233.70", "0.007"], ["70233.60", "0.187"], ["70233.50", "0.026"], ["70233.30", "0.001"], ["70233.20", "0.044"], ["70233.00", "0.205"], ["70232.90", "0.082"], ["70232.70", "0.004"], ["70232.50", "0.002"], ["70232.40", "0.041"], ["70232.30", "0.083"], ["70232.20", "0.044"], ["70232.10", "1.371"], ["70232.00", "11.635"], ["70231.80", "0.128"], ["70231.50", "0.099"], ["70231.20", "0.004"], ["70231.00", "0.002"], ["70230.80", "0.607"], ["70230.70", "0.008"], ["70230.60", "0.079"], ["70230.40", "0.079"], ["70230.30", "0.123"], ["70230.10", "0.441"], ["70230.00", "1.257"], ["70229.90", "6.540"], ["70229.80", "0.083"], ["70229.60", "0.044"], ["70229.50", "0.005"], ["70229.40", "0.284"], ["70229.30", "0.039"], ["70229.10", "0.393"], ["70229.00", "0.020"], ["70228.90", "0.002"], ["70228.80", "0.083"], ["70228.70", "0.096"], ["70228.60", "0.085"], ["70228.50", "0.513"], ["70228.40", "0.008"], ["70228.30", "0.097"], ["70228.20", "0.538"], ["70228.10", "0.081"], ["70228.00", "0.091"], ["70227.80", "0.083"], ["70227.70", "0.002"], ["70227.60", "0.127"], ["70227.30", "0.082"], ["70227.00", "0.658"], ["70226.90", "0.097"], ["70226.80", "0.039"], ["70226.70", "0.245"], ["70226.60", "0.015"], ["70226.50", "0.191"], ["70226.40", "0.002"], ["70226.30", "0.082"], ["70226.20", "0.687"], ["70226.10", "0.009"], ["70226.00", "0.082"], ["70225.80", "0.111"], ["70225.60", "0.015"], ["70225.50", "0.002"], ["70225.40", "0.261"], ["70225.30", "0.103"], ["70225.20", "2.000"], ["70225.10", "0.122"], ["70225.00", "0.302"], ["70224.80", "0.003"], ["70224.70", "0.030"], ["70224.40", "0.096"], ["70224.30", "0.360"], ["70224.20", "0.006"], ["70224.10", "0.096"], ["70224.00", "0.091"], ["70223.70", "0.719"], ["70223.60", "0.096"], ["70223.30", "0.004"], ["70223.20", "0.012"], ["70223.10", "0.511"], ["70223.00", "0.044"], ["70222.90", "0.081"], ["70222.80", "0.200"], ["70222.50", "0.204"], ["70222.40", "0.080"], ["70222.30", "0.003"], ["70222.20", "0.017"], ["70222.10", "0.008"], ["70222.00", "0.365"], ["70221.90", "0.098"], ["70221.80", "0.197"], ["70221.70", "0.002"], ["70221.60", "0.424"], ["70221.50", "0.062"], ["70221.00", "0.128"], ["70220.80", "0.285"], ["70220.70", "0.276"], ["70220.60", "0.673"], ["70220.50", "0.368"], ["70220.40", "0.003"], ["70220.30", "0.002"], ["70220.00", "0.108"], ["70219.90", "0.046"], ["70219.70", "0.232"], ["70219.60", "0.039"], ["70219.40", "0.096"], ["70219.20", "0.005"], ["70218.90", "0.002"], ["70218.80", "0.087"], ["70218.70", "0.039"], ["70218.50", "0.041"], ["70218.40", "0.200"], ["70218.30", "0.082"], ["70218.20", "0.002"], ["70218.10", "0.523"], ["70218.00", "0.087"], ["70217.90", "0.039"], ["70217.70", "0.082"], ["70217.60", "0.012"], ["70217.50", "0.082"], ["70217.40", "0.006"], ["70217.20", "0.095"], ["70217.10", "0.098"], ["70217.00", "0.002"], ["70216.80", "2.807"], ["70216.70", "0.090"], ["70216.60", "0.036"], ["70216.40", "0.003"], ["70216.30", "0.193"]], "asks": [["70348.70", "0.169"], ["70348.80", "0.004"], ["70349.20", "0.002"], ["70349.30", "0.002"], ["70349.40", "0.002"], ["70349.50", "0.002"], ["70349.80", "0.001"], ["70350.00", "0.002"], ["70350.20", "0.002"], ["70350.30", "0.005"], ["70350.50", "0.003"], ["70350.80", "0.003"], ["70350.90", "0.002"], ["70351.10", "0.003"], ["70351.30", "0.001"], ["70351.40", "0.002"], ["70351.50", "0.003"], ["70351.60", "0.002"], ["70351.90", "0.003"], ["70352.00", "0.001"], ["70352.10", "0.004"], ["70352.30", "0.007"], ["70352.40", "0.002"], ["70352.60", "0.006"], ["70352.70", "0.126"], ["70352.80", "0.006"], ["70352.90", "0.342"], ["70353.00", "0.005"], ["70353.10", "0.002"], ["70353.20", "0.005"], ["70353.30", "0.007"], ["70353.50", "0.005"], ["70353.60", "0.002"], ["70353.70", "0.002"], ["70353.90", "0.198"], ["70354.00", "0.007"], ["70354.20", "0.002"], ["70354.40", "0.004"], ["70354.50", "0.003"], ["70354.70", "0.005"], ["70354.90", "0.004"], ["70355.00", "0.003"], ["70355.10", "0.002"], ["70355.30", "1.068"], ["70355.40", "0.003"], ["70355.50", "0.001"], ["70355.60", "0.002"], ["70355.70", "0.067"], ["70355.80", "0.097"], ["70355.90", "0.019"], ["70356.00", "0.002"], ["70356.10", "0.005"], ["70356.20", "0.006"], ["70356.30", "0.007"], ["70356.50", "0.003"], ["70356.60", "0.006"], ["70356.80", "0.003"], ["70356.90", "0.004"], ["70357.00", "0.006"], ["70357.10", "0.297"], ["70357.20", "0.556"], ["70357.30", "0.034"], ["70357.50", "0.074"], ["70357.60", "0.009"], ["70357.70", "0.002"], ["70357.80", "0.003"], ["70357.90", "0.003"], ["70358.00", "0.004"], ["70358.10", "0.007"], ["70358.20", "0.001"], ["70358.30", "0.024"], ["70358.40", "0.001"], ["70358.60", "0.429"], ["70358.70", "0.345"], ["70358.80", "0.003"], ["70358.90", "0.003"], ["70359.00", "0.021"], ["70359.10", "0.007"], ["70359.20", "0.006"], ["70359.30", "0.189"], ["70359.50", "0.004"], ["70359.60", "0.002"], ["70359.70", "0.004"], ["70359.80", "0.004"], ["70360.00", "0.015"], ["70360.10", "0.003"], ["70360.30", "0.060"], ["70360.40", "0.513"], ["70360.50", "0.008"], ["70360.60", "0.001"], ["70360.70", "0.002"], ["70360.80", "0.002"], ["70360.90", "0.007"], ["70361.00", "0.244"], ["70361.10", "0.879"], ["70361.20", "0.006"], ["70361.30", "1.068"], ["70361.40", "2.005"], ["70361.50", "0.097"], ["70361.60", "0.003"], ["70361.70", "0.002"], ["70361.90", "0.001"], ["70362.00", "0.002"], ["70362.10", "0.005"], ["70362.20", "0.003"], ["70362.30", "0.003"], ["70362.40", "0.036"], ["70362.50", "0.111"], ["70362.60", "0.536"], ["70362.70", "0.140"], ["70362.80", "0.411"], ["70362.90", "0.083"], ["70363.00", "0.214"], ["70363.10", "0.015"], ["70363.20", "0.007"], ["70363.30", "0.068"], ["70363.50", "0.002"], ["70363.60", "0.037"], ["70363.90", "0.142"], ["70364.00", "0.140"], ["70364.10", "0.009"], ["70364.20", "0.019"], ["70364.30", "0.181"], ["70364.40", "0.038"], ["70364.50", "0.049"], ["70364.60", "0.449"], ["70364.70", "0.082"], ["70364.80", "0.514"], ["70364.90", "0.004"], ["70365.00", "7.665"], ["70365.10", "0.014"], ["70365.20", "0.101"], ["70365.30", "0.005"], ["70365.40", "0.096"], ["70365.60", "0.003"], ["70365.70", "0.008"], ["70365.80", "0.002"], ["70365.90", "0.001"], ["70366.00", "0.004"], ["70366.10", "0.307"], ["70366.20", "0.005"], ["70366.30", "0.010"], ["70366.40", "0.075"], ["70366.50", "0.053"], ["70366.60", "0.005"], ["70366.70", "0.006"], ["70366.90", "0.003"], ["70367.00", "1.068"], ["70367.10", "0.515"], ["70367.20", "50.005"], ["70367.30", "0.044"], ["70367.40", "0.006"], ["70367.50", "0.002"], ["70367.70", "0.639"], ["70367.80", "0.003"], ["70368.00", "0.006"], ["70368.10", "0.006"], ["70368.30", "0.142"], ["70368.40", "0.108"], ["70368.50", "0.004"], ["70368.60", "0.216"], ["70368.70", "0.202"], ["70368.90", "0.007"], ["70369.00", "0.002"], ["70369.20", "0.002"], ["70369.30", "0.002"], ["70369.40", "0.004"], ["70369.50", "0.002"], ["70369.60", "0.196"], ["70369.70", "0.003"], ["70369.80", "0.293"], ["70369.90", "0.160"], ["70370.00", "0.004"], ["70370.10", "0.001"], ["70370.20", "0.375"], ["70370.30", "0.003"], ["70370.40", "0.002"], ["70370.50", "0.002"], ["70370.60", "0.004"], ["70370.70", "0.070"], ["70370.80", "0.009"], ["70370.90", "0.345"], ["70371.00", "0.081"], ["70371.10", "0.239"], ["70371.20", "0.005"], ["70371.30", "1.188"], ["70371.40", "0.002"], ["70371.50", "0.002"], ["70371.60", "0.085"], ["70372.10", "0.579"], ["70372.20", "0.009"], ["70372.30", "0.202"], ["70372.40", "0.002"], ["70372.50", "0.792"], ["70372.60", "0.414"], ["70372.70", "0.037"], ["70372.80", "0.005"], ["70372.90", "0.005"], ["70373.00", "0.006"], ["70373.20", "0.192"], ["70373.40", "0.006"], ["70373.60", "1.443"], ["70373.70", "0.006"], ["70373.80", "0.002"], ["70373.90", "0.003"], ["70374.10", "0.005"], ["70374.20", "0.002"], ["70374.30", "0.269"], ["70374.40", "0.004"], ["70374.50", "0.183"], ["70374.70", "0.004"], ["70374.80", "0.561"], ["70374.90", "0.605"], ["70375.00", "0.005"], ["70375.10", "0.003"], ["70375.20", "0.002"], ["70375.30", "0.020"], ["70375.40", "0.003"], ["70375.50", "0.002"], ["70375.60", "0.513"], ["70375.70", "0.014"], ["70375.80", "0.005"], ["70375.90", "0.001"], ["70376.00", "0.005"], ["70376.10", "0.009"], ["70376.20", "0.395"], ["70376.50", "0.006"], ["70376.60", "0.002"], ["70376.70", "0.343"], ["70376.80", "0.195"], ["70376.90", "0.478"], ["70377.00", "0.002"], ["70377.20", "0.003"], ["70377.30", "0.007"], ["70377.40", "0.214"], ["70377.50", "0.194"], ["70377.60", "0.002"], ["70377.80", "0.071"], ["70377.90", "0.046"], ["70378.00", "0.004"], ["70378.20", "0.002"], ["70378.30", "0.008"], ["70378.40", "0.027"], ["70378.50", "0.003"], ["70378.60", "0.053"], ["70378.80", "0.003"], ["70378.90", "0.455"], ["70379.00", "0.586"], ["70379.10", "0.189"], ["70379.40", "0.005"], ["70379.60", "0.005"], ["70379.70", "1.142"], ["70379.80", "0.201"], ["70380.00", "0.013"], ["70380.10", "0.004"], ["70380.20", "0.003"], ["70380.30", "0.004"], ["70380.40", "0.187"], ["70380.60", "0.003"], ["70380.70", "0.002"], ["70380.80", "0.084"], ["70380.90", "0.016"], ["70381.00", "0.003"], ["70381.10", "0.002"], ["70381.20", "0.002"], ["70381.30", "0.010"], ["70381.40", "0.511"], ["70381.50", "0.369"], ["70381.70", "0.008"], ["70382.00", "0.083"], ["70382.10", "0.002"], ["70382.30", "0.294"], ["70382.40", "0.006"], ["70382.50", "0.006"], ["70382.60", "0.387"], ["70382.70", "0.380"], ["70382.90", "0.002"], ["70383.00", "0.007"], ["70383.20", "0.001"], ["70383.40", "0.007"], ["70383.50", "0.003"], ["70383.60", "0.212"], ["70383.70", "0.002"], ["70383.90", "0.065"], ["70384.00", "0.192"], ["70384.10", "0.002"], ["70384.20", "0.006"], ["70384.40", "0.003"], ["70384.50", "1.207"], ["70384.70", "0.044"], ["70384.80", "0.002"], ["70385.00", "0.032"], ["70385.10", "0.847"], ["70385.20", "1.886"], ["70385.30", "0.002"], ["70385.40", "0.012"], ["70385.50", "0.511"], ["70385.80", "0.013"], ["70385.90", "0.040"], ["70386.00", "0.002"], ["70386.10", "0.004"], ["70386.20", "0.015"], ["70386.30", "0.002"], ["70386.80", "0.051"], ["70387.00", "1.069"], ["70387.10", "0.007"], ["70387.30", "0.002"], ["70387.40", "0.208"], ["70387.50", "0.388"], ["70387.60", "0.568"], ["70387.70", "0.515"], ["70387.80", "0.004"], ["70387.90", "0.004"], ["70388.00", "0.024"], ["70388.20", "0.002"], ["70388.30", "0.002"], ["70388.50", "0.007"], ["70388.60", "0.005"], ["70388.70", "0.083"], ["70388.80", "0.350"], ["70388.90", "0.007"], ["70389.00", "0.029"], ["70389.20", "0.004"], ["70389.40", "0.003"], ["70389.60", "0.122"], ["70389.80", "0.171"], ["70389.90", "0.002"], ["70390.00", "0.002"], ["70390.10", "0.046"], ["70390.20", "0.086"], ["70390.30", "0.595"], ["70390.40", "0.001"], ["70390.60", "0.003"], ["70390.70", "0.007"], ["70390.90", "0.005"], ["70391.00", "0.021"], ["70391.20", "0.190"], ["70391.30", "0.002"], ["70391.40", "0.005"], ["70391.60", "0.003"], ["70391.70", "0.067"], ["70391.90", "0.191"], ["70392.00", "0.392"], ["70392.10", "0.003"], ["70392.20", "0.002"], ["70392.30", "0.196"], ["70392.40", "0.003"], ["70392.60", "0.005"], ["70392.80", "0.385"], ["70392.90", "0.599"], ["70393.00", "1.414"], ["70393.20", "0.002"], ["70393.30", "0.113"], ["70393.40", "0.042"], ["70393.50", "0.002"], ["70393.60", "0.084"], ["70393.80", "0.003"], ["70393.90", "0.008"], ["70394.00", "0.202"], ["70394.10", "0.086"], ["70394.30", "0.053"], ["70394.40", "0.002"], ["70394.50", "0.099"], ["70394.60", "0.001"], ["70394.80", "0.191"], ["70395.00", "0.004"], ["70395.10", "0.002"], ["70395.20", "0.003"], ["70395.30", "0.002"], ["70395.40", "0.034"], ["70395.50", "0.023"], ["70395.60", "0.009"], ["70395.90", "0.437"], ["70396.00", "0.531"], ["70396.10", "0.006"], ["70396.20", "0.005"], ["70396.30", "0.002"], ["70396.50", "0.049"], ["70396.60", "0.002"], ["70396.70", "0.192"], ["70396.90", "0.002"], ["70397.00", "0.018"], ["70397.40", "0.090"], ["70397.50", "0.838"], ["70397.60", "0.067"], ["70397.70", "0.088"], ["70397.80", "0.139"], ["70398.10", "0.002"], ["70398.30", "0.240"], ["70398.40", "0.249"], ["70398.50", "0.003"], ["70398.60", "0.086"], ["70398.90", "0.044"], ["70399.00", "0.024"], ["70399.20", "0.857"], ["70399.30", "1.073"], ["70399.40", "0.042"], ["70399.50", "0.511"], ["70399.60", "0.088"], ["70399.70", "0.004"], ["70399.80", "0.004"], ["70399.90", "0.060"], ["70400.00", "2.040"], ["70400.10", "0.045"], ["70400.20", "0.002"], ["70400.30", "0.003"], ["70400.40", "0.004"], ["70400.50", "0.188"], ["70400.60", "0.122"], ["70400.70", "0.010"], ["70400.80", "0.015"], ["70400.90", "0.010"], ["70401.00", "0.007"], ["70401.10", "0.236"], ["70401.20", "0.002"], ["70401.30", "0.073"], ["70401.40", "0.005"], ["70401.50", "0.638"], ["70401.60", "0.003"], ["70401.70", "0.002"], ["70401.90", "0.004"], ["70402.00", "0.194"], ["70402.10", "0.345"], ["70402.30", "0.002"], ["70402.40", "0.009"], ["70402.50", "0.096"], ["70402.60", "0.015"], ["70402.70", "0.002"], ["70402.80", "0.132"], ["70402.90", "0.515"], ["70403.00", "1.880"], ["70403.10", "0.048"], ["70403.30", "0.115"], ["70403.40", "0.002"], ["70403.50", "0.086"], ["70403.60", "0.046"], ["70404.00", "0.386"], ["70404.10", "0.405"], ["70404.20", "0.851"], ["70404.40", "0.006"], ["70404.60", "10.229"], ["70404.80", "0.210"], ["70404.90", "0.002"], ["70405.00", "0.100"], ["70405.20", "0.003"], ["70405.30", "0.002"], ["70405.40", "0.002"], ["70405.50", "0.046"], ["70405.60", "0.217"], ["70405.70", "0.006"], ["70405.80", "0.007"], ["70405.90", "0.083"], ["70406.00", "1.929"], ["70406.10", "1.014"], ["70406.20", "0.518"], ["70406.30", "0.028"], ["70406.40", "0.003"], ["70406.60", "0.002"], ["70406.80", "0.004"], ["70406.90", "0.002"], ["70407.00", "0.037"], ["70407.20", "0.040"], ["70407.40", "0.002"], ["70407.50", "0.002"], ["70407.70", "3.665"], ["70407.90", "0.084"], ["70408.10", "0.039"], ["70408.20", "0.669"], ["70408.30", "0.007"], ["70408.50", "0.002"], ["70408.60", "0.095"], ["70408.70", "0.083"], ["70408.80", "0.003"], ["70408.90", "0.085"], ["70409.00", "0.007"], ["70409.10", "0.088"], ["70409.20", "0.900"], ["70409.40", "0.081"], ["70409.50", "0.789"], ["70409.60", "0.002"], ["70409.70", "0.063"], ["70409.80", "0.146"], ["70410.00", "0.008"], ["70410.10", "0.015"], ["70410.40", "0.128"], ["70410.50", "0.002"], ["70410.60", "0.007"], ["70410.70", "0.056"], ["70410.80", "0.111"], ["70410.90", "0.078"], ["70411.00", "0.011"], ["70411.10", "0.002"], ["70411.20", "0.002"], ["70411.40", "0.002"], ["70411.60", "0.030"], ["70411.70", "0.084"], ["70411.80", "0.004"], ["70411.90", "0.206"], ["70412.00", "0.002"], ["70412.10", "0.511"], ["70412.20", "0.004"], ["70412.30", "0.082"], ["70412.50", "0.007"], ["70412.60", "0.080"], ["70412.70", "0.003"], ["70412.80", "0.234"], ["70413.00", "1.348"], ["70413.10", "0.002"], ["70413.20", "0.004"], ["70413.30", "0.050"], ["70413.40", "0.002"], ["70413.50", "0.114"], ["70413.60", "0.073"], ["70413.70", "0.001"], ["70413.90", "0.002"], ["70414.00", "0.201"], ["70414.20", "0.005"], ["70414.30", "0.002"], ["70414.40", "0.008"], ["70414.70", "0.243"], ["70414.80", "0.006"], ["70414.90", "0.046"], ["70415.00", "0.003"], ["70415.10", "0.665"], ["70415.20", "0.017"], ["70415.30", "0.002"], ["70415.40", "0.595"], ["70415.50", "0.002"], ["70415.60", "0.002"], ["70415.70", "0.078"], ["70415.90", "0.044"], ["70416.00", "0.006"], ["70416.10", "0.002"], ["70416.20", "0.002"], ["70416.40", "0.249"], ["70416.50", "0.768"], ["70416.60", "0.008"], ["70416.80", "0.234"], ["70416.90", "0.082"], ["70417.00", "0.535"], ["70417.30", "0.003"], ["70417.50", "0.005"], ["70417.60", "0.522"], ["70417.70", "0.005"], ["70417.80", "0.570"], ["70417.90", "0.006"], ["70418.00", "0.344"], ["70418.20", "0.087"], ["70418.30", "0.003"], ["70418.40", "0.193"], ["70418.50", "0.012"], ["70418.60", "0.015"], ["70418.70", "0.002"], ["70418.90", "0.199"], ["70419.00", "0.101"], ["70419.10", "0.006"], ["70419.30", "0.002"], ["70419.40", "0.004"], ["70419.50", "0.010"], ["70419.60", "1.069"], ["70419.70", "0.196"], ["70419.80", "0.339"], ["70419.90", "0.675"], ["70420.00", "1.178"], ["70420.10", "0.206"], ["70420.20", "0.002"], ["70420.30", "0.081"], ["70420.40", "0.143"], ["70420.70", "0.085"], ["70420.80", "0.099"], ["70421.10", "0.198"], ["70421.30", "0.001"], ["70421.40", "0.006"], ["70421.50", "0.418"], ["70421.60", "0.004"], ["70421.90", "0.102"], ["70422.00", "2.826"], ["70422.10", "0.102"], ["70422.20", "0.153"], ["70422.30", "1.102"], ["70422.40", "0.085"], ["70422.50", "0.081"], ["70422.60", "0.356"], ["70422.70", "0.006"], ["70422.80", "0.497"], ["70422.90", "0.130"], ["70423.00", "0.044"], ["70423.20", "0.077"], ["70423.30", "0.594"], ["70423.40", "0.235"], ["70423.60", "0.228"], ["70423.70", "0.423"], ["70423.80", "0.002"], ["70423.90", "0.117"], ["70424.00", "0.031"], ["70424.10", "0.097"], ["70424.20", "0.036"], ["70424.30", "0.702"], ["70424.40", "0.199"], ["70424.50", "0.082"], ["70424.60", "0.108"], ["70424.80", "0.061"], ["70424.90", "0.036"], ["70425.00", "0.017"], ["70425.10", "0.002"], ["70425.20", "0.005"], ["70425.30", "0.087"], ["70425.40", "0.002"], ["70425.60", "0.001"], ["70425.80", "1.213"], ["70425.90", "0.607"], ["70426.00", "0.400"], ["70426.10", "0.192"], ["70426.20", "0.081"], ["70426.30", "0.083"], ["70426.50", "0.087"], ["70426.60", "0.002"], ["70426.80", "0.002"], ["70426.90", "0.002"], ["70427.00", "0.004"], ["70427.10", "0.345"], ["70427.20", "0.631"], ["70427.30", "0.198"], ["70427.40", "0.002"], ["70427.50", "0.025"], ["70427.60", "0.001"], ["70427.70", "0.056"], ["70427.80", "0.230"], ["70427.90", "0.020"], ["70428.10", "0.091"], ["70428.30", "0.076"], ["70428.40", "0.204"], ["70428.50", "0.002"], ["70428.70", "0.003"], ["70429.10", "0.511"], ["70429.20", "0.073"], ["70429.30", "0.002"], ["70429.60", "1.108"], ["70429.70", "0.002"], ["70429.90", "0.004"], ["70430.00", "0.015"], ["70430.10", "0.056"], ["70430.50", "0.513"], ["70430.70", "0.002"], ["70430.90", "0.189"], ["70431.00", "0.002"], ["70431.10", "0.002"], ["70431.20", "0.010"], ["70431.40", "0.801"], ["70431.50", "0.097"], ["70431.60", "0.001"], ["70431.70", "0.003"], ["70431.80", "0.002"], ["70432.00", "0.022"], ["70432.10", "0.516"], ["70432.20", "1.068"], ["70432.30", "0.002"], ["70432.40", "0.198"], ["70432.60", "0.002"], ["70432.80", "0.142"], ["70432.90", "0.004"], ["70433.00", "0.003"], ["70433.10", "0.002"], ["70433.20", "0.387"], ["70433.30", "0.087"], ["70433.50", "0.002"], ["70433.70", "0.053"], ["70433.90", "0.008"], ["70434.00", "0.006"], ["70434.10", "0.002"], ["70434.30", "0.001"], ["70434.40", "0.002"], ["70434.50", "0.776"], ["70434.60", "0.511"], ["70434.70", "0.197"], ["70434.90", "0.384"], ["70435.00", "0.192"], ["70435.10", "0.002"], ["70435.20", "0.002"], ["70435.30", "0.013"], ["70435.60", "0.342"], ["70435.80", "0.018"], ["70435.90", "0.005"], ["70436.10", "0.099"], ["70436.20", "0.073"], ["70436.30", "1.502"], ["70436.50", "0.010"], ["70436.60", "0.002"], ["70436.70", "0.198"], ["70436.80", "0.513"], ["70436.90", "0.178"], ["70437.30", "0.180"], ["70437.40", "0.003"], ["70437.50", "2.115"], ["70437.60", "0.002"], ["70437.70", "0.008"], ["70437.80", "0.003"], ["70437.90", "0.050"], ["70438.10", "0.001"], ["70438.30", "0.189"], ["70438.40", "6.521"], ["70438.60", "0.003"], ["70438.70", "0.574"], ["70438.80", "0.036"], ["70438.90", "0.004"], ["70439.30", "0.511"], ["70439.40", "0.002"], ["70439.50", "0.002"], ["70439.70", "0.090"], ["70439.80", "2.014"], ["70439.90", "0.142"], ["70440.00", "0.013"], ["70440.10", "0.002"], ["70440.20", "0.010"], ["70440.30", "0.059"], ["70440.40", "0.001"], ["70440.50", "0.018"], ["70440.60", "1.068"], ["70440.70", "0.781"], ["70440.90", "0.210"], ["70441.00", "2.117"], ["70441.10", "0.002"], ["70441.20", "0.090"], ["70441.30", "0.008"], ["70441.40", "0.258"], ["70441.50", "0.002"], ["70441.70", "0.085"], ["70441.80", "2.848"], ["70441.90", "0.271"], ["70442.00", "0.607"], ["70442.10", "0.043"], ["70442.20", "0.084"], ["70442.40", "0.022"], ["70442.60", "0.100"], ["70442.70", "0.081"], ["70442.80", "0.115"], ["70442.90", "0.143"], ["70443.10", "0.003"], ["70443.30", "9.673"], ["70443.40", "0.006"], ["70443.70", "1.669"], ["70443.80", "0.086"], ["70443.90", "0.002"], ["70444.00", "0.006"], ["70444.10", "0.354"], ["70444.20", "0.511"], ["70444.30", "6.992"], ["70444.40", "0.004"], ["70444.60", "0.090"], ["70444.70", "0.352"], ["70444.80", "1.705"], ["70444.90", "6.305"], ["70445.00", "0.030"], ["70445.10", "0.089"], ["70445.20", "0.004"], ["70445.40", "0.002"], ["70445.50", "0.191"], ["70445.80", "0.374"], ["70446.20", "0.007"], ["70446.40", "0.004"], ["70446.60", "0.002"], ["70446.80", "0.009"], ["70446.90", "1.326"], ["70447.00", "0.002"], ["70447.20", "0.094"], ["70447.30", "0.005"], ["70447.50", "0.060"], ["70447.70", "0.005"], ["70447.80", "0.090"], ["70447.90", "0.004"], ["70448.00", "0.007"], ["70448.10", "1.255"], ["70448.40", "0.002"], ["70448.50", "0.019"], ["70448.60", "0.019"], ["70448.70", "0.002"], ["70448.80", "0.011"], ["70448.90", "0.039"], ["70449.00", "0.046"], ["70449.10", "0.195"], ["70449.20", "0.724"], ["70449.40", "0.002"], ["70449.50", "0.008"], ["70449.60", "0.002"], ["70449.70", "0.009"], ["70449.80", "0.090"], ["70450.00", "0.705"], ["70450.20", "0.006"], ["70450.40", "2.000"], ["70450.50", "1.072"], ["70450.70", "0.089"], ["70450.90", "0.448"], ["70451.00", "0.216"], ["70451.30", "0.342"], ["70451.40", "0.601"], ["70451.50", "0.002"], ["70451.70", "0.055"], ["70451.80", "2.856"], ["70451.90", "0.002"], ["70452.00", "0.082"], ["70452.10", "0.002"], ["70452.20", "0.002"], ["70452.40", "0.002"], ["70452.70", "6.708"], ["70452.90", "0.006"], ["70453.00", "10.226"], ["70453.20", "0.383"], ["70453.30", "0.018"], ["70453.50", "0.002"], ["70453.60", "0.555"], ["70453.80", "0.279"], ["70454.00", "0.124"], ["70454.10", "0.044"], ["70454.40", "0.010"], ["70454.50", "0.087"], ["70454.60", "0.198"], ["70454.70", "0.025"], ["70454.90", "1.325"], ["70455.00", "0.016"], ["70455.10", "0.002"], ["70455.30", "0.067"], ["70455.40", "0.085"], ["70455.70", "0.006"], ["70455.80", "0.039"], ["70455.90", "0.086"], ["70456.00", "0.087"], ["70456.20", "0.291"], ["70456.30", "0.191"], ["70456.40", "0.008"], ["70456.50", "0.044"], ["70456.60", "0.641"], ["70456.70", "0.010"], ["70456.80", "0.002"], ["70457.00", "0.016"], ["70457.10", "0.387"], ["70457.30", "0.005"], ["70457.40", "0.089"], ["70457.50", "0.192"], ["70457.60", "0.020"], ["70457.80", "0.048"], ["70457.90", "0.091"], ["70458.00", "0.019"], ["70458.10", "0.171"], ["70458.50", "0.378"], ["70458.60", "0.201"], ["70459.00", "0.014"], ["70459.20", "0.002"], ["70459.30", "0.002"], ["70459.40", "0.003"], ["70459.60", "0.003"], ["70459.70", "0.041"], ["70459.80", "0.385"], ["70459.90", "0.191"], ["70460.00", "0.014"], ["70460.20", "0.182"], ["70460.30", "0.002"], ["70460.40", "0.094"], ["70460.60", "0.003"], ["70460.70", "0.029"], ["70460.90", "0.039"], ["70461.10", "0.575"], ["70461.40", "0.041"], ["70461.50", "0.013"], ["70461.60", "0.511"], ["70461.70", "0.097"], ["70461.80", "0.090"], ["70462.00", "0.007"], ["70462.10", "0.781"], ["70462.20", "0.006"], ["70462.40", "0.039"], ["70462.50", "0.150"], ["70462.60", "0.002"], ["70462.70", "0.003"], ["70462.80", "0.375"], ["70462.90", "0.199"], ["70463.00", "0.090"], ["70463.10", "0.009"], ["70463.30", "0.039"], ["70463.40", "0.003"], ["70463.50", "0.189"], ["70463.60", "0.045"], ["70463.70", "0.006"], ["70463.80", "0.008"], ["70463.90", "0.087"], ["70464.00", "0.002"], ["70464.10", "2.006"], ["70464.30", "0.081"], ["70464.40", "0.002"], ["70464.60", "0.087"], ["70464.90", "0.574"], ["70465.20", "0.002"], ["70465.30", "0.008"], ["70465.40", "0.595"], ["70465.50", "0.081"], ["70465.90", "0.002"], ["70466.10", "1.461"], ["70466.20", "0.044"], ["70466.40", "0.201"], ["70466.50", "0.044"], ["70466.60", "0.130"], ["70466.80", "0.084"], ["70467.00", "0.042"], ["70467.10", "0.189"], ["70467.30", "0.002"], ["70467.50", "0.123"], ["70467.60", "0.078"], ["70467.70", "0.002"], ["70467.80", "0.083"], ["70468.10", "0.344"], ["70468.20", "0.517"], ["70468.30", "6.518"], ["70468.40", "0.693"], ["70468.50", "0.395"], ["70468.60", "0.017"], ["70468.90", "0.041"], ["70469.00", "0.734"], ["70469.10", "0.081"], ["70469.20", "0.084"], ["70469.60", "0.083"], ["70469.80", "0.257"], ["70469.90", "0.279"], ["70470.00", "0.033"], ["70470.10", "0.099"], ["70470.20", "0.077"], ["70470.30", "0.002"], ["70470.40", "0.209"], ["70470.60", "0.250"], ["70470.70", "0.272"], ["70470.90", "0.002"], ["70471.00", "0.080"], ["70471.20", "0.081"], ["70471.30", "0.083"], ["70471.50", "0.248"], ["70471.70", "0.131"], ["70471.80", "0.590"], ["70471.90", "0.003"], ["70472.00", "0.080"], ["70472.10", "0.467"], ["70472.30", "0.010"], ["70472.40", "0.084"], ["70472.50", "0.002"], ["70472.60", "0.366"], ["70472.80", "0.008"], ["70473.00", "0.002"], ["70473.10", "0.260"], ["70473.50", "0.002"], ["70473.60", "0.008"], ["70473.70", "0.005"], ["70473.80", "0.002"], ["70474.20", "0.044"], ["70474.30", "0.189"], ["70474.50", "0.555"], ["70474.90", "0.189"], ["70475.00", "0.348"], ["70475.10", "0.042"], ["70475.30", "0.004"], ["70475.40", "0.137"], ["70475.50", "0.018"], ["70475.70", "0.088"], ["70475.90", "0.285"], ["70476.00", "0.197"], ["70476.40", "0.044"], ["70476.50", "0.042"], ["70476.60", "0.044"], ["70476.80", "0.002"], ["70476.90", "0.626"], ["70477.00", "0.513"], ["70477.20", "0.123"], ["70477.30", "0.046"], ["70477.40", "0.003"], ["70477.50", "0.036"], ["70477.60", "0.044"], ["70477.70", "0.085"], ["70477.80", "0.540"], ["70477.90", "0.379"], ["70478.00", "0.090"], ["70478.10", "0.447"], ["70478.50", "2.017"], ["70478.60", "0.044"], ["70478.70", "0.080"], ["70478.80", "0.062"], ["70478.90", "0.081"], ["70479.00", "0.002"], ["70479.10", "0.034"], ["70479.30", "0.003"], ["70479.40", "0.513"], ["70479.50", "1.345"], ["70479.60", "0.189"], ["70479.70", "0.044"], ["70479.80", "0.003"], ["70479.90", "0.259"], ["70480.00", "0.136"], ["70480.10", "0.085"], ["70480.20", "0.042"], ["70480.30", "0.564"], ["70480.40", "0.083"], ["70480.60", "3.610"], ["70480.70", "0.162"], ["70480.80", "0.002"], ["70480.90", "0.046"]]}
{"event": "depthUpdate", "raw_payload": "{\"e\": \"depthUpdate\", \"E\": 1773246384948, \"T\": 1773246384946, \"s\": \"BTCUSDT\", \"U\": 10089703793777, \"u\": 10089703800287, \"pu\": 10089703793684, \"b\": [[\"5000.00\", \"101.418\"], [\"19848.60\", \"0.940\"], [\"19948.60\", \"1.060\"], [\"20048.60\", \"0.790\"], [\"20148.60\", \"0.210\"], [\"40000.00\", \"50.522\"], [\"63313.70\", \"0.000\"], [\"66829.50\", \"0.002\"], [\"68427.00\", \"0.010\"], [\"68705.10\", \"0.003\"], [\"68983.30\", \"0.000\"], [\"69261.40\", \"0.000\"], [\"69401.50\", \"64.793\"], [\"69434.20\", \"0.000\"], [\"69539.60\", \"0.000\"], [\"69610.30\", \"54.907\"], [\"70114.80\", \"0.007\"], [\"70141.10\", \"0.049\"], [\"70151.40\", \"0.272\"], [\"70151.80\", \"0.047\"], [\"70223.70\", \"0.719\"], [\"70280.00\", \"1.428\"], [\"70286.70\", \"0.102\"], [\"70298.40\", \"0.003\"], [\"70298.60\", \"0.004\"], [\"70305.90\", \"0.902\"], [\"70306.00\", \"0.445\"], [\"70308.00\", \"0.014\"], [\"70308.10\", \"0.007\"], [\"70318.40\", \"0.007\"], [\"70318.50\", \"0.923\"], [\"70319.10\", \"0.005\"], [\"70319.20\", \"0.005\"], [\"70329.40\", \"0.641\"], [\"70330.70\", \"0.006\"], [\"70330.90\", \"0.000\"], [\"70331.20\", \"0.007\"], [\"70332.40\", \"0.175\"], [\"70334.00\", \"0.041\"], [\"70334.10\", \"0.205\"], [\"70334.30\", \"0.003\"], [\"70334.40\", \"0.157\"], [\"70334.60\", \"0.284\"], [\"70335.30\", \"0.007\"], [\"70336.60\", \"0.287\"], [\"70338.00\", \"0.059\"], [\"70338.50\", \"0.167\"], [\"70340.00\", \"0.019\"], [\"70348.60\", \"3.468\"]], \"a\": [[\"70348.70\", \"0.169\"], [\"70352.80\", \"0.442\"], [\"70353.90\", \"0.099\"], [\"70355.30\", \"0.000\"], [\"70355.70\", \"0.151\"], [\"70355.80\", \"0.094\"], [\"70356.90\", \"0.486\"], [\"70357.70\", \"0.005\"], [\"70358.20\", \"0.022\"], [\"70358.40\", \"0.426\"], [\"70358.50\", \"0.000\"], [\"70358.60\", \"0.429\"], [\"70358.90\", \"0.024\"], [\"70359.30\", \"0.186\"], [\"70360.30\", \"0.003\"], [\"70363.10\", \"0.183\"], [\"70364.00\", \"0.168\"], [\"70375.70\", \"0.000\"], [\"70377.20\", \"0.010\"], [\"70378.40\", \"0.007\"], [\"70379.20\", \"0.020\"], [\"70386.70\", \"0.000\"], [\"70387.80\", \"0.006\"], [\"70387.90\", \"0.006\"], [\"70388.50\", \"0.005\"], [\"70388.60\", \"0.003\"], [\"70389.20\", \"0.004\"], [\"70389.60\", \"0.208\"], [\"70391.10\", \"0.000\"], [\"70394.40\", \"0.088\"], [\"70398.00\", \"0.000\"], [\"70398.30\", \"0.240\"], [\"70399.60\", \"0.002\"], [\"70400.00\", \"2.126\"], [\"70400.60\", \"0.036\"], [\"70406.40\", \"0.089\"], [\"70407.40\", \"0.088\"], [\"70413.50\", \"0.028\"], [\"70417.30\", \"0.003\"], [\"70473.10\", \"0.177\"], [\"70473.60\", \"0.008\"], [\"70514.80\", \"0.084\"], [\"70587.40\", \"3.062\"], [\"70841.60\", \"0.002\"], [\"71052.20\", \"0.010\"], [\"71086.80\", \"54.764\"], [\"71300.00\", \"212.411\"], [\"77383.60\", \"0.002\"]]}", "symbol": "BTCUSDT"}
{"event": "depthUpdate", "raw_payload": "{\"e\": \"depthUpdate\", \"E\": 1773246385050, \"T\": 1773246385049, \"s\": \"BTCUSDT\", \"U\": 10089703800339, \"u\": 10089703807630, \"pu\": 10089703800287, \"b\": [[\"1000.00\", \"26.792\"], [\"5000.00\", \"101.438\"], [\"19848.60\", \"1.110\"], [\"19948.60\", \"0.890\"], [\"20048.60\", \"0.880\"], [\"20148.60\", \"0.120\"], [\"56279.00\", \"0.045\"], [\"66827.30\", \"0.002\"], [\"69138.60\", \"0.288\"], [\"69356.70\", \"0.432\"], [\"69645.10\", \"0.000\"], [\"69814.90\", \"0.000\"], [\"69819.70\", \"3.727\"], [\"69996.80\", \"0.000\"], [\"69996.90\", \"0.000\"], [\"70098.20\", \"0.044\"], [\"70150.90\", \"0.045\"], [\"70151.10\", \"0.055\"], [\"70151.40\", \"0.315\"], [\"70152.10\", \"0.066\"], [\"70152.70\", \"0.037\"], [\"70231.50\", \"0.085\"], [\"70235.60\", \"0.014\"], [\"70253.10\", \"0.005\"], [\"70253.30\", \"2.071\"], [\"70255.70\", \"0.000\"], [\"70260.20\", \"0.094\"], [\"70260.40\", \"0.544\"], [\"70261.40\", \"0.002\"], [\"70267.20\", \"0.101\"], [\"70267.40\", \"1.853\"], [\"70278.30\", \"0.084\"], [\"70286.40\", \"0.042\"], [\"70294.30\", \"0.406\"], [\"70298.50\", \"0.016\"], [\"70298.60\", \"0.002\"], [\"70301.00\", \"1.191\"], [\"70308.00\", \"0.635\"], [\"70312.10\", \"0.008\"], [\"70315.00\", \"0.629\"], [\"70317.00\", \"0.008\"], [\"70317.10\", \"0.066\"], [\"70318.10\", \"0.002\"], [\"70318.40\", \"0.005\"], [\"70318.50\", \"0.921\"], [\"70319.10\", \"0.014\"], [\"70319.20\", \"0.014\"], [\"70320.50\", \"0.004\"], [\"70320.60\", \"0.004\"], [\"70321.20\", \"0.000\"], [\"70321.30\", \"0.234\"], [\"70322.00\", \"0.630\"], [\"70324.00\", \"0.005\"], [\"70324.10\", \"0.008\"], [\"70325.30\", \"0.075\"], [\"70325.70\", \"0.069\"], [\"70326.50\", \"0.511\"], [\"70326.60\", \"0.052\"], [\"70329.00\", \"0.636\"], [\"70330.10\", \"1.069\"], [\"70331.80\", \"0.109\"], [\"70332.30\", \"0.005\"], [\"70332.90\", \"0.063\"], [\"70333.20\", \"2.119\"], [\"70333.30\", \"0.063\"], [\"70334.10\", \"0.212\"], [\"70334.50\", \"0.278\"], [\"70334.60\", \"0.284\"], [\"70335.10\", \"0.673\"], [\"70335.40\", \"0.011\"], [\"70336.70\", \"1.214\"], [\"70338.00\", \"0.005\"], [\"70338.40\", \"0.108\"], [\"70339.20\", \"0.144\"], [\"70339.30\", \"0.009\"], [\"70339.40\", \"0.005\"], [\"70339.60\", \"0.033\"], [\"70340.20\", \"0.000\"], [\"70340.30\", \"0.001\"], [\"70340.40\", \"0.010\"], [\"70341.60\", \"1.000\"], [\"70346.50\", \"0.002\"], [\"70348.60\", \"3.820\"]], \"a\": [[\"70348.70\", \"0.132\"], [\"70352.00\", \"0.001\"], [\"70352.60\", \"0.620\"], [\"70352.70\", \"0.218\"], [\"70352.80\", \"0.006\"], [\"70353.90\", \"0.175\"], [\"70355.70\", \"0.067\"], [\"70355.80\", \"0.094\"], [\"70356.80\", \"0.428\"], [\"70356.90\", \"0.004\"], [\"70357.00\", \"0.006\"], [\"70357.10\", \"0.510\"], [\"70357.20\", \"0.558\"], [\"70357.70\", \"0.002\"], [\"70358.00\", \"0.007\"], [\"70358.40\", \"0.001\"], [\"70358.60\", \"0.217\"], [\"70359.10\", \"0.003\"], [\"70359.20\", \"0.010\"], [\"70359.30\", \"0.084\"], [\"70360.90\", \"0.064\"], [\"70361.40\", \"2.009\"], [\"70362.30\", \"0.000\"], [\"70362.40\", \"0.004\"], [\"70364.00\", \"0.789\"], [\"70367.70\", \"0.000\"], [\"70368.90\", \"0.646\"], [\"70369.60\", \"0.009\"], [\"70369.80\", \"0.286\"], [\"70370.40\", \"0.000\"], [\"70370.60\", \"0.002\"], [\"70371.00\", \"0.702\"], [\"70371.90\", \"0.007\"], [\"70372.00\", \"1.004\"], [\"70372.50\", \"0.794\"], [\"70372.80\", \"0.007\"], [\"70373.50\", \"0.035\"], [\"70374.10\", \"0.005\"], [\"70374.80\", \"0.313\"], [\"70376.60\", \"0.250\"], [\"70377.30\", \"0.007\"], [\"70378.00\", \"0.625\"], [\"70378.80\", \"0.010\"], [\"70380.80\", \"0.075\"], [\"70380.90\", \"0.007\"], [\"70382.90\", \"0.009\"], [\"70383.00\", \"0.014\"], [\"70383.90\", \"0.013\"], [\"70385.00\", \"0.655\"], [\"70385.10\", \"0.849\"], [\"70386.00\", \"0.054\"], [\"70386.20\", \"0.000\"], [\"70387.80\", \"0.004\"], [\"70387.90\", \"0.004\"], [\"70389.20\", \"0.006\"], [\"70389.30\", \"0.002\"], [\"70389.60\", \"0.122\"], [\"70392.00\", \"1.013\"], [\"70393.30\", \"0.116\"], [\"70394.40\", \"0.002\"], [\"70395.20\", \"0.000\"], [\"70397.90\", \"0.000\"], [\"70400.00\", \"2.040\"], [\"70401.30\", \"0.071\"], [\"70401.50\", \"0.552\"], [\"70402.50\", \"0.010\"], [\"70403.50\", \"0.000\"], [\"70404.50\", \"0.000\"], [\"70405.00\", \"0.000\"], [\"70405.40\", \"0.002\"], [\"70406.40\", \"0.003\"], [\"70407.40\", \"0.002\"], [\"70408.30\", \"0.007\"], [\"70410.80\", \"0.184\"], [\"70410.90\", \"0.005\"], [\"70414.30\", \"0.002\"], [\"70415.30\", \"0.002\"], [\"70415.70\", \"0.002\"], [\"70418.80\", \"0.002\"], [\"70427.80\", \"0.230\"], [\"70429.20\", \"0.002\"], [\"70429.30\", \"0.073\"], [\"70434.80\", \"0.000\"], [\"70436.20\", \"0.002\"], [\"70436.30\", \"1.573\"], [\"70436.60\", \"0.104\"], [\"70439.50\", \"0.002\"], [\"70440.50\", \"0.018\"], [\"70441.20\", \"0.176\"], [\"70441.50\", \"0.002\"], [\"70442.40\", \"0.022\"], [\"70443.30\", \"9.602\"], [\"70443.40\", \"0.077\"], [\"70444.40\", \"0.004\"], [\"70445.30\", \"0.000\"], [\"70446.30\", \"0.000\"], [\"70451.50\", \"0.088\"], [\"70452.50\", \"0.086\"], [\"70453.50\", \"0.088\"], [\"70454.40\", \"0.096\"], [\"70455.40\", \"0.171\"], [\"70456.40\", \"0.094\"], [\"70457.30\", \"0.091\"], [\"70458.30\", \"0.086\"], [\"70476.60\", \"0.144\"], [\"70587.40\", \"3.417\"], [\"70877.70\", \"3.873\"], [\"70882.50\", \"0.000\"], [\"71052.20\", \"0.010\"], [\"73889.40\", \"0.006\"], [\"74000.00\", \"186.231\"], [\"89523.20\", \"0.000\"]]}", "symbol": "BTCUSDT"}
{"event": "depthUpdate", "raw_payload": "{\"e\": \"depthUpdate\", \"E\": 1773246385152, \"T\": 1773246385150, \"s\": \"BTCUSDT\", \"U\": 10089703807683, \"u\": 10089703814788, \"pu\": 10089703807630, \"b\": [[\"1000.00\", \"26.792\"], [\"5000.00\", \"101.418\"], [\"19848.60\", \"1.280\"], [\"19948.60\", \"0.720\"], [\"20048.60\", \"0.960\"], [\"20148.60\", \"0.040\"], [\"40000.00\", \"50.271\"], [\"67474.60\", \"0.002\"], [\"69344.40\", \"0.002\"], [\"69348.60\", \"0.004\"], [\"69349.60\", \"0.290\"], [\"69477.20\", \"0.867\"], [\"69680.30\", \"2.004\"], [\"69819.70\", \"0.007\"], [\"70068.50\", \"0.000\"], [\"70069.80\", \"0.568\"], [\"70111.40\", \"0.162\"], [\"70152.90\", \"0.278\"], [\"70154.40\", \"0.000\"], [\"70157.40\", \"0.158\"], [\"70197.40\", \"0.002\"], [\"70223.70\", \"0.719\"], [\"70243.60\", \"2.193\"], [\"70280.00\", \"1.428\"], [\"70286.70\", \"0.002\"], [\"70294.00\", \"0.818\"], [\"70298.50\", \"0.014\"], [\"70298.60\", \"0.004\"], [\"70301.00\", \"0.570\"], [\"70308.00\", \"0.014\"], [\"70308.10\", \"0.007\"], [\"70315.00\", \"0.008\"], [\"70315.20\", \"0.636\"], [\"70316.80\", \"0.089\"], [\"70322.00\", \"0.009\"], [\"70325.70\", \"0.029\"], [\"70326.20\", \"0.118\"], [\"70326.50\", \"0.000\"], [\"70327.60\", \"0.002\"], [\"70328.40\", \"0.073\"], [\"70329.00\", \"0.015\"], [\"70329.10\", \"0.846\"], [\"70329.40\", \"1.152\"], [\"70330.70\", \"0.126\"], [\"70330.90\", \"0.028\"], [\"70331.60\", \"0.511\"], [\"70331.80\", \"0.038\"], [\"70331.90\", \"0.005\"], [\"70333.00\", \"0.000\"], [\"70333.30\", \"0.094\"], [\"70333.80\", \"0.010\"], [\"70334.10\", \"0.233\"], [\"70334.20\", \"0.043\"], [\"70334.60\", \"0.000\"], [\"70334.90\", \"0.035\"], [\"70335.00\", \"0.102\"], [\"70335.10\", \"0.699\"], [\"70335.20\", \"0.360\"], [\"70335.30\", \"0.021\"], [\"70335.40\", \"0.097\"], [\"70335.50\", \"0.008\"], [\"70336.30\", \"0.488\"], [\"70336.40\", \"0.093\"], [\"70336.60\", \"0.294\"], [\"70337.30\", \"0.307\"], [\"70338.00\", \"0.056\"], [\"70338.50\", \"0.292\"], [\"70339.00\", \"0.008\"], [\"70339.20\", \"0.002\"], [\"70339.40\", \"0.052\"], [\"70339.70\", \"0.097\"], [\"70340.60\", \"0.142\"], [\"70343.00\", \"0.400\"], [\"70348.60\", \"4.283\"]], \"a\": [[\"70348.70\", \"0.042\"], [\"70352.40\", \"0.004\"], [\"70352.50\", \"0.056\"], [\"70352.60\", \"0.006\"], [\"70352.70\", \"0.005\"], [\"70352.80\", \"0.784\"], [\"70352.90\", \"0.000\"], [\"70353.90\", \"0.039\"], [\"70356.80\", \"0.003\"], [\"70357.00\", \"0.488\"], [\"70357.20\", \"0.516\"], [\"70357.50\", \"0.003\"], [\"70358.20\", \"0.043\"], [\"70358.50\", \"0.425\"], [\"70358.80\", \"0.003\"], [\"70358.90\", \"0.003\"], [\"70359.20\", \"0.010\"], [\"70359.30\", \"0.000\"], [\"70359.90\", \"0.007\"], [\"70360.70\", \"0.005\"], [\"70360.90\", \"0.007\"], [\"70361.40\", \"2.005\"], [\"70362.80\", \"0.309\"], [\"70363.10\", \"0.155\"], [\"70364.00\", \"0.140\"], [\"70368.30\", \"0.000\"], [\"70369.30\", \"0.144\"], [\"70369.60\", \"0.196\"], [\"70369.80\", \"0.002\"], [\"70370.20\", \"0.000\"], [\"70371.00\", \"0.081\"], [\"70371.80\", \"0.284\"], [\"70372.00\", \"0.004\"], [\"70372.60\", \"0.407\"], [\"70373.50\", \"0.042\"], [\"70373.60\", \"1.069\"], [\"70374.20\", \"0.002\"], [\"70374.30\", \"1.269\"], [\"70375.20\", \"0.009\"], [\"70375.60\", \"0.002\"], [\"70375.90\", \"0.072\"], [\"70376.60\", \"0.761\"], [\"70377.20\", \"0.003\"], [\"70377.80\", \"0.000\"], [\"70378.00\", \"0.004\"], [\"70378.20\", \"0.009\"], [\"70379.20\", \"0.000\"], [\"70379.60\", \"0.025\"], [\"70379.70\", \"1.071\"], [\"70380.70\", \"0.073\"], [\"70384.30\", \"0.002\"], [\"70384.40\", \"0.005\"], [\"70385.00\", \"0.032\"], [\"70385.10\", \"0.847\"], [\"70386.70\", \"0.000\"], [\"70389.00\", \"0.009\"], [\"70389.20\", \"0.006\"], [\"70391.20\", \"0.210\"], [\"70392.00\", \"0.392\"], [\"70405.70\", \"0.006\"], [\"70417.30\", \"0.003\"], [\"70431.90\", \"0.000\"], [\"70433.30\", \"0.087\"], [\"70436.60\", \"0.104\"], [\"70439.80\", \"0.000\"], [\"70441.20\", \"0.090\"], [\"70444.20\", \"0.597\"], [\"70445.20\", \"0.090\"], [\"70458.30\", \"0.000\"], [\"70473.60\", \"0.008\"], [\"70480.00\", \"0.134\"], [\"70482.70\", \"0.049\"], [\"70482.90\", \"0.081\"], [\"70487.50\", \"0.138\"], [\"70487.60\", \"0.055\"], [\"70539.20\", \"0.000\"], [\"70585.10\", \"0.000\"], [\"70647.80\", \"0.005\"], [\"70689.60\", \"0.030\"], [\"70690.80\", \"0.000\"], [\"70711.40\", \"0.000\"], [\"70713.10\", \"0.002\"], [\"70873.40\", \"3.720\"], [\"70877.70\", \"0.153\"], [\"71052.20\", \"0.010\"], [\"73889.40\", \"0.004\"], [\"73901.10\", \"0.010\"]]}", "symbol": "BTCUSDT"}
{"event": "depthUpdate", "raw_payload": "{\"e\": \"depthUpdate\", \"E\": 1773246385254, \"T\": 1773246385253, \"s\": \"BTCUSDT\", \"U\": 10089703814912, \"u\": 10089703829573, \"pu\": 10089703814788, \"b\": [[\"5000.00\", \"101.418\"], [\"19848.60\", \"1.340\"], [\"19848.70\", \"0.010\"], [\"19849.30\", \"0.020\"], [\"19851.00\", \"0.020\"], [\"19852.20\", \"0.020\"], [\"19852.50\", \"0.040\"], [\"19948.60\", \"0.550\"], [\"19949.30\", \"0.010\"], [\"19951.40\", \"0.010\"], [\"19952.50\", \"0.030\"], [\"20048.60\", \"0.950\"], [\"20049.30\", \"0.000\"], [\"20148.60\", \"0.000\"], [\"33000.00\", \"10.797\"], [\"40000.00\", \"50.271\"], [\"66819.80\", \"0.000\"], [\"66831.20\", \"0.008\"], [\"69344.40\", \"0.000\"], [\"69345.30\", \"0.000\"], [\"69346.40\", \"0.857\"], [\"69348.00\", \"0.576\"], [\"69348.20\", \"0.361\"], [\"69348.70\", \"0.020\"], [\"69349.30\", \"0.002\"], [\"69351.00\", \"0.884\"], [\"69352.20\", \"0.020\"], [\"69354.50\", \"0.004\"], [\"69354.90\", \"0.870\"], [\"69355.70\", \"0.000\"], [\"69358.30\", \"0.000\"], [\"69434.10\", \"4.015\"], [\"69645.20\", \"0.000\"], [\"69813.60\", \"0.000\"], [\"69815.80\", \"0.000\"], [\"69860.00\", \"0.027\"], [\"69900.00\", \"9.095\"], [\"70052.30\", \"0.844\"], [\"70056.10\", \"0.194\"], [\"70136.80\", \"0.000\"], [\"70227.80\", \"0.081\"], [\"70233.60\", \"0.185\"], [\"70243.60\", \"2.108\"], [\"70248.80\", \"0.083\"], [\"70252.10\", \"0.370\"], [\"70253.80\", \"0.108\"], [\"70260.70\", \"0.136\"], [\"70267.30\", \"0.016\"], [\"70267.50\", \"0.000\"], [\"70271.90\", \"0.008\"], [\"70272.20\", \"0.000\"], [\"70276.50\", \"0.096\"], [\"70278.00\", \"0.525\"], [\"70278.30\", \"0.000\"], [\"70278.40\", \"0.000\"], [\"70280.00\", \"1.430\"], [\"70281.50\", \"0.011\"], [\"70281.80\", \"0.319\"], [\"70281.90\", \"1.051\"], [\"70282.40\", \"0.304\"], [\"70282.50\", \"0.229\"], [\"70284.20\", \"0.228\"], [\"70289.20\", \"0.935\"], [\"70289.50\", \"0.215\"], [\"70292.70\", \"0.087\"], [\"70293.00\", \"0.468\"], [\"70293.70\", \"0.007\"], [\"70294.70\", \"0.000\"], [\"70295.90\", \"0.002\"], [\"70296.10\", \"0.283\"], [\"70298.60\", \"0.002\"], [\"70298.80\", \"0.002\"], [\"70299.00\", \"0.239\"], [\"70299.10\", \"0.002\"], [\"70299.20\", \"0.002\"], [\"70299.30\", \"0.084\"], [\"70299.40\", \"0.006\"], [\"70299.60\", \"0.002\"], [\"70299.70\", \"0.002\"], [\"70300.00\", \"1.477\"], [\"70300.60\", \"0.016\"], [\"70301.50\", \"0.048\"], [\"70301.80\", \"0.513\"], [\"70303.40\", \"0.000\"], [\"70304.60\", \"0.719\"], [\"70305.30\", \"0.417\"], [\"70305.90\", \"0.248\"], [\"70306.00\", \"0.233\"], [\"70306.10\", \"0.457\"], [\"70306.40\", \"0.003\"], [\"70306.70\", \"0.003\"], [\"70306.80\", \"0.005\"], [\"70307.00\", \"0.013\"], [\"70307.10\", \"0.025\"], [\"70307.30\", \"0.085\"], [\"70307.50\", \"0.014\"], [\"70308.70\", \"0.575\"], [\"70309.10\", \"0.209\"], [\"70309.20\", \"0.011\"], [\"70309.30\", \"0.000\"], [\"70309.40\", \"0.005\"], [\"70309.70\", \"0.004\"], [\"70310.90\", \"0.159\"], [\"70311.50\", \"1.074\"], [\"70311.70\", \"0.002\"], [\"70311.80\", \"0.025\"], [\"70312.00\", \"0.147\"], [\"70312.90\", \"1.004\"], [\"70313.40\", \"0.007\"], [\"70313.50\", \"0.379\"], [\"70315.00\", \"0.004\"], [\"70316.50\", \"0.006\"], [\"70316.80\", \"0.049\"], [\"70316.90\", \"0.000\"], [\"70317.10\", \"0.062\"], [\"70317.30\", \"0.012\"], [\"70318.50\", \"0.920\"], [\"70318.70\", \"0.022\"], [\"70319.30\", \"0.004\"], [\"70320.00\", \"0.048\"], [\"70320.10\", \"0.276\"], [\"70320.20\", \"0.099\"], [\"70320.50\", \"0.123\"], [\"70320.60\", \"0.004\"], [\"70320.70\", \"0.007\"], [\"70321.00\", \"0.007\"], [\"70321.10\", \"0.089\"], [\"70321.20\", \"0.000\"], [\"70321.30\", \"0.234\"], [\"70321.50\", \"0.012\"], [\"70321.80\", \"0.493\"], [\"70322.10\", \"0.629\"], [\"70323.00\", \"0.023\"], [\"70323.20\", \"0.002\"], [\"70323.40\", \"0.000\"], [\"70323.90\", \"0.058\"], [\"70324.10\", \"0.048\"], [\"70325.40\", \"0.649\"], [\"70325.80\", \"0.002\"], [\"70326.10\", \"0.018\"], [\"70327.50\", \"0.110\"], [\"70327.60\", \"0.000\"], [\"70328.20\", \"0.003\"], [\"70328.80\", \"0.002\"], [\"70329.10\", \"0.362\"], [\"70329.40\", \"0.513\"], [\"70329.90\", \"0.070\"], [\"70330.30\", \"0.003\"], [\"70330.40\", \"0.042\"], [\"70330.50\", \"0.414\"], [\"70330.70\", \"0.077\"], [\"70330.80\", \"0.003\"], [\"70330.90\", \"0.000\"], [\"70331.10\", \"0.007\"], [\"70331.40\", \"0.117\"], [\"70331.50\", \"0.185\"], [\"70331.70\", \"0.006\"], [\"70332.00\", \"0.487\"], [\"70332.10\", \"0.004\"], [\"70332.50\", \"0.666\"], [\"70332.70\", \"0.028\"], [\"70332.80\", \"0.021\"], [\"70333.00\", \"0.028\"], [\"70333.10\", \"0.002\"], [\"70333.30\", \"0.060\"], [\"70333.40\", \"0.090\"], [\"70334.10\", \"0.212\"], [\"70334.20\", \"0.000\"], [\"70334.40\", \"0.086\"], [\"70334.50\", \"0.227\"], [\"70334.90\", \"0.034\"], [\"70335.00\", \"0.059\"], [\"70335.10\", \"0.673\"], [\"70335.20\", \"0.346\"], [\"70335.30\", \"0.007\"], [\"70335.40\", \"0.004\"], [\"70335.50\", \"0.001\"], [\"70335.80\", \"0.002\"], [\"70336.20\", \"0.091\"], [\"70336.30\", \"0.000\"], [\"70336.40\", \"0.002\"], [\"70336.60\", \"0.315\"], [\"70336.70\", \"0.048\"], [\"70336.80\", \"0.000\"], [\"70337.00\", \"0.034\"], [\"70337.10\", \"0.000\"], [\"70337.20\", \"0.044\"], [\"70337.30\", \"0.424\"], [\"70337.40\", \"0.033\"], [\"70337.50\", \"0.093\"], [\"70337.70\", \"0.007\"], [\"70337.80\", \"0.205\"], [\"70338.00\", \"0.048\"], [\"70338.10\", \"0.020\"], [\"70338.40\", \"0.108\"], [\"70338.50\", \"0.406\"], [\"70338.60\", \"1.218\"], [\"70338.70\", \"0.006\"], [\"70338.90\", \"0.092\"], [\"70339.00\", \"0.000\"], [\"70339.20\", \"0.004\"], [\"70339.30\", \"0.037\"], [\"70339.40\", \"0.004\"], [\"70339.50\", \"0.002\"], [\"70339.60\", \"0.493\"], [\"70339.70\", \"0.000\"], [\"70339.80\", \"0.003\"], [\"70340.20\", \"0.000\"], [\"70340.50\", \"0.063\"], [\"70340.60\", \"0.000\"], [\"70340.70\", \"0.007\"], [\"70341.20\", \"0.003\"], [\"70341.50\", \"0.193\"], [\"70341.60\", \"0.000\"], [\"70341.70\", \"0.005\"], [\"70341.80\", \"0.096\"], [\"70341.90\", \"0.001\"], [\"70342.00\", \"0.005\"], [\"70342.20\", \"0.098\"], [\"70342.30\", \"0.007\"], [\"70342.50\", \"0.001\"], [\"70343.00\", \"0.004\"], [\"70343.10\", \"0.004\"], [\"70343.20\", \"0.016\"], [\"70343.60\", \"0.074\"], [\"70344.10\", \"0.005\"], [\"70344.20\", \"0.000\"], [\"70344.30\", \"0.005\"], [\"70344.70\", \"0.015\"], [\"70344.80\", \"0.007\"], [\"70344.90\", \"0.005\"], [\"70345.10\", \"0.297\"], [\"70345.40\", \"0.004\"], [\"70345.50\", \"0.007\"], [\"70345.60\", \"0.002\"], [\"70345.70\", \"0.256\"], [\"70345.80\", \"0.003\"], [\"70346.00\", \"0.002\"], [\"70346.10\", \"1.005\"], [\"70346.30\", \"0.090\"], [\"70346.80\", \"0.001\"], [\"70347.40\", \"0.000\"], [\"70347.50\", \"0.003\"], [\"70348.00\", \"0.001\"], [\"70348.50\", \"0.087\"], [\"70348.60\", \"0.089\"], [\"70348.70\", \"0.102\"], [\"70348.80\", \"0.000\"], [\"70348.90\", \"0.000\"], [\"70349.10\", \"0.000\"], [\"70349.20\", \"0.001\"], [\"70349.30\", \"0.655\"], [\"70349.40\", \"1.102\"], [\"70349.50\", \"0.004\"], [\"70349.70\", \"0.001\"], [\"70349.80\", \"0.003\"], [\"70349.90\", \"0.000\"], [\"70350.00\", \"0.004\"], [\"70350.10\", \"0.000\"], [\"70350.20\", \"0.000\"], [\"70350.40\", \"0.000\"], [\"70350.50\", \"0.003\"], [\"70350.70\", \"0.088\"], [\"70350.80\", \"0.002\"], [\"70350.90\", \"0.001\"], [\"70351.00\", \"0.589\"], [\"70351.10\", \"1.100\"], [\"70351.20\", \"0.000\"], [\"70351.30\", \"0.001\"], [\"70351.40\", \"0.001\"], [\"70351.50\", \"0.466\"], [\"70351.60\", \"0.000\"], [\"70351.70\", \"0.000\"], [\"70351.80\", \"0.086\"], [\"70351.90\", \"0.002\"], [\"70352.00\", \"0.000\"], [\"70352.10\", \"0.007\"], [\"70352.20\", \"0.051\"], [\"70352.30\", \"0.030\"], [\"70352.40\", \"0.001\"], [\"70352.50\", \"11.079\"]], \"a\": [[\"70348.70\", \"0.000\"], [\"70348.80\", \"0.000\"], [\"70349.20\", \"0.000\"], [\"70349.30\", \"0.000\"], [\"70349.40\", \"0.000\"], [\"70349.50\", \"0.000\"], [\"70349.80\", \"0.000\"], [\"70350.00\", \"0.000\"], [\"70350.20\", \"0.000\"], [\"70350.30\", \"0.000\"], [\"70350.50\", \"0.000\"], [\"70350.80\", \"0.000\"], [\"70350.90\", \"0.000\"], [\"70351.10\", \"0.000\"], [\"70351.30\", \"0.000\"], [\"70351.40\", \"0.000\"], [\"70351.50\", \"0.000\"], [\"70351.60\", \"0.000\"], [\"70351.70\", \"0.000\"], [\"70351.90\", \"0.000\"], [\"70352.00\", \"0.000\"], [\"70352.10\", \"0.000\"], [\"70352.30\", \"0.000\"], [\"70352.40\", \"0.000\"], [\"70352.50\", \"0.000\"], [\"70352.60\", \"0.013\"], [\"70352.70\", \"0.002\"], [\"70352.80\", \"0.004\"], [\"70353.00\", \"0.004\"], [\"70353.30\", \"0.005\"], [\"70353.50\", \"0.004\"], [\"70353.60\", \"0.000\"], [\"70353.80\", \"0.002\"], [\"70353.90\", \"0.039\"], [\"70354.00\", \"0.006\"], [\"70354.40\", \"0.002\"], [\"70354.90\", \"0.002\"], [\"70355.60\", \"0.000\"], [\"70355.70\", \"0.029\"], [\"70355.80\", \"0.092\"], [\"70356.10\", \"0.003\"], [\"70356.30\", \"0.008\"], [\"70356.90\", \"0.006\"], [\"70357.00\", \"0.008\"], [\"70357.10\", \"0.213\"], [\"70357.20\", \"0.005\"], [\"70357.30\", \"0.001\"], [\"70358.00\", \"0.002\"], [\"70358.20\", \"0.001\"], [\"70358.30\", \"0.009\"], [\"70358.50\", \"0.000\"], [\"70358.60\", \"0.455\"], [\"70359.20\", \"0.000\"], [\"70359.30\", \"0.000\"], [\"70359.40\", \"0.000\"], [\"70359.60\", \"0.104\"], [\"70359.80\", \"0.004\"], [\"70359.90\", \"0.000\"], [\"70360.00\", \"0.015\"], [\"70360.10\", \"0.060\"], [\"70360.20\", \"0.425\"], [\"70360.30\", \"0.428\"], [\"70360.40\", \"0.511\"], [\"70360.50\", \"0.010\"], [\"70360.70\", \"0.076\"], [\"70360.90\", \"0.007\"], [\"70361.00\", \"0.103\"], [\"70361.20\", \"0.051\"], [\"70361.30\", \"1.281\"], [\"70361.70\", \"0.003\"], [\"70361.90\", \"0.001\"], [\"70362.20\", \"0.003\"], [\"70362.30\", \"0.001\"], [\"70362.40\", \"0.009\"], [\"70362.50\", \"0.115\"], [\"70362.60\", \"0.536\"], [\"70362.80\", \"0.140\"], [\"70362.90\", \"0.136\"], [\"70363.00\", \"0.005\"], [\"70363.10\", \"0.143\"], [\"70363.20\", \"0.005\"], [\"70363.30\", \"0.068\"], [\"70363.40\", \"0.001\"], [\"70363.50\", \"0.004\"], [\"70363.70\", \"0.002\"], [\"70363.90\", \"0.005\"], [\"70364.10\", \"0.008\"], [\"70364.40\", \"0.036\"], [\"70364.60\", \"0.345\"], [\"70364.70\", \"0.143\"], [\"70364.90\", \"0.188\"], [\"70365.40\", \"0.097\"], [\"70365.70\", \"0.004\"], [\"70365.80\", \"0.000\"], [\"70366.00\", \"0.016\"], [\"70366.30\", \"0.008\"], [\"70366.40\", \"0.075\"], [\"70366.70\", \"0.008\"], [\"70366.90\", \"0.003\"], [\"70367.00\", \"1.074\"], [\"70368.10\", \"0.004\"], [\"70368.40\", \"0.102\"], [\"70368.60\", \"0.216\"], [\"70369.10\", \"0.003\"], [\"70369.30\", \"0.002\"], [\"70369.60\", \"0.189\"], [\"70369.80\", \"0.002\"], [\"70369.90\", \"0.160\"], [\"70370.00\", \"0.379\"], [\"70370.20\", \"0.006\"], [\"70370.60\", \"0.002\"], [\"70370.70\", \"0.000\"], [\"70371.00\", \"0.010\"], [\"70371.10\", \"0.239\"], [\"70371.70\", \"0.000\"], [\"70371.80\", \"0.000\"], [\"70371.90\", \"0.000\"], [\"70372.00\", \"0.000\"], [\"70372.20\", \"0.144\"], [\"70372.50\", \"0.025\"], [\"70372.60\", \"0.038\"], [\"70372.80\", \"0.005\"], [\"70373.10\", \"0.000\"], [\"70373.30\", \"0.000\"], [\"70373.40\", \"0.007\"], [\"70373.50\", \"0.071\"], [\"70374.00\", \"0.000\"], [\"70374.30\", \"0.269\"], [\"70374.40\", \"0.006\"], [\"70374.60\", \"0.002\"], [\"70375.20\", \"0.002\"], [\"70375.30\", \"0.000\"], [\"70375.40\", \"0.287\"], [\"70375.70\", \"0.007\"], [\"70375.90\", \"1.001\"], [\"70376.10\", \"0.013\"], [\"70376.50\", \"0.013\"], [\"70376.60\", \"0.376\"], [\"70376.90\", \"0.471\"], [\"70377.10\", \"0.006\"], [\"70377.30\", \"0.007\"], [\"70377.60\", \"0.000\"], [\"70377.80\", \"0.511\"], [\"70377.90\", \"0.006\"], [\"70378.20\", \"0.002\"], [\"70378.50\", \"0.010\"], [\"70378.80\", \"0.251\"], [\"70379.00\", \"0.003\"], [\"70379.30\", \"0.071\"], [\"70379.50\", \"0.007\"], [\"70379.60\", \"0.005\"], [\"70380.30\", \"0.007\"], [\"70380.70\", \"0.002\"], [\"70381.30\", \"0.003\"], [\"70381.90\", \"0.071\"], [\"70382.60\", \"0.389\"], [\"70384.00\", \"0.194\"], [\"70384.20\", \"0.380\"], [\"70384.30\", \"0.020\"], [\"70384.40\", \"0.003\"], [\"70385.00\", \"0.034\"], [\"70385.10\", \"0.849\"], [\"70385.60\", \"0.002\"], [\"70386.40\", \"0.040\"], [\"70386.60\", \"0.020\"], [\"70388.00\", \"0.004\"], [\"70388.20\", \"0.004\"], [\"70389.50\", \"0.002\"], [\"70389.90\", \"0.032\"], [\"70391.80\", \"0.004\"], [\"70394.30\", \"0.076\"], [\"70395.40\", \"0.037\"], [\"70396.10\", \"0.009\"], [\"70396.50\", \"0.000\"], [\"70397.40\", \"0.090\"], [\"70397.90\", \"0.000\"], [\"70400.30\", \"0.003\"], [\"70400.80\", \"0.015\"], [\"70401.60\", \"0.003\"], [\"70402.20\", \"0.000\"], [\"70402.90\", \"0.511\"], [\"70405.20\", \"0.007\"], [\"70409.70\", \"0.163\"], [\"70410.40\", \"0.000\"], [\"70410.50\", \"0.002\"], [\"70410.80\", \"0.111\"], [\"70410.90\", \"0.075\"], [\"70411.00\", \"0.139\"], [\"70416.90\", \"0.082\"], [\"70418.40\", \"0.193\"], [\"70419.10\", \"0.082\"], [\"70419.20\", \"0.192\"], [\"70419.40\", \"0.086\"], [\"70419.50\", \"0.007\"], [\"70420.00\", \"1.176\"], [\"70421.40\", \"0.092\"], [\"70421.80\", \"0.004\"], [\"70422.10\", \"0.105\"], [\"70423.70\", \"0.594\"], [\"70425.50\", \"0.000\"], [\"70425.70\", \"0.003\"], [\"70426.70\", \"0.000\"], [\"70427.00\", \"0.090\"], [\"70428.30\", \"0.076\"], [\"70428.90\", \"0.001\"], [\"70429.50\", \"0.000\"], [\"70429.80\", \"0.086\"], [\"70430.80\", \"0.086\"], [\"70431.70\", \"0.089\"], [\"70436.10\", \"0.099\"], [\"70436.60\", \"0.002\"], [\"70436.70\", \"0.256\"], [\"70437.00\", \"0.139\"], [\"70437.30\", \"0.238\"], [\"70441.00\", \"2.117\"], [\"70443.70\", \"1.755\"], [\"70444.20\", \"0.511\"], [\"70445.20\", \"0.004\"], [\"70449.90\", \"0.086\"], [\"70453.50\", \"0.002\"], [\"70454.40\", \"0.010\"], [\"70455.40\", \"0.085\"], [\"70456.40\", \"0.008\"], [\"70457.30\", \"0.005\"], [\"70472.50\", \"0.002\"], [\"70476.60\", \"0.044\"], [\"70479.20\", \"0.002\"], [\"70491.30\", \"0.000\"], [\"70499.70\", \"0.020\"], [\"70563.50\", \"0.056\"], [\"70587.40\", \"0.000\"], [\"70588.20\", \"0.014\"], [\"70589.40\", \"3.165\"], [\"70641.90\", \"0.186\"], [\"70729.90\", \"0.002\"], [\"70733.60\", \"0.004\"], [\"70740.40\", \"0.002\"], [\"70840.00\", \"0.544\"], [\"70873.40\", \"0.000\"], [\"70886.40\", \"0.000\"], [\"70888.60\", \"0.000\"], [\"70898.90\", \"0.000\"], [\"71052.20\", \"0.010\"], [\"71052.30\", \"0.000\"], [\"71352.60\", \"0.000\"], [\"71412.90\", \"2.656\"], [\"77174.20\", \"0.008\"], [\"77350.40\", \"0.000\"], [\"89523.20\", \"0.000\"]]}", "symbol": "BTCUSDT"}
{"event": "depthUpdate", "raw_payload": "{\"e\": \"depthUpdate\", \"E\": 1773246385356, \"T\": 1773246385355, \"s\": \"BTCUSDT\", \"U\": 10089703829646, \"u\": 10089703839746, \"pu\": 10089703829573, \"b\": [[\"1000.00\", \"26.792\"], [\"5000.00\", \"101.418\"], [\"19852.50\", \"0.210\"], [\"19948.60\", \"0.380\"], [\"19952.50\", \"0.110\"], [\"20048.60\", \"0.870\"], [\"33000.00\", \"10.793\"], [\"56279.00\", \"0.045\"], [\"66815.40\", \"0.012\"], [\"66829.50\", \"0.000\"], [\"67486.50\", \"0.000\"], [\"68908.60\", \"0.621\"], [\"68935.20\", \"0.720\"], [\"68945.50\", \"0.014\"], [\"68947.00\", \"0.011\"], [\"69105.60\", \"0.000\"], [\"69111.10\", \"0.334\"], [\"69352.50\", \"1.025\"], [\"69649.00\", \"0.052\"], [\"69996.90\", \"0.000\"], [\"70052.30\", \"0.657\"], [\"70226.80\", \"0.037\"], [\"70227.90\", \"0.002\"], [\"70239.60\", \"0.002\"], [\"70245.40\", \"0.006\"], [\"70253.30\", \"2.071\"], [\"70259.60\", \"0.220\"], [\"70260.40\", \"0.544\"], [\"70267.40\", \"1.853\"], [\"70281.50\", \"0.008\"], [\"70282.00\", \"0.011\"], [\"70282.10\", \"0.086\"], [\"70287.10\", \"2.020\"], [\"70287.90\", \"0.020\"], [\"70298.30\", \"0.009\"], [\"70299.00\", \"0.236\"], [\"70299.40\", \"0.003\"], [\"70299.70\", \"0.000\"], [\"70300.10\", \"0.000\"], [\"70302.20\", \"0.005\"], [\"70306.80\", \"0.002\"], [\"70307.30\", \"0.000\"], [\"70307.40\", \"0.087\"], [\"70310.20\", \"0.214\"], [\"70318.10\", \"0.000\"], [\"70318.20\", \"0.000\"], [\"70318.90\", \"0.026\"], [\"70319.00\", \"0.000\"], [\"70319.10\", \"0.005\"], [\"70319.20\", \"0.005\"], [\"70319.30\", \"0.044\"], [\"70319.80\", \"0.523\"], [\"70319.90\", \"0.011\"], [\"70320.50\", \"0.121\"], [\"70320.60\", \"0.002\"], [\"70321.20\", \"0.002\"], [\"70321.30\", \"0.236\"], [\"70322.00\", \"0.011\"], [\"70322.50\", \"0.002\"], [\"70323.70\", \"0.031\"], [\"70324.00\", \"0.003\"], [\"70324.10\", \"0.006\"], [\"70324.30\", \"0.695\"], [\"70324.70\", \"0.042\"], [\"70324.80\", \"0.007\"], [\"70324.90\", \"0.003\"], [\"70325.30\", \"0.080\"], [\"70326.90\", \"0.005\"], [\"70327.70\", \"0.003\"], [\"70329.30\", \"0.087\"], [\"70329.40\", \"0.002\"], [\"70331.20\", \"0.005\"], [\"70331.50\", \"0.696\"], [\"70332.20\", \"0.384\"], [\"70333.70\", \"0.037\"], [\"70334.00\", \"0.038\"], [\"70334.50\", \"0.108\"], [\"70337.10\", \"0.014\"], [\"70337.30\", \"0.323\"], [\"70337.40\", \"0.019\"], [\"70337.60\", \"0.018\"], [\"70337.70\", \"0.002\"], [\"70338.50\", \"0.000\"], [\"70338.70\", \"0.429\"], [\"70339.20\", \"0.464\"], [\"70339.60\", \"0.033\"], [\"70340.30\", \"0.003\"], [\"70340.70\", \"0.004\"], [\"70340.80\", \"0.000\"], [\"70341.80\", \"0.096\"], [\"70341.90\", \"0.001\"], [\"70342.00\", \"0.009\"], [\"70342.40\", \"0.000\"], [\"70342.50\", \"0.001\"], [\"70343.50\", \"0.003\"], [\"70344.70\", \"0.000\"], [\"70345.00\", \"0.212\"], [\"70345.10\", \"0.088\"], [\"70345.70\", \"0.279\"], [\"70346.00\", \"0.007\"], [\"70346.10\", \"1.039\"], [\"70346.20\", \"0.272\"], [\"70346.60\", \"0.003\"], [\"70348.00\", \"0.004\"], [\"70348.60\", \"0.085\"], [\"70348.70\", \"0.105\"], [\"70349.30\", \"0.657\"], [\"70349.40\", \"1.105\"], [\"70351.00\", \"0.179\"], [\"70352.10\", \"0.000\"], [\"70352.20\", \"0.000\"], [\"70352.30\", \"0.028\"], [\"70352.40\", \"0.003\"], [\"70352.50\", \"11.192\"]], \"a\": [[\"70352.60\", \"0.979\"], [\"70353.20\", \"0.002\"], [\"70353.80\", \"0.000\"], [\"70353.90\", \"0.000\"], [\"70354.00\", \"0.003\"], [\"70354.70\", \"0.006\"], [\"70354.90\", \"0.004\"], [\"70355.00\", \"0.032\"], [\"70355.80\", \"0.088\"], [\"70357.00\", \"0.444\"], [\"70357.10\", \"0.216\"], [\"70358.30\", \"0.003\"], [\"70358.50\", \"0.425\"], [\"70359.60\", \"0.030\"], [\"70360.20\", \"0.000\"], [\"70360.30\", \"0.216\"], [\"70360.50\", \"0.021\"], [\"70361.00\", \"0.107\"], [\"70361.30\", \"1.068\"], [\"70361.70\", \"0.000\"], [\"70362.50\", \"0.111\"], [\"70362.80\", \"0.138\"], [\"70363.10\", \"0.140\"], [\"70363.20\", \"0.092\"], [\"70363.50\", \"0.002\"], [\"70363.70\", \"0.000\"], [\"70363.80\", \"0.002\"], [\"70364.20\", \"0.017\"], [\"70364.90\", \"0.108\"], [\"70365.60\", \"0.001\"], [\"70368.90\", \"0.007\"], [\"70369.50\", \"0.004\"], [\"70370.10\", \"0.005\"], [\"70370.20\", \"0.645\"], [\"70371.10\", \"0.005\"], [\"70372.10\", \"0.359\"], [\"70372.90\", \"0.002\"], [\"70374.30\", \"0.272\"], [\"70382.90\", \"0.003\"], [\"70383.00\", \"0.005\"], [\"70383.60\", \"0.221\"], [\"70383.70\", \"0.011\"], [\"70384.20\", \"0.386\"], [\"70386.20\", \"0.234\"], [\"70389.20\", \"0.004\"], [\"70389.30\", \"0.000\"], [\"70389.90\", \"0.034\"], [\"70390.00\", \"0.004\"], [\"70394.80\", \"0.194\"], [\"70396.90\", \"0.005\"], [\"70397.40\", \"0.093\"], [\"70398.10\", \"0.005\"], [\"70400.80\", \"0.000\"], [\"70401.80\", \"0.084\"], [\"70409.70\", \"0.249\"], [\"70409.90\", \"2.017\"], [\"70410.60\", \"0.004\"], [\"70410.90\", \"0.161\"], [\"70411.10\", \"0.017\"], [\"70413.50\", \"0.000\"], [\"70414.70\", \"0.329\"], [\"70417.30\", \"0.031\"], [\"70417.60\", \"0.608\"], [\"70420.90\", \"0.002\"], [\"70429.30\", \"0.073\"], [\"70436.30\", \"1.573\"], [\"70437.00\", \"0.241\"], [\"70443.40\", \"0.077\"], [\"70443.70\", \"1.669\"], [\"70449.90\", \"0.000\"], [\"70451.50\", \"0.002\"], [\"70452.50\", \"0.000\"], [\"70542.90\", \"0.003\"], [\"70546.40\", \"0.000\"], [\"70650.30\", \"0.194\"], [\"70650.80\", \"0.211\"], [\"71056.10\", \"0.000\"]]}", "symbol": "BTCUSDT"}
{"event": "depthUpdate", "raw_payload": "{\"e\": \"depthUpdate\", \"E\": 1773246385458, \"T\": 1773246385457, \"s\": \"BTCUSDT\", \"U\": 10089703839775, \"u\": 10089703845299, \"pu\": 10089703839746, \"b\": [[\"1000.00\", \"26.792\"], [\"5000.00\", \"101.418\"], [\"19852.50\", \"0.200\"], [\"19948.60\", \"0.300\"], [\"19952.50\", \"0.200\"], [\"20048.60\", \"0.780\"], [\"20252.50\", \"0.090\"], [\"66818.80\", \"0.002\"], [\"66831.00\", \"0.002\"], [\"69649.00\", \"0.052\"], [\"70278.60\", \"0.087\"], [\"70284.20\", \"0.177\"], [\"70300.80\", \"0.000\"], [\"70301.50\", \"0.045\"], [\"70301.90\", \"0.006\"], [\"70302.20\", \"0.003\"], [\"70307.30\", \"0.085\"], [\"70307.40\", \"0.002\"], [\"70313.40\", \"0.011\"], [\"70315.20\", \"0.066\"], [\"70329.70\", \"0.009\"], [\"70330.20\", \"0.511\"], [\"70331.50\", \"0.185\"], [\"70334.50\", \"0.007\"], [\"70334.90\", \"0.054\"], [\"70336.60\", \"0.317\"], [\"70337.20\", \"0.049\"], [\"70337.30\", \"0.309\"], [\"70337.50\", \"0.002\"], [\"70338.50\", \"0.000\"], [\"70340.20\", \"0.002\"], [\"70341.00\", \"0.078\"], [\"70342.30\", \"0.000\"], [\"70343.60\", \"0.003\"], [\"70346.00\", \"0.002\"], [\"70347.70\", \"0.002\"], [\"70348.60\", \"0.018\"], [\"70349.30\", \"0.657\"], [\"70351.10\", \"0.003\"], [\"70351.50\", \"0.000\"], [\"70351.90\", \"0.004\"], [\"70352.30\", \"0.000\"], [\"70352.40\", \"0.001\"], [\"70352.50\", \"5.504\"]], \"a\": [[\"70352.60\", \"0.983\"], [\"70353.30\", \"0.002\"], [\"70354.40\", \"0.005\"], [\"70355.70\", \"0.029\"], [\"70357.00\", \"0.008\"], [\"70358.50\", \"0.000\"], [\"70358.60\", \"0.455\"], [\"70359.60\", \"0.355\"], [\"70359.70\", \"0.006\"], [\"70360.20\", \"0.213\"], [\"70360.30\", \"0.439\"], [\"70360.50\", \"0.010\"], [\"70360.90\", \"0.007\"], [\"70361.00\", \"0.107\"], [\"70361.30\", \"1.281\"], [\"70363.20\", \"0.008\"], [\"70364.90\", \"0.188\"], [\"70368.60\", \"0.336\"], [\"70369.10\", \"0.375\"], [\"70374.10\", \"1.005\"], [\"70374.60\", \"0.072\"], [\"70375.90\", \"0.001\"], [\"70382.90\", \"0.003\"], [\"70383.00\", \"0.005\"], [\"70383.60\", \"0.221\"], [\"70383.70\", \"0.011\"], [\"70385.00\", \"0.032\"], [\"70385.10\", \"0.847\"], [\"70385.30\", \"0.002\"], [\"70385.70\", \"0.002\"], [\"70385.80\", \"0.015\"], [\"70386.40\", \"0.040\"], [\"70387.40\", \"0.294\"], [\"70391.90\", \"0.277\"], [\"70396.30\", \"0.088\"], [\"70398.40\", \"0.252\"], [\"70399.00\", \"0.110\"], [\"70401.80\", \"0.000\"], [\"70409.00\", \"0.051\"], [\"70419.40\", \"0.000\"], [\"70421.40\", \"0.006\"], [\"70427.00\", \"0.004\"], [\"70429.80\", \"0.000\"], [\"70430.80\", \"0.000\"], [\"70431.70\", \"0.003\"], [\"70437.00\", \"0.000\"], [\"70487.50\", \"0.152\"], [\"70487.60\", \"0.041\"], [\"70527.60\", \"0.000\"], [\"70544.90\", \"0.054\"], [\"70545.10\", \"0.003\"], [\"70548.60\", \"0.002\"], [\"70560.80\", \"0.002\"], [\"70587.30\", \"0.009\"], [\"70599.30\", \"0.162\"], [\"70609.00\", \"0.002\"], [\"70647.70\", \"0.003\"], [\"70888.80\", \"0.299\"], [\"71430.90\", \"0.000\"], [\"71707.80\", \"0.684\"], [\"73166.70\", \"1.640\"], [\"73893.30\", \"0.002\"], [\"89523.20\", \"0.000\"]]}", "symbol": "BTCUSDT"}
{"event": "depthUpdate", "raw_payload": "{\"e\": \"depthUpdate\", \"E\": 1773246385560, \"T\": 1773246385559, \"s\": \"BTCUSDT\", \"U\": 10089703845381, \"u\": 10089703874192, \"pu\": 10089703845299, \"b\": [[\"5000.00\", \"101.418\"], [\"19848.60\", \"1.310\"], [\"19848.70\", \"0.000\"], [\"19849.30\", \"0.010\"], [\"19851.00\", \"0.010\"], [\"19852.20\", \"0.010\"], [\"19852.50\", \"0.230\"], [\"19853.40\", \"0.020\"], [\"19854.60\", \"0.010\"], [\"19854.80\", \"0.010\"], [\"19855.60\", \"0.010\"], [\"19948.60\", \"0.210\"], [\"19952.50\", \"0.240\"], [\"19953.40\", \"0.020\"], [\"19954.60\", \"0.010\"], [\"19955.60\", \"0.010\"], [\"20048.60\", \"0.700\"], [\"20252.50\", \"0.130\"], [\"20253.40\", \"0.020\"], [\"20254.60\", \"0.010\"], [\"20255.60\", \"0.010\"], [\"66806.40\", \"0.002\"], [\"67494.00\", \"0.000\"], [\"69229.00\", \"0.000\"], [\"69348.20\", \"0.359\"], [\"69348.60\", \"0.000\"], [\"69348.70\", \"0.002\"], [\"69349.30\", \"0.000\"], [\"69351.00\", \"0.870\"], [\"69352.50\", \"1.029\"], [\"69353.40\", \"0.018\"], [\"69354.60\", \"0.019\"], [\"69354.90\", \"0.872\"], [\"69370.70\", \"1.583\"], [\"69421.60\", \"0.013\"], [\"69649.00\", \"0.052\"], [\"69652.00\", \"0.002\"], [\"69822.60\", \"0.008\"], [\"69823.20\", \"0.000\"], [\"70056.20\", \"0.007\"], [\"70114.80\", \"0.000\"], [\"70140.60\", \"0.002\"], [\"70170.70\", \"0.000\"], [\"70228.00\", \"0.089\"], [\"70235.70\", \"0.000\"], [\"70237.80\", \"0.097\"], [\"70246.10\", \"0.207\"], [\"70250.90\", \"0.145\"], [\"70254.50\", \"0.098\"], [\"70256.00\", \"0.000\"], [\"70259.00\", \"2.364\"], [\"70259.10\", \"0.122\"], [\"70259.60\", \"0.220\"], [\"70260.00\", \"0.174\"], [\"70261.30\", \"0.016\"], [\"70262.40\", \"0.019\"], [\"70263.90\", \"0.389\"], [\"70266.00\", \"0.894\"], [\"70266.40\", \"1.284\"], [\"70268.50\", \"0.006\"], [\"70271.20\", \"0.000\"], [\"70272.30\", \"0.022\"], [\"70275.30\", \"0.006\"], [\"70278.20\", \"0.195\"], [\"70278.60\", \"0.003\"], [\"70279.70\", \"0.003\"], [\"70280.50\", \"0.564\"], [\"70280.70\", \"0.000\"], [\"70281.70\", \"0.031\"], [\"70281.80\", \"0.073\"], [\"70282.00\", \"0.008\"], [\"70282.10\", \"0.002\"], [\"70282.50\", \"0.178\"], [\"70282.60\", \"0.344\"], [\"70283.00\", \"0.269\"], [\"70283.80\", \"0.003\"], [\"70286.60\", \"0.005\"], [\"70287.50\", \"0.004\"], [\"70289.20\", \"0.000\"], [\"70290.10\", \"0.002\"], [\"70291.10\", \"0.527\"], [\"70291.20\", \"0.210\"], [\"70291.30\", \"0.001\"], [\"70292.40\", \"0.102\"], [\"70292.70\", \"0.003\"], [\"70292.80\", \"0.004\"], [\"70293.60\", \"0.009\"], [\"70294.40\", \"0.018\"], [\"70294.80\", \"0.395\"], [\"70297.40\", \"0.000\"], [\"70299.10\", \"0.000\"], [\"70299.40\", \"0.103\"], [\"70299.50\", \"0.120\"], [\"70301.90\", \"0.004\"], [\"70302.10\", \"0.002\"], [\"70302.20\", \"0.003\"], [\"70302.40\", \"0.003\"], [\"70302.50\", \"0.004\"], [\"70302.60\", \"0.004\"], [\"70302.90\", \"0.028\"], [\"70303.00\", \"0.349\"], [\"70304.60\", \"0.121\"], [\"70305.00\", \"0.103\"], [\"70305.30\", \"0.306\"], [\"70306.10\", \"0.203\"], [\"70306.60\", \"0.000\"], [\"70306.70\", \"0.005\"], [\"70307.30\", \"0.085\"], [\"70307.50\", \"0.014\"], [\"70307.70\", \"0.007\"], [\"70308.20\", \"0.711\"], [\"70308.70\", \"0.006\"], [\"70308.90\", \"0.547\"], [\"70309.70\", \"0.000\"], [\"70309.80\", \"0.005\"], [\"70309.90\", \"0.021\"], [\"70310.20\", \"0.002\"], [\"70310.50\", \"0.003\"], [\"70310.70\", \"0.117\"], [\"70311.10\", \"0.007\"], [\"70311.80\", \"0.025\"], [\"70311.90\", \"0.028\"], [\"70312.00\", \"0.043\"], [\"70312.30\", \"0.010\"], [\"70312.50\", \"0.575\"], [\"70313.10\", \"0.200\"], [\"70315.10\", \"0.033\"], [\"70315.90\", \"0.103\"], [\"70316.10\", \"0.002\"], [\"70316.50\", \"0.006\"], [\"70316.60\", \"0.002\"], [\"70317.70\", \"0.000\"], [\"70319.80\", \"0.514\"], [\"70319.90\", \"0.002\"], [\"70320.30\", \"0.259\"], [\"70320.50\", \"0.002\"], [\"70320.60\", \"0.002\"], [\"70320.90\", \"0.035\"], [\"70321.10\", \"0.087\"], [\"70321.20\", \"0.000\"], [\"70321.30\", \"0.000\"], [\"70321.90\", \"0.002\"], [\"70322.00\", \"0.011\"], [\"70322.10\", \"0.246\"], [\"70322.30\", \"0.592\"], [\"70322.40\", \"0.250\"], [\"70322.60\", \"0.000\"], [\"70322.70\", \"0.007\"], [\"70323.20\", \"0.022\"], [\"70323.30\", \"0.011\"], [\"70323.40\", \"0.243\"], [\"70323.50\", \"0.037\"], [\"70324.00\", \"0.002\"], [\"70324.10\", \"0.006\"], [\"70324.30\", \"0.377\"], [\"70324.70\", \"0.040\"], [\"70324.80\", \"0.003\"], [\"70325.20\", \"0.191\"], [\"70325.30\", \"0.075\"], [\"70325.40\", \"0.651\"], [\"70325.50\", \"0.099\"], [\"70326.20\", \"0.098\"], [\"70326.40\", \"0.089\"], [\"70326.60\", \"0.000\"], [\"70327.50\", \"0.030\"], [\"70327.60\", \"0.000\"], [\"70328.20\", \"0.003\"], [\"70328.30\", \"0.005\"], [\"70328.40\", \"0.002\"], [\"70328.80\", \"0.002\"], [\"70328.90\", \"0.004\"], [\"70329.00\", \"0.015\"], [\"70329.10\", \"0.342\"], [\"70330.20\", \"0.000\"], [\"70330.70\", \"0.006\"], [\"70330.80\", \"0.000\"], [\"70331.40\", \"0.115\"], [\"70331.60\", \"0.563\"], [\"70331.90\", \"0.005\"], [\"70332.00\", \"0.003\"], [\"70332.10\", \"0.006\"], [\"70332.20\", \"0.266\"], [\"70332.30\", \"0.005\"], [\"70332.40\", \"0.089\"], [\"70332.50\", \"0.027\"], [\"70332.70\", \"0.000\"], [\"70332.80\", \"0.000\"], [\"70333.00\", \"0.000\"], [\"70333.40\", \"0.012\"], [\"70333.50\", \"0.175\"], [\"70333.70\", \"0.037\"], [\"70333.80\", \"0.010\"], [\"70334.10\", \"0.205\"], [\"70334.40\", \"0.000\"], [\"70334.50\", \"0.009\"], [\"70334.60\", \"0.000\"], [\"70334.80\", \"0.000\"], [\"70334.90\", \"0.003\"], [\"70335.00\", \"0.012\"], [\"70335.10\", \"0.680\"], [\"70335.30\", \"0.518\"], [\"70335.40\", \"0.515\"], [\"70335.60\", \"0.000\"], [\"70335.70\", \"0.047\"], [\"70335.80\", \"0.116\"], [\"70335.90\", \"1.069\"], [\"70336.00\", \"0.009\"], [\"70336.10\", \"0.005\"], [\"70336.20\", \"0.325\"], [\"70336.40\", \"0.002\"], [\"70336.50\", \"0.488\"], [\"70336.60\", \"0.314\"], [\"70336.70\", \"0.005\"], [\"70337.00\", \"0.002\"], [\"70337.10\", \"0.028\"], [\"70337.20\", \"0.021\"], [\"70337.30\", \"0.307\"], [\"70337.40\", \"0.016\"], [\"70337.50\", \"0.002\"], [\"70337.60\", \"0.018\"], [\"70337.70\", \"0.002\"], [\"70338.00\", \"0.005\"], [\"70338.10\", \"0.041\"], [\"70338.20\", \"0.001\"], [\"70338.30\", \"0.099\"], [\"70338.50\", \"0.007\"], [\"70338.60\", \"1.211\"], [\"70338.90\", \"0.002\"], [\"70339.10\", \"0.000\"], [\"70339.20\", \"0.004\"], [\"70339.30\", \"0.012\"], [\"70339.60\", \"0.032\"], [\"70339.70\", \"0.000\"], [\"70339.80\", \"0.034\"], [\"70339.90\", \"0.000\"], [\"70340.10\", \"0.002\"], [\"70340.20\", \"0.002\"], [\"70340.30\", \"0.003\"], [\"70340.40\", \"0.007\"], [\"70340.70\", \"0.004\"], [\"70340.80\", \"0.071\"], [\"70340.90\", \"0.347\"], [\"70341.00\", \"0.071\"], [\"70341.10\", \"0.009\"], [\"70341.30\", \"0.639\"], [\"70341.50\", \"0.057\"], [\"70341.60\", \"0.069\"], [\"70341.70\", \"0.005\"], [\"70341.80\", \"0.181\"], [\"70341.90\", \"0.015\"], [\"70342.00\", \"0.100\"], [\"70342.20\", \"0.000\"], [\"70342.30\", \"0.053\"], [\"70342.40\", \"0.043\"], [\"70342.50\", \"0.003\"], [\"70342.80\", \"0.004\"], [\"70343.10\", \"0.006\"], [\"70343.20\", \"0.004\"], [\"70343.40\", \"0.001\"], [\"70343.50\", \"0.000\"], [\"70343.70\", \"0.118\"], [\"70344.00\", \"0.000\"], [\"70344.10\", \"0.005\"], [\"70344.20\", \"0.001\"], [\"70344.30\", \"0.125\"], [\"70344.40\", \"0.142\"], [\"70344.50\", \"0.004\"], [\"70345.40\", \"0.464\"], [\"70345.60\", \"0.002\"], [\"70345.70\", \"0.000\"], [\"70345.80\", \"0.001\"], [\"70346.00\", \"0.049\"], [\"70346.10\", \"0.039\"], [\"70346.20\", \"0.175\"], [\"70346.30\", \"0.093\"], [\"70346.50\", \"0.019\"], [\"70346.60\", \"0.003\"], [\"70347.10\", \"0.113\"], [\"70347.20\", \"0.001\"], [\"70347.30\", \"0.086\"], [\"70347.70\", \"0.007\"], [\"70348.00\", \"0.006\"], [\"70348.10\", \"0.000\"], [\"70348.40\", \"0.000\"], [\"70348.60\", \"0.013\"], [\"70348.80\", \"0.206\"], [\"70348.90\", \"0.206\"], [\"70349.30\", \"0.002\"], [\"70349.40\", \"0.008\"], [\"70349.50\", \"1.408\"], [\"70349.60\", \"0.002\"], [\"70350.00\", \"0.006\"], [\"70350.10\", \"0.001\"], [\"70350.40\", \"0.001\"], [\"70350.60\", \"0.003\"], [\"70351.00\", \"0.043\"], [\"70351.10\", \"0.000\"], [\"70351.30\", \"0.000\"], [\"70351.90\", \"0.004\"], [\"70352.20\", \"0.003\"], [\"70352.40\", \"0.000\"], [\"70352.50\", \"0.063\"], [\"70352.60\", \"0.000\"], [\"70352.70\", \"0.000\"], [\"70352.90\", \"0.062\"], [\"70353.00\", \"0.535\"], [\"70353.10\", \"0.000\"], [\"70353.20\", \"0.000\"], [\"70353.30\", \"0.001\"], [\"70353.40\", \"0.053\"], [\"70353.50\", \"1.931\"], [\"70353.60\", \"0.000\"], [\"70353.90\", \"0.000\"], [\"70354.10\", \"0.002\"], [\"70354.20\", \"0.001\"], [\"70354.30\", \"0.000\"], [\"70354.40\", \"0.000\"], [\"70354.50\", \"0.087\"], [\"70354.60\", \"0.255\"], [\"70354.70\", \"0.003\"], [\"70354.80\", \"0.001\"], [\"70354.90\", \"0.641\"], [\"70355.00\", \"0.000\"], [\"70355.10\", \"0.000\"], [\"70355.30\", \"0.432\"], [\"70355.50\", \"0.087\"], [\"70355.60\", \"10.755\"]], \"a\": [[\"70352.60\", \"0.000\"], [\"70352.70\", \"0.000\"], [\"70352.80\", \"0.000\"], [\"70353.00\", \"0.000\"], [\"70353.10\", \"0.000\"], [\"70353.20\", \"0.000\"], [\"70353.30\", \"0.000\"], [\"70353.50\", \"0.000\"], [\"70353.70\", \"0.000\"], [\"70354.00\", \"0.000\"], [\"70354.20\", \"0.000\"], [\"70354.40\", \"0.000\"], [\"70354.50\", \"0.000\"], [\"70354.70\", \"0.000\"], [\"70354.90\", \"0.000\"], [\"70355.00\", \"0.000\"], [\"70355.10\", \"0.000\"], [\"70355.40\", \"0.000\"], [\"70355.50\", \"0.000\"], [\"70355.60\", \"0.000\"], [\"70355.70\", \"0.033\"], [\"70355.80\", \"0.087\"], [\"70355.90\", \"0.018\"], [\"70356.30\", \"0.006\"], [\"70356.50\", \"0.002\"], [\"70356.60\", \"0.004\"], [\"70356.90\", \"0.003\"], [\"70357.00\", \"0.004\"], [\"70357.10\", \"0.000\"], [\"70357.20\", \"0.002\"], [\"70357.60\", \"0.005\"], [\"70357.70\", \"0.000\"], [\"70358.20\", \"0.000\"], [\"70358.40\", \"0.000\"], [\"70358.50\", \"0.002\"], [\"70358.60\", \"0.004\"], [\"70358.70\", \"0.003\"], [\"70359.00\", \"0.000\"], [\"70359.10\", \"0.002\"], [\"70359.60\", \"0.002\"], [\"70359.70\", \"0.006\"], [\"70359.90\", \"0.002\"], [\"70360.10\", \"0.003\"], [\"70360.20\", \"0.000\"], [\"70360.30\", \"0.003\"], [\"70360.40\", \"0.000\"], [\"70360.50\", \"0.004\"], [\"70360.70\", \"0.002\"], [\"70360.90\", \"0.007\"], [\"70361.00\", \"0.001\"], [\"70361.10\", \"0.000\"], [\"70361.30\", \"0.002\"], [\"70361.80\", \"0.015\"], [\"70362.20\", \"0.007\"], [\"70362.30\", \"0.001\"], [\"70362.40\", \"0.002\"], [\"70362.50\", \"0.000\"], [\"70362.60\", \"0.000\"], [\"70362.70\", \"0.251\"], [\"70362.90\", \"0.000\"], [\"70363.00\", \"0.003\"], [\"70363.10\", \"0.000\"], [\"70363.20\", \"0.003\"], [\"70363.30\", \"0.007\"], [\"70363.50\", \"0.113\"], [\"70363.60\", \"0.001\"], [\"70363.70\", \"0.000\"], [\"70363.80\", \"0.000\"], [\"70363.90\", \"0.005\"], [\"70364.00\", \"0.006\"], [\"70364.20\", \"0.000\"], [\"70364.30\", \"0.001\"], [\"70364.40\", \"0.000\"], [\"70364.50\", \"0.121\"], [\"70364.60\", \"0.003\"], [\"70364.70\", \"0.002\"], [\"70364.80\", \"0.345\"], [\"70364.90\", \"0.063\"], [\"70365.10\", \"0.015\"], [\"70365.20\", \"0.000\"], [\"70365.40\", \"0.003\"], [\"70365.50\", \"0.000\"], [\"70365.60\", \"0.001\"], [\"70366.00\", \"0.004\"], [\"70366.10\", \"0.309\"], [\"70366.30\", \"0.011\"], [\"70366.40\", \"0.004\"], [\"70366.50\", \"0.004\"], [\"70366.60\", \"0.005\"], [\"70366.70\", \"0.006\"], [\"70366.90\", \"0.003\"], [\"70367.00\", \"0.002\"], [\"70367.10\", \"0.513\"], [\"70367.20\", \"50.006\"], [\"70367.30\", \"0.006\"], [\"70367.40\", \"0.008\"], [\"70368.00\", \"0.003\"], [\"70368.10\", \"0.007\"], [\"70368.30\", \"0.102\"], [\"70368.40\", \"0.102\"], [\"70368.60\", \"0.216\"], [\"70369.00\", \"0.038\"], [\"70369.10\", \"0.000\"], [\"70369.20\", \"0.002\"], [\"70369.40\", \"0.004\"], [\"70369.60\", \"0.002\"], [\"70369.80\", \"0.005\"], [\"70369.90\", \"0.002\"], [\"70370.10\", \"0.005\"], [\"70370.20\", \"0.000\"], [\"70370.60\", \"0.002\"], [\"70370.70\", \"0.000\"], [\"70370.80\", \"0.002\"], [\"70370.90\", \"0.003\"], [\"70371.20\", \"0.005\"], [\"70371.50\", \"0.002\"], [\"70371.60\", \"0.085\"], [\"70371.70\", \"0.070\"], [\"70371.80\", \"0.002\"], [\"70372.20\", \"0.006\"], [\"70372.30\", \"0.204\"], [\"70372.50\", \"0.032\"], [\"70372.60\", \"0.002\"], [\"70372.70\", \"0.513\"], [\"70373.10\", \"0.000\"], [\"70373.20\", \"0.005\"], [\"70373.40\", \"0.007\"], [\"70373.50\", \"0.000\"], [\"70373.60\", \"0.003\"], [\"70373.70\", \"0.148\"], [\"70373.80\", \"0.002\"], [\"70374.00\", \"1.068\"], [\"70374.10\", \"0.005\"], [\"70374.40\", \"0.004\"], [\"70374.60\", \"0.000\"], [\"70374.70\", \"0.000\"], [\"70374.80\", \"0.511\"], [\"70374.90\", \"0.608\"], [\"70375.30\", \"0.000\"], [\"70375.60\", \"0.002\"], [\"70376.10\", \"0.012\"], [\"70376.20\", \"0.398\"], [\"70376.50\", \"0.013\"], [\"70376.70\", \"0.343\"], [\"70377.50\", \"1.194\"], [\"70377.60\", \"0.003\"], [\"70377.70\", \"0.070\"], [\"70377.80\", \"0.000\"], [\"70378.10\", \"0.094\"], [\"70378.30\", \"0.008\"], [\"70378.60\", \"0.000\"], [\"70378.80\", \"0.005\"], [\"70378.90\", \"0.455\"], [\"70379.00\", \"0.013\"], [\"70379.10\", \"0.187\"], [\"70379.30\", \"0.000\"], [\"70379.40\", \"0.005\"], [\"70379.50\", \"0.639\"], [\"70380.30\", \"0.000\"], [\"70380.40\", \"0.221\"], [\"70381.20\", \"0.073\"], [\"70381.30\", \"0.251\"], [\"70381.60\", \"0.000\"], [\"70381.70\", \"0.011\"], [\"70381.90\", \"0.003\"], [\"70382.00\", \"0.085\"], [\"70382.20\", \"0.000\"], [\"70383.40\", \"0.007\"], [\"70383.60\", \"0.212\"], [\"70383.70\", \"0.002\"], [\"70384.30\", \"0.020\"], [\"70384.40\", \"0.521\"], [\"70385.00\", \"0.034\"], [\"70385.10\", \"0.847\"], [\"70385.20\", \"0.005\"], [\"70385.30\", \"0.005\"], [\"70385.40\", \"0.019\"], [\"70385.70\", \"0.000\"], [\"70385.80\", \"0.084\"], [\"70386.00\", \"0.002\"], [\"70386.20\", \"0.234\"], [\"70386.40\", \"0.040\"], [\"70386.50\", \"0.000\"], [\"70387.10\", \"0.016\"], [\"70387.20\", \"0.009\"], [\"70387.40\", \"0.208\"], [\"70387.80\", \"0.004\"], [\"70387.90\", \"0.004\"], [\"70388.10\", \"0.000\"], [\"70388.50\", \"0.007\"], [\"70388.60\", \"0.005\"], [\"70388.70\", \"0.000\"], [\"70389.60\", \"0.028\"], [\"70389.90\", \"0.032\"], [\"70390.00\", \"0.000\"], [\"70390.20\", \"0.002\"], [\"70390.30\", \"0.511\"], [\"70390.50\", \"0.071\"], [\"70390.60\", \"0.003\"], [\"70390.70\", \"0.007\"], [\"70390.80\", \"0.052\"], [\"70391.20\", \"0.190\"], [\"70391.30\", \"0.002\"], [\"70391.40\", \"0.005\"], [\"70391.80\", \"0.000\"], [\"70391.90\", \"0.191\"], [\"70392.10\", \"0.025\"], [\"70392.70\", \"0.000\"], [\"70392.80\", \"0.383\"], [\"70392.90\", \"0.515\"], [\"70393.30\", \"0.003\"], [\"70393.40\", \"0.044\"], [\"70393.50\", \"0.004\"], [\"70393.60\", \"0.001\"], [\"70394.10\", \"0.002\"], [\"70394.30\", \"0.025\"], [\"70394.60\", \"0.001\"], [\"70396.30\", \"0.002\"], [\"70397.20\", \"0.000\"], [\"70398.40\", \"0.252\"], [\"70398.90\", \"0.047\"], [\"70399.00\", \"0.024\"], [\"70399.50\", \"0.511\"], [\"70399.60\", \"0.005\"], [\"70399.70\", \"0.008\"], [\"70400.00\", \"2.040\"], [\"70400.40\", \"0.004\"], [\"70401.30\", \"0.071\"], [\"70401.80\", \"0.084\"], [\"70402.30\", \"0.086\"], [\"70402.50\", \"0.061\"], [\"70402.60\", \"0.153\"], [\"70402.70\", \"0.086\"], [\"70404.20\", \"0.002\"], [\"70404.40\", \"0.006\"], [\"70404.70\", \"0.002\"], [\"70405.20\", \"0.003\"], [\"70405.30\", \"0.002\"], [\"70405.80\", \"0.027\"], [\"70406.30\", \"0.028\"], [\"70407.00\", \"0.040\"], [\"70407.70\", \"0.005\"], [\"70408.20\", \"0.588\"], [\"70408.50\", \"0.002\"], [\"70408.70\", \"0.002\"], [\"70409.00\", \"0.007\"], [\"70409.10\", \"0.092\"], [\"70409.20\", \"0.894\"], [\"70409.40\", \"0.000\"], [\"70409.70\", \"0.163\"], [\"70410.10\", \"0.000\"], [\"70410.40\", \"0.003\"], [\"70410.80\", \"0.030\"], [\"70410.90\", \"0.075\"], [\"70411.00\", \"0.011\"], [\"70411.70\", \"0.003\"], [\"70411.80\", \"0.004\"], [\"70412.00\", \"0.002\"], [\"70412.40\", \"0.000\"], [\"70412.70\", \"0.131\"], [\"70412.80\", \"0.195\"], [\"70412.90\", \"0.000\"], [\"70413.00\", \"1.309\"], [\"70413.30\", \"0.048\"], [\"70414.30\", \"0.000\"], [\"70414.70\", \"0.243\"], [\"70415.50\", \"0.002\"], [\"70415.60\", \"0.002\"], [\"70415.80\", \"0.000\"], [\"70416.60\", \"0.008\"], [\"70416.80\", \"0.279\"], [\"70416.90\", \"0.082\"], [\"70417.30\", \"0.031\"], [\"70417.50\", \"0.002\"], [\"70417.60\", \"0.522\"], [\"70418.60\", \"0.015\"], [\"70419.00\", \"0.101\"], [\"70419.10\", \"0.006\"], [\"70419.60\", \"1.069\"], [\"70420.30\", \"0.081\"], [\"70420.40\", \"0.143\"], [\"70420.50\", \"0.000\"], [\"70421.40\", \"0.006\"], [\"70421.50\", \"0.418\"], [\"70421.80\", \"0.000\"], [\"70422.10\", \"0.102\"], [\"70422.40\", \"0.003\"], [\"70422.50\", \"0.081\"], [\"70422.90\", \"0.000\"], [\"70423.20\", \"0.030\"], [\"70423.40\", \"0.269\"], [\"70423.50\", \"0.000\"], [\"70423.80\", \"0.002\"], [\"70424.20\", \"0.039\"], [\"70424.40\", \"0.199\"], [\"70425.40\", \"0.004\"], [\"70425.60\", \"0.005\"], [\"70426.30\", \"0.002\"], [\"70426.40\", \"0.000\"], [\"70426.60\", \"0.002\"], [\"70426.70\", \"0.000\"], [\"70426.90\", \"0.002\"], [\"70427.00\", \"0.004\"], [\"70427.30\", \"0.198\"], [\"70428.30\", \"0.076\"], [\"70429.30\", \"0.073\"], [\"70430.20\", \"0.049\"], [\"70430.30\", \"0.000\"], [\"70430.40\", \"0.047\"], [\"70431.20\", \"0.010\"], [\"70431.80\", \"0.096\"], [\"70432.20\", \"1.068\"], [\"70433.00\", \"0.004\"], [\"70433.20\", \"0.387\"], [\"70434.10\", \"0.002\"], [\"70435.10\", \"0.002\"], [\"70435.60\", \"0.444\"], [\"70435.80\", \"0.120\"], [\"70435.90\", \"0.107\"], [\"70436.20\", \"0.002\"], [\"70436.60\", \"0.002\"], [\"70436.80\", \"0.599\"], [\"70437.00\", \"0.000\"], [\"70437.30\", \"0.324\"], [\"70437.40\", \"0.003\"], [\"70437.50\", \"2.115\"], [\"70437.80\", \"0.006\"], [\"70437.90\", \"0.050\"], [\"70438.00\", \"0.086\"], [\"70440.50\", \"0.004\"], [\"70440.80\", \"0.086\"], [\"70441.50\", \"0.000\"], [\"70441.60\", \"0.000\"], [\"70441.70\", \"0.085\"], [\"70443.70\", \"1.515\"], [\"70444.70\", \"0.198\"], [\"70444.80\", \"1.705\"], [\"70445.40\", \"0.002\"], [\"70445.60\", \"0.086\"], [\"70446.20\", \"0.007\"], [\"70446.50\", \"0.000\"], [\"70446.80\", \"0.009\"], [\"70446.90\", \"1.342\"], [\"70447.40\", \"0.000\"], [\"70447.70\", \"0.005\"], [\"70447.80\", \"0.176\"], [\"70447.90\", \"0.004\"], [\"70448.00\", \"0.007\"], [\"70448.20\", \"0.000\"], [\"70448.40\", \"0.002\"], [\"70448.70\", \"0.002\"], [\"70448.90\", \"0.039\"], [\"70449.30\", \"0.000\"], [\"70449.40\", \"0.002\"], [\"70449.90\", \"0.000\"], [\"70450.00\", \"0.791\"], [\"70450.30\", \"0.000\"], [\"70451.30\", \"0.342\"], [\"70451.60\", \"0.086\"], [\"70453.00\", \"10.312\"], [\"70454.40\", \"0.096\"], [\"70454.70\", \"0.000\"], [\"70455.00\", \"0.002\"], [\"70455.10\", \"0.000\"], [\"70455.60\", \"0.000\"], [\"70456.00\", \"0.173\"], [\"70457.00\", \"0.016\"], [\"70458.00\", \"0.019\"], [\"70460.30\", \"0.002\"], [\"70461.20\", \"0.000\"], [\"70463.20\", \"0.000\"], [\"70464.20\", \"0.000\"], [\"70465.40\", \"0.595\"], [\"70466.50\", \"0.129\"], [\"70467.40\", \"0.000\"], [\"70468.20\", \"0.519\"], [\"70468.50\", \"0.395\"], [\"70469.70\", \"0.085\"], [\"70470.20\", \"0.176\"], [\"70470.50\", \"0.000\"], [\"70471.20\", \"0.083\"], [\"70471.60\", \"0.154\"], [\"70472.20\", \"0.000\"], [\"70472.40\", \"0.169\"], [\"70472.50\", \"0.156\"], [\"70472.70\", \"0.085\"], [\"70473.10\", \"0.177\"], [\"70474.10\", \"0.000\"], [\"70474.40\", \"0.085\"], [\"70474.60\", \"0.002\"], [\"70475.10\", \"0.042\"], [\"70475.70\", \"0.173\"], [\"70476.20\", \"0.000\"], [\"70478.00\", \"0.090\"], [\"70478.60\", \"0.044\"], [\"70479.30\", \"0.003\"], [\"70479.80\", \"0.003\"], [\"70480.40\", \"0.083\"], [\"70480.50\", \"0.002\"], [\"70481.80\", \"0.511\"], [\"70483.60\", \"0.001\"], [\"70483.90\", \"0.125\"], [\"70484.00\", \"0.002\"], [\"70485.10\", \"0.228\"], [\"70485.30\", \"0.079\"], [\"70485.40\", \"0.117\"], [\"70488.40\", \"0.003\"], [\"70489.80\", \"0.000\"], [\"70490.80\", \"0.004\"], [\"70491.80\", \"0.379\"], [\"70492.70\", \"0.050\"], [\"70493.70\", \"0.000\"], [\"70494.70\", \"1.395\"], [\"70495.70\", \"0.003\"], [\"70499.50\", \"0.802\"], [\"70499.90\", \"10.091\"], [\"70500.70\", \"0.007\"], [\"70501.20\", \"0.002\"], [\"70502.40\", \"0.009\"], [\"70505.00\", \"0.079\"], [\"70507.70\", \"0.004\"], [\"70509.40\", \"0.007\"], [\"70514.70\", \"0.000\"], [\"70516.40\", \"0.009\"], [\"70521.70\", \"0.006\"], [\"70523.40\", \"0.009\"], [\"70524.20\", \"0.081\"], [\"70524.40\", \"0.081\"], [\"70527.00\", \"0.081\"], [\"70528.50\", \"0.161\"], [\"70528.70\", \"0.000\"], [\"70528.80\", \"0.286\"], [\"70530.40\", \"0.009\"], [\"70531.20\", \"0.081\"], [\"70532.60\", \"0.122\"], [\"70534.90\", \"0.233\"], [\"70535.70\", \"0.000\"], [\"70537.40\", \"0.009\"], [\"70538.20\", \"0.081\"], [\"70539.20\", \"0.039\"], [\"70540.90\", \"0.592\"], [\"70542.70\", \"0.093\"], [\"70544.40\", \"0.009\"], [\"70544.80\", \"0.036\"], [\"70546.50\", \"0.081\"], [\"70549.70\", \"0.002\"], [\"70551.40\", \"0.008\"], [\"70551.90\", \"0.271\"], [\"70555.30\", \"6.589\"], [\"70557.50\", \"0.103\"], [\"70566.60\", \"0.011\"], [\"70613.20\", \"0.000\"], [\"70617.70\", \"0.002\"], [\"70651.30\", \"0.186\"], [\"70840.00\", \"0.546\"], [\"70882.00\", \"0.004\"], [\"70883.60\", \"0.000\"], [\"70884.30\", \"0.000\"], [\"71056.10\", \"0.000\"], [\"71059.30\", \"1.407\"], [\"76645.60\", \"0.000\"], [\"76821.80\", \"0.000\"], [\"76998.00\", \"0.344\"]]}", "symbol": "BTCUSDT"}
{"event": "depthUpdate", "raw_payload": "{\"e\": \"depthUpdate\", \"E\": 1773246385662, \"T\": 1773246385661, \"s\": \"BTCUSDT\", \"U\": 10089703874247, \"u\": 10089703913136, \"pu\": 10089703874192, \"b\": [[\"1000.00\", \"26.942\"], [\"5000.00\", \"101.438\"], [\"19848.60\", \"1.230\"], [\"19855.60\", \"0.030\"], [\"19855.70\", \"0.030\"], [\"19861.10\", \"0.010\"], [\"19861.20\", \"0.020\"], [\"19948.60\", \"0.130\"], [\"19955.60\", \"0.030\"], [\"19955.70\", \"0.030\"], [\"19960.10\", \"0.010\"], [\"19961.10\", \"0.010\"], [\"19961.20\", \"0.010\"], [\"20048.60\", \"0.620\"], [\"20255.60\", \"0.040\"], [\"20255.70\", \"0.020\"], [\"20260.10\", \"0.010\"], [\"20261.10\", \"0.010\"], [\"20261.20\", \"0.010\"], [\"66806.40\", \"0.000\"], [\"66823.20\", \"0.002\"], [\"69351.00\", \"0.866\"], [\"69352.20\", \"0.004\"], [\"69352.50\", \"1.027\"], [\"69361.10\", \"0.012\"], [\"69361.20\", \"0.010\"], [\"69597.80\", \"0.002\"], [\"69652.00\", \"0.000\"], [\"69977.60\", \"0.000\"], [\"69989.30\", \"0.002\"], [\"69990.20\", \"0.000\"], [\"69996.90\", \"0.000\"], [\"70049.60\", \"0.003\"], [\"70052.40\", \"0.151\"], [\"70058.60\", \"0.000\"], [\"70062.90\", \"0.298\"], [\"70145.10\", \"0.008\"], [\"70146.10\", \"0.012\"], [\"70153.30\", \"0.002\"], [\"70160.30\", \"0.011\"], [\"70182.10\", \"0.010\"], [\"70183.70\", \"0.000\"], [\"70192.80\", \"0.000\"], [\"70194.40\", \"0.010\"], [\"70196.80\", \"0.000\"], [\"70221.00\", \"0.080\"], [\"70223.70\", \"0.716\"], [\"70225.80\", \"0.000\"], [\"70226.80\", \"0.009\"], [\"70227.60\", \"0.000\"], [\"70228.20\", \"0.002\"], [\"70232.00\", \"11.633\"], [\"70239.90\", \"0.005\"], [\"70241.80\", \"0.195\"], [\"70242.00\", \"0.472\"], [\"70242.70\", \"0.028\"], [\"70245.40\", \"0.000\"], [\"70248.40\", \"0.216\"], [\"70250.70\", \"0.081\"], [\"70251.20\", \"0.000\"], [\"70253.30\", \"2.000\"], [\"70256.80\", \"0.588\"], [\"70258.70\", \"0.082\"], [\"70260.00\", \"0.172\"], [\"70260.40\", \"0.473\"], [\"70260.70\", \"0.000\"], [\"70262.40\", \"0.005\"], [\"70263.60\", \"0.617\"], [\"70263.80\", \"1.341\"], [\"70263.90\", \"0.257\"], [\"70264.60\", \"0.023\"], [\"70264.90\", \"0.002\"], [\"70265.00\", \"0.064\"], [\"70265.30\", \"0.000\"], [\"70266.00\", \"0.891\"], [\"70266.70\", \"0.002\"], [\"70267.40\", \"1.782\"], [\"70267.90\", \"0.183\"], [\"70268.70\", \"0.257\"], [\"70269.00\", \"0.018\"], [\"70270.90\", \"0.000\"], [\"70272.30\", \"0.004\"], [\"70273.10\", \"6.534\"], [\"70273.60\", \"0.042\"], [\"70274.40\", \"0.071\"], [\"70274.90\", \"0.306\"], [\"70275.00\", \"10.370\"], [\"70275.10\", \"2.838\"], [\"70275.30\", \"0.006\"], [\"70275.40\", \"0.014\"], [\"70276.00\", \"0.002\"], [\"70276.50\", \"0.000\"], [\"70277.10\", \"0.009\"], [\"70277.60\", \"0.002\"], [\"70278.00\", \"0.522\"], [\"70278.20\", \"0.091\"], [\"70278.50\", \"0.083\"], [\"70278.60\", \"0.000\"], [\"70278.90\", \"0.002\"], [\"70279.90\", \"0.000\"], [\"70280.00\", \"1.427\"], [\"70280.50\", \"0.582\"], [\"70280.90\", \"0.390\"], [\"70281.40\", \"1.073\"], [\"70281.70\", \"0.003\"], [\"70281.80\", \"0.000\"], [\"70281.90\", \"1.155\"], [\"70282.00\", \"0.150\"], [\"70282.40\", \"0.061\"], [\"70282.50\", \"0.039\"], [\"70283.00\", \"0.218\"], [\"70283.80\", \"0.051\"], [\"70283.90\", \"0.002\"], [\"70284.00\", \"0.111\"], [\"70285.10\", \"0.047\"], [\"70285.50\", \"0.000\"], [\"70285.70\", \"1.342\"], [\"70285.80\", \"0.011\"], [\"70286.30\", \"0.016\"], [\"70286.60\", \"0.044\"], [\"70287.20\", \"0.302\"], [\"70287.50\", \"0.047\"], [\"70289.20\", \"0.004\"], [\"70289.70\", \"0.158\"], [\"70290.20\", \"0.031\"], [\"70291.00\", \"0.000\"], [\"70291.70\", \"0.117\"], [\"70291.80\", \"0.002\"], [\"70292.20\", \"1.090\"], [\"70292.70\", \"0.023\"], [\"70293.40\", \"0.003\"], [\"70294.00\", \"0.816\"], [\"70294.30\", \"0.403\"], [\"70294.80\", \"0.344\"], [\"70295.50\", \"1.392\"], [\"70295.80\", \"0.127\"], [\"70297.40\", \"0.851\"], [\"70298.50\", \"0.000\"], [\"70300.50\", \"1.066\"], [\"70301.30\", \"0.001\"], [\"70302.20\", \"0.000\"], [\"70302.40\", \"0.006\"], [\"70302.90\", \"0.276\"], [\"70303.00\", \"0.347\"], [\"70303.60\", \"1.810\"], [\"70303.90\", \"0.004\"], [\"70304.30\", \"0.533\"], [\"70304.50\", \"0.006\"], [\"70304.60\", \"0.010\"], [\"70305.00\", \"0.103\"], [\"70305.20\", \"0.101\"], [\"70305.60\", \"0.005\"], [\"70305.70\", \"0.007\"], [\"70306.00\", \"0.191\"], [\"70306.40\", \"0.013\"], [\"70306.50\", \"0.003\"], [\"70307.00\", \"0.003\"], [\"70307.30\", \"0.000\"], [\"70307.50\", \"0.002\"], [\"70307.60\", \"0.004\"], [\"70308.10\", \"0.004\"], [\"70308.20\", \"0.000\"], [\"70308.40\", \"0.038\"], [\"70308.80\", \"0.110\"], [\"70308.90\", \"0.540\"], [\"70309.00\", \"0.002\"], [\"70309.10\", \"0.209\"], [\"70309.40\", \"0.001\"], [\"70309.50\", \"0.000\"], [\"70309.90\", \"0.000\"], [\"70310.60\", \"0.511\"], [\"70310.90\", \"0.161\"], [\"70311.00\", \"0.000\"], [\"70311.20\", \"0.010\"], [\"70311.60\", \"0.003\"], [\"70311.70\", \"0.075\"], [\"70311.80\", \"0.126\"], [\"70311.90\", \"0.000\"], [\"70312.00\", \"0.014\"], [\"70312.30\", \"0.001\"], [\"70312.50\", \"0.006\"], [\"70312.60\", \"0.000\"], [\"70313.30\", \"0.002\"], [\"70313.40\", \"0.975\"], [\"70313.90\", \"0.711\"], [\"70314.50\", \"0.002\"], [\"70315.00\", \"0.089\"], [\"70315.10\", \"0.007\"], [\"70315.20\", \"0.577\"], [\"70315.30\", \"0.521\"], [\"70315.40\", \"1.078\"], [\"70316.00\", \"0.345\"], [\"70316.40\", \"0.001\"], [\"70318.70\", \"0.591\"], [\"70318.80\", \"0.232\"], [\"70319.30\", \"0.000\"], [\"70319.70\", \"0.044\"], [\"70320.00\", \"0.044\"], [\"70320.60\", \"0.008\"], [\"70320.80\", \"0.005\"], [\"70321.00\", \"0.048\"], [\"70322.00\", \"0.004\"], [\"70322.10\", \"0.235\"], [\"70322.40\", \"0.002\"], [\"70322.70\", \"0.014\"], [\"70322.90\", \"0.004\"], [\"70323.30\", \"0.002\"], [\"70323.40\", \"0.818\"], [\"70323.50\", \"0.041\"], [\"70323.70\", \"0.008\"], [\"70324.00\", \"0.002\"], [\"70324.10\", \"0.002\"], [\"70324.20\", \"0.491\"], [\"70324.30\", \"0.287\"], [\"70324.70\", \"0.040\"], [\"70324.80\", \"0.003\"], [\"70325.20\", \"0.200\"], [\"70325.30\", \"0.073\"], [\"70325.40\", \"0.655\"], [\"70325.50\", \"0.097\"], [\"70326.10\", \"0.053\"], [\"70326.20\", \"0.107\"], [\"70326.80\", \"0.000\"], [\"70326.90\", \"0.012\"], [\"70327.20\", \"0.045\"], [\"70327.50\", \"0.032\"], [\"70327.60\", \"0.002\"], [\"70328.10\", \"0.002\"], [\"70328.40\", \"0.006\"], [\"70328.90\", \"0.002\"], [\"70329.00\", \"0.013\"], [\"70329.10\", \"0.347\"], [\"70329.30\", \"0.335\"], [\"70329.60\", \"0.006\"], [\"70329.70\", \"0.011\"], [\"70329.80\", \"0.000\"], [\"70330.00\", \"0.090\"], [\"70330.40\", \"0.421\"], [\"70330.50\", \"0.412\"], [\"70330.70\", \"0.006\"], [\"70330.80\", \"0.191\"], [\"70331.00\", \"0.005\"], [\"70331.10\", \"0.004\"], [\"70331.20\", \"0.025\"], [\"70331.40\", \"0.113\"], [\"70331.50\", \"0.004\"], [\"70331.60\", \"0.511\"], [\"70331.70\", \"0.018\"], [\"70331.90\", \"0.086\"], [\"70332.70\", \"0.020\"], [\"70332.90\", \"0.381\"], [\"70333.40\", \"0.018\"], [\"70333.50\", \"0.002\"], [\"70333.80\", \"0.009\"], [\"70334.00\", \"0.003\"], [\"70334.50\", \"0.000\"], [\"70334.60\", \"0.000\"], [\"70334.70\", \"0.000\"], [\"70335.10\", \"0.000\"], [\"70335.20\", \"0.349\"], [\"70335.40\", \"0.004\"], [\"70335.50\", \"0.001\"], [\"70335.80\", \"0.013\"], [\"70335.90\", \"1.072\"], [\"70336.00\", \"0.009\"], [\"70336.20\", \"0.239\"], [\"70336.50\", \"0.004\"], [\"70336.80\", \"0.036\"], [\"70337.00\", \"0.000\"], [\"70337.10\", \"0.000\"], [\"70337.30\", \"0.310\"], [\"70337.40\", \"0.016\"], [\"70337.60\", \"0.018\"], [\"70338.10\", \"0.016\"], [\"70338.20\", \"0.053\"], [\"70338.30\", \"0.185\"], [\"70338.50\", \"0.000\"], [\"70338.60\", \"0.003\"], [\"70338.70\", \"0.006\"], [\"70338.80\", \"0.007\"], [\"70338.90\", \"0.513\"], [\"70339.00\", \"0.000\"], [\"70339.10\", \"0.000\"], [\"70339.40\", \"0.002\"], [\"70339.70\", \"0.000\"], [\"70339.80\", \"0.003\"], [\"70340.00\", \"0.019\"], [\"70340.10\", \"0.004\"], [\"70340.60\", \"0.003\"], [\"70340.90\", \"0.352\"], [\"70341.00\", \"0.002\"], [\"70341.10\", \"0.011\"], [\"70341.20\", \"0.000\"], [\"70341.30\", \"0.000\"], [\"70341.50\", \"0.544\"], [\"70341.60\", \"1.577\"], [\"70341.70\", \"0.491\"], [\"70341.80\", \"0.203\"], [\"70341.90\", \"0.001\"], [\"70342.00\", \"0.648\"], [\"70342.10\", \"0.010\"], [\"70342.30\", \"0.111\"], [\"70342.40\", \"0.000\"], [\"70342.50\", \"0.010\"], [\"70342.60\", \"0.422\"], [\"70342.70\", \"0.000\"], [\"70342.80\", \"0.380\"], [\"70343.30\", \"0.065\"], [\"70343.40\", \"0.022\"], [\"70343.50\", \"0.028\"], [\"70343.60\", \"0.005\"], [\"70343.70\", \"0.005\"], [\"70343.80\", \"0.000\"], [\"70343.90\", \"0.006\"], [\"70344.10\", \"0.007\"], [\"70344.40\", \"0.000\"], [\"70344.50\", \"0.000\"], [\"70344.80\", \"0.006\"], [\"70345.00\", \"0.212\"], [\"70345.10\", \"0.033\"], [\"70345.40\", \"0.003\"], [\"70345.70\", \"0.000\"], [\"70345.80\", \"0.003\"], [\"70345.90\", \"0.000\"], [\"70346.00\", \"0.004\"], [\"70346.10\", \"0.005\"], [\"70346.20\", \"0.173\"], [\"70346.30\", \"1.215\"], [\"70346.40\", \"0.007\"], [\"70346.50\", \"0.002\"], [\"70346.60\", \"0.345\"], [\"70346.70\", \"0.032\"], [\"70346.80\", \"0.064\"], [\"70346.90\", \"0.029\"], [\"70347.00\", \"0.017\"], [\"70347.10\", \"0.146\"], [\"70347.20\", \"0.092\"], [\"70347.50\", \"0.002\"], [\"70347.70\", \"0.052\"], [\"70348.00\", \"0.008\"], [\"70348.10\", \"0.000\"], [\"70348.20\", \"0.002\"], [\"70348.70\", \"0.116\"], [\"70348.80\", \"0.000\"], [\"70348.90\", \"0.236\"], [\"70349.00\", \"0.090\"], [\"70349.10\", \"0.003\"], [\"70349.30\", \"0.000\"], [\"70349.40\", \"0.006\"], [\"70349.50\", \"0.002\"], [\"70349.60\", \"0.604\"], [\"70349.70\", \"0.257\"], [\"70350.00\", \"0.008\"], [\"70350.70\", \"0.088\"], [\"70350.80\", \"0.004\"], [\"70351.00\", \"0.045\"], [\"70351.10\", \"0.002\"], [\"70351.20\", \"0.047\"], [\"70351.60\", \"0.002\"], [\"70351.70\", \"0.000\"], [\"70351.80\", \"0.092\"], [\"70351.90\", \"0.005\"], [\"70352.30\", \"0.002\"], [\"70352.40\", \"0.097\"], [\"70352.50\", \"0.001\"], [\"70352.60\", \"0.184\"], [\"70352.70\", \"0.014\"], [\"70353.00\", \"0.555\"], [\"70353.10\", \"0.004\"], [\"70353.30\", \"0.000\"], [\"70353.40\", \"0.043\"], [\"70353.50\", \"0.146\"], [\"70353.90\", \"0.004\"], [\"70354.10\", \"0.183\"], [\"70354.40\", \"0.094\"], [\"70354.50\", \"0.089\"], [\"70354.60\", \"0.069\"], [\"70354.70\", \"0.000\"], [\"70354.80\", \"0.000\"], [\"70354.90\", \"0.001\"], [\"70355.00\", \"0.004\"], [\"70355.30\", \"0.000\"], [\"70355.40\", \"0.000\"], [\"70355.60\", \"0.001\"], [\"70355.70\", \"0.131\"], [\"70355.80\", \"1.419\"], [\"70355.90\", \"0.001\"], [\"70356.00\", \"0.321\"], [\"70356.10\", \"0.000\"], [\"70356.20\", \"0.000\"], [\"70356.30\", \"0.003\"], [\"70356.40\", \"0.001\"], [\"70356.50\", \"0.179\"], [\"70356.60\", \"0.205\"], [\"70356.70\", \"0.100\"], [\"70356.80\", \"0.319\"], [\"70356.90\", \"0.001\"], [\"70357.00\", \"0.005\"], [\"70357.10\", \"0.140\"], [\"70357.20\", \"0.000\"], [\"70357.40\", \"0.028\"], [\"70357.50\", \"0.321\"], [\"70357.60\", \"0.001\"], [\"70357.70\", \"0.405\"], [\"70357.80\", \"0.118\"], [\"70357.90\", \"0.028\"], [\"70358.20\", \"0.347\"], [\"70358.40\", \"0.028\"], [\"70358.50\", \"0.028\"], [\"70358.60\", \"0.003\"], [\"70358.70\", \"0.120\"], [\"70358.80\", \"0.349\"], [\"70359.00\", \"0.347\"], [\"70359.40\", \"0.031\"], [\"70359.50\", \"0.028\"], [\"70359.60\", \"0.028\"], [\"70359.70\", \"0.347\"], [\"70359.80\", \"0.028\"], [\"70359.90\", \"0.623\"], [\"70360.00\", \"0.001\"], [\"70360.10\", \"0.081\"], [\"70360.20\", \"0.183\"], [\"70360.30\", \"0.000\"], [\"70360.40\", \"0.000\"], [\"70360.50\", \"0.115\"], [\"70360.60\", \"0.049\"], [\"70360.70\", \"0.001\"], [\"70360.80\", \"0.001\"], [\"70360.90\", \"0.000\"], [\"70361.00\", \"0.007\"], [\"70361.10\", \"0.393\"], [\"70361.20\", \"4.499\"], [\"70361.30\", \"19.049\"]], \"a\": [[\"70355.70\", \"0.000\"], [\"70355.80\", \"0.000\"], [\"70355.90\", \"0.000\"], [\"70356.00\", \"0.000\"], [\"70356.10\", \"0.000\"], [\"70356.20\", \"0.000\"], [\"70356.30\", \"0.000\"], [\"70356.50\", \"0.000\"], [\"70356.60\", \"0.000\"], [\"70356.80\", \"0.000\"], [\"70356.90\", \"0.000\"], [\"70357.00\", \"0.000\"], [\"70357.20\", \"0.000\"], [\"70357.30\", \"0.000\"], [\"70357.50\", \"0.000\"], [\"70357.60\", \"0.000\"], [\"70357.80\", \"0.000\"], [\"70357.90\", \"0.000\"], [\"70358.00\", \"0.000\"], [\"70358.30\", \"0.000\"], [\"70358.50\", \"0.000\"], [\"70358.60\", \"0.000\"], [\"70358.70\", \"0.000\"], [\"70358.80\", \"0.000\"], [\"70358.90\", \"0.000\"], [\"70359.10\", \"0.000\"], [\"70359.50\", \"0.000\"], [\"70359.60\", \"0.000\"], [\"70359.70\", \"0.000\"], [\"70359.80\", \"0.000\"], [\"70359.90\", \"0.000\"], [\"70360.00\", \"0.000\"], [\"70360.10\", \"0.000\"], [\"70360.30\", \"0.000\"], [\"70360.50\", \"0.000\"], [\"70360.60\", \"0.000\"], [\"70360.70\", \"0.000\"], [\"70360.80\", \"0.000\"], [\"70360.90\", \"0.000\"], [\"70361.00\", \"0.000\"], [\"70361.20\", \"0.000\"], [\"70361.30\", \"0.000\"], [\"70361.40\", \"2.002\"], [\"70361.60\", \"0.000\"], [\"70361.80\", \"0.000\"], [\"70361.90\", \"0.000\"], [\"70362.00\", \"0.002\"], [\"70362.20\", \"0.000\"], [\"70362.30\", \"0.000\"], [\"70362.40\", \"0.002\"], [\"70362.60\", \"0.000\"], [\"70362.70\", \"0.004\"], [\"70362.80\", \"0.002\"], [\"70363.20\", \"0.000\"], [\"70363.30\", \"0.005\"], [\"70363.50\", \"0.002\"], [\"70363.60\", \"0.000\"], [\"70363.80\", \"0.000\"], [\"70363.90\", \"0.003\"], [\"70364.00\", \"0.004\"], [\"70364.40\", \"0.000\"], [\"70364.50\", \"0.000\"], [\"70364.60\", \"0.003\"], [\"70364.70\", \"0.002\"], [\"70364.80\", \"0.002\"], [\"70364.90\", \"0.002\"], [\"70365.00\", \"0.002\"], [\"70365.10\", \"0.003\"], [\"70365.20\", \"0.002\"], [\"70365.30\", \"0.005\"], [\"70366.00\", \"0.004\"], [\"70366.10\", \"0.002\"], [\"70366.30\", \"0.008\"], [\"70366.50\", \"0.019\"], [\"70366.80\", \"0.000\"], [\"70367.10\", \"0.002\"], [\"70367.20\", \"50.003\"], [\"70367.30\", \"0.004\"], [\"70367.40\", \"0.006\"], [\"70367.90\", \"0.000\"], [\"70368.10\", \"0.004\"], [\"70368.30\", \"0.000\"], [\"70368.40\", \"0.099\"], [\"70368.60\", \"0.006\"], [\"70368.70\", \"0.000\"], [\"70368.80\", \"0.007\"], [\"70368.90\", \"0.010\"], [\"70369.10\", \"0.000\"], [\"70369.30\", \"0.004\"], [\"70369.60\", \"0.000\"], [\"70369.80\", \"0.076\"], [\"70369.90\", \"0.023\"], [\"70370.00\", \"0.004\"], [\"70370.10\", \"0.026\"], [\"70370.40\", \"0.026\"], [\"70370.50\", \"0.344\"], [\"70370.60\", \"0.000\"], [\"70370.80\", \"0.025\"], [\"70371.10\", \"0.041\"], [\"70371.20\", \"0.003\"], [\"70371.30\", \"0.007\"], [\"70371.50\", \"0.038\"], [\"70371.70\", \"0.076\"], [\"70371.80\", \"0.074\"], [\"70372.10\", \"0.003\"], [\"70372.20\", \"0.002\"], [\"70372.30\", \"0.003\"], [\"70372.50\", \"0.026\"], [\"70372.70\", \"0.002\"], [\"70373.20\", \"0.007\"], [\"70373.30\", \"0.002\"], [\"70373.40\", \"0.007\"], [\"70373.70\", \"0.003\"], [\"70373.90\", \"0.001\"], [\"70374.00\", \"0.063\"], [\"70374.10\", \"0.055\"], [\"70374.20\", \"0.002\"], [\"70374.30\", \"0.003\"], [\"70374.40\", \"0.006\"], [\"70374.50\", \"0.002\"], [\"70374.80\", \"0.311\"], [\"70374.90\", \"0.007\"], [\"70375.40\", \"0.003\"], [\"70375.70\", \"0.000\"], [\"70375.90\", \"0.001\"], [\"70376.10\", \"0.009\"], [\"70376.20\", \"0.651\"], [\"70376.50\", \"0.008\"], [\"70376.60\", \"0.002\"], [\"70376.70\", \"0.001\"], [\"70376.80\", \"0.008\"], [\"70376.90\", \"0.278\"], [\"70377.40\", \"0.214\"], [\"70377.50\", \"0.003\"], [\"70377.60\", \"0.000\"], [\"70377.70\", \"0.000\"], [\"70377.80\", \"0.004\"], [\"70378.10\", \"0.096\"], [\"70378.30\", \"0.519\"], [\"70378.50\", \"0.003\"], [\"70378.70\", \"0.007\"], [\"70378.80\", \"0.145\"], [\"70379.10\", \"0.000\"], [\"70379.30\", \"0.007\"], [\"70379.50\", \"0.000\"], [\"70379.60\", \"0.005\"], [\"70379.70\", \"0.186\"], [\"70379.90\", \"0.003\"], [\"70380.30\", \"0.000\"], [\"70380.40\", \"0.000\"], [\"70380.50\", \"0.511\"], [\"70380.70\", \"0.286\"], [\"70380.80\", \"0.077\"], [\"70381.00\", \"0.184\"], [\"70381.10\", \"0.004\"], [\"70381.20\", \"0.059\"], [\"70381.30\", \"1.069\"], [\"70381.40\", \"0.003\"], [\"70381.50\", \"0.543\"], [\"70381.60\", \"0.639\"], [\"70381.70\", \"0.018\"], [\"70381.80\", \"0.000\"], [\"70382.00\", \"0.002\"], [\"70382.40\", \"0.008\"], [\"70382.70\", \"0.704\"], [\"70383.00\", \"0.005\"], [\"70383.40\", \"0.007\"], [\"70383.50\", \"0.010\"], [\"70383.90\", \"0.014\"], [\"70384.00\", \"0.007\"], [\"70384.30\", \"0.000\"], [\"70384.40\", \"0.074\"], [\"70385.00\", \"0.036\"], [\"70385.10\", \"0.009\"], [\"70385.30\", \"0.003\"], [\"70385.40\", \"0.005\"], [\"70385.50\", \"0.000\"], [\"70385.90\", \"0.000\"], [\"70386.00\", \"0.377\"], [\"70386.10\", \"0.485\"], [\"70386.60\", \"0.003\"], [\"70386.80\", \"0.052\"], [\"70387.10\", \"0.007\"], [\"70387.20\", \"0.002\"], [\"70387.30\", \"0.013\"], [\"70387.40\", \"0.208\"], [\"70387.70\", \"0.515\"], [\"70387.80\", \"0.004\"], [\"70387.90\", \"0.004\"], [\"70388.00\", \"0.004\"], [\"70388.10\", \"0.000\"], [\"70388.40\", \"0.007\"], [\"70388.50\", \"0.005\"], [\"70388.60\", \"0.010\"], [\"70388.70\", \"0.511\"], [\"70388.80\", \"0.370\"], [\"70388.90\", \"0.000\"], [\"70389.20\", \"0.001\"], [\"70389.30\", \"0.000\"], [\"70389.80\", \"0.085\"], [\"70389.90\", \"0.032\"], [\"70390.00\", \"0.002\"], [\"70390.10\", \"0.005\"], [\"70390.20\", \"0.250\"], [\"70390.50\", \"0.000\"], [\"70390.60\", \"0.003\"], [\"70390.70\", \"0.007\"], [\"70390.80\", \"0.000\"], [\"70391.00\", \"0.000\"], [\"70391.20\", \"0.774\"], [\"70391.30\", \"0.011\"], [\"70391.40\", \"0.012\"], [\"70391.50\", \"0.059\"], [\"70391.80\", \"0.002\"], [\"70392.00\", \"0.392\"], [\"70392.10\", \"0.025\"], [\"70392.20\", \"0.145\"], [\"70392.70\", \"0.002\"], [\"70392.80\", \"0.385\"], [\"70393.30\", \"0.005\"], [\"70393.40\", \"0.000\"], [\"70393.50\", \"0.002\"], [\"70394.10\", \"0.002\"], [\"70394.20\", \"0.071\"], [\"70394.50\", \"0.005\"], [\"70394.80\", \"0.194\"], [\"70394.90\", \"0.000\"], [\"70395.20\", \"0.029\"], [\"70395.50\", \"0.023\"], [\"70395.60\", \"0.009\"], [\"70396.20\", \"0.005\"], [\"70396.30\", \"0.002\"], [\"70396.40\", \"0.003\"], [\"70396.90\", \"0.005\"], [\"70397.00\", \"0.018\"], [\"70397.40\", \"0.093\"], [\"70397.60\", \"0.067\"], [\"70397.70\", \"0.002\"], [\"70397.90\", \"0.002\"], [\"70398.30\", \"0.242\"], [\"70398.40\", \"0.252\"], [\"70399.30\", \"1.076\"], [\"70399.60\", \"0.002\"], [\"70399.90\", \"0.060\"], [\"70400.00\", \"2.045\"], [\"70400.10\", \"0.097\"], [\"70401.50\", \"0.510\"], [\"70401.70\", \"0.009\"], [\"70401.80\", \"0.000\"], [\"70402.30\", \"0.002\"], [\"70402.70\", \"0.002\"], [\"70403.40\", \"0.002\"], [\"70403.50\", \"0.007\"], [\"70404.70\", \"0.004\"], [\"70404.80\", \"0.208\"], [\"70405.50\", \"0.002\"], [\"70405.90\", \"0.002\"], [\"70406.00\", \"1.080\"], [\"70406.10\", \"0.000\"], [\"70406.40\", \"0.003\"], [\"70407.00\", \"0.089\"], [\"70408.10\", \"0.000\"], [\"70408.90\", \"0.046\"], [\"70409.00\", \"0.005\"], [\"70409.10\", \"0.088\"], [\"70409.70\", \"0.100\"], [\"70410.40\", \"0.000\"], [\"70410.50\", \"0.851\"], [\"70410.90\", \"0.002\"], [\"70411.00\", \"0.084\"], [\"70412.20\", \"0.004\"], [\"70412.30\", \"0.931\"], [\"70412.40\", \"0.003\"], [\"70412.60\", \"0.041\"], [\"70412.70\", \"0.003\"], [\"70413.00\", \"1.075\"], [\"70413.90\", \"0.065\"], [\"70414.60\", \"0.004\"], [\"70414.90\", \"0.046\"], [\"70415.50\", \"0.004\"], [\"70415.60\", \"0.002\"], [\"70417.30\", \"0.028\"], [\"70418.20\", \"0.008\"], [\"70418.30\", \"0.006\"], [\"70418.50\", \"0.002\"], [\"70418.60\", \"0.013\"], [\"70419.50\", \"0.004\"], [\"70419.90\", \"0.513\"], [\"70420.20\", \"0.000\"], [\"70420.30\", \"0.002\"], [\"70420.40\", \"0.271\"], [\"70421.50\", \"0.424\"], [\"70421.90\", \"0.103\"], [\"70422.20\", \"0.000\"], [\"70422.70\", \"0.004\"], [\"70423.30\", \"0.513\"], [\"70423.40\", \"0.192\"], [\"70424.20\", \"0.036\"], [\"70424.30\", \"0.002\"], [\"70424.50\", \"0.001\"], [\"70425.20\", \"0.005\"], [\"70425.30\", \"0.006\"], [\"70425.60\", \"0.001\"], [\"70425.70\", \"0.000\"], [\"70425.80\", \"1.071\"], [\"70425.90\", \"0.525\"], [\"70426.70\", \"0.192\"], [\"70427.50\", \"0.008\"], [\"70427.80\", \"0.230\"], [\"70427.90\", \"0.000\"], [\"70428.10\", \"0.327\"], [\"70428.30\", \"0.008\"], [\"70429.30\", \"0.002\"], [\"70429.50\", \"0.003\"], [\"70429.60\", \"1.033\"], [\"70430.10\", \"0.049\"], [\"70430.70\", \"0.002\"], [\"70431.00\", \"0.006\"], [\"70431.30\", \"0.003\"], [\"70432.10\", \"0.519\"], [\"70432.80\", \"0.000\"], [\"70433.10\", \"0.002\"], [\"70433.20\", \"0.227\"], [\"70435.00\", \"0.235\"], [\"70435.10\", \"0.138\"], [\"70435.50\", \"0.000\"], [\"70435.60\", \"0.342\"], [\"70435.70\", \"0.000\"], [\"70435.80\", \"0.018\"], [\"70435.90\", \"0.156\"], [\"70436.20\", \"0.240\"], [\"70436.30\", \"1.505\"], [\"70436.50\", \"0.011\"], [\"70436.70\", \"0.358\"], [\"70436.80\", \"0.634\"], [\"70437.20\", \"0.142\"], [\"70437.30\", \"0.238\"], [\"70437.40\", \"0.000\"], [\"70437.50\", \"0.905\"], [\"70437.60\", \"0.104\"], [\"70437.70\", \"0.089\"], [\"70437.90\", \"0.043\"], [\"70438.00\", \"0.000\"], [\"70438.20\", \"0.000\"], [\"70438.40\", \"0.002\"], [\"70438.80\", \"0.036\"], [\"70439.30\", \"0.511\"], [\"70439.40\", \"0.002\"], [\"70439.90\", \"0.071\"], [\"70440.50\", \"0.004\"], [\"70440.80\", \"0.000\"], [\"70441.00\", \"2.117\"], [\"70441.30\", \"0.025\"], [\"70441.40\", \"0.258\"], [\"70441.60\", \"0.000\"], [\"70441.70\", \"0.105\"], [\"70441.90\", \"0.271\"], [\"70442.00\", \"0.605\"], [\"70442.20\", \"0.084\"], [\"70442.30\", \"0.000\"], [\"70443.10\", \"0.003\"], [\"70443.20\", \"0.170\"], [\"70443.30\", \"9.668\"], [\"70443.40\", \"0.006\"], [\"70443.50\", \"0.075\"], [\"70444.20\", \"0.734\"], [\"70444.30\", \"6.992\"], [\"70445.60\", \"0.000\"], [\"70445.70\", \"0.086\"], [\"70445.80\", \"0.374\"], [\"70446.40\", \"0.004\"], [\"70446.50\", \"0.000\"], [\"70446.90\", \"1.397\"], [\"70447.00\", \"0.000\"], [\"70447.10\", \"0.000\"], [\"70447.40\", \"0.000\"], [\"70447.60\", \"0.086\"], [\"70447.70\", \"0.005\"], [\"70447.80\", \"0.090\"], [\"70447.90\", \"0.011\"], [\"70448.80\", \"0.011\"], [\"70449.40\", \"0.088\"], [\"70449.50\", \"0.009\"], [\"70449.60\", \"0.002\"], [\"70449.90\", \"0.000\"], [\"70450.00\", \"0.705\"], [\"70450.40\", \"2.086\"], [\"70450.50\", \"1.072\"], [\"70450.80\", \"0.007\"], [\"70451.30\", \"0.484\"], [\"70451.50\", \"0.088\"], [\"70451.60\", \"0.000\"], [\"70451.70\", \"0.055\"], [\"70452.00\", \"0.082\"], [\"70452.20\", \"0.000\"], [\"70452.50\", \"0.000\"], [\"70452.60\", \"0.000\"], [\"70452.70\", \"6.708\"], [\"70452.80\", \"0.086\"], [\"70453.00\", \"10.226\"], [\"70453.30\", \"0.018\"], [\"70453.50\", \"0.016\"], [\"70453.70\", \"0.002\"], [\"70454.00\", \"0.195\"], [\"70454.20\", \"0.000\"], [\"70454.40\", \"0.010\"], [\"70455.10\", \"0.086\"], [\"70456.00\", \"0.087\"], [\"70457.00\", \"0.016\"], [\"70457.30\", \"0.044\"], [\"70458.00\", \"0.019\"], [\"70458.90\", \"0.000\"], [\"70459.90\", \"0.191\"], [\"70460.90\", \"0.039\"], [\"70461.30\", \"0.000\"], [\"70461.40\", \"0.127\"], [\"70461.90\", \"0.000\"], [\"70462.40\", \"0.125\"], [\"70462.60\", \"0.002\"], [\"70462.80\", \"0.375\"], [\"70463.00\", \"0.092\"], [\"70463.60\", \"0.045\"], [\"70463.80\", \"0.008\"], [\"70464.50\", \"0.000\"], [\"70464.80\", \"0.000\"], [\"70465.50\", \"0.081\"], [\"70465.80\", \"0.000\"], [\"70465.90\", \"0.028\"], [\"70466.50\", \"0.129\"], [\"70466.70\", \"0.000\"], [\"70467.30\", \"0.000\"], [\"70467.70\", \"0.000\"], [\"70468.50\", \"0.384\"], [\"70468.70\", \"0.000\"], [\"70469.60\", \"0.083\"], [\"70470.40\", \"0.209\"], [\"70470.60\", \"0.250\"], [\"70471.60\", \"0.154\"], [\"70472.60\", \"0.366\"], [\"70473.00\", \"0.000\"], [\"70473.50\", \"0.002\"], [\"70473.60\", \"0.005\"], [\"70473.90\", \"0.086\"], [\"70476.70\", \"0.002\"], [\"70478.30\", \"0.085\"], [\"70478.80\", \"0.064\"], [\"70480.90\", \"0.048\"], [\"70481.80\", \"0.511\"], [\"70482.40\", \"0.011\"], [\"70482.80\", \"0.002\"], [\"70483.80\", \"0.036\"], [\"70484.70\", \"0.000\"], [\"70485.70\", \"0.000\"], [\"70486.70\", \"0.000\"], [\"70487.60\", \"0.041\"], [\"70488.60\", \"0.000\"], [\"70489.60\", \"0.000\"], [\"70490.60\", \"0.002\"], [\"70491.00\", \"0.000\"], [\"70491.30\", \"0.002\"], [\"70491.50\", \"0.087\"], [\"70491.70\", \"0.002\"], [\"70492.50\", \"0.000\"], [\"70498.30\", \"0.000\"], [\"70499.90\", \"0.091\"], [\"70503.10\", \"0.271\"], [\"70506.70\", \"0.760\"], [\"70506.90\", \"0.028\"], [\"70510.30\", \"0.187\"], [\"70532.20\", \"0.041\"], [\"70533.60\", \"0.081\"], [\"70534.80\", \"0.083\"], [\"70537.40\", \"0.090\"], [\"70538.70\", \"0.286\"], [\"70538.90\", \"0.135\"], [\"70542.00\", \"0.081\"], [\"70543.90\", \"0.025\"], [\"70544.40\", \"0.045\"], [\"70545.10\", \"0.039\"], [\"70545.20\", \"0.081\"], [\"70545.50\", \"0.025\"], [\"70545.60\", \"0.038\"], [\"70546.50\", \"10.081\"], [\"70548.20\", \"0.043\"], [\"70549.50\", \"0.709\"], [\"70550.00\", \"1.460\"], [\"70550.30\", \"0.005\"], [\"70553.80\", \"0.005\"], [\"70558.10\", \"0.081\"], [\"70561.30\", \"0.006\"], [\"70563.70\", \"0.002\"], [\"70568.30\", \"0.004\"], [\"70573.10\", \"0.001\"], [\"70575.30\", \"0.004\"], [\"70577.40\", \"0.000\"], [\"70589.40\", \"0.008\"], [\"70593.10\", \"10.004\"], [\"70597.20\", \"0.061\"], [\"70598.20\", \"0.063\"], [\"70598.40\", \"0.005\"], [\"70601.60\", \"0.000\"], [\"70623.00\", \"1.928\"], [\"70624.10\", \"10.000\"], [\"70654.90\", \"1.695\"], [\"70655.10\", \"10.002\"], [\"70657.60\", \"0.380\"], [\"70657.70\", \"0.193\"], [\"70664.60\", \"6.502\"], [\"70679.20\", \"0.000\"], [\"70679.30\", \"0.000\"], [\"70701.60\", \"10.000\"], [\"70737.10\", \"0.002\"], [\"70793.00\", \"5.761\"], [\"71059.30\", \"1.405\"], [\"75257.70\", \"0.016\"], [\"89523.20\", \"0.000\"]]}", "symbol": "BTCUSDT"}
{"event": "depthUpdate", "raw_payload": "{\"e\": \"depthUpdate\", \"E\": 1773246385764, \"T\": 1773246385763, \"s\": \"BTCUSDT\", \"U\": 10089703913139, \"u\": 10089703936891, \"pu\": 10089703913136, \"b\": [[\"1000.00\", \"26.792\"], [\"5000.00\", \"101.418\"], [\"19848.60\", \"1.140\"], [\"19861.30\", \"0.090\"], [\"19948.60\", \"0.040\"], [\"19961.30\", \"0.090\"], [\"20048.60\", \"0.530\"], [\"20261.30\", \"0.090\"], [\"66815.40\", \"0.010\"], [\"66834.20\", \"0.006\"], [\"66835.70\", \"0.002\"], [\"69401.30\", \"0.288\"], [\"69421.60\", \"0.013\"], [\"69657.70\", \"0.002\"], [\"70056.20\", \"0.000\"], [\"70111.40\", \"0.000\"], [\"70120.50\", \"0.205\"], [\"70146.30\", \"0.166\"], [\"70149.30\", \"0.203\"], [\"70152.80\", \"0.014\"], [\"70155.40\", \"0.189\"], [\"70199.00\", \"0.127\"], [\"70201.40\", \"0.000\"], [\"70210.30\", \"0.015\"], [\"70225.30\", \"0.084\"], [\"70225.40\", \"0.002\"], [\"70230.30\", \"0.089\"], [\"70232.10\", \"1.390\"], [\"70236.90\", \"0.178\"], [\"70238.70\", \"1.114\"], [\"70240.70\", \"0.257\"], [\"70242.80\", \"0.000\"], [\"70244.60\", \"0.128\"], [\"70245.50\", \"0.578\"], [\"70247.50\", \"0.076\"], [\"70248.40\", \"0.210\"], [\"70252.10\", \"0.008\"], [\"70254.30\", \"1.414\"], [\"70256.90\", \"0.002\"], [\"70258.20\", \"0.228\"], [\"70260.50\", \"0.000\"], [\"70265.50\", \"0.373\"], [\"70271.70\", \"0.000\"], [\"70273.00\", \"0.259\"], [\"70274.10\", \"0.077\"], [\"70280.50\", \"0.564\"], [\"70282.10\", \"0.030\"], [\"70282.40\", \"0.000\"], [\"70283.20\", \"0.005\"], [\"70283.90\", \"0.002\"], [\"70285.00\", \"0.207\"], [\"70286.00\", \"0.002\"], [\"70286.60\", \"0.057\"], [\"70287.90\", \"0.069\"], [\"70288.50\", \"0.000\"], [\"70289.50\", \"0.191\"], [\"70290.90\", \"0.214\"], [\"70291.00\", \"0.056\"], [\"70294.20\", \"0.648\"], [\"70294.30\", \"0.001\"], [\"70295.50\", \"0.541\"], [\"70296.10\", \"0.279\"], [\"70296.80\", \"0.003\"], [\"70297.40\", \"0.000\"], [\"70300.90\", \"0.006\"], [\"70301.50\", \"0.000\"], [\"70303.10\", \"0.000\"], [\"70305.00\", \"0.100\"], [\"70305.40\", \"0.136\"], [\"70305.70\", \"0.002\"], [\"70305.80\", \"0.002\"], [\"70306.30\", \"0.004\"], [\"70306.40\", \"0.010\"], [\"70307.00\", \"0.000\"], [\"70307.10\", \"0.010\"], [\"70307.30\", \"0.218\"], [\"70307.70\", \"0.004\"], [\"70308.00\", \"0.008\"], [\"70308.30\", \"0.086\"], [\"70308.40\", \"0.035\"], [\"70309.10\", \"0.206\"], [\"70309.80\", \"0.004\"], [\"70311.50\", \"1.070\"], [\"70313.40\", \"0.971\"], [\"70313.60\", \"0.000\"], [\"70314.70\", \"0.000\"], [\"70315.00\", \"0.004\"], [\"70315.10\", \"0.000\"], [\"70315.40\", \"1.475\"], [\"70316.30\", \"0.003\"], [\"70316.80\", \"0.009\"], [\"70317.10\", \"0.055\"], [\"70317.30\", \"0.012\"], [\"70317.70\", \"0.032\"], [\"70318.00\", \"0.044\"], [\"70318.10\", \"0.085\"], [\"70318.30\", \"0.017\"], [\"70318.70\", \"0.573\"], [\"70319.50\", \"0.002\"], [\"70320.10\", \"0.273\"], [\"70320.20\", \"0.027\"], [\"70320.60\", \"0.002\"], [\"70320.70\", \"0.000\"], [\"70320.90\", \"0.001\"], [\"70321.00\", \"0.041\"], [\"70321.10\", \"0.128\"], [\"70321.80\", \"0.497\"], [\"70323.00\", \"0.004\"], [\"70323.70\", \"0.002\"], [\"70325.10\", \"0.029\"], [\"70325.50\", \"0.211\"], [\"70325.70\", \"0.064\"], [\"70326.10\", \"0.053\"], [\"70326.20\", \"0.107\"], [\"70326.30\", \"0.006\"], [\"70326.80\", \"0.000\"], [\"70326.90\", \"0.012\"], [\"70327.20\", \"0.040\"], [\"70327.50\", \"0.006\"], [\"70328.60\", \"0.200\"], [\"70329.30\", \"0.077\"], [\"70329.80\", \"0.007\"], [\"70330.60\", \"0.388\"], [\"70330.70\", \"0.254\"], [\"70330.80\", \"0.193\"], [\"70330.90\", \"0.383\"], [\"70331.70\", \"0.012\"], [\"70331.90\", \"0.081\"], [\"70332.50\", \"0.002\"], [\"70332.90\", \"0.323\"], [\"70333.00\", \"0.000\"], [\"70333.20\", \"2.087\"], [\"70333.30\", \"0.058\"], [\"70333.40\", \"0.012\"], [\"70333.70\", \"0.002\"], [\"70333.80\", \"0.002\"], [\"70335.40\", \"0.002\"], [\"70336.50\", \"0.017\"], [\"70336.60\", \"0.307\"], [\"70336.70\", \"0.009\"], [\"70337.20\", \"0.016\"], [\"70337.30\", \"0.026\"], [\"70338.30\", \"0.000\"], [\"70338.80\", \"0.005\"], [\"70339.10\", \"0.018\"], [\"70340.10\", \"0.002\"], [\"70340.20\", \"0.004\"], [\"70340.30\", \"0.001\"], [\"70340.60\", \"0.083\"], [\"70340.80\", \"0.000\"], [\"70341.10\", \"0.004\"], [\"70341.20\", \"0.071\"], [\"70341.30\", \"0.511\"], [\"70341.50\", \"0.033\"], [\"70341.60\", \"1.757\"], [\"70341.70\", \"0.007\"], [\"70341.90\", \"0.062\"], [\"70342.00\", \"0.009\"], [\"70342.10\", \"0.000\"], [\"70342.40\", \"0.007\"], [\"70342.60\", \"0.493\"], [\"70342.70\", \"0.054\"], [\"70342.80\", \"0.451\"], [\"70342.90\", \"0.020\"], [\"70343.00\", \"0.039\"], [\"70343.10\", \"0.645\"], [\"70343.20\", \"0.004\"], [\"70343.30\", \"0.037\"], [\"70343.40\", \"0.001\"], [\"70343.50\", \"0.000\"], [\"70343.70\", \"0.489\"], [\"70343.80\", \"0.523\"], [\"70344.40\", \"0.014\"], [\"70344.90\", \"0.289\"], [\"70345.00\", \"0.233\"], [\"70345.10\", \"1.210\"], [\"70345.20\", \"0.001\"], [\"70345.30\", \"0.028\"], [\"70345.40\", \"0.024\"], [\"70345.50\", \"0.037\"], [\"70346.10\", \"0.007\"], [\"70346.20\", \"0.543\"], [\"70346.30\", \"0.007\"], [\"70346.40\", \"0.007\"], [\"70346.70\", \"0.000\"], [\"70346.80\", \"0.000\"], [\"70346.90\", \"0.003\"], [\"70347.00\", \"0.005\"], [\"70347.10\", \"0.160\"], [\"70347.20\", \"0.001\"], [\"70347.40\", \"0.142\"], [\"70347.70\", \"0.012\"], [\"70348.60\", \"0.008\"], [\"70348.70\", \"0.077\"], [\"70348.80\", \"0.064\"], [\"70348.90\", \"0.234\"], [\"70349.00\", \"0.000\"], [\"70349.10\", \"0.017\"], [\"70349.20\", \"0.001\"], [\"70349.30\", \"0.002\"], [\"70349.60\", \"0.462\"], [\"70349.70\", \"0.300\"], [\"70350.10\", \"0.001\"], [\"70350.40\", \"0.001\"], [\"70350.50\", \"0.003\"], [\"70350.60\", \"0.003\"], [\"70350.80\", \"0.010\"], [\"70350.90\", \"0.031\"], [\"70351.00\", \"0.135\"], [\"70351.20\", \"0.003\"], [\"70352.40\", \"0.000\"], [\"70352.60\", \"0.184\"], [\"70352.70\", \"0.017\"], [\"70353.20\", \"0.047\"], [\"70353.50\", \"0.144\"], [\"70354.40\", \"0.191\"], [\"70354.50\", \"0.353\"], [\"70354.70\", \"0.003\"], [\"70355.40\", \"0.003\"], [\"70355.60\", \"0.001\"], [\"70355.70\", \"0.128\"], [\"70355.80\", \"1.100\"], [\"70356.00\", \"0.002\"], [\"70356.10\", \"0.002\"], [\"70356.70\", \"0.000\"], [\"70356.80\", \"0.000\"], [\"70357.40\", \"0.000\"], [\"70357.50\", \"0.005\"], [\"70357.70\", \"0.058\"], [\"70357.80\", \"0.090\"], [\"70357.90\", \"0.000\"], [\"70358.20\", \"0.003\"], [\"70358.40\", \"0.000\"], [\"70358.50\", \"0.000\"], [\"70358.60\", \"0.003\"], [\"70358.70\", \"0.092\"], [\"70358.80\", \"0.002\"], [\"70358.90\", \"0.000\"], [\"70359.00\", \"0.000\"], [\"70359.40\", \"0.003\"], [\"70359.50\", \"0.000\"], [\"70359.60\", \"0.000\"], [\"70359.70\", \"0.000\"], [\"70359.80\", \"0.000\"], [\"70359.90\", \"0.002\"], [\"70360.10\", \"0.001\"], [\"70360.20\", \"0.155\"], [\"70360.50\", \"0.000\"], [\"70360.60\", \"0.002\"], [\"70360.70\", \"0.000\"], [\"70360.80\", \"0.000\"], [\"70361.00\", \"0.002\"], [\"70361.10\", \"0.352\"], [\"70361.20\", \"1.333\"], [\"70361.30\", \"7.265\"], [\"70361.40\", \"3.649\"], [\"70361.50\", \"0.002\"], [\"70361.60\", \"0.920\"], [\"70361.90\", \"1.298\"], [\"70362.00\", \"0.307\"], [\"70362.30\", \"0.217\"], [\"70362.60\", \"1.921\"]], \"a\": [[\"70361.40\", \"0.000\"], [\"70361.50\", \"0.000\"], [\"70362.00\", \"0.000\"], [\"70362.10\", \"0.000\"], [\"70362.40\", \"0.000\"], [\"70364.00\", \"0.004\"], [\"70364.10\", \"0.007\"], [\"70364.80\", \"0.007\"], [\"70364.90\", \"0.138\"], [\"70365.90\", \"0.000\"], [\"70366.30\", \"0.005\"], [\"70366.70\", \"0.236\"], [\"70367.00\", \"0.002\"], [\"70367.10\", \"7.473\"], [\"70367.30\", \"0.006\"], [\"70367.40\", \"0.015\"], [\"70367.50\", \"0.004\"], [\"70368.10\", \"0.005\"], [\"70368.40\", \"0.102\"], [\"70368.80\", \"0.074\"], [\"70369.00\", \"0.002\"], [\"70369.50\", \"0.002\"], [\"70369.80\", \"0.005\"], [\"70370.10\", \"0.001\"], [\"70370.40\", \"0.001\"], [\"70370.50\", \"0.418\"], [\"70370.80\", \"0.000\"], [\"70371.00\", \"0.012\"], [\"70371.10\", \"0.004\"], [\"70371.50\", \"0.041\"], [\"70371.60\", \"0.086\"], [\"70371.80\", \"0.002\"], [\"70371.90\", \"0.003\"], [\"70372.30\", \"0.003\"], [\"70373.20\", \"0.008\"], [\"70373.30\", \"0.000\"], [\"70374.00\", \"0.002\"], [\"70374.10\", \"0.002\"], [\"70374.40\", \"0.004\"], [\"70375.30\", \"0.511\"], [\"70375.60\", \"1.068\"], [\"70375.80\", \"0.261\"], [\"70375.90\", \"0.004\"], [\"70376.00\", \"0.036\"], [\"70376.10\", \"0.002\"], [\"70376.70\", \"0.026\"], [\"70376.80\", \"0.150\"], [\"70376.90\", \"0.103\"], [\"70377.00\", \"0.146\"], [\"70377.10\", \"0.000\"], [\"70377.80\", \"0.000\"], [\"70378.10\", \"0.004\"], [\"70378.50\", \"0.007\"], [\"70378.80\", \"0.060\"], [\"70378.90\", \"0.463\"], [\"70379.00\", \"0.015\"], [\"70379.20\", \"0.058\"], [\"70379.30\", \"0.000\"], [\"70379.70\", \"0.193\"], [\"70379.90\", \"0.005\"], [\"70380.10\", \"0.004\"], [\"70380.20\", \"0.000\"], [\"70380.60\", \"0.010\"], [\"70380.80\", \"0.077\"], [\"70381.10\", \"0.643\"], [\"70381.20\", \"0.002\"], [\"70381.60\", \"0.000\"], [\"70381.70\", \"0.011\"], [\"70382.20\", \"0.007\"], [\"70382.60\", \"0.002\"], [\"70382.70\", \"0.950\"], [\"70382.80\", \"0.094\"], [\"70382.90\", \"0.000\"], [\"70383.30\", \"0.000\"], [\"70383.40\", \"0.079\"], [\"70383.50\", \"0.003\"], [\"70383.90\", \"0.001\"], [\"70384.20\", \"0.199\"], [\"70384.40\", \"0.003\"], [\"70384.70\", \"0.004\"], [\"70385.10\", \"0.009\"], [\"70385.80\", \"0.013\"], [\"70386.20\", \"0.000\"], [\"70386.30\", \"0.009\"], [\"70386.40\", \"0.040\"], [\"70386.60\", \"0.093\"], [\"70387.60\", \"0.567\"], [\"70388.20\", \"0.006\"], [\"70388.40\", \"0.000\"], [\"70388.60\", \"0.003\"], [\"70388.70\", \"0.000\"], [\"70388.80\", \"0.350\"], [\"70389.10\", \"0.071\"], [\"70389.30\", \"0.511\"], [\"70389.40\", \"1.003\"], [\"70389.50\", \"0.009\"], [\"70389.60\", \"0.000\"], [\"70389.70\", \"0.005\"], [\"70389.90\", \"0.037\"], [\"70390.10\", \"0.032\"], [\"70390.40\", \"0.375\"], [\"70390.70\", \"0.005\"], [\"70391.00\", \"0.001\"], [\"70391.30\", \"0.017\"], [\"70391.40\", \"0.003\"], [\"70391.70\", \"0.000\"], [\"70391.90\", \"0.383\"], [\"70392.00\", \"0.401\"], [\"70392.10\", \"0.036\"], [\"70392.20\", \"0.125\"], [\"70392.30\", \"0.195\"], [\"70392.70\", \"0.000\"], [\"70392.80\", \"0.383\"], [\"70393.00\", \"1.418\"], [\"70393.20\", \"0.005\"], [\"70393.40\", \"0.009\"], [\"70393.50\", \"0.004\"], [\"70394.40\", \"0.042\"], [\"70395.40\", \"0.053\"], [\"70395.50\", \"0.036\"], [\"70395.60\", \"0.000\"], [\"70396.70\", \"0.187\"], [\"70397.00\", \"0.000\"], [\"70397.60\", \"0.067\"], [\"70398.30\", \"0.240\"], [\"70398.40\", \"0.250\"], [\"70398.70\", \"0.273\"], [\"70399.00\", \"0.024\"], [\"70399.10\", \"0.000\"], [\"70399.20\", \"0.877\"], [\"70399.40\", \"0.042\"], [\"70399.70\", \"0.010\"], [\"70399.80\", \"0.006\"], [\"70399.90\", \"0.002\"], [\"70400.40\", \"0.004\"], [\"70400.90\", \"0.013\"], [\"70401.10\", \"0.208\"], [\"70401.20\", \"0.004\"], [\"70401.60\", \"0.006\"], [\"70402.30\", \"0.005\"], [\"70402.40\", \"0.009\"], [\"70403.00\", \"1.883\"], [\"70403.60\", \"0.046\"], [\"70404.10\", \"0.433\"], [\"70404.30\", \"0.066\"], [\"70404.90\", \"0.002\"], [\"70405.80\", \"0.007\"], [\"70406.30\", \"0.028\"], [\"70406.50\", \"0.095\"], [\"70407.00\", \"0.007\"], [\"70407.30\", \"0.000\"], [\"70407.40\", \"0.051\"], [\"70408.20\", \"0.588\"], [\"70409.20\", \"0.894\"], [\"70409.30\", \"0.030\"], [\"70409.50\", \"0.798\"], [\"70409.80\", \"0.116\"], [\"70410.50\", \"0.002\"], [\"70410.90\", \"0.022\"], [\"70411.10\", \"0.002\"], [\"70412.10\", \"0.511\"], [\"70412.30\", \"0.082\"], [\"70413.40\", \"0.002\"], [\"70413.50\", \"0.058\"], [\"70413.60\", \"0.000\"], [\"70413.90\", \"0.002\"], [\"70414.30\", \"0.064\"], [\"70414.60\", \"0.000\"], [\"70414.70\", \"0.243\"], [\"70415.50\", \"0.008\"], [\"70415.90\", \"0.000\"], [\"70416.40\", \"0.335\"], [\"70417.10\", \"0.020\"], [\"70417.30\", \"0.000\"], [\"70417.40\", \"0.018\"], [\"70418.60\", \"0.013\"], [\"70420.20\", \"0.000\"], [\"70420.40\", \"0.143\"], [\"70420.50\", \"0.048\"], [\"70420.60\", \"0.000\"], [\"70420.90\", \"0.002\"], [\"70421.40\", \"0.006\"], [\"70421.50\", \"0.424\"], [\"70421.60\", \"0.132\"], [\"70424.80\", \"0.036\"], [\"70425.00\", \"0.045\"], [\"70425.90\", \"0.527\"], [\"70426.30\", \"0.002\"], [\"70428.10\", \"0.400\"], [\"70428.40\", \"0.204\"], [\"70429.50\", \"0.003\"], [\"70431.00\", \"0.002\"], [\"70431.40\", \"0.801\"], [\"70432.10\", \"0.523\"], [\"70433.20\", \"0.010\"], [\"70433.80\", \"0.000\"], [\"70435.10\", \"0.002\"], [\"70435.30\", \"0.000\"], [\"70435.40\", \"0.044\"], [\"70436.20\", \"0.104\"], [\"70436.80\", \"0.513\"], [\"70437.50\", \"0.908\"], [\"70437.90\", \"0.043\"], [\"70440.70\", \"0.646\"], [\"70440.80\", \"0.000\"], [\"70441.30\", \"0.025\"], [\"70442.00\", \"0.605\"], [\"70443.40\", \"0.006\"], [\"70443.70\", \"1.515\"], [\"70445.00\", \"0.000\"], [\"70445.70\", \"0.000\"], [\"70446.20\", \"0.225\"], [\"70446.40\", \"0.004\"], [\"70446.50\", \"0.000\"], [\"70446.90\", \"0.072\"], [\"70447.60\", \"0.000\"], [\"70449.40\", \"0.002\"], [\"70450.30\", \"0.013\"], [\"70450.40\", \"2.000\"], [\"70451.50\", \"0.002\"], [\"70452.80\", \"0.000\"], [\"70453.90\", \"0.000\"], [\"70454.30\", \"0.133\"], [\"70455.10\", \"0.000\"], [\"70456.00\", \"0.126\"], [\"70461.40\", \"0.041\"], [\"70461.70\", \"0.090\"], [\"70462.40\", \"0.039\"], [\"70463.30\", \"0.039\"], [\"70464.30\", \"0.081\"], [\"70465.30\", \"0.008\"], [\"70466.30\", \"0.000\"], [\"70471.70\", \"0.138\"], [\"70473.90\", \"0.000\"], [\"70477.80\", \"0.001\"], [\"70482.20\", \"0.083\"], [\"70483.90\", \"0.084\"], [\"70495.10\", \"0.091\"], [\"70495.40\", \"0.000\"], [\"70496.00\", \"0.543\"], [\"70497.70\", \"0.002\"], [\"70498.70\", \"0.301\"], [\"70499.70\", \"0.002\"], [\"70505.30\", \"0.018\"], [\"70507.60\", \"0.322\"], [\"70508.00\", \"0.000\"], [\"70508.70\", \"0.125\"], [\"70511.00\", \"0.366\"], [\"70511.60\", \"1.061\"], [\"70512.60\", \"0.116\"], [\"70513.90\", \"0.208\"], [\"70514.00\", \"10.000\"], [\"70516.00\", \"0.024\"], [\"70518.40\", \"0.163\"], [\"70522.60\", \"0.437\"], [\"70523.50\", \"2.003\"], [\"70528.90\", \"0.121\"], [\"70543.70\", \"0.025\"], [\"70544.10\", \"0.547\"], [\"70545.10\", \"0.111\"], [\"70545.90\", \"0.234\"], [\"70546.00\", \"0.464\"], [\"70546.20\", \"0.025\"], [\"70546.50\", \"0.081\"], [\"70546.90\", \"0.045\"], [\"70557.40\", \"0.000\"], [\"70560.50\", \"10.000\"], [\"70583.30\", \"0.143\"], [\"70587.80\", \"0.285\"], [\"70591.50\", \"10.000\"], [\"70593.10\", \"0.004\"], [\"70606.70\", \"3.353\"], [\"70623.00\", \"0.547\"], [\"70624.10\", \"0.000\"], [\"71065.00\", \"0.064\"], [\"71293.20\", \"0.280\"], [\"73333.00\", \"15.305\"]]}", "symbol": "BTCUSDT"}
{"event": "depthUpdate", "raw_payload": "{\"e\": \"depthUpdate\", \"E\": 1773246385866, \"T\": 1773246385865, \"s\": \"BTCUSDT\", \"U\": 10089703936897, \"u\": 10089703953199, \"pu\": 10089703936891, \"b\": [[\"5000.00\", \"101.418\"], [\"19848.60\", \"1.050\"], [\"19863.20\", \"0.000\"], [\"19864.80\", \"0.000\"], [\"19948.60\", \"0.000\"], [\"19962.60\", \"0.010\"], [\"19964.80\", \"0.080\"], [\"20048.60\", \"0.440\"], [\"20261.30\", \"0.100\"], [\"20264.80\", \"0.120\"], [\"40000.00\", \"50.522\"], [\"63328.30\", \"0.007\"], [\"68407.50\", \"0.007\"], [\"69352.20\", \"0.000\"], [\"69352.50\", \"1.023\"], [\"69353.40\", \"0.004\"], [\"69362.60\", \"0.006\"], [\"69363.20\", \"0.016\"], [\"69657.70\", \"0.000\"], [\"69661.20\", \"3.695\"], [\"69831.70\", \"0.000\"], [\"69832.40\", \"0.365\"], [\"69981.50\", \"0.000\"], [\"69984.70\", \"0.000\"], [\"70062.20\", \"0.000\"], [\"70133.40\", \"0.000\"], [\"70148.60\", \"0.000\"], [\"70154.20\", \"0.889\"], [\"70158.80\", \"0.000\"], [\"70158.90\", \"0.000\"], [\"70160.20\", \"2.009\"], [\"70166.10\", \"0.062\"], [\"70182.20\", \"0.000\"], [\"70182.70\", \"10.210\"], [\"70185.10\", \"2.089\"], [\"70185.70\", \"0.059\"], [\"70211.80\", \"0.043\"], [\"70212.80\", \"0.065\"], [\"70216.30\", \"0.191\"], [\"70222.30\", \"0.359\"], [\"70236.40\", \"0.006\"], [\"70240.00\", \"0.268\"], [\"70243.10\", \"0.018\"], [\"70244.10\", \"0.383\"], [\"70244.20\", \"2.030\"], [\"70246.20\", \"0.000\"], [\"70250.90\", \"0.143\"], [\"70252.40\", \"0.012\"], [\"70253.80\", \"0.023\"], [\"70254.10\", \"0.123\"], [\"70254.20\", \"4.048\"], [\"70254.30\", \"1.408\"], [\"70254.70\", \"0.000\"], [\"70259.00\", \"2.370\"], [\"70259.60\", \"0.119\"], [\"70259.70\", \"1.333\"], [\"70260.70\", \"0.167\"], [\"70264.10\", \"0.103\"], [\"70270.20\", \"0.002\"], [\"70272.90\", \"0.912\"], [\"70275.80\", \"0.628\"], [\"70277.80\", \"0.203\"], [\"70283.80\", \"0.000\"], [\"70283.90\", \"0.053\"], [\"70285.00\", \"0.206\"], [\"70285.80\", \"0.008\"], [\"70287.20\", \"0.299\"], [\"70287.90\", \"0.020\"], [\"70290.50\", \"0.624\"], [\"70291.50\", \"0.050\"], [\"70292.70\", \"0.026\"], [\"70294.00\", \"0.742\"], [\"70294.20\", \"0.654\"], [\"70299.50\", \"0.006\"], [\"70300.90\", \"0.002\"], [\"70302.40\", \"0.003\"], [\"70304.60\", \"0.008\"], [\"70305.00\", \"0.000\"], [\"70305.40\", \"0.987\"], [\"70305.50\", \"0.005\"], [\"70306.70\", \"0.002\"], [\"70307.20\", \"0.885\"], [\"70307.40\", \"0.102\"], [\"70307.60\", \"0.035\"], [\"70308.40\", \"0.014\"], [\"70308.50\", \"0.118\"], [\"70308.60\", \"0.074\"], [\"70309.80\", \"0.002\"], [\"70310.20\", \"0.002\"], [\"70310.40\", \"0.006\"], [\"70310.50\", \"0.103\"], [\"70310.90\", \"0.176\"], [\"70311.10\", \"0.035\"], [\"70311.60\", \"0.000\"], [\"70312.00\", \"0.008\"], [\"70312.10\", \"0.005\"], [\"70312.60\", \"0.014\"], [\"70312.80\", \"0.002\"], [\"70313.50\", \"0.376\"], [\"70313.80\", \"0.002\"], [\"70313.90\", \"0.000\"], [\"70314.30\", \"0.709\"], [\"70314.60\", \"0.026\"], [\"70314.80\", \"0.000\"], [\"70316.20\", \"0.000\"], [\"70317.10\", \"0.053\"], [\"70317.30\", \"0.002\"], [\"70318.10\", \"0.000\"], [\"70318.40\", \"0.716\"], [\"70318.60\", \"0.085\"], [\"70318.70\", \"0.004\"], [\"70318.80\", \"0.020\"], [\"70320.00\", \"0.050\"], [\"70320.10\", \"0.193\"], [\"70320.40\", \"0.000\"], [\"70320.80\", \"0.008\"], [\"70320.90\", \"0.570\"], [\"70322.50\", \"0.214\"], [\"70322.60\", \"0.021\"], [\"70322.80\", \"0.073\"], [\"70323.20\", \"0.002\"], [\"70325.00\", \"0.208\"], [\"70325.50\", \"0.210\"], [\"70325.70\", \"0.029\"], [\"70326.90\", \"0.007\"], [\"70328.00\", \"0.014\"], [\"70328.40\", \"0.002\"], [\"70328.50\", \"0.028\"], [\"70329.30\", \"0.000\"], [\"70329.50\", \"0.002\"], [\"70329.80\", \"0.000\"], [\"70329.90\", \"0.105\"], [\"70330.40\", \"0.385\"], [\"70330.70\", \"0.006\"], [\"70330.80\", \"0.193\"], [\"70330.90\", \"0.386\"], [\"70331.20\", \"0.005\"], [\"70331.50\", \"0.007\"], [\"70331.70\", \"0.254\"], [\"70331.80\", \"0.002\"], [\"70332.10\", \"0.004\"], [\"70332.20\", \"0.089\"], [\"70332.60\", \"0.149\"], [\"70332.90\", \"0.005\"], [\"70333.30\", \"0.004\"], [\"70333.40\", \"0.014\"], [\"70333.70\", \"0.000\"], [\"70334.30\", \"0.005\"], [\"70334.40\", \"0.572\"], [\"70335.20\", \"0.347\"], [\"70335.40\", \"0.002\"], [\"70336.00\", \"0.759\"], [\"70336.40\", \"0.000\"], [\"70336.60\", \"0.605\"], [\"70336.70\", \"0.005\"], [\"70337.20\", \"0.176\"], [\"70337.90\", \"0.020\"], [\"70338.20\", \"0.001\"], [\"70339.20\", \"0.004\"], [\"70339.30\", \"0.009\"], [\"70339.40\", \"0.008\"], [\"70339.60\", \"0.002\"], [\"70339.70\", \"0.071\"], [\"70339.90\", \"0.052\"], [\"70340.20\", \"0.002\"], [\"70340.30\", \"0.072\"], [\"70340.60\", \"0.003\"], [\"70341.10\", \"0.002\"], [\"70341.20\", \"0.000\"], [\"70341.30\", \"0.000\"], [\"70341.50\", \"0.033\"], [\"70341.70\", \"0.263\"], [\"70342.10\", \"0.511\"], [\"70342.40\", \"0.000\"], [\"70342.50\", \"0.003\"], [\"70342.60\", \"0.422\"], [\"70342.80\", \"0.377\"], [\"70343.00\", \"0.039\"], [\"70343.10\", \"0.006\"], [\"70343.30\", \"0.037\"], [\"70343.40\", \"0.001\"], [\"70343.60\", \"0.003\"], [\"70343.70\", \"0.005\"], [\"70343.80\", \"1.238\"], [\"70343.90\", \"0.008\"], [\"70344.10\", \"0.028\"], [\"70344.20\", \"0.001\"], [\"70344.30\", \"0.125\"], [\"70344.40\", \"0.073\"], [\"70344.50\", \"0.036\"], [\"70344.90\", \"0.005\"], [\"70345.00\", \"0.211\"], [\"70345.10\", \"0.002\"], [\"70345.30\", \"0.000\"], [\"70345.40\", \"0.003\"], [\"70345.50\", \"0.016\"], [\"70345.60\", \"0.004\"], [\"70345.70\", \"0.000\"], [\"70345.80\", \"0.141\"], [\"70345.90\", \"0.000\"], [\"70346.00\", \"0.004\"], [\"70346.10\", \"0.007\"], [\"70346.20\", \"0.175\"], [\"70346.30\", \"0.518\"], [\"70346.40\", \"0.000\"], [\"70346.70\", \"0.047\"], [\"70346.90\", \"0.003\"], [\"70347.00\", \"0.005\"], [\"70347.10\", \"0.002\"], [\"70347.20\", \"0.015\"], [\"70347.30\", \"0.000\"], [\"70347.40\", \"0.000\"], [\"70347.60\", \"0.000\"], [\"70347.70\", \"0.012\"], [\"70347.80\", \"0.000\"], [\"70348.20\", \"0.000\"], [\"70348.30\", \"0.009\"], [\"70348.50\", \"0.001\"], [\"70348.70\", \"0.045\"], [\"70348.80\", \"0.002\"], [\"70348.90\", \"0.221\"], [\"70349.10\", \"0.005\"], [\"70349.40\", \"0.006\"], [\"70349.60\", \"0.000\"], [\"70349.70\", \"0.031\"], [\"70349.80\", \"1.211\"], [\"70349.90\", \"0.348\"], [\"70350.10\", \"0.004\"], [\"70350.20\", \"0.000\"], [\"70350.30\", \"0.002\"], [\"70350.60\", \"0.000\"], [\"70350.80\", \"0.017\"], [\"70350.90\", \"0.001\"], [\"70351.00\", \"0.045\"], [\"70351.10\", \"0.002\"], [\"70351.20\", \"0.005\"], [\"70351.30\", \"0.002\"], [\"70351.40\", \"0.001\"], [\"70351.50\", \"0.000\"], [\"70351.60\", \"0.002\"], [\"70351.70\", \"0.284\"], [\"70351.90\", \"0.005\"], [\"70352.00\", \"0.000\"], [\"70352.10\", \"0.000\"], [\"70352.60\", \"0.186\"], [\"70352.70\", \"0.000\"], [\"70352.80\", \"0.000\"], [\"70352.90\", \"0.062\"], [\"70353.00\", \"0.537\"], [\"70353.10\", \"0.002\"], [\"70353.20\", \"0.000\"], [\"70353.30\", \"0.000\"], [\"70353.50\", \"0.228\"], [\"70353.60\", \"0.145\"], [\"70354.20\", \"0.001\"], [\"70354.30\", \"0.002\"], [\"70354.40\", \"0.094\"], [\"70354.50\", \"0.005\"], [\"70354.60\", \"0.004\"], [\"70354.70\", \"0.003\"], [\"70354.90\", \"0.001\"], [\"70355.00\", \"0.004\"], [\"70355.10\", \"0.000\"], [\"70355.30\", \"0.002\"], [\"70355.50\", \"0.001\"], [\"70355.70\", \"0.128\"], [\"70355.80\", \"0.000\"], [\"70356.00\", \"0.005\"], [\"70356.10\", \"0.000\"], [\"70356.50\", \"0.179\"], [\"70356.60\", \"0.002\"], [\"70356.90\", \"0.001\"], [\"70357.10\", \"0.003\"], [\"70357.40\", \"0.015\"], [\"70357.90\", \"0.004\"], [\"70358.00\", \"0.264\"], [\"70358.10\", \"0.002\"], [\"70358.70\", \"0.009\"], [\"70359.10\", \"0.001\"], [\"70359.60\", \"0.003\"], [\"70359.70\", \"0.000\"], [\"70360.00\", \"0.005\"], [\"70360.10\", \"0.000\"], [\"70360.20\", \"0.001\"], [\"70360.30\", \"0.003\"], [\"70360.50\", \"0.003\"], [\"70360.60\", \"0.003\"], [\"70360.80\", \"0.003\"], [\"70361.10\", \"0.004\"], [\"70361.20\", \"0.146\"], [\"70361.30\", \"0.004\"], [\"70361.40\", \"1.103\"], [\"70361.50\", \"0.658\"], [\"70361.60\", \"0.000\"], [\"70361.90\", \"0.000\"], [\"70362.00\", \"0.000\"], [\"70362.30\", \"0.000\"], [\"70362.40\", \"0.005\"], [\"70362.50\", \"0.001\"], [\"70362.60\", \"0.141\"], [\"70362.70\", \"0.000\"], [\"70362.80\", \"0.000\"], [\"70362.90\", \"0.002\"], [\"70363.10\", \"0.004\"], [\"70363.20\", \"0.001\"], [\"70363.30\", \"0.002\"], [\"70363.40\", \"0.000\"], [\"70363.60\", \"0.002\"], [\"70363.80\", \"0.000\"], [\"70363.90\", \"0.000\"], [\"70364.00\", \"0.000\"], [\"70364.20\", \"0.000\"], [\"70364.50\", \"0.000\"], [\"70364.60\", \"0.000\"], [\"70364.70\", \"0.003\"], [\"70364.80\", \"6.737\"]], \"a\": [[\"70362.70\", \"0.000\"], [\"70362.80\", \"0.000\"], [\"70363.00\", \"0.000\"], [\"70363.30\", \"0.000\"], [\"70363.40\", \"0.000\"], [\"70363.50\", \"0.000\"], [\"70363.90\", \"0.000\"], [\"70364.00\", \"0.000\"], [\"70364.10\", \"0.000\"], [\"70364.30\", \"0.000\"], [\"70364.60\", \"0.000\"], [\"70364.70\", \"0.000\"], [\"70364.80\", \"0.000\"], [\"70364.90\", \"2.459\"], [\"70365.00\", \"0.003\"], [\"70365.10\", \"0.002\"], [\"70365.20\", \"0.000\"], [\"70365.30\", \"0.002\"], [\"70365.40\", \"0.000\"], [\"70365.60\", \"0.000\"], [\"70366.00\", \"0.001\"], [\"70366.10\", \"0.000\"], [\"70366.20\", \"0.002\"], [\"70366.30\", \"0.002\"], [\"70366.40\", \"0.004\"], [\"70366.50\", \"0.004\"], [\"70366.60\", \"0.004\"], [\"70366.70\", \"0.235\"], [\"70367.00\", \"0.006\"], [\"70367.10\", \"7.472\"], [\"70367.20\", \"50.001\"], [\"70367.30\", \"0.007\"], [\"70367.40\", \"0.007\"], [\"70367.80\", \"0.003\"], [\"70367.90\", \"0.000\"], [\"70368.30\", \"0.030\"], [\"70368.40\", \"0.102\"], [\"70368.50\", \"0.002\"], [\"70368.60\", \"0.004\"], [\"70368.80\", \"0.000\"], [\"70369.30\", \"0.002\"], [\"70369.80\", \"0.002\"], [\"70369.90\", \"0.021\"], [\"70370.00\", \"0.002\"], [\"70370.10\", \"0.003\"], [\"70370.50\", \"0.005\"], [\"70371.00\", \"0.015\"], [\"70371.30\", \"0.005\"], [\"70371.40\", \"0.000\"], [\"70371.50\", \"0.170\"], [\"70371.60\", \"0.006\"], [\"70371.70\", \"0.002\"], [\"70371.90\", \"0.000\"], [\"70372.10\", \"0.208\"], [\"70372.30\", \"0.017\"], [\"70372.50\", \"0.026\"], [\"70372.60\", \"0.344\"], [\"70372.70\", \"0.000\"], [\"70372.80\", \"0.003\"], [\"70373.40\", \"0.518\"], [\"70373.60\", \"0.010\"], [\"70373.80\", \"0.004\"], [\"70373.90\", \"0.001\"], [\"70374.00\", \"0.000\"], [\"70374.10\", \"0.003\"], [\"70374.20\", \"0.000\"], [\"70374.30\", \"0.000\"], [\"70374.50\", \"0.004\"], [\"70374.60\", \"0.000\"], [\"70374.80\", \"0.485\"], [\"70374.90\", \"0.004\"], [\"70375.00\", \"0.005\"], [\"70375.30\", \"0.000\"], [\"70375.40\", \"0.005\"], [\"70375.50\", \"0.004\"], [\"70375.60\", \"0.514\"], [\"70375.80\", \"0.026\"], [\"70376.00\", \"0.000\"], [\"70376.10\", \"0.258\"], [\"70376.20\", \"0.306\"], [\"70376.60\", \"0.030\"], [\"70376.70\", \"0.001\"], [\"70376.80\", \"0.064\"], [\"70376.90\", \"0.101\"], [\"70377.00\", \"0.086\"], [\"70377.20\", \"0.069\"], [\"70377.30\", \"0.004\"], [\"70377.40\", \"0.032\"], [\"70377.50\", \"0.085\"], [\"70377.70\", \"0.090\"], [\"70377.80\", \"1.594\"], [\"70378.10\", \"0.002\"], [\"70378.20\", \"0.261\"], [\"70378.30\", \"0.348\"], [\"70378.50\", \"0.054\"], [\"70378.70\", \"0.150\"], [\"70378.90\", \"0.007\"], [\"70379.00\", \"0.101\"], [\"70379.10\", \"0.003\"], [\"70379.20\", \"0.043\"], [\"70379.60\", \"0.005\"], [\"70379.70\", \"0.005\"], [\"70380.00\", \"0.070\"], [\"70380.40\", \"0.000\"], [\"70380.50\", \"0.511\"], [\"70380.60\", \"0.003\"], [\"70380.70\", \"0.002\"], [\"70380.80\", \"0.075\"], [\"70381.00\", \"0.003\"], [\"70381.10\", \"0.002\"], [\"70381.30\", \"0.003\"], [\"70381.40\", \"0.000\"], [\"70381.70\", \"0.013\"], [\"70381.90\", \"0.003\"], [\"70382.20\", \"0.000\"], [\"70382.30\", \"0.391\"], [\"70382.40\", \"0.012\"], [\"70382.50\", \"0.008\"], [\"70382.60\", \"0.005\"], [\"70382.70\", \"0.071\"], [\"70383.10\", \"0.000\"], [\"70383.20\", \"0.001\"], [\"70383.30\", \"0.142\"], [\"70383.40\", \"0.002\"], [\"70383.50\", \"0.003\"], [\"70383.60\", \"1.278\"], [\"70383.80\", \"0.000\"], [\"70384.00\", \"0.833\"], [\"70384.10\", \"0.002\"], [\"70384.20\", \"0.006\"], [\"70384.40\", \"0.189\"], [\"70384.50\", \"0.865\"], [\"70384.60\", \"0.007\"], [\"70384.70\", \"0.527\"], [\"70384.90\", \"0.000\"], [\"70385.20\", \"0.005\"], [\"70385.30\", \"0.003\"], [\"70385.40\", \"0.007\"], [\"70385.50\", \"0.000\"], [\"70385.60\", \"0.000\"], [\"70385.80\", \"0.015\"], [\"70385.90\", \"0.000\"], [\"70386.10\", \"0.007\"], [\"70386.40\", \"0.042\"], [\"70386.60\", \"0.098\"], [\"70386.70\", \"0.284\"], [\"70386.90\", \"0.007\"], [\"70387.00\", \"0.004\"], [\"70387.30\", \"0.188\"], [\"70387.60\", \"0.380\"], [\"70387.70\", \"0.004\"], [\"70388.00\", \"0.002\"], [\"70388.10\", \"0.000\"], [\"70388.30\", \"0.513\"], [\"70388.50\", \"0.006\"], [\"70388.70\", \"0.007\"], [\"70388.80\", \"0.611\"], [\"70389.10\", \"0.000\"], [\"70389.30\", \"0.000\"], [\"70389.40\", \"0.003\"], [\"70389.50\", \"0.002\"], [\"70389.70\", \"0.012\"], [\"70389.90\", \"0.005\"], [\"70390.10\", \"0.025\"], [\"70390.20\", \"0.002\"], [\"70390.30\", \"0.071\"], [\"70390.50\", \"0.511\"], [\"70390.90\", \"1.071\"], [\"70391.10\", \"0.255\"], [\"70391.40\", \"0.023\"], [\"70391.80\", \"0.009\"], [\"70391.90\", \"1.383\"], [\"70392.00\", \"0.392\"], [\"70392.10\", \"0.027\"], [\"70392.20\", \"0.039\"], [\"70392.40\", \"0.005\"], [\"70392.70\", \"0.511\"], [\"70392.80\", \"0.002\"], [\"70392.90\", \"0.514\"], [\"70393.00\", \"0.352\"], [\"70393.40\", \"0.007\"], [\"70393.50\", \"0.002\"], [\"70394.10\", \"0.002\"], [\"70394.20\", \"0.000\"], [\"70394.30\", \"0.002\"], [\"70394.50\", \"0.007\"], [\"70394.80\", \"0.203\"], [\"70394.90\", \"0.009\"], [\"70395.00\", \"0.006\"], [\"70395.40\", \"0.197\"], [\"70395.50\", \"0.015\"], [\"70395.60\", \"0.000\"], [\"70395.80\", \"0.000\"], [\"70396.20\", \"0.007\"], [\"70396.30\", \"0.004\"], [\"70396.60\", \"0.002\"], [\"70397.20\", \"0.087\"], [\"70397.60\", \"0.119\"], [\"70397.80\", \"0.097\"], [\"70398.30\", \"0.311\"], [\"70398.90\", \"0.010\"], [\"70399.00\", \"0.002\"], [\"70399.20\", \"0.857\"], [\"70399.70\", \"0.004\"], [\"70399.80\", \"0.004\"], [\"70400.10\", \"0.045\"], [\"70400.20\", \"0.004\"], [\"70400.40\", \"0.004\"], [\"70400.50\", \"0.422\"], [\"70400.60\", \"0.003\"], [\"70400.90\", \"0.007\"], [\"70401.10\", \"0.208\"], [\"70401.20\", \"0.004\"], [\"70401.80\", \"0.002\"], [\"70401.90\", \"0.009\"], [\"70402.20\", \"0.000\"], [\"70402.40\", \"0.009\"], [\"70402.70\", \"1.847\"], [\"70403.70\", \"0.003\"], [\"70404.20\", \"0.004\"], [\"70404.40\", \"0.009\"], [\"70404.70\", \"0.002\"], [\"70404.80\", \"0.214\"], [\"70405.10\", \"0.003\"], [\"70405.80\", \"0.010\"], [\"70405.90\", \"0.032\"], [\"70406.50\", \"0.098\"], [\"70406.90\", \"0.006\"], [\"70407.20\", \"0.064\"], [\"70407.40\", \"0.002\"], [\"70408.90\", \"0.046\"], [\"70410.60\", \"0.052\"], [\"70410.90\", \"0.022\"], [\"70411.00\", \"0.011\"], [\"70411.10\", \"0.075\"], [\"70412.60\", \"0.046\"], [\"70413.10\", \"0.035\"], [\"70413.90\", \"0.008\"], [\"70414.30\", \"0.000\"], [\"70415.50\", \"0.004\"], [\"70415.70\", \"0.088\"], [\"70416.40\", \"0.249\"], [\"70417.40\", \"0.022\"], [\"70417.50\", \"0.063\"], [\"70417.80\", \"0.573\"], [\"70420.20\", \"0.086\"], [\"70420.40\", \"0.992\"], [\"70421.20\", \"0.000\"], [\"70421.30\", \"0.001\"], [\"70421.60\", \"0.004\"], [\"70421.90\", \"0.103\"], [\"70422.20\", \"0.877\"], [\"70422.50\", \"0.081\"], [\"70422.60\", \"0.000\"], [\"70422.70\", \"0.132\"], [\"70423.60\", \"0.192\"], [\"70424.60\", \"0.036\"], [\"70424.90\", \"0.000\"], [\"70425.20\", \"3.547\"], [\"70428.50\", \"0.002\"], [\"70429.50\", \"0.000\"], [\"70430.10\", \"0.052\"], [\"70430.20\", \"0.000\"], [\"70430.40\", \"0.192\"], [\"70430.50\", \"0.513\"], [\"70430.70\", \"0.002\"], [\"70430.90\", \"0.219\"], [\"70431.00\", \"0.088\"], [\"70432.10\", \"0.516\"], [\"70432.50\", \"0.695\"], [\"70432.80\", \"0.000\"], [\"70433.20\", \"0.366\"], [\"70433.40\", \"0.000\"], [\"70434.00\", \"0.010\"], [\"70434.20\", \"0.000\"], [\"70434.70\", \"0.197\"], [\"70435.20\", \"0.016\"], [\"70435.30\", \"0.086\"], [\"70435.70\", \"0.000\"], [\"70436.20\", \"0.110\"], [\"70436.30\", \"1.505\"], [\"70436.70\", \"0.358\"], [\"70436.80\", \"0.515\"], [\"70437.20\", \"0.189\"], [\"70437.30\", \"0.240\"], [\"70437.60\", \"0.153\"], [\"70437.80\", \"0.003\"], [\"70438.60\", \"0.003\"], [\"70439.60\", \"0.000\"], [\"70440.00\", \"0.013\"], [\"70440.10\", \"0.138\"], [\"70440.50\", \"0.004\"], [\"70440.60\", \"1.068\"], [\"70440.70\", \"0.782\"], [\"70441.40\", \"0.256\"], [\"70441.50\", \"0.000\"], [\"70441.70\", \"0.105\"], [\"70442.50\", \"0.000\"], [\"70443.20\", \"0.170\"], [\"70443.30\", \"9.675\"], [\"70443.50\", \"0.075\"], [\"70444.40\", \"0.004\"], [\"70445.40\", \"0.000\"], [\"70446.40\", \"0.004\"], [\"70447.40\", \"0.000\"], [\"70447.90\", \"0.004\"], [\"70448.30\", \"0.000\"], [\"70449.10\", \"0.198\"], [\"70449.30\", \"0.000\"], [\"70450.30\", \"0.013\"], [\"70451.20\", \"0.000\"], [\"70452.20\", \"0.000\"], [\"70452.80\", \"2.014\"], [\"70453.20\", \"0.383\"], [\"70453.50\", \"0.014\"], [\"70453.80\", \"0.281\"], [\"70456.80\", \"0.088\"], [\"70458.20\", \"0.086\"], [\"70459.20\", \"0.088\"], [\"70459.90\", \"0.193\"], [\"70461.20\", \"0.086\"], [\"70462.20\", \"0.092\"], [\"70462.90\", \"0.084\"], [\"70463.10\", \"0.095\"], [\"70464.10\", \"2.006\"], [\"70465.00\", \"0.030\"], [\"70465.10\", \"0.000\"], [\"70468.20\", \"0.513\"], [\"70469.80\", \"1.582\"], [\"70470.20\", \"0.101\"], [\"70471.20\", \"0.081\"], [\"70471.70\", \"0.131\"], [\"70479.40\", \"0.515\"], [\"70480.30\", \"0.394\"], [\"70480.50\", \"0.008\"], [\"70480.70\", \"0.169\"], [\"70482.70\", \"0.124\"], [\"70483.00\", \"0.076\"], [\"70484.10\", \"0.155\"], [\"70486.40\", \"0.087\"], [\"70489.20\", \"0.041\"], [\"70495.90\", \"0.440\"], [\"70498.90\", \"0.004\"], [\"70505.30\", \"0.000\"], [\"70513.90\", \"0.039\"], [\"70532.20\", \"0.083\"], [\"70552.30\", \"0.075\"], [\"70555.50\", \"0.049\"], [\"70557.40\", \"0.003\"], [\"70558.10\", \"0.000\"], [\"70560.90\", \"30.971\"], [\"70561.20\", \"0.000\"], [\"70566.50\", \"0.008\"], [\"70568.10\", \"0.019\"], [\"70570.30\", \"0.081\"], [\"70576.80\", \"0.448\"], [\"70582.30\", \"0.127\"], [\"70583.30\", \"0.085\"], [\"70587.30\", \"0.003\"], [\"70591.40\", \"1.695\"], [\"70598.00\", \"0.043\"], [\"70661.30\", \"0.228\"], [\"70662.40\", \"0.385\"], [\"70713.60\", \"0.002\"], [\"70736.80\", \"0.004\"], [\"70896.70\", \"3.720\"], [\"70897.40\", \"0.000\"], [\"70898.10\", \"0.000\"], [\"71065.00\", \"0.062\"], [\"71068.50\", \"0.064\"], [\"73871.90\", \"0.005\"], [\"73885.10\", \"0.008\"], [\"77401.40\", \"0.002\"], [\"89523.20\", \"0.000\"], [\"100000.00\", \"15.236\"]]}", "symbol": "BTCUSDT"}
