{"event": "depthUpdate", "raw_payload": "{\"e\": \"depthUpdate\", \"E\": 1773246395574, \"T\": 1773246395572, \"s\": \"BTCUSDT\", \"U\": 10089704789226, \"u\": 10089704795425, \"pu\": 10089704789025, \"b\": [[\"1000.00\", \"26.792\"], [\"5000.00\", \"101.418\"], [\"19991.80\", \"0.650\"], [\"20067.10\", \"0.740\"], [\"20091.80\", \"0.390\"], [\"20191.80\", \"0.650\"], [\"20267.10\", \"0.350\"], [\"63352.60\", \"0.008\"], [\"69223.00\", \"2.134\"], [\"69260.30\", \"6.016\"], [\"69265.50\", \"1.000\"], [\"69300.70\", \"9.000\"], [\"69328.50\", \"3.196\"], [\"69330.60\", \"12.856\"], [\"69330.70\", \"0.038\"], [\"69371.10\", \"11.703\"], [\"69687.90\", \"1.136\"], [\"69847.30\", \"0.000\"], [\"70039.80\", \"0.002\"], [\"70197.80\", \"0.000\"], [\"70202.60\", \"0.003\"], [\"70202.90\", \"0.036\"], [\"70235.20\", \"0.078\"], [\"70251.30\", \"0.002\"], [\"70254.60\", \"0.093\"], [\"70266.40\", \"1.286\"], [\"70266.80\", \"0.003\"], [\"70288.30\", \"0.256\"], [\"70323.10\", \"1.423\"], [\"70324.90\", \"0.026\"], [\"70340.20\", \"0.000\"], [\"70341.60\", \"0.002\"], [\"70342.10\", \"0.256\"], [\"70342.20\", \"0.007\"], [\"70342.30\", \"0.328\"], [\"70345.60\", \"0.005\"], [\"70351.30\", \"0.010\"], [\"70362.80\", \"0.052\"], [\"70363.60\", \"0.920\"], [\"70364.90\", \"0.000\"], [\"70366.00\", \"0.513\"], [\"70367.50\", \"0.003\"], [\"70368.40\", \"0.100\"], [\"70369.50\", \"0.000\"], [\"70374.20\", \"0.154\"], [\"70374.80\", \"0.048\"], [\"70374.90\", \"0.004\"], [\"70377.70\", \"0.129\"], [\"70377.80\", \"0.238\"], [\"70384.80\", \"0.255\"], [\"70385.10\", \"0.660\"], [\"70388.40\", \"0.002\"], [\"70388.50\", \"0.021\"], [\"70389.10\", \"0.065\"], [\"70391.70\", \"0.001\"], [\"70391.80\", \"1.595\"]], \"a\": [[\"70391.90\", \"3.684\"], [\"70394.10\", \"0.063\"], [\"70394.80\", \"0.016\"], [\"70396.20\", \"0.051\"], [\"70402.10\", \"0.005\"], [\"70409.50\", \"0.786\"], [\"70412.00\", \"0.029\"], [\"70414.40\", \"0.000\"], [\"70415.10\", \"0.586\"], [\"70418.30\", \"0.260\"], [\"70424.50\", \"0.000\"], [\"70432.40\", \"0.201\"], [\"70434.10\", \"0.145\"], [\"70435.20\", \"0.002\"], [\"70435.60\", \"0.347\"], [\"70436.30\", \"0.007\"], [\"70437.00\", \"0.005\"], [\"70437.70\", \"0.011\"], [\"70443.20\", \"0.003\"], [\"70443.30\", \"0.258\"], [\"70445.20\", \"0.004\"], [\"70460.60\", \"0.006\"], [\"70462.80\", \"0.209\"], [\"70475.10\", \"7.892\"], [\"70475.40\", \"0.137\"], [\"70508.10\", \"0.088\"], [\"70508.60\", \"0.051\"], [\"70516.90\", \"0.090\"], [\"70519.50\", \"0.008\"], [\"70520.20\", \"0.000\"], [\"70523.80\", \"2.000\"], [\"70524.80\", \"0.002\"], [\"70527.20\", \"0.000\"], [\"70534.20\", \"0.120\"], [\"70538.20\", \"0.081\"], [\"70541.20\", \"6.509\"], [\"70548.20\", \"0.004\"], [\"70555.20\", \"1.142\"], [\"70562.20\", \"0.002\"], [\"70569.20\", \"0.035\"], [\"70601.80\", \"0.011\"], [\"70624.90\", \"0.009\"], [\"70631.90\", \"0.177\"], [\"70635.70\", \"0.002\"], [\"70638.90\", \"0.021\"], [\"70645.90\", \"0.009\"], [\"70652.90\", \"0.016\"], [\"70659.90\", \"0.009\"], [\"70666.90\", \"0.027\"], [\"70673.90\", \"0.026\"], [\"70933.10\", \"0.000\"], [\"70936.30\", \"0.003\"], [\"71095.80\", \"0.000\"], [\"71118.30\", \"0.004\"], [\"71125.50\", \"37.856\"], [\"71331.00\", \"0.004\"], [\"71338.90\", \"45.100\"], [\"71352.30\", \"0.067\"], [\"71379.20\", \"0.000\"], [\"71391.50\", \"2.921\"], [\"71461.90\", \"1.325\"], [\"71519.90\", \"0.000\"], [\"71532.20\", \"0.006\"], [\"71543.80\", \"0.004\"], [\"71756.50\", \"0.004\"], [\"71888.00\", \"39.418\"], [\"73912.10\", \"0.002\"], [\"73929.30\", \"0.000\"]]}", "symbol": "BTCUSDT"}
{"event": "depthUpdate", "raw_payload": "{\"e\": \"depthUpdate\", \"E\": 1773246395678, \"T\": 1773246395676, \"s\": \"BTCUSDT\", \"U\": 10089704795625, \"u\": 10089704801912, \"pu\": 10089704795425, \"b\": [[\"1000.00\", \"26.792\"], [\"5000.00\", \"101.418\"], [\"19991.80\", \"0.830\"], [\"20067.10\", \"0.650\"], [\"20091.80\", \"0.300\"], [\"20191.80\", \"0.730\"], [\"20267.10\", \"0.270\"], [\"66855.10\", \"0.002\"], [\"69261.30\", \"2.018\"], [\"69300.70\", \"10.000\"], [\"69328.50\", \"1.180\"], [\"69371.10\", \"13.701\"], [\"69434.10\", \"2.589\"], [\"69483.70\", \"1.425\"], [\"70121.00\", \"0.001\"], [\"70122.60\", \"0.007\"], [\"70157.80\", \"0.000\"], [\"70188.40\", \"0.000\"], [\"70192.20\", \"0.000\"], [\"70202.70\", \"1.654\"], [\"70210.50\", \"0.043\"], [\"70212.70\", \"0.025\"], [\"70213.90\", \"0.004\"], [\"70214.20\", \"0.002\"], [\"70215.20\", \"0.122\"], [\"70241.30\", \"0.014\"], [\"70251.30\", \"0.016\"], [\"70254.60\", \"0.079\"], [\"70266.80\", \"0.003\"], [\"70267.30\", \"0.000\"], [\"70277.20\", \"0.080\"], [\"70279.40\", \"0.163\"], [\"70287.70\", \"0.252\"], [\"70288.60\", \"0.344\"], [\"70289.60\", \"0.080\"], [\"70290.10\", \"0.084\"], [\"70291.70\", \"0.131\"], [\"70312.70\", \"0.000\"], [\"70314.40\", \"0.002\"], [\"70323.10\", \"1.423\"], [\"70325.40\", \"0.649\"], [\"70328.00\", \"0.049\"], [\"70337.80\", \"0.228\"], [\"70338.00\", \"0.966\"], [\"70342.30\", \"0.328\"], [\"70342.40\", \"0.195\"], [\"70345.50\", \"0.004\"], [\"70346.20\", \"0.274\"], [\"70349.40\", \"0.578\"], [\"70349.50\", \"1.851\"], [\"70351.30\", \"0.010\"], [\"70355.10\", \"0.529\"], [\"70362.20\", \"0.020\"], [\"70375.70\", \"0.002\"], [\"70382.70\", \"0.005\"], [\"70390.90\", \"0.002\"], [\"70391.10\", \"0.002\"], [\"70391.50\", \"0.058\"], [\"70391.60\", \"0.004\"], [\"70391.80\", \"1.538\"]], \"a\": [[\"70391.90\", \"3.682\"], [\"70394.50\", \"0.005\"], [\"70432.40\", \"0.201\"], [\"70438.40\", \"0.005\"], [\"70439.10\", \"0.003\"], [\"70439.80\", \"0.073\"], [\"70440.50\", \"0.007\"], [\"70443.30\", \"0.130\"], [\"70443.40\", \"0.138\"], [\"70460.60\", \"0.006\"], [\"70472.60\", \"1.971\"], [\"70494.00\", \"0.193\"], [\"70516.90\", \"0.090\"], [\"70535.80\", \"0.828\"], [\"70553.90\", \"0.020\"], [\"70557.30\", \"0.002\"], [\"70777.00\", \"1.296\"], [\"70888.00\", \"159.490\"], [\"70999.00\", \"12.526\"], [\"71123.00\", \"0.043\"], [\"71222.00\", \"1.782\"], [\"71307.00\", \"6.249\"], [\"71333.00\", \"202.765\"], [\"71412.50\", \"2.660\"], [\"73924.90\", \"0.050\"], [\"89523.20\", \"0.000\"]]}", "symbol": "BTCUSDT"}
{"event": "depthUpdate", "raw_payload": "{\"e\": \"depthUpdate\", \"E\": 1773246395782, \"T\": 1773246395781, \"s\": \"BTCUSDT\", \"U\": 10089704802108, \"u\": 10089704808810, \"pu\": 10089704801912, \"b\": [[\"5000.00\", \"101.418\"], [\"19991.80\", \"1.000\"], [\"20067.10\", \"0.570\"], [\"20091.80\", \"0.210\"], [\"20191.80\", \"0.820\"], [\"20267.10\", \"0.180\"], [\"66845.70\", \"0.002\"], [\"66848.70\", \"0.007\"], [\"66849.70\", \"0.000\"], [\"69187.80\", \"0.910\"], [\"69230.30\", \"3.003\"], [\"69309.00\", \"0.002\"], [\"69687.90\", \"1.136\"], [\"69874.20\", \"0.000\"], [\"69882.60\", \"0.286\"], [\"70209.00\", \"0.194\"], [\"70238.90\", \"0.090\"], [\"70242.70\", \"0.002\"], [\"70251.30\", \"0.002\"], [\"70254.60\", \"0.093\"], [\"70285.40\", \"0.014\"], [\"70298.40\", \"0.005\"], [\"70302.40\", \"0.004\"], [\"70303.40\", \"0.091\"], [\"70321.80\", \"0.510\"], [\"70334.20\", \"0.000\"], [\"70335.80\", \"0.000\"], [\"70337.80\", \"0.226\"], [\"70338.80\", \"0.019\"], [\"70343.50\", \"1.898\"], [\"70346.20\", \"0.536\"], [\"70348.50\", \"0.002\"], [\"70354.10\", \"0.018\"], [\"70354.20\", \"0.022\"], [\"70359.60\", \"0.002\"], [\"70364.60\", \"0.026\"], [\"70364.70\", \"0.012\"], [\"70377.00\", \"0.002\"], [\"70379.40\", \"0.408\"], [\"70381.30\", \"0.302\"], [\"70383.40\", \"0.003\"], [\"70391.80\", \"1.864\"]], \"a\": [[\"70402.10\", \"0.008\"], [\"70402.50\", \"0.004\"], [\"70403.80\", \"0.344\"], [\"70412.00\", \"0.029\"], [\"70414.60\", \"0.002\"], [\"70416.30\", \"0.337\"], [\"70417.10\", \"0.003\"], [\"70417.90\", \"0.007\"], [\"70418.20\", \"0.009\"], [\"70419.10\", \"0.000\"], [\"70421.80\", \"0.040\"], [\"70427.80\", \"10.439\"], [\"70429.00\", \"0.009\"], [\"70435.20\", \"1.911\"], [\"70464.80\", \"0.017\"], [\"70474.50\", \"0.561\"], [\"70477.60\", \"0.043\"], [\"70494.10\", \"0.099\"], [\"70499.80\", \"13.728\"], [\"70501.30\", \"0.170\"], [\"70503.00\", \"0.091\"], [\"70504.80\", \"0.251\"], [\"70505.70\", \"0.178\"], [\"70510.60\", \"0.091\"], [\"70513.50\", \"0.091\"], [\"70514.80\", \"0.094\"], [\"70842.50\", \"0.000\"], [\"70901.00\", \"0.003\"], [\"70901.70\", \"3.720\"], [\"70909.50\", \"0.002\"], [\"71095.80\", \"0.000\"], [\"71412.50\", \"3.639\"], [\"71482.90\", \"1.956\"]]}", "symbol": "BTCUSDT"}
{"event": "depthUpdate", "raw_payload": "{\"e\": \"depthUpdate\", \"E\": 1773246395886, \"T\": 1773246395885, \"s\": \"BTCUSDT\", \"U\": 10089704808951, \"u\": 10089704815133, \"pu\": 10089704808810, \"b\": [[\"1000.00\", \"26.792\"], [\"5000.00\", \"101.418\"], [\"19991.80\", \"1.170\"], [\"20067.10\", \"0.480\"], [\"20091.80\", \"0.130\"], [\"20191.80\", \"0.910\"], [\"20267.10\", \"0.090\"], [\"33000.00\", \"10.797\"], [\"63352.60\", \"0.010\"], [\"66837.50\", \"0.002\"], [\"66855.10\", \"0.000\"], [\"68716.80\", \"0.002\"], [\"69260.20\", \"1.008\"], [\"69260.30\", \"4.014\"], [\"69300.70\", \"13.000\"], [\"69330.50\", \"1.487\"], [\"69330.60\", \"10.142\"], [\"69335.50\", \"0.864\"], [\"69371.10\", \"19.410\"], [\"69687.90\", \"1.136\"], [\"70026.00\", \"0.000\"], [\"70026.30\", \"0.245\"], [\"70039.80\", \"0.002\"], [\"70103.10\", \"0.000\"], [\"70104.80\", \"0.090\"], [\"70251.30\", \"0.002\"], [\"70254.60\", \"0.093\"], [\"70297.60\", \"0.000\"], [\"70312.50\", \"0.052\"], [\"70313.40\", \"0.004\"], [\"70320.20\", \"0.028\"], [\"70338.80\", \"0.017\"], [\"70339.20\", \"0.006\"], [\"70341.80\", \"0.100\"], [\"70341.90\", \"0.511\"], [\"70342.10\", \"0.256\"], [\"70342.30\", \"0.243\"], [\"70370.90\", \"0.003\"], [\"70373.10\", \"0.010\"], [\"70373.20\", \"0.009\"], [\"70374.20\", \"0.156\"], [\"70374.60\", \"0.000\"], [\"70377.60\", \"0.296\"], [\"70378.50\", \"0.002\"], [\"70390.40\", \"0.002\"], [\"70391.10\", \"0.004\"], [\"70391.50\", \"0.000\"], [\"70391.60\", \"0.002\"], [\"70391.70\", \"0.000\"], [\"70391.80\", \"1.267\"]], \"a\": [[\"70394.50\", \"0.005\"], [\"70402.10\", \"0.008\"], [\"70404.30\", \"0.002\"], [\"70405.10\", \"0.145\"], [\"70405.60\", \"1.279\"], [\"70408.50\", \"0.050\"], [\"70409.00\", \"0.000\"], [\"70411.00\", \"0.076\"], [\"70411.10\", \"0.002\"], [\"70413.80\", \"0.000\"], [\"70428.00\", \"0.082\"], [\"70435.20\", \"1.914\"], [\"70435.70\", \"0.000\"], [\"70633.20\", \"0.000\"], [\"70647.50\", \"2.630\"], [\"70651.00\", \"0.002\"], [\"70728.60\", \"0.097\"], [\"70728.70\", \"0.002\"], [\"70901.70\", \"0.000\"], [\"71095.80\", \"0.000\"], [\"71271.70\", \"0.132\"], [\"71412.60\", \"1.811\"], [\"71427.20\", \"0.000\"], [\"71454.30\", \"0.703\"], [\"71553.30\", \"1.959\"], [\"71553.40\", \"1.600\"], [\"77431.10\", \"0.002\"], [\"89523.20\", \"0.000\"]]}", "symbol": "BTCUSDT"}
{"event": "depthUpdate", "raw_payload": "{\"e\": \"depthUpdate\", \"E\": 1773246395988, \"T\": 1773246395986, \"s\": \"BTCUSDT\", \"U\": 10089704815229, \"u\": 10089704820929, \"pu\": 10089704815133, \"b\": [[\"1000.00\", \"26.792\"], [\"5000.00\", \"101.418\"], [\"19991.80\", \"1.340\"], [\"20067.10\", \"0.400\"], [\"20091.80\", \"0.040\"], [\"20191.80\", \"0.990\"], [\"20267.10\", \"0.010\"], [\"33000.00\", \"10.793\"], [\"63352.60\", \"0.008\"], [\"66845.70\", \"0.000\"], [\"68984.00\", \"0.006\"], [\"69190.60\", \"0.216\"], [\"69223.00\", \"1.124\"], [\"69230.30\", \"4.004\"], [\"69245.40\", \"0.004\"], [\"69260.30\", \"3.013\"], [\"69265.50\", \"2.000\"], [\"69300.70\", \"14.000\"], [\"69330.60\", \"9.142\"], [\"69366.50\", \"0.291\"], [\"69371.10\", \"20.409\"], [\"69401.00\", \"1.434\"], [\"69441.50\", \"2.852\"], [\"69471.30\", \"2.139\"], [\"69511.90\", \"1.445\"], [\"69687.90\", \"1.136\"], [\"69708.70\", \"2.840\"], [\"69748.00\", \"0.715\"], [\"69800.00\", \"29.571\"], [\"70249.40\", \"0.052\"], [\"70251.30\", \"0.016\"], [\"70254.60\", \"0.079\"], [\"70266.20\", \"0.012\"], [\"70303.50\", \"0.107\"], [\"70303.70\", \"0.008\"], [\"70329.30\", \"0.087\"], [\"70329.60\", \"0.004\"], [\"70336.60\", \"0.005\"], [\"70338.90\", \"0.410\"], [\"70339.20\", \"0.004\"], [\"70341.60\", \"0.087\"], [\"70341.70\", \"10.230\"], [\"70341.80\", \"0.015\"], [\"70346.00\", \"0.004\"], [\"70350.20\", \"0.040\"], [\"70351.50\", \"0.000\"], [\"70356.30\", \"0.207\"], [\"70360.40\", \"0.006\"], [\"70362.10\", \"0.189\"], [\"70363.40\", \"0.011\"], [\"70364.70\", \"0.014\"], [\"70365.30\", \"0.004\"], [\"70370.80\", \"0.014\"], [\"70372.20\", \"0.001\"], [\"70374.20\", \"0.295\"], [\"70381.80\", \"0.005\"], [\"70382.70\", \"0.002\"], [\"70383.40\", \"0.006\"], [\"70384.60\", \"0.015\"], [\"70391.80\", \"1.275\"]], \"a\": [[\"70391.90\", \"3.662\"], [\"70401.90\", \"0.003\"], [\"70405.70\", \"0.223\"], [\"70408.00\", \"0.075\"], [\"70422.80\", \"0.009\"], [\"70422.90\", \"0.009\"], [\"70423.50\", \"0.017\"], [\"70423.60\", \"0.212\"], [\"70430.10\", \"0.049\"], [\"70443.00\", \"0.002\"], [\"70443.10\", \"0.130\"], [\"70443.20\", \"0.003\"], [\"70443.40\", \"0.010\"], [\"70458.50\", \"1.008\"], [\"70458.80\", \"3.502\"], [\"70461.60\", \"0.513\"], [\"70475.50\", \"0.024\"], [\"70475.60\", \"0.008\"], [\"70488.70\", \"0.188\"], [\"70489.30\", \"0.018\"], [\"70540.70\", \"0.002\"], [\"71095.80\", \"0.000\"], [\"71352.30\", \"0.000\"], [\"71708.10\", \"0.556\"], [\"77431.10\", \"0.000\"]]}", "symbol": "BTCUSDT"}
{"event": "depthUpdate", "raw_payload": "{\"e\": \"depthUpdate\", \"E\": 1773246396090, \"T\": 1773246396089, \"s\": \"BTCUSDT\", \"U\": 10089704820961, \"u\": 10089704828474, \"pu\": 10089704820929, \"b\": [[\"5000.00\", \"101.418\"], [\"19991.80\", \"1.510\"], [\"20067.10\", \"0.310\"], [\"20086.20\", \"0.000\"], [\"20087.40\", \"0.000\"], [\"20088.90\", \"0.000\"], [\"20090.80\", \"0.000\"], [\"20091.80\", \"0.080\"], [\"20191.80\", \"0.920\"], [\"20267.10\", \"0.000\"], [\"56294.00\", \"0.000\"], [\"66872.00\", \"0.002\"], [\"68907.30\", \"0.000\"], [\"68948.80\", \"0.146\"], [\"69259.00\", \"0.000\"], [\"69259.40\", \"0.000\"], [\"69264.60\", \"0.019\"], [\"69300.70\", \"17.114\"], [\"69324.90\", \"0.008\"], [\"69328.50\", \"0.172\"], [\"69330.60\", \"8.428\"], [\"69335.00\", \"2.737\"], [\"69371.10\", \"24.120\"], [\"69401.00\", \"0.721\"], [\"69441.50\", \"3.565\"], [\"69471.30\", \"1.426\"], [\"69511.90\", \"2.157\"], [\"69574.80\", \"0.900\"], [\"69624.50\", \"2.915\"], [\"69687.90\", \"1.136\"], [\"69708.80\", \"0.000\"], [\"69747.40\", \"0.724\"], [\"69906.20\", \"3.720\"], [\"69918.10\", \"0.650\"], [\"70026.10\", \"1.261\"], [\"70039.90\", \"0.007\"], [\"70078.60\", \"0.000\"], [\"70082.90\", \"0.053\"], [\"70122.60\", \"0.000\"], [\"70251.20\", \"0.031\"], [\"70280.60\", \"0.036\"], [\"70297.70\", \"0.071\"], [\"70297.90\", \"0.362\"], [\"70300.00\", \"1.476\"], [\"70304.80\", \"0.074\"], [\"70311.30\", \"0.387\"], [\"70311.80\", \"0.081\"], [\"70329.90\", \"0.070\"], [\"70331.00\", \"0.005\"], [\"70331.70\", \"0.602\"], [\"70338.90\", \"0.408\"], [\"70339.30\", \"0.007\"], [\"70341.00\", \"0.342\"], [\"70343.00\", \"2.101\"], [\"70349.60\", \"1.552\"], [\"70350.00\", \"0.006\"], [\"70351.30\", \"0.250\"], [\"70357.00\", \"0.005\"], [\"70357.90\", \"0.220\"], [\"70364.00\", \"0.009\"], [\"70365.40\", \"0.114\"], [\"70367.30\", \"0.377\"], [\"70369.50\", \"0.007\"], [\"70370.80\", \"0.007\"], [\"70374.20\", \"0.156\"], [\"70377.80\", \"0.238\"], [\"70381.40\", \"0.433\"], [\"70382.40\", \"0.403\"], [\"70384.80\", \"0.255\"], [\"70391.10\", \"0.002\"], [\"70391.50\", \"0.060\"], [\"70391.60\", \"0.004\"], [\"70391.80\", \"1.392\"]], \"a\": [[\"70391.90\", \"3.667\"], [\"70394.50\", \"0.005\"], [\"70398.90\", \"0.031\"], [\"70404.60\", \"0.000\"], [\"70405.90\", \"0.511\"], [\"70406.00\", \"0.004\"], [\"70412.00\", \"0.009\"], [\"70413.00\", \"1.178\"], [\"70419.10\", \"0.020\"], [\"70420.00\", \"1.081\"], [\"70422.80\", \"0.009\"], [\"70422.90\", \"0.009\"], [\"70423.50\", \"0.017\"], [\"70423.60\", \"0.212\"], [\"70427.00\", \"0.002\"], [\"70429.10\", \"0.511\"], [\"70429.20\", \"0.002\"], [\"70429.80\", \"0.002\"], [\"70429.90\", \"0.006\"], [\"70432.00\", \"0.003\"], [\"70434.00\", \"0.008\"], [\"70473.90\", \"0.071\"], [\"70474.20\", \"0.044\"], [\"70480.90\", \"0.201\"], [\"70481.20\", \"0.003\"], [\"70488.00\", \"0.264\"], [\"70488.30\", \"0.041\"], [\"70512.90\", \"0.543\"], [\"70570.10\", \"0.003\"], [\"70571.60\", \"0.002\"], [\"70627.10\", \"0.006\"], [\"70650.90\", \"0.006\"], [\"70745.30\", \"0.362\"], [\"70877.50\", \"3.720\"], [\"71095.80\", \"0.000\"], [\"71133.80\", \"0.004\"], [\"72335.60\", \"0.000\"], [\"73920.00\", \"0.300\"], [\"73937.50\", \"0.009\"], [\"89523.20\", \"0.000\"]]}", "symbol": "BTCUSDT"}
{"event": "depthUpdate", "raw_payload": "{\"e\": \"depthUpdate\", \"E\": 1773246396192, \"T\": 1773246396191, \"s\": \"BTCUSDT\", \"U\": 10089704828498, \"u\": 10089704844583, \"pu\": 10089704828474, \"b\": [[\"1000.00\", \"26.792\"], [\"5000.00\", \"101.418\"], [\"19891.80\", \"0.030\"], [\"19991.80\", \"1.620\"], [\"20067.10\", \"0.260\"], [\"20074.80\", \"0.010\"], [\"20076.80\", \"0.000\"], [\"20079.10\", \"0.000\"], [\"20079.90\", \"0.000\"], [\"20080.00\", \"0.000\"], [\"20082.60\", \"0.000\"], [\"20083.10\", \"0.000\"], [\"20084.20\", \"0.000\"], [\"20091.80\", \"0.160\"], [\"20191.80\", \"0.840\"], [\"40000.00\", \"50.521\"], [\"66837.50\", \"0.000\"], [\"66852.70\", \"0.002\"], [\"69223.00\", \"0.114\"], [\"69265.50\", \"3.000\"], [\"69330.50\", \"0.773\"], [\"69330.60\", \"7.714\"], [\"69335.00\", \"2.023\"], [\"69371.10\", \"26.262\"], [\"69497.70\", \"2.136\"], [\"69506.50\", \"3.504\"], [\"69510.80\", \"0.712\"], [\"69547.10\", \"2.136\"], [\"69568.00\", \"1.593\"], [\"69617.50\", \"0.711\"], [\"69686.60\", \"0.000\"], [\"69687.90\", \"1.136\"], [\"69723.10\", \"2.226\"], [\"69787.90\", \"0.005\"], [\"69828.60\", \"0.716\"], [\"69906.20\", \"0.000\"], [\"69907.90\", \"3.948\"], [\"69928.60\", \"0.014\"], [\"69928.80\", \"0.062\"], [\"69969.40\", \"0.714\"], [\"69980.00\", \"0.304\"], [\"70004.60\", \"0.056\"], [\"70039.80\", \"0.002\"], [\"70039.90\", \"0.000\"], [\"70069.20\", \"0.000\"], [\"70069.80\", \"0.419\"], [\"70080.90\", \"0.000\"], [\"70084.50\", \"0.012\"], [\"70110.20\", \"0.213\"], [\"70132.60\", \"0.000\"], [\"70157.80\", \"0.007\"], [\"70180.10\", \"0.002\"], [\"70206.10\", \"0.004\"], [\"70212.20\", \"0.000\"], [\"70213.40\", \"0.006\"], [\"70214.40\", \"0.513\"], [\"70217.70\", \"0.002\"], [\"70218.70\", \"0.000\"], [\"70220.70\", \"0.196\"], [\"70220.80\", \"0.202\"], [\"70231.20\", \"0.006\"], [\"70248.40\", \"0.210\"], [\"70251.30\", \"0.002\"], [\"70256.80\", \"0.602\"], [\"70260.60\", \"0.511\"], [\"70263.80\", \"0.209\"], [\"70286.00\", \"4.065\"], [\"70287.00\", \"1.267\"], [\"70287.60\", \"0.080\"], [\"70289.70\", \"0.082\"], [\"70294.60\", \"0.041\"], [\"70303.80\", \"0.471\"], [\"70307.30\", \"0.124\"], [\"70310.80\", \"0.352\"], [\"70320.30\", \"0.297\"], [\"70329.50\", \"0.043\"], [\"70337.50\", \"0.014\"], [\"70339.30\", \"0.005\"], [\"70339.50\", \"0.104\"], [\"70341.60\", \"0.002\"], [\"70342.20\", \"0.007\"], [\"70342.90\", \"1.068\"], [\"70343.10\", \"0.092\"], [\"70343.20\", \"0.004\"], [\"70343.90\", \"0.117\"], [\"70347.30\", \"0.000\"], [\"70349.20\", \"0.016\"], [\"70349.30\", \"0.017\"], [\"70349.60\", \"1.552\"], [\"70349.80\", \"0.003\"], [\"70355.30\", \"0.380\"], [\"70355.90\", \"0.080\"], [\"70357.90\", \"0.200\"], [\"70359.40\", \"0.059\"], [\"70361.10\", \"0.008\"], [\"70361.20\", \"0.000\"], [\"70361.80\", \"0.008\"], [\"70361.90\", \"0.002\"], [\"70362.10\", \"0.065\"], [\"70363.60\", \"0.616\"], [\"70366.00\", \"0.002\"], [\"70366.10\", \"0.020\"], [\"70366.40\", \"0.399\"], [\"70366.50\", \"0.512\"], [\"70367.30\", \"0.248\"], [\"70367.60\", \"0.003\"], [\"70368.00\", \"1.145\"], [\"70368.20\", \"0.005\"], [\"70369.50\", \"0.000\"], [\"70369.80\", \"0.008\"], [\"70369.90\", \"0.000\"], [\"70370.10\", \"0.181\"], [\"70370.20\", \"0.128\"], [\"70370.40\", \"0.006\"], [\"70370.80\", \"0.000\"], [\"70370.90\", \"0.003\"], [\"70371.30\", \"0.000\"], [\"70371.50\", \"0.000\"], [\"70371.70\", \"0.004\"], [\"70372.30\", \"0.002\"], [\"70372.40\", \"0.012\"], [\"70372.60\", \"0.002\"], [\"70372.70\", \"0.005\"], [\"70372.80\", \"0.180\"], [\"70372.90\", \"0.566\"], [\"70373.00\", \"0.028\"], [\"70373.20\", \"0.002\"], [\"70373.30\", \"0.007\"], [\"70373.60\", \"0.003\"], [\"70373.90\", \"0.110\"], [\"70374.20\", \"0.156\"], [\"70374.30\", \"1.207\"], [\"70374.90\", \"0.011\"], [\"70375.20\", \"0.000\"], [\"70375.30\", \"0.181\"], [\"70375.40\", \"0.004\"], [\"70375.50\", \"0.284\"], [\"70375.70\", \"0.002\"], [\"70376.20\", \"0.253\"], [\"70376.30\", \"0.002\"], [\"70376.70\", \"0.162\"], [\"70376.80\", \"0.120\"], [\"70376.90\", \"0.000\"], [\"70377.00\", \"0.055\"], [\"70377.10\", \"0.061\"], [\"70377.20\", \"0.142\"], [\"70377.40\", \"0.082\"], [\"70377.50\", \"0.181\"], [\"70377.60\", \"0.519\"], [\"70377.70\", \"0.447\"], [\"70377.80\", \"0.238\"], [\"70377.90\", \"0.003\"], [\"70378.40\", \"0.002\"], [\"70378.50\", \"0.002\"], [\"70378.60\", \"0.000\"], [\"70378.70\", \"0.003\"], [\"70378.80\", \"0.000\"], [\"70379.00\", \"0.002\"], [\"70379.10\", \"0.001\"], [\"70379.20\", \"0.040\"], [\"70379.30\", \"0.000\"], [\"70379.40\", \"0.008\"], [\"70379.50\", \"0.000\"], [\"70379.60\", \"0.003\"], [\"70380.10\", \"0.004\"], [\"70380.60\", \"0.010\"], [\"70380.70\", \"0.038\"], [\"70380.80\", \"0.000\"], [\"70380.90\", \"0.470\"], [\"70381.00\", \"0.001\"], [\"70381.20\", \"0.000\"], [\"70381.40\", \"0.002\"], [\"70381.50\", \"0.003\"], [\"70381.70\", \"0.005\"], [\"70381.90\", \"0.202\"], [\"70382.40\", \"0.002\"], [\"70382.60\", \"0.003\"], [\"70382.80\", \"0.000\"], [\"70383.40\", \"0.006\"], [\"70383.70\", \"0.001\"], [\"70384.20\", \"0.001\"], [\"70384.60\", \"0.015\"], [\"70384.90\", \"0.258\"], [\"70385.20\", \"0.005\"], [\"70386.30\", \"0.002\"], [\"70387.60\", \"0.001\"], [\"70387.70\", \"0.047\"], [\"70391.60\", \"0.004\"], [\"70391.70\", \"0.001\"], [\"70391.80\", \"1.471\"]], \"a\": [[\"70391.90\", \"4.326\"], [\"70392.00\", \"0.003\"], [\"70392.20\", \"0.000\"], [\"70393.40\", \"0.000\"], [\"70393.50\", \"0.033\"], [\"70395.90\", \"0.105\"], [\"70396.30\", \"0.001\"], [\"70396.40\", \"0.003\"], [\"70396.60\", \"0.002\"], [\"70397.40\", \"0.017\"], [\"70398.40\", \"0.264\"], [\"70398.50\", \"0.344\"], [\"70398.60\", \"0.001\"], [\"70399.10\", \"0.201\"], [\"70399.80\", \"0.003\"], [\"70399.90\", \"0.513\"], [\"70401.10\", \"0.105\"], [\"70401.20\", \"0.003\"], [\"70401.30\", \"0.002\"], [\"70401.60\", \"0.009\"], [\"70402.00\", \"0.006\"], [\"70402.10\", \"0.516\"], [\"70402.90\", \"1.066\"], [\"70403.00\", \"0.296\"], [\"70403.10\", \"0.006\"], [\"70403.70\", \"0.005\"], [\"70403.80\", \"0.002\"], [\"70404.20\", \"0.352\"], [\"70404.40\", \"0.009\"], [\"70404.70\", \"0.536\"], [\"70404.80\", \"0.206\"], [\"70404.90\", \"0.039\"], [\"70405.10\", \"0.045\"], [\"70405.20\", \"0.005\"], [\"70405.50\", \"0.030\"], [\"70405.60\", \"0.213\"], [\"70405.80\", \"0.004\"], [\"70405.90\", \"0.070\"], [\"70406.10\", \"0.154\"], [\"70406.20\", \"0.149\"], [\"70406.40\", \"0.103\"], [\"70406.60\", \"0.002\"], [\"70406.70\", \"0.570\"], [\"70406.90\", \"0.511\"], [\"70407.20\", \"0.005\"], [\"70407.40\", \"0.700\"], [\"70407.50\", \"0.002\"], [\"70407.70\", \"0.002\"], [\"70408.00\", \"0.002\"], [\"70408.20\", \"0.006\"], [\"70408.40\", \"0.004\"], [\"70408.50\", \"0.043\"], [\"70408.70\", \"0.060\"], [\"70408.80\", \"0.234\"], [\"70409.10\", \"1.755\"], [\"70409.20\", \"0.188\"], [\"70409.30\", \"0.003\"], [\"70409.50\", \"0.006\"], [\"70409.80\", \"0.003\"], [\"70410.40\", \"0.000\"], [\"70410.90\", \"0.004\"], [\"70411.10\", \"0.073\"], [\"70411.20\", \"0.004\"], [\"70411.30\", \"0.000\"], [\"70411.50\", \"0.000\"], [\"70411.80\", \"0.007\"], [\"70412.00\", \"0.002\"], [\"70412.10\", \"0.000\"], [\"70412.30\", \"0.347\"], [\"70412.40\", \"0.003\"], [\"70412.80\", \"0.192\"], [\"70412.90\", \"0.000\"], [\"70413.00\", \"0.112\"], [\"70413.10\", \"0.004\"], [\"70413.20\", \"0.002\"], [\"70413.30\", \"0.014\"], [\"70413.40\", \"0.578\"], [\"70413.60\", \"0.002\"], [\"70413.70\", \"0.004\"], [\"70413.80\", \"0.000\"], [\"70414.30\", \"0.092\"], [\"70414.50\", \"0.350\"], [\"70415.00\", \"1.071\"], [\"70415.30\", \"0.009\"], [\"70415.40\", \"0.005\"], [\"70415.70\", \"0.013\"], [\"70415.90\", \"0.519\"], [\"70416.00\", \"0.271\"], [\"70416.10\", \"0.371\"], [\"70416.30\", \"0.778\"], [\"70416.90\", \"0.000\"], [\"70417.10\", \"0.003\"], [\"70417.20\", \"0.000\"], [\"70417.50\", \"0.143\"], [\"70417.60\", \"0.226\"], [\"70417.90\", \"0.000\"], [\"70418.20\", \"0.002\"], [\"70418.30\", \"0.260\"], [\"70418.80\", \"0.003\"], [\"70419.10\", \"0.000\"], [\"70419.30\", \"0.009\"], [\"70419.50\", \"0.093\"], [\"70419.60\", \"0.073\"], [\"70419.70\", \"0.198\"], [\"70421.00\", \"0.009\"], [\"70421.30\", \"0.001\"], [\"70421.60\", \"0.007\"], [\"70421.90\", \"0.002\"], [\"70422.80\", \"0.000\"], [\"70422.90\", \"0.000\"], [\"70423.50\", \"0.026\"], [\"70423.60\", \"0.203\"], [\"70423.90\", \"0.000\"], [\"70424.20\", \"0.000\"], [\"70424.90\", \"0.000\"], [\"70425.00\", \"0.017\"], [\"70425.60\", \"0.002\"], [\"70425.70\", \"0.007\"], [\"70426.40\", \"0.020\"], [\"70426.70\", \"1.213\"], [\"70427.10\", \"0.345\"], [\"70427.40\", \"0.002\"], [\"70428.00\", \"0.002\"], [\"70428.70\", \"0.016\"], [\"70428.80\", \"0.000\"], [\"70429.00\", \"0.009\"], [\"70429.80\", \"0.002\"], [\"70429.90\", \"0.004\"], [\"70430.10\", \"0.049\"], [\"70430.30\", \"0.002\"], [\"70430.50\", \"0.870\"], [\"70430.60\", \"2.897\"], [\"70430.70\", \"0.007\"], [\"70431.80\", \"0.007\"], [\"70431.90\", \"0.000\"], [\"70432.20\", \"1.070\"], [\"70435.10\", \"0.082\"], [\"70436.90\", \"0.000\"], [\"70440.10\", \"0.048\"], [\"70443.10\", \"0.002\"], [\"70443.20\", \"0.131\"], [\"70444.70\", \"1.247\"], [\"70448.10\", \"1.284\"], [\"70452.00\", \"0.652\"], [\"70458.40\", \"0.002\"], [\"70458.80\", \"3.505\"], [\"70459.70\", \"0.002\"], [\"70459.80\", \"0.382\"], [\"70465.50\", \"0.001\"], [\"70471.50\", \"0.267\"], [\"70472.90\", \"0.002\"], [\"70474.00\", \"0.047\"], [\"70474.90\", \"1.255\"], [\"70483.00\", \"0.115\"], [\"70483.10\", \"1.110\"], [\"70483.40\", \"0.203\"], [\"70490.00\", \"0.537\"], [\"70492.40\", \"0.000\"], [\"70492.80\", \"6.850\"], [\"70496.90\", \"0.342\"], [\"70502.10\", \"0.080\"], [\"70522.10\", \"0.000\"], [\"70526.00\", \"0.000\"], [\"70535.50\", \"0.000\"], [\"70538.70\", \"0.291\"], [\"70539.10\", \"0.000\"], [\"70539.30\", \"0.039\"], [\"70542.70\", \"0.093\"], [\"70547.80\", \"0.141\"], [\"70554.50\", \"3.126\"], [\"70554.60\", \"12.732\"], [\"70555.20\", \"0.062\"], [\"70568.20\", \"0.188\"], [\"70568.70\", \"0.075\"], [\"70571.60\", \"0.082\"], [\"70575.00\", \"0.000\"], [\"70579.50\", \"0.000\"], [\"70590.50\", \"0.000\"], [\"70742.10\", \"0.122\"], [\"70805.10\", \"0.002\"], [\"70836.70\", \"0.000\"], [\"70875.80\", \"3.720\"], [\"70877.50\", \"0.000\"], [\"71095.80\", \"0.000\"], [\"71373.80\", \"0.700\"], [\"71452.60\", \"0.007\"]]}", "symbol": "BTCUSDT"}
{"event": "depthUpdate", "raw_payload": "{\"e\": \"depthUpdate\", \"E\": 1773246396294, \"T\": 1773246396293, \"s\": \"BTCUSDT\", \"U\": 10089704844656, \"u\": 10089704868689, \"pu\": 10089704844583, \"b\": [[\"1000.00\", \"26.792\"], [\"5000.00\", \"101.418\"], [\"19887.30\", \"0.050\"], [\"19889.50\", \"0.010\"], [\"19891.10\", \"0.010\"], [\"19891.80\", \"0.050\"], [\"19987.30\", \"0.040\"], [\"19987.60\", \"0.010\"], [\"19989.70\", \"0.010\"], [\"19991.80\", \"1.550\"], [\"20070.40\", \"0.000\"], [\"20072.70\", \"0.000\"], [\"20072.80\", \"0.000\"], [\"20073.30\", \"0.000\"], [\"20074.80\", \"0.000\"], [\"20087.30\", \"0.050\"], [\"20088.90\", \"0.010\"], [\"20091.00\", \"0.010\"], [\"20091.80\", \"0.180\"], [\"20191.80\", \"0.750\"], [\"56310.00\", \"100.007\"], [\"66872.20\", \"0.006\"], [\"67940.00\", \"0.016\"], [\"68985.60\", \"0.000\"], [\"69471.30\", \"0.713\"], [\"69497.70\", \"0.712\"], [\"69508.20\", \"0.712\"], [\"69543.40\", \"0.738\"], [\"69547.10\", \"2.848\"], [\"69568.00\", \"0.169\"], [\"69612.00\", \"1.076\"], [\"69613.80\", \"0.711\"], [\"69615.60\", \"1.138\"], [\"69650.80\", \"0.715\"], [\"69672.60\", \"0.050\"], [\"69673.60\", \"0.710\"], [\"69683.40\", \"0.000\"], [\"69708.70\", \"2.130\"], [\"69708.80\", \"0.781\"], [\"69721.20\", \"0.710\"], [\"69754.60\", \"1.263\"], [\"69907.90\", \"0.228\"], [\"69951.00\", \"0.134\"], [\"70077.90\", \"0.000\"], [\"70083.00\", \"0.000\"], [\"70175.60\", \"0.001\"], [\"70191.40\", \"0.003\"], [\"70194.90\", \"0.003\"], [\"70245.80\", \"0.000\"], [\"70267.20\", \"0.101\"], [\"70294.40\", \"0.193\"], [\"70295.40\", \"0.016\"], [\"70296.90\", \"0.402\"], [\"70303.00\", \"2.042\"], [\"70303.10\", \"0.089\"], [\"70303.30\", \"0.084\"], [\"70303.80\", \"0.504\"], [\"70304.60\", \"0.000\"], [\"70305.40\", \"0.003\"], [\"70308.80\", \"0.167\"], [\"70309.50\", \"0.342\"], [\"70310.30\", \"0.009\"], [\"70310.50\", \"0.000\"], [\"70311.90\", \"0.000\"], [\"70314.00\", \"0.002\"], [\"70314.30\", \"0.440\"], [\"70315.30\", \"0.515\"], [\"70317.50\", \"0.249\"], [\"70321.10\", \"0.083\"], [\"70321.90\", \"0.002\"], [\"70322.00\", \"0.004\"], [\"70322.90\", \"0.001\"], [\"70332.40\", \"0.940\"], [\"70332.50\", \"0.045\"], [\"70333.20\", \"0.003\"], [\"70333.90\", \"0.003\"], [\"70334.40\", \"0.576\"], [\"70334.70\", \"0.000\"], [\"70335.50\", \"0.048\"], [\"70335.70\", \"0.002\"], [\"70336.10\", \"0.002\"], [\"70336.80\", \"0.511\"], [\"70337.00\", \"0.002\"], [\"70337.30\", \"0.031\"], [\"70337.40\", \"0.002\"], [\"70339.00\", \"1.041\"], [\"70339.20\", \"0.004\"], [\"70339.50\", \"0.102\"], [\"70339.60\", \"0.188\"], [\"70340.40\", \"0.087\"], [\"70341.10\", \"0.000\"], [\"70341.40\", \"0.916\"], [\"70341.80\", \"0.015\"], [\"70343.00\", \"2.101\"], [\"70343.10\", \"0.007\"], [\"70343.60\", \"0.003\"], [\"70343.90\", \"0.000\"], [\"70344.30\", \"0.039\"], [\"70345.30\", \"0.212\"], [\"70345.40\", \"0.572\"], [\"70345.50\", \"0.140\"], [\"70347.40\", \"0.237\"], [\"70347.60\", \"0.000\"], [\"70347.90\", \"0.590\"], [\"70348.00\", \"0.003\"], [\"70349.30\", \"0.019\"], [\"70349.50\", \"1.070\"], [\"70349.60\", \"1.501\"], [\"70349.70\", \"0.251\"], [\"70350.10\", \"0.058\"], [\"70350.20\", \"0.040\"], [\"70351.30\", \"0.111\"], [\"70351.40\", \"0.000\"], [\"70352.40\", \"0.000\"], [\"70352.80\", \"0.002\"], [\"70353.10\", \"0.195\"], [\"70353.20\", \"0.511\"], [\"70353.30\", \"0.288\"], [\"70355.00\", \"0.004\"], [\"70355.10\", \"0.018\"], [\"70355.20\", \"1.082\"], [\"70355.30\", \"0.018\"], [\"70355.40\", \"0.006\"], [\"70356.50\", \"0.009\"], [\"70356.60\", \"3.307\"], [\"70356.70\", \"1.652\"], [\"70356.90\", \"0.071\"], [\"70357.30\", \"0.000\"], [\"70358.80\", \"0.054\"], [\"70359.30\", \"0.007\"], [\"70359.40\", \"0.003\"], [\"70360.20\", \"0.199\"], [\"70360.40\", \"0.000\"], [\"70360.50\", \"0.207\"], [\"70360.80\", \"0.006\"], [\"70360.90\", \"0.511\"], [\"70361.00\", \"0.002\"], [\"70361.10\", \"0.011\"], [\"70361.20\", \"0.004\"], [\"70361.50\", \"0.377\"], [\"70361.60\", \"1.924\"], [\"70361.80\", \"0.006\"], [\"70361.90\", \"0.000\"], [\"70362.10\", \"0.068\"], [\"70362.30\", \"0.073\"], [\"70362.60\", \"0.639\"], [\"70362.70\", \"0.065\"], [\"70362.80\", \"0.000\"], [\"70363.00\", \"0.002\"], [\"70363.10\", \"0.077\"], [\"70363.20\", \"0.002\"], [\"70363.30\", \"0.009\"], [\"70363.60\", \"0.619\"], [\"70363.80\", \"0.016\"], [\"70363.90\", \"0.511\"], [\"70364.00\", \"0.295\"], [\"70364.80\", \"0.000\"], [\"70365.20\", \"0.009\"], [\"70365.40\", \"0.114\"], [\"70365.50\", \"0.000\"], [\"70365.90\", \"0.007\"], [\"70366.40\", \"0.057\"], [\"70366.50\", \"0.001\"], [\"70366.60\", \"0.000\"], [\"70367.00\", \"0.099\"], [\"70367.20\", \"0.002\"], [\"70367.30\", \"0.248\"], [\"70367.50\", \"0.005\"], [\"70368.00\", \"0.008\"], [\"70368.10\", \"1.069\"], [\"70368.20\", \"1.557\"], [\"70368.30\", \"0.289\"], [\"70368.40\", \"0.029\"], [\"70368.50\", \"0.002\"], [\"70368.70\", \"0.000\"], [\"70368.80\", \"0.007\"], [\"70368.90\", \"0.021\"], [\"70369.00\", \"0.020\"], [\"70369.40\", \"0.000\"], [\"70369.70\", \"0.015\"], [\"70369.80\", \"0.292\"], [\"70369.90\", \"0.003\"], [\"70370.00\", \"0.266\"], [\"70370.40\", \"0.006\"], [\"70370.50\", \"0.156\"], [\"70370.60\", \"0.641\"], [\"70370.70\", \"0.000\"], [\"70370.80\", \"0.450\"], [\"70370.90\", \"0.691\"], [\"70371.00\", \"0.405\"], [\"70371.20\", \"0.464\"], [\"70371.50\", \"0.139\"], [\"70372.10\", \"0.000\"], [\"70372.40\", \"0.005\"], [\"70372.70\", \"0.003\"], [\"70372.90\", \"0.446\"], [\"70373.00\", \"0.002\"], [\"70373.10\", \"0.003\"], [\"70373.20\", \"0.002\"], [\"70373.30\", \"0.002\"], [\"70373.40\", \"0.003\"], [\"70373.50\", \"0.212\"], [\"70373.70\", \"0.000\"], [\"70373.80\", \"0.009\"], [\"70374.10\", \"0.401\"], [\"70374.20\", \"0.037\"], [\"70374.30\", \"0.002\"], [\"70374.40\", \"0.110\"], [\"70374.50\", \"0.344\"], [\"70374.80\", \"0.048\"], [\"70374.90\", \"0.004\"], [\"70375.00\", \"0.005\"], [\"70375.40\", \"0.403\"], [\"70375.50\", \"0.000\"], [\"70375.60\", \"0.003\"], [\"70375.70\", \"0.002\"], [\"70376.00\", \"0.003\"], [\"70376.10\", \"0.005\"], [\"70376.20\", \"0.246\"], [\"70376.50\", \"0.207\"], [\"70376.70\", \"0.163\"], [\"70376.90\", \"0.000\"], [\"70377.00\", \"0.002\"], [\"70377.10\", \"0.061\"], [\"70377.20\", \"0.000\"], [\"70377.40\", \"0.083\"], [\"70377.50\", \"0.184\"], [\"70377.60\", \"0.213\"], [\"70377.70\", \"0.403\"], [\"70377.80\", \"0.038\"], [\"70377.90\", \"0.388\"], [\"70378.00\", \"0.054\"], [\"70378.30\", \"0.000\"], [\"70378.40\", \"0.002\"], [\"70378.50\", \"0.002\"], [\"70378.80\", \"0.000\"], [\"70379.20\", \"0.471\"], [\"70379.40\", \"0.008\"], [\"70379.70\", \"0.002\"], [\"70379.80\", \"0.000\"], [\"70379.90\", \"0.001\"], [\"70380.00\", \"0.016\"], [\"70380.10\", \"0.202\"], [\"70380.20\", \"0.003\"], [\"70380.30\", \"0.005\"], [\"70380.40\", \"0.000\"], [\"70380.50\", \"0.266\"], [\"70380.60\", \"0.404\"], [\"70380.70\", \"0.001\"], [\"70380.90\", \"0.000\"], [\"70381.00\", \"0.001\"], [\"70381.20\", \"0.000\"], [\"70381.30\", \"0.000\"], [\"70381.40\", \"0.005\"], [\"70381.50\", \"0.005\"], [\"70381.60\", \"0.000\"], [\"70381.90\", \"0.456\"], [\"70382.00\", \"1.061\"], [\"70382.10\", \"0.015\"], [\"70382.50\", \"0.059\"], [\"70382.60\", \"0.005\"], [\"70382.70\", \"0.000\"], [\"70382.90\", \"0.007\"], [\"70383.20\", \"0.001\"], [\"70383.40\", \"0.003\"], [\"70383.50\", \"0.003\"], [\"70383.60\", \"0.000\"], [\"70383.70\", \"0.002\"], [\"70384.00\", \"0.000\"], [\"70384.20\", \"0.000\"], [\"70384.30\", \"0.000\"], [\"70384.40\", \"0.002\"], [\"70384.60\", \"0.000\"], [\"70384.70\", \"0.002\"], [\"70384.80\", \"0.000\"], [\"70384.90\", \"0.006\"], [\"70385.00\", \"0.004\"], [\"70385.10\", \"0.002\"], [\"70385.20\", \"0.003\"], [\"70385.30\", \"0.002\"], [\"70385.40\", \"0.000\"], [\"70385.60\", \"0.000\"], [\"70385.70\", \"0.000\"], [\"70385.90\", \"0.003\"], [\"70386.00\", \"0.000\"], [\"70386.20\", \"0.003\"], [\"70386.30\", \"0.000\"], [\"70386.40\", \"1.000\"], [\"70386.60\", \"0.000\"], [\"70386.80\", \"0.002\"], [\"70387.00\", \"0.000\"], [\"70387.10\", \"0.000\"], [\"70387.20\", \"0.003\"], [\"70387.30\", \"2.977\"], [\"70387.40\", \"0.000\"], [\"70387.60\", \"0.000\"], [\"70387.70\", \"0.000\"], [\"70388.10\", \"0.000\"], [\"70388.20\", \"0.000\"], [\"70388.30\", \"0.000\"], [\"70388.40\", \"0.000\"], [\"70388.50\", \"0.000\"], [\"70388.70\", \"0.000\"], [\"70388.80\", \"0.000\"], [\"70388.90\", \"0.000\"], [\"70389.00\", \"0.000\"], [\"70389.10\", \"0.000\"], [\"70389.30\", \"0.000\"], [\"70389.40\", \"0.000\"], [\"70389.50\", \"0.000\"], [\"70389.70\", \"0.000\"], [\"70389.80\", \"0.000\"], [\"70389.90\", \"0.000\"], [\"70390.00\", \"0.000\"], [\"70390.10\", \"0.000\"], [\"70390.40\", \"0.000\"], [\"70390.60\", \"0.000\"], [\"70390.70\", \"0.000\"], [\"70390.90\", \"0.000\"], [\"70391.00\", \"0.000\"], [\"70391.10\", \"0.000\"], [\"70391.50\", \"0.000\"], [\"70391.60\", \"0.000\"], [\"70391.70\", \"0.000\"], [\"70391.80\", \"0.000\"]], \"a\": [[\"70387.40\", \"1.747\"], [\"70387.50\", \"0.002\"], [\"70387.60\", \"0.002\"], [\"70387.70\", \"0.001\"], [\"70387.80\", \"0.000\"], [\"70387.90\", \"0.000\"], [\"70388.10\", \"0.000\"], [\"70388.20\", \"0.000\"], [\"70388.40\", \"0.000\"], [\"70388.50\", \"0.000\"], [\"70388.60\", \"0.000\"], [\"70388.80\", \"0.002\"], [\"70388.90\", \"0.000\"], [\"70389.00\", \"0.000\"], [\"70389.10\", \"0.004\"], [\"70389.20\", \"0.002\"], [\"70389.30\", \"0.002\"], [\"70389.40\", \"0.000\"], [\"70389.50\", \"0.003\"], [\"70389.60\", \"0.000\"], [\"70389.70\", \"0.002\"], [\"70389.80\", \"0.002\"], [\"70389.90\", \"0.005\"], [\"70390.00\", \"0.004\"], [\"70390.10\", \"0.000\"], [\"70390.20\", \"0.000\"], [\"70390.30\", \"0.001\"], [\"70390.50\", \"0.003\"], [\"70390.70\", \"0.000\"], [\"70390.80\", \"0.000\"], [\"70390.90\", \"0.000\"], [\"70391.00\", \"0.000\"], [\"70391.10\", \"0.009\"], [\"70391.20\", \"0.003\"], [\"70391.30\", \"0.004\"], [\"70391.40\", \"0.002\"], [\"70391.50\", \"0.000\"], [\"70391.60\", \"0.001\"], [\"70391.70\", \"0.000\"], [\"70391.80\", \"0.000\"], [\"70391.90\", \"0.016\"], [\"70392.00\", \"0.005\"], [\"70392.40\", \"0.003\"], [\"70392.50\", \"0.003\"], [\"70392.90\", \"0.003\"], [\"70393.30\", \"0.006\"], [\"70393.40\", \"0.000\"], [\"70393.50\", \"0.062\"], [\"70393.60\", \"0.022\"], [\"70394.10\", \"0.065\"], [\"70394.20\", \"0.002\"], [\"70394.50\", \"0.005\"], [\"70394.60\", \"0.012\"], [\"70394.90\", \"0.000\"], [\"70395.30\", \"0.004\"], [\"70395.50\", \"0.055\"], [\"70395.80\", \"0.000\"], [\"70395.90\", \"0.324\"], [\"70396.10\", \"0.005\"], [\"70396.30\", \"0.001\"], [\"70396.80\", \"0.001\"], [\"70396.90\", \"0.010\"], [\"70397.10\", \"0.000\"], [\"70397.40\", \"0.017\"], [\"70397.50\", \"0.515\"], [\"70397.60\", \"0.066\"], [\"70397.70\", \"0.000\"], [\"70398.00\", \"0.003\"], [\"70398.10\", \"0.008\"], [\"70398.20\", \"0.000\"], [\"70398.30\", \"0.002\"], [\"70398.40\", \"0.264\"], [\"70398.50\", \"0.344\"], [\"70398.60\", \"0.001\"], [\"70398.70\", \"0.002\"], [\"70398.90\", \"0.003\"], [\"70399.00\", \"0.008\"], [\"70399.10\", \"0.201\"], [\"70399.20\", \"0.653\"], [\"70399.30\", \"0.007\"], [\"70399.70\", \"0.016\"], [\"70399.80\", \"0.003\"], [\"70399.90\", \"0.513\"], [\"70400.00\", \"2.038\"], [\"70400.10\", \"0.000\"], [\"70400.20\", \"0.009\"], [\"70400.30\", \"0.076\"], [\"70400.40\", \"0.008\"], [\"70400.80\", \"0.000\"], [\"70400.90\", \"0.005\"], [\"70401.00\", \"0.007\"], [\"70401.10\", \"0.105\"], [\"70401.20\", \"0.002\"], [\"70401.40\", \"0.034\"], [\"70401.50\", \"0.024\"], [\"70401.60\", \"0.006\"], [\"70401.80\", \"0.000\"], [\"70401.90\", \"0.784\"], [\"70402.00\", \"0.188\"], [\"70402.40\", \"0.034\"], [\"70402.50\", \"0.002\"], [\"70402.60\", \"0.004\"], [\"70402.80\", \"0.456\"], [\"70402.90\", \"1.068\"], [\"70403.00\", \"0.007\"], [\"70403.10\", \"0.004\"], [\"70403.20\", \"0.000\"], [\"70403.40\", \"0.002\"], [\"70403.60\", \"0.000\"], [\"70403.70\", \"0.005\"], [\"70404.00\", \"0.001\"], [\"70404.10\", \"0.000\"], [\"70404.20\", \"0.344\"], [\"70404.60\", \"0.000\"], [\"70404.80\", \"0.209\"], [\"70405.00\", \"0.029\"], [\"70405.10\", \"0.045\"], [\"70405.20\", \"0.003\"], [\"70405.40\", \"0.031\"], [\"70405.50\", \"0.002\"], [\"70405.70\", \"0.225\"], [\"70405.80\", \"0.004\"], [\"70405.90\", \"0.073\"], [\"70406.10\", \"0.104\"], [\"70406.20\", \"0.007\"], [\"70406.40\", \"0.075\"], [\"70406.70\", \"0.567\"], [\"70407.00\", \"0.006\"], [\"70407.20\", \"0.076\"], [\"70407.40\", \"0.061\"], [\"70407.80\", \"0.047\"], [\"70407.90\", \"0.405\"], [\"70408.20\", \"0.004\"], [\"70408.50\", \"0.043\"], [\"70408.60\", \"0.005\"], [\"70408.70\", \"0.100\"], [\"70408.80\", \"0.234\"], [\"70408.90\", \"0.002\"], [\"70409.00\", \"0.248\"], [\"70409.20\", \"0.186\"], [\"70409.40\", \"0.450\"], [\"70409.50\", \"0.002\"], [\"70409.80\", \"0.003\"], [\"70410.20\", \"0.000\"], [\"70410.60\", \"0.004\"], [\"70410.70\", \"0.013\"], [\"70410.80\", \"0.103\"], [\"70410.90\", \"0.232\"], [\"70411.00\", \"0.003\"], [\"70411.10\", \"0.002\"], [\"70411.20\", \"0.002\"], [\"70411.30\", \"0.000\"], [\"70411.40\", \"0.015\"], [\"70411.80\", \"0.077\"], [\"70412.00\", \"0.002\"], [\"70412.20\", \"0.513\"], [\"70412.30\", \"0.347\"], [\"70412.40\", \"0.003\"], [\"70412.70\", \"0.003\"], [\"70412.80\", \"0.189\"], [\"70413.00\", \"0.008\"], [\"70413.10\", \"0.002\"], [\"70413.70\", \"0.001\"], [\"70413.90\", \"0.003\"], [\"70414.40\", \"0.070\"], [\"70414.50\", \"0.303\"], [\"70414.60\", \"0.009\"], [\"70414.90\", \"0.210\"], [\"70415.20\", \"0.017\"], [\"70415.40\", \"0.005\"], [\"70415.70\", \"0.013\"], [\"70415.80\", \"0.051\"], [\"70415.90\", \"0.512\"], [\"70416.00\", \"0.264\"], [\"70416.10\", \"0.301\"], [\"70416.20\", \"0.009\"], [\"70416.30\", \"0.019\"], [\"70416.60\", \"0.046\"], [\"70416.80\", \"0.226\"], [\"70416.90\", \"0.006\"], [\"70417.50\", \"0.002\"], [\"70417.90\", \"0.186\"], [\"70418.00\", \"0.390\"], [\"70418.10\", \"0.003\"], [\"70418.20\", \"0.054\"], [\"70418.30\", \"0.003\"], [\"70418.40\", \"0.193\"], [\"70418.50\", \"0.007\"], [\"70418.60\", \"0.022\"], [\"70419.10\", \"0.111\"], [\"70419.30\", \"0.002\"], [\"70419.40\", \"0.000\"], [\"70419.60\", \"0.003\"], [\"70419.70\", \"0.205\"], [\"70420.00\", \"1.078\"], [\"70420.60\", \"0.007\"], [\"70420.70\", \"0.005\"], [\"70420.90\", \"0.003\"], [\"70421.00\", \"0.002\"], [\"70421.20\", \"0.000\"], [\"70421.40\", \"0.008\"], [\"70421.60\", \"0.007\"], [\"70421.90\", \"0.002\"], [\"70422.70\", \"0.248\"], [\"70423.50\", \"0.022\"], [\"70423.70\", \"0.426\"], [\"70424.10\", \"0.138\"], [\"70424.90\", \"0.002\"], [\"70425.00\", \"0.019\"], [\"70425.10\", \"0.095\"], [\"70425.40\", \"0.003\"], [\"70425.60\", \"0.000\"], [\"70425.70\", \"0.005\"], [\"70426.00\", \"0.400\"], [\"70426.40\", \"0.000\"], [\"70426.50\", \"0.006\"], [\"70426.70\", \"0.213\"], [\"70427.10\", \"0.486\"], [\"70427.20\", \"2.156\"], [\"70427.80\", \"10.419\"], [\"70428.60\", \"0.023\"], [\"70429.80\", \"0.000\"], [\"70430.30\", \"0.000\"], [\"70431.80\", \"0.054\"], [\"70435.10\", \"0.002\"], [\"70436.50\", \"0.011\"], [\"70436.70\", \"0.198\"], [\"70437.00\", \"0.005\"], [\"70437.30\", \"0.005\"], [\"70437.40\", \"0.051\"], [\"70438.20\", \"0.020\"], [\"70438.60\", \"0.003\"], [\"70439.40\", \"0.020\"], [\"70439.80\", \"0.070\"], [\"70440.40\", \"0.129\"], [\"70440.50\", \"0.004\"], [\"70440.70\", \"0.004\"], [\"70441.30\", \"0.008\"], [\"70442.00\", \"0.600\"], [\"70442.90\", \"0.000\"], [\"70443.20\", \"0.003\"], [\"70443.30\", \"0.030\"], [\"70444.60\", \"0.003\"], [\"70444.70\", \"1.066\"], [\"70447.20\", \"0.088\"], [\"70448.10\", \"1.256\"], [\"70448.30\", \"0.413\"], [\"70449.50\", \"0.000\"], [\"70450.20\", \"0.006\"], [\"70450.30\", \"0.000\"], [\"70450.70\", \"0.084\"], [\"70451.70\", \"0.055\"], [\"70452.00\", \"0.680\"], [\"70452.50\", \"0.111\"], [\"70456.00\", \"0.087\"], [\"70458.40\", \"0.005\"], [\"70460.90\", \"0.798\"], [\"70461.00\", \"0.001\"], [\"70464.80\", \"0.014\"], [\"70467.80\", \"0.198\"], [\"70468.20\", \"0.513\"], [\"70469.90\", \"0.415\"], [\"70470.30\", \"0.104\"], [\"70470.60\", \"0.352\"], [\"70470.70\", \"0.374\"], [\"70471.50\", \"0.167\"], [\"70471.70\", \"0.326\"], [\"70472.50\", \"0.108\"], [\"70474.00\", \"0.000\"], [\"70478.10\", \"0.364\"], [\"70482.50\", \"0.044\"], [\"70482.60\", \"0.061\"], [\"70482.70\", \"0.107\"], [\"70483.10\", \"1.232\"], [\"70483.90\", \"0.100\"], [\"70484.10\", \"0.083\"], [\"70485.10\", \"0.230\"], [\"70489.60\", \"0.080\"], [\"70489.80\", \"0.319\"], [\"70491.10\", \"0.625\"], [\"70491.20\", \"0.180\"], [\"70497.60\", \"6.613\"], [\"70502.80\", \"0.273\"], [\"70506.10\", \"0.002\"], [\"70519.50\", \"0.006\"], [\"70531.90\", \"0.081\"], [\"70532.40\", \"0.044\"], [\"70532.70\", \"0.328\"], [\"70535.00\", \"0.083\"], [\"70543.30\", \"4.634\"], [\"70544.10\", \"10.511\"], [\"70553.90\", \"0.002\"], [\"70568.70\", \"0.036\"], [\"70571.80\", \"0.000\"], [\"70584.90\", \"0.000\"], [\"70586.90\", \"0.005\"], [\"70590.40\", \"0.005\"], [\"70591.40\", \"0.202\"], [\"70603.90\", \"0.002\"], [\"70613.60\", \"6.533\"], [\"70615.40\", \"0.000\"], [\"70616.70\", \"0.000\"], [\"70618.80\", \"0.384\"], [\"70875.80\", \"0.000\"], [\"70882.90\", \"0.000\"], [\"70897.40\", \"0.000\"], [\"70926.40\", \"0.440\"], [\"71033.30\", \"0.917\"], [\"71091.30\", \"0.000\"], [\"71348.80\", \"0.002\"], [\"71351.90\", \"0.000\"], [\"71352.00\", \"0.152\"], [\"71352.70\", \"0.279\"], [\"71354.30\", \"0.490\"], [\"71359.70\", \"0.014\"], [\"71360.60\", \"0.000\"], [\"71361.30\", \"0.008\"], [\"71361.50\", \"0.490\"], [\"71361.60\", \"0.000\"], [\"71361.80\", \"0.028\"], [\"71387.40\", \"0.014\"], [\"71389.00\", \"0.013\"], [\"71389.40\", \"0.006\"], [\"71390.10\", \"0.002\"], [\"71391.10\", \"0.116\"], [\"73937.50\", \"0.007\"], [\"89523.20\", \"0.000\"], [\"100000.00\", \"15.487\"]]}", "symbol": "BTCUSDT"}
{"event": "depthUpdate", "raw_payload": "{\"e\": \"depthUpdate\", \"E\": 1773246396396, \"T\": 1773246396394, \"s\": \"BTCUSDT\", \"U\": 10089704868742, \"u\": 10089704877585, \"pu\": 10089704868689, \"b\": [[\"5000.00\", \"101.398\"], [\"19887.30\", \"0.130\"], [\"19987.30\", \"0.130\"], [\"19991.80\", \"1.470\"], [\"20067.10\", \"0.180\"], [\"20068.30\", \"0.000\"], [\"20087.30\", \"0.130\"], [\"20191.80\", \"0.670\"], [\"56310.00\", \"100.003\"], [\"68540.60\", \"0.002\"], [\"69330.60\", \"6.714\"], [\"69366.70\", \"2.433\"], [\"69506.50\", \"2.792\"], [\"69542.60\", \"0.712\"], [\"69603.20\", \"0.018\"], [\"69606.30\", \"0.000\"], [\"69641.80\", \"0.711\"], [\"69648.20\", \"0.782\"], [\"69673.60\", \"0.000\"], [\"69683.40\", \"0.000\"], [\"69717.50\", \"3.536\"], [\"69718.60\", \"0.710\"], [\"69753.80\", \"0.710\"], [\"69824.20\", \"0.715\"], [\"70039.80\", \"0.002\"], [\"70080.20\", \"0.076\"], [\"70166.20\", \"0.162\"], [\"70178.50\", \"5.562\"], [\"70191.40\", \"0.000\"], [\"70221.30\", \"13.030\"], [\"70223.70\", \"2.763\"], [\"70254.30\", \"0.342\"], [\"70278.00\", \"0.605\"], [\"70286.10\", \"0.084\"], [\"70294.80\", \"0.346\"], [\"70302.80\", \"0.000\"], [\"70303.00\", \"1.958\"], [\"70303.10\", \"0.005\"], [\"70306.40\", \"0.084\"], [\"70314.30\", \"0.444\"], [\"70314.40\", \"0.045\"], [\"70317.40\", \"1.073\"], [\"70321.30\", \"0.131\"], [\"70328.00\", \"0.006\"], [\"70334.50\", \"0.513\"], [\"70335.50\", \"0.046\"], [\"70340.40\", \"0.087\"], [\"70340.50\", \"0.061\"], [\"70340.90\", \"0.005\"], [\"70342.20\", \"0.010\"], [\"70343.60\", \"0.025\"], [\"70345.10\", \"0.053\"], [\"70345.30\", \"0.212\"], [\"70350.20\", \"0.000\"], [\"70350.70\", \"0.011\"], [\"70355.50\", \"0.001\"], [\"70355.70\", \"0.010\"], [\"70355.90\", \"0.000\"], [\"70356.90\", \"0.000\"], [\"70357.40\", \"0.174\"], [\"70359.00\", \"0.011\"], [\"70359.10\", \"0.009\"], [\"70359.70\", \"0.000\"], [\"70359.80\", \"0.000\"], [\"70362.20\", \"0.000\"], [\"70362.60\", \"0.000\"], [\"70363.50\", \"0.282\"], [\"70363.60\", \"0.616\"], [\"70364.00\", \"0.622\"], [\"70366.00\", \"0.005\"], [\"70367.20\", \"0.641\"], [\"70367.30\", \"0.321\"], [\"70368.20\", \"1.577\"], [\"70368.80\", \"0.010\"], [\"70369.00\", \"0.020\"], [\"70369.50\", \"0.009\"], [\"70369.70\", \"0.015\"], [\"70369.80\", \"0.296\"], [\"70370.00\", \"0.246\"], [\"70370.20\", \"0.000\"], [\"70370.30\", \"0.552\"], [\"70370.80\", \"0.149\"], [\"70371.00\", \"0.004\"], [\"70371.20\", \"0.002\"], [\"70371.50\", \"0.000\"], [\"70371.60\", \"0.006\"], [\"70372.80\", \"0.182\"], [\"70372.90\", \"0.045\"], [\"70373.20\", \"0.002\"], [\"70373.50\", \"0.318\"], [\"70373.70\", \"0.003\"], [\"70374.10\", \"0.000\"], [\"70374.20\", \"0.035\"], [\"70374.30\", \"0.002\"], [\"70374.60\", \"1.066\"], [\"70375.40\", \"0.305\"], [\"70375.60\", \"0.006\"], [\"70376.50\", \"0.206\"], [\"70376.70\", \"0.167\"], [\"70376.90\", \"0.000\"], [\"70377.00\", \"0.000\"], [\"70377.60\", \"0.426\"], [\"70377.70\", \"0.002\"], [\"70377.90\", \"0.003\"], [\"70378.30\", \"0.002\"], [\"70378.60\", \"0.003\"], [\"70379.20\", \"0.040\"], [\"70379.40\", \"0.018\"], [\"70380.20\", \"0.016\"], [\"70380.30\", \"0.005\"], [\"70380.60\", \"0.003\"], [\"70380.70\", \"0.104\"], [\"70382.10\", \"0.244\"], [\"70382.60\", \"0.003\"], [\"70383.80\", \"0.005\"], [\"70386.50\", \"0.002\"], [\"70387.30\", \"3.220\"]], \"a\": [[\"70387.40\", \"1.414\"], [\"70387.50\", \"0.000\"], [\"70387.70\", \"0.000\"], [\"70391.00\", \"0.000\"], [\"70391.10\", \"0.007\"], [\"70391.80\", \"0.002\"], [\"70391.90\", \"0.008\"], [\"70392.30\", \"0.041\"], [\"70393.50\", \"0.034\"], [\"70394.30\", \"0.003\"], [\"70395.60\", \"0.436\"], [\"70395.70\", \"0.808\"], [\"70395.80\", \"0.425\"], [\"70395.90\", \"0.492\"], [\"70397.40\", \"0.900\"], [\"70398.00\", \"0.105\"], [\"70398.30\", \"0.002\"], [\"70398.40\", \"0.264\"], [\"70399.00\", \"0.010\"], [\"70399.10\", \"0.201\"], [\"70400.10\", \"0.002\"], [\"70400.30\", \"0.074\"], [\"70401.90\", \"0.003\"], [\"70402.00\", \"0.188\"], [\"70403.00\", \"0.054\"], [\"70404.00\", \"0.143\"], [\"70404.10\", \"0.639\"], [\"70404.30\", \"0.004\"], [\"70407.20\", \"0.005\"], [\"70408.00\", \"0.002\"], [\"70409.00\", \"0.002\"], [\"70409.10\", \"1.826\"], [\"70410.70\", \"0.086\"], [\"70410.80\", \"0.030\"], [\"70411.70\", \"0.154\"], [\"70411.80\", \"0.007\"], [\"70412.00\", \"0.117\"], [\"70412.10\", \"0.248\"], [\"70412.90\", \"0.000\"], [\"70413.80\", \"0.070\"], [\"70414.90\", \"0.153\"], [\"70415.50\", \"0.003\"], [\"70415.80\", \"0.000\"], [\"70416.50\", \"0.565\"], [\"70417.90\", \"1.186\"], [\"70418.20\", \"0.002\"], [\"70419.10\", \"0.429\"], [\"70419.60\", \"0.000\"], [\"70419.90\", \"0.518\"], [\"70420.40\", \"0.052\"], [\"70421.80\", \"0.000\"], [\"70422.40\", \"0.003\"], [\"70422.70\", \"0.246\"], [\"70422.80\", \"0.000\"], [\"70422.90\", \"0.000\"], [\"70423.50\", \"0.022\"], [\"70423.60\", \"0.203\"], [\"70424.20\", \"0.000\"], [\"70424.30\", \"0.002\"], [\"70424.90\", \"0.002\"], [\"70425.00\", \"0.019\"], [\"70426.10\", \"0.491\"], [\"70426.30\", \"0.053\"], [\"70427.90\", \"0.003\"], [\"70429.10\", \"0.511\"], [\"70429.20\", \"0.002\"], [\"70429.80\", \"0.002\"], [\"70429.90\", \"0.006\"], [\"70430.50\", \"0.868\"], [\"70430.60\", \"2.895\"], [\"70431.80\", \"0.049\"], [\"70437.00\", \"0.002\"], [\"70437.70\", \"0.008\"], [\"70438.20\", \"0.000\"], [\"70438.40\", \"0.002\"], [\"70439.10\", \"0.000\"], [\"70441.10\", \"0.020\"], [\"70447.20\", \"0.112\"], [\"70448.10\", \"1.284\"], [\"70452.00\", \"0.652\"], [\"70452.50\", \"0.000\"], [\"70454.30\", \"0.084\"], [\"70456.60\", \"0.645\"], [\"70457.80\", \"0.007\"], [\"70469.90\", \"0.279\"], [\"70470.30\", \"0.002\"], [\"70470.60\", \"0.250\"], [\"70470.70\", \"0.272\"], [\"70471.70\", \"0.309\"], [\"70486.50\", \"0.482\"], [\"70489.60\", \"0.000\"], [\"70489.80\", \"0.044\"], [\"70494.70\", \"2.067\"], [\"70497.50\", \"0.000\"], [\"70534.90\", \"0.194\"], [\"70544.00\", \"0.022\"], [\"70605.20\", \"0.018\"], [\"70687.40\", \"0.204\"], [\"70905.60\", \"0.008\"], [\"71091.30\", \"0.000\"], [\"71118.30\", \"0.008\"], [\"71235.70\", \"1.120\"], [\"71331.00\", \"0.008\"], [\"71543.80\", \"0.008\"], [\"71756.50\", \"0.008\"], [\"73914.00\", \"0.102\"], [\"73927.70\", \"0.020\"]]}", "symbol": "BTCUSDT"}
{"event": "depthUpdate", "raw_payload": "{\"e\": \"depthUpdate\", \"E\": 1773246396498, \"T\": 1773246396497, \"s\": \"BTCUSDT\", \"U\": 10089704877673, \"u\": 10089704883534, \"pu\": 10089704877585, \"b\": [[\"1000.00\", \"26.792\"], [\"5000.00\", \"101.418\"], [\"19887.30\", \"0.220\"], [\"19987.30\", \"0.210\"], [\"19991.80\", \"1.380\"], [\"20067.10\", \"0.100\"], [\"20087.30\", \"0.220\"], [\"20191.80\", \"0.580\"], [\"69120.80\", \"0.000\"], [\"69227.60\", \"0.000\"], [\"69251.20\", \"0.830\"], [\"69260.30\", \"2.012\"], [\"69296.30\", \"2.003\"], [\"69330.50\", \"0.059\"], [\"69330.60\", \"5.714\"], [\"69359.70\", \"2.810\"], [\"69366.70\", \"4.146\"], [\"69436.70\", \"0.000\"], [\"69479.30\", \"1.446\"], [\"69541.70\", \"0.712\"], [\"69577.80\", \"0.725\"], [\"69638.40\", \"0.038\"], [\"69683.40\", \"0.710\"], [\"69708.70\", \"1.420\"], [\"69717.40\", \"0.000\"], [\"69717.50\", \"2.116\"], [\"69738.80\", \"0.199\"], [\"69753.80\", \"2.840\"], [\"69853.30\", \"3.729\"], [\"69951.10\", \"0.000\"], [\"70041.90\", \"0.119\"], [\"70157.80\", \"0.000\"], [\"70157.90\", \"0.007\"], [\"70223.70\", \"2.815\"], [\"70256.80\", \"0.588\"], [\"70257.00\", \"0.095\"], [\"70279.50\", \"6.961\"], [\"70285.50\", \"0.000\"], [\"70302.50\", \"0.022\"], [\"70302.80\", \"0.084\"], [\"70309.90\", \"0.051\"], [\"70319.80\", \"0.590\"], [\"70332.90\", \"0.008\"], [\"70333.80\", \"0.165\"], [\"70334.50\", \"0.511\"], [\"70340.40\", \"0.087\"], [\"70340.50\", \"0.061\"], [\"70340.80\", \"0.024\"], [\"70341.50\", \"0.402\"], [\"70360.50\", \"0.227\"], [\"70362.00\", \"0.345\"], [\"70362.60\", \"0.080\"], [\"70362.70\", \"0.014\"], [\"70363.50\", \"0.202\"], [\"70365.70\", \"0.639\"], [\"70367.20\", \"0.002\"], [\"70369.00\", \"0.000\"], [\"70370.70\", \"0.002\"], [\"70374.20\", \"0.001\"], [\"70376.30\", \"0.006\"], [\"70376.50\", \"0.206\"], [\"70376.60\", \"0.036\"], [\"70376.70\", \"0.163\"], [\"70379.30\", \"0.034\"], [\"70379.40\", \"0.008\"], [\"70380.20\", \"0.006\"], [\"70382.00\", \"0.660\"], [\"70382.10\", \"0.015\"], [\"70385.90\", \"0.000\"], [\"70386.10\", \"0.003\"], [\"70387.30\", \"2.620\"]], \"a\": [[\"70387.40\", \"3.614\"], [\"70387.50\", \"0.001\"], [\"70389.30\", \"0.000\"], [\"70389.50\", \"0.001\"], [\"70390.00\", \"0.002\"], [\"70391.20\", \"0.001\"], [\"70391.90\", \"0.006\"], [\"70392.70\", \"0.342\"], [\"70393.50\", \"0.300\"], [\"70394.40\", \"0.106\"], [\"70395.30\", \"0.517\"], [\"70395.40\", \"0.383\"], [\"70395.50\", \"0.538\"], [\"70395.60\", \"1.066\"], [\"70395.70\", \"0.000\"], [\"70395.80\", \"0.000\"], [\"70395.90\", \"0.109\"], [\"70397.40\", \"0.017\"], [\"70398.00\", \"0.003\"], [\"70398.40\", \"0.262\"], [\"70399.00\", \"0.221\"], [\"70399.80\", \"0.006\"], [\"70399.90\", \"0.515\"], [\"70401.10\", \"0.003\"], [\"70403.50\", \"0.066\"], [\"70403.90\", \"0.073\"], [\"70409.10\", \"1.755\"], [\"70411.70\", \"0.011\"], [\"70414.40\", \"1.070\"], [\"70414.90\", \"0.010\"], [\"70415.50\", \"0.003\"], [\"70416.30\", \"0.076\"], [\"70416.80\", \"0.226\"], [\"70416.90\", \"0.000\"], [\"70417.90\", \"0.186\"], [\"70419.10\", \"0.327\"], [\"70422.70\", \"0.194\"], [\"70422.80\", \"0.009\"], [\"70422.90\", \"0.009\"], [\"70423.50\", \"0.013\"], [\"70423.60\", \"0.194\"], [\"70424.20\", \"0.002\"], [\"70424.30\", \"0.004\"], [\"70424.90\", \"0.000\"], [\"70425.00\", \"0.017\"], [\"70426.10\", \"0.595\"], [\"70440.00\", \"0.199\"], [\"70440.20\", \"0.010\"], [\"70440.40\", \"0.001\"], [\"70444.30\", \"0.030\"], [\"70448.10\", \"1.264\"], [\"70454.30\", \"0.000\"], [\"70472.50\", \"0.004\"], [\"70479.00\", \"0.043\"], [\"70561.80\", \"0.052\"], [\"70581.90\", \"0.198\"], [\"70601.40\", \"0.000\"], [\"70601.80\", \"0.009\"], [\"70611.00\", \"0.107\"], [\"70613.60\", \"6.515\"], [\"70622.30\", \"0.000\"], [\"70650.90\", \"0.000\"], [\"70752.90\", \"0.120\"], [\"70875.70\", \"0.006\"], [\"70912.20\", \"0.002\"], [\"70921.50\", \"3.720\"], [\"71071.40\", \"0.224\"], [\"71091.30\", \"0.000\"], [\"71193.60\", \"0.000\"], [\"71352.80\", \"0.000\"], [\"71373.90\", \"0.624\"], [\"73914.00\", \"0.100\"], [\"89523.20\", \"0.000\"]]}", "symbol": "BTCUSDT"}
{"event": "depthUpdate", "raw_payload": "{\"e\": \"depthUpdate\", \"E\": 1773246396600, \"T\": 1773246396599, \"s\": \"BTCUSDT\", \"U\": 10089704883569, \"u\": 10089704894878, \"pu\": 10089704883534, \"b\": [[\"1000.00\", \"26.792\"], [\"5000.00\", \"101.418\"], [\"19887.30\", \"0.300\"], [\"19987.30\", \"0.300\"], [\"19991.80\", \"1.300\"], [\"20067.10\", \"0.010\"], [\"20087.30\", \"0.300\"], [\"20191.80\", \"0.500\"], [\"33000.00\", \"10.797\"], [\"69069.20\", \"0.006\"], [\"69234.20\", \"0.721\"], [\"69253.00\", \"0.007\"], [\"69260.20\", \"0.007\"], [\"69296.30\", \"4.003\"], [\"69329.30\", \"0.864\"], [\"69330.60\", \"3.000\"], [\"69366.70\", \"6.858\"], [\"69381.40\", \"0.002\"], [\"69506.50\", \"0.000\"], [\"69541.70\", \"0.000\"], [\"69542.60\", \"1.424\"], [\"69577.80\", \"1.436\"], [\"69647.20\", \"0.008\"], [\"69683.40\", \"1.420\"], [\"69717.50\", \"1.406\"], [\"69753.80\", \"3.550\"], [\"69853.30\", \"0.009\"], [\"69856.70\", \"0.000\"], [\"70198.70\", \"0.000\"], [\"70204.60\", \"2.272\"], [\"70226.30\", \"0.082\"], [\"70228.20\", \"0.049\"], [\"70232.40\", \"0.041\"], [\"70232.50\", \"0.002\"], [\"70233.00\", \"0.205\"], [\"70233.10\", \"0.000\"], [\"70233.40\", \"0.000\"], [\"70233.70\", \"0.000\"], [\"70233.80\", \"0.000\"], [\"70234.10\", \"0.000\"], [\"70235.20\", \"0.008\"], [\"70255.90\", \"0.049\"], [\"70257.50\", \"0.054\"], [\"70259.80\", \"0.000\"], [\"70262.30\", \"0.191\"], [\"70263.20\", \"0.004\"], [\"70266.80\", \"0.000\"], [\"70276.30\", \"0.000\"], [\"70278.00\", \"0.599\"], [\"70279.60\", \"0.127\"], [\"70280.00\", \"2.326\"], [\"70290.50\", \"1.540\"], [\"70293.40\", \"0.003\"], [\"70293.50\", \"0.041\"], [\"70293.60\", \"0.084\"], [\"70293.70\", \"0.018\"], [\"70294.00\", \"2.925\"], [\"70294.20\", \"0.002\"], [\"70294.40\", \"0.135\"], [\"70294.70\", \"0.161\"], [\"70295.10\", \"0.000\"], [\"70295.30\", \"0.002\"], [\"70306.50\", \"0.054\"], [\"70306.60\", \"0.015\"], [\"70309.90\", \"0.000\"], [\"70315.80\", \"0.000\"], [\"70318.60\", \"0.006\"], [\"70322.60\", \"0.002\"], [\"70323.10\", \"1.420\"], [\"70333.80\", \"0.163\"], [\"70334.10\", \"0.207\"], [\"70340.40\", \"0.002\"], [\"70340.50\", \"0.146\"], [\"70342.60\", \"0.000\"], [\"70345.10\", \"0.002\"], [\"70346.80\", \"0.003\"], [\"70351.30\", \"0.108\"], [\"70357.90\", \"0.198\"], [\"70360.30\", \"0.197\"], [\"70367.10\", \"0.137\"], [\"70373.30\", \"0.002\"], [\"70375.10\", \"0.053\"], [\"70376.00\", \"0.007\"], [\"70376.30\", \"0.096\"], [\"70376.40\", \"0.000\"], [\"70376.50\", \"0.206\"], [\"70376.60\", \"0.038\"], [\"70376.70\", \"0.041\"], [\"70376.80\", \"0.080\"], [\"70377.10\", \"0.003\"], [\"70377.40\", \"0.094\"], [\"70377.50\", \"0.130\"], [\"70377.70\", \"0.403\"], [\"70377.80\", \"0.003\"], [\"70378.10\", \"0.406\"], [\"70378.20\", \"0.013\"], [\"70380.20\", \"0.013\"], [\"70380.30\", \"0.005\"], [\"70381.50\", \"0.003\"], [\"70382.10\", \"0.017\"], [\"70386.10\", \"0.006\"], [\"70387.30\", \"3.037\"]], \"a\": [[\"70387.40\", \"1.713\"], [\"70387.50\", \"0.000\"], [\"70391.80\", \"0.000\"], [\"70392.20\", \"0.002\"], [\"70392.60\", \"0.007\"], [\"70393.50\", \"0.201\"], [\"70394.40\", \"0.004\"], [\"70395.20\", \"0.436\"], [\"70395.40\", \"0.009\"], [\"70398.00\", \"0.003\"], [\"70398.30\", \"0.000\"], [\"70398.40\", \"0.698\"], [\"70399.00\", \"0.008\"], [\"70404.70\", \"0.511\"], [\"70404.90\", \"0.003\"], [\"70405.00\", \"0.004\"], [\"70405.30\", \"0.002\"], [\"70405.40\", \"0.042\"], [\"70405.70\", \"0.189\"], [\"70406.10\", \"0.007\"], [\"70406.30\", \"0.000\"], [\"70406.40\", \"0.075\"], [\"70406.50\", \"0.004\"], [\"70406.60\", \"0.004\"], [\"70408.90\", \"0.004\"], [\"70412.00\", \"0.219\"], [\"70414.30\", \"0.378\"], [\"70414.40\", \"0.070\"], [\"70415.60\", \"0.002\"], [\"70416.90\", \"1.000\"], [\"70422.50\", \"0.044\"], [\"70424.20\", \"0.000\"], [\"70424.30\", \"0.002\"], [\"70424.90\", \"0.002\"], [\"70425.00\", \"0.019\"], [\"70426.10\", \"0.697\"], [\"70427.90\", \"0.006\"], [\"70429.10\", \"0.513\"], [\"70429.20\", \"0.004\"], [\"70429.80\", \"0.000\"], [\"70429.90\", \"0.004\"], [\"70432.40\", \"0.198\"], [\"70444.30\", \"0.002\"], [\"70448.10\", \"1.292\"], [\"70454.30\", \"0.084\"], [\"70456.10\", \"0.005\"], [\"70460.60\", \"0.003\"], [\"70465.30\", \"0.044\"], [\"70466.60\", \"0.125\"], [\"70480.40\", \"0.245\"], [\"70496.60\", \"0.002\"], [\"70506.80\", \"0.002\"], [\"70506.90\", \"0.000\"], [\"70507.20\", \"0.002\"], [\"70507.60\", \"0.588\"], [\"70507.80\", \"0.201\"], [\"70507.90\", \"0.000\"], [\"70508.30\", \"0.026\"], [\"70508.60\", \"0.015\"], [\"70508.80\", \"0.003\"], [\"70508.90\", \"0.039\"], [\"70509.40\", \"0.002\"], [\"70512.40\", \"0.295\"], [\"70515.00\", \"0.255\"], [\"70516.90\", \"0.087\"], [\"70525.20\", \"0.036\"], [\"70526.80\", \"0.164\"], [\"70536.60\", \"0.000\"], [\"70543.70\", \"0.000\"], [\"70554.50\", \"3.162\"], [\"70566.80\", \"0.000\"], [\"70566.90\", \"0.082\"], [\"70567.10\", \"0.013\"], [\"70567.50\", \"0.000\"], [\"70567.80\", \"0.004\"], [\"70568.10\", \"0.000\"], [\"70568.20\", \"0.080\"], [\"70568.70\", \"0.000\"], [\"70569.00\", \"0.000\"], [\"70569.20\", \"0.010\"], [\"70578.50\", \"0.164\"], [\"70593.90\", \"0.007\"], [\"70600.90\", \"0.392\"], [\"70607.90\", \"8.143\"], [\"70610.60\", \"0.000\"], [\"70614.90\", \"0.007\"], [\"70621.30\", \"0.004\"], [\"70621.90\", \"0.007\"], [\"70624.90\", \"0.002\"], [\"70628.90\", \"0.007\"], [\"70631.90\", \"0.170\"], [\"70635.90\", \"0.207\"], [\"70638.90\", \"0.014\"], [\"70642.90\", \"0.013\"], [\"70645.90\", \"0.002\"], [\"70652.90\", \"0.009\"], [\"70659.90\", \"0.002\"], [\"70666.90\", \"0.020\"], [\"70673.90\", \"0.019\"], [\"70752.80\", \"0.041\"], [\"70753.50\", \"0.000\"], [\"70914.90\", \"3.720\"], [\"70918.00\", \"0.023\"], [\"70921.50\", \"0.000\"], [\"71091.30\", \"0.000\"], [\"73931.70\", \"0.000\"]]}", "symbol": "BTCUSDT"}
{"event": "depthUpdate", "raw_payload": "{\"e\": \"depthUpdate\", \"E\": 1773246396702, \"T\": 1773246396700, \"s\": \"BTCUSDT\", \"U\": 10089704895124, \"u\": 10089704907741, \"pu\": 10089704894878, \"b\": [[\"5000.00\", \"101.418\"], [\"19887.30\", \"0.460\"], [\"19987.30\", \"0.310\"], [\"19991.80\", \"1.140\"], [\"20067.10\", \"0.000\"], [\"20087.30\", \"0.390\"], [\"20191.80\", \"0.410\"], [\"33000.00\", \"10.793\"], [\"56310.00\", \"100.003\"], [\"66848.70\", \"0.005\"], [\"69387.30\", \"0.004\"], [\"69388.90\", \"0.018\"], [\"69437.10\", \"0.287\"], [\"69541.80\", \"0.000\"], [\"69542.70\", \"2.078\"], [\"69577.80\", \"2.147\"], [\"69682.40\", \"0.000\"], [\"69683.40\", \"1.420\"], [\"69718.60\", \"1.420\"], [\"69753.80\", \"4.260\"], [\"69862.90\", \"3.720\"], [\"70035.40\", \"0.000\"], [\"70170.90\", \"0.002\"], [\"70195.90\", \"0.004\"], [\"70249.70\", \"0.047\"], [\"70256.40\", \"0.083\"], [\"70256.80\", \"0.635\"], [\"70301.70\", \"2.087\"], [\"70302.80\", \"0.084\"], [\"70303.30\", \"0.000\"], [\"70304.90\", \"0.004\"], [\"70309.90\", \"0.051\"], [\"70331.80\", \"0.004\"], [\"70340.40\", \"0.087\"], [\"70340.50\", \"0.061\"], [\"70345.10\", \"0.053\"], [\"70345.30\", \"0.212\"], [\"70357.70\", \"0.000\"], [\"70360.50\", \"0.207\"], [\"70362.70\", \"0.014\"], [\"70364.10\", \"0.141\"], [\"70367.10\", \"0.139\"], [\"70367.20\", \"0.000\"], [\"70367.40\", \"0.006\"], [\"70367.50\", \"0.003\"], [\"70369.10\", \"0.004\"], [\"70369.40\", \"0.000\"], [\"70369.70\", \"0.015\"], [\"70370.00\", \"0.266\"], [\"70373.80\", \"0.002\"], [\"70375.80\", \"0.007\"], [\"70376.00\", \"0.003\"], [\"70376.30\", \"0.183\"], [\"70376.60\", \"0.132\"], [\"70376.70\", \"0.041\"], [\"70377.60\", \"0.426\"], [\"70377.70\", \"0.002\"], [\"70378.10\", \"0.005\"], [\"70380.20\", \"0.013\"], [\"70380.30\", \"0.008\"], [\"70380.60\", \"0.045\"], [\"70380.70\", \"0.104\"], [\"70382.10\", \"0.186\"], [\"70387.30\", \"3.041\"]], \"a\": [[\"70387.40\", \"3.082\"], [\"70387.50\", \"0.001\"], [\"70392.10\", \"0.002\"], [\"70395.20\", \"0.000\"], [\"70395.90\", \"0.106\"], [\"70396.00\", \"0.020\"], [\"70396.10\", \"0.008\"], [\"70398.00\", \"0.003\"], [\"70398.10\", \"0.065\"], [\"70398.40\", \"0.262\"], [\"70399.80\", \"0.003\"], [\"70400.20\", \"0.002\"], [\"70401.40\", \"0.034\"], [\"70401.80\", \"0.007\"], [\"70402.00\", \"0.002\"], [\"70403.90\", \"0.002\"], [\"70405.20\", \"0.005\"], [\"70405.40\", \"0.040\"], [\"70405.50\", \"0.004\"], [\"70405.70\", \"0.187\"], [\"70406.00\", \"0.076\"], [\"70406.40\", \"0.147\"], [\"70406.50\", \"0.075\"], [\"70407.20\", \"0.005\"], [\"70407.50\", \"0.002\"], [\"70408.60\", \"0.148\"], [\"70412.00\", \"0.219\"], [\"70414.70\", \"1.008\"], [\"70416.30\", \"0.019\"], [\"70416.40\", \"0.252\"], [\"70416.90\", \"0.000\"], [\"70418.50\", \"0.007\"], [\"70420.10\", \"0.206\"], [\"70422.50\", \"0.000\"], [\"70424.20\", \"0.000\"], [\"70424.30\", \"0.002\"], [\"70424.90\", \"0.002\"], [\"70425.00\", \"0.019\"], [\"70440.00\", \"0.071\"], [\"70440.10\", \"0.176\"], [\"70454.30\", \"0.000\"], [\"70466.00\", \"0.083\"], [\"70466.30\", \"0.072\"], [\"70469.50\", \"0.036\"], [\"70485.90\", \"0.165\"], [\"70512.60\", \"0.002\"], [\"70525.90\", \"0.040\"], [\"70526.20\", \"0.133\"], [\"70532.90\", \"0.036\"], [\"70581.40\", \"0.002\"], [\"70622.30\", \"0.006\"], [\"70911.80\", \"3.720\"], [\"70914.90\", \"0.000\"], [\"71091.30\", \"0.000\"], [\"71425.80\", \"1.258\"], [\"73932.10\", \"0.000\"], [\"89523.20\", \"0.000\"]]}", "symbol": "BTCUSDT"}
{"event": "depthUpdate", "raw_payload": "{\"e\": \"depthUpdate\", \"E\": 1773246396806, \"T\": 1773246396804, \"s\": \"BTCUSDT\", \"U\": 10089704907943, \"u\": 10089704914230, \"pu\": 10089704907741, \"b\": [[\"1000.00\", \"26.792\"], [\"5000.00\", \"101.418\"], [\"19887.30\", \"0.640\"], [\"19991.80\", \"0.960\"], [\"20087.30\", \"0.470\"], [\"20191.80\", \"0.330\"], [\"66821.40\", \"0.004\"], [\"68979.50\", \"0.013\"], [\"69077.40\", \"0.506\"], [\"69321.80\", \"0.005\"], [\"69366.70\", \"7.572\"], [\"69500.00\", \"89.157\"], [\"69631.40\", \"0.000\"], [\"69676.80\", \"0.057\"], [\"69683.40\", \"1.420\"], [\"69807.30\", \"0.000\"], [\"69852.70\", \"0.028\"], [\"70167.70\", \"0.191\"], [\"70209.10\", \"0.209\"], [\"70221.40\", \"0.040\"], [\"70250.60\", \"0.175\"], [\"70256.10\", \"0.388\"], [\"70256.40\", \"0.126\"], [\"70256.50\", \"0.043\"], [\"70257.10\", \"0.155\"], [\"70257.80\", \"0.077\"], [\"70257.90\", \"0.039\"], [\"70327.40\", \"0.008\"], [\"70346.00\", \"0.002\"], [\"70355.60\", \"0.000\"], [\"70363.80\", \"0.014\"], [\"70364.30\", \"0.645\"], [\"70365.70\", \"0.000\"], [\"70368.30\", \"0.003\"], [\"70368.80\", \"0.012\"], [\"70370.90\", \"0.119\"], [\"70372.90\", \"0.047\"], [\"70373.20\", \"0.004\"], [\"70374.30\", \"0.000\"], [\"70375.70\", \"0.000\"], [\"70376.20\", \"0.289\"], [\"70376.30\", \"0.222\"], [\"70376.40\", \"0.004\"], [\"70376.60\", \"0.172\"], [\"70376.70\", \"0.044\"], [\"70377.00\", \"0.058\"], [\"70377.10\", \"0.001\"], [\"70377.30\", \"0.045\"], [\"70377.70\", \"0.037\"], [\"70378.00\", \"0.089\"], [\"70380.20\", \"0.006\"], [\"70380.30\", \"0.005\"], [\"70385.60\", \"0.003\"], [\"70386.10\", \"0.003\"], [\"70386.70\", \"0.002\"], [\"70387.30\", \"2.625\"]], \"a\": [[\"70387.40\", \"3.983\"], [\"70393.50\", \"0.127\"], [\"70394.40\", \"0.150\"], [\"70395.10\", \"0.000\"], [\"70395.20\", \"0.000\"], [\"70395.30\", \"0.515\"], [\"70395.50\", \"0.366\"], [\"70397.60\", \"0.069\"], [\"70398.00\", \"0.102\"], [\"70399.90\", \"0.513\"], [\"70402.00\", \"0.188\"], [\"70402.80\", \"0.456\"], [\"70403.00\", \"0.056\"], [\"70404.30\", \"0.002\"], [\"70404.60\", \"0.025\"], [\"70405.00\", \"0.029\"], [\"70405.40\", \"0.065\"], [\"70405.50\", \"0.006\"], [\"70405.70\", \"0.223\"], [\"70406.10\", \"0.043\"], [\"70406.40\", \"0.219\"], [\"70407.70\", \"0.377\"], [\"70408.60\", \"0.005\"], [\"70409.40\", \"0.075\"], [\"70412.00\", \"0.117\"], [\"70412.30\", \"0.349\"], [\"70413.30\", \"1.014\"], [\"70414.30\", \"0.092\"], [\"70414.70\", \"0.008\"], [\"70417.40\", \"0.003\"], [\"70426.10\", \"0.595\"], [\"70437.40\", \"0.002\"], [\"70464.70\", \"0.025\"], [\"70464.90\", \"2.107\"], [\"70465.60\", \"0.036\"], [\"70465.80\", \"0.025\"], [\"70466.30\", \"0.108\"], [\"70466.50\", \"0.165\"], [\"70483.70\", \"0.036\"], [\"70524.80\", \"0.052\"], [\"70525.50\", \"1.344\"], [\"70526.10\", \"0.025\"], [\"70526.20\", \"0.169\"], [\"70526.60\", \"0.039\"], [\"70537.60\", \"0.002\"], [\"70555.50\", \"0.015\"], [\"70955.00\", \"1.734\"], [\"71091.30\", \"0.000\"], [\"71236.60\", \"0.236\"], [\"71721.90\", \"0.004\"]]}", "symbol": "BTCUSDT"}
{"event": "depthUpdate", "raw_payload": "{\"e\": \"depthUpdate\", \"E\": 1773246396908, \"T\": 1773246396907, \"s\": \"BTCUSDT\", \"U\": 10089704914402, \"u\": 10089704921109, \"pu\": 10089704914230, \"b\": [[\"1000.00\", \"26.792\"], [\"5000.00\", \"101.418\"], [\"19887.30\", \"0.800\"], [\"19991.80\", \"0.800\"], [\"20087.30\", \"0.560\"], [\"20191.80\", \"0.240\"], [\"63348.60\", \"0.002\"], [\"66852.70\", \"0.000\"], [\"69181.20\", \"0.000\"], [\"69226.00\", \"2.149\"], [\"69260.30\", \"1.011\"], [\"69296.30\", \"5.003\"], [\"69330.60\", \"1.000\"], [\"69366.70\", \"9.570\"], [\"69683.40\", \"1.420\"], [\"69862.90\", \"0.000\"], [\"70154.20\", \"0.047\"], [\"70195.70\", \"0.049\"], [\"70197.60\", \"0.342\"], [\"70255.90\", \"0.074\"], [\"70301.00\", \"0.575\"], [\"70302.80\", \"0.000\"], [\"70303.80\", \"0.420\"], [\"70312.50\", \"0.050\"], [\"70318.70\", \"3.880\"], [\"70321.80\", \"1.061\"], [\"70367.50\", \"0.006\"], [\"70368.30\", \"0.296\"], [\"70369.70\", \"0.008\"], [\"70370.80\", \"0.007\"], [\"70371.00\", \"0.004\"], [\"70371.40\", \"0.002\"], [\"70373.00\", \"0.144\"], [\"70376.60\", \"0.197\"], [\"70376.70\", \"0.044\"], [\"70380.20\", \"0.006\"], [\"70385.60\", \"0.000\"]], \"a\": [[\"70387.40\", \"4.252\"], [\"70392.00\", \"0.005\"], [\"70392.40\", \"0.006\"], [\"70394.40\", \"0.106\"], [\"70398.00\", \"0.102\"], [\"70399.90\", \"0.515\"], [\"70401.90\", \"0.145\"], [\"70404.00\", \"0.001\"], [\"70405.10\", \"0.336\"], [\"70406.10\", \"0.068\"], [\"70407.30\", \"0.005\"], [\"70408.20\", \"0.011\"], [\"70409.10\", \"2.266\"], [\"70412.20\", \"0.002\"], [\"70413.30\", \"1.007\"], [\"70413.50\", \"0.374\"], [\"70414.50\", \"0.020\"], [\"70415.30\", \"0.002\"], [\"70441.60\", \"0.004\"], [\"70446.10\", \"0.000\"], [\"70458.30\", \"0.004\"], [\"70462.70\", \"0.003\"], [\"70466.50\", \"0.190\"], [\"70477.90\", \"0.382\"], [\"70488.40\", \"0.017\"], [\"70489.30\", \"0.004\"], [\"70526.80\", \"0.189\"], [\"70911.80\", \"0.000\"], [\"71091.30\", \"0.000\"], [\"77426.10\", \"0.036\"], [\"89523.20\", \"0.000\"]]}", "symbol": "BTCUSDT"}
{"event": "depthUpdate", "raw_payload": "{\"e\": \"depthUpdate\", \"E\": 1773246397010, \"T\": 1773246397008, \"s\": \"BTCUSDT\", \"U\": 10089704921134, \"u\": 10089704926255, \"pu\": 10089704921109, \"b\": [[\"5000.00\", \"101.438\"], [\"19887.30\", \"0.980\"], [\"19991.80\", \"0.620\"], [\"20087.30\", \"0.640\"], [\"20191.80\", \"0.160\"], [\"63348.60\", \"0.000\"], [\"66856.30\", \"0.002\"], [\"68364.40\", \"0.002\"], [\"69258.30\", \"0.437\"], [\"69296.30\", \"6.003\"], [\"69401.00\", \"0.008\"], [\"69437.10\", \"1.000\"], [\"69471.30\", \"0.000\"], [\"69507.50\", \"2.139\"], [\"69532.90\", \"0.008\"], [\"69577.80\", \"2.858\"], [\"69683.40\", \"1.420\"], [\"69708.70\", \"0.000\"], [\"69753.80\", \"4.970\"], [\"69753.90\", \"0.710\"], [\"69800.10\", \"0.771\"], [\"69870.00\", \"3.770\"], [\"69918.00\", \"0.000\"], [\"69918.10\", \"0.002\"], [\"70039.80\", \"0.002\"], [\"70143.70\", \"0.040\"], [\"70186.30\", \"0.247\"], [\"70196.50\", \"0.085\"], [\"70196.90\", \"0.047\"], [\"70236.40\", \"0.003\"], [\"70306.40\", \"0.000\"], [\"70309.90\", \"0.135\"], [\"70318.70\", \"3.883\"], [\"70319.50\", \"0.072\"], [\"70323.30\", \"0.084\"], [\"70347.70\", \"0.010\"], [\"70356.40\", \"0.003\"], [\"70364.00\", \"0.551\"], [\"70365.30\", \"0.002\"], [\"70365.50\", \"0.020\"], [\"70368.80\", \"0.083\"], [\"70370.70\", \"0.288\"], [\"70371.50\", \"0.002\"], [\"70373.30\", \"0.002\"], [\"70374.70\", \"0.292\"], [\"70376.30\", \"0.222\"], [\"70376.40\", \"0.004\"], [\"70376.70\", \"0.041\"], [\"70377.70\", \"0.323\"], [\"70380.20\", \"0.003\"], [\"70380.30\", \"0.005\"], [\"70382.10\", \"0.017\"], [\"70387.30\", \"3.005\"]], \"a\": [[\"70387.40\", \"3.298\"], [\"70391.90\", \"0.008\"], [\"70392.00\", \"0.010\"], [\"70392.20\", \"0.000\"], [\"70394.40\", \"0.004\"], [\"70395.20\", \"0.438\"], [\"70398.00\", \"0.102\"], [\"70398.40\", \"0.687\"], [\"70401.00\", \"0.078\"], [\"70401.50\", \"0.024\"], [\"70403.00\", \"0.054\"], [\"70404.20\", \"0.346\"], [\"70405.50\", \"0.004\"], [\"70406.10\", \"0.061\"], [\"70406.50\", \"0.004\"], [\"70407.30\", \"0.012\"], [\"70413.20\", \"0.513\"], [\"70414.00\", \"0.203\"], [\"70414.60\", \"0.002\"], [\"70415.60\", \"0.009\"], [\"70419.00\", \"0.029\"], [\"70422.50\", \"0.081\"], [\"70424.20\", \"0.002\"], [\"70424.30\", \"0.004\"], [\"70424.90\", \"0.000\"], [\"70425.00\", \"0.017\"], [\"70426.10\", \"0.615\"], [\"70429.60\", \"0.056\"], [\"70500.70\", \"0.005\"], [\"70505.60\", \"0.601\"], [\"70561.30\", \"0.042\"], [\"70834.80\", \"0.000\"], [\"70904.70\", \"3.720\"], [\"71091.30\", \"0.000\"], [\"73912.10\", \"0.000\"], [\"77426.10\", \"0.034\"]]}", "symbol": "BTCUSDT"}
{"event": "depthUpdate", "raw_payload": "{\"e\": \"depthUpdate\", \"E\": 1773246397112, \"T\": 1773246397110, \"s\": \"BTCUSDT\", \"U\": 10089704926425, \"u\": 10089704933311, \"pu\": 10089704926255, \"b\": [[\"1000.00\", \"26.792\"], [\"5000.00\", \"101.438\"], [\"19887.30\", \"1.140\"], [\"19991.80\", \"0.460\"], [\"20087.30\", \"0.730\"], [\"20191.80\", \"0.070\"], [\"56310.00\", \"100.003\"], [\"69425.70\", \"0.000\"], [\"69634.60\", \"0.000\"], [\"69683.40\", \"1.420\"], [\"69717.50\", \"0.000\"], [\"69753.80\", \"5.665\"], [\"69792.20\", \"0.000\"], [\"69852.80\", \"0.000\"], [\"70035.40\", \"0.036\"], [\"70154.30\", \"0.074\"], [\"70157.90\", \"0.000\"], [\"70196.00\", \"2.650\"], [\"70196.20\", \"0.241\"], [\"70196.50\", \"0.128\"], [\"70197.20\", \"0.058\"], [\"70197.80\", \"0.035\"], [\"70197.90\", \"0.035\"], [\"70246.90\", \"0.004\"], [\"70251.20\", \"0.029\"], [\"70255.30\", \"1.389\"], [\"70284.60\", \"0.000\"], [\"70334.10\", \"0.205\"], [\"70334.50\", \"0.513\"], [\"70340.10\", \"0.087\"], [\"70340.20\", \"0.000\"], [\"70340.30\", \"0.001\"], [\"70340.40\", \"0.002\"], [\"70343.00\", \"2.101\"], [\"70350.00\", \"0.006\"], [\"70351.30\", \"0.105\"], [\"70352.10\", \"0.003\"], [\"70357.00\", \"0.005\"], [\"70360.40\", \"0.000\"], [\"70360.50\", \"0.207\"], [\"70361.10\", \"0.011\"], [\"70361.20\", \"0.004\"], [\"70363.90\", \"0.511\"], [\"70364.00\", \"0.551\"], [\"70364.60\", \"0.026\"], [\"70364.70\", \"0.014\"], [\"70367.30\", \"0.466\"], [\"70371.00\", \"0.004\"], [\"70374.40\", \"0.223\"], [\"70376.40\", \"0.000\"], [\"70376.50\", \"0.210\"], [\"70376.70\", \"0.044\"], [\"70380.20\", \"0.016\"], [\"70385.40\", \"0.002\"], [\"70385.60\", \"0.003\"]], \"a\": [[\"70390.20\", \"0.002\"], [\"70391.90\", \"0.008\"], [\"70393.50\", \"0.127\"], [\"70394.40\", \"0.106\"], [\"70395.20\", \"0.438\"], [\"70398.00\", \"0.105\"], [\"70398.40\", \"0.262\"], [\"70399.00\", \"0.221\"], [\"70400.10\", \"0.002\"], [\"70402.80\", \"0.648\"], [\"70406.00\", \"0.076\"], [\"70413.00\", \"0.008\"], [\"70420.00\", \"1.078\"], [\"70427.00\", \"0.002\"], [\"70434.00\", \"0.008\"], [\"70439.90\", \"0.033\"], [\"70440.00\", \"0.199\"], [\"70440.10\", \"0.048\"], [\"70442.00\", \"0.602\"], [\"70503.60\", \"0.362\"], [\"70504.90\", \"0.434\"], [\"70518.90\", \"0.446\"], [\"70520.40\", \"1.701\"], [\"70568.30\", \"0.006\"], [\"70571.60\", \"0.080\"], [\"70687.40\", \"0.011\"], [\"70962.30\", \"0.000\"], [\"71067.20\", \"0.000\"], [\"71125.50\", \"0.000\"], [\"71338.90\", \"0.000\"], [\"71620.00\", \"0.136\"], [\"73921.10\", \"0.006\"], [\"89523.20\", \"0.000\"]]}", "symbol": "BTCUSDT"}
{"event": "depthUpdate", "raw_payload": "{\"e\": \"depthUpdate\", \"E\": 1773246397214, \"T\": 1773246397212, \"s\": \"BTCUSDT\", \"U\": 10089704933481, \"u\": 10089704941572, \"pu\": 10089704933311, \"b\": [[\"1000.00\", \"26.792\"], [\"5000.00\", \"101.438\"], [\"19887.30\", \"1.320\"], [\"19987.30\", \"0.320\"], [\"19991.80\", \"0.280\"], [\"20087.30\", \"0.800\"], [\"20091.80\", \"0.170\"], [\"20191.80\", \"0.000\"], [\"66837.10\", \"0.033\"], [\"66867.00\", \"0.000\"], [\"68893.00\", \"0.014\"], [\"69260.30\", \"0.010\"], [\"69296.30\", \"7.003\"], [\"69330.60\", \"0.000\"], [\"69366.70\", \"10.569\"], [\"69683.40\", \"1.581\"], [\"69753.80\", \"6.375\"], [\"69870.00\", \"0.050\"], [\"69872.40\", \"3.792\"], [\"70130.40\", \"0.002\"], [\"70135.80\", \"0.002\"], [\"70160.70\", \"1.924\"], [\"70195.50\", \"0.218\"], [\"70321.70\", \"0.165\"], [\"70334.50\", \"0.511\"], [\"70335.00\", \"0.007\"], [\"70340.00\", \"0.100\"], [\"70340.10\", \"0.002\"], [\"70340.20\", \"0.000\"], [\"70351.10\", \"0.002\"], [\"70360.40\", \"0.002\"], [\"70360.50\", \"0.209\"], [\"70361.10\", \"0.009\"], [\"70361.20\", \"0.002\"], [\"70363.90\", \"0.513\"], [\"70364.00\", \"0.553\"], [\"70364.60\", \"0.024\"], [\"70364.70\", \"0.012\"], [\"70368.10\", \"1.071\"], [\"70369.60\", \"0.294\"], [\"70374.40\", \"0.110\"], [\"70376.20\", \"0.133\"], [\"70376.50\", \"0.210\"], [\"70376.70\", \"0.044\"], [\"70380.20\", \"0.016\"], [\"70381.90\", \"0.307\"]], \"a\": [[\"70387.40\", \"3.026\"], [\"70391.90\", \"0.010\"], [\"70393.50\", \"0.127\"], [\"70394.40\", \"0.004\"], [\"70395.20\", \"0.438\"], [\"70398.00\", \"0.105\"], [\"70399.00\", \"0.221\"], [\"70405.50\", \"0.004\"], [\"70413.30\", \"0.007\"], [\"70414.90\", \"1.010\"], [\"70422.50\", \"0.034\"], [\"70424.90\", \"0.011\"], [\"70428.40\", \"0.013\"], [\"70440.70\", \"0.000\"], [\"70511.60\", \"0.482\"], [\"70707.40\", \"0.037\"], [\"70799.20\", \"0.016\"], [\"70805.10\", \"0.000\"], [\"70902.30\", \"3.720\"], [\"70904.70\", \"0.000\"], [\"71091.30\", \"0.000\"]]}", "symbol": "BTCUSDT"}
{"event": "depthUpdate", "raw_payload": "{\"e\": \"depthUpdate\", \"E\": 1773246397316, \"T\": 1773246397315, \"s\": \"BTCUSDT\", \"U\": 10089704941735, \"u\": 10089704948174, \"pu\": 10089704941572, \"b\": [[\"5000.00\", \"101.438\"], [\"19887.30\", \"1.480\"], [\"19987.30\", \"0.410\"], [\"19991.80\", \"0.120\"], [\"20091.80\", \"0.080\"], [\"33000.00\", \"10.797\"], [\"56310.00\", \"100.003\"], [\"66831.30\", \"0.002\"], [\"66840.80\", \"0.002\"], [\"68983.20\", \"0.002\"], [\"69329.50\", \"0.000\"], [\"69366.70\", \"11.568\"], [\"69533.10\", \"3.240\"], [\"69683.40\", \"1.581\"], [\"69792.30\", \"0.002\"], [\"69800.10\", \"0.123\"], [\"69872.40\", \"0.072\"], [\"69895.30\", \"0.000\"], [\"69896.80\", \"3.720\"], [\"70035.40\", \"0.036\"], [\"70040.60\", \"33.251\"], [\"70040.70\", \"0.657\"], [\"70041.80\", \"5.250\"], [\"70117.80\", \"27.783\"], [\"70118.00\", \"5.376\"], [\"70176.10\", \"0.010\"], [\"70289.20\", \"0.002\"], [\"70294.80\", \"0.344\"], [\"70296.90\", \"1.111\"], [\"70297.50\", \"0.071\"], [\"70297.70\", \"0.000\"], [\"70304.60\", \"0.071\"], [\"70304.80\", \"0.003\"], [\"70311.60\", \"0.156\"], [\"70311.80\", \"0.010\"], [\"70320.40\", \"0.002\"], [\"70321.70\", \"0.065\"], [\"70335.00\", \"0.005\"], [\"70335.20\", \"0.348\"], [\"70340.00\", \"0.015\"], [\"70340.10\", \"0.087\"], [\"70345.00\", \"0.245\"], [\"70360.40\", \"0.000\"], [\"70360.50\", \"0.207\"], [\"70361.10\", \"0.011\"], [\"70361.20\", \"0.004\"], [\"70363.90\", \"0.511\"], [\"70364.00\", \"0.551\"], [\"70364.60\", \"0.026\"], [\"70364.70\", \"0.014\"], [\"70371.50\", \"0.004\"], [\"70376.50\", \"0.210\"], [\"70376.70\", \"0.041\"], [\"70380.20\", \"0.013\"], [\"70380.30\", \"0.005\"]], \"a\": [[\"70387.40\", \"3.279\"], [\"70391.80\", \"0.002\"], [\"70391.90\", \"0.008\"], [\"70393.50\", \"0.127\"], [\"70393.60\", \"0.003\"], [\"70394.40\", \"0.106\"], [\"70395.20\", \"0.002\"], [\"70398.00\", \"0.105\"], [\"70399.00\", \"0.008\"], [\"70400.30\", \"0.003\"], [\"70422.50\", \"0.071\"], [\"70435.60\", \"0.394\"], [\"70473.70\", \"0.158\"], [\"70473.90\", \"0.000\"], [\"70480.70\", \"0.150\"], [\"70480.90\", \"0.130\"], [\"70487.80\", \"0.292\"], [\"70488.00\", \"0.193\"], [\"70651.00\", \"4.230\"], [\"70651.10\", \"27.324\"], [\"70728.60\", \"5.051\"], [\"70728.70\", \"0.650\"], [\"70728.80\", \"33.273\"], [\"70799.90\", \"22.014\"], [\"70877.90\", \"3.720\"], [\"70879.40\", \"0.012\"], [\"70887.80\", \"0.002\"], [\"70902.30\", \"0.000\"], [\"70903.30\", \"0.000\"], [\"71091.30\", \"0.000\"], [\"71093.50\", \"0.000\"], [\"71098.90\", \"0.049\"], [\"71306.10\", \"0.047\"], [\"89523.20\", \"0.000\"]]}", "symbol": "BTCUSDT"}
{"event": "depthUpdate", "raw_payload": "{\"e\": \"depthUpdate\", \"E\": 1773246397418, \"T\": 1773246397417, \"s\": \"BTCUSDT\", \"U\": 10089704948244, \"u\": 10089704954191, \"pu\": 10089704948174, \"b\": [[\"1000.00\", \"26.792\"], [\"5000.00\", \"101.438\"], [\"19887.30\", \"1.600\"], [\"19891.10\", \"0.000\"], [\"19891.80\", \"0.000\"], [\"19987.30\", \"0.490\"], [\"19991.80\", \"0.000\"], [\"20091.80\", \"0.000\"], [\"20287.30\", \"0.060\"], [\"33000.00\", \"10.793\"], [\"66845.40\", \"0.004\"], [\"69137.60\", \"0.002\"], [\"69234.00\", \"1.718\"], [\"69497.70\", \"0.000\"], [\"69542.60\", \"2.136\"], [\"69683.40\", \"1.581\"], [\"69896.80\", \"0.000\"], [\"70187.10\", \"0.000\"], [\"70255.30\", \"1.401\"], [\"70306.40\", \"0.084\"], [\"70335.00\", \"0.007\"], [\"70335.20\", \"0.346\"], [\"70340.00\", \"0.100\"], [\"70340.10\", \"0.002\"], [\"70343.30\", \"0.232\"], [\"70352.80\", \"0.000\"], [\"70357.40\", \"0.035\"], [\"70360.50\", \"0.152\"], [\"70370.00\", \"0.268\"], [\"70371.00\", \"0.004\"], [\"70372.90\", \"0.189\"], [\"70373.00\", \"0.002\"], [\"70374.70\", \"0.006\"], [\"70376.40\", \"0.004\"], [\"70376.50\", \"0.206\"], [\"70376.60\", \"0.197\"], [\"70376.70\", \"0.041\"], [\"70377.70\", \"0.037\"], [\"70378.20\", \"0.016\"], [\"70380.20\", \"0.013\"], [\"70385.60\", \"0.000\"], [\"70386.00\", \"0.002\"], [\"70387.30\", \"2.616\"]], \"a\": [[\"70387.40\", \"4.090\"], [\"70389.70\", \"0.000\"], [\"70389.90\", \"0.007\"], [\"70393.50\", \"0.175\"], [\"70394.40\", \"0.153\"], [\"70395.20\", \"0.002\"], [\"70398.00\", \"0.105\"], [\"70399.90\", \"0.515\"], [\"70404.60\", \"0.027\"], [\"70405.00\", \"0.029\"], [\"70413.50\", \"1.374\"], [\"70414.90\", \"0.010\"], [\"70422.50\", \"0.034\"], [\"70439.70\", \"0.128\"], [\"70440.00\", \"0.071\"], [\"70511.40\", \"1.298\"], [\"70518.90\", \"0.446\"], [\"70520.30\", \"1.563\"], [\"70520.40\", \"0.142\"], [\"70526.20\", \"0.262\"], [\"70533.20\", \"0.099\"], [\"70538.00\", \"0.093\"], [\"70544.00\", \"0.115\"], [\"70547.70\", \"0.093\"], [\"70549.70\", \"1.583\"], [\"70551.00\", \"0.095\"], [\"70554.70\", \"0.093\"], [\"70557.10\", \"1.691\"], [\"70707.40\", \"0.002\"], [\"70876.60\", \"3.723\"], [\"70877.90\", \"0.000\"], [\"70880.80\", \"0.007\"], [\"71091.30\", \"0.000\"], [\"71518.80\", \"0.002\"], [\"71731.40\", \"0.000\"]]}", "symbol": "BTCUSDT"}
{"event": "depthUpdate", "raw_payload": "{\"e\": \"depthUpdate\", \"E\": 1773246397522, \"T\": 1773246397520, \"s\": \"BTCUSDT\", \"U\": 10089704954357, \"u\": 10089704958335, \"pu\": 10089704954191, \"b\": [[\"1000.00\", \"26.792\"], [\"5000.00\", \"101.418\"], [\"19887.30\", \"1.620\"], [\"19889.50\", \"0.000\"], [\"19987.30\", \"0.510\"], [\"19987.60\", \"0.000\"], [\"19989.70\", \"0.000\"], [\"20087.30\", \"0.730\"], [\"20088.90\", \"0.000\"], [\"20091.00\", \"0.000\"], [\"20287.30\", \"0.140\"], [\"68188.20\", \"0.630\"], [\"69683.40\", \"1.581\"], [\"70262.30\", \"0.191\"], [\"70318.60\", \"0.006\"], [\"70346.80\", \"0.003\"], [\"70348.70\", \"0.422\"], [\"70354.90\", \"0.162\"], [\"70360.40\", \"0.002\"], [\"70360.50\", \"0.154\"], [\"70361.10\", \"0.009\"], [\"70361.20\", \"0.002\"], [\"70362.60\", \"0.000\"], [\"70363.90\", \"0.513\"], [\"70364.00\", \"0.553\"], [\"70364.60\", \"0.024\"], [\"70364.70\", \"0.012\"], [\"70373.20\", \"0.004\"], [\"70380.20\", \"0.013\"], [\"70387.30\", \"2.608\"]], \"a\": [[\"70404.60\", \"0.025\"], [\"70427.90\", \"0.006\"], [\"70456.10\", \"0.005\"], [\"70512.40\", \"0.295\"], [\"70575.50\", \"0.002\"], [\"70577.70\", \"0.114\"], [\"70581.90\", \"0.196\"], [\"70584.70\", \"1.332\"], [\"70591.70\", \"0.388\"], [\"70593.90\", \"0.000\"], [\"70598.70\", \"0.007\"], [\"70600.90\", \"0.385\"], [\"70605.70\", \"0.009\"], [\"70607.90\", \"8.136\"], [\"70612.70\", \"0.007\"], [\"70614.90\", \"0.000\"], [\"70619.70\", \"0.009\"], [\"70621.90\", \"0.000\"], [\"70626.70\", \"0.007\"], [\"70628.90\", \"0.000\"], [\"70635.90\", \"0.200\"], [\"70642.90\", \"0.006\"], [\"70876.60\", \"0.003\"], [\"70901.20\", \"0.004\"], [\"71091.30\", \"0.000\"], [\"73923.50\", \"0.002\"], [\"89523.20\", \"0.000\"]]}", "symbol": "BTCUSDT"}
{"event": "depthUpdate", "raw_payload": "{\"e\": \"depthUpdate\", \"E\": 1773246397624, \"T\": 1773246397623, \"s\": \"BTCUSDT\", \"U\": 10089704958431, \"u\": 10089704974894, \"pu\": 10089704958335, \"b\": [[\"5000.00\", \"101.418\"], [\"19885.20\", \"0.060\"], [\"19885.40\", \"0.010\"], [\"19887.30\", \"1.540\"], [\"19985.20\", \"0.060\"], [\"19985.40\", \"0.010\"], [\"19987.30\", \"0.440\"], [\"20087.30\", \"0.650\"], [\"20285.20\", \"0.070\"], [\"20287.20\", \"0.010\"], [\"20287.30\", \"0.150\"], [\"69682.50\", \"0.000\"], [\"69683.40\", \"1.540\"], [\"69683.50\", \"0.724\"], [\"69793.90\", \"0.068\"], [\"69882.70\", \"0.002\"], [\"69887.40\", \"0.000\"], [\"70005.60\", \"0.002\"], [\"70017.30\", \"0.002\"], [\"70018.20\", \"0.002\"], [\"70035.40\", \"0.036\"], [\"70066.10\", \"0.040\"], [\"70088.00\", \"0.231\"], [\"70136.90\", \"0.047\"], [\"70154.30\", \"0.067\"], [\"70192.80\", \"7.803\"], [\"70255.20\", \"0.014\"], [\"70257.00\", \"0.081\"], [\"70259.10\", \"2.005\"], [\"70262.30\", \"0.188\"], [\"70265.10\", \"0.081\"], [\"70292.00\", \"0.056\"], [\"70292.90\", \"4.063\"], [\"70294.00\", \"2.928\"], [\"70296.90\", \"0.402\"], [\"70298.40\", \"0.003\"], [\"70301.00\", \"0.572\"], [\"70302.70\", \"0.000\"], [\"70304.50\", \"0.364\"], [\"70305.40\", \"0.087\"], [\"70306.30\", \"0.084\"], [\"70309.90\", \"0.000\"], [\"70310.80\", \"0.050\"], [\"70315.50\", \"0.002\"], [\"70317.50\", \"0.200\"], [\"70318.60\", \"0.003\"], [\"70329.60\", \"0.459\"], [\"70330.20\", \"0.002\"], [\"70330.80\", \"0.358\"], [\"70331.80\", \"0.002\"], [\"70332.10\", \"0.045\"], [\"70332.40\", \"0.090\"], [\"70332.60\", \"0.064\"], [\"70332.90\", \"0.008\"], [\"70333.40\", \"0.004\"], [\"70334.60\", \"0.560\"], [\"70335.00\", \"0.005\"], [\"70335.70\", \"0.042\"], [\"70337.40\", \"0.005\"], [\"70339.10\", \"0.711\"], [\"70339.60\", \"0.273\"], [\"70339.80\", \"0.000\"], [\"70340.00\", \"0.015\"], [\"70340.70\", \"0.001\"], [\"70340.80\", \"0.027\"], [\"70341.40\", \"0.205\"], [\"70341.50\", \"0.458\"], [\"70343.10\", \"0.788\"], [\"70343.30\", \"0.160\"], [\"70343.60\", \"0.273\"], [\"70345.10\", \"0.002\"], [\"70345.30\", \"0.000\"], [\"70345.40\", \"0.003\"], [\"70346.50\", \"0.002\"], [\"70346.80\", \"0.000\"], [\"70348.00\", \"0.003\"], [\"70348.60\", \"0.015\"], [\"70348.90\", \"0.230\"], [\"70349.70\", \"0.003\"], [\"70350.00\", \"0.010\"], [\"70350.10\", \"0.054\"], [\"70351.10\", \"0.086\"], [\"70354.10\", \"0.002\"], [\"70354.20\", \"0.006\"], [\"70354.30\", \"0.000\"], [\"70354.50\", \"0.081\"], [\"70354.60\", \"0.513\"], [\"70354.70\", \"0.033\"], [\"70354.90\", \"0.082\"], [\"70355.40\", \"0.040\"], [\"70355.60\", \"0.000\"], [\"70355.80\", \"0.071\"], [\"70356.30\", \"0.846\"], [\"70356.60\", \"3.303\"], [\"70356.90\", \"0.009\"], [\"70357.00\", \"0.065\"], [\"70357.20\", \"0.429\"], [\"70357.40\", \"0.000\"], [\"70357.60\", \"0.000\"], [\"70357.70\", \"0.000\"], [\"70358.10\", \"0.071\"], [\"70358.30\", \"0.002\"], [\"70358.40\", \"0.002\"], [\"70358.80\", \"0.002\"], [\"70358.90\", \"0.002\"], [\"70359.00\", \"0.002\"], [\"70359.10\", \"0.000\"], [\"70359.40\", \"0.116\"], [\"70359.70\", \"0.000\"], [\"70359.80\", \"0.000\"], [\"70360.40\", \"0.000\"], [\"70360.50\", \"0.275\"], [\"70360.80\", \"0.006\"], [\"70360.90\", \"0.000\"], [\"70361.20\", \"0.007\"], [\"70361.30\", \"0.012\"], [\"70361.60\", \"0.349\"], [\"70361.70\", \"1.578\"], [\"70361.80\", \"0.008\"], [\"70361.90\", \"0.002\"], [\"70362.10\", \"0.068\"], [\"70362.30\", \"0.002\"], [\"70362.40\", \"0.010\"], [\"70362.50\", \"0.010\"], [\"70362.60\", \"0.000\"], [\"70362.70\", \"0.016\"], [\"70362.80\", \"0.071\"], [\"70363.00\", \"0.009\"], [\"70363.10\", \"0.006\"], [\"70363.20\", \"0.002\"], [\"70363.30\", \"0.009\"], [\"70363.50\", \"0.202\"], [\"70363.60\", \"0.606\"], [\"70363.90\", \"0.000\"], [\"70364.00\", \"0.009\"], [\"70364.10\", \"0.000\"], [\"70364.20\", \"0.009\"], [\"70364.30\", \"0.002\"], [\"70364.40\", \"1.210\"], [\"70364.60\", \"0.000\"], [\"70364.70\", \"0.012\"], [\"70364.80\", \"0.284\"], [\"70364.90\", \"0.007\"], [\"70365.00\", \"0.305\"], [\"70365.20\", \"0.004\"], [\"70365.30\", \"0.020\"], [\"70365.40\", \"0.003\"], [\"70365.60\", \"0.242\"], [\"70366.20\", \"0.080\"], [\"70366.40\", \"0.060\"], [\"70366.50\", \"0.001\"], [\"70366.90\", \"0.000\"], [\"70367.10\", \"0.137\"], [\"70367.20\", \"0.000\"], [\"70367.40\", \"1.412\"], [\"70367.70\", \"0.005\"], [\"70368.00\", \"0.003\"], [\"70368.10\", \"0.005\"], [\"70368.20\", \"0.028\"], [\"70368.30\", \"0.003\"], [\"70368.40\", \"0.171\"], [\"70368.50\", \"0.002\"], [\"70368.60\", \"0.073\"], [\"70368.80\", \"0.003\"], [\"70368.90\", \"0.000\"], [\"70369.60\", \"0.252\"], [\"70369.70\", \"0.004\"], [\"70369.80\", \"0.012\"], [\"70369.90\", \"0.087\"], [\"70370.00\", \"0.248\"], [\"70370.30\", \"0.222\"], [\"70370.50\", \"0.161\"], [\"70370.60\", \"0.257\"], [\"70370.70\", \"0.657\"], [\"70370.80\", \"0.007\"], [\"70371.00\", \"0.405\"], [\"70371.10\", \"0.087\"], [\"70371.20\", \"0.021\"], [\"70371.30\", \"0.143\"], [\"70371.40\", \"0.018\"], [\"70371.80\", \"0.007\"], [\"70372.20\", \"0.003\"], [\"70372.30\", \"0.036\"], [\"70372.60\", \"0.047\"], [\"70372.80\", \"0.179\"], [\"70372.90\", \"0.047\"], [\"70373.10\", \"0.004\"], [\"70373.50\", \"0.000\"], [\"70373.90\", \"0.000\"], [\"70374.00\", \"0.097\"], [\"70374.10\", \"0.003\"], [\"70374.50\", \"0.002\"], [\"70374.60\", \"0.000\"], [\"70374.80\", \"0.049\"], [\"70375.10\", \"0.000\"], [\"70375.30\", \"0.014\"], [\"70375.40\", \"0.004\"], [\"70375.50\", \"0.000\"], [\"70375.60\", \"0.003\"], [\"70375.70\", \"0.001\"], [\"70375.80\", \"0.000\"], [\"70376.20\", \"0.085\"], [\"70376.30\", \"0.002\"], [\"70376.40\", \"0.000\"], [\"70376.50\", \"0.003\"], [\"70376.60\", \"0.002\"], [\"70376.70\", \"0.003\"], [\"70376.80\", \"0.247\"], [\"70376.90\", \"0.000\"], [\"70377.00\", \"0.000\"], [\"70377.30\", \"0.002\"], [\"70377.40\", \"0.004\"], [\"70377.50\", \"0.000\"], [\"70377.60\", \"0.070\"], [\"70377.70\", \"0.002\"], [\"70377.80\", \"0.003\"], [\"70378.00\", \"0.007\"], [\"70378.10\", \"0.005\"], [\"70378.20\", \"0.003\"], [\"70378.40\", \"0.279\"], [\"70378.50\", \"0.004\"], [\"70378.90\", \"0.047\"], [\"70379.00\", \"1.002\"], [\"70379.10\", \"0.001\"], [\"70379.20\", \"0.000\"], [\"70379.30\", \"0.000\"], [\"70379.40\", \"0.001\"], [\"70379.50\", \"0.000\"], [\"70379.70\", \"0.002\"], [\"70380.10\", \"0.002\"], [\"70380.20\", \"0.000\"], [\"70380.30\", \"0.001\"], [\"70380.40\", \"0.000\"], [\"70380.50\", \"0.004\"], [\"70380.60\", \"0.003\"], [\"70380.70\", \"0.001\"], [\"70380.80\", \"0.021\"], [\"70381.00\", \"0.003\"], [\"70381.50\", \"0.052\"], [\"70381.80\", \"0.003\"], [\"70381.90\", \"0.000\"], [\"70382.00\", \"0.003\"], [\"70382.10\", \"0.013\"], [\"70382.30\", \"0.002\"], [\"70382.40\", \"0.000\"], [\"70382.50\", \"0.001\"], [\"70382.60\", \"0.005\"], [\"70382.90\", \"0.003\"], [\"70383.10\", \"0.000\"], [\"70383.20\", \"0.000\"], [\"70383.50\", \"0.003\"], [\"70383.70\", \"0.000\"], [\"70383.80\", \"0.002\"], [\"70384.00\", \"0.002\"], [\"70384.50\", \"0.000\"], [\"70384.90\", \"0.003\"], [\"70385.00\", \"0.000\"], [\"70385.10\", \"0.002\"], [\"70385.20\", \"0.806\"], [\"70385.30\", \"0.000\"], [\"70385.40\", \"0.000\"], [\"70385.80\", \"0.000\"], [\"70386.00\", \"0.000\"], [\"70386.10\", \"0.000\"], [\"70386.20\", \"0.000\"], [\"70386.40\", \"0.000\"], [\"70386.50\", \"0.000\"], [\"70386.70\", \"0.000\"], [\"70386.80\", \"0.000\"], [\"70386.90\", \"0.000\"], [\"70387.20\", \"0.000\"], [\"70387.30\", \"0.000\"]], \"a\": [[\"70385.30\", \"6.601\"], [\"70385.40\", \"0.133\"], [\"70385.50\", \"0.000\"], [\"70385.60\", \"0.000\"], [\"70385.70\", \"0.000\"], [\"70385.90\", \"0.000\"], [\"70386.00\", \"0.002\"], [\"70386.10\", \"0.000\"], [\"70386.20\", \"0.000\"], [\"70386.30\", \"0.000\"], [\"70386.40\", \"0.005\"], [\"70386.50\", \"0.040\"], [\"70386.60\", \"0.001\"], [\"70386.80\", \"0.000\"], [\"70386.90\", \"0.002\"], [\"70387.00\", \"0.005\"], [\"70387.10\", \"0.023\"], [\"70387.20\", \"0.009\"], [\"70387.30\", \"0.720\"], [\"70387.40\", \"0.003\"], [\"70387.50\", \"0.001\"], [\"70387.60\", \"0.000\"], [\"70387.80\", \"0.016\"], [\"70388.40\", \"0.003\"], [\"70388.50\", \"0.049\"], [\"70389.90\", \"0.010\"], [\"70390.00\", \"0.003\"], [\"70390.20\", \"0.043\"], [\"70390.40\", \"0.041\"], [\"70390.50\", \"0.006\"], [\"70390.70\", \"0.004\"], [\"70391.00\", \"0.202\"], [\"70391.10\", \"0.009\"], [\"70391.30\", \"0.006\"], [\"70391.40\", \"0.021\"], [\"70391.50\", \"0.005\"], [\"70391.80\", \"0.000\"], [\"70391.90\", \"0.029\"], [\"70392.20\", \"0.063\"], [\"70392.30\", \"0.107\"], [\"70392.50\", \"0.005\"], [\"70392.60\", \"0.291\"], [\"70392.70\", \"0.853\"], [\"70392.80\", \"0.000\"], [\"70393.10\", \"0.639\"], [\"70393.30\", \"0.006\"], [\"70393.50\", \"0.002\"], [\"70393.60\", \"0.003\"], [\"70393.70\", \"0.000\"], [\"70394.00\", \"0.004\"], [\"70394.10\", \"0.044\"], [\"70394.20\", \"0.003\"], [\"70394.30\", \"0.000\"], [\"70394.40\", \"0.006\"], [\"70394.60\", \"0.214\"], [\"70394.70\", \"0.000\"], [\"70394.80\", \"0.003\"], [\"70395.10\", \"0.007\"], [\"70395.20\", \"0.000\"], [\"70395.30\", \"0.515\"], [\"70395.40\", \"0.009\"], [\"70395.50\", \"0.647\"], [\"70395.60\", \"1.087\"], [\"70395.70\", \"0.043\"], [\"70395.80\", \"0.014\"], [\"70395.90\", \"0.109\"], [\"70396.20\", \"0.067\"], [\"70396.30\", \"0.102\"], [\"70396.40\", \"0.037\"], [\"70396.50\", \"0.043\"], [\"70396.60\", \"0.002\"], [\"70396.70\", \"0.144\"], [\"70396.80\", \"0.029\"], [\"70396.90\", \"0.021\"], [\"70397.00\", \"0.004\"], [\"70397.10\", \"0.000\"], [\"70397.20\", \"0.048\"], [\"70397.30\", \"0.000\"], [\"70397.40\", \"0.074\"], [\"70397.60\", \"0.066\"], [\"70397.70\", \"0.028\"], [\"70397.80\", \"0.006\"], [\"70397.90\", \"0.131\"], [\"70398.00\", \"0.000\"], [\"70398.10\", \"0.079\"], [\"70398.30\", \"0.002\"], [\"70398.40\", \"0.448\"], [\"70398.50\", \"0.344\"], [\"70398.70\", \"0.004\"], [\"70399.00\", \"0.065\"], [\"70399.10\", \"0.200\"], [\"70399.70\", \"0.014\"], [\"70399.80\", \"0.004\"], [\"70399.90\", \"0.513\"], [\"70400.10\", \"0.002\"], [\"70400.30\", \"0.005\"], [\"70400.40\", \"0.005\"], [\"70400.60\", \"0.004\"], [\"70401.00\", \"0.007\"], [\"70401.20\", \"0.099\"], [\"70401.30\", \"0.513\"], [\"70401.40\", \"0.006\"], [\"70401.70\", \"0.002\"], [\"70401.80\", \"0.000\"], [\"70401.90\", \"0.003\"], [\"70402.00\", \"0.437\"], [\"70402.40\", \"0.004\"], [\"70402.60\", \"0.004\"], [\"70402.70\", \"0.004\"], [\"70402.80\", \"0.648\"], [\"70402.90\", \"1.068\"], [\"70403.00\", \"0.007\"], [\"70403.40\", \"0.009\"], [\"70403.60\", \"0.003\"], [\"70404.10\", \"0.007\"], [\"70404.20\", \"0.344\"], [\"70404.90\", \"0.003\"], [\"70405.00\", \"0.027\"], [\"70405.20\", \"0.003\"], [\"70405.30\", \"0.073\"], [\"70405.50\", \"0.002\"], [\"70405.90\", \"0.070\"], [\"70406.50\", \"0.006\"], [\"70406.60\", \"0.004\"], [\"70406.70\", \"0.567\"], [\"70406.80\", \"0.000\"], [\"70407.00\", \"0.008\"], [\"70407.30\", \"0.005\"], [\"70407.50\", \"0.002\"], [\"70407.60\", \"0.058\"], [\"70407.70\", \"0.377\"], [\"70408.20\", \"0.004\"], [\"70408.40\", \"0.004\"], [\"70408.50\", \"0.043\"], [\"70408.60\", \"0.074\"], [\"70409.10\", \"1.755\"], [\"70409.20\", \"0.188\"], [\"70409.50\", \"0.326\"], [\"70409.60\", \"1.002\"], [\"70410.40\", \"0.007\"], [\"70410.50\", \"0.163\"], [\"70410.60\", \"0.004\"], [\"70410.70\", \"0.013\"], [\"70410.80\", \"0.030\"], [\"70410.90\", \"0.002\"], [\"70411.10\", \"0.002\"], [\"70411.70\", \"0.122\"], [\"70412.00\", \"0.002\"], [\"70412.10\", \"0.000\"], [\"70412.20\", \"0.002\"], [\"70412.30\", \"0.349\"], [\"70412.70\", \"0.010\"], [\"70413.30\", \"0.007\"], [\"70413.50\", \"0.374\"], [\"70413.80\", \"0.002\"], [\"70414.20\", \"0.011\"], [\"70414.30\", \"0.144\"], [\"70414.40\", \"0.000\"], [\"70414.60\", \"0.000\"], [\"70414.90\", \"0.061\"], [\"70415.30\", \"0.002\"], [\"70415.60\", \"0.002\"], [\"70415.80\", \"0.186\"], [\"70416.00\", \"0.271\"], [\"70416.20\", \"0.002\"], [\"70416.50\", \"0.564\"], [\"70416.60\", \"0.046\"], [\"70416.90\", \"0.000\"], [\"70419.10\", \"0.111\"], [\"70419.70\", \"0.198\"], [\"70420.00\", \"0.901\"], [\"70420.10\", \"0.215\"], [\"70420.40\", \"0.583\"], [\"70420.60\", \"0.054\"], [\"70421.00\", \"0.000\"], [\"70421.40\", \"0.008\"], [\"70421.50\", \"0.002\"], [\"70422.10\", \"0.004\"], [\"70422.20\", \"0.002\"], [\"70422.80\", \"0.000\"], [\"70422.90\", \"0.000\"], [\"70423.50\", \"0.011\"], [\"70423.60\", \"0.194\"], [\"70424.00\", \"0.142\"], [\"70424.20\", \"0.000\"], [\"70424.30\", \"0.002\"], [\"70424.90\", \"0.183\"], [\"70425.80\", \"1.314\"], [\"70426.10\", \"0.236\"], [\"70426.30\", \"0.004\"], [\"70426.40\", \"0.002\"], [\"70427.00\", \"0.002\"], [\"70427.10\", \"0.486\"], [\"70427.50\", \"0.008\"], [\"70427.70\", \"0.000\"], [\"70427.80\", \"10.419\"], [\"70427.90\", \"0.003\"], [\"70428.00\", \"0.002\"], [\"70428.40\", \"0.059\"], [\"70428.50\", \"0.005\"], [\"70429.10\", \"0.511\"], [\"70429.20\", \"0.002\"], [\"70429.30\", \"0.005\"], [\"70431.30\", \"0.000\"], [\"70436.10\", \"0.009\"], [\"70436.70\", \"0.218\"], [\"70439.50\", \"0.130\"], [\"70439.70\", \"0.000\"], [\"70440.10\", \"0.002\"], [\"70441.10\", \"0.000\"], [\"70443.40\", \"0.090\"], [\"70444.60\", \"0.194\"], [\"70444.80\", \"1.705\"], [\"70447.20\", \"0.028\"], [\"70447.40\", \"0.000\"], [\"70448.60\", \"0.116\"], [\"70450.60\", \"0.000\"], [\"70450.70\", \"0.000\"], [\"70452.20\", \"0.084\"], [\"70452.40\", \"0.002\"], [\"70455.90\", \"0.086\"], [\"70456.10\", \"0.002\"], [\"70465.50\", \"0.000\"], [\"70469.00\", \"1.914\"], [\"70469.20\", \"6.600\"], [\"70473.30\", \"0.000\"], [\"70478.90\", \"0.083\"], [\"70479.80\", \"0.003\"], [\"70485.20\", \"0.000\"], [\"70491.30\", \"0.006\"], [\"70494.70\", \"2.061\"], [\"70504.00\", \"0.085\"], [\"70509.40\", \"0.000\"], [\"70511.60\", \"0.382\"], [\"70512.40\", \"0.292\"], [\"70520.40\", \"0.000\"], [\"70527.70\", \"10.002\"], [\"70528.30\", \"0.039\"], [\"70544.10\", \"0.511\"], [\"70583.40\", \"0.003\"], [\"70586.90\", \"0.002\"], [\"70589.00\", \"0.022\"], [\"70590.40\", \"0.002\"], [\"70600.50\", \"0.002\"], [\"70693.90\", \"0.055\"], [\"70694.70\", \"0.003\"], [\"70765.10\", \"0.000\"], [\"70887.30\", \"0.000\"], [\"70891.70\", \"0.000\"], [\"70919.80\", \"0.000\"], [\"71089.20\", \"0.000\"], [\"71090.20\", \"0.000\"], [\"71091.30\", \"0.000\"], [\"71113.90\", \"0.004\"], [\"71287.10\", \"0.007\"], [\"71326.60\", \"0.250\"], [\"71352.20\", \"0.000\"], [\"71354.30\", \"0.486\"], [\"71359.70\", \"0.012\"], [\"71385.30\", \"0.002\"], [\"71385.50\", \"0.008\"], [\"71386.30\", \"0.002\"], [\"71386.50\", \"0.012\"], [\"71389.00\", \"0.011\"], [\"71389.40\", \"0.004\"], [\"71390.10\", \"0.000\"], [\"71391.10\", \"0.106\"], [\"71478.40\", \"0.349\"], [\"71539.30\", \"0.004\"], [\"71752.00\", \"0.011\"], [\"73918.90\", \"0.004\"], [\"73921.10\", \"0.004\"], [\"100000.00\", \"15.236\"]]}", "symbol": "BTCUSDT"}
{"event": "depthUpdate", "raw_payload": "{\"e\": \"depthUpdate\", \"E\": 1773246397726, \"T\": 1773246397725, \"s\": \"BTCUSDT\", \"U\": 10089704974919, \"u\": 10089704981708, \"pu\": 10089704974894, \"b\": [[\"1000.00\", \"26.792\"], [\"5000.00\", \"101.438\"], [\"19885.20\", \"0.150\"], [\"19887.30\", \"1.460\"], [\"19985.20\", \"0.150\"], [\"19987.30\", \"0.350\"], [\"20087.30\", \"0.560\"], [\"20285.20\", \"0.150\"], [\"20287.40\", \"0.007\"], [\"56308.00\", \"0.002\"], [\"66848.70\", \"0.007\"], [\"66852.80\", \"0.002\"], [\"68716.80\", \"0.004\"], [\"68964.80\", \"0.000\"], [\"69681.30\", \"0.000\"], [\"69683.50\", \"0.717\"], [\"70066.10\", \"0.000\"], [\"70128.80\", \"0.038\"], [\"70134.20\", \"0.038\"], [\"70135.80\", \"0.045\"], [\"70135.90\", \"0.043\"], [\"70136.60\", \"0.043\"], [\"70137.30\", \"0.058\"], [\"70137.70\", \"0.035\"], [\"70138.00\", \"1.455\"], [\"70143.90\", \"0.036\"], [\"70153.50\", \"0.002\"], [\"70221.30\", \"0.000\"], [\"70223.70\", \"0.768\"], [\"70238.40\", \"0.278\"], [\"70255.20\", \"0.000\"], [\"70258.30\", \"0.057\"], [\"70260.20\", \"0.095\"], [\"70278.00\", \"0.605\"], [\"70279.50\", \"0.000\"], [\"70279.60\", \"0.121\"], [\"70280.00\", \"1.427\"], [\"70305.40\", \"0.003\"], [\"70306.30\", \"0.000\"], [\"70306.40\", \"0.000\"], [\"70316.50\", \"0.007\"], [\"70318.70\", \"0.161\"], [\"70321.80\", \"0.510\"], [\"70325.80\", \"0.924\"], [\"70331.20\", \"0.004\"], [\"70331.70\", \"0.000\"], [\"70332.10\", \"0.971\"], [\"70332.60\", \"0.062\"], [\"70339.40\", \"0.005\"], [\"70339.60\", \"0.188\"], [\"70339.70\", \"0.085\"], [\"70339.80\", \"0.000\"], [\"70340.10\", \"0.005\"], [\"70343.50\", \"0.014\"], [\"70344.70\", \"0.514\"], [\"70346.20\", \"0.274\"], [\"70348.90\", \"0.207\"], [\"70354.40\", \"0.003\"], [\"70354.70\", \"0.003\"], [\"70356.20\", \"0.013\"], [\"70356.30\", \"0.855\"], [\"70356.60\", \"3.283\"], [\"70356.80\", \"0.072\"], [\"70356.90\", \"0.023\"], [\"70357.00\", \"0.056\"], [\"70357.60\", \"0.002\"], [\"70357.70\", \"0.002\"], [\"70358.30\", \"0.000\"], [\"70358.40\", \"0.000\"], [\"70360.60\", \"0.004\"], [\"70365.00\", \"0.004\"], [\"70366.10\", \"0.025\"], [\"70368.60\", \"0.001\"], [\"70369.50\", \"0.095\"], [\"70369.70\", \"0.040\"], [\"70369.90\", \"0.159\"], [\"70370.10\", \"0.482\"], [\"70370.20\", \"0.058\"], [\"70370.50\", \"0.204\"], [\"70370.60\", \"0.005\"], [\"70370.80\", \"0.451\"], [\"70370.90\", \"0.154\"], [\"70371.30\", \"0.178\"], [\"70371.40\", \"0.018\"], [\"70371.50\", \"0.020\"], [\"70371.80\", \"0.388\"], [\"70373.00\", \"0.002\"], [\"70373.10\", \"0.004\"], [\"70373.20\", \"0.283\"], [\"70374.00\", \"0.093\"], [\"70374.10\", \"0.003\"], [\"70374.20\", \"0.464\"], [\"70374.30\", \"0.004\"], [\"70374.40\", \"0.202\"], [\"70374.50\", \"0.002\"], [\"70374.70\", \"0.010\"], [\"70378.10\", \"0.047\"], [\"70378.20\", \"0.003\"], [\"70378.30\", \"0.002\"], [\"70378.90\", \"0.005\"], [\"70379.00\", \"0.002\"], [\"70381.10\", \"0.000\"], [\"70381.40\", \"0.005\"], [\"70382.20\", \"0.005\"], [\"70382.60\", \"1.003\"], [\"70382.70\", \"0.000\"], [\"70385.10\", \"0.002\"], [\"70385.20\", \"1.478\"]], \"a\": [[\"70385.30\", \"5.691\"], [\"70386.40\", \"0.003\"], [\"70386.50\", \"0.000\"], [\"70387.00\", \"0.007\"], [\"70387.80\", \"0.016\"], [\"70390.60\", \"0.102\"], [\"70390.80\", \"0.003\"], [\"70392.30\", \"0.005\"], [\"70393.10\", \"0.000\"], [\"70394.40\", \"0.008\"], [\"70394.70\", \"0.000\"], [\"70395.90\", \"0.007\"], [\"70396.20\", \"0.706\"], [\"70396.70\", \"0.002\"], [\"70398.30\", \"0.144\"], [\"70398.70\", \"0.002\"], [\"70399.30\", \"0.009\"], [\"70399.80\", \"0.002\"], [\"70401.30\", \"0.002\"], [\"70401.90\", \"0.005\"], [\"70402.00\", \"0.189\"], [\"70402.80\", \"0.652\"], [\"70403.20\", \"0.511\"], [\"70404.10\", \"0.255\"], [\"70405.30\", \"0.002\"], [\"70406.80\", \"0.000\"], [\"70408.70\", \"0.171\"], [\"70414.80\", \"0.006\"], [\"70419.30\", \"0.011\"], [\"70419.40\", \"0.009\"], [\"70420.00\", \"0.892\"], [\"70420.10\", \"0.206\"], [\"70421.40\", \"0.010\"], [\"70421.50\", \"0.004\"], [\"70422.10\", \"0.002\"], [\"70422.20\", \"0.000\"], [\"70424.00\", \"0.244\"], [\"70424.90\", \"0.153\"], [\"70425.60\", \"0.002\"], [\"70425.70\", \"0.007\"], [\"70425.80\", \"1.317\"], [\"70426.30\", \"0.002\"], [\"70426.40\", \"0.000\"], [\"70427.50\", \"0.144\"], [\"70428.00\", \"0.022\"], [\"70429.40\", \"0.009\"], [\"70432.30\", \"0.002\"], [\"70434.50\", \"0.436\"], [\"70434.90\", \"0.384\"], [\"70435.20\", \"0.005\"], [\"70435.60\", \"0.391\"], [\"70436.30\", \"0.004\"], [\"70436.70\", \"0.198\"], [\"70437.20\", \"0.000\"], [\"70439.30\", \"0.643\"], [\"70439.50\", \"0.002\"], [\"70440.80\", \"0.855\"], [\"70454.00\", \"0.127\"], [\"70458.40\", \"0.002\"], [\"70458.50\", \"0.654\"], [\"70458.80\", \"0.014\"], [\"70460.30\", \"0.008\"], [\"70466.90\", \"0.191\"], [\"70492.80\", \"0.088\"], [\"70507.80\", \"0.293\"], [\"70510.30\", \"0.189\"], [\"70525.50\", \"2.691\"], [\"70527.60\", \"0.018\"], [\"70543.30\", \"2.440\"], [\"70544.00\", \"0.097\"], [\"70554.50\", \"1.276\"], [\"70554.60\", \"0.000\"], [\"70733.70\", \"0.002\"], [\"71089.20\", \"0.000\"], [\"71180.30\", \"0.018\"], [\"89523.20\", \"0.000\"]]}", "symbol": "BTCUSDT"}
{"event": "depthUpdate", "raw_payload": "{\"e\": \"depthUpdate\", \"E\": 1773246397828, \"T\": 1773246397827, \"s\": \"BTCUSDT\", \"U\": 10089704981806, \"u\": 10089704987500, \"pu\": 10089704981708, \"b\": [[\"1000.00\", \"26.792\"], [\"5000.00\", \"101.418\"], [\"19885.20\", \"0.220\"], [\"19887.30\", \"1.360\"], [\"19985.20\", \"0.230\"], [\"19987.30\", \"0.280\"], [\"20087.30\", \"0.480\"], [\"20285.20\", \"0.250\"], [\"20287.40\", \"0.000\"], [\"68385.20\", \"0.003\"], [\"69141.70\", \"0.000\"], [\"69303.40\", \"1.000\"], [\"69385.70\", \"0.287\"], [\"69681.30\", \"0.000\"], [\"69810.10\", \"47.171\"], [\"69836.30\", \"3.720\"], [\"69936.00\", \"40.044\"], [\"70080.20\", \"0.123\"], [\"70100.60\", \"0.393\"], [\"70122.80\", \"0.047\"], [\"70135.10\", \"0.027\"], [\"70135.60\", \"0.047\"], [\"70136.60\", \"0.040\"], [\"70137.70\", \"0.054\"], [\"70156.50\", \"0.237\"], [\"70199.70\", \"0.051\"], [\"70213.30\", \"13.549\"], [\"70275.30\", \"6.874\"], [\"70313.30\", \"3.584\"], [\"70331.20\", \"0.002\"], [\"70331.90\", \"0.088\"], [\"70335.70\", \"0.002\"], [\"70337.00\", \"1.941\"], [\"70344.40\", \"0.186\"], [\"70345.00\", \"0.205\"], [\"70353.00\", \"0.513\"], [\"70355.20\", \"1.102\"], [\"70357.60\", \"0.000\"], [\"70357.70\", \"0.000\"], [\"70358.30\", \"0.002\"], [\"70358.40\", \"0.002\"], [\"70366.10\", \"0.028\"], [\"70368.20\", \"0.008\"], [\"70369.60\", \"0.386\"], [\"70369.90\", \"0.184\"], [\"70370.00\", \"0.295\"], [\"70370.70\", \"0.747\"], [\"70374.30\", \"0.000\"], [\"70374.40\", \"0.627\"], [\"70374.50\", \"0.002\"], [\"70379.80\", \"1.000\"], [\"70381.00\", \"0.003\"], [\"70382.20\", \"0.003\"], [\"70382.60\", \"0.003\"], [\"70382.70\", \"0.002\"], [\"70385.20\", \"0.778\"]], \"a\": [[\"70385.30\", \"6.070\"], [\"70389.80\", \"0.002\"], [\"70392.30\", \"0.166\"], [\"70394.40\", \"0.006\"], [\"70394.80\", \"0.005\"], [\"70407.70\", \"0.417\"], [\"70407.90\", \"0.005\"], [\"70419.30\", \"0.002\"], [\"70419.40\", \"0.000\"], [\"70419.70\", \"0.278\"], [\"70420.00\", \"0.901\"], [\"70420.10\", \"0.215\"], [\"70420.60\", \"0.007\"], [\"70423.40\", \"2.064\"], [\"70424.00\", \"0.142\"], [\"70424.10\", \"0.098\"], [\"70447.00\", \"3.517\"], [\"70448.10\", \"1.264\"], [\"70484.80\", \"8.787\"], [\"70489.70\", \"0.007\"], [\"70833.80\", \"37.672\"], [\"70934.10\", \"3.723\"], [\"71089.20\", \"0.000\"], [\"71254.40\", \"0.000\"], [\"71307.00\", \"7.089\"], [\"71401.00\", \"0.841\"], [\"72144.60\", \"0.593\"], [\"73923.50\", \"0.000\"], [\"73928.70\", \"0.052\"]]}", "symbol": "BTCUSDT"}
{"event": "depthUpdate", "raw_payload": "{\"e\": \"depthUpdate\", \"E\": 1773246397930, \"T\": 1773246397929, \"s\": \"BTCUSDT\", \"U\": 10089704987535, \"u\": 10089704994971, \"pu\": 10089704987500, \"b\": [[\"5000.00\", \"101.418\"], [\"19887.30\", \"1.190\"], [\"19985.20\", \"0.320\"], [\"20087.30\", \"0.390\"], [\"20285.20\", \"0.420\"], [\"63346.70\", \"0.002\"], [\"68256.70\", \"0.000\"], [\"69533.10\", \"0.000\"], [\"69681.30\", \"0.000\"], [\"69836.30\", \"0.000\"], [\"69841.60\", \"3.720\"], [\"69936.10\", \"3.312\"], [\"70039.80\", \"0.002\"], [\"70080.20\", \"0.076\"], [\"70129.00\", \"0.036\"], [\"70135.10\", \"0.002\"], [\"70135.80\", \"0.002\"], [\"70136.60\", \"0.043\"], [\"70136.90\", \"0.000\"], [\"70137.00\", \"0.029\"], [\"70137.30\", \"0.000\"], [\"70137.70\", \"0.000\"], [\"70143.90\", \"0.000\"], [\"70156.50\", \"0.201\"], [\"70192.00\", \"0.006\"], [\"70193.30\", \"0.000\"], [\"70218.70\", \"0.002\"], [\"70227.30\", \"0.084\"], [\"70259.80\", \"0.003\"], [\"70260.20\", \"0.095\"], [\"70266.20\", \"0.009\"], [\"70295.00\", \"0.005\"], [\"70301.00\", \"0.570\"], [\"70304.30\", \"0.689\"], [\"70316.50\", \"0.007\"], [\"70320.50\", \"0.002\"], [\"70330.20\", \"0.005\"], [\"70330.30\", \"0.007\"], [\"70331.90\", \"0.086\"], [\"70332.10\", \"0.973\"], [\"70332.50\", \"0.041\"], [\"70335.70\", \"0.042\"], [\"70336.60\", \"0.002\"], [\"70339.50\", \"0.102\"], [\"70339.60\", \"0.188\"], [\"70339.70\", \"0.085\"], [\"70343.00\", \"2.101\"], [\"70344.70\", \"0.514\"], [\"70345.90\", \"0.004\"], [\"70346.60\", \"0.008\"], [\"70347.90\", \"0.586\"], [\"70354.20\", \"0.021\"], [\"70355.20\", \"1.082\"], [\"70355.80\", \"0.000\"], [\"70356.20\", \"0.013\"], [\"70356.30\", \"0.855\"], [\"70356.90\", \"0.023\"], [\"70357.00\", \"0.076\"], [\"70358.90\", \"0.002\"], [\"70369.60\", \"0.429\"], [\"70370.00\", \"0.331\"], [\"70370.10\", \"0.484\"], [\"70371.00\", \"0.004\"], [\"70371.10\", \"0.087\"], [\"70371.50\", \"0.018\"], [\"70372.90\", \"0.045\"], [\"70373.20\", \"0.004\"], [\"70374.30\", \"0.245\"], [\"70374.40\", \"0.202\"], [\"70375.30\", \"0.017\"], [\"70378.50\", \"1.004\"], [\"70379.80\", \"0.000\"], [\"70380.50\", \"0.002\"], [\"70382.20\", \"0.005\"], [\"70382.70\", \"0.000\"], [\"70384.60\", \"0.002\"], [\"70384.90\", \"0.000\"], [\"70385.20\", \"0.448\"]], \"a\": [[\"70385.30\", \"6.938\"], [\"70387.30\", \"0.723\"], [\"70387.40\", \"0.005\"], [\"70388.50\", \"0.049\"], [\"70390.60\", \"0.000\"], [\"70391.10\", \"0.007\"], [\"70391.40\", \"0.002\"], [\"70394.40\", \"0.004\"], [\"70395.20\", \"0.003\"], [\"70398.10\", \"0.008\"], [\"70400.80\", \"0.284\"], [\"70400.90\", \"0.012\"], [\"70402.00\", \"0.191\"], [\"70405.10\", \"0.045\"], [\"70409.20\", \"0.186\"], [\"70409.90\", \"0.010\"], [\"70412.70\", \"0.003\"], [\"70416.10\", \"0.303\"], [\"70421.40\", \"0.010\"], [\"70421.50\", \"0.004\"], [\"70422.10\", \"0.002\"], [\"70422.20\", \"0.000\"], [\"70423.40\", \"2.067\"], [\"70425.20\", \"0.002\"], [\"70425.60\", \"0.002\"], [\"70425.70\", \"0.007\"], [\"70425.80\", \"1.317\"], [\"70425.90\", \"0.527\"], [\"70426.30\", \"0.002\"], [\"70426.40\", \"0.000\"], [\"70440.30\", \"0.062\"], [\"70444.30\", \"0.030\"], [\"70454.00\", \"0.127\"], [\"70490.10\", \"2.474\"], [\"70497.60\", \"6.513\"], [\"70510.30\", \"0.189\"], [\"70510.80\", \"0.009\"], [\"70928.80\", \"3.720\"], [\"70934.10\", \"0.003\"], [\"71089.20\", \"0.000\"], [\"71422.10\", \"0.559\"], [\"73918.40\", \"0.002\"], [\"73928.70\", \"0.050\"], [\"77423.80\", \"0.002\"], [\"89523.20\", \"0.000\"]]}", "symbol": "BTCUSDT"}
{"event": "depthUpdate", "raw_payload": "{\"e\": \"depthUpdate\", \"E\": 1773246398032, \"T\": 1773246398031, \"s\": \"BTCUSDT\", \"U\": 10089704995358, \"u\": 10089705018582, \"pu\": 10089704994971, \"b\": [[\"1000.00\", \"26.792\"], [\"5000.00\", \"101.418\"], [\"19887.30\", \"1.020\"], [\"19982.30\", \"0.030\"], [\"19983.30\", \"0.010\"], [\"19985.20\", \"0.360\"], [\"20087.30\", \"0.310\"], [\"20282.30\", \"0.080\"], [\"20283.30\", \"0.010\"], [\"20285.10\", \"0.010\"], [\"20285.20\", \"0.490\"], [\"33000.00\", \"10.797\"], [\"63346.70\", \"0.000\"], [\"66857.30\", \"0.000\"], [\"66857.40\", \"0.002\"], [\"66865.50\", \"0.002\"], [\"68012.00\", \"0.010\"], [\"68256.10\", \"0.007\"], [\"69036.90\", \"0.000\"], [\"69190.60\", \"0.000\"], [\"69404.30\", \"0.985\"], [\"69643.60\", \"0.000\"], [\"69680.10\", \"0.000\"], [\"69681.20\", \"1.420\"], [\"69681.30\", \"0.000\"], [\"69683.40\", \"1.420\"], [\"69841.60\", \"0.000\"], [\"70077.60\", \"6.552\"], [\"70084.40\", \"0.186\"], [\"70084.70\", \"0.193\"], [\"70100.60\", \"0.391\"], [\"70128.80\", \"0.002\"], [\"70134.20\", \"0.002\"], [\"70135.90\", \"0.000\"], [\"70138.00\", \"1.420\"], [\"70160.70\", \"1.922\"], [\"70171.90\", \"0.003\"], [\"70184.90\", \"0.000\"], [\"70188.40\", \"0.003\"], [\"70211.40\", \"0.000\"], [\"70234.80\", \"0.036\"], [\"70263.00\", \"0.156\"], [\"70285.20\", \"0.014\"], [\"70285.40\", \"0.000\"], [\"70286.40\", \"0.042\"], [\"70287.00\", \"1.270\"], [\"70291.00\", \"0.014\"], [\"70291.60\", \"0.182\"], [\"70294.00\", \"2.925\"], [\"70294.30\", \"0.219\"], [\"70295.30\", \"0.002\"], [\"70298.50\", \"0.000\"], [\"70301.40\", \"0.125\"], [\"70302.10\", \"0.002\"], [\"70302.40\", \"0.088\"], [\"70303.00\", \"0.342\"], [\"70303.80\", \"0.202\"], [\"70304.20\", \"0.135\"], [\"70304.90\", \"0.088\"], [\"70305.20\", \"0.054\"], [\"70306.40\", \"0.018\"], [\"70306.60\", \"0.016\"], [\"70306.80\", \"0.000\"], [\"70308.80\", \"0.149\"], [\"70309.00\", \"0.001\"], [\"70311.40\", \"0.141\"], [\"70311.60\", \"0.159\"], [\"70313.30\", \"3.587\"], [\"70314.30\", \"0.441\"], [\"70314.40\", \"0.043\"], [\"70314.80\", \"0.049\"], [\"70315.20\", \"0.005\"], [\"70317.50\", \"0.200\"], [\"70325.80\", \"0.927\"], [\"70326.50\", \"0.100\"], [\"70328.40\", \"0.046\"], [\"70328.60\", \"1.055\"], [\"70329.00\", \"0.631\"], [\"70330.00\", \"0.129\"], [\"70330.30\", \"0.003\"], [\"70330.40\", \"0.382\"], [\"70330.80\", \"0.358\"], [\"70331.20\", \"0.009\"], [\"70331.80\", \"0.002\"], [\"70331.90\", \"0.086\"], [\"70332.10\", \"0.971\"], [\"70333.80\", \"0.102\"], [\"70334.60\", \"0.000\"], [\"70335.90\", \"0.003\"], [\"70336.00\", \"0.712\"], [\"70336.30\", \"0.000\"], [\"70336.70\", \"0.087\"], [\"70336.80\", \"0.511\"], [\"70337.00\", \"1.944\"], [\"70337.30\", \"0.003\"], [\"70337.40\", \"0.713\"], [\"70338.00\", \"0.969\"], [\"70338.70\", \"0.194\"], [\"70339.00\", \"0.530\"], [\"70339.10\", \"0.000\"], [\"70339.20\", \"0.515\"], [\"70339.30\", \"0.253\"], [\"70339.60\", \"0.188\"], [\"70339.70\", \"0.000\"], [\"70340.00\", \"0.227\"], [\"70340.80\", \"0.003\"], [\"70341.00\", \"0.911\"], [\"70341.10\", \"0.000\"], [\"70341.90\", \"0.000\"], [\"70342.10\", \"0.000\"], [\"70342.90\", \"0.002\"], [\"70343.00\", \"2.723\"], [\"70343.10\", \"0.007\"], [\"70343.20\", \"1.581\"], [\"70343.60\", \"0.142\"], [\"70343.90\", \"0.004\"], [\"70344.70\", \"0.003\"], [\"70345.90\", \"0.000\"], [\"70346.20\", \"0.434\"], [\"70346.70\", \"0.000\"], [\"70347.40\", \"0.190\"], [\"70348.10\", \"0.006\"], [\"70349.50\", \"0.004\"], [\"70349.60\", \"0.579\"], [\"70349.70\", \"0.770\"], [\"70350.00\", \"0.632\"], [\"70350.50\", \"0.125\"], [\"70350.70\", \"0.381\"], [\"70351.10\", \"0.002\"], [\"70351.40\", \"0.004\"], [\"70351.80\", \"1.074\"], [\"70351.90\", \"0.517\"], [\"70352.00\", \"0.514\"], [\"70352.60\", \"0.040\"], [\"70352.70\", \"0.209\"], [\"70352.80\", \"0.009\"], [\"70353.00\", \"0.513\"], [\"70353.20\", \"0.000\"], [\"70353.60\", \"0.031\"], [\"70353.70\", \"0.105\"], [\"70354.10\", \"0.336\"], [\"70354.20\", \"0.642\"], [\"70354.50\", \"0.077\"], [\"70354.60\", \"0.002\"], [\"70354.70\", \"0.004\"], [\"70354.80\", \"0.000\"], [\"70354.90\", \"0.002\"], [\"70355.20\", \"0.016\"], [\"70355.30\", \"0.871\"], [\"70355.40\", \"0.011\"], [\"70355.50\", \"0.001\"], [\"70355.60\", \"0.000\"], [\"70355.70\", \"0.006\"], [\"70356.00\", \"0.005\"], [\"70356.20\", \"0.004\"], [\"70356.30\", \"0.207\"], [\"70356.40\", \"0.001\"], [\"70356.70\", \"1.141\"], [\"70356.80\", \"0.074\"], [\"70356.90\", \"0.000\"], [\"70357.00\", \"0.627\"], [\"70357.10\", \"0.002\"], [\"70357.20\", \"0.111\"], [\"70357.30\", \"0.001\"], [\"70357.40\", \"0.003\"], [\"70357.60\", \"1.068\"], [\"70357.70\", \"0.073\"], [\"70358.00\", \"1.721\"], [\"70358.20\", \"0.010\"], [\"70358.30\", \"0.007\"], [\"70358.40\", \"0.000\"], [\"70358.60\", \"0.291\"], [\"70359.00\", \"0.002\"], [\"70359.10\", \"0.000\"], [\"70359.30\", \"0.007\"], [\"70359.40\", \"0.003\"], [\"70359.50\", \"0.000\"], [\"70359.60\", \"0.002\"], [\"70359.70\", \"0.000\"], [\"70359.90\", \"0.207\"], [\"70360.00\", \"0.006\"], [\"70360.40\", \"0.003\"], [\"70360.50\", \"0.275\"], [\"70360.60\", \"0.088\"], [\"70360.80\", \"0.006\"], [\"70361.10\", \"0.009\"], [\"70361.20\", \"0.007\"], [\"70361.30\", \"0.008\"], [\"70361.40\", \"0.000\"], [\"70361.50\", \"0.384\"], [\"70361.60\", \"0.005\"], [\"70361.70\", \"0.143\"], [\"70361.80\", \"0.013\"], [\"70361.90\", \"0.000\"], [\"70362.10\", \"0.068\"], [\"70362.40\", \"0.008\"], [\"70362.50\", \"0.003\"], [\"70362.70\", \"0.014\"], [\"70362.80\", \"0.000\"], [\"70362.90\", \"0.018\"], [\"70363.00\", \"0.002\"], [\"70363.60\", \"0.008\"], [\"70363.70\", \"1.069\"], [\"70363.80\", \"0.602\"], [\"70364.00\", \"0.631\"], [\"70364.20\", \"0.002\"], [\"70364.40\", \"0.003\"], [\"70364.50\", \"0.342\"], [\"70364.80\", \"0.000\"], [\"70364.90\", \"0.000\"], [\"70365.30\", \"0.020\"], [\"70366.00\", \"0.010\"], [\"70366.10\", \"0.025\"], [\"70366.40\", \"0.210\"], [\"70366.50\", \"0.003\"], [\"70367.00\", \"0.096\"], [\"70367.20\", \"0.007\"], [\"70367.30\", \"0.367\"], [\"70367.40\", \"0.004\"], [\"70367.50\", \"0.006\"], [\"70367.70\", \"0.052\"], [\"70367.90\", \"0.304\"], [\"70368.20\", \"0.098\"], [\"70368.40\", \"0.029\"], [\"70368.50\", \"0.025\"], [\"70368.60\", \"0.003\"], [\"70368.70\", \"0.245\"], [\"70369.50\", \"0.009\"], [\"70369.60\", \"0.253\"], [\"70369.70\", \"0.001\"], [\"70369.80\", \"0.008\"], [\"70369.90\", \"0.000\"], [\"70370.00\", \"0.284\"], [\"70370.10\", \"0.115\"], [\"70370.20\", \"0.000\"], [\"70370.30\", \"0.222\"], [\"70370.40\", \"0.004\"], [\"70370.50\", \"0.004\"], [\"70370.60\", \"0.003\"], [\"70370.70\", \"0.657\"], [\"70370.80\", \"0.444\"], [\"70370.90\", \"0.119\"], [\"70371.00\", \"0.004\"], [\"70371.10\", \"0.004\"], [\"70371.20\", \"0.005\"], [\"70371.30\", \"0.162\"], [\"70371.40\", \"0.000\"], [\"70371.50\", \"0.002\"], [\"70371.60\", \"0.006\"], [\"70371.70\", \"0.007\"], [\"70371.80\", \"0.009\"], [\"70371.90\", \"0.005\"], [\"70372.40\", \"0.003\"], [\"70372.50\", \"0.003\"], [\"70372.60\", \"0.000\"], [\"70372.70\", \"0.003\"], [\"70372.80\", \"0.002\"], [\"70372.90\", \"0.005\"], [\"70373.40\", \"0.003\"], [\"70373.60\", \"0.001\"], [\"70373.80\", \"0.003\"], [\"70374.00\", \"0.003\"], [\"70374.20\", \"0.001\"], [\"70374.30\", \"0.241\"], [\"70374.40\", \"0.000\"], [\"70374.50\", \"0.002\"], [\"70374.60\", \"0.003\"], [\"70374.80\", \"0.006\"], [\"70374.90\", \"0.004\"], [\"70375.00\", \"0.019\"], [\"70375.30\", \"0.257\"], [\"70375.60\", \"0.000\"], [\"70375.80\", \"0.070\"], [\"70376.20\", \"0.000\"], [\"70376.40\", \"1.000\"], [\"70376.80\", \"0.006\"], [\"70377.20\", \"0.000\"], [\"70377.30\", \"0.015\"], [\"70377.40\", \"0.004\"], [\"70377.60\", \"0.000\"], [\"70377.80\", \"0.001\"], [\"70378.10\", \"0.007\"], [\"70378.20\", \"0.003\"], [\"70378.40\", \"0.002\"], [\"70378.50\", \"0.002\"], [\"70378.60\", \"0.005\"], [\"70378.70\", \"0.001\"], [\"70379.90\", \"0.039\"], [\"70380.00\", \"0.008\"], [\"70380.60\", \"0.000\"], [\"70380.80\", \"0.000\"], [\"70381.00\", \"0.001\"], [\"70381.40\", \"0.002\"], [\"70381.50\", \"0.002\"], [\"70381.70\", \"0.002\"], [\"70382.00\", \"0.002\"], [\"70382.10\", \"0.000\"], [\"70382.20\", \"0.000\"], [\"70382.30\", \"0.468\"], [\"70382.50\", \"0.000\"], [\"70382.60\", \"0.000\"], [\"70382.90\", \"0.000\"], [\"70383.30\", \"0.000\"], [\"70383.40\", \"0.000\"], [\"70383.50\", \"0.000\"], [\"70383.80\", \"0.000\"], [\"70383.90\", \"0.000\"], [\"70384.00\", \"0.000\"], [\"70384.40\", \"0.000\"], [\"70384.60\", \"0.000\"], [\"70384.70\", \"0.000\"], [\"70385.10\", \"0.000\"], [\"70385.20\", \"0.000\"]], \"a\": [[\"70382.40\", \"11.629\"], [\"70382.50\", \"0.741\"], [\"70382.60\", \"0.000\"], [\"70382.70\", \"0.003\"], [\"70382.90\", \"0.058\"], [\"70383.00\", \"0.000\"], [\"70383.10\", \"0.002\"], [\"70383.20\", \"0.000\"], [\"70383.30\", \"0.000\"], [\"70383.40\", \"0.040\"], [\"70383.50\", \"0.003\"], [\"70383.60\", \"0.000\"], [\"70383.90\", \"0.002\"], [\"70384.00\", \"0.040\"], [\"70384.10\", \"0.004\"], [\"70384.50\", \"0.000\"], [\"70384.70\", \"0.004\"], [\"70384.80\", \"0.003\"], [\"70384.90\", \"0.002\"], [\"70385.00\", \"1.059\"], [\"70385.10\", \"1.109\"], [\"70385.20\", \"2.518\"], [\"70385.30\", \"0.347\"], [\"70385.40\", \"0.003\"], [\"70385.70\", \"0.021\"], [\"70385.90\", \"0.003\"], [\"70386.30\", \"0.003\"], [\"70386.40\", \"0.024\"], [\"70386.80\", \"0.022\"], [\"70387.00\", \"0.207\"], [\"70387.10\", \"0.003\"], [\"70387.20\", \"0.019\"], [\"70387.30\", \"0.758\"], [\"70387.40\", \"0.003\"], [\"70387.80\", \"0.003\"], [\"70388.10\", \"0.000\"], [\"70388.20\", \"0.001\"], [\"70388.50\", \"0.002\"], [\"70388.60\", \"0.002\"], [\"70388.70\", \"0.001\"], [\"70388.90\", \"0.002\"], [\"70389.60\", \"0.014\"], [\"70389.70\", \"0.002\"], [\"70389.80\", \"0.002\"], [\"70389.90\", \"0.011\"], [\"70390.00\", \"0.033\"], [\"70390.10\", \"0.075\"], [\"70390.20\", \"0.004\"], [\"70390.30\", \"0.044\"], [\"70390.40\", \"0.180\"], [\"70391.00\", \"0.864\"], [\"70391.20\", \"0.047\"], [\"70391.30\", \"0.012\"], [\"70391.50\", \"0.028\"], [\"70391.60\", \"0.035\"], [\"70391.70\", \"0.000\"], [\"70391.80\", \"0.200\"], [\"70391.90\", \"0.008\"], [\"70392.00\", \"0.010\"], [\"70392.20\", \"0.091\"], [\"70392.30\", \"0.019\"], [\"70392.40\", \"0.006\"], [\"70392.50\", \"0.005\"], [\"70392.60\", \"0.268\"], [\"70392.80\", \"0.059\"], [\"70393.20\", \"0.002\"], [\"70393.30\", \"0.096\"], [\"70393.40\", \"0.073\"], [\"70393.90\", \"0.003\"], [\"70394.00\", \"0.003\"], [\"70394.20\", \"0.004\"], [\"70394.30\", \"0.000\"], [\"70394.40\", \"0.004\"], [\"70394.50\", \"0.005\"], [\"70394.60\", \"0.216\"], [\"70394.70\", \"0.000\"], [\"70394.80\", \"0.191\"], [\"70394.90\", \"0.002\"], [\"70395.10\", \"0.097\"], [\"70395.20\", \"0.010\"], [\"70395.30\", \"0.515\"], [\"70395.50\", \"0.633\"], [\"70395.60\", \"1.066\"], [\"70395.70\", \"0.000\"], [\"70395.80\", \"0.000\"], [\"70395.90\", \"0.003\"], [\"70396.20\", \"0.002\"], [\"70396.30\", \"0.001\"], [\"70396.40\", \"0.003\"], [\"70396.50\", \"0.000\"], [\"70396.60\", \"0.002\"], [\"70396.80\", \"0.008\"], [\"70396.90\", \"0.008\"], [\"70397.20\", \"0.048\"], [\"70397.40\", \"0.076\"], [\"70397.50\", \"0.514\"], [\"70397.70\", \"0.000\"], [\"70397.90\", \"0.004\"], [\"70398.10\", \"0.007\"], [\"70398.30\", \"0.250\"], [\"70398.60\", \"0.000\"], [\"70398.70\", \"0.003\"], [\"70398.90\", \"0.003\"], [\"70399.00\", \"0.008\"], [\"70399.10\", \"0.200\"], [\"70399.20\", \"0.733\"], [\"70399.30\", \"0.007\"], [\"70399.60\", \"0.011\"], [\"70399.80\", \"0.513\"], [\"70400.00\", \"2.040\"], [\"70400.10\", \"0.000\"], [\"70400.30\", \"0.003\"], [\"70400.60\", \"0.002\"], [\"70400.90\", \"0.005\"], [\"70401.20\", \"0.002\"], [\"70401.60\", \"0.008\"], [\"70401.90\", \"0.003\"], [\"70402.00\", \"0.261\"], [\"70402.50\", \"0.003\"], [\"70402.80\", \"0.648\"], [\"70402.90\", \"1.066\"], [\"70403.20\", \"0.000\"], [\"70403.40\", \"0.002\"], [\"70403.60\", \"0.005\"], [\"70403.90\", \"0.000\"], [\"70404.10\", \"0.000\"], [\"70404.30\", \"0.000\"], [\"70404.60\", \"0.025\"], [\"70404.80\", \"0.206\"], [\"70405.10\", \"0.045\"], [\"70405.20\", \"0.003\"], [\"70405.40\", \"0.063\"], [\"70405.60\", \"0.211\"], [\"70405.70\", \"0.294\"], [\"70405.80\", \"0.024\"], [\"70405.90\", \"0.072\"], [\"70406.00\", \"0.698\"], [\"70406.10\", \"0.061\"], [\"70406.20\", \"0.062\"], [\"70406.40\", \"0.219\"], [\"70406.50\", \"0.004\"], [\"70406.60\", \"0.011\"], [\"70406.70\", \"1.570\"], [\"70407.50\", \"0.009\"], [\"70407.90\", \"0.057\"], [\"70408.30\", \"0.008\"], [\"70408.60\", \"0.003\"], [\"70408.70\", \"0.042\"], [\"70409.60\", \"0.002\"], [\"70409.90\", \"0.003\"], [\"70410.30\", \"0.073\"], [\"70410.40\", \"0.000\"], [\"70410.50\", \"0.090\"], [\"70410.70\", \"0.015\"], [\"70412.10\", \"0.004\"], [\"70412.30\", \"0.384\"], [\"70413.00\", \"0.630\"], [\"70413.20\", \"0.511\"], [\"70413.80\", \"0.000\"], [\"70414.30\", \"0.011\"], [\"70414.80\", \"0.006\"], [\"70415.00\", \"1.069\"], [\"70415.50\", \"0.002\"], [\"70415.60\", \"0.002\"], [\"70415.90\", \"0.511\"], [\"70416.00\", \"0.264\"], [\"70416.50\", \"0.573\"], [\"70416.60\", \"0.020\"], [\"70417.90\", \"0.002\"], [\"70418.00\", \"0.392\"], [\"70418.50\", \"0.071\"], [\"70418.60\", \"0.002\"], [\"70418.70\", \"0.002\"], [\"70419.30\", \"0.002\"], [\"70419.40\", \"0.000\"], [\"70419.70\", \"0.276\"], [\"70419.80\", \"0.260\"], [\"70420.00\", \"1.514\"], [\"70420.10\", \"0.206\"], [\"70420.40\", \"0.685\"], [\"70420.70\", \"0.005\"], [\"70420.80\", \"0.004\"], [\"70421.40\", \"0.008\"], [\"70421.50\", \"0.000\"], [\"70421.80\", \"0.142\"], [\"70422.80\", \"0.002\"], [\"70422.90\", \"0.002\"], [\"70424.20\", \"0.000\"], [\"70424.30\", \"0.002\"], [\"70424.60\", \"0.084\"], [\"70424.90\", \"0.153\"], [\"70425.00\", \"0.017\"], [\"70425.60\", \"0.102\"], [\"70425.70\", \"0.005\"], [\"70426.20\", \"0.025\"], [\"70426.90\", \"0.006\"], [\"70427.00\", \"0.624\"], [\"70432.10\", \"0.513\"], [\"70432.80\", \"0.324\"], [\"70433.50\", \"0.002\"], [\"70434.00\", \"0.677\"], [\"70434.20\", \"0.482\"], [\"70435.60\", \"0.344\"], [\"70436.60\", \"0.054\"], [\"70437.30\", \"0.133\"], [\"70437.50\", \"0.476\"], [\"70438.00\", \"0.028\"], [\"70439.30\", \"0.512\"], [\"70442.20\", \"0.168\"], [\"70443.20\", \"0.105\"], [\"70444.30\", \"0.002\"], [\"70447.00\", \"3.520\"], [\"70447.20\", \"0.004\"], [\"70448.10\", \"1.261\"], [\"70448.60\", \"0.032\"], [\"70451.80\", \"2.130\"], [\"70452.20\", \"0.000\"], [\"70452.70\", \"0.194\"], [\"70454.30\", \"0.004\"], [\"70455.20\", \"0.043\"], [\"70457.00\", \"0.063\"], [\"70457.80\", \"0.056\"], [\"70458.30\", \"0.000\"], [\"70460.30\", \"0.005\"], [\"70462.00\", \"0.009\"], [\"70463.10\", \"0.018\"], [\"70466.00\", \"0.036\"], [\"70466.10\", \"0.016\"], [\"70468.60\", \"0.056\"], [\"70473.70\", \"0.216\"], [\"70475.70\", \"0.102\"], [\"70476.30\", \"0.000\"], [\"70477.60\", \"0.041\"], [\"70478.10\", \"0.188\"], [\"70480.90\", \"0.129\"], [\"70481.00\", \"0.191\"], [\"70483.10\", \"1.149\"], [\"70483.20\", \"0.344\"], [\"70485.00\", \"0.082\"], [\"70501.90\", \"0.284\"], [\"70508.60\", \"0.013\"], [\"70515.40\", \"0.084\"], [\"70523.20\", \"0.008\"], [\"70524.70\", \"0.000\"], [\"70541.20\", \"6.567\"], [\"70546.90\", \"12.639\"], [\"70549.80\", \"6.049\"], [\"70571.60\", \"0.000\"], [\"70582.90\", \"0.378\"], [\"70583.40\", \"0.000\"], [\"70592.30\", \"0.000\"], [\"70602.80\", \"0.018\"], [\"70603.10\", \"0.000\"], [\"70605.20\", \"0.000\"], [\"70641.40\", \"0.000\"], [\"70641.70\", \"0.036\"], [\"70928.00\", \"0.000\"], [\"70928.80\", \"0.000\"], [\"70957.00\", \"47.553\"], [\"71056.10\", \"0.703\"], [\"71086.20\", \"0.035\"], [\"71087.20\", \"0.007\"], [\"71089.10\", \"0.051\"], [\"71089.20\", \"0.000\"], [\"71348.80\", \"0.000\"], [\"71383.40\", \"0.004\"], [\"71384.00\", \"0.002\"], [\"71385.20\", \"0.012\"], [\"71386.50\", \"0.006\"], [\"71387.40\", \"0.002\"], [\"71389.00\", \"0.007\"], [\"71389.40\", \"0.000\"], [\"77423.80\", \"0.000\"]]}", "symbol": "BTCUSDT"}
{"event": "depthUpdate", "raw_payload": "{\"e\": \"depthUpdate\", \"E\": 1773246398134, \"T\": 1773246398133, \"s\": \"BTCUSDT\", \"U\": 10089705018828, \"u\": 10089705053916, \"pu\": 10089705018582, \"b\": [[\"1000.00\", \"26.792\"], [\"5000.00\", \"101.418\"], [\"19887.30\", \"0.880\"], [\"19974.20\", \"0.020\"], [\"19979.90\", \"0.010\"], [\"19982.30\", \"0.080\"], [\"20087.30\", \"0.230\"], [\"20274.20\", \"0.040\"], [\"20282.00\", \"0.010\"], [\"20282.30\", \"0.170\"], [\"33000.00\", \"10.793\"], [\"56310.00\", \"100.003\"], [\"56313.00\", \"0.000\"], [\"66830.00\", \"0.534\"], [\"66865.50\", \"0.000\"], [\"68029.90\", \"1.468\"], [\"68972.40\", \"0.003\"], [\"69670.50\", \"0.002\"], [\"69678.30\", \"0.000\"], [\"69678.50\", \"0.015\"], [\"69834.20\", \"0.000\"], [\"69835.20\", \"3.315\"], [\"69835.80\", \"0.000\"], [\"69888.00\", \"1.741\"], [\"69995.50\", \"0.002\"], [\"69998.70\", \"0.008\"], [\"70077.80\", \"0.380\"], [\"70078.30\", \"0.189\"], [\"70080.20\", \"1.093\"], [\"70083.40\", \"0.189\"], [\"70135.10\", \"0.027\"], [\"70137.70\", \"0.054\"], [\"70156.50\", \"0.237\"], [\"70162.30\", \"0.001\"], [\"70167.90\", \"0.027\"], [\"70196.70\", \"0.058\"], [\"70207.40\", \"0.000\"], [\"70208.40\", \"0.074\"], [\"70213.50\", \"2.270\"], [\"70217.50\", \"0.123\"], [\"70224.00\", \"0.130\"], [\"70246.90\", \"0.002\"], [\"70256.70\", \"0.002\"], [\"70258.80\", \"0.210\"], [\"70259.50\", \"0.161\"], [\"70260.90\", \"0.006\"], [\"70262.40\", \"0.007\"], [\"70273.60\", \"3.620\"], [\"70275.10\", \"0.081\"], [\"70275.40\", \"4.413\"], [\"70277.20\", \"0.082\"], [\"70278.00\", \"0.599\"], [\"70279.90\", \"0.010\"], [\"70280.80\", \"0.002\"], [\"70281.30\", \"0.085\"], [\"70281.90\", \"0.018\"], [\"70282.70\", \"0.000\"], [\"70285.20\", \"0.000\"], [\"70286.50\", \"0.084\"], [\"70287.00\", \"1.267\"], [\"70291.00\", \"0.000\"], [\"70291.30\", \"0.001\"], [\"70292.00\", \"0.054\"], [\"70294.10\", \"0.051\"], [\"70294.30\", \"0.270\"], [\"70295.00\", \"0.144\"], [\"70296.80\", \"0.599\"], [\"70296.90\", \"0.620\"], [\"70297.90\", \"0.000\"], [\"70299.40\", \"0.028\"], [\"70301.10\", \"0.047\"], [\"70301.20\", \"0.052\"], [\"70301.70\", \"2.105\"], [\"70301.80\", \"0.516\"], [\"70302.40\", \"0.086\"], [\"70303.50\", \"0.003\"], [\"70304.20\", \"0.084\"], [\"70304.30\", \"0.638\"], [\"70304.40\", \"0.003\"], [\"70304.50\", \"0.146\"], [\"70304.90\", \"0.086\"], [\"70306.40\", \"0.000\"], [\"70308.00\", \"0.143\"], [\"70310.80\", \"0.003\"], [\"70311.40\", \"0.092\"], [\"70311.60\", \"0.156\"], [\"70311.70\", \"0.002\"], [\"70313.20\", \"0.000\"], [\"70313.30\", \"0.005\"], [\"70313.80\", \"0.004\"], [\"70314.30\", \"1.112\"], [\"70314.80\", \"0.000\"], [\"70316.10\", \"0.097\"], [\"70316.60\", \"0.005\"], [\"70318.20\", \"0.405\"], [\"70318.60\", \"0.000\"], [\"70319.10\", \"0.002\"], [\"70319.80\", \"0.552\"], [\"70320.10\", \"0.116\"], [\"70320.90\", \"0.398\"], [\"70321.10\", \"0.085\"], [\"70321.70\", \"0.002\"], [\"70322.10\", \"0.235\"], [\"70322.60\", \"0.004\"], [\"70323.20\", \"0.005\"], [\"70324.60\", \"0.001\"], [\"70325.00\", \"0.208\"], [\"70325.30\", \"0.021\"], [\"70325.60\", \"0.186\"], [\"70325.80\", \"0.934\"], [\"70326.30\", \"0.027\"], [\"70326.70\", \"0.015\"], [\"70327.20\", \"0.080\"], [\"70327.50\", \"0.002\"], [\"70328.30\", \"0.002\"], [\"70328.40\", \"0.042\"], [\"70328.60\", \"0.205\"], [\"70328.70\", \"0.305\"], [\"70329.00\", \"0.009\"], [\"70329.10\", \"0.342\"], [\"70329.50\", \"0.004\"], [\"70330.00\", \"0.127\"], [\"70330.80\", \"0.330\"], [\"70331.20\", \"0.002\"], [\"70331.90\", \"1.019\"], [\"70332.00\", \"2.201\"], [\"70332.40\", \"0.087\"], [\"70332.70\", \"0.569\"], [\"70333.10\", \"0.004\"], [\"70333.60\", \"0.000\"], [\"70333.80\", \"0.002\"], [\"70334.60\", \"0.004\"], [\"70335.00\", \"0.372\"], [\"70335.30\", \"0.250\"], [\"70335.80\", \"0.000\"], [\"70335.90\", \"0.003\"], [\"70336.00\", \"0.090\"], [\"70336.50\", \"0.004\"], [\"70336.70\", \"0.002\"], [\"70336.90\", \"0.005\"], [\"70337.00\", \"0.008\"], [\"70337.10\", \"1.066\"], [\"70337.40\", \"0.002\"], [\"70337.50\", \"0.000\"], [\"70337.70\", \"0.011\"], [\"70338.60\", \"0.010\"], [\"70338.80\", \"0.002\"], [\"70338.90\", \"0.002\"], [\"70339.00\", \"0.538\"], [\"70339.10\", \"0.000\"], [\"70339.30\", \"0.005\"], [\"70339.50\", \"0.002\"], [\"70340.00\", \"0.019\"], [\"70340.70\", \"0.008\"], [\"70341.00\", \"0.342\"], [\"70341.50\", \"0.005\"], [\"70341.70\", \"10.250\"], [\"70341.80\", \"0.649\"], [\"70342.20\", \"0.003\"], [\"70342.40\", \"0.199\"], [\"70343.00\", \"2.103\"], [\"70343.20\", \"0.004\"], [\"70343.30\", \"0.125\"], [\"70343.40\", \"1.066\"], [\"70343.50\", \"0.000\"], [\"70343.60\", \"0.107\"], [\"70343.90\", \"0.000\"], [\"70344.30\", \"0.133\"], [\"70345.00\", \"0.209\"], [\"70345.50\", \"0.004\"], [\"70345.60\", \"0.516\"], [\"70345.70\", \"0.038\"], [\"70345.80\", \"0.082\"], [\"70346.00\", \"0.320\"], [\"70346.10\", \"0.005\"], [\"70346.20\", \"0.441\"], [\"70346.30\", \"0.005\"], [\"70346.40\", \"0.002\"], [\"70346.50\", \"0.002\"], [\"70346.60\", \"0.011\"], [\"70346.70\", \"0.000\"], [\"70346.80\", \"0.342\"], [\"70347.10\", \"0.008\"], [\"70347.20\", \"0.003\"], [\"70347.30\", \"0.639\"], [\"70347.60\", \"0.071\"], [\"70347.80\", \"0.012\"], [\"70347.90\", \"0.584\"], [\"70348.10\", \"0.004\"], [\"70348.30\", \"0.007\"], [\"70348.50\", \"0.002\"], [\"70348.60\", \"0.016\"], [\"70349.20\", \"1.224\"], [\"70349.30\", \"0.026\"], [\"70349.40\", \"0.008\"], [\"70349.60\", \"0.000\"], [\"70349.70\", \"0.003\"], [\"70349.80\", \"1.076\"], [\"70349.90\", \"0.286\"], [\"70350.00\", \"0.012\"], [\"70350.10\", \"0.002\"], [\"70350.30\", \"0.001\"], [\"70350.40\", \"0.000\"], [\"70350.50\", \"0.005\"], [\"70350.60\", \"0.000\"], [\"70350.70\", \"0.385\"], [\"70350.80\", \"0.004\"], [\"70351.00\", \"0.045\"], [\"70351.10\", \"0.002\"], [\"70351.20\", \"0.239\"], [\"70351.30\", \"0.004\"], [\"70351.40\", \"0.000\"], [\"70351.50\", \"0.006\"], [\"70351.60\", \"0.003\"], [\"70351.80\", \"0.006\"], [\"70351.90\", \"0.006\"], [\"70352.00\", \"0.003\"], [\"70352.10\", \"0.145\"], [\"70352.20\", \"0.195\"], [\"70352.30\", \"0.008\"], [\"70352.40\", \"0.000\"], [\"70352.60\", \"0.005\"], [\"70352.70\", \"0.200\"], [\"70352.80\", \"0.002\"], [\"70353.00\", \"0.478\"], [\"70353.10\", \"0.209\"], [\"70353.20\", \"0.000\"], [\"70353.30\", \"0.580\"], [\"70353.40\", \"0.005\"], [\"70353.50\", \"0.008\"], [\"70353.70\", \"0.034\"], [\"70354.10\", \"0.002\"], [\"70354.20\", \"0.004\"], [\"70354.50\", \"0.024\"], [\"70354.60\", \"0.183\"], [\"70354.70\", \"0.011\"], [\"70354.80\", \"0.000\"], [\"70354.90\", \"0.002\"], [\"70355.00\", \"0.004\"], [\"70355.10\", \"0.018\"], [\"70355.20\", \"0.087\"], [\"70355.30\", \"0.018\"], [\"70355.40\", \"0.306\"], [\"70355.50\", \"0.001\"], [\"70355.60\", \"0.007\"], [\"70356.20\", \"0.004\"], [\"70356.30\", \"0.382\"], [\"70356.40\", \"0.001\"], [\"70356.50\", \"0.009\"], [\"70356.70\", \"0.948\"], [\"70356.80\", \"0.000\"], [\"70356.90\", \"0.000\"], [\"70357.00\", \"0.007\"], [\"70357.10\", \"0.000\"], [\"70357.30\", \"0.008\"], [\"70357.40\", \"0.000\"], [\"70357.50\", \"0.098\"], [\"70357.60\", \"0.000\"], [\"70357.70\", \"0.003\"], [\"70357.80\", \"0.002\"], [\"70357.90\", \"0.008\"], [\"70358.00\", \"0.004\"], [\"70358.10\", \"0.000\"], [\"70358.20\", \"0.005\"], [\"70358.30\", \"0.000\"], [\"70358.50\", \"0.002\"], [\"70358.60\", \"0.003\"], [\"70358.70\", \"0.003\"], [\"70358.80\", \"0.075\"], [\"70359.10\", \"0.000\"], [\"70359.20\", \"0.000\"], [\"70359.30\", \"0.001\"], [\"70359.40\", \"0.003\"], [\"70359.70\", \"0.000\"], [\"70359.90\", \"0.205\"], [\"70360.10\", \"0.000\"], [\"70360.20\", \"0.006\"], [\"70360.30\", \"0.011\"], [\"70360.40\", \"0.000\"], [\"70360.50\", \"0.575\"], [\"70360.60\", \"0.000\"], [\"70360.70\", \"0.002\"], [\"70360.80\", \"0.003\"], [\"70361.00\", \"0.185\"], [\"70361.30\", \"0.002\"], [\"70361.50\", \"0.377\"], [\"70361.70\", \"0.001\"], [\"70361.80\", \"0.006\"], [\"70361.90\", \"0.003\"], [\"70362.10\", \"0.048\"], [\"70362.20\", \"0.000\"], [\"70362.30\", \"0.000\"], [\"70362.40\", \"0.010\"], [\"70362.50\", \"0.001\"], [\"70362.70\", \"0.002\"], [\"70362.90\", \"0.065\"], [\"70363.00\", \"0.002\"], [\"70363.30\", \"0.007\"], [\"70363.40\", \"0.106\"], [\"70363.50\", \"0.002\"], [\"70363.60\", \"0.005\"], [\"70363.70\", \"0.028\"], [\"70363.80\", \"0.084\"], [\"70363.90\", \"0.000\"], [\"70364.00\", \"0.009\"], [\"70364.50\", \"0.054\"], [\"70364.60\", \"0.655\"], [\"70364.70\", \"0.010\"], [\"70364.80\", \"0.004\"], [\"70365.00\", \"0.131\"], [\"70365.20\", \"0.002\"], [\"70365.30\", \"0.011\"], [\"70365.50\", \"0.001\"], [\"70365.60\", \"0.008\"], [\"70365.70\", \"0.000\"], [\"70365.90\", \"0.010\"], [\"70366.00\", \"0.011\"], [\"70366.20\", \"0.000\"], [\"70366.40\", \"0.057\"], [\"70366.80\", \"0.000\"], [\"70367.00\", \"0.099\"], [\"70367.10\", \"0.097\"], [\"70367.30\", \"0.000\"], [\"70367.40\", \"0.002\"], [\"70367.70\", \"0.002\"], [\"70367.80\", \"0.000\"], [\"70367.90\", \"0.003\"], [\"70368.00\", \"0.000\"], [\"70368.20\", \"0.008\"], [\"70368.40\", \"0.000\"], [\"70368.50\", \"0.002\"], [\"70368.60\", \"0.003\"], [\"70368.70\", \"0.000\"], [\"70369.20\", \"0.002\"], [\"70369.30\", \"0.005\"], [\"70369.60\", \"0.000\"], [\"70370.00\", \"0.009\"], [\"70370.10\", \"0.002\"], [\"70370.30\", \"0.001\"], [\"70370.50\", \"0.003\"], [\"70370.60\", \"0.000\"], [\"70370.70\", \"0.000\"], [\"70370.80\", \"0.000\"], [\"70370.90\", \"0.002\"], [\"70371.00\", \"0.002\"], [\"70371.10\", \"0.000\"], [\"70371.20\", \"0.000\"], [\"70371.30\", \"0.000\"], [\"70371.50\", \"0.000\"], [\"70371.60\", \"0.000\"], [\"70371.70\", \"0.000\"], [\"70371.80\", \"0.000\"], [\"70371.90\", \"0.000\"], [\"70372.00\", \"0.000\"], [\"70372.20\", \"0.000\"], [\"70372.30\", \"0.000\"], [\"70372.40\", \"0.000\"], [\"70372.50\", \"0.000\"], [\"70372.70\", \"0.000\"], [\"70372.80\", \"0.000\"], [\"70372.90\", \"0.000\"], [\"70373.00\", \"0.000\"], [\"70373.10\", \"0.000\"], [\"70373.20\", \"0.000\"], [\"70373.30\", \"0.000\"], [\"70373.40\", \"0.000\"], [\"70373.50\", \"0.000\"], [\"70373.60\", \"0.000\"], [\"70373.70\", \"0.000\"], [\"70373.80\", \"0.000\"], [\"70374.00\", \"0.000\"], [\"70374.10\", \"0.000\"], [\"70374.20\", \"0.000\"], [\"70374.30\", \"0.000\"], [\"70374.50\", \"0.000\"], [\"70374.60\", \"0.000\"], [\"70374.70\", \"0.000\"], [\"70374.80\", \"0.000\"], [\"70374.90\", \"0.000\"], [\"70375.00\", \"0.000\"], [\"70375.30\", \"0.000\"], [\"70375.40\", \"0.000\"], [\"70375.70\", \"0.000\"], [\"70375.80\", \"0.000\"], [\"70376.00\", \"0.000\"], [\"70376.10\", \"0.000\"], [\"70376.30\", \"0.000\"], [\"70376.40\", \"0.000\"], [\"70376.50\", \"0.000\"], [\"70376.60\", \"0.000\"], [\"70376.70\", \"0.000\"], [\"70376.80\", \"0.000\"], [\"70377.10\", \"0.000\"], [\"70377.30\", \"0.000\"], [\"70377.40\", \"0.000\"], [\"70377.70\", \"0.000\"], [\"70377.80\", \"0.000\"], [\"70377.90\", \"0.000\"], [\"70378.00\", \"0.000\"], [\"70378.10\", \"0.000\"], [\"70378.20\", \"0.000\"], [\"70378.30\", \"0.000\"], [\"70378.40\", \"0.000\"], [\"70378.50\", \"0.000\"], [\"70378.60\", \"0.000\"], [\"70378.70\", \"0.000\"], [\"70378.90\", \"0.000\"], [\"70379.00\", \"0.000\"], [\"70379.10\", \"0.000\"], [\"70379.40\", \"0.000\"], [\"70379.60\", \"0.000\"], [\"70379.70\", \"0.000\"], [\"70379.90\", \"0.000\"], [\"70380.00\", \"0.000\"], [\"70380.10\", \"0.000\"], [\"70380.30\", \"0.000\"], [\"70380.50\", \"0.000\"], [\"70380.70\", \"0.000\"], [\"70381.00\", \"0.000\"], [\"70381.40\", \"0.000\"], [\"70381.50\", \"0.000\"], [\"70381.70\", \"0.000\"], [\"70381.80\", \"0.000\"], [\"70382.00\", \"0.000\"], [\"70382.30\", \"0.000\"]], \"a\": [[\"70371.40\", \"1.135\"], [\"70372.40\", \"4.715\"], [\"70372.70\", \"0.902\"], [\"70373.00\", \"1.253\"], [\"70373.50\", \"0.004\"], [\"70373.60\", \"2.240\"], [\"70373.80\", \"1.417\"], [\"70373.90\", \"2.300\"], [\"70374.10\", \"1.883\"], [\"70374.20\", \"12.558\"], [\"70374.30\", \"13.048\"], [\"70374.40\", \"0.005\"], [\"70374.60\", \"0.000\"], [\"70374.70\", \"0.002\"], [\"70374.80\", \"0.014\"], [\"70374.90\", \"0.001\"], [\"70375.00\", \"0.017\"], [\"70375.10\", \"0.270\"], [\"70375.20\", \"0.002\"], [\"70375.30\", \"0.000\"], [\"70375.40\", \"1.453\"], [\"70375.50\", \"0.001\"], [\"70375.70\", \"0.000\"], [\"70375.80\", \"0.016\"], [\"70375.90\", \"0.015\"], [\"70376.00\", \"0.004\"], [\"70376.10\", \"0.000\"], [\"70376.20\", \"0.014\"], [\"70376.40\", \"0.016\"], [\"70376.50\", \"1.100\"], [\"70376.60\", \"0.015\"], [\"70376.70\", \"0.863\"], [\"70376.80\", \"0.868\"], [\"70376.90\", \"0.849\"], [\"70377.00\", \"0.003\"], [\"70377.10\", \"0.000\"], [\"70377.20\", \"0.000\"], [\"70377.30\", \"0.003\"], [\"70377.40\", \"0.170\"], [\"70377.50\", \"0.513\"], [\"70377.60\", \"0.000\"], [\"70377.80\", \"0.024\"], [\"70377.90\", \"0.004\"], [\"70378.00\", \"0.016\"], [\"70378.10\", \"0.014\"], [\"70378.20\", \"0.014\"], [\"70378.30\", \"0.014\"], [\"70378.40\", \"0.014\"], [\"70378.50\", \"0.015\"], [\"70378.60\", \"0.014\"], [\"70378.70\", \"0.014\"], [\"70378.80\", \"0.863\"], [\"70378.90\", \"0.000\"], [\"70379.00\", \"0.359\"], [\"70379.10\", \"0.113\"], [\"70379.20\", \"0.000\"], [\"70379.30\", \"0.002\"], [\"70379.40\", \"0.000\"], [\"70379.50\", \"0.850\"], [\"70379.60\", \"0.371\"], [\"70379.70\", \"1.574\"], [\"70379.80\", \"0.000\"], [\"70379.90\", \"1.722\"], [\"70380.00\", \"0.048\"], [\"70380.10\", \"0.003\"], [\"70380.20\", \"0.000\"], [\"70380.40\", \"0.000\"], [\"70380.50\", \"0.001\"], [\"70380.60\", \"0.002\"], [\"70380.80\", \"0.000\"], [\"70381.00\", \"0.022\"], [\"70381.10\", \"0.002\"], [\"70381.30\", \"0.003\"], [\"70381.40\", \"0.002\"], [\"70381.50\", \"0.846\"], [\"70381.60\", \"0.001\"], [\"70381.80\", \"0.002\"], [\"70381.90\", \"1.438\"], [\"70382.00\", \"2.188\"], [\"70382.10\", \"0.005\"], [\"70382.20\", \"0.876\"], [\"70382.30\", \"2.055\"], [\"70382.40\", \"1.059\"], [\"70382.50\", \"0.512\"], [\"70382.60\", \"0.000\"], [\"70382.70\", \"0.000\"], [\"70382.80\", \"0.000\"], [\"70382.90\", \"0.060\"], [\"70383.00\", \"0.001\"], [\"70383.40\", \"0.242\"], [\"70383.50\", \"0.001\"], [\"70383.60\", \"0.030\"], [\"70383.80\", \"0.007\"], [\"70384.10\", \"0.047\"], [\"70384.20\", \"0.016\"], [\"70384.40\", \"0.002\"], [\"70384.50\", \"0.036\"], [\"70384.60\", \"0.031\"], [\"70384.70\", \"0.061\"], [\"70384.80\", \"0.008\"], [\"70384.90\", \"0.107\"], [\"70385.00\", \"0.670\"], [\"70385.10\", \"0.033\"], [\"70385.20\", \"1.331\"], [\"70385.30\", \"0.347\"], [\"70385.40\", \"0.000\"], [\"70385.50\", \"0.175\"], [\"70385.70\", \"0.003\"], [\"70385.90\", \"0.184\"], [\"70386.00\", \"0.009\"], [\"70386.10\", \"0.003\"], [\"70386.20\", \"0.090\"], [\"70386.40\", \"0.015\"], [\"70386.50\", \"0.639\"], [\"70386.60\", \"0.001\"], [\"70386.70\", \"0.000\"], [\"70386.80\", \"0.022\"], [\"70386.90\", \"0.000\"], [\"70387.10\", \"0.107\"], [\"70387.20\", \"0.012\"], [\"70387.30\", \"0.003\"], [\"70387.40\", \"0.002\"], [\"70387.50\", \"0.091\"], [\"70387.60\", \"0.186\"], [\"70387.70\", \"0.003\"], [\"70387.80\", \"0.003\"], [\"70388.10\", \"0.000\"], [\"70388.30\", \"0.000\"], [\"70388.50\", \"0.002\"], [\"70388.60\", \"0.000\"], [\"70388.80\", \"0.008\"], [\"70389.00\", \"0.002\"], [\"70389.40\", \"0.000\"], [\"70389.50\", \"0.008\"], [\"70389.60\", \"0.000\"], [\"70389.70\", \"1.068\"], [\"70389.80\", \"0.071\"], [\"70389.90\", \"0.009\"], [\"70390.00\", \"0.002\"], [\"70390.10\", \"0.000\"], [\"70390.20\", \"0.002\"], [\"70390.30\", \"0.001\"], [\"70390.50\", \"0.009\"], [\"70390.60\", \"0.000\"], [\"70390.70\", \"0.000\"], [\"70390.80\", \"0.070\"], [\"70390.90\", \"0.002\"], [\"70391.00\", \"0.214\"], [\"70391.10\", \"0.005\"], [\"70391.20\", \"0.259\"], [\"70391.30\", \"0.003\"], [\"70391.40\", \"0.002\"], [\"70391.50\", \"0.000\"], [\"70391.60\", \"0.001\"], [\"70391.80\", \"0.000\"], [\"70391.90\", \"0.009\"], [\"70392.00\", \"0.013\"], [\"70392.10\", \"0.513\"], [\"70392.20\", \"0.002\"], [\"70392.30\", \"0.008\"], [\"70392.40\", \"0.053\"], [\"70392.50\", \"0.005\"], [\"70392.70\", \"0.853\"], [\"70392.80\", \"0.000\"], [\"70392.90\", \"0.007\"], [\"70393.10\", \"0.000\"], [\"70393.30\", \"0.004\"], [\"70393.40\", \"0.002\"], [\"70393.60\", \"0.002\"], [\"70393.90\", \"0.002\"], [\"70394.00\", \"0.005\"], [\"70394.10\", \"0.042\"], [\"70394.20\", \"0.001\"], [\"70394.40\", \"0.002\"], [\"70394.60\", \"0.213\"], [\"70394.90\", \"0.000\"], [\"70395.10\", \"0.000\"], [\"70395.20\", \"0.251\"], [\"70395.30\", \"0.772\"], [\"70395.50\", \"0.635\"], [\"70395.70\", \"1.000\"], [\"70396.00\", \"0.020\"], [\"70396.40\", \"0.039\"], [\"70396.60\", \"0.002\"], [\"70396.70\", \"0.002\"], [\"70396.80\", \"0.001\"], [\"70396.90\", \"0.076\"], [\"70397.00\", \"0.002\"], [\"70397.10\", \"0.000\"], [\"70397.20\", \"0.026\"], [\"70397.30\", \"0.002\"], [\"70397.40\", \"0.003\"], [\"70397.50\", \"0.586\"], [\"70397.60\", \"0.066\"], [\"70397.80\", \"0.003\"], [\"70397.90\", \"0.002\"], [\"70398.20\", \"0.053\"], [\"70398.30\", \"0.002\"], [\"70399.00\", \"0.184\"], [\"70399.60\", \"0.004\"], [\"70399.70\", \"0.004\"], [\"70399.80\", \"0.004\"], [\"70400.00\", \"2.038\"], [\"70400.80\", \"0.286\"], [\"70401.00\", \"0.261\"], [\"70401.10\", \"0.052\"], [\"70401.20\", \"0.002\"], [\"70401.60\", \"0.006\"], [\"70402.00\", \"0.197\"], [\"70402.40\", \"0.002\"], [\"70402.70\", \"0.004\"], [\"70402.80\", \"0.646\"], [\"70402.90\", \"1.117\"], [\"70403.00\", \"0.013\"], [\"70403.20\", \"0.007\"], [\"70403.30\", \"0.073\"], [\"70403.40\", \"0.002\"], [\"70403.60\", \"0.000\"], [\"70403.70\", \"0.003\"], [\"70404.00\", \"0.027\"], [\"70404.30\", \"0.000\"], [\"70404.70\", \"0.705\"], [\"70404.80\", \"0.392\"], [\"70404.90\", \"0.002\"], [\"70405.20\", \"0.191\"], [\"70405.50\", \"0.004\"], [\"70405.70\", \"0.113\"], [\"70405.80\", \"0.031\"], [\"70405.90\", \"0.000\"], [\"70406.00\", \"0.076\"], [\"70406.40\", \"0.183\"], [\"70406.60\", \"0.004\"], [\"70406.70\", \"0.570\"], [\"70406.80\", \"0.002\"], [\"70407.00\", \"0.005\"], [\"70407.20\", \"0.007\"], [\"70407.30\", \"0.003\"], [\"70407.50\", \"0.002\"], [\"70407.60\", \"0.057\"], [\"70407.90\", \"0.005\"], [\"70408.00\", \"0.000\"], [\"70408.10\", \"0.000\"], [\"70408.20\", \"0.002\"], [\"70408.80\", \"0.057\"], [\"70409.10\", \"1.580\"], [\"70409.40\", \"0.157\"], [\"70409.50\", \"0.002\"], [\"70409.60\", \"0.084\"], [\"70409.70\", \"0.073\"], [\"70410.00\", \"0.013\"], [\"70410.10\", \"0.000\"], [\"70410.30\", \"0.000\"], [\"70410.50\", \"0.000\"], [\"70411.00\", \"0.003\"], [\"70411.20\", \"0.113\"], [\"70411.40\", \"0.005\"], [\"70411.70\", \"0.005\"], [\"70411.80\", \"0.020\"], [\"70412.00\", \"0.004\"], [\"70412.10\", \"0.000\"], [\"70412.30\", \"0.347\"], [\"70412.60\", \"0.082\"], [\"70412.90\", \"0.000\"], [\"70413.00\", \"0.092\"], [\"70413.30\", \"0.003\"], [\"70414.40\", \"0.009\"], [\"70414.50\", \"0.009\"], [\"70414.90\", \"0.010\"], [\"70415.10\", \"0.586\"], [\"70415.20\", \"0.017\"], [\"70415.50\", \"0.002\"], [\"70415.80\", \"0.000\"], [\"70415.90\", \"0.557\"], [\"70416.00\", \"0.004\"], [\"70416.10\", \"0.301\"], [\"70416.30\", \"0.015\"], [\"70416.50\", \"0.566\"], [\"70416.60\", \"0.095\"], [\"70416.70\", \"0.000\"], [\"70417.00\", \"0.006\"], [\"70417.10\", \"0.000\"], [\"70417.20\", \"0.000\"], [\"70417.30\", \"0.000\"], [\"70417.60\", \"0.012\"], [\"70417.90\", \"0.000\"], [\"70418.00\", \"0.390\"], [\"70418.50\", \"0.007\"], [\"70418.90\", \"0.197\"], [\"70419.10\", \"0.000\"], [\"70419.60\", \"0.067\"], [\"70419.80\", \"0.256\"], [\"70420.00\", \"1.258\"], [\"70420.40\", \"0.583\"], [\"70420.60\", \"0.005\"], [\"70421.40\", \"0.006\"], [\"70423.50\", \"0.002\"], [\"70424.00\", \"0.006\"], [\"70424.40\", \"0.317\"], [\"70424.60\", \"0.000\"], [\"70425.60\", \"0.000\"], [\"70425.80\", \"1.074\"], [\"70426.10\", \"0.219\"], [\"70427.00\", \"0.035\"], [\"70427.40\", \"0.008\"], [\"70427.50\", \"0.008\"], [\"70428.00\", \"0.002\"], [\"70428.40\", \"0.141\"], [\"70428.60\", \"0.003\"], [\"70429.00\", \"0.002\"], [\"70429.20\", \"0.005\"], [\"70430.10\", \"0.069\"], [\"70430.60\", \"2.875\"], [\"70431.60\", \"0.001\"], [\"70432.00\", \"0.003\"], [\"70433.90\", \"0.003\"], [\"70434.00\", \"0.008\"], [\"70434.10\", \"0.125\"], [\"70434.40\", \"0.000\"], [\"70434.90\", \"0.384\"], [\"70435.00\", \"0.201\"], [\"70436.10\", \"0.009\"], [\"70436.30\", \"0.004\"], [\"70436.40\", \"0.000\"], [\"70436.60\", \"0.002\"], [\"70436.70\", \"0.198\"], [\"70437.30\", \"0.005\"], [\"70438.80\", \"0.002\"], [\"70439.10\", \"0.100\"], [\"70439.90\", \"0.000\"], [\"70440.40\", \"0.029\"], [\"70440.80\", \"0.849\"], [\"70441.60\", \"0.000\"], [\"70442.20\", \"0.084\"], [\"70443.20\", \"0.003\"], [\"70443.30\", \"0.002\"], [\"70443.40\", \"0.010\"], [\"70443.90\", \"0.008\"], [\"70444.60\", \"0.191\"], [\"70444.70\", \"0.535\"], [\"70444.80\", \"1.720\"], [\"70445.00\", \"0.000\"], [\"70445.70\", \"0.417\"], [\"70447.20\", \"0.004\"], [\"70447.90\", \"0.004\"], [\"70448.00\", \"0.010\"], [\"70448.60\", \"0.004\"], [\"70449.30\", \"0.049\"], [\"70451.70\", \"0.058\"], [\"70452.10\", \"0.002\"], [\"70453.50\", \"0.100\"], [\"70453.80\", \"0.281\"], [\"70454.80\", \"6.517\"], [\"70455.30\", \"0.006\"], [\"70455.50\", \"0.000\"], [\"70456.30\", \"0.191\"], [\"70456.50\", \"0.046\"], [\"70457.80\", \"0.007\"], [\"70459.80\", \"0.381\"], [\"70460.30\", \"0.172\"], [\"70462.40\", \"0.088\"], [\"70465.80\", \"0.083\"], [\"70466.60\", \"0.139\"], [\"70466.90\", \"0.000\"], [\"70467.40\", \"0.000\"], [\"70467.70\", \"0.002\"], [\"70467.80\", \"0.098\"], [\"70468.30\", \"0.002\"], [\"70470.50\", \"0.000\"], [\"70472.40\", \"0.166\"], [\"70473.40\", \"0.000\"], [\"70475.10\", \"7.974\"], [\"70475.70\", \"0.088\"], [\"70476.70\", \"0.084\"], [\"70478.80\", \"1.131\"], [\"70478.90\", \"0.081\"], [\"70480.30\", \"0.476\"], [\"70482.60\", \"0.017\"], [\"70482.70\", \"0.049\"], [\"70484.20\", \"0.786\"], [\"70489.60\", \"0.025\"], [\"70495.60\", \"0.513\"], [\"70496.10\", \"0.000\"], [\"70497.40\", \"0.008\"], [\"70497.70\", \"0.002\"], [\"70499.30\", \"0.000\"], [\"70499.80\", \"13.726\"], [\"70502.40\", \"0.002\"], [\"70517.50\", \"0.003\"], [\"70521.10\", \"0.000\"], [\"70538.70\", \"0.286\"], [\"70546.00\", \"2.547\"], [\"70547.90\", \"0.234\"], [\"70559.50\", \"0.054\"], [\"70561.90\", \"0.000\"], [\"70562.10\", \"0.018\"], [\"70565.40\", \"0.006\"], [\"70566.90\", \"0.000\"], [\"70568.00\", \"0.000\"], [\"70568.20\", \"0.000\"], [\"70568.30\", \"0.004\"], [\"70568.40\", \"0.003\"], [\"70577.00\", \"0.000\"], [\"70578.50\", \"0.000\"], [\"70579.90\", \"0.000\"], [\"70588.00\", \"1.497\"], [\"70588.40\", \"0.005\"], [\"70592.00\", \"0.002\"], [\"70595.40\", \"0.003\"], [\"70598.30\", \"0.018\"], [\"70602.80\", \"0.000\"], [\"70679.50\", \"0.000\"], [\"70739.90\", \"0.079\"], [\"70750.80\", \"0.000\"], [\"70757.90\", \"0.036\"], [\"70761.60\", \"0.023\"], [\"70768.40\", \"0.000\"], [\"70928.20\", \"0.004\"], [\"70934.50\", \"0.000\"], [\"71086.20\", \"0.035\"], [\"71380.00\", \"0.285\"], [\"71381.50\", \"0.008\"], [\"71382.10\", \"0.002\"], [\"71382.40\", \"2.937\"], [\"71385.20\", \"0.002\"], [\"71385.30\", \"0.000\"], [\"71385.50\", \"0.000\"], [\"71386.30\", \"0.000\"], [\"71386.50\", \"0.000\"], [\"71387.40\", \"0.000\"], [\"73945.10\", \"0.000\"], [\"89523.20\", \"0.000\"]]}", "symbol": "BTCUSDT"}
{"event": "depthUpdate", "raw_payload": "{\"e\": \"depthUpdate\", \"E\": 1773246398236, \"T\": 1773246398235, \"s\": \"BTCUSDT\", \"U\": 10089705053944, \"u\": 10089705091771, \"pu\": 10089705053916, \"b\": [[\"5000.00\", \"101.418\"], [\"19887.30\", \"0.680\"], [\"19970.40\", \"0.070\"], [\"19971.00\", \"0.010\"], [\"19972.40\", \"0.010\"], [\"20087.30\", \"0.140\"], [\"20270.40\", \"0.140\"], [\"20270.50\", \"0.020\"], [\"20271.00\", \"0.010\"], [\"20272.30\", \"0.010\"], [\"20273.80\", \"0.010\"], [\"20274.20\", \"0.050\"], [\"65051.80\", \"0.000\"], [\"66826.20\", \"0.000\"], [\"66845.40\", \"0.002\"], [\"68262.90\", \"4.246\"], [\"68407.60\", \"0.000\"], [\"68540.60\", \"0.004\"], [\"69217.90\", \"0.618\"], [\"69245.00\", \"0.880\"], [\"69337.20\", \"0.023\"], [\"69434.00\", \"54.843\"], [\"69642.90\", \"43.851\"], [\"69664.20\", \"0.052\"], [\"69666.70\", \"0.002\"], [\"69667.50\", \"0.000\"], [\"69667.60\", \"0.002\"], [\"69670.10\", \"0.010\"], [\"69670.50\", \"0.000\"], [\"69678.50\", \"0.006\"], [\"69951.10\", \"0.020\"], [\"69983.90\", \"0.056\"], [\"69991.60\", \"0.010\"], [\"70003.30\", \"0.002\"], [\"70004.20\", \"0.004\"], [\"70004.60\", \"0.000\"], [\"70033.30\", \"0.000\"], [\"70066.10\", \"0.040\"], [\"70073.00\", \"0.186\"], [\"70073.10\", \"0.189\"], [\"70073.60\", \"0.197\"], [\"70136.60\", \"0.083\"], [\"70136.90\", \"0.047\"], [\"70137.00\", \"0.022\"], [\"70141.00\", \"0.162\"], [\"70158.50\", \"0.001\"], [\"70160.80\", \"0.007\"], [\"70166.20\", \"0.000\"], [\"70170.90\", \"0.002\"], [\"70174.40\", \"0.003\"], [\"70177.10\", \"0.015\"], [\"70180.60\", \"0.005\"], [\"70182.70\", \"10.210\"], [\"70183.60\", \"0.017\"], [\"70185.10\", \"2.065\"], [\"70186.90\", \"0.283\"], [\"70187.50\", \"0.084\"], [\"70190.60\", \"0.025\"], [\"70205.50\", \"0.213\"], [\"70209.70\", \"0.041\"], [\"70210.00\", \"0.549\"], [\"70210.20\", \"0.137\"], [\"70211.60\", \"6.048\"], [\"70213.30\", \"0.000\"], [\"70213.40\", \"0.024\"], [\"70213.50\", \"0.376\"], [\"70213.80\", \"0.169\"], [\"70213.90\", \"0.043\"], [\"70215.40\", \"0.039\"], [\"70218.50\", \"0.287\"], [\"70220.20\", \"0.164\"], [\"70220.30\", \"0.039\"], [\"70220.80\", \"0.366\"], [\"70223.10\", \"0.593\"], [\"70224.90\", \"0.164\"], [\"70227.10\", \"0.082\"], [\"70228.00\", \"0.000\"], [\"70230.00\", \"1.257\"], [\"70230.30\", \"0.089\"], [\"70231.10\", \"0.084\"], [\"70237.50\", \"0.087\"], [\"70243.10\", \"0.113\"], [\"70243.70\", \"2.002\"], [\"70252.50\", \"0.012\"], [\"70254.60\", \"0.081\"], [\"70255.90\", \"0.187\"], [\"70257.10\", \"0.183\"], [\"70259.00\", \"1.315\"], [\"70259.10\", \"0.005\"], [\"70260.20\", \"0.092\"], [\"70262.10\", \"0.042\"], [\"70262.20\", \"3.563\"], [\"70262.50\", \"0.362\"], [\"70262.60\", \"0.346\"], [\"70270.10\", \"0.004\"], [\"70271.40\", \"0.134\"], [\"70271.60\", \"0.230\"], [\"70271.70\", \"0.000\"], [\"70271.90\", \"2.006\"], [\"70272.10\", \"0.740\"], [\"70273.50\", \"0.004\"], [\"70273.60\", \"0.042\"], [\"70273.90\", \"1.152\"], [\"70274.30\", \"0.004\"], [\"70275.30\", \"0.007\"], [\"70275.40\", \"0.022\"], [\"70277.00\", \"0.467\"], [\"70278.40\", \"0.000\"], [\"70279.20\", \"0.094\"], [\"70279.50\", \"0.025\"], [\"70279.90\", \"0.011\"], [\"70280.00\", \"1.430\"], [\"70280.20\", \"0.699\"], [\"70281.60\", \"0.309\"], [\"70281.80\", \"1.500\"], [\"70282.50\", \"0.041\"], [\"70282.80\", \"0.663\"], [\"70284.10\", \"0.004\"], [\"70284.80\", \"0.016\"], [\"70284.90\", \"0.002\"], [\"70285.50\", \"0.000\"], [\"70285.80\", \"0.008\"], [\"70286.00\", \"5.483\"], [\"70286.10\", \"0.002\"], [\"70286.20\", \"0.083\"], [\"70286.50\", \"0.078\"], [\"70287.00\", \"1.185\"], [\"70287.10\", \"2.020\"], [\"70287.30\", \"0.207\"], [\"70287.60\", \"0.000\"], [\"70287.70\", \"0.090\"], [\"70288.60\", \"0.039\"], [\"70289.50\", \"0.191\"], [\"70289.70\", \"0.000\"], [\"70292.30\", \"0.000\"], [\"70292.50\", \"0.000\"], [\"70292.70\", \"0.003\"], [\"70293.10\", \"1.204\"], [\"70293.50\", \"0.059\"], [\"70293.70\", \"0.160\"], [\"70294.60\", \"0.002\"], [\"70294.80\", \"0.483\"], [\"70295.00\", \"0.005\"], [\"70296.50\", \"0.425\"], [\"70296.70\", \"0.000\"], [\"70296.90\", \"0.402\"], [\"70297.10\", \"0.000\"], [\"70297.20\", \"0.004\"], [\"70297.50\", \"0.000\"], [\"70298.00\", \"0.161\"], [\"70298.20\", \"0.124\"], [\"70299.40\", \"0.003\"], [\"70300.00\", \"2.478\"], [\"70300.10\", \"0.003\"], [\"70300.30\", \"0.009\"], [\"70301.20\", \"0.049\"], [\"70301.30\", \"0.040\"], [\"70301.70\", \"0.590\"], [\"70301.80\", \"0.544\"], [\"70302.60\", \"0.002\"], [\"70303.60\", \"0.159\"], [\"70303.80\", \"0.386\"], [\"70304.30\", \"0.638\"], [\"70304.50\", \"0.004\"], [\"70304.60\", \"0.000\"], [\"70305.00\", \"0.029\"], [\"70305.10\", \"0.008\"], [\"70306.20\", \"0.002\"], [\"70306.80\", \"0.017\"], [\"70306.90\", \"0.068\"], [\"70307.60\", \"0.022\"], [\"70308.00\", \"0.124\"], [\"70308.40\", \"0.031\"], [\"70309.00\", \"0.078\"], [\"70310.50\", \"0.000\"], [\"70310.70\", \"0.581\"], [\"70311.00\", \"0.236\"], [\"70311.60\", \"0.082\"], [\"70312.10\", \"0.005\"], [\"70312.40\", \"0.030\"], [\"70312.90\", \"1.858\"], [\"70313.30\", \"0.002\"], [\"70313.70\", \"0.003\"], [\"70313.90\", \"0.041\"], [\"70314.00\", \"0.225\"], [\"70314.10\", \"0.006\"], [\"70314.20\", \"0.004\"], [\"70314.30\", \"0.441\"], [\"70314.40\", \"0.000\"], [\"70314.60\", \"0.015\"], [\"70315.40\", \"0.001\"], [\"70315.50\", \"0.005\"], [\"70315.90\", \"0.046\"], [\"70316.10\", \"0.090\"], [\"70316.40\", \"0.003\"], [\"70316.50\", \"0.004\"], [\"70316.60\", \"0.002\"], [\"70316.90\", \"0.000\"], [\"70317.00\", \"0.149\"], [\"70318.00\", \"0.043\"], [\"70318.20\", \"0.412\"], [\"70318.60\", \"0.007\"], [\"70318.70\", \"0.007\"], [\"70319.00\", \"0.056\"], [\"70319.50\", \"0.172\"], [\"70319.80\", \"1.475\"], [\"70320.30\", \"0.256\"], [\"70320.80\", \"0.046\"], [\"70321.10\", \"0.085\"], [\"70321.20\", \"0.056\"], [\"70321.30\", \"0.102\"], [\"70321.40\", \"0.215\"], [\"70321.80\", \"0.493\"], [\"70322.20\", \"0.000\"], [\"70323.00\", \"0.004\"], [\"70323.30\", \"0.008\"], [\"70324.00\", \"0.006\"], [\"70324.30\", \"0.711\"], [\"70324.40\", \"0.002\"], [\"70324.50\", \"0.764\"], [\"70324.60\", \"0.132\"], [\"70324.70\", \"0.147\"], [\"70324.80\", \"0.000\"], [\"70325.10\", \"0.100\"], [\"70325.30\", \"0.007\"], [\"70325.40\", \"0.649\"], [\"70325.80\", \"0.074\"], [\"70326.50\", \"0.000\"], [\"70326.70\", \"0.000\"], [\"70326.80\", \"0.007\"], [\"70327.10\", \"0.002\"], [\"70327.50\", \"0.002\"], [\"70328.10\", \"0.571\"], [\"70328.20\", \"0.214\"], [\"70328.30\", \"0.002\"], [\"70328.60\", \"0.203\"], [\"70328.70\", \"0.305\"], [\"70328.80\", \"0.000\"], [\"70328.90\", \"0.014\"], [\"70329.50\", \"0.002\"], [\"70329.60\", \"0.036\"], [\"70329.80\", \"0.000\"], [\"70330.00\", \"0.088\"], [\"70330.20\", \"0.005\"], [\"70330.40\", \"0.380\"], [\"70330.50\", \"0.069\"], [\"70330.80\", \"0.195\"], [\"70330.90\", \"0.052\"], [\"70331.20\", \"0.014\"], [\"70331.40\", \"0.002\"], [\"70331.60\", \"0.514\"], [\"70331.70\", \"0.000\"], [\"70331.90\", \"0.100\"], [\"70332.10\", \"0.933\"], [\"70332.70\", \"0.004\"], [\"70332.80\", \"1.246\"], [\"70333.00\", \"0.511\"], [\"70333.10\", \"0.002\"], [\"70333.70\", \"0.003\"], [\"70334.10\", \"0.205\"], [\"70334.20\", \"0.071\"], [\"70334.40\", \"0.579\"], [\"70334.60\", \"0.588\"], [\"70334.70\", \"0.639\"], [\"70335.00\", \"0.379\"], [\"70335.10\", \"0.004\"], [\"70335.30\", \"0.002\"], [\"70335.60\", \"0.000\"], [\"70335.70\", \"0.045\"], [\"70336.30\", \"0.000\"], [\"70336.40\", \"0.000\"], [\"70336.50\", \"0.005\"], [\"70336.60\", \"0.006\"], [\"70336.90\", \"0.003\"], [\"70337.00\", \"0.009\"], [\"70337.10\", \"1.137\"], [\"70337.20\", \"0.080\"], [\"70337.30\", \"0.032\"], [\"70337.40\", \"0.012\"], [\"70337.50\", \"0.000\"], [\"70337.70\", \"0.011\"], [\"70338.00\", \"0.034\"], [\"70338.10\", \"0.000\"], [\"70338.20\", \"0.035\"], [\"70338.40\", \"0.016\"], [\"70338.60\", \"0.003\"], [\"70338.90\", \"0.031\"], [\"70339.00\", \"0.008\"], [\"70339.10\", \"0.381\"], [\"70339.20\", \"0.515\"], [\"70339.40\", \"0.014\"], [\"70339.50\", \"0.011\"], [\"70339.60\", \"0.188\"], [\"70339.70\", \"0.004\"], [\"70339.80\", \"0.002\"], [\"70340.40\", \"0.002\"], [\"70340.50\", \"0.064\"], [\"70340.60\", \"0.000\"], [\"70340.70\", \"0.001\"], [\"70340.80\", \"0.005\"], [\"70340.90\", \"0.005\"], [\"70341.10\", \"0.000\"], [\"70341.40\", \"0.205\"], [\"70341.50\", \"0.005\"], [\"70341.60\", \"0.002\"], [\"70341.80\", \"0.512\"], [\"70341.90\", \"0.000\"], [\"70342.20\", \"0.003\"], [\"70342.30\", \"0.561\"], [\"70342.40\", \"0.193\"], [\"70342.50\", \"0.225\"], [\"70342.60\", \"0.000\"], [\"70342.80\", \"0.003\"], [\"70342.90\", \"0.002\"], [\"70343.00\", \"2.103\"], [\"70343.20\", \"0.022\"], [\"70343.30\", \"0.129\"], [\"70343.50\", \"0.072\"], [\"70343.60\", \"0.111\"], [\"70343.70\", \"0.005\"], [\"70343.90\", \"0.073\"], [\"70344.00\", \"0.240\"], [\"70344.10\", \"0.007\"], [\"70344.20\", \"0.007\"], [\"70344.30\", \"0.136\"], [\"70344.40\", \"0.186\"], [\"70344.60\", \"0.002\"], [\"70344.70\", \"0.000\"], [\"70345.00\", \"0.209\"], [\"70345.10\", \"0.002\"], [\"70345.20\", \"0.021\"], [\"70345.60\", \"0.007\"], [\"70345.70\", \"0.029\"], [\"70345.80\", \"0.077\"], [\"70346.00\", \"0.002\"], [\"70346.10\", \"1.220\"], [\"70346.20\", \"0.281\"], [\"70346.30\", \"0.003\"], [\"70346.40\", \"0.002\"], [\"70346.50\", \"0.215\"], [\"70346.60\", \"0.009\"], [\"70346.70\", \"0.001\"], [\"70346.90\", \"0.003\"], [\"70347.10\", \"0.007\"], [\"70347.20\", \"0.001\"], [\"70347.30\", \"0.000\"], [\"70347.40\", \"0.201\"], [\"70347.60\", \"0.002\"], [\"70347.70\", \"0.011\"], [\"70347.80\", \"0.006\"], [\"70347.90\", \"0.000\"], [\"70348.00\", \"0.010\"], [\"70348.10\", \"0.007\"], [\"70348.20\", \"0.544\"], [\"70348.30\", \"0.014\"], [\"70348.50\", \"0.022\"], [\"70348.60\", \"0.011\"], [\"70348.90\", \"0.218\"], [\"70349.10\", \"0.002\"], [\"70349.20\", \"0.001\"], [\"70349.30\", \"0.004\"], [\"70349.40\", \"0.150\"], [\"70349.50\", \"0.004\"], [\"70349.60\", \"0.088\"], [\"70349.70\", \"0.006\"], [\"70349.80\", \"1.069\"], [\"70349.90\", \"0.284\"], [\"70350.00\", \"0.312\"], [\"70350.30\", \"0.004\"], [\"70350.40\", \"0.020\"], [\"70350.50\", \"0.006\"], [\"70350.70\", \"0.006\"], [\"70350.80\", \"0.004\"], [\"70351.00\", \"0.056\"], [\"70351.10\", \"0.000\"], [\"70351.30\", \"0.002\"], [\"70351.40\", \"0.050\"], [\"70351.50\", \"0.000\"], [\"70351.60\", \"0.006\"], [\"70351.70\", \"0.055\"], [\"70351.80\", \"0.051\"], [\"70352.10\", \"0.003\"], [\"70352.20\", \"0.005\"], [\"70352.30\", \"0.001\"], [\"70352.40\", \"0.000\"], [\"70352.70\", \"0.430\"], [\"70352.80\", \"0.002\"], [\"70353.00\", \"0.451\"], [\"70353.10\", \"0.358\"], [\"70353.30\", \"0.285\"], [\"70353.40\", \"0.658\"], [\"70353.60\", \"0.000\"], [\"70353.70\", \"0.000\"], [\"70353.80\", \"0.000\"], [\"70354.00\", \"0.002\"], [\"70354.20\", \"0.001\"], [\"70354.50\", \"0.006\"], [\"70354.70\", \"0.004\"], [\"70355.20\", \"0.016\"], [\"70355.40\", \"0.004\"], [\"70355.60\", \"0.000\"], [\"70356.00\", \"0.028\"], [\"70356.10\", \"0.006\"], [\"70356.30\", \"0.332\"], [\"70356.40\", \"0.001\"], [\"70356.50\", \"0.012\"], [\"70356.60\", \"3.180\"], [\"70356.70\", \"0.784\"], [\"70356.80\", \"0.407\"], [\"70357.00\", \"0.121\"], [\"70357.10\", \"0.000\"], [\"70357.30\", \"0.001\"], [\"70357.50\", \"0.095\"], [\"70357.60\", \"0.000\"], [\"70357.70\", \"0.016\"], [\"70357.80\", \"0.000\"], [\"70358.10\", \"0.035\"], [\"70358.20\", \"0.405\"], [\"70358.30\", \"0.182\"], [\"70358.40\", \"0.000\"], [\"70358.50\", \"0.008\"], [\"70358.80\", \"0.002\"], [\"70359.00\", \"0.000\"], [\"70359.10\", \"0.000\"], [\"70359.20\", \"0.000\"], [\"70359.30\", \"0.001\"], [\"70359.50\", \"0.001\"], [\"70359.80\", \"0.000\"], [\"70359.90\", \"0.209\"], [\"70360.00\", \"0.004\"], [\"70360.10\", \"0.032\"], [\"70360.20\", \"0.008\"], [\"70360.50\", \"0.005\"], [\"70360.60\", \"0.000\"], [\"70360.70\", \"0.000\"], [\"70360.90\", \"0.002\"], [\"70361.00\", \"0.002\"], [\"70361.10\", \"0.009\"], [\"70361.20\", \"0.002\"], [\"70361.50\", \"0.003\"], [\"70361.60\", \"0.003\"], [\"70361.80\", \"1.020\"], [\"70361.90\", \"0.005\"], [\"70362.00\", \"0.013\"], [\"70362.10\", \"0.005\"], [\"70362.20\", \"0.433\"], [\"70362.30\", \"0.002\"], [\"70362.40\", \"0.008\"], [\"70362.70\", \"0.002\"], [\"70362.80\", \"0.000\"], [\"70362.90\", \"0.000\"], [\"70363.00\", \"0.002\"], [\"70363.40\", \"0.001\"], [\"70363.70\", \"0.000\"], [\"70363.80\", \"0.001\"], [\"70363.90\", \"0.000\"], [\"70364.00\", \"0.013\"], [\"70364.10\", \"0.001\"], [\"70364.50\", \"0.000\"], [\"70364.60\", \"0.000\"], [\"70364.70\", \"0.010\"], [\"70364.80\", \"0.000\"], [\"70365.00\", \"0.004\"], [\"70365.30\", \"0.000\"], [\"70365.60\", \"0.005\"], [\"70365.80\", \"0.002\"], [\"70365.90\", \"0.007\"], [\"70366.00\", \"0.004\"], [\"70366.10\", \"0.000\"], [\"70366.50\", \"0.001\"], [\"70366.70\", \"0.000\"], [\"70367.00\", \"0.009\"], [\"70367.20\", \"0.002\"], [\"70367.50\", \"0.006\"], [\"70367.60\", \"0.003\"], [\"70367.70\", \"0.000\"], [\"70367.90\", \"0.000\"], [\"70368.30\", \"0.005\"], [\"70368.60\", \"0.003\"], [\"70368.80\", \"0.000\"], [\"70369.10\", \"0.001\"], [\"70369.20\", \"0.000\"], [\"70369.30\", \"0.000\"], [\"70369.50\", \"0.000\"], [\"70369.70\", \"0.000\"], [\"70369.80\", \"0.005\"], [\"70370.00\", \"0.004\"], [\"70370.10\", \"0.002\"], [\"70370.30\", \"0.000\"], [\"70370.40\", \"0.223\"], [\"70370.50\", \"0.000\"], [\"70370.90\", \"0.000\"], [\"70371.00\", \"0.000\"]], \"a\": [[\"70370.50\", \"11.694\"], [\"70370.60\", \"0.005\"], [\"70370.70\", \"0.029\"], [\"70370.80\", \"0.002\"], [\"70370.90\", \"0.002\"], [\"70371.00\", \"0.000\"], [\"70371.10\", \"0.000\"], [\"70371.20\", \"0.003\"], [\"70371.30\", \"0.000\"], [\"70371.40\", \"0.004\"], [\"70371.50\", \"0.002\"], [\"70371.60\", \"0.002\"], [\"70371.70\", \"0.003\"], [\"70371.80\", \"0.002\"], [\"70371.90\", \"0.000\"], [\"70372.00\", \"0.002\"], [\"70372.10\", \"0.003\"], [\"70372.20\", \"0.000\"], [\"70372.30\", \"0.000\"], [\"70372.40\", \"0.004\"], [\"70372.50\", \"0.006\"], [\"70372.60\", \"0.000\"], [\"70372.70\", \"0.000\"], [\"70372.80\", \"0.000\"], [\"70372.90\", \"0.000\"], [\"70373.00\", \"0.002\"], [\"70373.10\", \"0.511\"], [\"70373.20\", \"0.342\"], [\"70373.30\", \"0.003\"], [\"70373.40\", \"0.000\"], [\"70373.50\", \"0.000\"], [\"70373.60\", \"0.003\"], [\"70373.70\", \"0.002\"], [\"70373.80\", \"0.002\"], [\"70373.90\", \"0.818\"], [\"70374.00\", \"0.002\"], [\"70374.10\", \"0.641\"], [\"70374.20\", \"1.888\"], [\"70374.30\", \"0.086\"], [\"70374.40\", \"0.005\"], [\"70374.70\", \"0.003\"], [\"70374.80\", \"0.000\"], [\"70374.90\", \"0.000\"], [\"70375.00\", \"0.006\"], [\"70375.10\", \"0.000\"], [\"70375.30\", \"0.511\"], [\"70375.40\", \"0.040\"], [\"70375.50\", \"0.001\"], [\"70375.60\", \"0.001\"], [\"70375.80\", \"0.002\"], [\"70375.90\", \"0.003\"], [\"70376.00\", \"0.004\"], [\"70376.20\", \"0.000\"], [\"70376.30\", \"1.066\"], [\"70376.40\", \"0.261\"], [\"70376.50\", \"0.002\"], [\"70376.60\", \"0.002\"], [\"70376.70\", \"0.002\"], [\"70376.80\", \"0.006\"], [\"70376.90\", \"0.002\"], [\"70377.00\", \"0.064\"], [\"70377.10\", \"0.004\"], [\"70377.30\", \"0.005\"], [\"70377.40\", \"0.000\"], [\"70377.50\", \"0.516\"], [\"70377.60\", \"0.002\"], [\"70377.70\", \"0.007\"], [\"70377.80\", \"0.049\"], [\"70377.90\", \"0.006\"], [\"70378.00\", \"0.002\"], [\"70378.10\", \"0.001\"], [\"70378.20\", \"0.000\"], [\"70378.30\", \"0.003\"], [\"70378.40\", \"0.157\"], [\"70378.50\", \"0.001\"], [\"70378.60\", \"0.003\"], [\"70378.70\", \"0.000\"], [\"70378.80\", \"0.000\"], [\"70379.00\", \"0.345\"], [\"70379.10\", \"0.000\"], [\"70379.40\", \"0.002\"], [\"70379.50\", \"0.001\"], [\"70379.60\", \"0.002\"], [\"70379.70\", \"0.725\"], [\"70379.80\", \"0.002\"], [\"70379.90\", \"1.728\"], [\"70380.00\", \"0.046\"], [\"70380.20\", \"0.000\"], [\"70380.50\", \"0.048\"], [\"70380.90\", \"0.000\"], [\"70381.00\", \"0.062\"], [\"70381.10\", \"0.003\"], [\"70381.40\", \"0.070\"], [\"70381.50\", \"0.748\"], [\"70381.60\", \"0.059\"], [\"70381.70\", \"0.043\"], [\"70381.80\", \"0.004\"], [\"70381.90\", \"0.000\"], [\"70382.00\", \"1.100\"], [\"70382.10\", \"0.016\"], [\"70382.30\", \"0.809\"], [\"70382.40\", \"1.058\"], [\"70382.50\", \"0.514\"], [\"70382.80\", \"0.511\"], [\"70383.00\", \"0.014\"], [\"70383.10\", \"0.092\"], [\"70383.70\", \"0.002\"], [\"70384.00\", \"0.226\"], [\"70384.10\", \"0.004\"], [\"70384.20\", \"0.000\"], [\"70384.40\", \"0.000\"], [\"70384.50\", \"0.002\"], [\"70384.60\", \"0.000\"], [\"70384.70\", \"0.003\"], [\"70384.80\", \"0.010\"], [\"70384.90\", \"0.309\"], [\"70385.00\", \"0.422\"], [\"70385.10\", \"0.007\"], [\"70385.20\", \"1.316\"], [\"70385.30\", \"0.347\"], [\"70385.50\", \"0.246\"], [\"70385.60\", \"0.002\"], [\"70385.70\", \"0.001\"], [\"70386.10\", \"0.002\"], [\"70386.20\", \"0.000\"], [\"70386.40\", \"0.001\"], [\"70386.50\", \"0.000\"], [\"70386.60\", \"0.000\"], [\"70386.70\", \"0.002\"], [\"70386.80\", \"0.002\"], [\"70386.90\", \"0.000\"], [\"70387.00\", \"0.209\"], [\"70387.10\", \"0.109\"], [\"70387.30\", \"0.005\"], [\"70387.60\", \"0.258\"], [\"70387.90\", \"0.003\"], [\"70388.00\", \"0.119\"], [\"70388.10\", \"0.002\"], [\"70388.60\", \"0.071\"], [\"70388.80\", \"0.005\"], [\"70389.20\", \"0.004\"], [\"70389.60\", \"0.404\"], [\"70389.80\", \"0.071\"], [\"70389.90\", \"0.008\"], [\"70390.00\", \"0.004\"], [\"70390.20\", \"0.004\"], [\"70390.30\", \"0.003\"], [\"70390.40\", \"0.003\"], [\"70390.50\", \"0.006\"], [\"70391.00\", \"0.204\"], [\"70391.10\", \"0.007\"], [\"70391.60\", \"0.008\"], [\"70391.70\", \"0.053\"], [\"70391.80\", \"0.000\"], [\"70391.90\", \"0.009\"], [\"70392.00\", \"0.009\"], [\"70392.10\", \"0.002\"], [\"70392.40\", \"0.414\"], [\"70392.50\", \"0.075\"], [\"70392.60\", \"0.005\"], [\"70392.80\", \"0.052\"], [\"70392.90\", \"0.006\"], [\"70393.60\", \"0.376\"], [\"70393.90\", \"0.002\"], [\"70394.00\", \"0.000\"], [\"70394.30\", \"1.002\"], [\"70394.50\", \"0.219\"], [\"70394.80\", \"0.194\"], [\"70394.90\", \"0.029\"], [\"70395.00\", \"0.006\"], [\"70395.10\", \"0.000\"], [\"70395.20\", \"0.023\"], [\"70395.30\", \"0.770\"], [\"70395.40\", \"0.009\"], [\"70395.50\", \"0.633\"], [\"70395.70\", \"0.000\"], [\"70396.30\", \"0.005\"], [\"70396.50\", \"0.000\"], [\"70396.90\", \"0.005\"], [\"70397.00\", \"0.045\"], [\"70397.10\", \"0.036\"], [\"70397.20\", \"0.066\"], [\"70397.30\", \"0.000\"], [\"70397.40\", \"0.044\"], [\"70397.50\", \"0.622\"], [\"70397.90\", \"0.000\"], [\"70398.10\", \"0.005\"], [\"70398.80\", \"0.011\"], [\"70398.90\", \"0.005\"], [\"70399.10\", \"0.235\"], [\"70399.30\", \"0.011\"], [\"70399.60\", \"0.002\"], [\"70399.70\", \"0.000\"], [\"70399.80\", \"0.002\"], [\"70400.50\", \"0.003\"], [\"70400.60\", \"0.002\"], [\"70400.70\", \"0.080\"], [\"70400.90\", \"0.767\"], [\"70401.10\", \"0.000\"], [\"70401.20\", \"0.002\"], [\"70401.30\", \"0.008\"], [\"70402.00\", \"0.195\"], [\"70402.20\", \"0.008\"], [\"70402.60\", \"0.000\"], [\"70402.70\", \"0.004\"], [\"70402.80\", \"0.658\"], [\"70402.90\", \"1.066\"], [\"70403.00\", \"0.006\"], [\"70403.10\", \"0.013\"], [\"70403.20\", \"0.000\"], [\"70403.50\", \"0.069\"], [\"70404.00\", \"0.001\"], [\"70404.10\", \"0.002\"], [\"70404.50\", \"0.006\"], [\"70404.70\", \"0.742\"], [\"70404.80\", \"0.405\"], [\"70404.90\", \"0.005\"], [\"70405.00\", \"0.025\"], [\"70405.10\", \"0.045\"], [\"70405.20\", \"0.227\"], [\"70405.40\", \"0.040\"], [\"70405.60\", \"0.213\"], [\"70405.70\", \"0.042\"], [\"70405.80\", \"0.075\"], [\"70405.90\", \"0.913\"], [\"70406.00\", \"0.040\"], [\"70406.10\", \"0.056\"], [\"70406.20\", \"0.060\"], [\"70406.40\", \"0.147\"], [\"70406.80\", \"0.000\"], [\"70406.90\", \"0.513\"], [\"70407.00\", \"0.003\"], [\"70407.30\", \"0.586\"], [\"70407.50\", \"0.002\"], [\"70407.60\", \"0.000\"], [\"70407.80\", \"0.069\"], [\"70407.90\", \"0.196\"], [\"70408.40\", \"0.000\"], [\"70408.70\", \"0.188\"], [\"70408.80\", \"0.052\"], [\"70409.40\", \"0.087\"], [\"70409.50\", \"0.166\"], [\"70409.70\", \"0.000\"], [\"70409.80\", \"0.197\"], [\"70410.00\", \"0.011\"], [\"70410.20\", \"0.000\"], [\"70410.40\", \"0.006\"], [\"70410.60\", \"0.010\"], [\"70410.70\", \"0.013\"], [\"70411.00\", \"0.005\"], [\"70411.20\", \"0.002\"], [\"70411.60\", \"0.023\"], [\"70411.80\", \"0.005\"], [\"70411.90\", \"0.206\"], [\"70412.30\", \"0.353\"], [\"70412.60\", \"0.002\"], [\"70412.70\", \"0.005\"], [\"70413.00\", \"0.012\"], [\"70413.50\", \"0.000\"], [\"70413.60\", \"0.007\"], [\"70414.20\", \"0.008\"], [\"70414.30\", \"0.000\"], [\"70414.70\", \"0.003\"], [\"70414.90\", \"0.006\"], [\"70415.10\", \"0.584\"], [\"70416.30\", \"0.000\"], [\"70416.50\", \"0.594\"], [\"70416.60\", \"0.090\"], [\"70416.80\", \"0.206\"], [\"70417.10\", \"0.004\"], [\"70417.60\", \"0.012\"], [\"70417.80\", \"0.573\"], [\"70418.00\", \"0.344\"], [\"70418.20\", \"0.098\"], [\"70418.70\", \"0.031\"], [\"70418.80\", \"0.012\"], [\"70419.50\", \"0.006\"], [\"70419.80\", \"0.258\"], [\"70419.90\", \"0.516\"], [\"70420.00\", \"1.172\"], [\"70420.40\", \"0.000\"], [\"70420.50\", \"0.000\"], [\"70420.60\", \"0.000\"], [\"70420.70\", \"0.000\"], [\"70420.90\", \"0.003\"], [\"70421.10\", \"0.198\"], [\"70421.40\", \"0.004\"], [\"70421.50\", \"0.187\"], [\"70421.80\", \"0.333\"], [\"70421.90\", \"0.143\"], [\"70422.10\", \"0.483\"], [\"70422.80\", \"0.130\"], [\"70423.70\", \"0.423\"], [\"70424.00\", \"0.008\"], [\"70424.20\", \"0.003\"], [\"70424.30\", \"0.002\"], [\"70424.40\", \"0.314\"], [\"70424.70\", \"0.000\"], [\"70425.00\", \"0.128\"], [\"70425.10\", \"0.002\"], [\"70425.20\", \"0.113\"], [\"70425.30\", \"0.108\"], [\"70425.50\", \"0.004\"], [\"70425.80\", \"1.126\"], [\"70426.10\", \"0.212\"], [\"70426.20\", \"0.027\"], [\"70426.50\", \"0.003\"], [\"70426.80\", \"0.066\"], [\"70426.90\", \"0.004\"], [\"70427.10\", \"0.345\"], [\"70427.20\", \"2.153\"], [\"70427.90\", \"0.849\"], [\"70428.00\", \"0.002\"], [\"70428.20\", \"0.033\"], [\"70428.40\", \"0.013\"], [\"70428.50\", \"0.002\"], [\"70428.60\", \"0.000\"], [\"70429.20\", \"0.002\"], [\"70429.30\", \"0.002\"], [\"70429.40\", \"0.005\"], [\"70430.00\", \"0.015\"], [\"70430.10\", \"0.049\"], [\"70430.30\", \"0.084\"], [\"70430.70\", \"0.004\"], [\"70431.20\", \"0.100\"], [\"70431.40\", \"0.754\"], [\"70431.50\", \"0.097\"], [\"70433.10\", \"0.002\"], [\"70433.50\", \"0.017\"], [\"70433.80\", \"0.089\"], [\"70434.20\", \"0.001\"], [\"70434.30\", \"0.000\"], [\"70434.50\", \"0.403\"], [\"70435.50\", \"0.193\"], [\"70435.60\", \"0.342\"], [\"70436.10\", \"0.006\"], [\"70436.60\", \"0.002\"], [\"70437.00\", \"0.000\"], [\"70439.10\", \"0.000\"], [\"70439.30\", \"1.231\"], [\"70440.00\", \"0.013\"], [\"70440.40\", \"0.001\"], [\"70440.50\", \"0.077\"], [\"70440.70\", \"0.003\"], [\"70440.80\", \"0.000\"], [\"70440.90\", \"1.296\"], [\"70441.50\", \"0.033\"], [\"70442.60\", \"0.232\"], [\"70443.60\", \"0.000\"], [\"70443.90\", \"0.002\"], [\"70444.10\", \"0.357\"], [\"70444.30\", \"0.240\"], [\"70444.40\", \"0.084\"], [\"70444.50\", \"0.122\"], [\"70444.70\", \"0.455\"], [\"70444.80\", \"1.705\"], [\"70445.50\", \"0.191\"], [\"70445.80\", \"0.374\"], [\"70448.00\", \"0.057\"], [\"70448.20\", \"0.081\"], [\"70448.60\", \"0.000\"], [\"70448.70\", \"0.152\"], [\"70450.40\", \"0.000\"], [\"70450.60\", \"0.259\"], [\"70451.50\", \"0.002\"], [\"70451.70\", \"0.055\"], [\"70452.00\", \"0.082\"], [\"70452.20\", \"0.142\"], [\"70452.70\", \"0.191\"], [\"70454.00\", \"0.124\"], [\"70454.70\", \"0.000\"], [\"70454.90\", \"1.510\"], [\"70455.10\", \"0.083\"], [\"70455.20\", \"0.114\"], [\"70455.90\", \"0.103\"], [\"70456.50\", \"0.044\"], [\"70456.60\", \"0.665\"], [\"70456.80\", \"0.041\"], [\"70456.90\", \"0.221\"], [\"70457.00\", \"0.016\"], [\"70457.10\", \"0.387\"], [\"70457.20\", \"0.068\"], [\"70457.40\", \"0.089\"], [\"70458.00\", \"0.094\"], [\"70458.80\", \"0.003\"], [\"70459.20\", \"0.144\"], [\"70459.30\", \"0.002\"], [\"70460.90\", \"0.082\"], [\"70461.70\", \"0.081\"], [\"70462.20\", \"0.019\"], [\"70462.30\", \"0.071\"], [\"70462.40\", \"0.078\"], [\"70463.30\", \"0.000\"], [\"70464.50\", \"0.000\"], [\"70464.80\", \"0.000\"], [\"70466.20\", \"0.164\"], [\"70466.30\", \"0.250\"], [\"70466.70\", \"0.233\"], [\"70468.10\", \"0.498\"], [\"70468.80\", \"0.100\"], [\"70468.90\", \"0.099\"], [\"70469.00\", \"3.914\"], [\"70470.80\", \"0.002\"], [\"70471.00\", \"0.080\"], [\"70471.20\", \"0.081\"], [\"70471.40\", \"0.014\"], [\"70471.70\", \"0.089\"], [\"70472.30\", \"0.010\"], [\"70473.70\", \"0.145\"], [\"70474.20\", \"0.044\"], [\"70475.10\", \"8.074\"], [\"70478.60\", \"0.000\"], [\"70479.00\", \"0.030\"], [\"70479.20\", \"0.002\"], [\"70480.70\", \"0.079\"], [\"70481.10\", \"0.128\"], [\"70481.60\", \"0.000\"], [\"70481.70\", \"0.082\"], [\"70481.90\", \"0.039\"], [\"70482.60\", \"0.003\"], [\"70483.40\", \"0.209\"], [\"70483.90\", \"0.000\"], [\"70484.80\", \"6.787\"], [\"70487.80\", \"0.221\"], [\"70489.60\", \"0.000\"], [\"70490.10\", \"2.374\"], [\"70491.30\", \"0.000\"], [\"70492.80\", \"0.113\"], [\"70493.10\", \"0.078\"], [\"70493.50\", \"0.000\"], [\"70495.00\", \"0.038\"], [\"70497.00\", \"5.004\"], [\"70497.20\", \"2.379\"], [\"70499.60\", \"0.079\"], [\"70501.70\", \"0.090\"], [\"70508.00\", \"0.000\"], [\"70508.30\", \"0.001\"], [\"70510.30\", \"0.186\"], [\"70510.50\", \"0.000\"], [\"70511.40\", \"2.704\"], [\"70512.30\", \"10.002\"], [\"70512.80\", \"0.000\"], [\"70513.00\", \"0.007\"], [\"70513.90\", \"0.021\"], [\"70517.30\", \"0.400\"], [\"70521.40\", \"0.028\"], [\"70522.60\", \"0.369\"], [\"70525.50\", \"1.344\"], [\"70526.20\", \"0.226\"], [\"70527.60\", \"0.000\"], [\"70527.70\", \"0.002\"], [\"70537.90\", \"0.000\"], [\"70538.50\", \"0.017\"], [\"70547.20\", \"1.634\"], [\"70547.90\", \"0.195\"], [\"70561.00\", \"0.000\"], [\"70562.80\", \"10.000\"], [\"70566.50\", \"0.008\"], [\"70568.40\", \"0.000\"], [\"70571.90\", \"0.000\"], [\"70574.70\", \"0.000\"], [\"70577.70\", \"0.072\"], [\"70578.20\", \"0.000\"], [\"70580.90\", \"0.008\"], [\"70588.10\", \"0.192\"], [\"70589.60\", \"5.421\"], [\"70589.80\", \"0.018\"], [\"70590.80\", \"0.367\"], [\"70595.90\", \"0.002\"], [\"70598.20\", \"0.031\"], [\"70598.30\", \"0.000\"], [\"70603.80\", \"0.252\"], [\"70606.70\", \"0.000\"], [\"70609.60\", \"0.907\"], [\"70609.90\", \"3.386\"], [\"70611.00\", \"0.088\"], [\"70611.50\", \"0.279\"], [\"70630.10\", \"0.032\"], [\"70630.90\", \"0.290\"], [\"70631.90\", \"0.008\"], [\"70676.40\", \"0.196\"], [\"70679.40\", \"0.131\"], [\"70681.90\", \"0.000\"], [\"70742.10\", \"0.076\"], [\"70745.30\", \"0.000\"], [\"70751.10\", \"0.000\"], [\"70783.70\", \"0.002\"], [\"70799.20\", \"0.014\"], [\"71074.20\", \"0.000\"], [\"71074.80\", \"0.000\"], [\"71119.40\", \"55.842\"], [\"71332.70\", \"63.939\"], [\"71370.50\", \"0.019\"], [\"71371.30\", \"0.012\"], [\"71373.90\", \"0.634\"], [\"71382.40\", \"2.927\"], [\"71383.40\", \"0.002\"], [\"71420.00\", \"2.193\"], [\"71422.10\", \"1.887\"], [\"71671.70\", \"0.004\"], [\"71707.00\", \"0.010\"], [\"75256.80\", \"0.000\"]]}", "symbol": "BTCUSDT"}
{"event": "depthUpdate", "raw_payload": "{\"e\": \"depthUpdate\", \"E\": 1773246398338, \"T\": 1773246398337, \"s\": \"BTCUSDT\", \"U\": 10089705091788, \"u\": 10089705114691, \"pu\": 10089705091771, \"b\": [[\"1000.00\", \"26.792\"], [\"5000.00\", \"101.418\"], [\"19887.30\", \"0.510\"], [\"19967.10\", \"0.030\"], [\"19968.20\", \"0.010\"], [\"19970.40\", \"0.120\"], [\"20087.30\", \"0.050\"], [\"20267.10\", \"0.070\"], [\"20268.50\", \"0.010\"], [\"20269.80\", \"0.010\"], [\"20270.40\", \"0.220\"], [\"56310.00\", \"100.003\"], [\"66840.80\", \"0.000\"], [\"66872.20\", \"0.004\"], [\"66872.30\", \"0.002\"], [\"68983.20\", \"0.000\"], [\"69317.90\", \"2.792\"], [\"69666.70\", \"0.000\"], [\"69678.50\", \"0.002\"], [\"70017.60\", \"0.002\"], [\"70084.50\", \"0.214\"], [\"70128.80\", \"0.038\"], [\"70134.20\", \"0.038\"], [\"70135.80\", \"0.045\"], [\"70135.90\", \"0.043\"], [\"70136.60\", \"0.040\"], [\"70137.30\", \"0.058\"], [\"70137.70\", \"0.054\"], [\"70138.00\", \"1.455\"], [\"70155.20\", \"0.001\"], [\"70155.90\", \"0.897\"], [\"70157.40\", \"0.288\"], [\"70160.80\", \"0.000\"], [\"70167.30\", \"0.003\"], [\"70170.80\", \"0.003\"], [\"70176.60\", \"0.000\"], [\"70178.50\", \"5.616\"], [\"70196.70\", \"0.004\"], [\"70203.60\", \"0.041\"], [\"70208.40\", \"0.092\"], [\"70210.00\", \"3.019\"], [\"70213.40\", \"0.006\"], [\"70213.50\", \"1.159\"], [\"70214.00\", \"0.045\"], [\"70218.50\", \"0.369\"], [\"70220.30\", \"0.078\"], [\"70224.90\", \"0.246\"], [\"70235.10\", \"0.092\"], [\"70242.40\", \"0.130\"], [\"70245.50\", \"0.045\"], [\"70250.40\", \"0.083\"], [\"70259.00\", \"1.309\"], [\"70262.30\", \"0.194\"], [\"70262.50\", \"0.856\"], [\"70263.20\", \"1.332\"], [\"70265.90\", \"0.002\"], [\"70274.80\", \"0.014\"], [\"70275.10\", \"2.874\"], [\"70275.20\", \"0.084\"], [\"70280.00\", \"1.427\"], [\"70280.20\", \"0.006\"], [\"70280.80\", \"0.000\"], [\"70281.10\", \"0.000\"], [\"70281.90\", \"0.004\"], [\"70282.50\", \"0.002\"], [\"70282.80\", \"0.663\"], [\"70283.60\", \"0.032\"], [\"70284.30\", \"0.003\"], [\"70284.60\", \"0.002\"], [\"70285.80\", \"0.375\"], [\"70289.20\", \"0.000\"], [\"70289.80\", \"0.010\"], [\"70290.10\", \"0.002\"], [\"70291.40\", \"0.057\"], [\"70291.80\", \"0.002\"], [\"70293.50\", \"0.041\"], [\"70294.10\", \"0.047\"], [\"70294.30\", \"0.219\"], [\"70294.40\", \"0.184\"], [\"70294.80\", \"0.344\"], [\"70295.30\", \"0.003\"], [\"70296.00\", \"0.009\"], [\"70296.70\", \"0.136\"], [\"70296.90\", \"0.405\"], [\"70297.40\", \"0.000\"], [\"70297.80\", \"0.000\"], [\"70299.80\", \"0.001\"], [\"70299.90\", \"0.049\"], [\"70300.00\", \"2.481\"], [\"70300.10\", \"0.056\"], [\"70300.70\", \"0.000\"], [\"70301.10\", \"0.000\"], [\"70301.20\", \"0.000\"], [\"70301.50\", \"0.000\"], [\"70301.70\", \"0.590\"], [\"70301.90\", \"0.004\"], [\"70304.40\", \"0.434\"], [\"70305.40\", \"0.027\"], [\"70308.90\", \"0.603\"], [\"70309.70\", \"0.028\"], [\"70310.50\", \"0.000\"], [\"70310.70\", \"1.432\"], [\"70310.90\", \"0.004\"], [\"70313.20\", \"0.100\"], [\"70313.40\", \"0.018\"], [\"70314.40\", \"0.004\"], [\"70314.80\", \"0.024\"], [\"70315.30\", \"0.517\"], [\"70316.00\", \"0.342\"], [\"70316.10\", \"0.090\"], [\"70316.40\", \"0.001\"], [\"70316.50\", \"0.004\"], [\"70316.70\", \"0.007\"], [\"70317.00\", \"0.149\"], [\"70317.10\", \"0.053\"], [\"70317.80\", \"0.005\"], [\"70320.10\", \"0.112\"], [\"70320.30\", \"0.296\"], [\"70320.80\", \"0.005\"], [\"70321.20\", \"0.000\"], [\"70321.80\", \"0.633\"], [\"70322.30\", \"1.303\"], [\"70324.30\", \"0.000\"], [\"70324.80\", \"0.212\"], [\"70325.00\", \"0.252\"], [\"70326.00\", \"0.000\"], [\"70326.30\", \"0.596\"], [\"70327.20\", \"0.040\"], [\"70328.10\", \"0.002\"], [\"70328.20\", \"0.002\"], [\"70328.80\", \"0.004\"], [\"70328.90\", \"0.009\"], [\"70329.40\", \"0.003\"], [\"70329.90\", \"0.073\"], [\"70330.10\", \"1.072\"], [\"70330.90\", \"0.055\"], [\"70331.60\", \"0.517\"], [\"70332.70\", \"0.006\"], [\"70333.40\", \"0.384\"], [\"70334.60\", \"0.584\"], [\"70334.80\", \"0.670\"], [\"70335.00\", \"0.083\"], [\"70336.40\", \"0.006\"], [\"70336.60\", \"0.000\"], [\"70336.70\", \"0.006\"], [\"70336.80\", \"0.517\"], [\"70337.00\", \"0.010\"], [\"70337.10\", \"1.066\"], [\"70337.50\", \"0.001\"], [\"70338.50\", \"0.194\"], [\"70338.60\", \"0.003\"], [\"70338.70\", \"0.203\"], [\"70338.80\", \"0.015\"], [\"70338.90\", \"0.349\"], [\"70339.20\", \"0.939\"], [\"70339.40\", \"0.005\"], [\"70339.50\", \"0.002\"], [\"70339.70\", \"0.001\"], [\"70340.10\", \"0.007\"], [\"70340.20\", \"0.002\"], [\"70340.40\", \"0.004\"], [\"70340.70\", \"0.000\"], [\"70340.80\", \"0.003\"], [\"70340.90\", \"0.003\"], [\"70341.00\", \"0.413\"], [\"70341.20\", \"0.001\"], [\"70341.30\", \"0.004\"], [\"70341.80\", \"0.514\"], [\"70342.10\", \"0.002\"], [\"70342.30\", \"0.243\"], [\"70342.50\", \"0.089\"], [\"70342.60\", \"0.007\"], [\"70342.90\", \"0.377\"], [\"70343.00\", \"2.105\"], [\"70343.10\", \"0.005\"], [\"70343.50\", \"0.359\"], [\"70343.60\", \"0.109\"], [\"70343.70\", \"0.005\"], [\"70343.90\", \"0.000\"], [\"70344.00\", \"0.101\"], [\"70344.10\", \"0.518\"], [\"70344.30\", \"0.133\"], [\"70344.50\", \"1.208\"], [\"70344.90\", \"0.006\"], [\"70345.10\", \"0.000\"], [\"70346.10\", \"0.005\"], [\"70346.20\", \"0.561\"], [\"70346.30\", \"0.289\"], [\"70346.50\", \"0.216\"], [\"70347.40\", \"0.011\"], [\"70347.50\", \"0.144\"], [\"70347.60\", \"0.376\"], [\"70347.70\", \"0.058\"], [\"70348.00\", \"0.012\"], [\"70348.50\", \"0.203\"], [\"70348.70\", \"0.043\"], [\"70349.40\", \"0.008\"], [\"70349.80\", \"0.003\"], [\"70349.90\", \"1.359\"], [\"70350.00\", \"0.842\"], [\"70350.30\", \"0.001\"], [\"70350.60\", \"0.014\"], [\"70350.80\", \"0.006\"], [\"70351.10\", \"0.002\"], [\"70351.40\", \"0.086\"], [\"70351.60\", \"0.042\"], [\"70351.70\", \"0.091\"], [\"70351.80\", \"0.087\"], [\"70352.00\", \"0.093\"], [\"70352.10\", \"0.064\"], [\"70352.30\", \"0.004\"], [\"70352.40\", \"0.043\"], [\"70352.70\", \"0.383\"], [\"70352.80\", \"0.379\"], [\"70353.10\", \"0.037\"], [\"70353.30\", \"0.410\"], [\"70353.60\", \"0.000\"], [\"70354.00\", \"0.000\"], [\"70354.30\", \"0.302\"], [\"70354.60\", \"0.002\"], [\"70355.10\", \"0.002\"], [\"70355.20\", \"0.000\"], [\"70355.30\", \"0.002\"], [\"70355.80\", \"0.001\"], [\"70355.90\", \"0.003\"], [\"70356.00\", \"0.006\"], [\"70356.30\", \"0.205\"], [\"70356.50\", \"1.012\"], [\"70356.80\", \"0.214\"], [\"70356.90\", \"0.000\"], [\"70357.10\", \"0.000\"], [\"70357.30\", \"0.001\"], [\"70357.50\", \"0.006\"], [\"70357.60\", \"0.000\"], [\"70357.70\", \"0.000\"], [\"70357.90\", \"0.008\"], [\"70358.20\", \"0.003\"], [\"70358.30\", \"0.000\"], [\"70358.40\", \"0.402\"], [\"70358.80\", \"0.003\"], [\"70359.00\", \"0.000\"], [\"70359.50\", \"0.001\"], [\"70359.80\", \"0.107\"], [\"70359.90\", \"0.010\"], [\"70360.00\", \"0.004\"], [\"70360.10\", \"0.034\"], [\"70360.80\", \"0.004\"], [\"70361.40\", \"0.001\"], [\"70361.80\", \"0.020\"], [\"70362.10\", \"0.002\"], [\"70362.20\", \"0.001\"], [\"70362.70\", \"0.000\"], [\"70362.90\", \"0.001\"], [\"70363.10\", \"0.008\"], [\"70363.40\", \"0.000\"], [\"70363.80\", \"0.000\"], [\"70364.00\", \"0.007\"], [\"70364.40\", \"0.004\"], [\"70365.10\", \"0.008\"], [\"70365.20\", \"0.000\"], [\"70365.80\", \"0.000\"], [\"70365.90\", \"0.004\"], [\"70366.00\", \"0.001\"], [\"70366.30\", \"0.000\"], [\"70366.50\", \"0.002\"], [\"70367.00\", \"0.005\"], [\"70367.10\", \"0.329\"], [\"70367.20\", \"0.000\"], [\"70367.40\", \"0.000\"], [\"70367.50\", \"0.000\"], [\"70367.60\", \"0.000\"], [\"70368.10\", \"0.000\"], [\"70368.20\", \"0.000\"], [\"70368.30\", \"0.000\"], [\"70368.50\", \"0.000\"], [\"70368.60\", \"0.000\"], [\"70369.10\", \"0.000\"], [\"70369.40\", \"0.000\"], [\"70369.80\", \"0.000\"], [\"70370.00\", \"0.000\"], [\"70370.10\", \"0.000\"], [\"70370.40\", \"0.000\"]], \"a\": [[\"70367.20\", \"12.436\"], [\"70367.30\", \"0.001\"], [\"70367.50\", \"0.000\"], [\"70367.60\", \"0.000\"], [\"70367.70\", \"0.000\"], [\"70367.80\", \"0.002\"], [\"70368.10\", \"0.002\"], [\"70368.20\", \"0.026\"], [\"70368.30\", \"0.000\"], [\"70368.40\", \"0.103\"], [\"70368.50\", \"0.001\"], [\"70368.60\", \"0.000\"], [\"70368.70\", \"0.001\"], [\"70368.80\", \"0.001\"], [\"70369.00\", \"0.003\"], [\"70369.10\", \"0.000\"], [\"70369.20\", \"0.000\"], [\"70369.30\", \"0.002\"], [\"70369.50\", \"0.000\"], [\"70369.60\", \"0.003\"], [\"70369.70\", \"0.002\"], [\"70369.80\", \"0.002\"], [\"70369.90\", \"0.801\"], [\"70370.00\", \"0.003\"], [\"70370.10\", \"0.002\"], [\"70370.20\", \"1.313\"], [\"70370.30\", \"0.001\"], [\"70370.40\", \"0.012\"], [\"70370.50\", \"0.940\"], [\"70370.60\", \"0.003\"], [\"70370.70\", \"0.004\"], [\"70371.00\", \"0.002\"], [\"70371.10\", \"0.003\"], [\"70371.20\", \"0.004\"], [\"70371.90\", \"0.001\"], [\"70372.40\", \"0.016\"], [\"70372.90\", \"0.001\"], [\"70373.00\", \"0.004\"], [\"70373.10\", \"0.513\"], [\"70373.20\", \"0.400\"], [\"70373.40\", \"0.001\"], [\"70373.70\", \"0.003\"], [\"70373.80\", \"0.480\"], [\"70373.90\", \"0.804\"], [\"70374.00\", \"0.803\"], [\"70374.10\", \"0.641\"], [\"70374.20\", \"0.851\"], [\"70374.40\", \"0.004\"], [\"70374.50\", \"0.002\"], [\"70374.80\", \"0.003\"], [\"70374.90\", \"0.000\"], [\"70375.10\", \"0.000\"], [\"70375.20\", \"0.384\"], [\"70375.40\", \"0.001\"], [\"70375.50\", \"0.202\"], [\"70375.60\", \"0.048\"], [\"70375.70\", \"0.003\"], [\"70376.00\", \"0.004\"], [\"70376.10\", \"0.002\"], [\"70376.20\", \"0.000\"], [\"70376.30\", \"1.066\"], [\"70376.40\", \"0.262\"], [\"70376.50\", \"0.000\"], [\"70377.40\", \"0.001\"], [\"70377.60\", \"0.002\"], [\"70377.80\", \"0.052\"], [\"70377.90\", \"0.004\"], [\"70378.00\", \"0.004\"], [\"70378.10\", \"0.003\"], [\"70378.20\", \"0.002\"], [\"70378.30\", \"0.000\"], [\"70378.50\", \"0.004\"], [\"70378.60\", \"0.000\"], [\"70378.90\", \"0.000\"], [\"70379.20\", \"0.005\"], [\"70379.50\", \"0.003\"], [\"70379.60\", \"0.367\"], [\"70379.80\", \"0.075\"], [\"70379.90\", \"0.635\"], [\"70380.10\", \"0.005\"], [\"70380.40\", \"0.186\"], [\"70380.50\", \"0.004\"], [\"70380.60\", \"0.005\"], [\"70381.00\", \"0.076\"], [\"70381.10\", \"0.000\"], [\"70381.20\", \"0.001\"], [\"70381.40\", \"0.006\"], [\"70381.50\", \"0.445\"], [\"70381.60\", \"0.001\"], [\"70381.70\", \"0.000\"], [\"70381.80\", \"0.002\"], [\"70382.00\", \"1.100\"], [\"70382.10\", \"0.002\"], [\"70382.20\", \"0.000\"], [\"70382.30\", \"0.008\"], [\"70382.40\", \"0.258\"], [\"70382.90\", \"0.058\"], [\"70383.10\", \"0.027\"], [\"70383.50\", \"0.026\"], [\"70383.90\", \"0.027\"], [\"70384.20\", \"0.037\"], [\"70384.50\", \"0.005\"], [\"70384.80\", \"0.010\"], [\"70384.90\", \"0.324\"], [\"70385.00\", \"0.266\"], [\"70385.10\", \"0.005\"], [\"70385.20\", \"0.514\"], [\"70385.50\", \"0.175\"], [\"70387.10\", \"0.131\"], [\"70387.20\", \"0.062\"], [\"70387.70\", \"0.000\"], [\"70388.00\", \"0.119\"], [\"70388.10\", \"0.000\"], [\"70388.40\", \"0.005\"], [\"70388.70\", \"0.000\"], [\"70388.80\", \"0.002\"], [\"70389.50\", \"0.008\"], [\"70389.60\", \"0.527\"], [\"70389.80\", \"0.071\"], [\"70389.90\", \"0.008\"], [\"70390.30\", \"1.003\"], [\"70390.40\", \"0.003\"], [\"70391.00\", \"0.202\"], [\"70391.10\", \"0.007\"], [\"70391.30\", \"0.003\"], [\"70391.40\", \"0.002\"], [\"70391.60\", \"0.008\"], [\"70391.70\", \"0.051\"], [\"70391.80\", \"0.000\"], [\"70392.30\", \"0.010\"], [\"70393.90\", \"0.022\"], [\"70394.30\", \"0.002\"], [\"70394.60\", \"0.203\"], [\"70396.80\", \"0.000\"], [\"70397.60\", \"0.064\"], [\"70399.40\", \"0.042\"], [\"70400.00\", \"2.036\"], [\"70400.40\", \"0.007\"], [\"70400.50\", \"0.002\"], [\"70400.60\", \"0.585\"], [\"70400.80\", \"0.286\"], [\"70401.00\", \"0.613\"], [\"70401.20\", \"0.013\"], [\"70401.30\", \"0.006\"], [\"70401.90\", \"0.003\"], [\"70402.10\", \"0.520\"], [\"70402.40\", \"0.002\"], [\"70402.50\", \"0.003\"], [\"70402.80\", \"0.644\"], [\"70403.50\", \"0.003\"], [\"70405.00\", \"0.000\"], [\"70405.70\", \"0.006\"], [\"70405.80\", \"0.004\"], [\"70406.00\", \"0.004\"], [\"70406.10\", \"0.020\"], [\"70406.40\", \"0.003\"], [\"70407.10\", \"0.066\"], [\"70407.30\", \"0.003\"], [\"70407.80\", \"0.022\"], [\"70408.50\", \"0.000\"], [\"70409.20\", \"0.259\"], [\"70409.30\", \"0.003\"], [\"70409.40\", \"0.087\"], [\"70409.50\", \"0.093\"], [\"70409.70\", \"0.163\"], [\"70410.40\", \"0.000\"], [\"70410.60\", \"0.004\"], [\"70411.00\", \"0.006\"], [\"70411.60\", \"0.022\"], [\"70412.40\", \"0.024\"], [\"70412.90\", \"0.024\"], [\"70415.70\", \"0.002\"], [\"70415.90\", \"0.581\"], [\"70417.40\", \"0.051\"], [\"70419.30\", \"0.143\"], [\"70419.50\", \"0.003\"], [\"70419.60\", \"0.000\"], [\"70419.70\", \"0.337\"], [\"70419.90\", \"0.516\"], [\"70420.20\", \"0.000\"], [\"70420.70\", \"0.000\"], [\"70420.90\", \"0.099\"], [\"70421.50\", \"0.000\"], [\"70421.60\", \"0.004\"], [\"70421.90\", \"0.002\"], [\"70422.30\", \"0.128\"], [\"70422.60\", \"0.000\"], [\"70422.80\", \"0.002\"], [\"70422.90\", \"0.002\"], [\"70423.00\", \"0.019\"], [\"70423.20\", \"0.038\"], [\"70423.70\", \"0.601\"], [\"70425.90\", \"1.376\"], [\"70426.20\", \"0.027\"], [\"70426.70\", \"0.192\"], [\"70427.10\", \"0.445\"], [\"70428.90\", \"0.001\"], [\"70429.40\", \"0.000\"], [\"70429.80\", \"0.015\"], [\"70430.30\", \"0.000\"], [\"70431.20\", \"0.000\"], [\"70432.90\", \"0.010\"], [\"70433.80\", \"0.005\"], [\"70434.00\", \"0.006\"], [\"70434.70\", \"0.208\"], [\"70437.50\", \"0.670\"], [\"70437.60\", \"0.107\"], [\"70439.20\", \"0.009\"], [\"70440.80\", \"0.000\"], [\"70440.90\", \"1.212\"], [\"70441.00\", \"0.013\"], [\"70441.10\", \"0.056\"], [\"70443.40\", \"0.093\"], [\"70443.70\", \"0.080\"], [\"70444.10\", \"0.354\"], [\"70448.00\", \"0.054\"], [\"70448.10\", \"1.260\"], [\"70451.60\", \"0.170\"], [\"70451.80\", \"3.086\"], [\"70453.90\", \"0.100\"], [\"70454.30\", \"0.000\"], [\"70455.20\", \"0.071\"], [\"70456.30\", \"0.230\"], [\"70459.20\", \"0.244\"], [\"70459.50\", \"0.014\"], [\"70460.30\", \"0.002\"], [\"70462.10\", \"0.783\"], [\"70462.50\", \"0.041\"], [\"70464.60\", \"0.087\"], [\"70466.50\", \"0.189\"], [\"70466.60\", \"0.125\"], [\"70466.70\", \"0.133\"], [\"70467.00\", \"0.770\"], [\"70467.60\", \"0.178\"], [\"70467.70\", \"0.000\"], [\"70468.80\", \"0.000\"], [\"70473.40\", \"1.325\"], [\"70475.10\", \"7.974\"], [\"70483.80\", \"0.025\"], [\"70489.20\", \"0.041\"], [\"70491.40\", \"10.444\"], [\"70492.20\", \"0.000\"], [\"70495.50\", \"0.009\"], [\"70508.20\", \"0.092\"], [\"70509.30\", \"0.108\"], [\"70510.10\", \"0.095\"], [\"70510.30\", \"0.000\"], [\"70511.60\", \"0.474\"], [\"70512.20\", \"0.018\"], [\"70514.00\", \"0.092\"], [\"70516.90\", \"0.179\"], [\"70517.30\", \"0.382\"], [\"70523.00\", \"0.145\"], [\"70524.80\", \"0.027\"], [\"70526.40\", \"0.094\"], [\"70528.90\", \"0.220\"], [\"70536.70\", \"0.092\"], [\"70541.20\", \"6.509\"], [\"70541.40\", \"0.376\"], [\"70543.30\", \"3.436\"], [\"70544.90\", \"0.054\"], [\"70547.80\", \"0.102\"], [\"70559.50\", \"0.000\"], [\"70566.40\", \"2.065\"], [\"70584.70\", \"1.331\"], [\"70587.70\", \"0.396\"], [\"70589.80\", \"0.000\"], [\"70590.80\", \"0.000\"], [\"70597.50\", \"0.000\"], [\"70670.60\", \"0.199\"], [\"70671.20\", \"4.120\"], [\"70674.20\", \"0.000\"], [\"70679.40\", \"0.007\"], [\"70680.50\", \"0.000\"], [\"70681.10\", \"0.056\"], [\"70685.90\", \"0.000\"], [\"71072.10\", \"0.000\"], [\"71074.20\", \"0.000\"], [\"71367.20\", \"0.002\"], [\"71368.40\", \"0.854\"], [\"71368.60\", \"1.500\"], [\"71369.90\", \"0.234\"], [\"71370.20\", \"3.710\"], [\"71373.90\", \"0.624\"], [\"71380.00\", \"0.279\"], [\"71381.50\", \"0.000\"], [\"71382.10\", \"0.000\"], [\"71382.40\", \"2.925\"], [\"71384.00\", \"0.000\"], [\"71385.20\", \"0.000\"], [\"89523.20\", \"0.000\"], [\"100000.00\", \"15.487\"]]}", "symbol": "BTCUSDT"}
