{"event": "depthUpdate", "raw_payload": "{\"e\": \"depthUpdate\", \"E\": 1773246385968, \"T\": 1773246385967, \"s\": \"BTCUSDT\", \"U\": 10089703953200, \"u\": 10089703960357, \"pu\": 10089703953199, \"b\": [[\"1000.00\", \"26.792\"], [\"5000.00\", \"101.398\"], [\"19848.60\", \"0.970\"], [\"19861.30\", \"0.000\"], [\"19964.80\", \"0.160\"], [\"20048.60\", \"0.360\"], [\"20264.80\", \"0.290\"], [\"33000.00\", \"10.797\"], [\"55000.00\", \"210.789\"], [\"56000.00\", \"60.796\"], [\"63328.30\", \"0.005\"], [\"68544.60\", \"0.000\"], [\"69316.20\", \"0.000\"], [\"69661.20\", \"3.695\"], [\"69996.90\", \"0.000\"], [\"70118.60\", \"0.000\"], [\"70226.60\", \"0.012\"], [\"70232.10\", \"1.371\"], [\"70235.80\", \"0.042\"], [\"70236.40\", \"0.003\"], [\"70239.90\", \"0.008\"], [\"70247.50\", \"0.095\"], [\"70261.60\", \"0.000\"], [\"70271.00\", \"0.006\"], [\"70281.30\", \"0.003\"], [\"70282.10\", \"0.002\"], [\"70283.90\", \"0.002\"], [\"70287.20\", \"0.248\"], [\"70292.70\", \"0.023\"], [\"70296.20\", \"0.003\"], [\"70296.90\", \"0.260\"], [\"70306.20\", \"0.005\"], [\"70307.60\", \"0.065\"], [\"70308.40\", \"0.000\"], [\"70310.40\", \"0.004\"], [\"70311.10\", \"0.063\"], [\"70311.50\", \"1.072\"], [\"70314.20\", \"0.000\"], [\"70314.60\", \"0.050\"], [\"70314.90\", \"0.003\"], [\"70318.60\", \"0.000\"], [\"70318.80\", \"0.020\"], [\"70319.30\", \"0.085\"], [\"70320.80\", \"0.005\"], [\"70322.80\", \"0.073\"], [\"70324.30\", \"0.290\"], [\"70329.00\", \"0.010\"], [\"70330.50\", \"0.376\"], [\"70332.00\", \"0.000\"], [\"70332.60\", \"0.109\"], [\"70334.00\", \"0.000\"], [\"70336.70\", \"0.185\"], [\"70336.80\", \"0.000\"], [\"70337.20\", \"0.016\"], [\"70340.60\", \"0.083\"], [\"70341.70\", \"0.261\"], [\"70341.90\", \"0.076\"], [\"70342.60\", \"0.379\"], [\"70344.70\", \"0.028\"], [\"70344.90\", \"0.033\"], [\"70346.30\", \"0.521\"], [\"70347.00\", \"0.048\"], [\"70347.10\", \"0.045\"], [\"70347.30\", \"0.040\"], [\"70347.40\", \"0.076\"], [\"70347.80\", \"0.058\"], [\"70348.10\", \"0.043\"], [\"70348.80\", \"0.037\"], [\"70349.20\", \"0.004\"], [\"70350.10\", \"0.039\"], [\"70350.20\", \"0.002\"], [\"70351.30\", \"0.005\"], [\"70353.50\", \"0.230\"], [\"70354.00\", \"0.205\"], [\"70354.20\", \"0.001\"], [\"70356.30\", \"0.006\"], [\"70356.60\", \"0.137\"], [\"70356.90\", \"0.001\"], [\"70358.10\", \"0.068\"], [\"70361.50\", \"0.006\"], [\"70362.70\", \"0.002\"], [\"70362.90\", \"0.000\"], [\"70364.40\", \"0.003\"], [\"70364.80\", \"7.465\"]], \"a\": [[\"70364.90\", \"0.611\"], [\"70365.00\", \"0.002\"], [\"70366.60\", \"0.002\"], [\"70366.70\", \"0.003\"], [\"70367.00\", \"0.008\"], [\"70368.70\", \"0.003\"], [\"70371.90\", \"0.028\"], [\"70372.00\", \"0.002\"], [\"70373.10\", \"0.071\"], [\"70373.90\", \"0.001\"], [\"70374.10\", \"0.000\"], [\"70376.20\", \"0.309\"], [\"70376.60\", \"0.002\"], [\"70377.00\", \"0.000\"], [\"70377.10\", \"0.000\"], [\"70377.20\", \"0.004\"], [\"70377.50\", \"0.057\"], [\"70378.50\", \"0.007\"], [\"70378.70\", \"0.000\"], [\"70378.80\", \"0.085\"], [\"70379.20\", \"0.025\"], [\"70379.60\", \"0.030\"], [\"70379.80\", \"0.237\"], [\"70380.00\", \"0.013\"], [\"70380.20\", \"0.066\"], [\"70380.50\", \"0.547\"], [\"70380.60\", \"0.039\"], [\"70381.20\", \"0.005\"], [\"70382.40\", \"0.016\"], [\"70382.80\", \"0.155\"], [\"70382.90\", \"0.050\"], [\"70384.30\", \"0.375\"], [\"70384.40\", \"0.189\"], [\"70385.30\", \"0.043\"], [\"70386.00\", \"0.002\"], [\"70388.50\", \"0.086\"], [\"70388.90\", \"0.034\"], [\"70389.50\", \"0.006\"], [\"70390.40\", \"0.001\"], [\"70392.80\", \"0.000\"], [\"70394.80\", \"0.194\"], [\"70394.90\", \"0.000\"], [\"70395.50\", \"0.015\"], [\"70395.60\", \"0.000\"], [\"70396.20\", \"0.014\"], [\"70396.30\", \"0.011\"], [\"70396.90\", \"0.005\"], [\"70397.00\", \"0.000\"], [\"70397.60\", \"0.067\"], [\"70397.70\", \"0.002\"], [\"70398.30\", \"0.313\"], [\"70398.40\", \"0.252\"], [\"70399.80\", \"0.002\"], [\"70400.00\", \"2.045\"], [\"70400.50\", \"0.474\"], [\"70401.30\", \"0.000\"], [\"70401.80\", \"0.000\"], [\"70401.90\", \"0.004\"], [\"70402.50\", \"0.061\"], [\"70402.60\", \"0.153\"], [\"70403.20\", \"0.002\"], [\"70403.30\", \"0.117\"], [\"70405.40\", \"0.005\"], [\"70405.90\", \"0.002\"], [\"70407.00\", \"0.004\"], [\"70407.90\", \"0.087\"], [\"70408.60\", \"0.098\"], [\"70409.30\", \"0.033\"], [\"70410.00\", \"0.011\"], [\"70410.60\", \"0.004\"], [\"70410.70\", \"0.059\"], [\"70411.00\", \"0.084\"], [\"70411.10\", \"0.002\"], [\"70411.40\", \"0.005\"], [\"70415.70\", \"0.002\"], [\"70416.40\", \"0.252\"], [\"70417.50\", \"0.002\"], [\"70418.50\", \"0.074\"], [\"70419.40\", \"0.111\"], [\"70420.20\", \"0.000\"], [\"70422.70\", \"0.004\"], [\"70423.00\", \"0.172\"], [\"70424.00\", \"0.006\"], [\"70425.00\", \"0.017\"], [\"70428.00\", \"0.002\"], [\"70428.90\", \"0.029\"], [\"70430.10\", \"0.049\"], [\"70431.00\", \"0.002\"], [\"70431.90\", \"0.079\"], [\"70432.50\", \"0.002\"], [\"70432.80\", \"0.002\"], [\"70433.60\", \"0.003\"], [\"70436.10\", \"0.101\"], [\"70440.50\", \"0.125\"], [\"70442.10\", \"0.004\"], [\"70443.30\", \"9.668\"], [\"70445.80\", \"0.455\"], [\"70451.70\", \"0.058\"], [\"70457.70\", \"0.002\"], [\"70459.50\", \"0.039\"], [\"70464.10\", \"2.008\"], [\"70470.40\", \"0.126\"], [\"70470.60\", \"0.252\"], [\"70477.60\", \"0.041\"], [\"70486.40\", \"0.084\"], [\"70487.00\", \"0.003\"], [\"70488.90\", \"0.002\"], [\"70489.90\", \"0.003\"], [\"70513.60\", \"0.203\"], [\"70528.90\", \"0.042\"], [\"70531.90\", \"0.081\"], [\"70534.00\", \"0.081\"], [\"70534.80\", \"0.002\"], [\"70537.20\", \"0.081\"], [\"70548.20\", \"0.004\"], [\"70568.10\", \"0.000\"], [\"70570.30\", \"0.000\"], [\"70583.50\", \"0.021\"], [\"70587.20\", \"0.006\"], [\"70598.20\", \"0.013\"], [\"70598.40\", \"0.041\"], [\"70896.70\", \"0.000\"], [\"71068.50\", \"0.064\"], [\"71697.90\", \"0.000\"], [\"71709.10\", \"0.696\"], [\"73891.40\", \"0.002\"], [\"73901.10\", \"0.008\"], [\"77401.40\", \"0.000\"]]}", "symbol": "BTCUSDT"}
{"event": "depthUpdate", "raw_payload": "{\"e\": \"depthUpdate\", \"E\": 1773246386070, \"T\": 1773246386069, \"s\": \"BTCUSDT\", \"U\": 10089703960369, \"u\": 10089703971397, \"pu\": 10089703960357, \"b\": [[\"1000.00\", \"26.792\"], [\"5000.00\", \"101.418\"], [\"19848.60\", \"0.880\"], [\"19855.60\", \"0.010\"], [\"19855.70\", \"0.000\"], [\"19861.10\", \"0.000\"], [\"19861.20\", \"0.000\"], [\"19964.80\", \"0.250\"], [\"20048.60\", \"0.270\"], [\"20264.80\", \"0.460\"], [\"33000.00\", \"10.793\"], [\"40000.00\", \"50.271\"], [\"56279.00\", \"0.045\"], [\"65051.60\", \"0.014\"], [\"66840.70\", \"0.002\"], [\"68241.30\", \"0.000\"], [\"69235.80\", \"0.002\"], [\"69354.60\", \"0.015\"], [\"69364.80\", \"0.291\"], [\"69597.80\", \"0.004\"], [\"69661.20\", \"3.695\"], [\"69847.20\", \"3.720\"], [\"70066.50\", \"0.031\"], [\"70132.30\", \"0.009\"], [\"70150.90\", \"0.002\"], [\"70152.90\", \"0.243\"], [\"70281.90\", \"0.787\"], [\"70291.50\", \"0.002\"], [\"70292.70\", \"0.071\"], [\"70293.00\", \"0.002\"], [\"70296.50\", \"0.207\"], [\"70299.40\", \"0.003\"], [\"70300.00\", \"1.453\"], [\"70302.90\", \"0.274\"], [\"70310.10\", \"0.100\"], [\"70310.50\", \"0.003\"], [\"70311.50\", \"1.070\"], [\"70311.80\", \"0.101\"], [\"70312.00\", \"0.010\"], [\"70315.00\", \"0.004\"], [\"70315.10\", \"0.002\"], [\"70315.20\", \"0.575\"], [\"70316.50\", \"0.004\"], [\"70316.70\", \"0.107\"], [\"70318.30\", \"0.423\"], [\"70318.90\", \"0.005\"], [\"70319.30\", \"0.000\"], [\"70319.40\", \"0.193\"], [\"70320.00\", \"0.135\"], [\"70322.00\", \"0.004\"], [\"70322.40\", \"0.015\"], [\"70324.30\", \"0.296\"], [\"70326.10\", \"0.044\"], [\"70326.20\", \"0.098\"], [\"70326.90\", \"0.000\"], [\"70327.50\", \"0.004\"], [\"70329.00\", \"0.010\"], [\"70329.40\", \"0.000\"], [\"70329.50\", \"0.025\"], [\"70330.80\", \"0.195\"], [\"70330.90\", \"0.392\"], [\"70331.10\", \"0.006\"], [\"70331.70\", \"0.002\"], [\"70332.20\", \"0.046\"], [\"70332.60\", \"0.062\"], [\"70333.50\", \"0.000\"], [\"70333.80\", \"0.011\"], [\"70333.90\", \"0.012\"], [\"70335.40\", \"0.250\"], [\"70336.00\", \"0.759\"], [\"70336.60\", \"0.515\"], [\"70337.30\", \"0.023\"], [\"70337.80\", \"0.212\"], [\"70338.40\", \"0.106\"], [\"70339.70\", \"0.000\"], [\"70340.20\", \"0.000\"], [\"70341.60\", \"1.667\"], [\"70341.80\", \"0.167\"], [\"70342.50\", \"0.005\"], [\"70343.30\", \"0.002\"], [\"70343.70\", \"0.007\"], [\"70343.80\", \"0.670\"], [\"70344.10\", \"0.007\"], [\"70344.30\", \"0.085\"], [\"70344.70\", \"0.000\"], [\"70344.90\", \"0.005\"], [\"70345.30\", \"0.484\"], [\"70345.90\", \"0.000\"], [\"70346.20\", \"0.175\"], [\"70346.90\", \"0.031\"], [\"70347.10\", \"0.073\"], [\"70347.20\", \"0.008\"], [\"70347.60\", \"0.000\"], [\"70347.70\", \"0.033\"], [\"70348.10\", \"0.045\"], [\"70348.20\", \"0.463\"], [\"70348.70\", \"0.073\"], [\"70348.80\", \"0.035\"], [\"70348.90\", \"0.257\"], [\"70349.00\", \"0.072\"], [\"70349.10\", \"0.050\"], [\"70349.20\", \"0.004\"], [\"70349.40\", \"0.037\"], [\"70349.60\", \"0.083\"], [\"70349.70\", \"0.033\"], [\"70349.80\", \"0.005\"], [\"70350.00\", \"1.074\"], [\"70350.10\", \"0.093\"], [\"70350.60\", \"0.014\"], [\"70350.70\", \"0.194\"], [\"70350.80\", \"0.010\"], [\"70350.90\", \"0.003\"], [\"70351.00\", \"0.077\"], [\"70351.10\", \"0.092\"], [\"70351.40\", \"0.015\"], [\"70351.50\", \"0.093\"], [\"70351.80\", \"0.094\"], [\"70351.90\", \"0.644\"], [\"70352.00\", \"0.043\"], [\"70352.30\", \"0.344\"], [\"70352.50\", \"0.003\"], [\"70352.90\", \"0.064\"], [\"70353.00\", \"0.544\"], [\"70353.20\", \"0.028\"], [\"70353.30\", \"0.090\"], [\"70353.50\", \"0.471\"], [\"70353.60\", \"0.003\"], [\"70353.90\", \"0.044\"], [\"70354.20\", \"1.208\"], [\"70354.30\", \"0.002\"], [\"70354.50\", \"0.015\"], [\"70354.60\", \"0.002\"], [\"70354.70\", \"0.003\"], [\"70355.50\", \"0.048\"], [\"70355.60\", \"0.003\"], [\"70355.70\", \"0.085\"], [\"70355.90\", \"0.098\"], [\"70356.50\", \"0.186\"], [\"70356.60\", \"0.320\"], [\"70356.80\", \"0.003\"], [\"70356.90\", \"0.011\"], [\"70357.00\", \"0.007\"], [\"70357.60\", \"0.206\"], [\"70357.80\", \"0.232\"], [\"70358.10\", \"0.112\"], [\"70358.90\", \"0.002\"], [\"70361.30\", \"0.008\"], [\"70361.40\", \"1.105\"], [\"70361.50\", \"0.192\"], [\"70361.60\", \"0.000\"], [\"70363.60\", \"0.004\"], [\"70364.70\", \"0.005\"], [\"70364.80\", \"8.906\"]], \"a\": [[\"70364.90\", \"0.037\"], [\"70365.10\", \"0.000\"], [\"70365.40\", \"0.002\"], [\"70366.60\", \"0.000\"], [\"70366.90\", \"0.003\"], [\"70367.00\", \"0.002\"], [\"70367.10\", \"0.009\"], [\"70368.10\", \"0.005\"], [\"70368.30\", \"0.000\"], [\"70369.90\", \"0.000\"], [\"70371.10\", \"0.000\"], [\"70371.30\", \"0.003\"], [\"70371.40\", \"0.000\"], [\"70371.50\", \"0.091\"], [\"70372.10\", \"0.003\"], [\"70372.30\", \"0.003\"], [\"70372.40\", \"0.344\"], [\"70372.60\", \"0.000\"], [\"70373.40\", \"0.007\"], [\"70373.50\", \"0.047\"], [\"70373.60\", \"0.003\"], [\"70374.10\", \"0.014\"], [\"70374.80\", \"0.311\"], [\"70375.00\", \"0.003\"], [\"70375.60\", \"0.003\"], [\"70375.80\", \"0.005\"], [\"70376.10\", \"0.002\"], [\"70376.80\", \"0.008\"], [\"70377.10\", \"0.007\"], [\"70377.40\", \"0.000\"], [\"70377.50\", \"0.003\"], [\"70377.60\", \"0.511\"], [\"70377.70\", \"1.066\"], [\"70377.80\", \"0.003\"], [\"70378.20\", \"0.261\"], [\"70378.80\", \"0.028\"], [\"70379.00\", \"0.001\"], [\"70379.50\", \"0.036\"], [\"70379.80\", \"0.748\"], [\"70380.20\", \"0.036\"], [\"70380.30\", \"0.025\"], [\"70380.50\", \"0.036\"], [\"70380.60\", \"0.183\"], [\"70382.30\", \"0.294\"], [\"70382.50\", \"0.004\"], [\"70382.70\", \"0.000\"], [\"70382.80\", \"0.270\"], [\"70383.30\", \"0.000\"], [\"70383.80\", \"0.030\"], [\"70384.00\", \"0.194\"], [\"70384.30\", \"0.000\"], [\"70384.60\", \"0.000\"], [\"70385.00\", \"0.036\"], [\"70385.30\", \"0.043\"], [\"70385.80\", \"0.004\"], [\"70386.30\", \"0.151\"], [\"70386.40\", \"0.111\"], [\"70386.60\", \"0.093\"], [\"70386.70\", \"0.000\"], [\"70386.90\", \"0.070\"], [\"70387.10\", \"0.003\"], [\"70387.20\", \"0.012\"], [\"70387.40\", \"0.215\"], [\"70388.30\", \"0.513\"], [\"70388.70\", \"0.000\"], [\"70388.90\", \"0.639\"], [\"70389.30\", \"0.002\"], [\"70389.60\", \"0.009\"], [\"70389.70\", \"0.005\"], [\"70389.80\", \"0.001\"], [\"70390.10\", \"0.060\"], [\"70390.30\", \"0.284\"], [\"70390.40\", \"0.004\"], [\"70390.60\", \"0.005\"], [\"70391.00\", \"0.008\"], [\"70391.10\", \"0.000\"], [\"70391.40\", \"0.003\"], [\"70391.60\", \"0.029\"], [\"70391.80\", \"0.002\"], [\"70392.00\", \"0.392\"], [\"70392.60\", \"0.012\"], [\"70392.70\", \"0.000\"], [\"70393.20\", \"0.005\"], [\"70393.80\", \"0.010\"], [\"70394.70\", \"0.007\"], [\"70395.80\", \"0.319\"], [\"70396.20\", \"0.005\"], [\"70396.30\", \"0.002\"], [\"70397.10\", \"0.511\"], [\"70397.60\", \"0.076\"], [\"70397.70\", \"0.011\"], [\"70398.30\", \"0.240\"], [\"70398.40\", \"0.250\"], [\"70398.70\", \"0.293\"], [\"70399.00\", \"0.002\"], [\"70399.10\", \"0.000\"], [\"70399.70\", \"0.006\"], [\"70399.80\", \"0.004\"], [\"70400.40\", \"0.007\"], [\"70400.50\", \"0.433\"], [\"70401.30\", \"0.071\"], [\"70401.90\", \"0.000\"], [\"70402.50\", \"0.113\"], [\"70402.60\", \"0.153\"], [\"70402.80\", \"0.084\"], [\"70403.00\", \"1.885\"], [\"70403.20\", \"0.000\"], [\"70403.30\", \"0.115\"], [\"70403.90\", \"0.002\"], [\"70404.00\", \"0.388\"], [\"70404.80\", \"0.208\"], [\"70406.00\", \"1.080\"], [\"70406.30\", \"0.000\"], [\"70408.90\", \"0.002\"], [\"70409.70\", \"0.113\"], [\"70409.80\", \"0.085\"], [\"70410.90\", \"0.022\"], [\"70412.10\", \"0.560\"], [\"70412.30\", \"0.082\"], [\"70413.00\", \"1.071\"], [\"70416.60\", \"0.006\"], [\"70416.80\", \"0.310\"], [\"70418.20\", \"0.008\"], [\"70418.80\", \"0.000\"], [\"70421.20\", \"0.111\"], [\"70421.90\", \"0.088\"], [\"70422.30\", \"1.002\"], [\"70422.90\", \"0.002\"], [\"70423.00\", \"0.019\"], [\"70423.90\", \"0.134\"], [\"70424.00\", \"0.134\"], [\"70424.80\", \"0.000\"], [\"70424.90\", \"0.004\"], [\"70425.40\", \"0.002\"], [\"70427.30\", \"0.200\"], [\"70429.70\", \"0.004\"], [\"70431.90\", \"0.000\"], [\"70432.20\", \"1.070\"], [\"70432.30\", \"0.002\"], [\"70434.60\", \"0.513\"], [\"70435.00\", \"0.192\"], [\"70435.30\", \"0.000\"], [\"70436.30\", \"1.507\"], [\"70436.90\", \"0.180\"], [\"70438.80\", \"0.002\"], [\"70443.30\", \"9.775\"], [\"70449.80\", \"0.133\"], [\"70465.90\", \"0.002\"], [\"70477.60\", \"0.066\"], [\"70487.50\", \"0.138\"], [\"70487.70\", \"0.014\"], [\"70540.80\", \"0.003\"], [\"70543.70\", \"0.000\"], [\"70545.60\", \"0.002\"], [\"70557.50\", \"0.022\"], [\"70560.90\", \"30.968\"], [\"70569.90\", \"0.288\"], [\"70583.30\", \"0.143\"], [\"70587.20\", \"0.000\"], [\"70597.20\", \"0.000\"], [\"70600.00\", \"13.891\"], [\"70604.40\", \"0.230\"], [\"70605.40\", \"2.573\"], [\"70606.50\", \"0.036\"], [\"70606.90\", \"0.033\"], [\"70882.60\", \"3.976\"], [\"71068.50\", \"0.064\"], [\"73891.40\", \"0.000\"], [\"89523.20\", \"0.006\"], [\"100000.00\", \"15.487\"]]}", "symbol": "BTCUSDT"}
{"event": "depthUpdate", "raw_payload": "{\"e\": \"depthUpdate\", \"E\": 1773246386172, \"T\": 1773246386170, \"s\": \"BTCUSDT\", \"U\": 10089703971408, \"u\": 10089703981923, \"pu\": 10089703971397, \"b\": [[\"5000.00\", \"101.418\"], [\"19848.60\", \"0.800\"], [\"19852.50\", \"0.190\"], [\"19853.40\", \"0.000\"], [\"19854.60\", \"0.000\"], [\"19854.80\", \"0.000\"], [\"19855.60\", \"0.000\"], [\"19964.80\", \"0.330\"], [\"20048.60\", \"0.190\"], [\"20264.80\", \"0.630\"], [\"66802.20\", \"0.000\"], [\"66804.00\", \"0.838\"], [\"66812.50\", \"0.011\"], [\"66841.90\", \"0.002\"], [\"69642.00\", \"0.050\"], [\"69782.60\", \"0.008\"], [\"69877.10\", \"0.000\"], [\"69971.50\", \"0.000\"], [\"69983.80\", \"0.012\"], [\"69991.50\", \"0.000\"], [\"70013.00\", \"0.091\"], [\"70052.30\", \"0.462\"], [\"70056.10\", \"0.000\"], [\"70059.40\", \"0.023\"], [\"70065.90\", \"0.000\"], [\"70079.20\", \"0.012\"], [\"70092.00\", \"0.002\"], [\"70151.40\", \"0.272\"], [\"70160.30\", \"0.000\"], [\"70174.60\", \"0.018\"], [\"70214.50\", \"0.002\"], [\"70235.60\", \"0.000\"], [\"70237.70\", \"0.096\"], [\"70241.80\", \"0.209\"], [\"70246.90\", \"0.002\"], [\"70263.80\", \"1.270\"], [\"70267.90\", \"0.041\"], [\"70270.00\", \"0.061\"], [\"70273.40\", \"0.524\"], [\"70274.00\", \"0.074\"], [\"70274.40\", \"0.000\"], [\"70275.00\", \"10.228\"], [\"70278.70\", \"0.144\"], [\"70281.10\", \"0.071\"], [\"70281.40\", \"1.002\"], [\"70282.00\", \"0.008\"], [\"70285.80\", \"0.150\"], [\"70285.90\", \"0.000\"], [\"70287.50\", \"0.004\"], [\"70288.10\", \"0.582\"], [\"70289.70\", \"0.154\"], [\"70292.40\", \"0.002\"], [\"70292.80\", \"0.146\"], [\"70297.00\", \"0.063\"], [\"70299.00\", \"0.213\"], [\"70300.20\", \"0.044\"], [\"70300.50\", \"1.094\"], [\"70302.90\", \"0.259\"], [\"70304.10\", \"0.126\"], [\"70306.10\", \"0.192\"], [\"70312.00\", \"0.008\"], [\"70312.60\", \"0.016\"], [\"70313.70\", \"0.007\"], [\"70315.10\", \"0.017\"], [\"70317.00\", \"0.028\"], [\"70319.50\", \"1.872\"], [\"70320.00\", \"0.050\"], [\"70320.20\", \"0.112\"], [\"70320.90\", \"0.570\"], [\"70322.80\", \"0.073\"], [\"70325.40\", \"0.649\"], [\"70326.10\", \"0.004\"], [\"70332.20\", \"0.003\"], [\"70332.70\", \"0.000\"], [\"70333.20\", \"2.127\"], [\"70333.80\", \"0.002\"], [\"70333.90\", \"0.003\"], [\"70334.50\", \"0.248\"], [\"70335.20\", \"0.356\"], [\"70335.30\", \"0.533\"], [\"70335.40\", \"0.002\"], [\"70335.70\", \"0.051\"], [\"70336.60\", \"0.621\"], [\"70336.70\", \"0.187\"], [\"70337.10\", \"0.006\"], [\"70339.00\", \"0.000\"], [\"70339.90\", \"0.000\"], [\"70341.00\", \"0.000\"], [\"70341.60\", \"1.627\"], [\"70341.90\", \"0.015\"], [\"70342.00\", \"0.061\"], [\"70342.10\", \"0.000\"], [\"70342.30\", \"0.053\"], [\"70342.50\", \"0.003\"], [\"70343.00\", \"0.004\"], [\"70343.80\", \"0.672\"], [\"70344.80\", \"0.004\"], [\"70345.10\", \"0.513\"], [\"70346.30\", \"0.521\"], [\"70347.20\", \"0.647\"], [\"70347.50\", \"0.002\"], [\"70348.80\", \"0.035\"], [\"70349.00\", \"0.583\"], [\"70350.00\", \"1.121\"], [\"70350.20\", \"0.002\"], [\"70350.40\", \"0.001\"], [\"70350.60\", \"0.050\"], [\"70350.70\", \"0.088\"], [\"70351.60\", \"0.085\"], [\"70351.70\", \"0.287\"], [\"70351.90\", \"0.005\"], [\"70355.70\", \"0.051\"], [\"70357.40\", \"0.000\"], [\"70359.80\", \"0.015\"], [\"70361.50\", \"0.181\"], [\"70364.80\", \"9.039\"]], \"a\": [[\"70367.00\", \"0.000\"], [\"70367.10\", \"0.008\"], [\"70367.20\", \"50.004\"], [\"70368.30\", \"0.000\"], [\"70373.10\", \"0.000\"], [\"70376.50\", \"0.006\"], [\"70378.20\", \"0.185\"], [\"70378.80\", \"0.003\"], [\"70379.20\", \"0.000\"], [\"70379.50\", \"0.000\"], [\"70379.60\", \"0.005\"], [\"70379.80\", \"0.712\"], [\"70380.20\", \"0.000\"], [\"70380.30\", \"0.000\"], [\"70380.50\", \"0.000\"], [\"70380.60\", \"0.003\"], [\"70382.80\", \"0.151\"], [\"70382.90\", \"0.000\"], [\"70384.00\", \"0.007\"], [\"70384.30\", \"0.072\"], [\"70385.70\", \"0.686\"], [\"70385.90\", \"0.000\"], [\"70386.60\", \"0.095\"], [\"70386.70\", \"0.375\"], [\"70386.80\", \"0.054\"], [\"70386.90\", \"0.113\"], [\"70388.90\", \"0.000\"], [\"70392.10\", \"0.005\"], [\"70392.20\", \"0.043\"], [\"70392.80\", \"0.248\"], [\"70395.80\", \"0.071\"], [\"70396.10\", \"0.005\"], [\"70396.60\", \"0.104\"], [\"70397.40\", \"0.093\"], [\"70397.60\", \"0.067\"], [\"70397.70\", \"0.002\"], [\"70398.30\", \"0.240\"], [\"70398.40\", \"0.250\"], [\"70399.00\", \"0.002\"], [\"70399.10\", \"0.000\"], [\"70399.70\", \"0.013\"], [\"70399.80\", \"0.011\"], [\"70400.40\", \"0.007\"], [\"70400.50\", \"0.433\"], [\"70401.10\", \"0.210\"], [\"70401.20\", \"0.006\"], [\"70401.30\", \"0.123\"], [\"70402.50\", \"0.061\"], [\"70402.60\", \"0.145\"], [\"70403.90\", \"0.000\"], [\"70404.00\", \"0.386\"], [\"70404.60\", \"10.229\"], [\"70404.70\", \"0.002\"], [\"70405.00\", \"0.022\"], [\"70405.30\", \"0.002\"], [\"70405.40\", \"0.005\"], [\"70405.80\", \"0.010\"], [\"70406.00\", \"1.082\"], [\"70406.10\", \"0.002\"], [\"70406.90\", \"0.002\"], [\"70411.00\", \"0.073\"], [\"70417.20\", \"0.004\"], [\"70420.00\", \"1.178\"], [\"70420.20\", \"0.005\"], [\"70421.50\", \"0.418\"], [\"70423.20\", \"0.005\"], [\"70423.60\", \"0.320\"], [\"70423.80\", \"0.002\"], [\"70423.90\", \"0.182\"], [\"70424.00\", \"0.006\"], [\"70426.70\", \"0.200\"], [\"70427.40\", \"0.030\"], [\"70430.90\", \"0.250\"], [\"70431.20\", \"0.000\"], [\"70433.10\", \"0.017\"], [\"70433.20\", \"0.372\"], [\"70435.10\", \"0.013\"], [\"70436.20\", \"0.008\"], [\"70436.40\", \"0.002\"], [\"70437.20\", \"0.047\"], [\"70439.90\", \"0.000\"], [\"70443.30\", \"9.768\"], [\"70443.70\", \"1.503\"], [\"70444.20\", \"0.592\"], [\"70446.90\", \"0.001\"], [\"70448.10\", \"1.397\"], [\"70448.70\", \"0.000\"], [\"70450.30\", \"0.084\"], [\"70451.30\", \"0.342\"], [\"70454.00\", \"0.124\"], [\"70455.10\", \"0.142\"], [\"70455.20\", \"0.010\"], [\"70456.70\", \"0.012\"], [\"70457.30\", \"0.115\"], [\"70462.20\", \"0.234\"], [\"70463.00\", \"0.090\"], [\"70463.70\", \"0.008\"], [\"70464.40\", \"0.073\"], [\"70470.80\", \"0.002\"], [\"70477.40\", \"0.005\"], [\"70482.90\", \"0.079\"], [\"70487.60\", \"0.055\"], [\"70487.70\", \"0.000\"], [\"70556.20\", \"0.011\"], [\"70564.70\", \"0.000\"], [\"70588.60\", \"0.036\"], [\"70610.00\", \"1.092\"], [\"70651.60\", \"0.211\"], [\"70713.10\", \"0.000\"], [\"70717.00\", \"0.002\"], [\"70727.00\", \"0.000\"], [\"70732.60\", \"0.002\"], [\"70747.00\", \"2.013\"], [\"70842.40\", \"0.017\"], [\"70937.80\", \"0.012\"], [\"71068.50\", \"0.064\"], [\"71314.70\", \"0.279\"], [\"71347.40\", \"0.282\"], [\"73878.60\", \"0.000\"], [\"89523.20\", \"0.000\"]]}", "symbol": "BTCUSDT"}
{"event": "depthUpdate", "raw_payload": "{\"e\": \"depthUpdate\", \"E\": 1773246386274, \"T\": 1773246386273, \"s\": \"BTCUSDT\", \"U\": 10089703982138, \"u\": 10089703992489, \"pu\": 10089703981923, \"b\": [[\"1000.00\", \"26.792\"], [\"5000.00\", \"101.418\"], [\"19848.60\", \"0.710\"], [\"19852.50\", \"0.110\"], [\"19964.80\", \"0.370\"], [\"19967.10\", \"0.050\"], [\"20048.60\", \"0.100\"], [\"20264.80\", \"0.710\"], [\"20266.10\", \"0.010\"], [\"20267.10\", \"0.080\"], [\"69353.40\", \"0.000\"], [\"69354.40\", \"0.289\"], [\"69354.60\", \"0.003\"], [\"69354.90\", \"0.870\"], [\"69365.90\", \"0.012\"], [\"69366.10\", \"0.724\"], [\"69367.10\", \"0.002\"], [\"69661.20\", \"3.695\"], [\"69663.40\", \"0.000\"], [\"69846.50\", \"0.000\"], [\"69847.20\", \"0.000\"], [\"70013.00\", \"0.091\"], [\"70055.90\", \"0.004\"], [\"70060.60\", \"0.000\"], [\"70070.10\", \"0.000\"], [\"70118.60\", \"0.036\"], [\"70150.90\", \"0.045\"], [\"70152.80\", \"0.049\"], [\"70195.80\", \"0.001\"], [\"70203.50\", \"0.000\"], [\"70216.70\", \"0.006\"], [\"70225.20\", \"0.000\"], [\"70227.00\", \"0.394\"], [\"70234.10\", \"0.000\"], [\"70237.80\", \"0.000\"], [\"70240.40\", \"2.000\"], [\"70248.30\", \"4.064\"], [\"70253.30\", \"0.000\"], [\"70261.20\", \"0.002\"], [\"70266.70\", \"0.000\"], [\"70267.40\", \"0.282\"], [\"70268.40\", \"0.635\"], [\"70268.60\", \"2.000\"], [\"70268.70\", \"0.256\"], [\"70268.80\", \"0.034\"], [\"70272.50\", \"0.000\"], [\"70272.70\", \"0.110\"], [\"70278.50\", \"0.058\"], [\"70279.10\", \"0.498\"], [\"70279.80\", \"0.103\"], [\"70281.40\", \"0.000\"], [\"70281.90\", \"0.108\"], [\"70282.70\", \"1.500\"], [\"70284.00\", \"0.047\"], [\"70286.20\", \"0.097\"], [\"70287.20\", \"0.245\"], [\"70287.40\", \"0.013\"], [\"70292.70\", \"0.023\"], [\"70293.70\", \"0.018\"], [\"70294.00\", \"0.790\"], [\"70294.20\", \"0.651\"], [\"70295.50\", \"0.539\"], [\"70296.70\", \"1.002\"], [\"70296.80\", \"0.009\"], [\"70302.60\", \"0.063\"], [\"70307.30\", \"0.232\"], [\"70309.60\", \"0.191\"], [\"70310.30\", \"10.231\"], [\"70310.80\", \"0.005\"], [\"70312.40\", \"0.002\"], [\"70312.50\", \"0.006\"], [\"70312.60\", \"0.014\"], [\"70312.90\", \"1.006\"], [\"70314.80\", \"0.002\"], [\"70317.80\", \"0.004\"], [\"70318.40\", \"0.005\"], [\"70319.40\", \"0.193\"], [\"70319.50\", \"1.875\"], [\"70319.90\", \"0.002\"], [\"70320.00\", \"0.044\"], [\"70320.10\", \"0.115\"], [\"70320.20\", \"0.027\"], [\"70320.30\", \"0.256\"], [\"70320.70\", \"0.796\"], [\"70320.90\", \"0.001\"], [\"70321.20\", \"0.000\"], [\"70321.30\", \"0.023\"], [\"70322.50\", \"0.002\"], [\"70322.60\", \"0.021\"], [\"70322.80\", \"0.003\"], [\"70324.20\", \"0.497\"], [\"70324.80\", \"0.784\"], [\"70324.90\", \"0.056\"], [\"70325.50\", \"0.096\"], [\"70325.90\", \"0.000\"], [\"70326.20\", \"0.098\"], [\"70328.70\", \"0.042\"], [\"70330.00\", \"0.086\"], [\"70330.90\", \"0.389\"], [\"70331.10\", \"0.002\"], [\"70333.20\", \"2.087\"], [\"70333.30\", \"0.011\"], [\"70334.90\", \"0.002\"], [\"70335.20\", \"0.353\"], [\"70335.30\", \"0.647\"], [\"70335.90\", \"1.072\"], [\"70336.00\", \"0.759\"], [\"70336.10\", \"0.004\"], [\"70336.60\", \"0.303\"], [\"70336.70\", \"0.390\"], [\"70337.60\", \"0.024\"], [\"70338.30\", \"0.014\"], [\"70338.90\", \"0.831\"], [\"70340.30\", \"0.001\"], [\"70340.60\", \"0.003\"], [\"70341.60\", \"1.584\"], [\"70341.90\", \"0.001\"], [\"70342.70\", \"0.000\"], [\"70343.70\", \"0.005\"], [\"70343.80\", \"0.625\"], [\"70344.00\", \"0.071\"], [\"70344.50\", \"0.000\"], [\"70344.80\", \"0.004\"], [\"70345.00\", \"0.209\"], [\"70345.90\", \"0.641\"], [\"70346.70\", \"0.000\"], [\"70347.00\", \"0.005\"], [\"70347.20\", \"0.008\"], [\"70347.30\", \"0.036\"], [\"70347.70\", \"0.036\"], [\"70348.30\", \"0.089\"], [\"70348.70\", \"0.071\"], [\"70348.80\", \"0.000\"], [\"70349.20\", \"0.006\"], [\"70349.40\", \"0.008\"], [\"70349.50\", \"0.006\"], [\"70349.70\", \"0.035\"], [\"70350.40\", \"0.000\"], [\"70350.60\", \"0.036\"], [\"70350.90\", \"0.001\"], [\"70351.20\", \"0.091\"], [\"70351.40\", \"0.051\"], [\"70351.50\", \"0.042\"], [\"70351.60\", \"0.121\"], [\"70351.80\", \"0.092\"], [\"70351.90\", \"0.062\"], [\"70352.10\", \"0.001\"], [\"70352.20\", \"0.046\"], [\"70352.50\", \"0.002\"], [\"70352.70\", \"1.207\"], [\"70352.90\", \"0.099\"], [\"70353.50\", \"0.678\"], [\"70354.20\", \"0.008\"], [\"70354.40\", \"0.000\"], [\"70354.50\", \"0.005\"], [\"70354.90\", \"0.003\"], [\"70355.20\", \"0.001\"], [\"70355.60\", \"0.002\"], [\"70356.00\", \"0.144\"], [\"70356.50\", \"0.182\"], [\"70356.60\", \"0.188\"], [\"70356.70\", \"0.002\"], [\"70356.80\", \"0.000\"], [\"70356.90\", \"0.001\"], [\"70357.00\", \"0.007\"], [\"70357.10\", \"0.003\"], [\"70357.20\", \"0.001\"], [\"70357.30\", \"0.000\"], [\"70357.70\", \"0.058\"], [\"70357.80\", \"0.090\"], [\"70358.00\", \"0.000\"], [\"70358.10\", \"0.000\"], [\"70358.20\", \"0.004\"], [\"70358.40\", \"0.000\"], [\"70359.20\", \"0.094\"], [\"70359.40\", \"0.006\"], [\"70360.20\", \"0.004\"], [\"70360.30\", \"0.232\"], [\"70360.40\", \"0.109\"], [\"70360.90\", \"0.001\"], [\"70361.10\", \"0.002\"], [\"70361.20\", \"0.213\"], [\"70361.30\", \"0.005\"], [\"70361.60\", \"0.002\"], [\"70361.70\", \"0.001\"], [\"70362.50\", \"0.004\"], [\"70362.60\", \"0.144\"], [\"70362.70\", \"0.000\"], [\"70364.70\", \"0.008\"], [\"70364.80\", \"0.721\"], [\"70364.90\", \"1.286\"], [\"70365.00\", \"0.006\"], [\"70365.20\", \"0.000\"], [\"70365.30\", \"0.000\"], [\"70365.40\", \"0.003\"], [\"70365.60\", \"0.002\"], [\"70365.80\", \"0.001\"], [\"70365.90\", \"0.004\"], [\"70366.00\", \"1.101\"], [\"70366.10\", \"0.034\"], [\"70366.20\", \"0.002\"], [\"70366.30\", \"0.000\"], [\"70366.40\", \"0.002\"], [\"70366.60\", \"0.000\"], [\"70366.80\", \"0.000\"], [\"70367.00\", \"0.001\"], [\"70367.10\", \"10.796\"]], \"a\": [[\"70364.90\", \"0.000\"], [\"70365.00\", \"0.000\"], [\"70365.30\", \"0.000\"], [\"70365.40\", \"0.000\"], [\"70365.70\", \"0.000\"], [\"70366.00\", \"0.000\"], [\"70366.20\", \"0.000\"], [\"70366.30\", \"0.000\"], [\"70366.40\", \"0.000\"], [\"70366.50\", \"0.000\"], [\"70366.70\", \"0.000\"], [\"70366.90\", \"0.000\"], [\"70367.10\", \"0.000\"], [\"70367.20\", \"50.011\"], [\"70367.40\", \"0.004\"], [\"70367.60\", \"0.002\"], [\"70367.80\", \"0.002\"], [\"70368.10\", \"0.004\"], [\"70368.20\", \"0.002\"], [\"70368.30\", \"0.025\"], [\"70368.40\", \"0.099\"], [\"70368.60\", \"0.003\"], [\"70368.70\", \"0.000\"], [\"70368.90\", \"0.006\"], [\"70369.00\", \"0.002\"], [\"70369.50\", \"0.000\"], [\"70369.70\", \"0.003\"], [\"70370.70\", \"0.000\"], [\"70371.90\", \"0.000\"], [\"70372.30\", \"0.005\"], [\"70372.40\", \"0.342\"], [\"70373.50\", \"0.000\"], [\"70374.70\", \"0.001\"], [\"70375.40\", \"0.076\"], [\"70375.50\", \"0.001\"], [\"70375.80\", \"0.052\"], [\"70376.20\", \"0.110\"], [\"70376.30\", \"0.001\"], [\"70376.60\", \"0.002\"], [\"70377.30\", \"0.006\"], [\"70377.80\", \"0.006\"], [\"70378.00\", \"0.005\"], [\"70378.80\", \"0.004\"], [\"70379.40\", \"0.003\"], [\"70379.50\", \"0.001\"], [\"70380.70\", \"0.004\"], [\"70382.40\", \"0.010\"], [\"70382.50\", \"0.002\"], [\"70382.60\", \"0.005\"], [\"70382.90\", \"0.025\"], [\"70383.20\", \"0.026\"], [\"70383.70\", \"0.027\"], [\"70383.90\", \"0.037\"], [\"70384.30\", \"0.108\"], [\"70384.50\", \"0.002\"], [\"70384.60\", \"0.036\"], [\"70384.70\", \"0.567\"], [\"70384.80\", \"0.004\"], [\"70385.40\", \"0.007\"], [\"70386.40\", \"0.000\"], [\"70386.60\", \"0.092\"], [\"70386.90\", \"0.104\"], [\"70387.00\", \"0.054\"], [\"70387.20\", \"0.014\"], [\"70387.50\", \"0.390\"], [\"70387.60\", \"0.193\"], [\"70388.20\", \"0.006\"], [\"70389.10\", \"0.071\"], [\"70389.30\", \"0.000\"], [\"70389.60\", \"0.007\"], [\"70390.10\", \"0.025\"], [\"70391.00\", \"0.008\"], [\"70391.80\", \"0.002\"], [\"70392.80\", \"0.000\"], [\"70392.90\", \"0.888\"], [\"70393.00\", \"0.348\"], [\"70393.80\", \"0.003\"], [\"70394.10\", \"0.000\"], [\"70394.60\", \"0.043\"], [\"70395.70\", \"0.248\"], [\"70395.80\", \"0.071\"], [\"70396.50\", \"0.007\"], [\"70396.60\", \"0.002\"], [\"70396.80\", \"0.001\"], [\"70398.80\", \"0.005\"], [\"70399.00\", \"0.011\"], [\"70399.10\", \"0.009\"], [\"70399.70\", \"0.004\"], [\"70399.80\", \"0.002\"], [\"70400.00\", \"2.033\"], [\"70401.10\", \"0.208\"], [\"70401.70\", \"0.002\"], [\"70402.70\", \"0.002\"], [\"70404.30\", \"0.071\"], [\"70408.20\", \"0.586\"], [\"70409.40\", \"0.002\"], [\"70411.00\", \"0.000\"], [\"70411.10\", \"0.075\"], [\"70412.10\", \"0.511\"], [\"70412.30\", \"0.085\"], [\"70413.00\", \"1.074\"], [\"70413.90\", \"0.015\"], [\"70414.90\", \"0.048\"], [\"70416.50\", \"0.770\"], [\"70417.40\", \"0.018\"], [\"70419.10\", \"0.006\"], [\"70421.30\", \"0.005\"], [\"70422.30\", \"0.000\"], [\"70423.50\", \"0.002\"], [\"70423.60\", \"0.192\"], [\"70423.80\", \"0.130\"], [\"70424.20\", \"0.000\"], [\"70425.20\", \"0.005\"], [\"70427.80\", \"0.194\"], [\"70428.90\", \"0.001\"], [\"70431.40\", \"0.754\"], [\"70433.80\", \"0.000\"], [\"70434.00\", \"0.006\"], [\"70434.50\", \"0.554\"], [\"70435.50\", \"0.001\"], [\"70436.10\", \"0.006\"], [\"70436.20\", \"0.005\"], [\"70436.30\", \"0.007\"], [\"70437.50\", \"0.911\"], [\"70437.60\", \"1.155\"], [\"70438.00\", \"0.004\"], [\"70439.30\", \"0.512\"], [\"70439.90\", \"0.102\"], [\"70441.50\", \"0.001\"], [\"70444.50\", \"0.001\"], [\"70450.40\", \"0.000\"], [\"70451.60\", \"1.500\"], [\"70453.70\", \"0.000\"], [\"70459.40\", \"0.003\"], [\"70459.60\", \"0.005\"], [\"70460.40\", \"0.004\"], [\"70465.70\", \"2.000\"], [\"70476.50\", \"0.044\"], [\"70478.50\", \"0.017\"], [\"70480.00\", \"0.109\"], [\"70485.10\", \"0.232\"], [\"70489.20\", \"0.043\"], [\"70491.50\", \"0.000\"], [\"70493.20\", \"0.025\"], [\"70493.90\", \"2.000\"], [\"70508.10\", \"0.086\"], [\"70512.70\", \"6.614\"], [\"70513.90\", \"0.226\"], [\"70514.50\", \"0.455\"], [\"70516.20\", \"0.287\"], [\"70517.70\", \"0.086\"], [\"70520.00\", \"0.096\"], [\"70524.60\", \"0.095\"], [\"70538.10\", \"0.379\"], [\"70550.00\", \"1.472\"], [\"70559.70\", \"0.003\"], [\"70563.20\", \"0.013\"], [\"70597.20\", \"0.061\"], [\"70598.20\", \"0.063\"], [\"70599.90\", \"0.006\"], [\"70600.00\", \"13.885\"], [\"70604.30\", \"0.027\"], [\"70606.20\", \"0.047\"], [\"70632.50\", \"0.004\"], [\"70676.60\", \"0.036\"], [\"70743.90\", \"0.002\"], [\"70747.60\", \"0.049\"], [\"70754.40\", \"0.009\"], [\"70881.30\", \"0.000\"], [\"70882.60\", \"0.256\"], [\"70883.30\", \"0.000\"], [\"71068.40\", \"0.000\"], [\"71068.50\", \"0.064\"], [\"71070.90\", \"0.049\"], [\"72475.80\", \"0.000\"], [\"73885.10\", \"0.006\"], [\"73891.00\", \"0.002\"]]}", "symbol": "BTCUSDT"}
{"event": "depthUpdate", "raw_payload": "{\"e\": \"depthUpdate\", \"E\": 1773246386376, \"T\": 1773246386374, \"s\": \"BTCUSDT\", \"U\": 10089703992512, \"u\": 10089703998779, \"pu\": 10089703992489, \"b\": [[\"1000.00\", \"26.792\"], [\"5000.00\", \"101.418\"], [\"19848.60\", \"0.630\"], [\"19852.50\", \"0.020\"], [\"19967.10\", \"0.130\"], [\"20048.60\", \"0.020\"], [\"20267.10\", \"0.250\"], [\"56279.00\", \"0.045\"], [\"66818.80\", \"0.000\"], [\"68947.00\", \"0.009\"], [\"69245.40\", \"0.002\"], [\"69297.20\", \"0.114\"], [\"69804.20\", \"0.000\"], [\"69853.50\", \"0.000\"], [\"69854.20\", \"3.720\"], [\"70151.40\", \"0.315\"], [\"70162.80\", \"0.000\"], [\"70166.30\", \"0.000\"], [\"70201.30\", \"2.016\"], [\"70204.10\", \"0.000\"], [\"70227.90\", \"0.000\"], [\"70244.60\", \"0.130\"], [\"70289.70\", \"0.179\"], [\"70312.90\", \"1.004\"], [\"70314.90\", \"0.005\"], [\"70315.60\", \"0.191\"], [\"70317.70\", \"0.040\"], [\"70324.20\", \"0.491\"], [\"70325.30\", \"0.002\"], [\"70326.20\", \"0.000\"], [\"70328.40\", \"0.013\"], [\"70328.70\", \"0.002\"], [\"70330.60\", \"0.388\"], [\"70330.90\", \"0.000\"], [\"70331.40\", \"0.000\"], [\"70331.70\", \"0.250\"], [\"70333.30\", \"0.004\"], [\"70334.50\", \"0.000\"], [\"70334.80\", \"0.160\"], [\"70335.20\", \"0.344\"], [\"70335.30\", \"0.638\"], [\"70335.50\", \"0.005\"], [\"70335.90\", \"1.121\"], [\"70336.00\", \"0.768\"], [\"70337.60\", \"0.018\"], [\"70338.40\", \"0.000\"], [\"70340.10\", \"0.054\"], [\"70342.00\", \"0.009\"], [\"70342.40\", \"0.511\"], [\"70343.80\", \"0.589\"], [\"70344.00\", \"0.000\"], [\"70344.30\", \"0.724\"], [\"70344.70\", \"0.071\"], [\"70345.10\", \"0.002\"], [\"70345.90\", \"0.002\"], [\"70347.10\", \"0.030\"], [\"70347.40\", \"0.000\"], [\"70347.80\", \"0.000\"], [\"70348.10\", \"0.002\"], [\"70348.30\", \"0.009\"], [\"70348.40\", \"0.071\"], [\"70348.60\", \"0.008\"], [\"70349.90\", \"0.446\"], [\"70350.20\", \"0.009\"], [\"70351.90\", \"0.064\"], [\"70353.00\", \"0.537\"], [\"70353.50\", \"0.681\"], [\"70354.00\", \"0.207\"], [\"70356.00\", \"0.147\"], [\"70356.50\", \"0.182\"], [\"70356.60\", \"0.192\"], [\"70356.90\", \"0.114\"], [\"70357.30\", \"0.003\"], [\"70359.40\", \"0.003\"], [\"70360.70\", \"0.014\"], [\"70360.90\", \"0.035\"], [\"70361.40\", \"1.105\"], [\"70361.50\", \"0.838\"], [\"70362.50\", \"0.002\"], [\"70362.60\", \"0.145\"], [\"70364.00\", \"0.003\"], [\"70364.40\", \"0.000\"], [\"70364.80\", \"0.066\"], [\"70364.90\", \"0.186\"], [\"70365.00\", \"0.008\"], [\"70365.60\", \"0.005\"], [\"70366.00\", \"0.001\"], [\"70366.10\", \"0.000\"], [\"70366.20\", \"0.000\"], [\"70367.10\", \"9.717\"]], \"a\": [[\"70367.20\", \"50.016\"], [\"70368.10\", \"0.006\"], [\"70368.20\", \"0.028\"], [\"70368.30\", \"0.000\"], [\"70372.00\", \"0.005\"], [\"70373.30\", \"0.003\"], [\"70374.20\", \"0.028\"], [\"70376.20\", \"0.120\"], [\"70377.70\", \"1.066\"], [\"70377.80\", \"0.006\"], [\"70378.40\", \"0.005\"], [\"70379.20\", \"0.003\"], [\"70379.80\", \"0.710\"], [\"70381.20\", \"0.003\"], [\"70382.50\", \"0.641\"], [\"70383.60\", \"1.314\"], [\"70384.00\", \"0.194\"], [\"70384.40\", \"0.214\"], [\"70384.60\", \"0.072\"], [\"70384.70\", \"0.675\"], [\"70385.70\", \"0.047\"], [\"70386.70\", \"0.002\"], [\"70386.90\", \"0.162\"], [\"70387.20\", \"0.004\"], [\"70387.40\", \"0.218\"], [\"70387.60\", \"0.380\"], [\"70388.50\", \"0.088\"], [\"70389.30\", \"0.375\"], [\"70389.50\", \"0.517\"], [\"70390.40\", \"0.001\"], [\"70390.80\", \"0.248\"], [\"70392.90\", \"0.514\"], [\"70395.70\", \"0.000\"], [\"70397.10\", \"0.000\"], [\"70397.70\", \"0.000\"], [\"70398.80\", \"0.009\"], [\"70398.90\", \"0.010\"], [\"70399.00\", \"0.002\"], [\"70399.10\", \"0.000\"], [\"70399.70\", \"0.013\"], [\"70399.80\", \"0.011\"], [\"70404.90\", \"0.853\"], [\"70411.00\", \"0.073\"], [\"70411.10\", \"0.002\"], [\"70420.70\", \"0.000\"], [\"70423.90\", \"0.146\"], [\"70424.60\", \"0.000\"], [\"70431.40\", \"0.757\"], [\"70432.70\", \"0.028\"], [\"70433.00\", \"0.006\"], [\"70433.30\", \"0.002\"], [\"70437.60\", \"1.053\"], [\"70441.10\", \"0.104\"], [\"70449.10\", \"0.195\"], [\"70495.70\", \"2.017\"], [\"70507.00\", \"0.013\"], [\"70513.90\", \"0.039\"], [\"70526.90\", \"0.127\"], [\"70528.20\", \"0.086\"], [\"70528.90\", \"0.128\"], [\"70529.70\", \"0.597\"], [\"70531.90\", \"0.167\"], [\"70563.20\", \"0.010\"], [\"70583.30\", \"0.085\"], [\"70598.00\", \"0.000\"], [\"70604.30\", \"0.002\"], [\"70606.20\", \"0.022\"], [\"70662.30\", \"0.042\"], [\"70880.00\", \"7.090\"], [\"70880.80\", \"0.007\"], [\"71070.90\", \"0.049\"], [\"73891.00\", \"0.000\"], [\"73896.00\", \"0.549\"], [\"89523.20\", \"0.000\"]]}", "symbol": "BTCUSDT"}
{"event": "depthUpdate", "raw_payload": "{\"e\": \"depthUpdate\", \"E\": 1773246386478, \"T\": 1773246386477, \"s\": \"BTCUSDT\", \"U\": 10089703998925, \"u\": 10089704005812, \"pu\": 10089703998779, \"b\": [[\"5000.00\", \"101.418\"], [\"19848.60\", \"0.510\"], [\"19849.30\", \"0.000\"], [\"19851.00\", \"0.000\"], [\"19852.20\", \"0.000\"], [\"19852.50\", \"0.000\"], [\"19867.10\", \"0.070\"], [\"19967.10\", \"0.080\"], [\"20048.60\", \"0.000\"], [\"20267.10\", \"0.420\"], [\"66840.70\", \"0.000\"], [\"67552.50\", \"0.004\"], [\"69382.00\", \"4.417\"], [\"69386.70\", \"4.676\"], [\"69663.40\", \"0.000\"], [\"70079.30\", \"0.009\"], [\"70120.50\", \"0.198\"], [\"70166.10\", \"0.116\"], [\"70185.60\", \"0.000\"], [\"70185.70\", \"0.005\"], [\"70189.00\", \"1.345\"], [\"70239.90\", \"0.005\"], [\"70245.30\", \"0.002\"], [\"70248.50\", \"1.597\"], [\"70273.40\", \"0.564\"], [\"70277.00\", \"0.100\"], [\"70296.20\", \"0.000\"], [\"70303.60\", \"0.007\"], [\"70303.70\", \"0.046\"], [\"70314.30\", \"0.711\"], [\"70314.90\", \"0.003\"], [\"70316.30\", \"0.000\"], [\"70316.80\", \"0.006\"], [\"70319.50\", \"0.005\"], [\"70320.70\", \"0.711\"], [\"70321.00\", \"0.041\"], [\"70321.30\", \"0.108\"], [\"70324.30\", \"0.293\"], [\"70335.20\", \"0.353\"], [\"70335.30\", \"0.647\"], [\"70335.90\", \"1.112\"], [\"70336.00\", \"0.759\"], [\"70347.30\", \"0.000\"], [\"70348.80\", \"0.002\"], [\"70356.50\", \"0.179\"], [\"70359.80\", \"0.000\"], [\"70363.00\", \"0.002\"], [\"70364.80\", \"0.005\"], [\"70367.10\", \"8.962\"]], \"a\": [[\"70367.20\", \"50.345\"], [\"70370.00\", \"0.002\"], [\"70377.80\", \"0.048\"], [\"70379.70\", \"0.003\"], [\"70381.10\", \"0.000\"], [\"70390.10\", \"0.005\"], [\"70393.60\", \"0.375\"], [\"70399.00\", \"0.011\"], [\"70399.10\", \"0.009\"], [\"70399.70\", \"0.004\"], [\"70399.80\", \"0.002\"], [\"70401.50\", \"0.530\"], [\"70405.40\", \"0.002\"], [\"70433.60\", \"0.000\"], [\"70435.00\", \"0.194\"], [\"70441.80\", \"0.002\"], [\"70444.30\", \"0.041\"], [\"70480.40\", \"0.127\"], [\"70485.30\", \"0.123\"], [\"70489.80\", \"0.044\"], [\"70489.90\", \"0.000\"], [\"70495.80\", \"0.044\"], [\"70504.90\", \"0.434\"], [\"70505.40\", \"0.203\"], [\"70597.20\", \"0.000\"], [\"70598.20\", \"0.013\"], [\"70604.40\", \"0.194\"], [\"70606.90\", \"0.008\"], [\"70617.70\", \"0.000\"], [\"70632.50\", \"0.006\"], [\"70662.30\", \"0.006\"], [\"71633.70\", \"0.017\"], [\"72000.00\", \"246.199\"], [\"73895.40\", \"0.002\"]]}", "symbol": "BTCUSDT"}
{"event": "depthUpdate", "raw_payload": "{\"e\": \"depthUpdate\", \"E\": 1773246386580, \"T\": 1773246386578, \"s\": \"BTCUSDT\", \"U\": 10089704005943, \"u\": 10089704012816, \"pu\": 10089704005812, \"b\": [[\"1000.00\", \"26.792\"], [\"5000.00\", \"101.438\"], [\"19848.60\", \"0.360\"], [\"19867.10\", \"0.150\"], [\"19967.10\", \"0.000\"], [\"20167.10\", \"0.020\"], [\"20267.10\", \"0.550\"], [\"66823.20\", \"0.000\"], [\"69258.20\", \"1.658\"], [\"69297.30\", \"3.739\"], [\"69663.40\", \"0.000\"], [\"69854.20\", \"0.000\"], [\"70013.00\", \"0.091\"], [\"70079.30\", \"0.002\"], [\"70196.60\", \"36.668\"], [\"70242.20\", \"0.086\"], [\"70259.00\", \"9.350\"], [\"70276.90\", \"0.431\"], [\"70279.10\", \"0.447\"], [\"70280.60\", \"0.042\"], [\"70291.50\", \"0.045\"], [\"70292.50\", \"0.035\"], [\"70297.00\", \"3.695\"], [\"70298.50\", \"0.003\"], [\"70307.30\", \"0.218\"], [\"70314.00\", \"0.004\"], [\"70314.30\", \"0.709\"], [\"70320.80\", \"1.955\"], [\"70321.30\", \"0.108\"], [\"70321.40\", \"0.205\"], [\"70324.30\", \"0.287\"], [\"70326.60\", \"0.003\"], [\"70327.50\", \"0.002\"], [\"70327.60\", \"0.000\"], [\"70335.30\", \"0.641\"], [\"70337.30\", \"0.025\"], [\"70337.40\", \"0.018\"], [\"70353.20\", \"0.028\"], [\"70360.20\", \"0.004\"], [\"70364.80\", \"0.003\"], [\"70366.40\", \"0.004\"], [\"70367.10\", \"8.964\"]], \"a\": [[\"70367.20\", \"50.020\"], [\"70387.40\", \"0.215\"], [\"70388.70\", \"0.003\"], [\"70391.90\", \"1.385\"], [\"70407.70\", \"0.008\"], [\"70412.00\", \"1.921\"], [\"70423.80\", \"0.002\"], [\"70424.00\", \"0.006\"], [\"70424.30\", \"0.130\"], [\"70435.70\", \"3.588\"], [\"70435.90\", \"0.159\"], [\"70449.80\", \"0.090\"], [\"70472.60\", \"1.384\"], [\"70473.70\", \"7.041\"], [\"70492.20\", \"2.003\"], [\"70502.40\", \"0.002\"], [\"70509.40\", \"0.000\"], [\"70515.50\", \"0.007\"], [\"70516.40\", \"0.002\"], [\"70522.50\", \"0.007\"], [\"70523.40\", \"0.002\"], [\"70529.50\", \"1.357\"], [\"70530.40\", \"0.002\"], [\"70535.80\", \"2.657\"], [\"70536.30\", \"12.871\"], [\"70536.50\", \"0.007\"], [\"70537.40\", \"0.083\"], [\"70543.50\", \"0.007\"], [\"70543.70\", \"0.025\"], [\"70544.40\", \"0.038\"], [\"70545.60\", \"0.038\"], [\"70550.50\", \"0.007\"], [\"70551.40\", \"0.001\"], [\"70557.50\", \"0.029\"], [\"70564.50\", \"0.007\"], [\"70880.00\", \"3.370\"], [\"70881.70\", \"3.790\"], [\"71470.70\", \"0.000\"], [\"73181.80\", \"0.004\"], [\"73910.70\", \"0.002\"], [\"89523.20\", \"0.000\"]]}", "symbol": "BTCUSDT"}
{"event": "depthUpdate", "raw_payload": "{\"e\": \"depthUpdate\", \"E\": 1773246386682, \"T\": 1773246386680, \"s\": \"BTCUSDT\", \"U\": 10089704012940, \"u\": 10089704018418, \"pu\": 10089704012816, \"b\": [[\"1000.00\", \"26.792\"], [\"5000.00\", \"101.418\"], [\"19848.60\", \"0.280\"], [\"19867.10\", \"0.240\"], [\"19964.80\", \"0.280\"], [\"20167.10\", \"0.110\"], [\"20267.10\", \"0.540\"], [\"33000.00\", \"10.797\"], [\"40000.00\", \"50.458\"], [\"56294.00\", \"0.000\"], [\"66833.00\", \"0.064\"], [\"66848.00\", \"0.004\"], [\"67552.50\", \"0.006\"], [\"69297.30\", \"3.732\"], [\"69421.60\", \"0.015\"], [\"69522.00\", \"0.065\"], [\"69663.40\", \"0.000\"], [\"69853.60\", \"0.000\"], [\"69855.80\", \"3.720\"], [\"70098.20\", \"0.004\"], [\"70259.00\", \"9.344\"], [\"70259.10\", \"0.128\"], [\"70320.50\", \"0.000\"], [\"70321.30\", \"0.023\"], [\"70321.40\", \"0.205\"], [\"70321.50\", \"0.097\"], [\"70329.60\", \"0.004\"], [\"70329.70\", \"0.009\"], [\"70337.20\", \"0.030\"], [\"70340.10\", \"0.056\"], [\"70340.20\", \"0.002\"], [\"70348.20\", \"0.003\"], [\"70351.00\", \"0.045\"], [\"70351.10\", \"0.066\"], [\"70351.40\", \"0.037\"], [\"70352.00\", \"0.000\"], [\"70353.30\", \"0.000\"], [\"70355.50\", \"0.001\"], [\"70355.90\", \"0.001\"], [\"70356.70\", \"0.000\"], [\"70359.60\", \"0.005\"], [\"70367.10\", \"8.806\"]], \"a\": [[\"70370.00\", \"0.002\"], [\"70377.10\", \"0.000\"], [\"70399.90\", \"0.007\"], [\"70424.10\", \"0.225\"], [\"70424.30\", \"0.002\"], [\"70435.50\", \"0.044\"], [\"70463.00\", \"0.088\"], [\"70471.90\", \"0.005\"], [\"70473.60\", \"0.011\"], [\"70480.50\", \"0.002\"], [\"70605.40\", \"2.537\"], [\"70676.60\", \"0.000\"], [\"70878.50\", \"3.760\"], [\"70881.70\", \"0.070\"], [\"71070.90\", \"0.049\"], [\"71120.50\", \"0.696\"], [\"73895.40\", \"0.000\"]]}", "symbol": "BTCUSDT"}
{"event": "depthUpdate", "raw_payload": "{\"e\": \"depthUpdate\", \"E\": 1773246386784, \"T\": 1773246386783, \"s\": \"BTCUSDT\", \"U\": 10089704018443, \"u\": 10089704022674, \"pu\": 10089704018418, \"b\": [[\"5000.00\", \"101.418\"], [\"19848.60\", \"0.190\"], [\"19867.10\", \"0.320\"], [\"19964.80\", \"0.200\"], [\"20167.10\", \"0.190\"], [\"20267.10\", \"0.550\"], [\"33000.00\", \"10.793\"], [\"40000.00\", \"50.271\"], [\"66833.00\", \"0.062\"], [\"66834.20\", \"0.004\"], [\"66836.80\", \"0.002\"], [\"69663.40\", \"0.000\"], [\"69849.30\", \"3.720\"], [\"69855.80\", \"0.000\"], [\"70015.30\", \"0.018\"], [\"70120.60\", \"0.007\"], [\"70152.70\", \"0.002\"], [\"70242.20\", \"0.086\"], [\"70294.00\", \"0.742\"], [\"70298.50\", \"0.003\"], [\"70306.30\", \"0.000\"], [\"70307.30\", \"0.303\"], [\"70310.60\", \"0.596\"], [\"70312.20\", \"0.004\"], [\"70313.50\", \"0.378\"], [\"70314.00\", \"0.002\"], [\"70321.80\", \"0.493\"], [\"70323.40\", \"0.234\"], [\"70323.50\", \"0.037\"], [\"70326.60\", \"0.003\"], [\"70327.60\", \"0.004\"], [\"70330.60\", \"0.972\"], [\"70331.50\", \"0.003\"], [\"70335.30\", \"0.645\"], [\"70345.50\", \"0.009\"], [\"70347.20\", \"0.001\"], [\"70348.30\", \"0.002\"], [\"70348.70\", \"0.531\"], [\"70349.50\", \"0.013\"], [\"70349.90\", \"0.098\"], [\"70350.00\", \"1.128\"], [\"70350.10\", \"0.124\"], [\"70351.70\", \"0.319\"], [\"70351.80\", \"0.118\"], [\"70352.00\", \"0.014\"], [\"70352.10\", \"0.015\"], [\"70352.20\", \"0.137\"], [\"70352.60\", \"0.229\"], [\"70352.80\", \"0.007\"], [\"70352.90\", \"0.101\"], [\"70354.00\", \"0.295\"], [\"70356.20\", \"0.047\"], [\"70356.60\", \"0.135\"], [\"70357.30\", \"0.100\"], [\"70360.70\", \"0.000\"], [\"70361.20\", \"0.208\"], [\"70361.70\", \"0.015\"], [\"70364.10\", \"0.003\"], [\"70367.00\", \"0.006\"], [\"70367.10\", \"8.807\"]], \"a\": [[\"70368.30\", \"0.002\"], [\"70371.20\", \"0.014\"], [\"70379.10\", \"0.005\"], [\"70384.90\", \"0.142\"], [\"70386.30\", \"0.009\"], [\"70391.20\", \"0.190\"], [\"70391.70\", \"0.035\"], [\"70393.30\", \"0.076\"], [\"70393.60\", \"0.377\"], [\"70394.50\", \"0.078\"], [\"70395.80\", \"0.000\"], [\"70401.30\", \"0.052\"], [\"70401.50\", \"0.044\"], [\"70407.70\", \"0.008\"], [\"70413.60\", \"0.049\"], [\"70420.50\", \"0.111\"], [\"70434.60\", \"0.590\"], [\"70435.90\", \"0.159\"], [\"70441.10\", \"0.002\"], [\"70492.20\", \"2.003\"], [\"70606.50\", \"0.000\"], [\"70878.50\", \"0.040\"], [\"70885.00\", \"4.141\"], [\"71070.90\", \"0.049\"], [\"71192.70\", \"0.561\"], [\"72000.00\", \"245.505\"], [\"89523.20\", \"0.000\"]]}", "symbol": "BTCUSDT"}
{"event": "depthUpdate", "raw_payload": "{\"e\": \"depthUpdate\", \"E\": 1773246386886, \"T\": 1773246386884, \"s\": \"BTCUSDT\", \"U\": 10089704022723, \"u\": 10089704027738, \"pu\": 10089704022674, \"b\": [[\"1000.00\", \"26.792\"], [\"5000.00\", \"101.418\"], [\"19848.60\", \"0.110\"], [\"19867.10\", \"0.410\"], [\"19964.80\", \"0.110\"], [\"20167.10\", \"0.280\"], [\"20266.10\", \"0.000\"], [\"20267.10\", \"0.550\"], [\"40000.00\", \"50.271\"], [\"63330.40\", \"0.002\"], [\"67534.70\", \"0.640\"], [\"69663.40\", \"0.000\"], [\"69849.30\", \"0.000\"], [\"69998.60\", \"0.000\"], [\"69999.10\", \"0.204\"], [\"70015.30\", \"0.008\"], [\"70075.70\", \"0.000\"], [\"70076.90\", \"0.360\"], [\"70098.30\", \"0.007\"], [\"70118.70\", \"0.000\"], [\"70120.60\", \"0.000\"], [\"70151.10\", \"0.012\"], [\"70157.40\", \"0.270\"], [\"70158.40\", \"8.559\"], [\"70216.80\", \"1.476\"], [\"70235.80\", \"0.039\"], [\"70236.50\", \"0.855\"], [\"70241.70\", \"0.003\"], [\"70243.10\", \"0.016\"], [\"70262.50\", \"1.860\"], [\"70297.10\", \"1.423\"], [\"70306.20\", \"0.002\"], [\"70312.10\", \"0.008\"], [\"70313.50\", \"0.376\"], [\"70314.30\", \"0.711\"], [\"70321.50\", \"0.097\"], [\"70321.60\", \"0.035\"], [\"70321.80\", \"0.812\"], [\"70322.20\", \"0.005\"], [\"70338.80\", \"0.002\"], [\"70341.80\", \"0.367\"], [\"70345.30\", \"0.000\"], [\"70346.60\", \"0.829\"], [\"70346.90\", \"0.003\"], [\"70347.10\", \"0.002\"], [\"70348.30\", \"0.030\"], [\"70348.50\", \"0.029\"], [\"70348.70\", \"0.531\"], [\"70350.10\", \"0.124\"], [\"70351.10\", \"0.002\"], [\"70351.70\", \"0.340\"], [\"70351.80\", \"0.161\"], [\"70352.00\", \"0.000\"], [\"70352.10\", \"0.015\"], [\"70352.20\", \"0.046\"], [\"70352.60\", \"0.229\"], [\"70353.20\", \"0.000\"], [\"70353.90\", \"0.072\"], [\"70354.00\", \"0.295\"], [\"70356.10\", \"0.047\"], [\"70356.20\", \"0.000\"], [\"70357.30\", \"0.100\"], [\"70357.90\", \"0.006\"], [\"70361.60\", \"0.004\"], [\"70362.10\", \"0.003\"], [\"70365.10\", \"0.002\"], [\"70367.10\", \"8.805\"]], \"a\": [[\"70369.80\", \"0.002\"], [\"70372.10\", \"0.051\"], [\"70379.10\", \"0.003\"], [\"70380.80\", \"0.075\"], [\"70381.80\", \"0.000\"], [\"70387.00\", \"0.057\"], [\"70392.80\", \"0.322\"], [\"70398.90\", \"0.112\"], [\"70416.40\", \"0.249\"], [\"70424.10\", \"0.097\"], [\"70424.20\", \"0.128\"], [\"70434.50\", \"0.971\"], [\"70457.50\", \"0.195\"], [\"70481.70\", \"0.080\"], [\"70501.90\", \"1.602\"], [\"70511.40\", \"2.982\"], [\"70538.60\", \"2.014\"], [\"70605.40\", \"2.501\"], [\"70609.10\", \"1.565\"], [\"70610.50\", \"0.000\"], [\"70611.40\", \"0.112\"], [\"70661.60\", \"1.759\"], [\"70686.00\", \"0.961\"], [\"70688.20\", \"0.000\"], [\"70873.70\", \"3.736\"], [\"70885.00\", \"0.421\"], [\"71070.90\", \"0.049\"], [\"71134.10\", \"0.701\"], [\"71357.00\", \"0.208\"], [\"73892.30\", \"0.010\"], [\"77403.90\", \"0.002\"]]}", "symbol": "BTCUSDT"}
{"event": "depthUpdate", "raw_payload": "{\"e\": \"depthUpdate\", \"E\": 1773246386988, \"T\": 1773246386984, \"s\": \"BTCUSDT\", \"U\": 10089704027844, \"u\": 10089704032415, \"pu\": 10089704027738, \"b\": [[\"1000.00\", \"26.792\"], [\"5000.00\", \"101.418\"], [\"19848.60\", \"0.020\"], [\"19867.10\", \"0.490\"], [\"19964.80\", \"0.030\"], [\"20167.10\", \"0.360\"], [\"20264.80\", \"0.630\"], [\"20267.10\", \"0.640\"], [\"63330.40\", \"0.000\"], [\"66848.70\", \"0.005\"], [\"69367.90\", \"0.287\"], [\"69663.40\", \"0.000\"], [\"69859.90\", \"3.723\"], [\"70118.60\", \"0.000\"], [\"70133.70\", \"0.000\"], [\"70285.30\", \"0.008\"], [\"70311.70\", \"0.175\"], [\"70314.00\", \"0.004\"], [\"70314.30\", \"0.709\"], [\"70323.40\", \"0.199\"], [\"70348.40\", \"0.000\"], [\"70352.60\", \"0.300\"]], \"a\": [[\"70367.20\", \"50.022\"], [\"70383.90\", \"0.039\"], [\"70385.10\", \"0.080\"], [\"70386.80\", \"0.056\"], [\"70387.10\", \"0.000\"], [\"70389.10\", \"0.000\"], [\"70491.60\", \"0.138\"], [\"70873.70\", \"0.016\"], [\"70874.30\", \"4.912\"], [\"70888.00\", \"159.493\"], [\"71070.90\", \"0.049\"], [\"71359.40\", \"0.699\"], [\"71366.40\", \"0.279\"], [\"73902.50\", \"0.002\"], [\"77403.90\", \"0.000\"], [\"89523.20\", \"0.000\"]]}", "symbol": "BTCUSDT"}
{"event": "depthUpdate", "raw_payload": "{\"e\": \"depthUpdate\", \"E\": 1773246387090, \"T\": 1773246387089, \"s\": \"BTCUSDT\", \"U\": 10089704032589, \"u\": 10089704039339, \"pu\": 10089704032415, \"b\": [[\"5000.00\", \"101.418\"], [\"19848.60\", \"0.000\"], [\"19867.10\", \"0.580\"], [\"19961.30\", \"0.040\"], [\"19962.60\", \"0.000\"], [\"19964.80\", \"0.000\"], [\"20167.10\", \"0.510\"], [\"20264.80\", \"0.540\"], [\"20267.10\", \"0.600\"], [\"40000.00\", \"50.522\"], [\"56279.00\", \"0.045\"], [\"66834.00\", \"0.004\"], [\"68256.10\", \"0.013\"], [\"69663.40\", \"0.000\"], [\"69858.60\", \"3.782\"], [\"69859.90\", \"0.003\"], [\"69895.40\", \"0.648\"], [\"69998.70\", \"0.008\"], [\"69999.10\", \"0.034\"], [\"70015.30\", \"0.008\"], [\"70015.40\", \"0.007\"], [\"70057.00\", \"0.017\"], [\"70060.70\", \"0.000\"], [\"70064.90\", \"0.000\"], [\"70098.30\", \"0.000\"], [\"70191.70\", \"0.189\"], [\"70222.30\", \"0.003\"], [\"70236.50\", \"0.853\"], [\"70240.70\", \"0.614\"], [\"70268.80\", \"0.545\"], [\"70273.90\", \"1.138\"], [\"70274.00\", \"0.003\"], [\"70281.00\", \"0.076\"], [\"70281.10\", \"0.000\"], [\"70288.00\", \"0.081\"], [\"70288.10\", \"0.511\"], [\"70313.80\", \"0.004\"], [\"70314.00\", \"0.002\"], [\"70339.20\", \"0.036\"], [\"70346.60\", \"0.345\"], [\"70348.30\", \"0.002\"], [\"70348.50\", \"0.001\"], [\"70348.70\", \"0.071\"], [\"70350.10\", \"0.093\"], [\"70350.70\", \"0.002\"], [\"70351.70\", \"0.287\"], [\"70351.80\", \"0.006\"], [\"70352.10\", \"0.001\"], [\"70352.60\", \"0.257\"], [\"70353.00\", \"0.451\"], [\"70353.10\", \"0.004\"], [\"70353.90\", \"0.044\"], [\"70354.00\", \"0.205\"], [\"70354.20\", \"0.001\"], [\"70356.10\", \"0.000\"], [\"70356.20\", \"0.002\"], [\"70356.30\", \"0.107\"], [\"70357.30\", \"0.003\"], [\"70358.30\", \"0.007\"], [\"70360.10\", \"0.002\"], [\"70364.10\", \"0.000\"], [\"70367.10\", \"8.803\"]], \"a\": [[\"70374.20\", \"0.030\"], [\"70377.20\", \"0.007\"], [\"70377.80\", \"0.045\"], [\"70379.80\", \"0.710\"], [\"70380.80\", \"0.103\"], [\"70381.20\", \"0.005\"], [\"70381.80\", \"0.028\"], [\"70382.80\", \"0.158\"], [\"70387.40\", \"0.208\"], [\"70387.80\", \"0.002\"], [\"70405.20\", \"0.027\"], [\"70409.40\", \"0.007\"], [\"70409.50\", \"0.793\"], [\"70411.00\", \"0.000\"], [\"70417.60\", \"0.527\"], [\"70417.70\", \"0.000\"], [\"70425.70\", \"0.005\"], [\"70425.80\", \"1.066\"], [\"70433.80\", \"0.005\"], [\"70433.90\", \"0.003\"], [\"70441.90\", \"0.276\"], [\"70442.00\", \"0.600\"], [\"70450.10\", \"0.071\"], [\"70450.30\", \"0.013\"], [\"70457.10\", \"0.458\"], [\"70457.30\", \"0.044\"], [\"70464.20\", \"0.071\"], [\"70464.40\", \"0.002\"], [\"70477.40\", \"0.003\"], [\"70501.90\", \"1.602\"], [\"70506.60\", \"0.002\"], [\"70688.10\", \"0.047\"], [\"70794.10\", \"0.648\"], [\"70874.30\", \"1.192\"], [\"70875.60\", \"3.720\"], [\"71070.90\", \"0.049\"], [\"72462.40\", \"0.000\"], [\"72466.40\", \"0.000\"]]}", "symbol": "BTCUSDT"}
{"event": "depthUpdate", "raw_payload": "{\"e\": \"depthUpdate\", \"E\": 1773246387192, \"T\": 1773246387188, \"s\": \"BTCUSDT\", \"U\": 10089704039340, \"u\": 10089704047572, \"pu\": 10089704039339, \"b\": [[\"1000.00\", \"26.792\"], [\"5000.00\", \"101.418\"], [\"19867.10\", \"0.660\"], [\"19955.70\", \"0.020\"], [\"19960.10\", \"0.000\"], [\"19961.10\", \"0.000\"], [\"19961.20\", \"0.000\"], [\"19961.30\", \"0.000\"], [\"20167.10\", \"0.680\"], [\"20264.80\", \"0.460\"], [\"20267.10\", \"0.510\"], [\"66831.30\", \"0.004\"], [\"69663.40\", \"0.000\"], [\"69858.60\", \"0.062\"], [\"69860.00\", \"0.027\"], [\"70015.40\", \"0.000\"], [\"70132.80\", \"0.000\"], [\"70250.30\", \"0.082\"], [\"70260.20\", \"0.092\"], [\"70285.50\", \"0.002\"], [\"70290.70\", \"0.043\"], [\"70296.80\", \"0.006\"], [\"70297.00\", \"3.698\"], [\"70310.40\", \"0.006\"], [\"70311.70\", \"0.075\"], [\"70313.80\", \"0.002\"], [\"70314.00\", \"0.004\"], [\"70320.30\", \"0.341\"], [\"70320.50\", \"0.000\"], [\"70320.80\", \"1.958\"], [\"70321.50\", \"0.009\"], [\"70334.80\", \"0.000\"], [\"70335.20\", \"0.344\"], [\"70335.30\", \"0.636\"], [\"70335.90\", \"1.121\"], [\"70336.00\", \"0.768\"], [\"70337.80\", \"0.264\"], [\"70340.10\", \"0.002\"], [\"70340.20\", \"0.000\"], [\"70340.80\", \"0.002\"], [\"70340.90\", \"0.354\"], [\"70341.90\", \"0.024\"], [\"70343.20\", \"0.075\"], [\"70344.40\", \"0.002\"], [\"70347.60\", \"0.080\"], [\"70347.70\", \"0.066\"], [\"70347.80\", \"0.007\"], [\"70348.80\", \"0.016\"], [\"70348.90\", \"0.250\"], [\"70349.20\", \"0.013\"], [\"70349.50\", \"0.006\"], [\"70349.90\", \"0.100\"], [\"70350.00\", \"1.121\"], [\"70350.10\", \"1.300\"], [\"70350.20\", \"0.002\"], [\"70351.10\", \"0.002\"], [\"70351.70\", \"0.294\"], [\"70352.70\", \"0.000\"], [\"70352.80\", \"0.000\"], [\"70352.90\", \"0.099\"], [\"70353.10\", \"0.002\"], [\"70354.20\", \"0.143\"], [\"70356.00\", \"0.005\"], [\"70356.70\", \"0.007\"], [\"70358.30\", \"0.000\"], [\"70360.10\", \"0.000\"], [\"70361.20\", \"0.003\"], [\"70361.30\", \"0.010\"], [\"70363.90\", \"0.000\"], [\"70364.80\", \"0.001\"], [\"70364.90\", \"0.184\"], [\"70365.00\", \"0.006\"], [\"70365.10\", \"0.000\"], [\"70365.90\", \"0.002\"], [\"70367.00\", \"0.003\"], [\"70367.10\", \"5.139\"]], \"a\": [[\"70367.20\", \"50.569\"], [\"70367.70\", \"0.002\"], [\"70369.80\", \"0.002\"], [\"70374.20\", \"0.028\"], [\"70374.40\", \"0.204\"], [\"70380.40\", \"0.187\"], [\"70381.20\", \"0.003\"], [\"70383.70\", \"0.169\"], [\"70384.90\", \"0.000\"], [\"70388.70\", \"0.010\"], [\"70389.30\", \"0.375\"], [\"70390.20\", \"0.009\"], [\"70391.00\", \"0.001\"], [\"70392.60\", \"0.005\"], [\"70394.50\", \"0.085\"], [\"70394.90\", \"0.020\"], [\"70396.50\", \"0.000\"], [\"70398.90\", \"0.010\"], [\"70399.00\", \"0.002\"], [\"70399.10\", \"0.000\"], [\"70399.70\", \"0.013\"], [\"70399.80\", \"0.011\"], [\"70401.50\", \"0.024\"], [\"70410.90\", \"0.095\"], [\"70423.10\", \"0.128\"], [\"70423.30\", \"0.513\"], [\"70424.20\", \"0.000\"], [\"70433.20\", \"0.016\"], [\"70435.70\", \"3.591\"], [\"70436.30\", \"0.004\"], [\"70441.10\", \"0.104\"], [\"70450.80\", \"0.364\"], [\"70472.50\", \"0.158\"], [\"70491.60\", \"0.038\"], [\"70510.30\", \"0.000\"], [\"70599.90\", \"0.000\"], [\"70605.30\", \"0.010\"], [\"70732.60\", \"0.000\"], [\"70740.90\", \"0.002\"], [\"70873.60\", \"0.000\"], [\"70875.60\", \"0.000\"], [\"70876.20\", \"0.000\"], [\"71070.90\", \"0.049\"], [\"71197.60\", \"0.000\"], [\"71359.60\", \"2.088\"], [\"71364.50\", \"0.557\"], [\"89523.20\", \"0.000\"]]}", "symbol": "BTCUSDT"}
{"event": "depthUpdate", "raw_payload": "{\"e\": \"depthUpdate\", \"E\": 1773246387294, \"T\": 1773246387293, \"s\": \"BTCUSDT\", \"U\": 10089704047708, \"u\": 10089704061984, \"pu\": 10089704047572, \"b\": [[\"1000.00\", \"26.792\"], [\"5000.00\", \"101.438\"], [\"19867.10\", \"0.750\"], [\"19952.50\", \"0.230\"], [\"19953.40\", \"0.000\"], [\"19954.60\", \"0.000\"], [\"19955.60\", \"0.000\"], [\"19955.70\", \"0.000\"], [\"20167.10\", \"0.850\"], [\"20264.80\", \"0.370\"], [\"20267.10\", \"0.430\"], [\"56279.00\", \"0.045\"], [\"66816.50\", \"0.007\"], [\"66841.90\", \"0.000\"], [\"68960.00\", \"0.165\"], [\"69245.40\", \"0.004\"], [\"69255.90\", \"0.360\"], [\"69663.40\", \"0.000\"], [\"69851.30\", \"0.000\"], [\"69885.80\", \"0.000\"], [\"70065.00\", \"0.000\"], [\"70182.70\", \"0.210\"], [\"70244.60\", \"0.128\"], [\"70245.60\", \"0.004\"], [\"70289.20\", \"0.000\"], [\"70296.00\", \"0.055\"], [\"70313.50\", \"0.378\"], [\"70314.00\", \"0.002\"], [\"70319.90\", \"0.087\"], [\"70320.20\", \"0.027\"], [\"70320.30\", \"0.256\"], [\"70321.60\", \"0.006\"], [\"70323.40\", \"0.000\"], [\"70323.50\", \"0.002\"], [\"70325.60\", \"0.000\"], [\"70327.10\", \"0.248\"], [\"70327.30\", \"0.000\"], [\"70329.90\", \"0.070\"], [\"70330.20\", \"0.000\"], [\"70331.70\", \"0.002\"], [\"70332.30\", \"0.005\"], [\"70335.20\", \"0.373\"], [\"70335.30\", \"0.531\"], [\"70335.60\", \"0.052\"], [\"70335.90\", \"1.112\"], [\"70336.00\", \"0.759\"], [\"70336.60\", \"0.305\"], [\"70336.70\", \"0.392\"], [\"70337.30\", \"0.023\"], [\"70337.40\", \"0.016\"], [\"70337.80\", \"0.212\"], [\"70337.90\", \"0.000\"], [\"70338.00\", \"0.536\"], [\"70338.10\", \"0.000\"], [\"70339.50\", \"0.002\"], [\"70339.90\", \"0.639\"], [\"70340.10\", \"0.004\"], [\"70340.20\", \"0.002\"], [\"70340.30\", \"0.001\"], [\"70340.60\", \"0.154\"], [\"70340.80\", \"0.000\"], [\"70340.90\", \"0.352\"], [\"70341.00\", \"0.000\"], [\"70341.20\", \"0.071\"], [\"70341.50\", \"0.289\"], [\"70341.60\", \"1.584\"], [\"70341.70\", \"0.007\"], [\"70342.10\", \"0.000\"], [\"70342.40\", \"0.000\"], [\"70342.70\", \"0.000\"], [\"70342.90\", \"0.020\"], [\"70343.20\", \"0.004\"], [\"70343.80\", \"0.007\"], [\"70343.90\", \"0.519\"], [\"70344.20\", \"0.001\"], [\"70344.30\", \"0.085\"], [\"70345.50\", \"0.011\"], [\"70345.60\", \"0.032\"], [\"70345.80\", \"0.121\"], [\"70346.30\", \"0.010\"], [\"70346.40\", \"0.511\"], [\"70346.70\", \"1.222\"], [\"70346.90\", \"0.003\"], [\"70347.10\", \"0.002\"], [\"70347.40\", \"0.000\"], [\"70347.60\", \"0.000\"], [\"70347.70\", \"0.045\"], [\"70347.80\", \"0.007\"], [\"70348.00\", \"0.011\"], [\"70348.10\", \"0.004\"], [\"70348.40\", \"0.284\"], [\"70348.80\", \"0.002\"], [\"70349.00\", \"0.072\"], [\"70349.10\", \"0.270\"], [\"70349.20\", \"0.004\"], [\"70349.50\", \"0.004\"], [\"70349.90\", \"0.098\"], [\"70350.00\", \"0.055\"], [\"70350.10\", \"0.093\"], [\"70350.20\", \"0.009\"], [\"70351.50\", \"0.045\"], [\"70351.70\", \"0.003\"], [\"70352.00\", \"0.142\"], [\"70352.20\", \"0.053\"], [\"70352.30\", \"0.002\"], [\"70352.40\", \"0.443\"], [\"70352.70\", \"0.000\"], [\"70352.80\", \"0.002\"], [\"70352.90\", \"0.193\"], [\"70353.30\", \"0.264\"], [\"70353.60\", \"0.655\"], [\"70354.10\", \"0.199\"], [\"70354.20\", \"0.503\"], [\"70354.30\", \"0.018\"], [\"70354.40\", \"0.016\"], [\"70354.70\", \"0.407\"], [\"70355.00\", \"0.007\"], [\"70355.70\", \"0.011\"], [\"70355.80\", \"0.034\"], [\"70356.30\", \"0.006\"], [\"70356.50\", \"0.179\"], [\"70356.60\", \"0.006\"], [\"70356.70\", \"0.365\"], [\"70357.10\", \"0.000\"], [\"70357.30\", \"0.397\"], [\"70357.40\", \"0.003\"], [\"70357.60\", \"0.001\"], [\"70358.00\", \"0.000\"], [\"70358.10\", \"0.014\"], [\"70358.50\", \"1.000\"], [\"70358.70\", \"0.006\"], [\"70359.20\", \"0.000\"], [\"70360.30\", \"0.003\"], [\"70360.40\", \"0.000\"], [\"70360.50\", \"0.000\"], [\"70360.90\", \"0.001\"], [\"70361.30\", \"0.005\"], [\"70361.40\", \"0.005\"], [\"70361.50\", \"0.005\"], [\"70361.70\", \"0.001\"], [\"70364.90\", \"0.141\"], [\"70365.60\", \"0.002\"], [\"70365.80\", \"0.001\"], [\"70367.00\", \"0.002\"], [\"70367.10\", \"0.243\"]], \"a\": [[\"70367.20\", \"51.152\"], [\"70367.70\", \"0.005\"], [\"70370.30\", \"0.006\"], [\"70370.80\", \"0.200\"], [\"70373.70\", \"0.006\"], [\"70375.30\", \"0.511\"], [\"70375.60\", \"0.000\"], [\"70376.00\", \"0.256\"], [\"70377.20\", \"0.010\"], [\"70377.50\", \"0.017\"], [\"70377.80\", \"0.079\"], [\"70378.10\", \"0.030\"], [\"70378.60\", \"0.021\"], [\"70378.70\", \"0.050\"], [\"70379.00\", \"0.029\"], [\"70379.10\", \"0.031\"], [\"70379.30\", \"0.671\"], [\"70379.40\", \"0.057\"], [\"70379.50\", \"0.091\"], [\"70379.70\", \"0.017\"], [\"70380.30\", \"0.142\"], [\"70380.60\", \"0.060\"], [\"70380.80\", \"0.075\"], [\"70380.90\", \"0.097\"], [\"70381.80\", \"0.000\"], [\"70382.20\", \"0.000\"], [\"70382.50\", \"0.002\"], [\"70382.60\", \"0.002\"], [\"70382.80\", \"0.151\"], [\"70383.70\", \"0.027\"], [\"70383.90\", \"0.041\"], [\"70384.20\", \"0.103\"], [\"70384.30\", \"0.111\"], [\"70385.40\", \"0.007\"], [\"70385.60\", \"0.014\"], [\"70385.70\", \"0.047\"], [\"70386.80\", \"0.567\"], [\"70387.20\", \"0.002\"], [\"70387.50\", \"0.388\"], [\"70388.70\", \"0.000\"], [\"70389.20\", \"0.071\"], [\"70389.50\", \"0.006\"], [\"70389.60\", \"0.000\"], [\"70390.70\", \"0.056\"], [\"70391.20\", \"0.261\"], [\"70391.80\", \"0.073\"], [\"70393.30\", \"0.005\"], [\"70394.50\", \"0.014\"], [\"70396.60\", \"0.054\"], [\"70399.00\", \"0.011\"], [\"70399.10\", \"0.009\"], [\"70399.70\", \"0.004\"], [\"70399.80\", \"0.002\"], [\"70400.40\", \"0.007\"], [\"70400.50\", \"0.433\"], [\"70401.10\", \"0.208\"], [\"70401.20\", \"0.006\"], [\"70401.30\", \"0.000\"], [\"70402.50\", \"0.010\"], [\"70403.10\", \"0.068\"], [\"70405.30\", \"0.004\"], [\"70405.40\", \"0.004\"], [\"70405.60\", \"0.262\"], [\"70406.00\", \"1.080\"], [\"70406.10\", \"0.000\"], [\"70410.90\", \"0.075\"], [\"70416.80\", \"0.265\"], [\"70417.80\", \"0.003\"], [\"70422.60\", \"0.128\"], [\"70422.90\", \"0.002\"], [\"70423.10\", \"0.000\"], [\"70425.00\", \"0.017\"], [\"70432.70\", \"0.000\"], [\"70439.70\", \"0.000\"], [\"70441.20\", \"0.000\"], [\"70444.60\", \"0.000\"], [\"70447.20\", \"0.004\"], [\"70447.80\", \"0.000\"], [\"70449.80\", \"0.000\"], [\"70451.40\", \"0.511\"], [\"70458.10\", \"0.081\"], [\"70462.80\", \"0.285\"], [\"70487.60\", \"0.041\"], [\"70487.70\", \"0.000\"], [\"70488.20\", \"0.072\"], [\"70847.40\", \"3.720\"], [\"70848.40\", \"0.000\"], [\"70882.90\", \"0.021\"], [\"71070.90\", \"0.049\"], [\"100000.00\", \"15.236\"]]}", "symbol": "BTCUSDT"}
{"event": "depthUpdate", "raw_payload": "{\"e\": \"depthUpdate\", \"E\": 1773246387396, \"T\": 1773246387393, \"s\": \"BTCUSDT\", \"U\": 10089704062442, \"u\": 10089704084529, \"pu\": 10089704061984, \"b\": [[\"5000.00\", \"101.418\"], [\"19867.10\", \"0.830\"], [\"19952.50\", \"0.150\"], [\"20167.10\", \"1.020\"], [\"20261.30\", \"0.050\"], [\"20264.80\", \"0.340\"], [\"20267.10\", \"0.340\"], [\"33000.00\", \"10.797\"], [\"66836.80\", \"0.000\"], [\"69663.40\", \"0.171\"], [\"70015.30\", \"0.008\"], [\"70071.70\", \"0.000\"], [\"70071.80\", \"0.000\"], [\"70114.60\", \"2.711\"], [\"70114.70\", \"6.549\"], [\"70115.50\", \"2.020\"], [\"70132.90\", \"0.451\"], [\"70146.00\", \"0.511\"], [\"70157.60\", \"0.000\"], [\"70157.70\", \"0.000\"], [\"70179.80\", \"10.200\"], [\"70185.10\", \"0.732\"], [\"70200.60\", \"0.000\"], [\"70200.70\", \"0.082\"], [\"70203.10\", \"0.000\"], [\"70243.60\", \"0.000\"], [\"70243.70\", \"0.002\"], [\"70279.10\", \"0.419\"], [\"70284.20\", \"0.041\"], [\"70284.80\", \"0.016\"], [\"70284.90\", \"0.020\"], [\"70286.60\", \"0.039\"], [\"70287.20\", \"0.109\"], [\"70287.70\", \"0.134\"], [\"70290.50\", \"0.671\"], [\"70294.10\", \"0.000\"], [\"70294.20\", \"0.005\"], [\"70296.90\", \"0.262\"], [\"70300.20\", \"0.001\"], [\"70312.30\", \"0.004\"], [\"70313.50\", \"0.376\"], [\"70314.50\", \"0.004\"], [\"70315.70\", \"0.447\"], [\"70315.80\", \"0.002\"], [\"70317.50\", \"0.200\"], [\"70317.80\", \"0.007\"], [\"70318.00\", \"0.041\"], [\"70319.20\", \"0.005\"], [\"70319.30\", \"0.000\"], [\"70319.40\", \"0.278\"], [\"70319.50\", \"0.005\"], [\"70319.90\", \"0.002\"], [\"70320.20\", \"0.000\"], [\"70323.90\", \"0.002\"], [\"70324.90\", \"0.217\"], [\"70325.50\", \"0.344\"], [\"70327.10\", \"0.000\"], [\"70332.10\", \"0.024\"], [\"70333.10\", \"0.011\"], [\"70333.20\", \"2.096\"], [\"70333.70\", \"0.072\"], [\"70333.80\", \"0.002\"], [\"70333.90\", \"0.003\"], [\"70334.50\", \"0.513\"], [\"70334.60\", \"0.000\"], [\"70335.20\", \"0.346\"], [\"70335.30\", \"0.013\"], [\"70335.60\", \"0.000\"], [\"70335.90\", \"0.046\"], [\"70336.00\", \"0.009\"], [\"70336.60\", \"0.303\"], [\"70336.70\", \"0.390\"], [\"70336.80\", \"0.511\"], [\"70337.10\", \"1.072\"], [\"70337.90\", \"0.005\"], [\"70338.00\", \"0.518\"], [\"70338.10\", \"0.002\"], [\"70338.40\", \"0.639\"], [\"70338.70\", \"0.077\"], [\"70338.80\", \"0.002\"], [\"70338.90\", \"0.320\"], [\"70339.00\", \"0.698\"], [\"70339.10\", \"0.018\"], [\"70339.40\", \"0.008\"], [\"70339.50\", \"0.002\"], [\"70339.80\", \"0.005\"], [\"70339.90\", \"0.000\"], [\"70340.10\", \"0.002\"], [\"70340.20\", \"0.000\"], [\"70340.60\", \"0.083\"], [\"70340.90\", \"0.010\"], [\"70341.00\", \"0.342\"], [\"70341.50\", \"0.033\"], [\"70341.60\", \"0.005\"], [\"70341.70\", \"0.005\"], [\"70341.80\", \"0.000\"], [\"70341.90\", \"0.535\"], [\"70342.30\", \"0.056\"], [\"70342.90\", \"1.086\"], [\"70343.00\", \"0.083\"], [\"70343.40\", \"0.003\"], [\"70343.70\", \"0.007\"], [\"70343.90\", \"0.008\"], [\"70344.40\", \"0.009\"], [\"70344.70\", \"0.241\"], [\"70345.10\", \"1.210\"], [\"70345.20\", \"0.001\"], [\"70345.50\", \"0.009\"], [\"70345.60\", \"0.025\"], [\"70346.20\", \"0.164\"], [\"70346.40\", \"0.007\"], [\"70346.60\", \"0.003\"], [\"70346.70\", \"0.349\"], [\"70347.00\", \"0.000\"], [\"70347.10\", \"0.002\"], [\"70347.30\", \"0.181\"], [\"70347.60\", \"0.007\"], [\"70347.80\", \"0.000\"], [\"70348.80\", \"0.144\"], [\"70349.10\", \"0.050\"], [\"70349.20\", \"1.070\"], [\"70349.30\", \"0.559\"], [\"70349.90\", \"0.202\"], [\"70350.00\", \"0.055\"], [\"70350.10\", \"0.090\"], [\"70350.20\", \"0.177\"], [\"70351.10\", \"0.002\"], [\"70351.40\", \"0.127\"], [\"70351.60\", \"0.128\"], [\"70351.70\", \"0.104\"], [\"70352.00\", \"0.000\"], [\"70352.30\", \"0.002\"], [\"70352.40\", \"0.000\"], [\"70352.60\", \"0.186\"], [\"70352.70\", \"0.200\"], [\"70353.10\", \"0.000\"], [\"70353.20\", \"0.000\"], [\"70353.50\", \"0.215\"], [\"70353.60\", \"0.000\"], [\"70354.00\", \"0.000\"], [\"70354.10\", \"0.018\"], [\"70354.20\", \"0.131\"], [\"70354.70\", \"0.003\"], [\"70354.80\", \"0.014\"], [\"70356.50\", \"0.010\"], [\"70356.70\", \"0.000\"], [\"70356.90\", \"0.148\"], [\"70357.30\", \"0.000\"], [\"70357.40\", \"0.655\"], [\"70357.80\", \"0.000\"], [\"70358.10\", \"0.000\"], [\"70358.50\", \"0.000\"], [\"70358.60\", \"0.003\"], [\"70359.40\", \"0.003\"], [\"70359.90\", \"0.005\"], [\"70360.50\", \"0.000\"], [\"70360.60\", \"0.001\"], [\"70361.50\", \"0.003\"], [\"70361.60\", \"0.002\"], [\"70361.80\", \"0.000\"], [\"70361.90\", \"0.002\"], [\"70362.00\", \"0.003\"], [\"70362.60\", \"0.142\"], [\"70362.80\", \"0.000\"], [\"70364.10\", \"0.000\"], [\"70365.40\", \"0.003\"], [\"70365.50\", \"0.000\"], [\"70367.00\", \"0.002\"], [\"70367.10\", \"0.719\"]], \"a\": [[\"70367.20\", \"51.258\"], [\"70368.20\", \"0.051\"], [\"70369.00\", \"0.004\"], [\"70369.70\", \"0.003\"], [\"70371.00\", \"0.013\"], [\"70371.50\", \"0.176\"], [\"70373.00\", \"0.008\"], [\"70373.10\", \"0.511\"], [\"70373.70\", \"0.020\"], [\"70374.80\", \"0.525\"], [\"70375.30\", \"0.514\"], [\"70375.50\", \"0.001\"], [\"70375.90\", \"0.018\"], [\"70376.20\", \"0.018\"], [\"70376.50\", \"0.006\"], [\"70376.70\", \"0.065\"], [\"70377.10\", \"0.031\"], [\"70377.20\", \"0.007\"], [\"70377.30\", \"0.677\"], [\"70377.40\", \"0.028\"], [\"70377.50\", \"0.029\"], [\"70377.60\", \"0.601\"], [\"70377.70\", \"1.302\"], [\"70377.80\", \"0.093\"], [\"70377.90\", \"0.009\"], [\"70378.60\", \"0.000\"], [\"70378.70\", \"0.064\"], [\"70378.90\", \"0.097\"], [\"70379.10\", \"0.000\"], [\"70379.20\", \"0.000\"], [\"70379.30\", \"0.000\"], [\"70379.40\", \"0.003\"], [\"70379.50\", \"0.001\"], [\"70379.70\", \"0.003\"], [\"70380.10\", \"0.004\"], [\"70380.30\", \"0.000\"], [\"70380.90\", \"0.007\"], [\"70381.80\", \"0.002\"], [\"70382.00\", \"0.004\"], [\"70382.30\", \"0.391\"], [\"70382.80\", \"0.000\"], [\"70383.60\", \"1.314\"], [\"70383.90\", \"0.039\"], [\"70384.20\", \"0.006\"], [\"70384.60\", \"0.072\"], [\"70386.10\", \"0.004\"], [\"70386.70\", \"0.250\"], [\"70390.50\", \"0.646\"], [\"70390.80\", \"0.000\"], [\"70391.50\", \"0.079\"], [\"70396.70\", \"0.193\"], [\"70396.90\", \"0.014\"], [\"70397.00\", \"0.009\"], [\"70397.60\", \"0.067\"], [\"70397.70\", \"0.000\"], [\"70398.30\", \"0.240\"], [\"70398.40\", \"0.250\"], [\"70398.70\", \"0.273\"], [\"70399.00\", \"0.004\"], [\"70399.10\", \"0.002\"], [\"70399.70\", \"0.004\"], [\"70399.80\", \"0.002\"], [\"70400.40\", \"0.007\"], [\"70400.50\", \"0.433\"], [\"70401.10\", \"0.206\"], [\"70401.20\", \"0.004\"], [\"70403.90\", \"0.002\"], [\"70404.00\", \"0.388\"], [\"70404.60\", \"10.229\"], [\"70404.70\", \"0.002\"], [\"70405.30\", \"0.002\"], [\"70405.40\", \"0.002\"], [\"70407.20\", \"0.068\"], [\"70407.50\", \"0.004\"], [\"70417.20\", \"0.000\"], [\"70421.90\", \"0.216\"], [\"70422.20\", \"0.877\"], [\"70422.60\", \"0.000\"], [\"70425.00\", \"0.045\"], [\"70428.90\", \"0.001\"], [\"70440.70\", \"0.136\"], [\"70441.00\", \"0.009\"], [\"70511.60\", \"0.415\"], [\"70512.10\", \"0.000\"], [\"70554.50\", \"0.000\"], [\"70555.00\", \"0.070\"], [\"70581.50\", \"2.014\"], [\"70584.90\", \"0.000\"], [\"70585.20\", \"0.000\"], [\"70605.30\", \"0.010\"], [\"70619.80\", \"3.392\"], [\"70620.30\", \"10.003\"], [\"70643.50\", \"0.000\"], [\"70643.60\", \"0.000\"], [\"70654.90\", \"0.203\"], [\"70655.10\", \"0.002\"], [\"70686.50\", \"0.000\"], [\"70686.60\", \"0.002\"], [\"70847.40\", \"0.000\"], [\"71070.90\", \"0.049\"], [\"71317.20\", \"1.119\"], [\"71364.40\", \"0.017\"], [\"73181.80\", \"0.006\"], [\"89523.20\", \"0.000\"]]}", "symbol": "BTCUSDT"}
{"event": "depthUpdate", "raw_payload": "{\"e\": \"depthUpdate\", \"E\": 1773246387498, \"T\": 1773246387496, \"s\": \"BTCUSDT\", \"U\": 10089704084762, \"u\": 10089704097008, \"pu\": 10089704084529, \"b\": [[\"1000.00\", \"26.792\"], [\"5000.00\", \"101.418\"], [\"19867.10\", \"0.920\"], [\"19952.50\", \"0.060\"], [\"20167.10\", \"1.190\"], [\"20255.70\", \"0.010\"], [\"20260.10\", \"0.000\"], [\"20261.10\", \"0.000\"], [\"20261.20\", \"0.000\"], [\"20261.30\", \"0.000\"], [\"20267.10\", \"0.260\"], [\"33000.00\", \"10.793\"], [\"67436.40\", \"0.020\"], [\"69663.40\", \"0.171\"], [\"70073.00\", \"0.000\"], [\"70150.90\", \"0.002\"], [\"70225.30\", \"0.082\"], [\"70244.80\", \"0.210\"], [\"70290.10\", \"0.045\"], [\"70290.80\", \"0.262\"], [\"70297.10\", \"0.000\"], [\"70313.70\", \"0.009\"], [\"70314.50\", \"0.002\"], [\"70317.80\", \"0.004\"], [\"70319.40\", \"0.193\"], [\"70319.50\", \"0.005\"], [\"70319.60\", \"0.085\"], [\"70332.10\", \"0.004\"], [\"70333.70\", \"0.052\"], [\"70334.60\", \"0.020\"], [\"70337.20\", \"0.014\"], [\"70339.20\", \"0.056\"], [\"70343.00\", \"0.011\"], [\"70343.60\", \"0.003\"], [\"70349.30\", \"0.377\"], [\"70350.50\", \"0.006\"], [\"70350.60\", \"0.038\"], [\"70353.10\", \"0.000\"], [\"70353.40\", \"0.698\"], [\"70353.50\", \"0.436\"], [\"70353.60\", \"0.397\"], [\"70353.70\", \"0.088\"], [\"70357.40\", \"0.000\"], [\"70360.10\", \"0.000\"], [\"70361.70\", \"0.001\"], [\"70362.90\", \"0.000\"], [\"70364.50\", \"1.000\"], [\"70367.00\", \"0.003\"], [\"70367.10\", \"1.926\"]], \"a\": [[\"70367.20\", \"50.672\"], [\"70367.70\", \"0.002\"], [\"70370.90\", \"0.006\"], [\"70374.20\", \"0.000\"], [\"70378.20\", \"0.242\"], [\"70378.70\", \"0.007\"], [\"70381.50\", \"0.614\"], [\"70385.10\", \"0.009\"], [\"70385.30\", \"0.045\"], [\"70407.00\", \"0.010\"], [\"70417.80\", \"0.573\"], [\"70421.20\", \"0.139\"], [\"70425.00\", \"0.017\"], [\"70437.50\", \"0.006\"], [\"70553.30\", \"0.000\"], [\"70581.80\", \"0.019\"], [\"70583.50\", \"0.002\"], [\"70584.70\", \"1.324\"], [\"70631.60\", \"0.002\"], [\"70632.50\", \"0.004\"], [\"70640.60\", \"0.136\"], [\"70686.00\", \"0.104\"], [\"71064.40\", \"0.005\"], [\"71070.90\", \"0.049\"], [\"73896.00\", \"0.547\"]]}", "symbol": "BTCUSDT"}
{"event": "depthUpdate", "raw_payload": "{\"e\": \"depthUpdate\", \"E\": 1773246387600, \"T\": 1773246387597, \"s\": \"BTCUSDT\", \"U\": 10089704097066, \"u\": 10089704103013, \"pu\": 10089704097008, \"b\": [[\"1000.00\", \"26.792\"], [\"5000.00\", \"101.418\"], [\"19867.10\", \"1.000\"], [\"19949.30\", \"0.000\"], [\"19951.40\", \"0.000\"], [\"19952.50\", \"0.000\"], [\"20167.10\", \"1.360\"], [\"20253.40\", \"0.000\"], [\"20254.60\", \"0.000\"], [\"20255.60\", \"0.000\"], [\"20255.70\", \"0.000\"], [\"20267.10\", \"0.170\"], [\"66831.20\", \"0.010\"], [\"66834.00\", \"0.002\"], [\"69663.40\", \"0.000\"], [\"69889.20\", \"3.723\"], [\"69961.70\", \"0.000\"], [\"69980.00\", \"0.360\"], [\"70242.20\", \"0.086\"], [\"70298.50\", \"0.003\"], [\"70313.70\", \"0.007\"], [\"70314.50\", \"0.004\"], [\"70319.50\", \"0.090\"], [\"70319.60\", \"0.000\"], [\"70319.70\", \"0.044\"], [\"70326.60\", \"0.003\"], [\"70333.70\", \"0.072\"], [\"70334.60\", \"0.000\"], [\"70342.80\", \"0.548\"], [\"70346.20\", \"0.093\"], [\"70349.90\", \"0.000\"], [\"70350.20\", \"0.248\"], [\"70355.00\", \"0.209\"], [\"70355.10\", \"0.143\"], [\"70364.50\", \"0.000\"], [\"70365.00\", \"0.004\"], [\"70366.70\", \"1.000\"], [\"70366.80\", \"0.002\"], [\"70367.10\", \"2.392\"]], \"a\": [[\"70367.20\", \"51.257\"], [\"70369.70\", \"0.003\"], [\"70402.30\", \"0.050\"], [\"70407.70\", \"0.008\"], [\"70417.30\", \"0.000\"], [\"70421.20\", \"0.139\"], [\"70435.90\", \"0.159\"], [\"70451.70\", \"0.055\"], [\"70461.10\", \"0.577\"], [\"70492.20\", \"2.003\"], [\"70512.80\", \"0.088\"], [\"70515.50\", \"0.000\"], [\"70519.80\", \"0.026\"], [\"70522.50\", \"0.000\"], [\"70526.80\", \"0.007\"], [\"70529.50\", \"1.350\"], [\"70533.80\", \"0.009\"], [\"70536.50\", \"0.000\"], [\"70540.80\", \"0.010\"], [\"70543.50\", \"0.000\"], [\"70547.80\", \"0.007\"], [\"70550.50\", \"0.000\"], [\"70554.80\", \"0.007\"], [\"70557.50\", \"0.022\"], [\"70561.80\", \"0.007\"], [\"70564.50\", \"0.000\"], [\"70845.00\", \"3.720\"], [\"71070.90\", \"1.454\"], [\"89523.20\", \"0.000\"]]}", "symbol": "BTCUSDT"}
{"event": "depthUpdate", "raw_payload": "{\"e\": \"depthUpdate\", \"E\": 1773246387702, \"T\": 1773246387700, \"s\": \"BTCUSDT\", \"U\": 10089704103185, \"u\": 10089704108165, \"pu\": 10089704103013, \"b\": [[\"5000.00\", \"101.418\"], [\"19867.10\", \"0.910\"], [\"20167.10\", \"1.530\"], [\"20252.50\", \"0.040\"], [\"20267.10\", \"0.180\"], [\"56294.00\", \"0.000\"], [\"66834.20\", \"0.006\"], [\"68610.40\", \"1.235\"], [\"69332.70\", \"1.368\"], [\"69576.60\", \"1.422\"], [\"70015.30\", \"0.008\"], [\"70307.50\", \"0.000\"], [\"70314.30\", \"0.711\"], [\"70314.50\", \"0.002\"], [\"70320.50\", \"0.002\"], [\"70333.70\", \"0.052\"], [\"70335.70\", \"0.009\"], [\"70339.80\", \"0.003\"], [\"70342.80\", \"0.550\"], [\"70343.60\", \"0.023\"], [\"70353.60\", \"0.000\"], [\"70356.20\", \"0.044\"], [\"70367.00\", \"0.061\"], [\"70367.10\", \"2.332\"]], \"a\": [[\"70367.20\", \"51.155\"], [\"70372.30\", \"0.107\"], [\"70383.70\", \"0.427\"], [\"70471.90\", \"0.003\"], [\"71070.90\", \"1.454\"], [\"73919.90\", \"11.294\"]]}", "symbol": "BTCUSDT"}
{"event": "depthUpdate", "raw_payload": "{\"e\": \"depthUpdate\", \"E\": 1773246387804, \"T\": 1773246387801, \"s\": \"BTCUSDT\", \"U\": 10089704108261, \"u\": 10089704115337, \"pu\": 10089704108165, \"b\": [[\"1000.00\", \"26.792\"], [\"5000.00\", \"101.418\"], [\"19867.10\", \"0.830\"], [\"20067.10\", \"0.040\"], [\"20167.10\", \"1.620\"], [\"20252.50\", \"0.000\"], [\"20267.10\", \"0.170\"], [\"66821.30\", \"0.000\"], [\"66848.00\", \"0.004\"], [\"69069.20\", \"0.004\"], [\"69192.60\", \"0.649\"], [\"69344.60\", \"0.000\"], [\"69451.60\", \"0.000\"], [\"69454.50\", \"0.007\"], [\"69663.40\", \"0.000\"], [\"69796.10\", \"0.004\"], [\"69889.20\", \"0.003\"], [\"69889.80\", \"3.722\"], [\"69980.10\", \"0.007\"], [\"70007.10\", \"1.137\"], [\"70132.90\", \"0.444\"], [\"70172.90\", \"0.000\"], [\"70319.40\", \"0.193\"], [\"70319.50\", \"0.090\"], [\"70333.90\", \"0.038\"], [\"70334.50\", \"0.515\"], [\"70334.60\", \"0.002\"], [\"70335.20\", \"0.344\"], [\"70335.30\", \"0.011\"], [\"70338.30\", \"0.034\"], [\"70339.20\", \"0.036\"], [\"70345.20\", \"0.008\"], [\"70345.90\", \"0.009\"], [\"70346.20\", \"0.100\"], [\"70346.40\", \"0.000\"], [\"70346.60\", \"0.287\"], [\"70346.70\", \"0.342\"], [\"70347.60\", \"0.000\"], [\"70348.40\", \"0.000\"], [\"70348.80\", \"0.002\"], [\"70349.20\", \"1.075\"], [\"70349.70\", \"0.177\"], [\"70350.30\", \"0.002\"], [\"70352.20\", \"0.048\"], [\"70355.10\", \"0.000\"], [\"70359.10\", \"0.071\"], [\"70360.50\", \"0.013\"], [\"70361.90\", \"0.000\"], [\"70362.40\", \"1.005\"], [\"70362.60\", \"0.001\"], [\"70363.70\", \"0.000\"], [\"70365.00\", \"0.006\"], [\"70366.70\", \"0.000\"], [\"70366.80\", \"0.000\"], [\"70367.00\", \"0.060\"], [\"70367.10\", \"0.659\"]], \"a\": [[\"70367.20\", \"51.340\"], [\"70368.50\", \"0.004\"], [\"70369.70\", \"0.003\"], [\"70372.30\", \"0.005\"], [\"70374.20\", \"0.039\"], [\"70375.20\", \"0.005\"], [\"70375.30\", \"0.511\"], [\"70377.70\", \"1.160\"], [\"70378.80\", \"0.146\"], [\"70382.20\", \"0.291\"], [\"70383.10\", \"0.007\"], [\"70385.00\", \"0.043\"], [\"70385.60\", \"0.000\"], [\"70389.00\", \"0.080\"], [\"70389.10\", \"0.071\"], [\"70390.20\", \"0.002\"], [\"70390.30\", \"0.000\"], [\"70391.20\", \"0.190\"], [\"70391.40\", \"0.010\"], [\"70391.70\", \"0.042\"], [\"70391.80\", \"0.002\"], [\"70394.50\", \"0.007\"], [\"70394.70\", \"0.000\"], [\"70398.30\", \"0.242\"], [\"70398.40\", \"0.252\"], [\"70399.00\", \"0.002\"], [\"70399.10\", \"0.000\"], [\"70402.30\", \"0.005\"], [\"70403.20\", \"0.002\"], [\"70403.30\", \"0.117\"], [\"70403.90\", \"0.000\"], [\"70404.00\", \"0.386\"], [\"70410.80\", \"0.103\"], [\"70410.90\", \"0.002\"], [\"70484.30\", \"0.171\"], [\"70844.40\", \"3.720\"], [\"70845.00\", \"0.000\"], [\"71070.90\", \"1.454\"], [\"71592.90\", \"0.030\"], [\"71683.10\", \"0.490\"], [\"89523.20\", \"0.000\"]]}", "symbol": "BTCUSDT"}
{"event": "depthUpdate", "raw_payload": "{\"e\": \"depthUpdate\", \"E\": 1773246387906, \"T\": 1773246387904, \"s\": \"BTCUSDT\", \"U\": 10089704115550, \"u\": 10089704123618, \"pu\": 10089704115337, \"b\": [[\"1000.00\", \"26.792\"], [\"5000.00\", \"101.398\"], [\"19867.10\", \"0.740\"], [\"20067.10\", \"0.130\"], [\"20167.10\", \"1.610\"], [\"20264.80\", \"0.260\"], [\"20267.10\", \"0.260\"], [\"63330.40\", \"0.002\"], [\"65000.00\", \"73.904\"], [\"69889.80\", \"0.002\"], [\"69890.40\", \"3.720\"], [\"69980.10\", \"0.000\"], [\"69999.10\", \"0.118\"], [\"70072.40\", \"0.060\"], [\"70132.40\", \"0.000\"], [\"70151.40\", \"0.272\"], [\"70151.80\", \"0.000\"], [\"70152.10\", \"0.008\"], [\"70179.40\", \"0.000\"], [\"70179.90\", \"2.611\"], [\"70242.20\", \"0.086\"], [\"70244.80\", \"1.985\"], [\"70276.90\", \"0.434\"], [\"70297.10\", \"1.019\"], [\"70298.50\", \"0.003\"], [\"70307.70\", \"2.758\"], [\"70313.40\", \"0.973\"], [\"70314.30\", \"0.709\"], [\"70319.40\", \"0.278\"], [\"70319.50\", \"0.005\"], [\"70326.60\", \"0.003\"], [\"70339.00\", \"1.360\"], [\"70345.80\", \"0.003\"], [\"70362.50\", \"0.004\"], [\"70367.00\", \"0.002\"], [\"70367.10\", \"0.719\"]], \"a\": [[\"70367.20\", \"50.757\"], [\"70371.10\", \"0.002\"], [\"70386.20\", \"0.000\"], [\"70386.70\", \"0.634\"], [\"70390.70\", \"0.005\"], [\"70405.60\", \"0.217\"], [\"70407.70\", \"0.008\"], [\"70409.50\", \"1.269\"], [\"70413.30\", \"0.093\"], [\"70417.20\", \"0.000\"], [\"70417.80\", \"0.003\"], [\"70421.90\", \"0.088\"], [\"70422.20\", \"1.008\"], [\"70427.70\", \"0.107\"], [\"70430.60\", \"2.754\"], [\"70435.90\", \"0.159\"], [\"70443.20\", \"2.026\"], [\"70492.20\", \"2.003\"], [\"70555.20\", \"1.142\"], [\"70600.90\", \"0.387\"], [\"70611.40\", \"0.110\"], [\"70624.40\", \"2.209\"], [\"70679.90\", \"0.035\"], [\"70700.00\", \"20.741\"], [\"70843.80\", \"3.723\"], [\"70844.40\", \"0.000\"], [\"71070.90\", \"1.454\"], [\"71366.40\", \"0.558\"], [\"72000.00\", \"245.367\"], [\"73893.60\", \"0.000\"], [\"77403.90\", \"0.002\"]]}", "symbol": "BTCUSDT"}
{"event": "depthUpdate", "raw_payload": "{\"e\": \"depthUpdate\", \"E\": 1773246388008, \"T\": 1773246388005, \"s\": \"BTCUSDT\", \"U\": 10089704123837, \"u\": 10089704137681, \"pu\": 10089704123618, \"b\": [[\"5000.00\", \"101.418\"], [\"19867.10\", \"0.660\"], [\"20067.10\", \"0.210\"], [\"20167.10\", \"1.620\"], [\"20264.80\", \"0.170\"], [\"20267.10\", \"0.340\"], [\"63330.40\", \"0.000\"], [\"66836.30\", \"0.002\"], [\"68425.90\", \"0.000\"], [\"69438.80\", \"0.863\"], [\"69663.40\", \"0.000\"], [\"69804.20\", \"0.072\"], [\"69890.40\", \"0.000\"], [\"69890.90\", \"3.720\"], [\"70015.30\", \"0.044\"], [\"70271.50\", \"0.000\"], [\"70273.90\", \"1.138\"], [\"70281.00\", \"0.076\"], [\"70281.10\", \"0.018\"], [\"70282.20\", \"0.007\"], [\"70284.90\", \"0.002\"], [\"70288.00\", \"0.081\"], [\"70306.90\", \"0.000\"], [\"70307.70\", \"2.761\"], [\"70307.80\", \"0.512\"], [\"70318.40\", \"0.090\"], [\"70318.90\", \"0.005\"], [\"70319.00\", \"0.000\"], [\"70319.20\", \"0.005\"], [\"70319.30\", \"0.000\"], [\"70319.40\", \"0.193\"], [\"70319.50\", \"0.005\"], [\"70336.30\", \"0.020\"], [\"70336.90\", \"0.514\"], [\"70338.00\", \"0.007\"], [\"70338.30\", \"0.014\"], [\"70339.00\", \"1.309\"], [\"70339.10\", \"0.018\"], [\"70340.20\", \"0.071\"], [\"70340.90\", \"0.012\"], [\"70341.20\", \"0.000\"], [\"70342.80\", \"0.548\"], [\"70344.80\", \"0.011\"], [\"70345.90\", \"0.002\"], [\"70349.20\", \"0.009\"], [\"70353.00\", \"0.451\"], [\"70353.40\", \"0.658\"], [\"70356.00\", \"0.008\"], [\"70360.00\", \"0.005\"], [\"70360.20\", \"1.004\"], [\"70362.40\", \"0.008\"], [\"70363.60\", \"0.007\"], [\"70364.90\", \"0.000\"], [\"70367.10\", \"0.256\"]], \"a\": [[\"70367.20\", \"51.710\"], [\"70369.70\", \"0.003\"], [\"70377.50\", \"0.171\"], [\"70378.80\", \"0.004\"], [\"70384.10\", \"0.513\"], [\"70386.80\", \"0.056\"], [\"70388.20\", \"0.008\"], [\"70413.20\", \"0.000\"], [\"70413.30\", \"0.093\"], [\"70421.90\", \"0.088\"], [\"70422.00\", \"2.954\"], [\"70422.20\", \"0.880\"], [\"70430.60\", \"2.757\"], [\"70432.10\", \"0.513\"], [\"70436.50\", \"0.011\"], [\"70450.00\", \"0.776\"], [\"70450.10\", \"0.000\"], [\"70457.00\", \"0.087\"], [\"70457.10\", \"0.387\"], [\"70464.10\", \"2.079\"], [\"70464.20\", \"0.000\"], [\"70843.30\", \"3.720\"], [\"70843.80\", \"0.003\"], [\"70880.70\", \"0.004\"], [\"71070.90\", \"1.454\"], [\"71093.40\", \"0.014\"], [\"71306.00\", \"0.009\"], [\"71518.70\", \"0.004\"], [\"71731.30\", \"0.004\"], [\"72478.20\", \"0.006\"], [\"73902.50\", \"0.000\"], [\"77403.90\", \"0.000\"], [\"89523.20\", \"0.000\"]]}", "symbol": "BTCUSDT"}
{"event": "depthUpdate", "raw_payload": "{\"e\": \"depthUpdate\", \"E\": 1773246388110, \"T\": 1773246388108, \"s\": \"BTCUSDT\", \"U\": 10089704138185, \"u\": 10089704155017, \"pu\": 10089704137681, \"b\": [[\"1000.00\", \"26.792\"], [\"5000.00\", \"101.418\"], [\"19867.10\", \"0.570\"], [\"20067.10\", \"0.300\"], [\"20167.10\", \"1.610\"], [\"20264.80\", \"0.090\"], [\"20267.10\", \"0.430\"], [\"33000.00\", \"10.797\"], [\"56279.00\", \"0.045\"], [\"66831.20\", \"0.008\"], [\"69663.40\", \"0.000\"], [\"69769.70\", \"0.000\"], [\"69890.90\", \"0.000\"], [\"69891.80\", \"3.720\"], [\"69895.30\", \"0.000\"], [\"70015.20\", \"0.000\"], [\"70057.00\", \"0.015\"], [\"70132.70\", \"0.007\"], [\"70238.20\", \"0.097\"], [\"70241.80\", \"0.195\"], [\"70279.10\", \"0.437\"], [\"70281.10\", \"0.000\"], [\"70281.90\", \"0.004\"], [\"70291.80\", \"0.006\"], [\"70310.70\", \"0.159\"], [\"70318.30\", \"0.508\"], [\"70318.40\", \"0.002\"], [\"70319.10\", \"0.002\"], [\"70319.70\", \"0.002\"], [\"70321.70\", \"0.007\"], [\"70322.00\", \"0.004\"], [\"70324.90\", \"0.321\"], [\"70329.00\", \"0.010\"], [\"70329.10\", \"0.342\"], [\"70332.30\", \"0.025\"], [\"70335.10\", \"0.020\"], [\"70336.00\", \"0.009\"], [\"70336.30\", \"0.000\"], [\"70337.30\", \"0.007\"], [\"70337.40\", \"0.000\"], [\"70337.60\", \"0.002\"], [\"70337.70\", \"0.073\"], [\"70338.70\", \"0.006\"], [\"70338.90\", \"0.322\"], [\"70340.90\", \"0.010\"], [\"70341.20\", \"0.003\"], [\"70343.00\", \"0.011\"], [\"70343.60\", \"0.003\"], [\"70344.00\", \"0.007\"], [\"70345.20\", \"0.001\"], [\"70346.10\", \"0.078\"], [\"70349.10\", \"0.192\"], [\"70349.30\", \"0.203\"], [\"70349.70\", \"0.035\"], [\"70350.20\", \"0.177\"], [\"70350.30\", \"1.068\"], [\"70355.10\", \"0.016\"], [\"70355.20\", \"0.017\"], [\"70355.30\", \"0.018\"], [\"70360.30\", \"0.005\"], [\"70364.80\", \"0.003\"], [\"70365.00\", \"0.004\"], [\"70367.10\", \"0.716\"]], \"a\": [[\"70367.20\", \"51.125\"], [\"70367.80\", \"0.002\"], [\"70378.00\", \"0.062\"], [\"70378.20\", \"0.185\"], [\"70379.90\", \"0.005\"], [\"70383.40\", \"0.042\"], [\"70385.00\", \"0.043\"], [\"70386.70\", \"0.636\"], [\"70388.90\", \"0.007\"], [\"70389.00\", \"0.009\"], [\"70390.00\", \"0.073\"], [\"70391.40\", \"0.003\"], [\"70392.00\", \"0.392\"], [\"70394.60\", \"0.003\"], [\"70399.00\", \"0.002\"], [\"70406.00\", \"1.080\"], [\"70413.00\", \"1.074\"], [\"70413.30\", \"0.048\"], [\"70413.60\", \"0.000\"], [\"70415.80\", \"0.002\"], [\"70417.30\", \"0.028\"], [\"70417.80\", \"0.573\"], [\"70421.20\", \"0.111\"], [\"70434.00\", \"0.010\"], [\"70435.50\", \"0.745\"], [\"70486.70\", \"0.014\"], [\"70488.20\", \"0.058\"], [\"70496.40\", \"0.002\"], [\"70506.60\", \"0.000\"], [\"70602.60\", \"0.006\"], [\"70605.30\", \"0.004\"], [\"70736.50\", \"0.004\"], [\"70740.90\", \"0.000\"], [\"70793.00\", \"0.111\"], [\"70794.20\", \"0.074\"], [\"70842.40\", \"3.737\"], [\"70843.30\", \"0.000\"], [\"70844.30\", \"0.025\"], [\"70923.30\", \"0.000\"], [\"71070.90\", \"1.454\"], [\"71300.00\", \"148.067\"]]}", "symbol": "BTCUSDT"}
{"event": "depthUpdate", "raw_payload": "{\"e\": \"depthUpdate\", \"E\": 1773246388212, \"T\": 1773246388209, \"s\": \"BTCUSDT\", \"U\": 10089704155235, \"u\": 10089704160877, \"pu\": 10089704155017, \"b\": [[\"1000.00\", \"26.792\"], [\"5000.00\", \"101.418\"], [\"19867.10\", \"0.490\"], [\"20067.10\", \"0.380\"], [\"20167.10\", \"1.620\"], [\"20264.80\", \"0.000\"], [\"20267.10\", \"0.510\"], [\"33000.00\", \"10.793\"], [\"69401.50\", \"0.002\"], [\"69610.30\", \"0.000\"], [\"69663.40\", \"0.000\"], [\"70212.00\", \"0.000\"], [\"70271.00\", \"0.003\"], [\"70273.90\", \"1.138\"], [\"70281.00\", \"0.076\"], [\"70287.20\", \"0.005\"], [\"70288.00\", \"0.081\"], [\"70313.40\", \"0.971\"], [\"70313.70\", \"0.009\"], [\"70318.30\", \"0.423\"], [\"70318.40\", \"0.002\"], [\"70319.80\", \"0.511\"], [\"70331.90\", \"0.084\"], [\"70335.10\", \"0.000\"], [\"70337.20\", \"0.118\"], [\"70337.70\", \"0.002\"], [\"70338.90\", \"0.320\"], [\"70339.00\", \"1.360\"], [\"70340.20\", \"0.071\"], [\"70341.70\", \"0.002\"], [\"70342.50\", \"0.005\"], [\"70342.70\", \"0.071\"], [\"70343.20\", \"0.024\"], [\"70346.10\", \"0.007\"], [\"70351.10\", \"0.073\"], [\"70351.70\", \"0.003\"], [\"70352.80\", \"0.344\"], [\"70353.50\", \"0.607\"], [\"70353.60\", \"0.377\"], [\"70354.30\", \"0.028\"], [\"70355.10\", \"0.026\"], [\"70356.10\", \"0.104\"], [\"70356.20\", \"0.046\"], [\"70356.30\", \"0.128\"], [\"70360.20\", \"0.004\"], [\"70362.50\", \"0.002\"], [\"70363.70\", \"0.000\"], [\"70364.80\", \"0.001\"], [\"70365.10\", \"0.000\"], [\"70365.20\", \"0.000\"], [\"70366.80\", \"1.000\"], [\"70366.90\", \"0.002\"], [\"70367.00\", \"0.003\"], [\"70367.10\", \"2.392\"]], \"a\": [[\"70367.20\", \"50.738\"], [\"70369.70\", \"0.003\"], [\"70377.50\", \"0.029\"], [\"70378.20\", \"0.185\"], [\"70378.80\", \"0.146\"], [\"70383.70\", \"0.827\"], [\"70384.10\", \"0.002\"], [\"70385.30\", \"0.556\"], [\"70388.90\", \"0.000\"], [\"70389.10\", \"0.000\"], [\"70390.10\", \"0.076\"], [\"70390.80\", \"0.007\"], [\"70411.30\", \"0.045\"], [\"70413.80\", \"0.000\"], [\"70421.00\", \"0.128\"], [\"70422.00\", \"2.826\"], [\"70427.70\", \"0.056\"], [\"70428.30\", \"0.059\"], [\"70434.10\", \"0.005\"], [\"70449.90\", \"0.071\"], [\"70450.00\", \"0.705\"], [\"70456.90\", \"0.071\"], [\"70457.00\", \"0.016\"], [\"70464.00\", \"0.073\"], [\"70464.10\", \"2.008\"], [\"70487.00\", \"0.000\"], [\"70578.40\", \"0.019\"], [\"70581.80\", \"0.000\"], [\"70918.60\", \"0.141\"], [\"71070.90\", \"1.454\"], [\"71086.80\", \"0.000\"], [\"71200.10\", \"1.402\"], [\"73910.70\", \"0.000\"], [\"89523.20\", \"0.000\"]]}", "symbol": "BTCUSDT"}
{"event": "depthUpdate", "raw_payload": "{\"e\": \"depthUpdate\", \"E\": 1773246388314, \"T\": 1773246388312, \"s\": \"BTCUSDT\", \"U\": 10089704161083, \"u\": 10089704166284, \"pu\": 10089704160877, \"b\": [[\"5000.00\", \"101.418\"], [\"19867.10\", \"0.400\"], [\"20067.10\", \"0.550\"], [\"20167.10\", \"1.450\"], [\"20267.10\", \"0.600\"], [\"56294.00\", \"0.000\"], [\"66831.30\", \"0.002\"], [\"66843.40\", \"0.000\"], [\"66848.70\", \"0.007\"], [\"68893.00\", \"0.012\"], [\"68960.00\", \"0.163\"], [\"69533.10\", \"3.240\"], [\"69719.00\", \"0.000\"], [\"69737.30\", \"0.016\"], [\"69769.80\", \"0.003\"], [\"69800.10\", \"0.771\"], [\"69893.30\", \"0.000\"], [\"69895.40\", \"0.000\"], [\"69911.60\", \"0.365\"], [\"70015.30\", \"0.044\"], [\"70068.00\", \"0.000\"], [\"70086.40\", \"0.011\"], [\"70243.20\", \"0.177\"], [\"70245.60\", \"0.002\"], [\"70247.80\", \"0.002\"], [\"70254.30\", \"1.410\"], [\"70259.70\", \"1.331\"], [\"70261.60\", \"0.002\"], [\"70278.00\", \"0.524\"], [\"70285.30\", \"0.006\"], [\"70313.70\", \"0.007\"], [\"70314.50\", \"0.004\"], [\"70336.90\", \"0.003\"], [\"70338.40\", \"1.150\"], [\"70339.50\", \"0.002\"], [\"70345.20\", \"0.512\"], [\"70350.50\", \"0.003\"]], \"a\": [[\"70369.20\", \"0.004\"], [\"70385.30\", \"0.045\"], [\"70386.50\", \"0.511\"], [\"70388.20\", \"0.008\"], [\"70407.70\", \"0.014\"], [\"70412.20\", \"0.002\"], [\"70412.40\", \"0.054\"], [\"70428.30\", \"0.008\"], [\"70454.10\", \"0.042\"], [\"70472.70\", \"0.087\"], [\"70576.00\", \"0.026\"], [\"70578.40\", \"0.000\"], [\"70630.20\", \"0.000\"], [\"70648.90\", \"0.004\"], [\"70793.00\", \"0.000\"], [\"70794.10\", \"0.000\"], [\"70799.90\", \"19.422\"], [\"70806.80\", \"0.000\"], [\"70825.50\", \"0.008\"], [\"70887.80\", \"3.242\"], [\"70983.80\", \"0.000\"], [\"71002.60\", \"0.078\"], [\"71070.90\", \"1.454\"], [\"71079.40\", \"1.114\"], [\"71211.60\", \"1.121\"], [\"71493.10\", \"0.697\"], [\"73891.70\", \"0.002\"]]}", "symbol": "BTCUSDT"}
{"event": "depthUpdate", "raw_payload": "{\"e\": \"depthUpdate\", \"E\": 1773246388418, \"T\": 1773246388417, \"s\": \"BTCUSDT\", \"U\": 10089704166487, \"u\": 10089704180644, \"pu\": 10089704166284, \"b\": [[\"1000.00\", \"26.792\"], [\"5000.00\", \"101.418\"], [\"19867.10\", \"0.320\"], [\"20067.10\", \"0.730\"], [\"20167.10\", \"1.270\"], [\"20267.10\", \"0.680\"], [\"66818.40\", \"0.006\"], [\"66831.20\", \"0.006\"], [\"66831.30\", \"0.004\"], [\"66836.30\", \"0.000\"], [\"68392.20\", \"1.285\"], [\"69349.80\", \"0.000\"], [\"69436.40\", \"0.728\"], [\"69663.40\", \"0.000\"], [\"69891.80\", \"0.000\"], [\"69892.50\", \"3.730\"], [\"70225.40\", \"0.000\"], [\"70232.20\", \"0.042\"], [\"70248.60\", \"0.160\"], [\"70264.80\", \"0.648\"], [\"70287.70\", \"0.091\"], [\"70300.40\", \"0.050\"], [\"70324.90\", \"0.270\"], [\"70325.50\", \"0.168\"], [\"70329.30\", \"0.248\"], [\"70332.30\", \"0.005\"], [\"70338.40\", \"0.511\"], [\"70339.00\", \"1.309\"], [\"70340.30\", \"0.021\"], [\"70340.60\", \"0.003\"], [\"70342.00\", \"0.648\"], [\"70343.40\", \"0.001\"], [\"70343.70\", \"0.005\"], [\"70344.10\", \"0.035\"], [\"70344.40\", \"0.030\"], [\"70345.10\", \"0.002\"], [\"70345.20\", \"0.512\"], [\"70345.50\", \"0.009\"], [\"70346.70\", \"0.349\"], [\"70347.60\", \"0.080\"], [\"70347.80\", \"0.002\"], [\"70349.00\", \"1.280\"], [\"70349.10\", \"0.050\"], [\"70351.10\", \"0.002\"], [\"70351.30\", \"0.147\"], [\"70353.30\", \"0.000\"], [\"70353.40\", \"0.003\"], [\"70353.70\", \"0.016\"], [\"70354.30\", \"0.018\"], [\"70354.60\", \"0.073\"], [\"70355.10\", \"0.016\"], [\"70355.20\", \"0.027\"], [\"70356.10\", \"0.003\"], [\"70356.30\", \"0.410\"], [\"70356.50\", \"0.061\"], [\"70357.00\", \"0.017\"], [\"70360.30\", \"0.269\"], [\"70360.40\", \"0.756\"], [\"70362.00\", \"0.006\"], [\"70367.10\", \"3.434\"]], \"a\": [[\"70367.20\", \"50.097\"], [\"70368.20\", \"0.028\"], [\"70369.70\", \"0.003\"], [\"70370.80\", \"0.000\"], [\"70370.90\", \"0.003\"], [\"70371.80\", \"0.004\"], [\"70373.30\", \"0.000\"], [\"70373.50\", \"0.102\"], [\"70374.10\", \"0.003\"], [\"70374.80\", \"0.311\"], [\"70375.90\", \"0.004\"], [\"70376.70\", \"0.001\"], [\"70377.10\", \"0.000\"], [\"70377.30\", \"0.006\"], [\"70377.40\", \"0.000\"], [\"70377.50\", \"0.003\"], [\"70377.60\", \"0.511\"], [\"70377.70\", \"0.094\"], [\"70377.80\", \"0.045\"], [\"70378.00\", \"0.005\"], [\"70378.10\", \"0.002\"], [\"70378.20\", \"0.316\"], [\"70378.80\", \"0.004\"], [\"70378.90\", \"0.646\"], [\"70379.00\", \"0.001\"], [\"70379.70\", \"0.003\"], [\"70380.60\", \"0.003\"], [\"70380.70\", \"0.004\"], [\"70381.80\", \"0.000\"], [\"70382.00\", \"0.002\"], [\"70382.10\", \"0.144\"], [\"70382.20\", \"0.284\"], [\"70382.30\", \"0.294\"], [\"70383.10\", \"0.000\"], [\"70383.50\", \"0.060\"], [\"70383.80\", \"0.032\"], [\"70384.00\", \"0.201\"], [\"70384.10\", \"0.004\"], [\"70384.20\", \"0.006\"], [\"70384.30\", \"0.108\"], [\"70385.00\", \"0.036\"], [\"70385.60\", \"0.007\"], [\"70386.40\", \"0.003\"], [\"70386.50\", \"0.000\"], [\"70388.10\", \"0.518\"], [\"70390.00\", \"0.002\"], [\"70390.10\", \"0.005\"], [\"70391.30\", \"0.088\"], [\"70391.50\", \"0.130\"], [\"70393.70\", \"0.000\"], [\"70394.90\", \"0.000\"], [\"70395.50\", \"0.035\"], [\"70403.40\", \"0.022\"], [\"70407.00\", \"0.004\"], [\"70410.70\", \"0.132\"], [\"70410.80\", \"0.030\"], [\"70411.30\", \"0.000\"], [\"70412.40\", \"0.003\"], [\"70415.40\", \"0.640\"], [\"70417.30\", \"0.000\"], [\"70421.00\", \"0.000\"], [\"70421.20\", \"0.139\"], [\"70421.50\", \"0.418\"], [\"70421.80\", \"0.000\"], [\"70422.50\", \"0.209\"], [\"70427.00\", \"0.055\"], [\"70473.50\", \"0.648\"], [\"70841.70\", \"3.720\"], [\"70842.40\", \"0.017\"], [\"70918.60\", \"0.000\"], [\"71070.90\", \"1.454\"], [\"71200.10\", \"1.121\"], [\"71349.90\", \"0.000\"], [\"89523.20\", \"0.000\"], [\"100000.00\", \"15.487\"]]}", "symbol": "BTCUSDT"}
{"event": "depthUpdate", "raw_payload": "{\"e\": \"depthUpdate\", \"E\": 1773246388520, \"T\": 1773246388519, \"s\": \"BTCUSDT\", \"U\": 10089704180703, \"u\": 10089704200214, \"pu\": 10089704180644, \"b\": [[\"1000.00\", \"26.792\"], [\"5000.00\", \"101.418\"], [\"19867.10\", \"0.240\"], [\"20067.10\", \"0.880\"], [\"20167.10\", \"1.120\"], [\"20267.10\", \"0.760\"], [\"40000.00\", \"50.271\"], [\"66816.50\", \"0.005\"], [\"68893.00\", \"0.010\"], [\"69370.60\", \"1.224\"], [\"69663.40\", \"0.000\"], [\"69892.50\", \"0.010\"], [\"70073.70\", \"0.012\"], [\"70093.60\", \"0.000\"], [\"70094.20\", \"26.201\"], [\"70094.30\", \"5.214\"], [\"70196.60\", \"23.351\"], [\"70232.10\", \"0.305\"], [\"70259.00\", \"2.370\"], [\"70259.10\", \"0.122\"], [\"70262.50\", \"0.571\"], [\"70264.80\", \"2.756\"], [\"70265.80\", \"0.939\"], [\"70272.70\", \"0.252\"], [\"70278.70\", \"0.002\"], [\"70279.10\", \"0.201\"], [\"70279.80\", \"0.245\"], [\"70281.50\", \"0.008\"], [\"70282.20\", \"0.007\"], [\"70284.90\", \"0.020\"], [\"70285.80\", \"0.008\"], [\"70286.80\", \"0.532\"], [\"70292.80\", \"0.004\"], [\"70297.00\", \"0.066\"], [\"70297.10\", \"0.000\"], [\"70311.20\", \"0.020\"], [\"70312.30\", \"0.001\"], [\"70314.50\", \"0.002\"], [\"70314.90\", \"0.005\"], [\"70320.80\", \"0.008\"], [\"70321.80\", \"0.493\"], [\"70331.00\", \"0.008\"], [\"70333.10\", \"0.002\"], [\"70333.20\", \"2.087\"], [\"70333.70\", \"0.000\"], [\"70333.80\", \"0.002\"], [\"70333.90\", \"0.038\"], [\"70334.50\", \"0.513\"], [\"70334.60\", \"0.000\"], [\"70335.20\", \"0.353\"], [\"70335.30\", \"0.020\"], [\"70336.60\", \"0.303\"], [\"70336.70\", \"0.390\"], [\"70337.30\", \"0.009\"], [\"70337.40\", \"0.002\"], [\"70338.00\", \"0.005\"], [\"70338.10\", \"0.000\"], [\"70338.30\", \"0.066\"], [\"70338.40\", \"0.000\"], [\"70338.70\", \"0.008\"], [\"70338.80\", \"0.004\"], [\"70339.00\", \"0.647\"], [\"70342.00\", \"0.520\"], [\"70342.10\", \"0.256\"], [\"70342.30\", \"0.053\"], [\"70342.50\", \"0.003\"], [\"70343.00\", \"0.004\"], [\"70343.30\", \"0.123\"], [\"70344.10\", \"0.007\"], [\"70344.40\", \"0.002\"], [\"70345.50\", \"0.648\"], [\"70345.60\", \"0.004\"], [\"70345.70\", \"0.000\"], [\"70345.90\", \"0.002\"], [\"70346.50\", \"0.002\"], [\"70346.60\", \"0.287\"], [\"70346.80\", \"0.000\"], [\"70346.90\", \"0.003\"], [\"70347.20\", \"0.003\"], [\"70347.40\", \"0.511\"], [\"70347.50\", \"0.002\"], [\"70347.80\", \"0.000\"], [\"70347.90\", \"0.028\"], [\"70348.00\", \"0.029\"], [\"70348.20\", \"0.031\"], [\"70348.30\", \"0.002\"], [\"70348.40\", \"0.000\"], [\"70348.60\", \"0.008\"], [\"70349.00\", \"0.079\"], [\"70349.50\", \"0.464\"], [\"70349.70\", \"0.035\"], [\"70349.80\", \"0.489\"], [\"70349.90\", \"0.000\"], [\"70350.10\", \"0.090\"], [\"70350.20\", \"0.197\"], [\"70350.40\", \"0.511\"], [\"70350.70\", \"0.005\"], [\"70351.30\", \"0.005\"], [\"70351.40\", \"0.148\"], [\"70351.50\", \"0.085\"], [\"70351.60\", \"0.135\"], [\"70351.70\", \"0.003\"], [\"70351.80\", \"0.006\"], [\"70351.90\", \"0.098\"], [\"70352.00\", \"0.000\"], [\"70352.10\", \"0.001\"], [\"70352.30\", \"0.002\"], [\"70352.70\", \"0.200\"], [\"70353.00\", \"0.502\"], [\"70353.10\", \"1.238\"], [\"70353.60\", \"0.470\"], [\"70354.00\", \"0.000\"], [\"70354.70\", \"0.177\"], [\"70354.80\", \"0.026\"], [\"70355.00\", \"0.206\"], [\"70355.10\", \"0.427\"], [\"70355.20\", \"0.074\"], [\"70355.60\", \"0.045\"], [\"70355.70\", \"0.018\"], [\"70355.90\", \"0.001\"], [\"70356.20\", \"0.099\"], [\"70356.30\", \"0.407\"], [\"70356.40\", \"1.067\"], [\"70356.50\", \"0.058\"], [\"70356.60\", \"0.021\"], [\"70356.90\", \"0.176\"], [\"70357.00\", \"0.114\"], [\"70357.10\", \"0.006\"], [\"70357.20\", \"0.459\"], [\"70357.40\", \"0.000\"], [\"70357.90\", \"0.019\"], [\"70359.20\", \"0.047\"], [\"70359.90\", \"0.205\"], [\"70360.10\", \"0.000\"], [\"70360.30\", \"0.267\"], [\"70360.50\", \"0.230\"], [\"70360.60\", \"0.398\"], [\"70367.00\", \"0.064\"], [\"70367.10\", \"3.883\"]], \"a\": [[\"70367.20\", \"48.437\"], [\"70368.20\", \"0.000\"], [\"70368.40\", \"0.096\"], [\"70369.60\", \"0.034\"], [\"70370.30\", \"0.052\"], [\"70370.50\", \"0.002\"], [\"70371.50\", \"0.002\"], [\"70371.70\", \"0.002\"], [\"70372.30\", \"0.003\"], [\"70372.40\", \"0.000\"], [\"70373.00\", \"0.006\"], [\"70373.10\", \"0.000\"], [\"70373.20\", \"0.008\"], [\"70373.50\", \"0.000\"], [\"70373.60\", \"0.000\"], [\"70373.70\", \"0.003\"], [\"70374.10\", \"0.000\"], [\"70374.40\", \"0.004\"], [\"70374.80\", \"0.000\"], [\"70375.20\", \"0.002\"], [\"70375.30\", \"0.000\"], [\"70375.60\", \"0.003\"], [\"70376.00\", \"0.000\"], [\"70376.20\", \"0.020\"], [\"70376.90\", \"0.098\"], [\"70377.20\", \"0.004\"], [\"70377.40\", \"0.000\"], [\"70377.50\", \"0.003\"], [\"70377.60\", \"0.000\"], [\"70377.70\", \"0.000\"], [\"70377.90\", \"0.006\"], [\"70378.10\", \"0.002\"], [\"70378.20\", \"0.002\"], [\"70378.30\", \"0.006\"], [\"70378.40\", \"0.005\"], [\"70378.50\", \"0.007\"], [\"70378.70\", \"0.000\"], [\"70378.80\", \"0.004\"], [\"70378.90\", \"0.007\"], [\"70379.00\", \"0.004\"], [\"70379.20\", \"0.000\"], [\"70379.30\", \"0.000\"], [\"70379.60\", \"0.005\"], [\"70379.70\", \"0.003\"], [\"70379.80\", \"0.199\"], [\"70379.90\", \"0.005\"], [\"70380.30\", \"0.000\"], [\"70380.40\", \"0.000\"], [\"70380.70\", \"0.002\"], [\"70381.00\", \"0.003\"], [\"70381.50\", \"0.616\"], [\"70381.60\", \"0.007\"], [\"70382.10\", \"0.002\"], [\"70382.20\", \"0.000\"], [\"70382.30\", \"0.004\"], [\"70382.40\", \"0.649\"], [\"70382.50\", \"0.005\"], [\"70383.00\", \"0.005\"], [\"70383.10\", \"0.094\"], [\"70383.20\", \"0.026\"], [\"70383.30\", \"0.000\"], [\"70383.60\", \"0.248\"], [\"70383.70\", \"0.027\"], [\"70383.80\", \"0.030\"], [\"70384.00\", \"0.007\"], [\"70384.10\", \"0.002\"], [\"70385.20\", \"0.005\"], [\"70385.50\", \"0.000\"], [\"70385.60\", \"0.142\"], [\"70385.80\", \"0.004\"], [\"70386.10\", \"0.007\"], [\"70386.40\", \"0.000\"], [\"70386.50\", \"0.000\"], [\"70386.70\", \"0.388\"], [\"70386.80\", \"0.056\"], [\"70387.10\", \"0.007\"], [\"70387.20\", \"0.289\"], [\"70388.10\", \"0.511\"], [\"70388.20\", \"0.011\"], [\"70388.70\", \"0.248\"], [\"70389.20\", \"0.073\"], [\"70390.30\", \"0.007\"], [\"70390.40\", \"0.008\"], [\"70391.30\", \"0.017\"], [\"70392.80\", \"0.393\"], [\"70396.60\", \"0.094\"], [\"70396.90\", \"0.005\"], [\"70397.00\", \"0.000\"], [\"70397.60\", \"0.067\"], [\"70397.70\", \"0.000\"], [\"70398.30\", \"0.240\"], [\"70398.40\", \"0.250\"], [\"70399.00\", \"0.002\"], [\"70399.10\", \"0.000\"], [\"70399.70\", \"0.013\"], [\"70399.80\", \"0.011\"], [\"70400.40\", \"0.007\"], [\"70400.50\", \"0.433\"], [\"70401.10\", \"0.208\"], [\"70401.20\", \"0.006\"], [\"70403.10\", \"0.048\"], [\"70403.20\", \"0.000\"], [\"70403.30\", \"0.115\"], [\"70403.90\", \"0.000\"], [\"70404.00\", \"0.386\"], [\"70404.30\", \"0.071\"], [\"70405.30\", \"0.002\"], [\"70405.40\", \"0.002\"], [\"70405.90\", \"0.022\"], [\"70406.00\", \"1.082\"], [\"70406.10\", \"0.002\"], [\"70409.50\", \"0.793\"], [\"70412.00\", \"0.002\"], [\"70415.10\", \"0.584\"], [\"70415.40\", \"0.558\"], [\"70421.20\", \"0.111\"], [\"70422.50\", \"0.081\"], [\"70422.80\", \"0.416\"], [\"70422.90\", \"0.002\"], [\"70423.00\", \"0.019\"], [\"70423.20\", \"0.005\"], [\"70423.50\", \"0.002\"], [\"70423.60\", \"0.320\"], [\"70428.90\", \"0.029\"], [\"70431.40\", \"0.754\"], [\"70434.50\", \"0.554\"], [\"70435.70\", \"0.003\"], [\"70441.70\", \"0.024\"], [\"70442.10\", \"0.146\"], [\"70442.50\", \"0.003\"], [\"70442.70\", \"0.000\"], [\"70444.80\", \"1.786\"], [\"70448.10\", \"1.255\"], [\"70449.10\", \"0.337\"], [\"70455.10\", \"0.000\"], [\"70456.20\", \"0.433\"], [\"70462.20\", \"0.092\"], [\"70473.50\", \"2.756\"], [\"70512.80\", \"0.081\"], [\"70514.20\", \"0.009\"], [\"70519.80\", \"0.019\"], [\"70521.20\", \"0.518\"], [\"70526.80\", \"0.000\"], [\"70528.20\", \"0.093\"], [\"70533.80\", \"0.002\"], [\"70535.20\", \"0.007\"], [\"70540.80\", \"0.003\"], [\"70542.20\", \"0.013\"], [\"70547.80\", \"0.000\"], [\"70548.90\", \"0.081\"], [\"70549.20\", \"0.007\"], [\"70554.80\", \"0.000\"], [\"70556.20\", \"0.018\"], [\"70560.00\", \"4.708\"], [\"70561.80\", \"0.000\"], [\"70563.20\", \"0.017\"], [\"70566.00\", \"0.124\"], [\"70569.90\", \"0.207\"], [\"70626.70\", \"26.380\"], [\"70631.60\", \"0.000\"], [\"70632.10\", \"0.006\"], [\"70841.70\", \"0.000\"], [\"71070.90\", \"1.454\"], [\"71073.90\", \"0.049\"], [\"71370.70\", \"0.981\"], [\"100000.00\", \"15.487\"]]}", "symbol": "BTCUSDT"}
{"event": "depthUpdate", "raw_payload": "{\"e\": \"depthUpdate\", \"E\": 1773246388622, \"T\": 1773246388620, \"s\": \"BTCUSDT\", \"U\": 10089704200307, \"u\": 10089704231576, \"pu\": 10089704200214, \"b\": [[\"5000.00\", \"101.418\"], [\"19867.10\", \"0.150\"], [\"20067.10\", \"1.070\"], [\"20167.10\", \"0.930\"], [\"20267.10\", \"0.850\"], [\"63430.70\", \"0.008\"], [\"66818.40\", \"0.004\"], [\"69069.20\", \"0.002\"], [\"69245.40\", \"0.002\"], [\"69270.70\", \"0.000\"], [\"69421.60\", \"0.013\"], [\"69597.80\", \"0.002\"], [\"69663.40\", \"0.000\"], [\"70015.30\", \"0.044\"], [\"70037.70\", \"0.015\"], [\"70084.90\", \"10.000\"], [\"70162.50\", \"0.002\"], [\"70164.80\", \"0.000\"], [\"70167.20\", \"0.000\"], [\"70168.00\", \"0.526\"], [\"70168.80\", \"0.000\"], [\"70177.60\", \"1.797\"], [\"70186.90\", \"0.283\"], [\"70193.60\", \"6.335\"], [\"70195.20\", \"0.000\"], [\"70200.10\", \"0.038\"], [\"70202.40\", \"3.361\"], [\"70202.50\", \"0.000\"], [\"70224.10\", \"0.000\"], [\"70224.40\", \"0.000\"], [\"70224.70\", \"0.000\"], [\"70228.00\", \"0.000\"], [\"70240.70\", \"0.257\"], [\"70240.80\", \"0.039\"], [\"70242.20\", \"0.083\"], [\"70257.20\", \"0.362\"], [\"70263.90\", \"0.247\"], [\"70269.90\", \"0.076\"], [\"70273.00\", \"0.256\"], [\"70279.10\", \"0.419\"], [\"70280.00\", \"1.430\"], [\"70283.00\", \"0.000\"], [\"70284.10\", \"0.002\"], [\"70284.90\", \"0.002\"], [\"70285.60\", \"0.010\"], [\"70286.30\", \"0.055\"], [\"70288.30\", \"0.039\"], [\"70288.60\", \"0.039\"], [\"70293.30\", \"1.117\"], [\"70294.80\", \"0.344\"], [\"70295.50\", \"0.511\"], [\"70296.00\", \"0.006\"], [\"70296.20\", \"0.000\"], [\"70296.50\", \"0.207\"], [\"70296.90\", \"0.278\"], [\"70297.30\", \"0.242\"], [\"70298.50\", \"0.000\"], [\"70299.00\", \"0.189\"], [\"70301.40\", \"0.041\"], [\"70301.60\", \"0.000\"], [\"70303.70\", \"0.006\"], [\"70307.20\", \"0.851\"], [\"70307.30\", \"0.342\"], [\"70308.60\", \"0.076\"], [\"70310.70\", \"0.072\"], [\"70311.80\", \"0.111\"], [\"70313.50\", \"0.000\"], [\"70314.50\", \"0.000\"], [\"70314.90\", \"0.003\"], [\"70315.20\", \"0.577\"], [\"70315.40\", \"0.398\"], [\"70315.70\", \"0.391\"], [\"70317.00\", \"0.008\"], [\"70317.80\", \"0.222\"], [\"70322.20\", \"0.047\"], [\"70323.10\", \"1.479\"], [\"70324.30\", \"0.003\"], [\"70325.70\", \"0.000\"], [\"70326.60\", \"0.006\"], [\"70328.40\", \"0.033\"], [\"70329.00\", \"0.030\"], [\"70329.30\", \"0.000\"], [\"70330.50\", \"0.000\"], [\"70330.70\", \"0.004\"], [\"70333.30\", \"0.004\"], [\"70333.40\", \"0.004\"], [\"70334.50\", \"0.511\"], [\"70334.90\", \"0.116\"], [\"70335.80\", \"0.002\"], [\"70335.90\", \"0.043\"], [\"70336.00\", \"0.090\"], [\"70336.20\", \"0.005\"], [\"70336.60\", \"0.305\"], [\"70336.70\", \"0.392\"], [\"70337.30\", \"0.007\"], [\"70337.40\", \"0.000\"], [\"70337.60\", \"0.008\"], [\"70338.30\", \"0.014\"], [\"70338.90\", \"0.002\"], [\"70339.10\", \"0.266\"], [\"70340.20\", \"0.000\"], [\"70340.60\", \"0.000\"], [\"70340.90\", \"0.005\"], [\"70342.00\", \"0.009\"], [\"70342.80\", \"0.171\"], [\"70342.90\", \"1.066\"], [\"70343.30\", \"0.002\"], [\"70343.50\", \"0.002\"], [\"70343.70\", \"0.015\"], [\"70343.90\", \"0.002\"], [\"70344.10\", \"0.059\"], [\"70344.30\", \"0.084\"], [\"70344.80\", \"0.003\"], [\"70345.30\", \"0.000\"], [\"70345.50\", \"0.007\"], [\"70346.70\", \"0.342\"], [\"70347.20\", \"0.032\"], [\"70347.50\", \"0.513\"], [\"70347.90\", \"0.000\"], [\"70348.00\", \"0.008\"], [\"70348.20\", \"0.003\"], [\"70348.50\", \"0.012\"], [\"70349.10\", \"0.057\"], [\"70349.20\", \"0.004\"], [\"70349.50\", \"0.075\"], [\"70349.80\", \"0.005\"], [\"70350.20\", \"0.177\"], [\"70350.80\", \"0.010\"], [\"70350.90\", \"0.235\"], [\"70351.10\", \"0.002\"], [\"70351.20\", \"0.091\"], [\"70351.30\", \"0.008\"], [\"70351.40\", \"0.127\"], [\"70351.50\", \"0.042\"], [\"70351.60\", \"0.121\"], [\"70351.70\", \"0.023\"], [\"70351.80\", \"0.490\"], [\"70351.90\", \"0.064\"], [\"70352.40\", \"0.071\"], [\"70352.60\", \"0.214\"], [\"70352.70\", \"0.732\"], [\"70352.80\", \"0.344\"], [\"70352.90\", \"0.127\"], [\"70353.00\", \"0.769\"], [\"70353.10\", \"1.846\"], [\"70353.30\", \"0.002\"], [\"70353.40\", \"0.024\"], [\"70353.50\", \"0.862\"], [\"70353.60\", \"0.014\"], [\"70354.20\", \"0.138\"], [\"70354.30\", \"0.018\"], [\"70354.60\", \"0.002\"], [\"70354.70\", \"0.003\"], [\"70354.80\", \"0.000\"], [\"70354.90\", \"0.463\"], [\"70355.00\", \"0.206\"], [\"70355.10\", \"0.049\"], [\"70355.20\", \"0.017\"], [\"70355.60\", \"0.002\"], [\"70355.70\", \"0.011\"], [\"70355.80\", \"0.000\"], [\"70356.10\", \"0.024\"], [\"70356.30\", \"0.206\"], [\"70356.40\", \"1.067\"], [\"70356.50\", \"0.447\"], [\"70356.60\", \"0.006\"], [\"70356.70\", \"0.032\"], [\"70356.90\", \"0.217\"], [\"70357.00\", \"0.031\"], [\"70357.10\", \"0.014\"], [\"70357.20\", \"0.001\"], [\"70357.30\", \"0.091\"], [\"70357.40\", \"0.000\"], [\"70357.70\", \"0.101\"], [\"70357.90\", \"0.016\"], [\"70358.20\", \"0.098\"], [\"70358.70\", \"0.008\"], [\"70359.00\", \"0.121\"], [\"70359.10\", \"0.143\"], [\"70359.20\", \"0.000\"], [\"70359.50\", \"0.000\"], [\"70359.60\", \"0.005\"], [\"70359.70\", \"0.000\"], [\"70359.80\", \"0.000\"], [\"70359.90\", \"0.205\"], [\"70360.00\", \"0.005\"], [\"70360.30\", \"0.272\"], [\"70360.40\", \"0.103\"], [\"70360.50\", \"0.216\"], [\"70360.60\", \"0.343\"], [\"70360.70\", \"0.007\"], [\"70360.80\", \"0.003\"], [\"70361.20\", \"0.050\"], [\"70361.30\", \"0.402\"], [\"70361.70\", \"0.001\"], [\"70361.80\", \"0.002\"], [\"70362.10\", \"0.003\"], [\"70362.40\", \"0.105\"], [\"70362.50\", \"0.005\"], [\"70362.60\", \"0.429\"], [\"70362.70\", \"0.301\"], [\"70363.20\", \"0.002\"], [\"70363.50\", \"0.200\"], [\"70363.60\", \"0.010\"], [\"70363.70\", \"0.014\"], [\"70364.00\", \"0.555\"], [\"70365.50\", \"0.002\"], [\"70365.90\", \"0.005\"], [\"70366.90\", \"0.592\"], [\"70367.00\", \"0.066\"], [\"70367.10\", \"4.782\"]], \"a\": [[\"70367.20\", \"37.015\"], [\"70367.30\", \"0.005\"], [\"70367.40\", \"0.002\"], [\"70367.50\", \"0.000\"], [\"70368.10\", \"0.004\"], [\"70368.30\", \"0.004\"], [\"70369.00\", \"0.002\"], [\"70369.60\", \"0.000\"], [\"70369.80\", \"0.002\"], [\"70370.30\", \"0.003\"], [\"70371.60\", \"0.008\"], [\"70372.50\", \"0.016\"], [\"70374.20\", \"0.039\"], [\"70374.50\", \"0.029\"], [\"70375.10\", \"0.003\"], [\"70375.20\", \"0.011\"], [\"70375.40\", \"0.005\"], [\"70375.60\", \"0.000\"], [\"70376.20\", \"0.010\"], [\"70376.50\", \"0.005\"], [\"70376.90\", \"0.002\"], [\"70377.30\", \"0.397\"], [\"70377.80\", \"0.003\"], [\"70377.90\", \"0.003\"], [\"70378.50\", \"0.005\"], [\"70378.90\", \"0.007\"], [\"70379.00\", \"0.001\"], [\"70379.50\", \"0.001\"], [\"70379.60\", \"0.002\"], [\"70379.70\", \"0.000\"], [\"70379.80\", \"0.000\"], [\"70379.90\", \"0.002\"], [\"70380.20\", \"0.071\"], [\"70380.40\", \"0.044\"], [\"70380.50\", \"0.096\"], [\"70380.80\", \"0.078\"], [\"70380.90\", \"0.109\"], [\"70381.00\", \"0.003\"], [\"70381.50\", \"0.002\"], [\"70381.60\", \"0.367\"], [\"70381.70\", \"0.524\"], [\"70381.90\", \"0.000\"], [\"70382.30\", \"0.001\"], [\"70382.40\", \"0.010\"], [\"70382.50\", \"0.002\"], [\"70382.80\", \"0.000\"], [\"70383.10\", \"0.000\"], [\"70383.20\", \"0.026\"], [\"70383.40\", \"0.002\"], [\"70383.50\", \"0.003\"], [\"70383.60\", \"0.042\"], [\"70383.90\", \"0.550\"], [\"70384.00\", \"0.012\"], [\"70384.20\", \"0.009\"], [\"70384.40\", \"0.033\"], [\"70384.70\", \"0.494\"], [\"70384.90\", \"0.007\"], [\"70385.00\", \"0.636\"], [\"70385.10\", \"1.073\"], [\"70385.30\", \"0.005\"], [\"70385.60\", \"0.000\"], [\"70386.00\", \"0.000\"], [\"70386.10\", \"0.895\"], [\"70386.30\", \"0.002\"], [\"70386.50\", \"0.000\"], [\"70386.60\", \"0.002\"], [\"70386.70\", \"0.004\"], [\"70386.90\", \"0.233\"], [\"70387.10\", \"0.000\"], [\"70387.20\", \"0.005\"], [\"70387.30\", \"0.002\"], [\"70387.50\", \"0.197\"], [\"70387.60\", \"0.000\"], [\"70388.10\", \"0.000\"], [\"70388.20\", \"0.013\"], [\"70388.50\", \"0.008\"], [\"70388.70\", \"0.000\"], [\"70388.90\", \"0.000\"], [\"70389.20\", \"0.071\"], [\"70389.30\", \"0.000\"], [\"70389.60\", \"0.002\"], [\"70390.00\", \"0.641\"], [\"70390.30\", \"0.000\"], [\"70390.40\", \"0.008\"], [\"70390.50\", \"0.511\"], [\"70390.70\", \"0.125\"], [\"70390.80\", \"0.057\"], [\"70391.20\", \"0.002\"], [\"70391.40\", \"0.005\"], [\"70391.50\", \"0.059\"], [\"70391.70\", \"0.002\"], [\"70392.30\", \"0.230\"], [\"70392.50\", \"0.040\"], [\"70392.70\", \"0.184\"], [\"70392.80\", \"0.322\"], [\"70393.60\", \"0.003\"], [\"70393.80\", \"0.212\"], [\"70393.90\", \"0.079\"], [\"70394.20\", \"0.090\"], [\"70394.40\", \"0.042\"], [\"70394.50\", \"0.005\"], [\"70394.80\", \"0.201\"], [\"70394.90\", \"0.000\"], [\"70395.50\", \"0.015\"], [\"70395.80\", \"0.000\"], [\"70396.60\", \"0.217\"], [\"70397.10\", \"0.000\"], [\"70397.40\", \"0.003\"], [\"70397.90\", \"0.002\"], [\"70398.30\", \"0.488\"], [\"70398.70\", \"0.000\"], [\"70398.90\", \"0.010\"], [\"70399.50\", \"0.531\"], [\"70399.70\", \"0.004\"], [\"70399.80\", \"0.002\"], [\"70400.10\", \"0.000\"], [\"70400.40\", \"0.007\"], [\"70400.50\", \"0.433\"], [\"70400.60\", \"0.014\"], [\"70400.70\", \"0.000\"], [\"70400.80\", \"0.000\"], [\"70401.10\", \"0.206\"], [\"70401.20\", \"0.002\"], [\"70401.80\", \"0.009\"], [\"70401.90\", \"0.009\"], [\"70402.20\", \"0.071\"], [\"70402.50\", \"0.010\"], [\"70402.60\", \"0.147\"], [\"70403.10\", \"0.004\"], [\"70403.20\", \"0.002\"], [\"70403.30\", \"0.117\"], [\"70403.60\", \"0.001\"], [\"70404.90\", \"0.002\"], [\"70405.20\", \"0.003\"], [\"70405.80\", \"0.003\"], [\"70405.90\", \"0.002\"], [\"70406.00\", \"1.080\"], [\"70406.10\", \"0.052\"], [\"70406.70\", \"0.000\"], [\"70406.80\", \"0.004\"], [\"70407.20\", \"0.003\"], [\"70407.40\", \"0.002\"], [\"70407.50\", \"0.004\"], [\"70407.70\", \"0.011\"], [\"70407.90\", \"0.005\"], [\"70408.10\", \"0.000\"], [\"70408.20\", \"0.586\"], [\"70408.80\", \"0.005\"], [\"70408.90\", \"0.004\"], [\"70409.10\", \"0.006\"], [\"70409.80\", \"0.003\"], [\"70410.70\", \"0.086\"], [\"70411.40\", \"0.096\"], [\"70411.60\", \"0.002\"], [\"70412.30\", \"0.003\"], [\"70412.60\", \"0.007\"], [\"70413.70\", \"0.001\"], [\"70414.30\", \"0.047\"], [\"70414.80\", \"0.026\"], [\"70415.40\", \"0.513\"], [\"70416.90\", \"0.000\"], [\"70417.10\", \"0.000\"], [\"70417.80\", \"0.003\"], [\"70418.20\", \"0.012\"], [\"70418.30\", \"0.003\"], [\"70418.40\", \"0.193\"], [\"70420.40\", \"0.910\"], [\"70420.50\", \"0.048\"], [\"70421.10\", \"0.259\"], [\"70422.10\", \"0.020\"], [\"70422.50\", \"0.000\"], [\"70423.20\", \"0.008\"], [\"70423.50\", \"0.047\"], [\"70423.60\", \"0.192\"], [\"70423.90\", \"0.065\"], [\"70424.80\", \"0.000\"], [\"70425.90\", \"0.530\"], [\"70426.50\", \"0.087\"], [\"70426.90\", \"0.022\"], [\"70427.00\", \"0.004\"], [\"70427.30\", \"0.200\"], [\"70428.60\", \"0.000\"], [\"70429.30\", \"0.002\"], [\"70430.30\", \"0.128\"], [\"70432.80\", \"0.000\"], [\"70433.60\", \"0.081\"], [\"70434.60\", \"0.513\"], [\"70435.20\", \"0.093\"], [\"70435.50\", \"0.001\"], [\"70435.90\", \"0.156\"], [\"70436.70\", \"0.256\"], [\"70438.90\", \"0.002\"], [\"70439.60\", \"0.192\"], [\"70439.90\", \"0.000\"], [\"70441.10\", \"0.102\"], [\"70441.80\", \"0.004\"], [\"70442.50\", \"0.000\"], [\"70442.60\", \"0.181\"], [\"70444.30\", \"0.002\"], [\"70444.80\", \"1.867\"], [\"70448.90\", \"0.000\"], [\"70455.80\", \"0.000\"], [\"70456.60\", \"0.684\"], [\"70456.80\", \"0.002\"], [\"70457.80\", \"0.007\"], [\"70458.20\", \"0.000\"], [\"70458.60\", \"0.204\"], [\"70459.20\", \"0.002\"], [\"70460.70\", \"0.000\"], [\"70461.10\", \"0.575\"], [\"70461.20\", \"0.000\"], [\"70461.40\", \"0.000\"], [\"70462.20\", \"0.006\"], [\"70463.10\", \"0.009\"], [\"70463.30\", \"0.000\"], [\"70465.90\", \"0.000\"], [\"70466.60\", \"0.089\"], [\"70475.30\", \"0.002\"], [\"70479.10\", \"0.115\"], [\"70480.90\", \"0.129\"], [\"70487.20\", \"0.029\"], [\"70492.20\", \"2.000\"], [\"70499.00\", \"0.489\"], [\"70505.10\", \"0.081\"], [\"70508.30\", \"0.001\"], [\"70508.90\", \"0.039\"], [\"70510.30\", \"0.187\"], [\"70511.40\", \"0.970\"], [\"70513.90\", \"0.226\"], [\"70514.00\", \"0.000\"], [\"70517.50\", \"0.190\"], [\"70519.40\", \"0.039\"], [\"70520.80\", \"0.000\"], [\"70521.10\", \"0.000\"], [\"70521.80\", \"10.000\"], [\"70522.00\", \"2.823\"], [\"70523.70\", \"0.093\"], [\"70525.70\", \"0.008\"], [\"70528.30\", \"0.039\"], [\"70532.40\", \"1.686\"], [\"70534.20\", \"0.120\"], [\"70535.70\", \"0.026\"], [\"70542.20\", \"0.094\"], [\"70542.70\", \"0.132\"], [\"70544.50\", \"0.081\"], [\"70544.80\", \"0.075\"], [\"70545.40\", \"0.247\"], [\"70546.80\", \"0.058\"], [\"70547.80\", \"0.081\"], [\"70549.20\", \"0.046\"], [\"70551.80\", \"0.000\"], [\"70553.30\", \"0.039\"], [\"70576.00\", \"0.007\"], [\"70578.40\", \"0.019\"], [\"70592.80\", \"0.004\"], [\"70602.60\", \"0.000\"], [\"70611.60\", \"0.279\"], [\"70841.60\", \"0.008\"], [\"71070.90\", \"1.454\"], [\"89523.20\", \"0.000\"]]}", "symbol": "BTCUSDT"}
{"event": "depthUpdate", "raw_payload": "{\"e\": \"depthUpdate\", \"E\": 1773246388724, \"T\": 1773246388723, \"s\": \"BTCUSDT\", \"U\": 10089704231964, \"u\": 10089704243096, \"pu\": 10089704231576, \"b\": [[\"1000.00\", \"26.792\"], [\"5000.00\", \"101.398\"], [\"19867.10\", \"0.060\"], [\"20067.10\", \"1.230\"], [\"20167.10\", \"0.770\"], [\"20267.10\", \"0.940\"], [\"66834.20\", \"0.004\"], [\"69663.40\", \"0.000\"], [\"69860.60\", \"3.720\"], [\"70038.50\", \"1.320\"], [\"70063.30\", \"0.000\"], [\"70066.40\", \"0.003\"], [\"70086.50\", \"0.007\"], [\"70100.00\", \"6.452\"], [\"70132.70\", \"0.000\"], [\"70164.00\", \"0.306\"], [\"70187.00\", \"0.025\"], [\"70215.20\", \"0.202\"], [\"70238.90\", \"0.086\"], [\"70242.20\", \"0.083\"], [\"70251.20\", \"0.029\"], [\"70257.40\", \"6.942\"], [\"70264.60\", \"0.000\"], [\"70265.00\", \"0.039\"], [\"70277.60\", \"0.025\"], [\"70278.00\", \"0.549\"], [\"70287.40\", \"6.546\"], [\"70291.70\", \"0.049\"], [\"70292.20\", \"1.073\"], [\"70292.70\", \"0.003\"], [\"70295.40\", \"3.675\"], [\"70297.30\", \"0.194\"], [\"70298.50\", \"0.000\"], [\"70306.10\", \"0.260\"], [\"70306.50\", \"0.020\"], [\"70307.10\", \"0.030\"], [\"70308.00\", \"0.094\"], [\"70315.20\", \"0.575\"], [\"70315.40\", \"0.400\"], [\"70319.10\", \"1.902\"], [\"70322.70\", \"0.007\"], [\"70323.10\", \"1.423\"], [\"70325.20\", \"0.191\"], [\"70326.60\", \"0.006\"], [\"70327.30\", \"0.056\"], [\"70332.00\", \"0.011\"], [\"70335.30\", \"0.268\"], [\"70335.80\", \"0.002\"], [\"70337.00\", \"0.007\"], [\"70337.20\", \"0.118\"], [\"70338.00\", \"0.014\"], [\"70339.10\", \"0.018\"], [\"70344.00\", \"0.000\"], [\"70346.00\", \"0.217\"], [\"70347.20\", \"0.030\"], [\"70347.60\", \"0.000\"], [\"70348.40\", \"0.071\"], [\"70348.60\", \"0.011\"], [\"70348.80\", \"0.641\"], [\"70350.10\", \"0.055\"], [\"70350.80\", \"0.008\"], [\"70351.50\", \"0.042\"], [\"70351.70\", \"0.030\"], [\"70352.40\", \"0.000\"], [\"70353.10\", \"0.000\"], [\"70353.90\", \"0.080\"], [\"70354.20\", \"0.017\"], [\"70354.90\", \"0.465\"], [\"70355.00\", \"0.241\"], [\"70355.10\", \"0.529\"], [\"70356.40\", \"2.274\"], [\"70356.50\", \"0.444\"], [\"70357.00\", \"0.017\"], [\"70357.30\", \"0.000\"], [\"70358.50\", \"0.080\"], [\"70360.00\", \"0.005\"], [\"70362.70\", \"0.205\"], [\"70363.30\", \"0.003\"], [\"70363.70\", \"0.000\"], [\"70364.00\", \"0.555\"], [\"70364.70\", \"0.008\"], [\"70365.60\", \"0.005\"], [\"70366.40\", \"0.007\"], [\"70366.50\", \"0.015\"], [\"70366.70\", \"0.015\"], [\"70367.10\", \"4.690\"]], \"a\": [[\"70367.20\", \"37.018\"], [\"70367.30\", \"0.007\"], [\"70367.40\", \"0.004\"], [\"70367.50\", \"0.002\"], [\"70369.80\", \"0.005\"], [\"70371.90\", \"0.021\"], [\"70374.20\", \"0.000\"], [\"70375.90\", \"0.001\"], [\"70376.70\", \"0.067\"], [\"70377.60\", \"0.085\"], [\"70377.80\", \"0.003\"], [\"70378.80\", \"0.004\"], [\"70379.70\", \"0.003\"], [\"70380.20\", \"0.000\"], [\"70381.80\", \"0.002\"], [\"70382.20\", \"0.002\"], [\"70385.70\", \"0.686\"], [\"70386.10\", \"0.523\"], [\"70386.90\", \"0.162\"], [\"70387.40\", \"0.350\"], [\"70388.20\", \"0.016\"], [\"70389.20\", \"0.001\"], [\"70389.60\", \"0.073\"], [\"70390.00\", \"0.002\"], [\"70390.70\", \"0.219\"], [\"70390.80\", \"0.432\"], [\"70391.50\", \"0.000\"], [\"70391.80\", \"0.002\"], [\"70392.30\", \"0.195\"], [\"70393.40\", \"0.000\"], [\"70393.80\", \"0.198\"], [\"70393.90\", \"0.008\"], [\"70395.00\", \"0.220\"], [\"70395.50\", \"0.002\"], [\"70395.80\", \"0.071\"], [\"70396.50\", \"0.007\"], [\"70397.10\", \"0.007\"], [\"70398.80\", \"0.520\"], [\"70401.80\", \"0.000\"], [\"70401.90\", \"0.011\"], [\"70402.30\", \"0.065\"], [\"70402.50\", \"0.019\"], [\"70402.60\", \"0.156\"], [\"70403.20\", \"0.000\"], [\"70403.30\", \"0.115\"], [\"70403.50\", \"0.014\"], [\"70403.90\", \"0.002\"], [\"70404.00\", \"0.388\"], [\"70404.50\", \"0.036\"], [\"70404.60\", \"10.242\"], [\"70405.30\", \"0.004\"], [\"70405.40\", \"0.022\"], [\"70406.50\", \"0.003\"], [\"70407.60\", \"0.013\"], [\"70407.70\", \"0.011\"], [\"70408.80\", \"0.003\"], [\"70408.90\", \"0.002\"], [\"70409.50\", \"0.795\"], [\"70409.60\", \"0.004\"], [\"70410.00\", \"0.013\"], [\"70412.50\", \"0.030\"], [\"70412.80\", \"0.216\"], [\"70414.30\", \"0.000\"], [\"70415.60\", \"0.022\"], [\"70418.00\", \"0.438\"], [\"70421.10\", \"0.198\"], [\"70421.50\", \"0.000\"], [\"70422.80\", \"0.000\"], [\"70423.50\", \"0.002\"], [\"70425.80\", \"1.066\"], [\"70426.90\", \"0.002\"], [\"70428.70\", \"0.003\"], [\"70428.90\", \"0.001\"], [\"70430.30\", \"0.000\"], [\"70430.50\", \"0.513\"], [\"70430.60\", \"2.885\"], [\"70432.70\", \"0.028\"], [\"70435.00\", \"0.201\"], [\"70435.20\", \"0.016\"], [\"70435.90\", \"0.156\"], [\"70441.30\", \"0.008\"], [\"70441.70\", \"0.004\"], [\"70443.30\", \"9.702\"], [\"70443.50\", \"0.000\"], [\"70444.20\", \"0.635\"], [\"70445.70\", \"0.417\"], [\"70448.30\", \"0.413\"], [\"70450.80\", \"0.007\"], [\"70455.70\", \"0.023\"], [\"70456.10\", \"0.020\"], [\"70456.60\", \"0.709\"], [\"70457.80\", \"0.082\"], [\"70464.10\", \"2.370\"], [\"70470.20\", \"0.087\"], [\"70470.90\", \"0.002\"], [\"70471.70\", \"0.145\"], [\"70482.40\", \"0.000\"], [\"70492.20\", \"2.000\"], [\"70495.40\", \"0.010\"], [\"70513.90\", \"0.208\"], [\"70521.70\", \"0.024\"], [\"70575.20\", \"0.000\"], [\"70604.00\", \"0.067\"], [\"70648.80\", \"0.006\"], [\"70841.60\", \"0.002\"], [\"70873.60\", \"3.720\"], [\"71070.90\", \"1.454\"], [\"71345.30\", \"1.609\"], [\"73892.30\", \"0.008\"]]}", "symbol": "BTCUSDT"}
{"event": "depthUpdate", "raw_payload": "{\"e\": \"depthUpdate\", \"E\": 1773246388826, \"T\": 1773246388824, \"s\": \"BTCUSDT\", \"U\": 10089704243120, \"u\": 10089704249329, \"pu\": 10089704243096, \"b\": [[\"1000.00\", \"26.792\"], [\"5000.00\", \"101.418\"], [\"19867.10\", \"0.000\"], [\"20067.10\", \"1.410\"], [\"20167.10\", \"0.610\"], [\"20267.10\", \"0.980\"], [\"33000.00\", \"10.797\"], [\"66822.30\", \"0.039\"], [\"66835.70\", \"0.000\"], [\"66835.80\", \"0.002\"], [\"69597.80\", \"0.004\"], [\"69663.40\", \"0.000\"], [\"69860.60\", \"0.000\"], [\"69862.90\", \"3.720\"], [\"70242.20\", \"0.086\"], [\"70295.80\", \"0.051\"], [\"70298.50\", \"0.003\"], [\"70300.50\", \"1.122\"], [\"70304.10\", \"0.150\"], [\"70309.00\", \"0.079\"], [\"70315.20\", \"0.005\"], [\"70315.40\", \"0.398\"], [\"70315.60\", \"0.193\"], [\"70321.40\", \"0.341\"], [\"70324.20\", \"0.116\"], [\"70324.90\", \"0.293\"], [\"70326.60\", \"0.009\"], [\"70332.00\", \"0.034\"], [\"70333.30\", \"0.252\"], [\"70335.30\", \"0.020\"], [\"70335.50\", \"0.050\"], [\"70335.70\", \"0.011\"], [\"70337.90\", \"0.000\"], [\"70339.00\", \"0.511\"], [\"70342.20\", \"0.052\"], [\"70342.70\", \"0.000\"], [\"70344.10\", \"0.007\"], [\"70344.90\", \"0.076\"], [\"70345.60\", \"0.515\"], [\"70346.20\", \"0.093\"], [\"70346.60\", \"0.003\"], [\"70347.00\", \"0.071\"], [\"70347.50\", \"0.641\"], [\"70348.40\", \"0.000\"], [\"70348.80\", \"0.002\"], [\"70348.90\", \"0.214\"], [\"70349.00\", \"0.047\"], [\"70349.10\", \"0.432\"], [\"70349.40\", \"0.578\"], [\"70349.60\", \"0.090\"], [\"70350.00\", \"0.008\"], [\"70350.10\", \"0.001\"], [\"70351.70\", \"0.023\"], [\"70352.80\", \"0.349\"], [\"70353.10\", \"0.007\"], [\"70353.50\", \"0.909\"], [\"70353.60\", \"0.144\"], [\"70353.80\", \"0.002\"], [\"70353.90\", \"0.152\"], [\"70354.60\", \"0.092\"], [\"70354.90\", \"0.463\"], [\"70356.10\", \"0.315\"], [\"70356.50\", \"0.659\"], [\"70357.90\", \"0.018\"], [\"70360.00\", \"0.005\"], [\"70360.70\", \"0.662\"], [\"70361.30\", \"0.005\"], [\"70362.60\", \"0.001\"], [\"70362.70\", \"0.169\"], [\"70363.30\", \"0.006\"], [\"70363.50\", \"0.202\"], [\"70364.00\", \"0.005\"], [\"70364.10\", \"0.000\"], [\"70366.90\", \"0.529\"], [\"70367.10\", \"4.033\"]], \"a\": [[\"70369.80\", \"0.009\"], [\"70369.90\", \"0.002\"], [\"70374.50\", \"0.004\"], [\"70375.20\", \"0.002\"], [\"70376.60\", \"0.036\"], [\"70376.80\", \"0.079\"], [\"70377.60\", \"0.014\"], [\"70377.80\", \"0.003\"], [\"70378.80\", \"0.004\"], [\"70378.90\", \"0.049\"], [\"70381.70\", \"0.524\"], [\"70382.20\", \"0.000\"], [\"70384.80\", \"0.106\"], [\"70387.40\", \"0.208\"], [\"70388.10\", \"0.142\"], [\"70390.40\", \"0.001\"], [\"70391.50\", \"0.291\"], [\"70392.60\", \"0.076\"], [\"70392.70\", \"0.943\"], [\"70394.70\", \"0.014\"], [\"70395.80\", \"0.000\"], [\"70396.50\", \"0.374\"], [\"70396.60\", \"0.177\"], [\"70396.80\", \"0.072\"], [\"70397.10\", \"0.000\"], [\"70397.60\", \"0.068\"], [\"70398.30\", \"0.240\"], [\"70398.80\", \"0.009\"], [\"70398.90\", \"0.112\"], [\"70401.30\", \"0.052\"], [\"70401.90\", \"0.045\"], [\"70402.20\", \"0.000\"], [\"70404.10\", \"0.415\"], [\"70406.10\", \"0.000\"], [\"70407.70\", \"0.014\"], [\"70409.00\", \"0.045\"], [\"70420.50\", \"0.015\"], [\"70424.70\", \"0.000\"], [\"70425.50\", \"0.000\"], [\"70426.30\", \"0.002\"], [\"70430.60\", \"2.757\"], [\"70431.50\", \"0.225\"], [\"70431.60\", \"0.034\"], [\"70432.80\", \"0.028\"], [\"70435.90\", \"0.005\"], [\"70440.90\", \"0.213\"], [\"70442.10\", \"0.004\"], [\"70449.10\", \"0.348\"], [\"70453.00\", \"10.368\"], [\"70456.20\", \"0.291\"], [\"70458.60\", \"0.201\"], [\"70460.00\", \"0.156\"], [\"70464.10\", \"2.008\"], [\"70467.10\", \"0.331\"], [\"70471.70\", \"0.131\"], [\"70471.80\", \"0.604\"], [\"70472.60\", \"0.746\"], [\"70473.60\", \"0.005\"], [\"70473.70\", \"0.005\"], [\"70480.50\", \"0.008\"], [\"70492.20\", \"2.003\"], [\"70521.40\", \"0.362\"], [\"70535.80\", \"0.828\"], [\"70536.30\", \"0.002\"], [\"70578.40\", \"0.000\"], [\"70593.10\", \"0.023\"], [\"70626.70\", \"0.000\"], [\"70711.20\", \"0.000\"], [\"70871.30\", \"3.942\"], [\"70873.60\", \"0.000\"], [\"71070.90\", \"1.454\"], [\"71317.20\", \"1.398\"], [\"73885.80\", \"0.000\"], [\"73900.00\", \"17.386\"], [\"89523.20\", \"0.000\"]]}", "symbol": "BTCUSDT"}
{"event": "depthUpdate", "raw_payload": "{\"e\": \"depthUpdate\", \"E\": 1773246388928, \"T\": 1773246388927, \"s\": \"BTCUSDT\", \"U\": 10089704249461, \"u\": 10089704253656, \"pu\": 10089704249329, \"b\": [[\"5000.00\", \"101.398\"], [\"20067.10\", \"1.570\"], [\"20167.10\", \"0.540\"], [\"20267.10\", \"0.890\"], [\"33000.00\", \"10.793\"], [\"63330.40\", \"0.002\"], [\"64700.00\", \"2.451\"], [\"66836.30\", \"0.002\"], [\"66848.00\", \"0.004\"], [\"69276.40\", \"2.009\"], [\"70015.30\", \"0.044\"], [\"70016.70\", \"0.000\"], [\"70017.20\", \"0.044\"], [\"70063.50\", \"0.241\"], [\"70086.50\", \"0.000\"], [\"70087.20\", \"1.775\"], [\"70132.90\", \"0.451\"], [\"70151.40\", \"0.232\"], [\"70196.00\", \"1.178\"], [\"70202.60\", \"13.542\"], [\"70262.50\", \"0.818\"], [\"70282.80\", \"0.521\"], [\"70300.00\", \"1.446\"], [\"70307.80\", \"1.454\"], [\"70315.60\", \"0.191\"], [\"70315.70\", \"0.393\"], [\"70328.40\", \"0.053\"], [\"70334.60\", \"0.560\"], [\"70347.30\", \"0.184\"], [\"70349.00\", \"0.000\"], [\"70349.10\", \"0.385\"], [\"70349.60\", \"0.047\"], [\"70350.60\", \"0.002\"], [\"70360.80\", \"0.431\"], [\"70361.40\", \"0.403\"], [\"70362.70\", \"0.282\"], [\"70363.30\", \"0.007\"]], \"a\": [[\"70367.20\", \"37.016\"], [\"70369.80\", \"0.012\"], [\"70374.20\", \"0.028\"], [\"70382.00\", \"0.005\"], [\"70390.70\", \"0.276\"], [\"70390.80\", \"0.375\"], [\"70391.20\", \"0.189\"], [\"70392.60\", \"0.005\"], [\"70392.70\", \"0.184\"], [\"70393.70\", \"0.000\"], [\"70394.10\", \"0.511\"], [\"70395.10\", \"0.073\"], [\"70395.80\", \"0.248\"], [\"70396.80\", \"0.001\"], [\"70398.20\", \"0.071\"], [\"70402.30\", \"0.005\"], [\"70403.30\", \"0.155\"], [\"70405.40\", \"0.056\"], [\"70412.50\", \"0.053\"], [\"70413.40\", \"0.559\"], [\"70413.50\", \"2.021\"], [\"70414.70\", \"0.000\"], [\"70417.80\", \"0.573\"], [\"70437.30\", \"3.863\"], [\"70437.50\", \"0.669\"], [\"70441.10\", \"0.000\"], [\"70441.60\", \"0.002\"], [\"70475.30\", \"0.008\"], [\"70475.40\", \"7.177\"], [\"70480.50\", \"0.002\"], [\"70492.60\", \"0.003\"], [\"70535.80\", \"3.020\"], [\"70538.20\", \"13.372\"], [\"70581.10\", \"0.541\"], [\"70600.90\", \"0.385\"], [\"70602.40\", \"0.031\"], [\"70624.70\", \"0.009\"], [\"70648.80\", \"0.000\"], [\"70687.90\", \"0.346\"], [\"71070.90\", \"1.454\"], [\"71366.00\", \"0.316\"], [\"77403.90\", \"0.002\"]]}", "symbol": "BTCUSDT"}
{"event": "depthUpdate", "raw_payload": "{\"e\": \"depthUpdate\", \"E\": 1773246389030, \"T\": 1773246389028, \"s\": \"BTCUSDT\", \"U\": 10089704253716, \"u\": 10089704258908, \"pu\": 10089704253656, \"b\": [[\"1000.00\", \"26.792\"], [\"5000.00\", \"101.418\"], [\"19967.10\", \"0.070\"], [\"20067.10\", \"1.610\"], [\"20167.10\", \"0.510\"], [\"20267.10\", \"0.810\"], [\"63330.40\", \"0.000\"], [\"66822.40\", \"0.009\"], [\"67552.50\", \"0.008\"], [\"69663.40\", \"0.000\"], [\"69862.90\", \"0.000\"], [\"69868.70\", \"3.720\"], [\"70132.90\", \"0.444\"], [\"70152.30\", \"0.002\"], [\"70221.90\", \"2.852\"], [\"70236.50\", \"0.166\"], [\"70236.60\", \"0.837\"], [\"70268.50\", \"0.004\"], [\"70285.40\", \"0.002\"], [\"70311.70\", \"0.175\"], [\"70325.30\", \"0.004\"], [\"70344.20\", \"0.512\"], [\"70345.60\", \"0.004\"], [\"70345.70\", \"0.071\"], [\"70346.10\", \"0.646\"], [\"70347.00\", \"0.000\"], [\"70347.50\", \"0.002\"], [\"70348.60\", \"0.008\"], [\"70349.60\", \"0.007\"], [\"70351.80\", \"0.604\"], [\"70354.40\", \"0.018\"], [\"70356.50\", \"0.659\"], [\"70359.90\", \"0.205\"], [\"70360.70\", \"0.007\"], [\"70361.50\", \"0.005\"], [\"70362.70\", \"0.205\"], [\"70362.80\", \"0.655\"], [\"70367.10\", \"4.045\"]], \"a\": [[\"70368.30\", \"0.002\"], [\"70369.80\", \"0.012\"], [\"70370.40\", \"0.003\"], [\"70371.10\", \"0.000\"], [\"70371.90\", \"0.000\"], [\"70375.50\", \"0.001\"], [\"70377.80\", \"0.003\"], [\"70379.80\", \"0.002\"], [\"70382.60\", \"0.004\"], [\"70384.80\", \"0.106\"], [\"70389.20\", \"0.071\"], [\"70391.70\", \"0.513\"], [\"70391.80\", \"0.250\"], [\"70394.10\", \"0.000\"], [\"70395.80\", \"0.000\"], [\"70410.70\", \"0.013\"], [\"70415.80\", \"0.000\"], [\"70423.60\", \"0.237\"], [\"70424.50\", \"0.001\"], [\"70465.00\", \"0.000\"], [\"70496.60\", \"0.000\"], [\"70501.20\", \"0.004\"], [\"70501.90\", \"0.252\"], [\"70510.50\", \"1.393\"], [\"70514.50\", \"0.906\"], [\"70516.40\", \"2.756\"], [\"70719.00\", \"0.035\"], [\"70865.60\", \"3.720\"], [\"70867.30\", \"0.000\"], [\"70871.30\", \"0.222\"], [\"71070.90\", \"1.454\"], [\"71211.60\", \"2.242\"], [\"73916.40\", \"0.002\"], [\"77403.90\", \"0.000\"], [\"89523.20\", \"0.000\"]]}", "symbol": "BTCUSDT"}
{"event": "depthUpdate", "raw_payload": "{\"e\": \"depthUpdate\", \"E\": 1773246389132, \"T\": 1773246389129, \"s\": \"BTCUSDT\", \"U\": 10089704259054, \"u\": 10089704264191, \"pu\": 10089704258908, \"b\": [[\"5000.00\", \"101.418\"], [\"19967.10\", \"0.150\"], [\"20067.10\", \"1.610\"], [\"20167.10\", \"0.520\"], [\"20267.10\", \"0.720\"], [\"56294.00\", \"0.000\"], [\"66821.80\", \"0.000\"], [\"66822.40\", \"0.002\"], [\"69663.40\", \"0.000\"], [\"69863.00\", \"0.092\"], [\"70133.00\", \"4.822\"], [\"70151.40\", \"0.272\"], [\"70273.90\", \"1.067\"], [\"70277.50\", \"0.071\"], [\"70281.00\", \"0.005\"], [\"70284.60\", \"0.071\"], [\"70288.00\", \"0.010\"], [\"70291.60\", \"0.253\"], [\"70298.80\", \"0.049\"], [\"70311.70\", \"0.075\"], [\"70315.70\", \"0.391\"], [\"70315.80\", \"0.004\"], [\"70322.00\", \"0.004\"], [\"70329.00\", \"0.030\"], [\"70335.90\", \"0.003\"], [\"70336.00\", \"0.090\"], [\"70343.00\", \"0.004\"], [\"70345.90\", \"0.042\"], [\"70350.00\", \"0.008\"], [\"70362.70\", \"0.000\"], [\"70362.90\", \"0.309\"], [\"70365.90\", \"0.007\"]], \"a\": [[\"70371.90\", \"0.022\"], [\"70379.90\", \"0.002\"], [\"70388.10\", \"0.000\"], [\"70388.70\", \"0.142\"], [\"70391.00\", \"0.003\"], [\"70392.00\", \"0.392\"], [\"70392.70\", \"0.219\"], [\"70396.50\", \"0.376\"], [\"70399.00\", \"0.002\"], [\"70406.00\", \"1.080\"], [\"70410.60\", \"0.077\"], [\"70413.00\", \"1.074\"], [\"70414.70\", \"0.048\"], [\"70420.00\", \"1.178\"], [\"70421.50\", \"0.062\"], [\"70435.60\", \"0.418\"], [\"70437.30\", \"3.914\"], [\"70449.90\", \"0.000\"], [\"70454.10\", \"0.113\"], [\"70456.90\", \"0.000\"], [\"70461.10\", \"0.646\"], [\"70464.00\", \"0.002\"], [\"70468.20\", \"0.584\"], [\"70496.40\", \"0.000\"], [\"70500.70\", \"0.005\"], [\"70529.10\", \"0.005\"], [\"70579.50\", \"0.002\"], [\"70736.50\", \"0.002\"], [\"70749.10\", \"0.004\"], [\"71070.90\", \"1.454\"], [\"71287.10\", \"0.840\"], [\"73920.10\", \"0.004\"]]}", "symbol": "BTCUSDT"}
{"event": "depthUpdate", "raw_payload": "{\"e\": \"depthUpdate\", \"E\": 1773246389234, \"T\": 1773246389232, \"s\": \"BTCUSDT\", \"U\": 10089704264306, \"u\": 10089704269149, \"pu\": 10089704264191, \"b\": [[\"5000.00\", \"101.418\"], [\"19967.10\", \"0.240\"], [\"20067.10\", \"1.610\"], [\"20167.10\", \"0.510\"], [\"20267.10\", \"0.640\"], [\"40000.00\", \"50.458\"], [\"66831.20\", \"0.004\"], [\"66831.30\", \"0.006\"], [\"67552.40\", \"0.017\"], [\"69331.30\", \"1.515\"], [\"69663.40\", \"0.000\"], [\"69800.00\", \"29.611\"], [\"69868.70\", \"0.000\"], [\"69870.20\", \"0.000\"], [\"70015.30\", \"0.044\"], [\"70026.00\", \"32.094\"], [\"70274.90\", \"0.000\"], [\"70299.70\", \"0.315\"], [\"70319.60\", \"0.104\"], [\"70322.40\", \"0.002\"], [\"70331.70\", \"0.250\"], [\"70333.30\", \"0.004\"], [\"70335.20\", \"0.344\"], [\"70335.30\", \"0.011\"], [\"70336.60\", \"0.303\"], [\"70336.70\", \"0.390\"], [\"70337.20\", \"0.014\"], [\"70338.00\", \"0.023\"], [\"70338.10\", \"0.009\"], [\"70339.40\", \"0.010\"], [\"70339.50\", \"0.004\"], [\"70340.20\", \"0.052\"], [\"70341.50\", \"0.054\"], [\"70342.20\", \"0.000\"], [\"70354.40\", \"0.016\"], [\"70354.90\", \"0.003\"], [\"70356.50\", \"0.659\"], [\"70356.70\", \"0.000\"], [\"70356.90\", \"0.191\"], [\"70357.00\", \"0.007\"], [\"70357.10\", \"0.000\"], [\"70357.40\", \"0.003\"], [\"70357.70\", \"0.058\"], [\"70357.90\", \"0.008\"], [\"70359.00\", \"0.031\"], [\"70359.10\", \"0.153\"], [\"70360.00\", \"0.015\"], [\"70360.20\", \"0.006\"], [\"70360.50\", \"0.214\"], [\"70361.20\", \"0.003\"], [\"70361.50\", \"0.003\"], [\"70362.40\", \"0.008\"], [\"70363.00\", \"0.004\"], [\"70367.10\", \"3.849\"]], \"a\": [[\"70367.20\", \"37.004\"], [\"70369.80\", \"0.012\"], [\"70371.60\", \"0.006\"], [\"70374.20\", \"0.000\"], [\"70375.60\", \"0.003\"], [\"70376.70\", \"0.070\"], [\"70377.30\", \"0.397\"], [\"70377.80\", \"0.000\"], [\"70377.90\", \"0.003\"], [\"70378.50\", \"0.005\"], [\"70379.10\", \"0.003\"], [\"70379.80\", \"0.000\"], [\"70380.80\", \"0.075\"], [\"70382.30\", \"0.640\"], [\"70382.60\", \"0.005\"], [\"70384.20\", \"0.006\"], [\"70384.80\", \"0.004\"], [\"70385.00\", \"0.480\"], [\"70385.70\", \"0.047\"], [\"70388.20\", \"0.013\"], [\"70389.20\", \"0.001\"], [\"70389.60\", \"0.075\"], [\"70396.70\", \"0.187\"], [\"70407.50\", \"0.033\"], [\"70407.70\", \"0.008\"], [\"70602.40\", \"0.025\"], [\"70632.70\", \"20.259\"], [\"70710.40\", \"23.458\"], [\"70718.90\", \"0.006\"], [\"70864.00\", \"0.000\"], [\"70865.60\", \"0.000\"], [\"70867.20\", \"0.002\"], [\"70887.80\", \"6.962\"], [\"71070.90\", \"1.454\"], [\"71282.00\", \"1.139\"], [\"71501.30\", \"1.386\"], [\"73889.10\", \"0.045\"], [\"89523.20\", \"0.000\"]]}", "symbol": "BTCUSDT"}
{"event": "depthUpdate", "raw_payload": "{\"e\": \"depthUpdate\", \"E\": 1773246389336, \"T\": 1773246389332, \"s\": \"BTCUSDT\", \"U\": 10089704269221, \"u\": 10089704273884, \"pu\": 10089704269149, \"b\": [[\"1000.00\", \"26.792\"], [\"5000.00\", \"101.418\"], [\"19967.10\", \"0.320\"], [\"20067.10\", \"1.610\"], [\"20167.10\", \"0.520\"], [\"20267.10\", \"0.550\"], [\"63330.40\", \"0.014\"], [\"68959.70\", \"0.004\"], [\"69421.60\", \"0.015\"], [\"69663.40\", \"0.000\"], [\"69854.80\", \"3.720\"], [\"70252.60\", \"0.296\"], [\"70254.30\", \"1.408\"], [\"70257.20\", \"0.000\"], [\"70268.80\", \"0.908\"], [\"70315.80\", \"0.002\"], [\"70315.90\", \"0.105\"], [\"70359.10\", \"0.143\"], [\"70366.00\", \"0.003\"], [\"70367.10\", \"4.026\"]], \"a\": [[\"70367.20\", \"37.006\"], [\"70402.30\", \"0.033\"], [\"70455.80\", \"0.002\"], [\"70458.00\", \"0.021\"], [\"70472.20\", \"0.018\"], [\"70491.80\", \"0.381\"], [\"70503.50\", \"0.089\"], [\"70505.60\", \"0.601\"], [\"70507.30\", \"0.087\"], [\"70510.20\", \"0.168\"], [\"70514.70\", \"0.087\"], [\"70516.80\", \"0.087\"], [\"70518.90\", \"0.246\"], [\"70521.60\", \"0.087\"], [\"70630.30\", \"3.221\"], [\"70708.90\", \"3.570\"], [\"70879.40\", \"3.732\"], [\"70887.80\", \"3.242\"], [\"71070.90\", \"1.454\"], [\"71362.70\", \"2.012\"], [\"73908.70\", \"0.002\"]]}", "symbol": "BTCUSDT"}
{"event": "depthUpdate", "raw_payload": "{\"e\": \"depthUpdate\", \"E\": 1773246389438, \"T\": 1773246389436, \"s\": \"BTCUSDT\", \"U\": 10089704273985, \"u\": 10089704280545, \"pu\": 10089704273884, \"b\": [[\"5000.00\", \"101.418\"], [\"19967.10\", \"0.430\"], [\"20067.10\", \"1.570\"], [\"20167.10\", \"0.530\"], [\"20267.10\", \"0.470\"], [\"66822.30\", \"0.037\"], [\"66831.20\", \"0.002\"], [\"66831.30\", \"0.008\"], [\"68941.70\", \"0.006\"], [\"68959.80\", \"0.003\"], [\"68979.50\", \"0.006\"], [\"69269.80\", \"0.000\"], [\"69600.10\", \"0.836\"], [\"69663.40\", \"0.000\"], [\"69854.80\", \"0.000\"], [\"69857.80\", \"3.720\"], [\"70133.00\", \"4.815\"], [\"70133.10\", \"0.007\"], [\"70242.20\", \"0.086\"], [\"70298.50\", \"0.003\"], [\"70326.60\", \"0.009\"], [\"70334.90\", \"0.151\"], [\"70357.00\", \"0.017\"], [\"70357.90\", \"0.006\"], [\"70360.50\", \"0.160\"], [\"70367.10\", \"4.030\"]], \"a\": [[\"70369.80\", \"0.012\"], [\"70370.60\", \"0.002\"], [\"70375.20\", \"0.000\"], [\"70382.30\", \"0.001\"], [\"70383.60\", \"0.681\"], [\"70384.90\", \"0.000\"], [\"70386.50\", \"0.007\"], [\"70389.20\", \"0.071\"], [\"70402.30\", \"0.005\"], [\"70407.70\", \"0.008\"], [\"70414.70\", \"0.000\"], [\"70415.60\", \"0.071\"], [\"70421.50\", \"0.000\"], [\"70421.60\", \"0.067\"], [\"70435.60\", \"0.342\"], [\"70435.70\", \"0.082\"], [\"70435.90\", \"0.005\"], [\"70486.70\", \"0.000\"], [\"70486.90\", \"0.049\"], [\"70492.20\", \"2.003\"], [\"70593.00\", \"0.008\"], [\"70718.90\", \"0.000\"], [\"70876.40\", \"3.723\"], [\"70879.40\", \"0.012\"], [\"71070.90\", \"1.454\"], [\"73908.60\", \"0.002\"], [\"89523.20\", \"0.000\"]]}", "symbol": "BTCUSDT"}
{"event": "depthUpdate", "raw_payload": "{\"e\": \"depthUpdate\", \"E\": 1773246389540, \"T\": 1773246389539, \"s\": \"BTCUSDT\", \"U\": 10089704280662, \"u\": 10089704287486, \"pu\": 10089704280545, \"b\": [[\"5000.00\", \"101.418\"], [\"19967.10\", \"0.590\"], [\"20067.10\", \"1.410\"], [\"20167.10\", \"0.620\"], [\"20267.10\", \"0.380\"], [\"33000.00\", \"10.797\"], [\"66817.50\", \"0.002\"], [\"68941.70\", \"0.003\"], [\"68959.80\", \"0.006\"], [\"69276.40\", \"3.018\"], [\"69346.80\", \"2.721\"], [\"69367.90\", \"0.574\"], [\"69421.70\", \"0.007\"], [\"69533.10\", \"0.000\"], [\"69663.40\", \"0.000\"], [\"69795.10\", \"45.600\"], [\"69800.10\", \"0.123\"], [\"69921.00\", \"40.069\"], [\"69921.10\", \"3.240\"], [\"70015.30\", \"0.044\"], [\"70026.10\", \"1.909\"], [\"70133.10\", \"0.000\"], [\"70179.00\", \"2.754\"], [\"70279.10\", \"0.201\"], [\"70297.10\", \"0.048\"], [\"70298.80\", \"0.002\"], [\"70306.80\", \"0.000\"], [\"70314.30\", \"0.927\"], [\"70317.80\", \"0.004\"], [\"70331.90\", \"0.086\"], [\"70338.70\", \"0.006\"], [\"70338.80\", \"0.002\"], [\"70342.20\", \"0.002\"], [\"70342.30\", \"0.055\"], [\"70349.10\", \"0.378\"], [\"70349.20\", \"0.001\"], [\"70351.00\", \"0.052\"], [\"70353.00\", \"0.896\"], [\"70354.40\", \"0.018\"], [\"70358.50\", \"0.083\"], [\"70361.50\", \"0.005\"], [\"70366.10\", \"0.002\"], [\"70367.10\", \"4.033\"]], \"a\": [[\"70371.90\", \"0.000\"], [\"70374.20\", \"0.028\"], [\"70384.00\", \"0.010\"], [\"70385.70\", \"0.000\"], [\"70389.70\", \"0.380\"], [\"70390.80\", \"0.000\"], [\"70392.70\", \"0.184\"], [\"70394.70\", \"0.000\"], [\"70395.80\", \"0.014\"], [\"70396.50\", \"0.002\"], [\"70402.40\", \"0.011\"], [\"70415.60\", \"0.002\"], [\"70416.20\", \"0.002\"], [\"70421.60\", \"0.004\"], [\"70428.70\", \"0.023\"], [\"70435.70\", \"0.003\"], [\"70437.90\", \"0.763\"], [\"70514.20\", \"0.002\"], [\"70521.20\", \"0.511\"], [\"70528.20\", \"0.086\"], [\"70529.50\", \"1.357\"], [\"70535.20\", \"0.000\"], [\"70536.50\", \"0.007\"], [\"70542.20\", \"0.087\"], [\"70543.50\", \"0.007\"], [\"70549.20\", \"0.039\"], [\"70550.50\", \"0.007\"], [\"70556.20\", \"0.011\"], [\"70557.50\", \"0.029\"], [\"70559.30\", \"2.754\"], [\"70563.20\", \"0.010\"], [\"70564.50\", \"0.007\"], [\"70571.50\", \"0.007\"], [\"70578.50\", \"0.007\"], [\"70632.10\", \"0.004\"], [\"70637.10\", \"0.002\"], [\"70816.50\", \"31.867\"], [\"70944.00\", \"36.597\"], [\"71070.90\", \"1.454\"], [\"71577.50\", \"0.349\"], [\"73181.80\", \"0.008\"], [\"73908.60\", \"0.000\"]]}", "symbol": "BTCUSDT"}
{"event": "depthUpdate", "raw_payload": "{\"e\": \"depthUpdate\", \"E\": 1773246389642, \"T\": 1773246389640, \"s\": \"BTCUSDT\", \"U\": 10089704287530, \"u\": 10089704292638, \"pu\": 10089704287486, \"b\": [[\"1000.00\", \"26.792\"], [\"5000.00\", \"101.398\"], [\"19967.10\", \"0.770\"], [\"20067.10\", \"1.230\"], [\"20167.10\", \"0.700\"], [\"20267.10\", \"0.300\"], [\"33000.00\", \"10.793\"], [\"67552.50\", \"0.010\"], [\"69165.40\", \"1.145\"], [\"69372.80\", \"1.878\"], [\"69411.80\", \"0.000\"], [\"69421.70\", \"0.000\"], [\"69663.40\", \"0.000\"], [\"69854.90\", \"0.000\"], [\"69857.80\", \"0.000\"], [\"70133.10\", \"0.007\"], [\"70272.70\", \"0.110\"], [\"70279.80\", \"0.103\"], [\"70286.00\", \"0.144\"], [\"70286.80\", \"0.390\"], [\"70293.10\", \"1.346\"], [\"70300.10\", \"0.142\"], [\"70315.90\", \"0.103\"], [\"70316.10\", \"0.004\"], [\"70318.50\", \"0.438\"], [\"70344.50\", \"0.639\"], [\"70344.70\", \"0.000\"], [\"70346.10\", \"0.007\"], [\"70354.40\", \"0.016\"], [\"70355.00\", \"0.280\"], [\"70355.20\", \"0.118\"], [\"70356.90\", \"0.044\"], [\"70357.40\", \"0.000\"], [\"70358.20\", \"0.101\"], [\"70360.40\", \"0.002\"], [\"70360.70\", \"0.209\"], [\"70360.80\", \"0.003\"], [\"70361.40\", \"0.005\"], [\"70361.50\", \"0.003\"], [\"70366.90\", \"0.154\"], [\"70367.10\", \"4.280\"]], \"a\": [[\"70367.20\", \"36.994\"], [\"70369.80\", \"0.012\"], [\"70371.10\", \"0.002\"], [\"70371.90\", \"0.000\"], [\"70376.70\", \"0.067\"], [\"70377.00\", \"0.002\"], [\"70377.80\", \"0.003\"], [\"70379.40\", \"0.006\"], [\"70388.20\", \"0.010\"], [\"70389.20\", \"0.001\"], [\"70392.40\", \"0.007\"], [\"70396.20\", \"0.379\"], [\"70418.00\", \"0.458\"], [\"70428.70\", \"0.003\"], [\"70441.10\", \"0.102\"], [\"70441.80\", \"0.002\"], [\"70529.00\", \"0.002\"], [\"70873.80\", \"3.720\"], [\"70876.40\", \"0.003\"], [\"71774.50\", \"0.003\"], [\"73908.70\", \"0.000\"], [\"89523.20\", \"0.000\"]]}", "symbol": "BTCUSDT"}
{"event": "depthUpdate", "raw_payload": "{\"e\": \"depthUpdate\", \"E\": 1773246389744, \"T\": 1773246389743, \"s\": \"BTCUSDT\", \"U\": 10089704292778, \"u\": 10089704299928, \"pu\": 10089704292638, \"b\": [[\"5000.00\", \"101.418\"], [\"19967.10\", \"0.930\"], [\"20067.10\", \"1.070\"], [\"20167.10\", \"0.790\"], [\"20267.10\", \"0.210\"], [\"66821.30\", \"0.002\"], [\"66834.20\", \"0.006\"], [\"69382.00\", \"5.280\"], [\"69663.40\", \"0.000\"], [\"69862.80\", \"0.002\"], [\"69865.00\", \"0.066\"], [\"70218.20\", \"0.000\"], [\"70236.30\", \"0.082\"], [\"70236.50\", \"0.164\"], [\"70255.50\", \"1.666\"], [\"70260.80\", \"0.025\"], [\"70264.70\", \"0.083\"], [\"70267.50\", \"0.002\"], [\"70279.40\", \"0.083\"], [\"70284.10\", \"0.004\"], [\"70292.80\", \"0.002\"], [\"70303.70\", \"0.008\"], [\"70306.70\", \"0.000\"], [\"70315.60\", \"0.193\"], [\"70316.00\", \"0.347\"], [\"70316.10\", \"0.002\"], [\"70320.50\", \"0.000\"], [\"70323.60\", \"0.007\"], [\"70332.80\", \"1.243\"], [\"70333.40\", \"0.006\"], [\"70338.20\", \"0.053\"], [\"70340.20\", \"0.000\"], [\"70342.40\", \"0.511\"], [\"70343.00\", \"0.643\"], [\"70343.80\", \"0.078\"], [\"70344.20\", \"0.001\"], [\"70344.50\", \"0.000\"], [\"70345.70\", \"0.000\"], [\"70348.20\", \"0.372\"], [\"70350.50\", \"0.242\"], [\"70355.70\", \"0.008\"], [\"70356.40\", \"2.277\"], [\"70357.80\", \"0.002\"], [\"70358.20\", \"0.098\"], [\"70359.00\", \"0.034\"], [\"70360.70\", \"0.864\"], [\"70360.80\", \"0.005\"], [\"70362.80\", \"0.000\"], [\"70362.90\", \"0.188\"], [\"70363.00\", \"0.002\"], [\"70365.90\", \"0.005\"], [\"70366.00\", \"0.001\"], [\"70366.10\", \"0.000\"], [\"70366.50\", \"0.000\"], [\"70366.70\", \"0.000\"], [\"70366.90\", \"0.000\"], [\"70367.10\", \"3.440\"]], \"a\": [[\"70367.20\", \"36.991\"], [\"70368.30\", \"0.027\"], [\"70371.90\", \"0.022\"], [\"70374.20\", \"0.031\"], [\"70374.30\", \"0.003\"], [\"70374.40\", \"0.004\"], [\"70376.80\", \"0.082\"], [\"70377.30\", \"0.400\"], [\"70379.40\", \"0.003\"], [\"70380.30\", \"0.639\"], [\"70381.30\", \"0.105\"], [\"70381.60\", \"0.567\"], [\"70381.70\", \"0.527\"], [\"70383.60\", \"0.082\"], [\"70384.00\", \"0.197\"], [\"70385.60\", \"0.003\"], [\"70386.50\", \"0.271\"], [\"70387.60\", \"0.187\"], [\"70389.20\", \"0.071\"], [\"70389.40\", \"0.050\"], [\"70390.60\", \"0.062\"], [\"70390.70\", \"0.179\"], [\"70391.00\", \"0.005\"], [\"70394.10\", \"0.071\"], [\"70394.40\", \"0.002\"], [\"70396.20\", \"0.399\"], [\"70398.20\", \"0.000\"], [\"70398.90\", \"0.010\"], [\"70401.90\", \"1.073\"], [\"70403.40\", \"0.002\"], [\"70410.50\", \"0.075\"], [\"70410.60\", \"0.004\"], [\"70430.60\", \"2.759\"], [\"70437.30\", \"3.917\"], [\"70437.50\", \"0.666\"], [\"70441.10\", \"0.000\"], [\"70513.90\", \"0.021\"], [\"70517.50\", \"0.003\"], [\"70612.70\", \"0.047\"], [\"70861.10\", \"3.720\"], [\"70869.20\", \"0.000\"], [\"70871.40\", \"0.002\"], [\"70873.80\", \"0.000\"], [\"71070.90\", \"1.454\"], [\"71609.50\", \"0.000\"], [\"73916.40\", \"0.000\"]]}", "symbol": "BTCUSDT"}
{"event": "depthUpdate", "raw_payload": "{\"e\": \"depthUpdate\", \"E\": 1773246389846, \"T\": 1773246389845, \"s\": \"BTCUSDT\", \"U\": 10089704299972, \"u\": 10089704309836, \"pu\": 10089704299928, \"b\": [[\"5000.00\", \"101.418\"], [\"19967.10\", \"1.110\"], [\"20067.10\", \"0.890\"], [\"20167.10\", \"0.870\"], [\"20267.10\", \"0.130\"], [\"63330.40\", \"0.016\"], [\"66831.60\", \"0.002\"], [\"68941.70\", \"0.000\"], [\"69135.70\", \"1.158\"], [\"69245.40\", \"0.004\"], [\"69663.40\", \"0.000\"], [\"69855.00\", \"0.537\"], [\"70015.30\", \"0.044\"], [\"70042.30\", \"0.008\"], [\"70133.10\", \"0.000\"], [\"70278.70\", \"0.000\"], [\"70289.70\", \"0.397\"], [\"70297.20\", \"0.004\"], [\"70315.30\", \"0.523\"], [\"70316.00\", \"0.345\"], [\"70319.30\", \"0.056\"], [\"70326.60\", \"0.003\"], [\"70327.30\", \"0.000\"], [\"70329.30\", \"0.248\"], [\"70331.70\", \"0.002\"], [\"70336.30\", \"0.052\"], [\"70337.60\", \"0.002\"], [\"70338.20\", \"0.001\"], [\"70338.90\", \"0.108\"], [\"70341.10\", \"0.513\"], [\"70341.50\", \"0.094\"], [\"70341.60\", \"0.076\"], [\"70342.40\", \"0.000\"], [\"70342.70\", \"0.000\"], [\"70343.70\", \"0.086\"], [\"70343.80\", \"0.007\"], [\"70344.90\", \"0.005\"], [\"70345.90\", \"0.002\"], [\"70348.70\", \"0.151\"], [\"70349.80\", \"0.012\"], [\"70351.00\", \"0.045\"], [\"70352.80\", \"0.351\"], [\"70353.00\", \"0.790\"], [\"70353.60\", \"0.146\"], [\"70353.80\", \"0.000\"], [\"70356.50\", \"0.661\"], [\"70358.10\", \"0.005\"], [\"70358.50\", \"0.003\"], [\"70360.00\", \"0.017\"], [\"70360.30\", \"0.267\"], [\"70360.70\", \"0.898\"], [\"70362.60\", \"0.016\"], [\"70363.60\", \"0.007\"], [\"70366.90\", \"0.002\"], [\"70367.00\", \"0.064\"], [\"70367.10\", \"3.411\"]], \"a\": [[\"70368.20\", \"0.000\"], [\"70368.30\", \"0.002\"], [\"70369.70\", \"0.003\"], [\"70374.30\", \"0.000\"], [\"70379.50\", \"0.512\"], [\"70380.20\", \"0.167\"], [\"70380.40\", \"0.000\"], [\"70381.30\", \"0.003\"], [\"70385.60\", \"0.000\"], [\"70386.80\", \"0.304\"], [\"70386.90\", \"0.162\"], [\"70388.20\", \"0.152\"], [\"70388.40\", \"0.511\"], [\"70388.70\", \"0.000\"], [\"70388.80\", \"0.668\"], [\"70389.60\", \"0.075\"], [\"70390.60\", \"0.005\"], [\"70391.50\", \"0.362\"], [\"70391.70\", \"0.002\"], [\"70391.80\", \"0.002\"], [\"70392.30\", \"0.266\"], [\"70393.70\", \"0.002\"], [\"70394.10\", \"0.051\"], [\"70395.00\", \"0.220\"], [\"70395.10\", \"0.002\"], [\"70396.20\", \"0.379\"], [\"70396.40\", \"0.055\"], [\"70398.20\", \"0.000\"], [\"70398.90\", \"0.112\"], [\"70401.30\", \"0.000\"], [\"70403.00\", \"1.905\"], [\"70408.30\", \"0.007\"], [\"70416.60\", \"0.051\"], [\"70417.30\", \"0.000\"], [\"70423.60\", \"0.192\"], [\"70430.50\", \"0.641\"], [\"70430.70\", \"0.002\"], [\"70431.50\", \"0.097\"], [\"70431.60\", \"0.034\"], [\"70437.30\", \"3.866\"], [\"70441.10\", \"0.000\"], [\"70510.30\", \"0.000\"], [\"70861.10\", \"0.000\"], [\"71070.90\", \"1.454\"], [\"71364.50\", \"0.280\"], [\"73891.70\", \"0.000\"], [\"77403.90\", \"0.002\"], [\"89523.20\", \"0.000\"]]}", "symbol": "BTCUSDT"}
{"event": "depthUpdate", "raw_payload": "{\"e\": \"depthUpdate\", \"E\": 1773246389948, \"T\": 1773246389945, \"s\": \"BTCUSDT\", \"U\": 10089704309993, \"u\": 10089704316760, \"pu\": 10089704309836, \"b\": [[\"1000.00\", \"26.792\"], [\"5000.00\", \"101.418\"], [\"19967.10\", \"1.270\"], [\"20067.10\", \"0.730\"], [\"20167.10\", \"0.960\"], [\"20267.10\", \"0.040\"], [\"63330.40\", \"0.014\"], [\"66831.60\", \"0.000\"], [\"66844.20\", \"0.002\"], [\"69337.20\", \"1.737\"], [\"69425.70\", \"67.186\"], [\"69634.60\", \"54.686\"], [\"69663.40\", \"0.000\"], [\"69855.00\", \"0.530\"], [\"69862.90\", \"0.000\"], [\"70026.30\", \"5.100\"], [\"70133.20\", \"0.000\"], [\"70178.50\", \"0.436\"], [\"70256.20\", \"0.081\"], [\"70296.80\", \"0.956\"], [\"70306.50\", \"0.022\"], [\"70307.70\", \"2.759\"], [\"70315.30\", \"0.521\"], [\"70315.60\", \"0.195\"], [\"70321.80\", \"0.821\"], [\"70325.30\", \"0.002\"], [\"70339.40\", \"0.010\"], [\"70339.50\", \"0.004\"], [\"70340.10\", \"0.002\"], [\"70340.20\", \"0.000\"], [\"70343.00\", \"1.216\"], [\"70349.00\", \"0.007\"], [\"70349.80\", \"0.005\"], [\"70367.10\", \"3.320\"]], \"a\": [[\"70371.30\", \"0.005\"], [\"70379.30\", \"0.379\"], [\"70379.40\", \"1.069\"], [\"70380.20\", \"0.000\"], [\"70382.60\", \"0.008\"], [\"70386.00\", \"0.071\"], [\"70387.50\", \"0.254\"], [\"70388.30\", \"0.513\"], [\"70388.80\", \"0.611\"], [\"70389.60\", \"0.004\"], [\"70391.50\", \"0.291\"], [\"70391.90\", \"1.387\"], [\"70392.30\", \"0.195\"], [\"70392.70\", \"0.255\"], [\"70393.40\", \"0.071\"], [\"70393.70\", \"0.009\"], [\"70393.80\", \"0.205\"], [\"70395.80\", \"0.000\"], [\"70397.40\", \"0.005\"], [\"70401.80\", \"0.009\"], [\"70401.90\", \"1.082\"], [\"70402.50\", \"0.010\"], [\"70402.60\", \"0.147\"], [\"70406.70\", \"0.316\"], [\"70408.80\", \"0.005\"], [\"70408.90\", \"0.004\"], [\"70409.50\", \"0.793\"], [\"70409.60\", \"0.002\"], [\"70410.20\", \"0.000\"], [\"70410.30\", \"0.000\"], [\"70413.40\", \"0.561\"], [\"70430.50\", \"0.513\"], [\"70430.60\", \"2.759\"], [\"70430.70\", \"0.130\"], [\"70434.50\", \"0.922\"], [\"70452.90\", \"0.008\"], [\"70462.00\", \"0.009\"], [\"70472.60\", \"1.748\"], [\"70570.00\", \"0.192\"], [\"70612.70\", \"0.000\"], [\"70624.70\", \"0.007\"], [\"70793.00\", \"0.016\"], [\"71070.90\", \"1.454\"], [\"71107.50\", \"55.556\"], [\"71320.80\", \"64.485\"], [\"71598.60\", \"1.116\"], [\"71963.80\", \"0.002\"], [\"72028.90\", \"0.596\"], [\"77403.90\", \"0.000\"]]}", "symbol": "BTCUSDT"}
{"event": "depthUpdate", "raw_payload": "{\"e\": \"depthUpdate\", \"E\": 1773246390050, \"T\": 1773246390048, \"s\": \"BTCUSDT\", \"U\": 10089704316901, \"u\": 10089704324864, \"pu\": 10089704316760, \"b\": [[\"5000.00\", \"101.418\"], [\"19967.10\", \"1.450\"], [\"20067.10\", \"0.590\"], [\"20167.10\", \"0.960\"], [\"20267.10\", \"0.000\"], [\"56294.00\", \"0.004\"], [\"66848.70\", \"0.005\"], [\"66848.80\", \"0.002\"], [\"69663.40\", \"0.000\"], [\"69878.90\", \"3.720\"], [\"70099.00\", \"0.013\"], [\"70152.30\", \"0.000\"], [\"70277.50\", \"0.000\"], [\"70279.70\", \"0.074\"], [\"70284.60\", \"0.000\"], [\"70286.80\", \"0.461\"], [\"70289.70\", \"0.481\"], [\"70290.60\", \"0.089\"], [\"70291.60\", \"0.182\"], [\"70291.80\", \"0.002\"], [\"70293.80\", \"0.075\"], [\"70315.60\", \"0.193\"], [\"70315.70\", \"0.393\"], [\"70322.00\", \"0.625\"], [\"70329.00\", \"0.651\"], [\"70336.00\", \"0.711\"], [\"70343.00\", \"1.837\"], [\"70347.00\", \"0.071\"], [\"70349.50\", \"0.004\"], [\"70350.00\", \"0.629\"], [\"70353.30\", \"0.002\"], [\"70360.40\", \"0.002\"], [\"70367.10\", \"3.320\"]], \"a\": [[\"70369.80\", \"0.012\"], [\"70379.90\", \"0.006\"], [\"70386.80\", \"0.056\"], [\"70387.40\", \"0.265\"], [\"70387.50\", \"0.197\"], [\"70388.70\", \"0.248\"], [\"70392.00\", \"1.013\"], [\"70393.10\", \"0.035\"], [\"70399.00\", \"0.623\"], [\"70406.00\", \"1.701\"], [\"70413.00\", \"1.695\"], [\"70415.10\", \"0.633\"], [\"70420.00\", \"1.799\"], [\"70422.00\", \"2.888\"], [\"70423.50\", \"0.086\"], [\"70430.50\", \"0.641\"], [\"70430.70\", \"0.002\"], [\"70434.00\", \"0.006\"], [\"70436.10\", \"0.084\"], [\"70454.10\", \"0.042\"], [\"70456.10\", \"0.091\"], [\"70461.10\", \"0.575\"], [\"70463.10\", \"0.080\"], [\"70468.20\", \"0.513\"], [\"70470.20\", \"0.158\"], [\"70485.40\", \"0.119\"], [\"70593.00\", \"0.002\"], [\"70745.90\", \"0.000\"], [\"70855.30\", \"3.720\"], [\"70861.00\", \"0.052\"], [\"70930.10\", \"0.153\"], [\"71070.90\", \"1.454\"], [\"71211.60\", \"2.523\"], [\"73920.10\", \"0.002\"], [\"89523.20\", \"0.000\"]]}", "symbol": "BTCUSDT"}
{"event": "depthUpdate", "raw_payload": "{\"e\": \"depthUpdate\", \"E\": 1773246390152, \"T\": 1773246390151, \"s\": \"BTCUSDT\", \"U\": 10089704324948, \"u\": 10089704333024, \"pu\": 10089704324864, \"b\": [[\"1000.00\", \"26.942\"], [\"5000.00\", \"101.398\"], [\"19967.10\", \"1.610\"], [\"20067.10\", \"0.520\"], [\"20167.10\", \"0.870\"], [\"56294.00\", \"0.000\"], [\"66817.50\", \"0.000\"], [\"66844.20\", \"0.000\"], [\"66848.00\", \"0.004\"], [\"69663.40\", \"0.000\"], [\"70015.30\", \"0.044\"], [\"70015.40\", \"0.000\"], [\"70133.30\", \"0.054\"], [\"70136.10\", \"2.501\"], [\"70239.60\", \"0.000\"], [\"70249.50\", \"0.046\"], [\"70273.30\", \"0.227\"], [\"70289.70\", \"0.481\"], [\"70293.20\", \"0.091\"], [\"70303.20\", \"0.000\"], [\"70303.60\", \"0.005\"], [\"70305.40\", \"0.989\"], [\"70305.80\", \"0.000\"], [\"70308.50\", \"0.116\"], [\"70309.00\", \"0.077\"], [\"70310.20\", \"0.000\"], [\"70310.40\", \"0.004\"], [\"70311.10\", \"0.061\"], [\"70311.30\", \"0.387\"], [\"70311.50\", \"1.068\"], [\"70312.80\", \"0.000\"], [\"70315.70\", \"0.391\"], [\"70315.80\", \"0.004\"], [\"70321.30\", \"0.025\"], [\"70322.00\", \"0.004\"], [\"70323.60\", \"0.005\"], [\"70327.10\", \"0.087\"], [\"70327.20\", \"0.040\"], [\"70329.00\", \"0.032\"], [\"70333.10\", \"0.004\"], [\"70334.40\", \"0.574\"], [\"70334.90\", \"0.149\"], [\"70336.00\", \"0.090\"], [\"70337.00\", \"0.009\"], [\"70340.90\", \"0.007\"], [\"70341.10\", \"0.511\"], [\"70342.90\", \"1.068\"], [\"70343.00\", \"1.216\"], [\"70343.10\", \"0.008\"], [\"70349.00\", \"0.009\"], [\"70349.70\", \"0.033\"], [\"70350.00\", \"0.008\"], [\"70350.10\", \"0.003\"], [\"70350.30\", \"1.070\"], [\"70351.30\", \"0.010\"], [\"70352.60\", \"0.216\"], [\"70353.80\", \"0.002\"], [\"70356.30\", \"0.208\"], [\"70359.00\", \"0.036\"], [\"70360.60\", \"0.345\"], [\"70361.30\", \"0.003\"], [\"70361.40\", \"0.003\"], [\"70367.00\", \"0.066\"]], \"a\": [[\"70372.50\", \"0.018\"], [\"70373.80\", \"0.002\"], [\"70378.30\", \"0.002\"], [\"70379.50\", \"0.514\"], [\"70379.90\", \"0.002\"], [\"70392.00\", \"0.392\"], [\"70392.10\", \"0.007\"], [\"70399.00\", \"0.002\"], [\"70402.90\", \"0.513\"], [\"70403.00\", \"1.903\"], [\"70406.00\", \"1.080\"], [\"70409.50\", \"0.791\"], [\"70413.00\", \"1.074\"], [\"70413.60\", \"0.002\"], [\"70420.00\", \"1.262\"], [\"70422.90\", \"0.000\"], [\"70423.50\", \"0.086\"], [\"70429.50\", \"0.002\"], [\"70430.20\", \"0.128\"], [\"70430.30\", \"0.000\"], [\"70430.40\", \"0.192\"], [\"70430.50\", \"0.513\"], [\"70430.70\", \"0.004\"], [\"70436.90\", \"0.178\"], [\"70437.40\", \"0.002\"], [\"70441.50\", \"0.003\"], [\"70475.60\", \"0.002\"], [\"70519.30\", \"0.006\"], [\"70529.10\", \"0.003\"], [\"70602.20\", \"2.308\"], [\"70624.60\", \"0.006\"], [\"70749.10\", \"0.002\"], [\"70750.50\", \"0.002\"], [\"70861.00\", \"0.046\"], [\"70880.80\", \"0.011\"], [\"71070.80\", \"0.000\"], [\"71093.50\", \"0.004\"], [\"71211.60\", \"2.804\"], [\"71306.10\", \"0.051\"], [\"71481.00\", \"0.006\"], [\"71518.80\", \"0.006\"], [\"71580.90\", \"0.000\"], [\"71643.70\", \"0.402\"], [\"71731.40\", \"0.004\"], [\"73526.70\", \"0.003\"], [\"73897.40\", \"0.002\"]]}", "symbol": "BTCUSDT"}
{"event": "depthUpdate", "raw_payload": "{\"e\": \"depthUpdate\", \"E\": 1773246390254, \"T\": 1773246390252, \"s\": \"BTCUSDT\", \"U\": 10089704333054, \"u\": 10089704338210, \"pu\": 10089704333024, \"b\": [[\"1000.00\", \"26.792\"], [\"5000.00\", \"101.418\"], [\"19867.10\", \"0.090\"], [\"19967.10\", \"1.610\"], [\"20067.10\", \"0.510\"], [\"20167.10\", \"0.790\"], [\"33000.00\", \"10.797\"], [\"66826.60\", \"0.005\"], [\"67474.40\", \"0.004\"], [\"69076.80\", \"0.008\"], [\"69346.80\", \"3.585\"], [\"69663.40\", \"0.000\"], [\"69878.90\", \"0.000\"], [\"69880.60\", \"3.720\"], [\"70042.40\", \"0.000\"], [\"70133.30\", \"0.054\"], [\"70136.10\", \"2.754\"], [\"70136.20\", \"0.697\"], [\"70197.10\", \"1.282\"], [\"70300.00\", \"1.481\"], [\"70315.80\", \"0.002\"], [\"70316.00\", \"0.347\"], [\"70327.10\", \"0.002\"], [\"70327.20\", \"0.040\"], [\"70327.30\", \"0.085\"], [\"70329.60\", \"0.002\"], [\"70350.50\", \"0.003\"], [\"70359.00\", \"0.033\"], [\"70359.30\", \"0.000\"], [\"70367.10\", \"3.322\"]], \"a\": [[\"70367.20\", \"36.992\"], [\"70369.80\", \"0.012\"], [\"70377.80\", \"0.000\"], [\"70393.80\", \"0.207\"], [\"70402.70\", \"0.266\"], [\"70430.20\", \"0.000\"], [\"70430.30\", \"0.128\"], [\"70457.40\", \"0.091\"], [\"70478.80\", \"1.092\"], [\"70529.10\", \"0.090\"], [\"70602.10\", \"0.755\"], [\"70602.20\", \"2.954\"], [\"70853.60\", \"3.723\"], [\"70855.30\", \"0.000\"], [\"70930.10\", \"0.294\"], [\"71070.90\", \"1.454\"], [\"73889.10\", \"0.043\"], [\"73898.80\", \"0.002\"], [\"89523.20\", \"0.000\"]]}", "symbol": "BTCUSDT"}
{"event": "depthUpdate", "raw_payload": "{\"e\": \"depthUpdate\", \"E\": 1773246390356, \"T\": 1773246390353, \"s\": \"BTCUSDT\", \"U\": 10089704338273, \"u\": 10089704343695, \"pu\": 10089704338210, \"b\": [[\"5000.00\", \"101.418\"], [\"19867.10\", \"0.170\"], [\"19967.10\", \"1.610\"], [\"20067.10\", \"0.520\"], [\"20167.10\", \"0.700\"], [\"33000.00\", \"10.793\"], [\"56294.00\", \"0.000\"], [\"66836.30\", \"0.000\"], [\"66840.30\", \"0.002\"], [\"68959.70\", \"0.002\"], [\"69398.40\", \"0.000\"], [\"69663.40\", \"0.000\"], [\"70252.60\", \"0.294\"], [\"70253.80\", \"0.025\"], [\"70272.00\", \"1.115\"], [\"70316.00\", \"0.345\"], [\"70316.10\", \"0.004\"], [\"70322.20\", \"0.045\"], [\"70327.20\", \"0.040\"], [\"70327.30\", \"0.085\"], [\"70341.60\", \"0.005\"], [\"70344.30\", \"0.155\"], [\"70356.50\", \"0.664\"], [\"70358.30\", \"0.142\"], [\"70359.10\", \"0.001\"], [\"70359.30\", \"0.335\"]], \"a\": [[\"70377.40\", \"0.014\"], [\"70377.80\", \"0.003\"], [\"70388.40\", \"0.000\"], [\"70389.60\", \"0.515\"], [\"70392.40\", \"0.009\"], [\"70392.70\", \"0.184\"], [\"70393.70\", \"0.002\"], [\"70393.80\", \"0.278\"], [\"70394.70\", \"0.007\"], [\"70396.40\", \"0.003\"], [\"70398.70\", \"0.052\"], [\"70418.00\", \"0.438\"], [\"70427.40\", \"0.050\"], [\"71070.90\", \"1.454\"], [\"71774.50\", \"0.006\"]]}", "symbol": "BTCUSDT"}
{"event": "depthUpdate", "raw_payload": "{\"e\": \"depthUpdate\", \"E\": 1773246390458, \"T\": 1773246390457, \"s\": \"BTCUSDT\", \"U\": 10089704343932, \"u\": 10089704351683, \"pu\": 10089704343695, \"b\": [[\"1000.00\", \"26.792\"], [\"5000.00\", \"101.398\"], [\"19867.10\", \"0.260\"], [\"19967.10\", \"1.610\"], [\"20067.10\", \"0.510\"], [\"20167.10\", \"0.620\"], [\"66840.30\", \"0.000\"], [\"66844.80\", \"0.002\"], [\"68961.90\", \"0.000\"], [\"68977.20\", \"0.009\"], [\"68984.70\", \"0.382\"], [\"69021.70\", \"0.000\"], [\"69040.10\", \"0.018\"], [\"69063.00\", \"0.385\"], [\"69069.20\", \"0.004\"], [\"69118.30\", \"0.000\"], [\"69141.20\", \"1.525\"], [\"69196.50\", \"0.000\"], [\"69263.60\", \"0.000\"], [\"69274.70\", \"0.000\"], [\"69352.90\", \"0.017\"], [\"69431.00\", \"0.013\"], [\"69509.20\", \"0.000\"], [\"69587.40\", \"0.000\"], [\"69663.40\", \"0.000\"], [\"69665.60\", \"0.000\"], [\"69880.60\", \"0.000\"], [\"69881.40\", \"0.000\"], [\"69886.50\", \"3.720\"], [\"70015.30\", \"0.044\"], [\"70177.60\", \"0.000\"], [\"70273.00\", \"0.465\"], [\"70316.10\", \"0.002\"], [\"70316.50\", \"0.006\"], [\"70327.10\", \"0.002\"], [\"70327.20\", \"0.125\"], [\"70327.30\", \"0.000\"], [\"70338.90\", \"0.002\"], [\"70340.50\", \"0.061\"], [\"70353.00\", \"0.896\"], [\"70356.50\", \"0.661\"], [\"70359.20\", \"0.000\"], [\"70359.30\", \"0.332\"], [\"70365.70\", \"0.002\"], [\"70367.10\", \"3.323\"]], \"a\": [[\"70369.80\", \"0.012\"], [\"70377.80\", \"0.003\"], [\"70380.40\", \"0.000\"], [\"70384.30\", \"0.156\"], [\"70385.70\", \"0.094\"], [\"70390.70\", \"0.085\"], [\"70410.40\", \"0.073\"], [\"70410.50\", \"0.002\"], [\"70418.00\", \"0.458\"], [\"70427.40\", \"0.030\"], [\"70495.30\", \"0.059\"], [\"70501.40\", \"0.044\"], [\"70847.80\", \"3.720\"], [\"70852.80\", \"0.002\"], [\"70853.60\", \"0.003\"], [\"71070.90\", \"1.454\"], [\"71073.00\", \"0.027\"], [\"71151.20\", \"0.002\"], [\"71229.40\", \"0.000\"], [\"71288.80\", \"0.601\"], [\"71307.60\", \"0.012\"], [\"71385.70\", \"0.003\"], [\"71462.20\", \"3.266\"], [\"71463.90\", \"0.704\"], [\"71542.10\", \"0.002\"], [\"71620.30\", \"0.005\"], [\"71698.50\", \"0.002\"], [\"71776.70\", \"0.002\"], [\"89523.20\", \"0.000\"]]}", "symbol": "BTCUSDT"}
{"event": "depthUpdate", "raw_payload": "{\"e\": \"depthUpdate\", \"E\": 1773246390560, \"T\": 1773246390556, \"s\": \"BTCUSDT\", \"U\": 10089704351945, \"u\": 10089704358856, \"pu\": 10089704351683, \"b\": [[\"1000.00\", \"26.792\"], [\"5000.00\", \"101.418\"], [\"19867.10\", \"0.340\"], [\"19967.10\", \"1.610\"], [\"20067.10\", \"0.520\"], [\"20167.10\", \"0.530\"], [\"68120.00\", \"0.447\"], [\"68336.00\", \"0.017\"], [\"68945.50\", \"0.011\"], [\"69180.50\", \"10.659\"], [\"69219.40\", \"0.380\"], [\"69297.60\", \"0.380\"], [\"69306.20\", \"0.000\"], [\"69375.80\", \"0.380\"], [\"69454.00\", \"0.388\"], [\"69532.20\", \"0.418\"], [\"69610.50\", \"0.380\"], [\"69663.40\", \"0.000\"], [\"69688.70\", \"0.380\"], [\"70108.80\", \"0.000\"], [\"70141.10\", \"0.002\"], [\"70150.40\", \"0.019\"], [\"70150.70\", \"0.000\"], [\"70151.40\", \"0.189\"], [\"70152.50\", \"0.000\"], [\"70152.80\", \"0.014\"], [\"70176.30\", \"0.000\"], [\"70178.50\", \"0.163\"], [\"70183.30\", \"0.000\"], [\"70204.60\", \"2.337\"], [\"70204.90\", \"0.081\"], [\"70211.10\", \"0.004\"], [\"70211.20\", \"0.040\"], [\"70211.40\", \"0.036\"], [\"70211.70\", \"0.000\"], [\"70211.80\", \"0.000\"], [\"70212.10\", \"0.541\"], [\"70212.40\", \"0.002\"], [\"70212.80\", \"0.011\"], [\"70213.10\", \"0.000\"], [\"70232.40\", \"0.066\"], [\"70234.40\", \"0.039\"], [\"70242.20\", \"0.086\"], [\"70248.40\", \"0.212\"], [\"70273.40\", \"0.524\"], [\"70290.10\", \"0.002\"], [\"70290.50\", \"0.624\"], [\"70290.70\", \"0.000\"], [\"70290.80\", \"0.204\"], [\"70291.50\", \"0.002\"], [\"70292.50\", \"0.000\"], [\"70298.50\", \"0.003\"], [\"70326.60\", \"0.003\"], [\"70327.20\", \"0.040\"], [\"70327.30\", \"0.085\"], [\"70351.20\", \"0.005\"], [\"70351.50\", \"0.002\"], [\"70351.60\", \"0.074\"], [\"70351.90\", \"0.006\"], [\"70352.20\", \"0.005\"], [\"70352.90\", \"0.092\"], [\"70353.50\", \"0.862\"], [\"70353.60\", \"0.063\"], [\"70353.90\", \"0.105\"], [\"70354.60\", \"0.038\"], [\"70355.00\", \"0.280\"], [\"70356.50\", \"0.664\"], [\"70357.10\", \"0.003\"], [\"70365.90\", \"0.007\"]], \"a\": [[\"70372.00\", \"0.007\"], [\"70381.60\", \"0.472\"], [\"70382.90\", \"0.000\"], [\"70383.20\", \"0.001\"], [\"70383.60\", \"0.046\"], [\"70383.70\", \"0.002\"], [\"70383.90\", \"0.514\"], [\"70384.30\", \"0.048\"], [\"70384.40\", \"0.008\"], [\"70384.60\", \"0.000\"], [\"70384.70\", \"0.350\"], [\"70386.30\", \"0.027\"], [\"70387.40\", \"0.290\"], [\"70387.60\", \"0.223\"], [\"70389.60\", \"0.517\"], [\"70407.70\", \"0.008\"], [\"70435.90\", \"0.005\"], [\"70443.60\", \"0.002\"], [\"70446.60\", \"0.027\"], [\"70448.10\", \"1.280\"], [\"70462.10\", \"0.817\"], [\"70483.40\", \"0.203\"], [\"70483.80\", \"0.000\"], [\"70484.10\", \"0.119\"], [\"70484.50\", \"0.207\"], [\"70484.80\", \"0.126\"], [\"70484.90\", \"0.005\"], [\"70485.20\", \"0.000\"], [\"70485.40\", \"0.083\"], [\"70485.50\", \"17.302\"], [\"70491.60\", \"0.002\"], [\"70492.20\", \"2.003\"], [\"70506.90\", \"0.053\"], [\"70513.30\", \"0.002\"], [\"70520.20\", \"0.000\"], [\"70529.50\", \"1.350\"], [\"70531.30\", \"0.011\"], [\"70536.50\", \"0.000\"], [\"70536.60\", \"0.036\"], [\"70538.30\", \"0.007\"], [\"70543.50\", \"0.000\"], [\"70543.70\", \"0.000\"], [\"70543.90\", \"0.000\"], [\"70544.10\", \"0.511\"], [\"70544.40\", \"0.002\"], [\"70544.80\", \"0.039\"], [\"70545.10\", \"0.003\"], [\"70545.30\", \"0.007\"], [\"70545.50\", \"0.000\"], [\"70545.60\", \"0.002\"], [\"70545.90\", \"0.198\"], [\"70546.20\", \"0.000\"], [\"70550.50\", \"0.000\"], [\"70552.30\", \"0.082\"], [\"70555.50\", \"0.013\"], [\"70557.50\", \"0.022\"], [\"70559.30\", \"2.761\"], [\"70564.50\", \"0.000\"], [\"70566.30\", \"0.212\"], [\"70571.50\", \"0.000\"], [\"70573.30\", \"0.007\"], [\"70578.50\", \"0.000\"], [\"70580.30\", \"0.007\"], [\"70587.80\", \"0.249\"], [\"70598.40\", \"0.005\"], [\"70637.10\", \"0.000\"], [\"70639.80\", \"0.044\"], [\"71070.90\", \"1.454\"], [\"71096.50\", \"0.380\"], [\"71174.70\", \"0.380\"], [\"71253.00\", \"2.945\"], [\"71331.20\", \"0.382\"], [\"71409.40\", \"0.380\"], [\"71487.60\", \"0.489\"], [\"71565.80\", \"0.380\"], [\"71644.00\", \"0.387\"], [\"71700.00\", \"28.168\"], [\"71722.20\", \"0.385\"], [\"71800.50\", \"0.393\"], [\"72555.00\", \"101.106\"], [\"73892.70\", \"0.002\"]]}", "symbol": "BTCUSDT"}
{"event": "depthUpdate", "raw_payload": "{\"e\": \"depthUpdate\", \"E\": 1773246390662, \"T\": 1773246390660, \"s\": \"BTCUSDT\", \"U\": 10089704359430, \"u\": 10089704365830, \"pu\": 10089704358856, \"b\": [[\"5000.00\", \"101.418\"], [\"19867.10\", \"0.470\"], [\"19967.10\", \"1.530\"], [\"20067.10\", \"0.550\"], [\"20167.10\", \"0.450\"], [\"68955.60\", \"0.000\"], [\"69663.40\", \"0.000\"], [\"69776.00\", \"0.045\"], [\"69886.50\", \"0.000\"], [\"70015.40\", \"0.007\"], [\"70133.30\", \"0.047\"], [\"70226.30\", \"0.129\"], [\"70232.50\", \"0.049\"], [\"70233.00\", \"0.288\"], [\"70234.10\", \"0.054\"], [\"70236.40\", \"0.645\"], [\"70236.60\", \"0.194\"], [\"70242.20\", \"0.083\"], [\"70255.30\", \"0.082\"], [\"70268.50\", \"0.002\"], [\"70275.30\", \"0.013\"], [\"70287.40\", \"6.548\"], [\"70298.50\", \"0.000\"], [\"70316.10\", \"0.141\"], [\"70316.50\", \"0.004\"], [\"70316.70\", \"0.109\"], [\"70319.60\", \"0.243\"], [\"70326.60\", \"0.000\"], [\"70327.10\", \"0.087\"], [\"70327.20\", \"0.040\"], [\"70327.30\", \"0.000\"], [\"70353.20\", \"0.000\"], [\"70353.60\", \"0.193\"], [\"70353.90\", \"0.152\"], [\"70354.60\", \"0.092\"], [\"70356.50\", \"0.661\"], [\"70357.10\", \"0.000\"], [\"70359.50\", \"0.003\"], [\"70360.20\", \"0.006\"]], \"a\": [[\"70367.20\", \"36.997\"], [\"70369.80\", \"0.012\"], [\"70374.30\", \"0.000\"], [\"70377.80\", \"0.000\"], [\"70380.30\", \"0.000\"], [\"70381.30\", \"0.003\"], [\"70381.60\", \"1.111\"], [\"70383.60\", \"0.006\"], [\"70383.80\", \"0.000\"], [\"70386.70\", \"0.040\"], [\"70387.30\", \"0.072\"], [\"70387.40\", \"0.326\"], [\"70387.70\", \"0.112\"], [\"70393.80\", \"0.271\"], [\"70395.10\", \"0.009\"], [\"70407.70\", \"0.005\"], [\"70435.90\", \"0.002\"], [\"70442.80\", \"0.254\"], [\"70446.90\", \"0.037\"], [\"70448.00\", \"0.079\"], [\"70448.30\", \"0.449\"], [\"70451.20\", \"0.036\"], [\"70492.20\", \"2.000\"], [\"70507.20\", \"0.038\"], [\"70507.70\", \"1.380\"], [\"70508.30\", \"0.073\"], [\"70508.80\", \"0.039\"], [\"70510.50\", \"0.000\"], [\"70515.00\", \"0.036\"], [\"70529.00\", \"0.000\"], [\"70536.50\", \"0.002\"], [\"70846.80\", \"3.744\"], [\"70847.80\", \"0.000\"], [\"71070.90\", \"1.454\"], [\"71282.00\", \"1.979\"], [\"73914.00\", \"0.102\"], [\"89523.20\", \"0.000\"]]}", "symbol": "BTCUSDT"}
{"event": "depthUpdate", "raw_payload": "{\"e\": \"depthUpdate\", \"E\": 1773246390764, \"T\": 1773246390761, \"s\": \"BTCUSDT\", \"U\": 10089704365952, \"u\": 10089704371027, \"pu\": 10089704365830, \"b\": [[\"1000.00\", \"26.792\"], [\"5000.00\", \"101.418\"], [\"19867.10\", \"0.630\"], [\"19967.10\", \"1.370\"], [\"20067.10\", \"0.640\"], [\"20167.10\", \"0.360\"], [\"66829.10\", \"0.004\"], [\"66834.20\", \"0.004\"], [\"69276.40\", \"4.027\"], [\"69655.30\", \"0.000\"], [\"69663.40\", \"0.000\"], [\"69888.20\", \"3.720\"], [\"70015.30\", \"0.044\"], [\"70093.20\", \"2.754\"], [\"70197.60\", \"0.328\"], [\"70232.70\", \"0.047\"], [\"70233.00\", \"0.331\"], [\"70233.10\", \"0.043\"], [\"70233.40\", \"0.047\"], [\"70233.70\", \"0.065\"], [\"70234.40\", \"0.074\"], [\"70242.20\", \"0.083\"], [\"70289.70\", \"0.263\"], [\"70298.50\", \"0.000\"], [\"70316.50\", \"0.006\"], [\"70316.70\", \"0.107\"], [\"70326.60\", \"0.000\"], [\"70327.10\", \"0.002\"], [\"70327.20\", \"0.125\"], [\"70353.60\", \"0.279\"], [\"70353.90\", \"0.239\"], [\"70354.30\", \"0.076\"], [\"70354.60\", \"0.135\"], [\"70355.30\", \"0.053\"], [\"70356.50\", \"0.661\"], [\"70359.50\", \"0.000\"], [\"70359.90\", \"0.205\"], [\"70365.10\", \"0.008\"], [\"70366.00\", \"0.003\"], [\"70367.10\", \"3.392\"]], \"a\": [[\"70367.20\", \"36.939\"], [\"70374.60\", \"0.002\"], [\"70377.80\", \"0.000\"], [\"70381.10\", \"0.000\"], [\"70385.90\", \"0.025\"], [\"70386.70\", \"0.065\"], [\"70387.00\", \"0.093\"], [\"70387.30\", \"0.108\"], [\"70387.40\", \"0.362\"], [\"70387.70\", \"0.184\"], [\"70394.10\", \"0.000\"], [\"70394.50\", \"0.056\"], [\"70395.10\", \"0.011\"], [\"70407.70\", \"0.005\"], [\"70430.30\", \"0.000\"], [\"70430.50\", \"0.641\"], [\"70435.90\", \"0.002\"], [\"70441.10\", \"0.102\"], [\"70446.40\", \"0.029\"], [\"70447.30\", \"0.041\"], [\"70447.40\", \"0.025\"], [\"70447.60\", \"0.036\"], [\"70448.00\", \"0.115\"], [\"70448.10\", \"1.316\"], [\"70465.50\", \"0.117\"], [\"70466.20\", \"0.002\"], [\"70471.70\", \"0.089\"], [\"70476.40\", \"0.002\"], [\"70492.20\", \"2.000\"], [\"70506.80\", \"0.027\"], [\"70507.60\", \"0.358\"], [\"70507.90\", \"0.036\"], [\"70508.30\", \"0.109\"], [\"70508.60\", \"0.049\"], [\"70543.70\", \"0.036\"], [\"70645.10\", \"2.780\"], [\"70846.00\", \"3.933\"], [\"70846.80\", \"0.024\"], [\"71062.60\", \"0.011\"], [\"71070.90\", \"1.454\"]]}", "symbol": "BTCUSDT"}
{"event": "depthUpdate", "raw_payload": "{\"e\": \"depthUpdate\", \"E\": 1773246390866, \"T\": 1773246390865, \"s\": \"BTCUSDT\", \"U\": 10089704371206, \"u\": 10089704376382, \"pu\": 10089704371027, \"b\": [[\"1000.00\", \"26.792\"], [\"5000.00\", \"101.418\"], [\"19867.10\", \"0.810\"], [\"19967.10\", \"1.190\"], [\"20067.10\", \"0.720\"], [\"20167.10\", \"0.280\"], [\"63330.40\", \"0.016\"], [\"67552.40\", \"0.000\"], [\"69276.40\", \"4.892\"], [\"69663.40\", \"0.002\"], [\"69888.20\", \"0.000\"], [\"69889.00\", \"3.722\"], [\"70130.10\", \"0.050\"], [\"70171.70\", \"0.421\"], [\"70171.90\", \"0.049\"], [\"70173.80\", \"0.054\"], [\"70174.20\", \"10.495\"], [\"70226.50\", \"0.193\"], [\"70256.20\", \"0.079\"], [\"70263.50\", \"0.083\"], [\"70327.10\", \"0.002\"], [\"70327.20\", \"0.125\"], [\"70357.80\", \"0.005\"], [\"70360.70\", \"0.864\"], [\"70367.10\", \"3.426\"]], \"a\": [[\"70369.80\", \"0.012\"], [\"70374.20\", \"0.003\"], [\"70377.60\", \"0.000\"], [\"70377.80\", \"0.003\"], [\"70379.00\", \"0.001\"], [\"70394.50\", \"0.005\"], [\"70398.30\", \"0.000\"], [\"70405.30\", \"0.084\"], [\"70407.70\", \"0.005\"], [\"70415.40\", \"0.564\"], [\"70435.90\", \"0.002\"], [\"70508.90\", \"0.064\"], [\"70624.60\", \"0.000\"], [\"70845.30\", \"0.060\"], [\"70846.00\", \"0.213\"], [\"70846.70\", \"0.006\"], [\"71070.90\", \"1.454\"], [\"71326.50\", \"0.000\"], [\"71429.20\", \"0.701\"], [\"71444.50\", \"0.554\"], [\"73898.80\", \"0.000\"], [\"73916.30\", \"0.002\"], [\"77403.90\", \"0.002\"], [\"89523.20\", \"0.000\"]]}", "symbol": "BTCUSDT"}
{"event": "depthUpdate", "raw_payload": "{\"e\": \"depthUpdate\", \"E\": 1773246390968, \"T\": 1773246390967, \"s\": \"BTCUSDT\", \"U\": 10089704376452, \"u\": 10089704382798, \"pu\": 10089704376382, \"b\": [[\"5000.00\", \"101.398\"], [\"19867.10\", \"0.970\"], [\"19967.10\", \"1.030\"], [\"20067.10\", \"0.810\"], [\"20167.10\", \"0.190\"], [\"33000.00\", \"10.797\"], [\"63330.40\", \"0.014\"], [\"68893.00\", \"0.012\"], [\"69061.00\", \"0.000\"], [\"69663.40\", \"0.000\"], [\"69889.00\", \"0.002\"], [\"70015.40\", \"0.000\"], [\"70133.40\", \"0.007\"], [\"70162.40\", \"0.047\"], [\"70172.70\", \"0.649\"], [\"70173.10\", \"0.047\"], [\"70226.00\", \"0.080\"], [\"70242.20\", \"0.086\"], [\"70253.20\", \"0.382\"], [\"70266.30\", \"0.079\"], [\"70286.20\", \"0.099\"], [\"70290.50\", \"1.540\"], [\"70295.60\", \"0.001\"], [\"70306.50\", \"0.020\"], [\"70307.80\", \"1.456\"], [\"70318.50\", \"0.636\"], [\"70327.10\", \"0.087\"], [\"70327.20\", \"0.040\"], [\"70333.20\", \"2.093\"], [\"70337.90\", \"0.402\"], [\"70367.10\", \"3.354\"]], \"a\": [[\"70373.50\", \"0.000\"], [\"70376.70\", \"0.067\"], [\"70377.10\", \"0.014\"], [\"70393.80\", \"0.273\"], [\"70402.30\", \"0.033\"], [\"70409.50\", \"0.963\"], [\"70415.40\", \"0.513\"], [\"70423.40\", \"0.243\"], [\"70430.50\", \"0.972\"], [\"70492.20\", \"2.003\"], [\"70507.60\", \"0.610\"], [\"70602.30\", \"0.006\"], [\"70644.70\", \"0.873\"], [\"70844.60\", \"3.720\"], [\"70846.70\", \"0.000\"], [\"71070.90\", \"1.454\"], [\"71429.90\", \"0.699\"], [\"73913.80\", \"0.002\"], [\"77403.90\", \"0.000\"]]}", "symbol": "BTCUSDT"}
{"event": "depthUpdate", "raw_payload": "{\"e\": \"depthUpdate\", \"E\": 1773246391070, \"T\": 1773246391068, \"s\": \"BTCUSDT\", \"U\": 10089704382807, \"u\": 10089704392826, \"pu\": 10089704382798, \"b\": [[\"1000.00\", \"26.792\"], [\"5000.00\", \"101.418\"], [\"19867.10\", \"1.150\"], [\"19967.10\", \"0.850\"], [\"20067.10\", \"0.890\"], [\"20167.10\", \"0.110\"], [\"33000.00\", \"10.793\"], [\"56294.00\", \"0.000\"], [\"69451.50\", \"0.000\"], [\"69663.40\", \"0.000\"], [\"69776.00\", \"0.113\"], [\"69890.20\", \"4.007\"], [\"70015.30\", \"0.044\"], [\"70050.60\", \"0.003\"], [\"70099.00\", \"0.011\"], [\"70108.40\", \"0.002\"], [\"70119.50\", \"0.258\"], [\"70172.20\", \"0.050\"], [\"70172.70\", \"0.692\"], [\"70172.80\", \"0.046\"], [\"70173.40\", \"0.247\"], [\"70174.40\", \"3.261\"], [\"70259.80\", \"0.002\"], [\"70279.50\", \"0.071\"], [\"70279.70\", \"0.003\"], [\"70286.60\", \"0.110\"], [\"70286.80\", \"0.390\"], [\"70292.40\", \"0.020\"], [\"70293.20\", \"0.309\"], [\"70293.60\", \"0.080\"], [\"70293.80\", \"0.004\"], [\"70295.40\", \"0.016\"], [\"70296.80\", \"0.006\"], [\"70296.90\", \"0.260\"], [\"70314.30\", \"0.709\"], [\"70316.50\", \"0.004\"], [\"70316.60\", \"0.004\"], [\"70316.70\", \"0.207\"], [\"70319.10\", \"0.002\"], [\"70321.80\", \"0.493\"], [\"70322.00\", \"0.625\"], [\"70326.10\", \"0.089\"], [\"70326.60\", \"0.003\"], [\"70327.00\", \"0.518\"], [\"70327.10\", \"0.002\"], [\"70329.00\", \"0.653\"], [\"70336.00\", \"0.711\"], [\"70341.10\", \"0.000\"], [\"70343.00\", \"1.837\"], [\"70343.80\", \"0.518\"], [\"70350.00\", \"0.629\"], [\"70353.20\", \"0.002\"], [\"70356.40\", \"1.211\"], [\"70357.10\", \"0.332\"], [\"70359.30\", \"0.000\"], [\"70360.20\", \"0.008\"], [\"70360.80\", \"0.186\"], [\"70362.90\", \"0.000\"], [\"70367.10\", \"3.299\"]], \"a\": [[\"70368.30\", \"0.002\"], [\"70369.80\", \"0.012\"], [\"70372.70\", \"0.002\"], [\"70374.20\", \"0.006\"], [\"70375.80\", \"0.005\"], [\"70379.90\", \"0.002\"], [\"70387.30\", \"0.110\"], [\"70388.70\", \"0.000\"], [\"70390.40\", \"0.249\"], [\"70392.00\", \"1.013\"], [\"70393.90\", \"0.008\"], [\"70394.50\", \"0.005\"], [\"70398.90\", \"0.010\"], [\"70399.00\", \"0.623\"], [\"70402.30\", \"0.005\"], [\"70406.00\", \"1.701\"], [\"70407.70\", \"0.008\"], [\"70410.30\", \"0.073\"], [\"70410.40\", \"0.000\"], [\"70413.00\", \"1.695\"], [\"70416.40\", \"0.251\"], [\"70418.00\", \"0.438\"], [\"70419.30\", \"0.002\"], [\"70420.00\", \"1.883\"], [\"70423.40\", \"0.192\"], [\"70427.40\", \"0.050\"], [\"70428.50\", \"0.053\"], [\"70429.60\", \"1.161\"], [\"70430.50\", \"0.844\"], [\"70435.90\", \"0.005\"], [\"70436.70\", \"0.258\"], [\"70455.60\", \"0.071\"], [\"70456.10\", \"0.020\"], [\"70462.60\", \"0.073\"], [\"70463.10\", \"0.009\"], [\"70469.70\", \"0.156\"], [\"70470.20\", \"0.087\"], [\"70507.80\", \"0.226\"], [\"70602.30\", \"0.000\"], [\"70645.00\", \"0.006\"], [\"70844.00\", \"3.720\"], [\"70844.60\", \"0.000\"], [\"71070.90\", \"1.454\"], [\"71401.60\", \"1.328\"], [\"73897.40\", \"0.000\"], [\"73904.60\", \"0.002\"], [\"89523.20\", \"0.000\"]]}", "symbol": "BTCUSDT"}
{"event": "depthUpdate", "raw_payload": "{\"e\": \"depthUpdate\", \"E\": 1773246391172, \"T\": 1773246391171, \"s\": \"BTCUSDT\", \"U\": 10089704392911, \"u\": 10089704401974, \"pu\": 10089704392826, \"b\": [[\"1000.00\", \"26.792\"], [\"5000.00\", \"101.418\"], [\"19867.10\", \"1.310\"], [\"19967.10\", \"0.690\"], [\"20067.10\", \"0.980\"], [\"20167.10\", \"0.020\"], [\"40000.00\", \"50.522\"], [\"66821.30\", \"0.000\"], [\"68959.70\", \"0.009\"], [\"69663.40\", \"0.000\"], [\"69890.20\", \"0.287\"], [\"69890.80\", \"3.720\"], [\"70279.40\", \"0.154\"], [\"70279.50\", \"0.000\"], [\"70279.60\", \"0.168\"], [\"70286.50\", \"0.073\"], [\"70286.60\", \"0.039\"], [\"70289.70\", \"0.481\"], [\"70293.30\", \"1.628\"], [\"70293.40\", \"0.050\"], [\"70293.50\", \"0.098\"], [\"70293.60\", \"0.009\"], [\"70294.70\", \"0.054\"], [\"70297.40\", \"0.002\"], [\"70298.50\", \"0.003\"], [\"70301.20\", \"3.602\"], [\"70314.30\", \"0.760\"], [\"70316.10\", \"0.143\"], [\"70316.60\", \"0.007\"], [\"70316.70\", \"0.107\"], [\"70322.00\", \"0.004\"], [\"70324.90\", \"2.229\"], [\"70325.30\", \"0.002\"], [\"70325.40\", \"0.734\"], [\"70326.00\", \"0.003\"], [\"70326.10\", \"0.004\"], [\"70326.20\", \"0.000\"], [\"70327.10\", \"0.250\"], [\"70329.00\", \"0.032\"], [\"70329.30\", \"0.000\"], [\"70331.00\", \"0.005\"], [\"70333.20\", \"2.087\"], [\"70335.40\", \"0.053\"], [\"70336.00\", \"0.090\"], [\"70337.20\", \"0.174\"], [\"70338.90\", \"0.320\"], [\"70339.40\", \"0.521\"], [\"70340.30\", \"0.061\"], [\"70340.60\", \"0.000\"], [\"70340.70\", \"0.075\"], [\"70341.10\", \"0.639\"], [\"70341.50\", \"0.054\"], [\"70342.20\", \"0.002\"], [\"70342.40\", \"0.000\"], [\"70342.60\", \"0.450\"], [\"70343.00\", \"0.577\"], [\"70343.70\", \"0.015\"], [\"70343.80\", \"0.007\"], [\"70344.30\", \"0.084\"], [\"70345.20\", \"0.001\"], [\"70347.40\", \"0.000\"], [\"70348.50\", \"0.017\"], [\"70348.60\", \"0.015\"], [\"70348.70\", \"0.071\"], [\"70349.40\", \"0.580\"], [\"70349.50\", \"1.070\"], [\"70349.60\", \"0.000\"], [\"70349.80\", \"0.012\"], [\"70350.00\", \"0.008\"], [\"70350.30\", \"0.004\"], [\"70350.40\", \"0.000\"], [\"70350.50\", \"0.104\"], [\"70351.40\", \"0.129\"], [\"70351.60\", \"0.076\"], [\"70351.80\", \"0.120\"], [\"70351.90\", \"0.013\"], [\"70352.60\", \"0.188\"], [\"70352.70\", \"0.200\"], [\"70352.80\", \"0.002\"], [\"70352.90\", \"0.064\"], [\"70353.00\", \"0.578\"], [\"70353.10\", \"0.007\"], [\"70353.20\", \"0.000\"], [\"70353.30\", \"0.000\"], [\"70353.40\", \"0.003\"], [\"70353.50\", \"0.266\"], [\"70353.60\", \"0.612\"], [\"70353.70\", \"0.016\"], [\"70354.00\", \"1.207\"], [\"70354.30\", \"0.360\"], [\"70354.60\", \"0.135\"], [\"70355.10\", \"0.018\"], [\"70355.20\", \"0.017\"], [\"70355.40\", \"0.145\"], [\"70356.10\", \"0.003\"], [\"70356.20\", \"0.046\"], [\"70356.40\", \"0.004\"], [\"70356.50\", \"0.610\"], [\"70356.90\", \"0.001\"], [\"70357.00\", \"0.007\"], [\"70357.20\", \"0.656\"], [\"70357.50\", \"0.008\"], [\"70357.90\", \"0.008\"], [\"70358.30\", \"0.007\"], [\"70358.60\", \"0.006\"], [\"70358.70\", \"0.006\"], [\"70359.00\", \"0.002\"], [\"70359.50\", \"0.000\"], [\"70360.00\", \"0.007\"], [\"70360.20\", \"0.006\"], [\"70360.60\", \"0.003\"], [\"70360.70\", \"0.202\"], [\"70360.80\", \"0.005\"], [\"70360.90\", \"0.004\"], [\"70361.40\", \"0.037\"], [\"70361.80\", \"0.000\"], [\"70362.00\", \"0.003\"], [\"70362.50\", \"0.002\"], [\"70362.60\", \"0.016\"], [\"70363.30\", \"0.007\"], [\"70363.50\", \"0.002\"], [\"70364.00\", \"0.005\"], [\"70365.50\", \"0.000\"], [\"70365.70\", \"0.000\"], [\"70365.90\", \"0.002\"], [\"70366.00\", \"0.001\"], [\"70367.10\", \"3.012\"]], \"a\": [[\"70367.20\", \"37.344\"], [\"70368.20\", \"0.002\"], [\"70368.30\", \"0.025\"], [\"70374.20\", \"0.034\"], [\"70376.10\", \"0.023\"], [\"70376.70\", \"0.181\"], [\"70376.80\", \"0.103\"], [\"70377.00\", \"0.513\"], [\"70377.80\", \"0.642\"], [\"70377.90\", \"0.003\"], [\"70378.00\", \"0.205\"], [\"70378.60\", \"0.000\"], [\"70381.00\", \"0.031\"], [\"70381.60\", \"0.472\"], [\"70381.90\", \"0.028\"], [\"70382.70\", \"0.000\"], [\"70382.90\", \"0.007\"], [\"70383.70\", \"0.002\"], [\"70384.50\", \"0.004\"], [\"70384.90\", \"0.142\"], [\"70385.00\", \"0.482\"], [\"70385.40\", \"0.007\"], [\"70385.80\", \"0.515\"], [\"70386.00\", \"0.319\"], [\"70386.50\", \"0.321\"], [\"70386.60\", \"0.002\"], [\"70387.40\", \"0.305\"], [\"70388.20\", \"0.013\"], [\"70389.40\", \"0.052\"], [\"70389.60\", \"0.008\"], [\"70389.90\", \"0.076\"], [\"70390.30\", \"0.071\"], [\"70390.40\", \"0.001\"], [\"70391.40\", \"0.010\"], [\"70391.70\", \"0.000\"], [\"70391.80\", \"0.000\"], [\"70392.00\", \"0.392\"], [\"70393.40\", \"0.000\"], [\"70393.80\", \"0.246\"], [\"70399.00\", \"0.002\"], [\"70405.10\", \"0.048\"], [\"70406.00\", \"1.080\"], [\"70413.00\", \"1.074\"], [\"70416.60\", \"0.006\"], [\"70418.00\", \"0.458\"], [\"70420.00\", \"1.262\"], [\"70423.10\", \"0.003\"], [\"70423.50\", \"0.086\"], [\"70427.40\", \"0.030\"], [\"70428.50\", \"0.002\"], [\"70428.60\", \"0.000\"], [\"70428.70\", \"0.131\"], [\"70429.60\", \"1.033\"], [\"70440.90\", \"0.210\"], [\"70455.60\", \"0.071\"], [\"70462.60\", \"0.073\"], [\"70469.70\", \"0.156\"], [\"70501.60\", \"0.011\"], [\"70519.00\", \"0.004\"], [\"70519.30\", \"0.004\"], [\"70589.40\", \"0.027\"], [\"70593.10\", \"0.004\"], [\"70747.70\", \"0.002\"], [\"70750.50\", \"0.000\"], [\"70843.50\", \"3.720\"], [\"70844.00\", \"0.000\"], [\"70880.70\", \"0.000\"], [\"71070.90\", \"1.454\"], [\"71093.40\", \"0.010\"], [\"71306.00\", \"0.005\"], [\"71518.70\", \"0.000\"], [\"71544.40\", \"0.000\"], [\"71731.30\", \"0.000\"], [\"74133.30\", \"0.023\"]]}", "symbol": "BTCUSDT"}
{"event": "depthUpdate", "raw_payload": "{\"e\": \"depthUpdate\", \"E\": 1773246391274, \"T\": 1773246391272, \"s\": \"BTCUSDT\", \"U\": 10089704402115, \"u\": 10089704408882, \"pu\": 10089704401974, \"b\": [[\"5000.00\", \"101.418\"], [\"19867.10\", \"1.490\"], [\"19967.10\", \"0.570\"], [\"20067.10\", \"0.940\"], [\"20167.10\", \"0.000\"], [\"66826.60\", \"0.003\"], [\"66848.00\", \"0.004\"], [\"69663.40\", \"0.000\"], [\"69890.80\", \"0.000\"], [\"70171.90\", \"0.002\"], [\"70293.70\", \"0.058\"], [\"70315.70\", \"0.393\"], [\"70316.60\", \"0.005\"], [\"70330.70\", \"0.006\"], [\"70334.20\", \"0.040\"], [\"70337.20\", \"0.014\"], [\"70340.30\", \"0.021\"], [\"70340.60\", \"0.080\"], [\"70349.40\", \"0.700\"], [\"70349.60\", \"0.002\"], [\"70349.80\", \"0.014\"], [\"70351.40\", \"0.127\"], [\"70351.60\", \"0.074\"], [\"70351.80\", \"0.006\"], [\"70355.30\", \"0.058\"], [\"70357.10\", \"0.000\"], [\"70357.20\", \"0.656\"], [\"70357.50\", \"0.008\"], [\"70358.10\", \"0.000\"], [\"70358.30\", \"0.007\"], [\"70360.40\", \"0.002\"], [\"70360.50\", \"0.162\"], [\"70360.80\", \"0.003\"], [\"70365.50\", \"0.002\"], [\"70367.10\", \"3.075\"]], \"a\": [[\"70368.30\", \"0.027\"], [\"70369.70\", \"0.003\"], [\"70371.50\", \"0.076\"], [\"70371.60\", \"0.348\"], [\"70371.90\", \"0.000\"], [\"70374.20\", \"0.006\"], [\"70376.30\", \"0.257\"], [\"70376.70\", \"0.262\"], [\"70377.20\", \"0.007\"], [\"70377.80\", \"0.639\"], [\"70379.30\", \"0.382\"], [\"70385.00\", \"0.719\"], [\"70385.20\", \"0.062\"], [\"70385.90\", \"0.025\"], [\"70386.50\", \"0.264\"], [\"70387.20\", \"0.002\"], [\"70387.60\", \"0.225\"], [\"70387.70\", \"0.191\"], [\"70387.80\", \"0.004\"], [\"70389.40\", \"0.050\"], [\"70389.60\", \"0.006\"], [\"70390.30\", \"0.000\"], [\"70391.50\", \"0.355\"], [\"70396.50\", \"0.004\"], [\"70418.00\", \"0.438\"], [\"70419.00\", \"0.121\"], [\"70479.60\", \"0.270\"], [\"70548.90\", \"0.000\"], [\"70578.30\", \"10.062\"], [\"70841.60\", \"3.722\"], [\"70843.50\", \"0.000\"], [\"71359.60\", \"1.394\"], [\"73181.80\", \"0.010\"], [\"73887.80\", \"0.012\"], [\"89523.20\", \"0.000\"]]}", "symbol": "BTCUSDT"}
{"event": "depthUpdate", "raw_payload": "{\"e\": \"depthUpdate\", \"E\": 1773246391378, \"T\": 1773246391377, \"s\": \"BTCUSDT\", \"U\": 10089704409045, \"u\": 10089704418211, \"pu\": 10089704408882, \"b\": [[\"1000.00\", \"26.792\"], [\"5000.00\", \"101.418\"], [\"19867.10\", \"1.620\"], [\"19967.10\", \"0.510\"], [\"20067.10\", \"0.850\"], [\"20267.10\", \"0.020\"], [\"56294.00\", \"0.000\"], [\"65051.60\", \"0.000\"], [\"66834.30\", \"0.045\"], [\"68348.60\", \"0.002\"], [\"68407.50\", \"0.000\"], [\"68958.10\", \"0.004\"], [\"68959.80\", \"0.013\"], [\"69663.40\", \"0.000\"], [\"69795.20\", \"3.240\"], [\"69804.20\", \"0.072\"], [\"69921.10\", \"0.648\"], [\"70015.30\", \"0.044\"], [\"70026.00\", \"0.000\"], [\"70026.10\", \"1.261\"], [\"70026.30\", \"0.245\"], [\"70094.20\", \"0.000\"], [\"70094.30\", \"1.715\"], [\"70133.40\", \"0.000\"], [\"70172.70\", \"0.652\"], [\"70172.80\", \"0.003\"], [\"70251.80\", \"0.002\"], [\"70253.80\", \"0.023\"], [\"70276.30\", \"0.040\"], [\"70294.20\", \"0.048\"], [\"70295.10\", \"0.035\"], [\"70295.30\", \"0.037\"], [\"70315.70\", \"0.391\"], [\"70315.90\", \"0.105\"], [\"70325.20\", \"0.276\"], [\"70325.40\", \"0.649\"], [\"70342.60\", \"0.379\"], [\"70345.50\", \"0.078\"], [\"70350.50\", \"0.003\"], [\"70351.10\", \"0.004\"], [\"70355.10\", \"0.119\"], [\"70355.40\", \"0.003\"], [\"70357.30\", \"0.142\"], [\"70357.50\", \"0.008\"], [\"70358.30\", \"0.007\"], [\"70361.90\", \"0.003\"], [\"70367.10\", \"3.077\"]], \"a\": [[\"70367.20\", \"37.020\"], [\"70376.70\", \"0.190\"], [\"70377.80\", \"0.000\"], [\"70379.20\", \"0.000\"], [\"70379.30\", \"0.384\"], [\"70380.60\", \"0.642\"], [\"70381.60\", \"0.474\"], [\"70384.90\", \"0.000\"], [\"70385.00\", \"0.776\"], [\"70385.20\", \"0.005\"], [\"70385.60\", \"0.142\"], [\"70385.80\", \"0.004\"], [\"70386.00\", \"0.071\"], [\"70387.20\", \"0.002\"], [\"70388.20\", \"0.258\"], [\"70388.70\", \"0.511\"], [\"70389.60\", \"0.009\"], [\"70389.90\", \"0.005\"], [\"70391.30\", \"0.017\"], [\"70391.50\", \"0.284\"], [\"70392.50\", \"0.111\"], [\"70392.70\", \"0.255\"], [\"70393.80\", \"0.195\"], [\"70401.80\", \"0.000\"], [\"70401.90\", \"1.073\"], [\"70402.30\", \"0.033\"], [\"70402.50\", \"0.019\"], [\"70402.60\", \"0.156\"], [\"70403.20\", \"0.000\"], [\"70403.30\", \"0.155\"], [\"70403.90\", \"0.002\"], [\"70404.00\", \"0.388\"], [\"70405.10\", \"0.003\"], [\"70408.80\", \"0.003\"], [\"70408.90\", \"0.002\"], [\"70409.50\", \"0.965\"], [\"70409.60\", \"0.004\"], [\"70414.40\", \"0.053\"], [\"70419.00\", \"0.101\"], [\"70426.10\", \"0.212\"], [\"70427.60\", \"0.052\"], [\"70428.50\", \"0.130\"], [\"70428.70\", \"0.003\"], [\"70473.60\", \"0.047\"], [\"70630.30\", \"0.000\"], [\"70632.70\", \"0.189\"], [\"70708.90\", \"0.079\"], [\"70710.40\", \"0.002\"], [\"71070.90\", \"1.454\"], [\"71707.80\", \"0.677\"], [\"73890.90\", \"0.002\"], [\"73904.60\", \"0.000\"], [\"75257.70\", \"0.002\"]]}", "symbol": "BTCUSDT"}
{"event": "depthUpdate", "raw_payload": "{\"e\": \"depthUpdate\", \"E\": 1773246391480, \"T\": 1773246391479, \"s\": \"BTCUSDT\", \"U\": 10089704418693, \"u\": 10089704428556, \"pu\": 10089704418211, \"b\": [[\"1000.00\", \"26.792\"], [\"5000.00\", \"101.418\"], [\"19867.10\", \"1.610\"], [\"19967.10\", \"0.510\"], [\"20067.10\", \"0.770\"], [\"20267.10\", \"0.110\"], [\"40000.00\", \"50.271\"], [\"56294.00\", \"0.000\"], [\"66848.70\", \"0.007\"], [\"68716.80\", \"0.002\"], [\"68900.00\", \"10.425\"], [\"68959.80\", \"0.006\"], [\"69663.40\", \"0.000\"], [\"69854.10\", \"0.000\"], [\"69890.40\", \"0.000\"], [\"70130.10\", \"0.003\"], [\"70133.00\", \"4.822\"], [\"70171.70\", \"0.396\"], [\"70173.80\", \"0.000\"], [\"70174.20\", \"10.460\"], [\"70314.30\", \"0.760\"], [\"70315.90\", \"0.103\"], [\"70316.10\", \"0.145\"], [\"70319.30\", \"0.000\"], [\"70324.20\", \"0.172\"], [\"70325.10\", \"0.114\"], [\"70325.20\", \"0.191\"], [\"70327.10\", \"0.002\"], [\"70331.70\", \"0.250\"], [\"70334.10\", \"0.205\"], [\"70335.40\", \"0.002\"], [\"70337.30\", \"0.007\"], [\"70338.90\", \"0.002\"], [\"70339.40\", \"0.010\"], [\"70340.60\", \"0.000\"], [\"70340.70\", \"0.004\"], [\"70341.10\", \"0.000\"], [\"70344.50\", \"0.710\"], [\"70344.60\", \"0.511\"], [\"70348.70\", \"0.151\"], [\"70348.90\", \"0.698\"], [\"70349.40\", \"0.698\"], [\"70349.60\", \"0.511\"], [\"70349.80\", \"0.012\"], [\"70351.30\", \"0.038\"], [\"70351.40\", \"0.148\"], [\"70351.50\", \"0.030\"], [\"70351.70\", \"0.025\"], [\"70352.00\", \"0.002\"], [\"70352.50\", \"0.004\"], [\"70353.00\", \"1.356\"], [\"70353.10\", \"0.007\"], [\"70353.50\", \"0.365\"], [\"70354.50\", \"0.079\"], [\"70354.60\", \"0.210\"], [\"70354.70\", \"0.003\"], [\"70355.00\", \"0.280\"], [\"70355.10\", \"0.119\"], [\"70355.20\", \"1.083\"], [\"70355.40\", \"0.046\"], [\"70356.50\", \"0.661\"], [\"70356.70\", \"0.028\"], [\"70356.80\", \"0.090\"], [\"70357.40\", \"0.000\"], [\"70357.50\", \"0.018\"], [\"70357.80\", \"0.002\"], [\"70358.30\", \"0.017\"], [\"70358.40\", \"0.003\"], [\"70358.70\", \"0.006\"], [\"70358.80\", \"0.049\"], [\"70360.10\", \"0.097\"], [\"70360.50\", \"0.294\"], [\"70360.80\", \"0.401\"], [\"70361.30\", \"0.401\"], [\"70361.50\", \"0.156\"], [\"70363.50\", \"0.002\"], [\"70367.10\", \"3.041\"]], \"a\": [[\"70367.20\", \"37.205\"], [\"70368.20\", \"0.000\"], [\"70368.30\", \"0.029\"], [\"70369.80\", \"0.012\"], [\"70374.20\", \"0.006\"], [\"70376.10\", \"0.002\"], [\"70376.80\", \"0.082\"], [\"70378.00\", \"0.005\"], [\"70378.10\", \"0.002\"], [\"70378.80\", \"0.004\"], [\"70379.30\", \"0.382\"], [\"70380.40\", \"0.187\"], [\"70380.60\", \"0.003\"], [\"70381.00\", \"0.003\"], [\"70381.90\", \"0.639\"], [\"70382.90\", \"0.000\"], [\"70383.90\", \"0.514\"], [\"70384.20\", \"0.013\"], [\"70385.60\", \"0.000\"], [\"70386.40\", \"0.142\"], [\"70387.60\", \"0.223\"], [\"70387.70\", \"0.184\"], [\"70387.80\", \"0.002\"], [\"70388.20\", \"0.010\"], [\"70388.70\", \"0.000\"], [\"70389.60\", \"0.011\"], [\"70389.80\", \"0.008\"], [\"70389.90\", \"0.007\"], [\"70390.30\", \"0.248\"], [\"70390.40\", \"0.512\"], [\"70392.50\", \"0.040\"], [\"70392.70\", \"0.184\"], [\"70394.20\", \"0.161\"], [\"70394.40\", \"0.073\"], [\"70395.20\", \"0.031\"], [\"70398.90\", \"0.010\"], [\"70401.80\", \"0.009\"], [\"70401.90\", \"1.082\"], [\"70402.30\", \"0.033\"], [\"70402.50\", \"0.010\"], [\"70402.60\", \"0.147\"], [\"70405.30\", \"0.004\"], [\"70408.80\", \"0.005\"], [\"70408.90\", \"0.004\"], [\"70409.50\", \"0.963\"], [\"70409.60\", \"0.002\"], [\"70414.40\", \"0.008\"], [\"70419.00\", \"0.121\"], [\"70421.00\", \"0.045\"], [\"70422.60\", \"0.000\"], [\"70426.10\", \"0.192\"], [\"70427.60\", \"0.001\"], [\"70428.90\", \"0.001\"], [\"70432.70\", \"0.028\"], [\"70435.80\", \"0.069\"], [\"70636.00\", \"0.002\"], [\"70754.20\", \"0.003\"], [\"70841.60\", \"0.002\"], [\"70843.80\", \"0.003\"], [\"70877.20\", \"3.720\"], [\"70880.20\", \"0.000\"], [\"71070.90\", \"1.454\"], [\"73901.60\", \"0.002\"], [\"73913.80\", \"0.000\"], [\"89523.20\", \"0.000\"]]}", "symbol": "BTCUSDT"}
{"event": "depthUpdate", "raw_payload": "{\"e\": \"depthUpdate\", \"E\": 1773246391582, \"T\": 1773246391581, \"s\": \"BTCUSDT\", \"U\": 10089704428670, \"u\": 10089704438037, \"pu\": 10089704428556, \"b\": [[\"5000.00\", \"101.418\"], [\"19867.10\", \"1.620\"], [\"19967.10\", \"0.510\"], [\"20067.10\", \"0.680\"], [\"20267.10\", \"0.190\"], [\"33000.00\", \"10.797\"], [\"66826.20\", \"0.002\"], [\"66831.30\", \"0.006\"], [\"67552.50\", \"0.012\"], [\"68983.20\", \"0.000\"], [\"70242.20\", \"0.083\"], [\"70269.90\", \"0.000\"], [\"70292.10\", \"0.020\"], [\"70292.40\", \"0.002\"], [\"70298.50\", \"0.000\"], [\"70316.10\", \"0.143\"], [\"70316.70\", \"0.109\"], [\"70325.00\", \"0.293\"], [\"70325.10\", \"0.029\"], [\"70326.60\", \"0.000\"], [\"70329.30\", \"0.248\"], [\"70331.70\", \"0.002\"], [\"70338.90\", \"0.320\"], [\"70340.10\", \"0.513\"], [\"70342.40\", \"0.071\"], [\"70342.60\", \"1.018\"], [\"70343.60\", \"0.074\"], [\"70344.50\", \"0.000\"], [\"70344.60\", \"0.000\"], [\"70344.70\", \"0.511\"], [\"70345.50\", \"0.007\"], [\"70349.50\", \"1.072\"], [\"70349.90\", \"0.002\"], [\"70350.20\", \"0.179\"], [\"70351.70\", \"0.023\"], [\"70352.00\", \"0.000\"], [\"70352.50\", \"0.002\"], [\"70353.00\", \"1.038\"], [\"70355.20\", \"1.083\"], [\"70355.50\", \"0.143\"], [\"70356.40\", \"0.004\"], [\"70356.50\", \"0.610\"], [\"70356.60\", \"0.006\"], [\"70357.20\", \"0.001\"], [\"70357.30\", \"0.000\"], [\"70357.50\", \"0.008\"], [\"70358.30\", \"0.007\"], [\"70360.50\", \"0.160\"], [\"70360.60\", \"0.658\"], [\"70360.80\", \"0.003\"], [\"70361.30\", \"0.003\"], [\"70361.40\", \"0.037\"], [\"70365.70\", \"0.002\"], [\"70367.10\", \"3.090\"]], \"a\": [[\"70368.20\", \"0.002\"], [\"70368.30\", \"0.027\"], [\"70378.00\", \"0.205\"], [\"70379.40\", \"1.071\"], [\"70384.60\", \"0.142\"], [\"70386.40\", \"0.000\"], [\"70387.80\", \"0.004\"], [\"70388.10\", \"0.002\"], [\"70389.60\", \"0.009\"], [\"70389.90\", \"0.005\"], [\"70394.00\", \"0.202\"], [\"70403.20\", \"0.002\"], [\"70403.30\", \"0.157\"], [\"70403.90\", \"0.000\"], [\"70404.00\", \"0.386\"], [\"70407.70\", \"0.005\"], [\"70408.70\", \"0.002\"], [\"70415.70\", \"0.002\"], [\"70417.20\", \"0.045\"], [\"70421.00\", \"0.000\"], [\"70428.30\", \"0.136\"], [\"70428.50\", \"0.002\"], [\"70428.80\", \"0.051\"], [\"70435.80\", \"0.018\"], [\"70435.90\", \"0.002\"], [\"70492.20\", \"2.000\"], [\"70524.00\", \"0.035\"], [\"70531.00\", \"0.197\"], [\"70531.30\", \"0.004\"], [\"70538.00\", \"0.007\"], [\"70538.30\", \"0.000\"], [\"70545.00\", \"13.640\"], [\"70545.30\", \"0.000\"], [\"70552.00\", \"0.012\"], [\"70552.30\", \"0.075\"], [\"70555.00\", \"0.072\"], [\"70559.00\", \"0.132\"], [\"70559.30\", \"2.754\"], [\"70566.00\", \"0.131\"], [\"70566.30\", \"0.205\"], [\"70573.00\", \"0.014\"], [\"70573.30\", \"0.000\"], [\"70580.30\", \"0.000\"], [\"70632.60\", \"0.006\"], [\"70639.80\", \"0.042\"], [\"70645.00\", \"0.000\"], [\"70841.50\", \"0.002\"], [\"71070.90\", \"1.454\"], [\"71352.30\", \"0.044\"]]}", "symbol": "BTCUSDT"}
{"event": "depthUpdate", "raw_payload": "{\"e\": \"depthUpdate\", \"E\": 1773246391686, \"T\": 1773246391685, \"s\": \"BTCUSDT\", \"U\": 10089704438363, \"u\": 10089704443921, \"pu\": 10089704438037, \"b\": [[\"1000.00\", \"26.792\"], [\"5000.00\", \"101.418\"], [\"19867.10\", \"1.610\"], [\"19967.10\", \"0.520\"], [\"20067.10\", \"0.590\"], [\"20267.10\", \"0.280\"], [\"33000.00\", \"10.793\"], [\"66838.10\", \"0.002\"], [\"66848.70\", \"0.009\"], [\"69663.40\", \"0.000\"], [\"70015.30\", \"0.044\"], [\"70119.50\", \"0.218\"], [\"70242.20\", \"0.086\"], [\"70293.50\", \"0.141\"], [\"70298.50\", \"0.003\"], [\"70325.00\", \"0.208\"], [\"70325.10\", \"0.114\"], [\"70326.60\", \"0.003\"]], \"a\": [[\"70369.70\", \"0.003\"], [\"70373.40\", \"0.009\"], [\"70401.80\", \"0.000\"], [\"70401.90\", \"1.073\"], [\"70402.30\", \"0.005\"], [\"70402.50\", \"0.019\"], [\"70402.60\", \"0.156\"], [\"70403.20\", \"0.000\"], [\"70403.30\", \"0.155\"], [\"70403.90\", \"0.002\"], [\"70404.00\", \"0.388\"], [\"70407.70\", \"0.008\"], [\"70408.80\", \"0.003\"], [\"70408.90\", \"0.002\"], [\"70409.50\", \"0.965\"], [\"70409.60\", \"0.004\"], [\"70410.30\", \"0.000\"], [\"70435.90\", \"0.005\"], [\"70492.20\", \"2.003\"], [\"70507.80\", \"0.228\"], [\"70536.50\", \"0.000\"], [\"70588.30\", \"0.022\"], [\"70589.40\", \"0.008\"], [\"70670.70\", \"0.002\"], [\"71070.90\", \"1.454\"], [\"71317.20\", \"1.677\"], [\"71453.10\", \"0.348\"], [\"89523.20\", \"0.000\"]]}", "symbol": "BTCUSDT"}
{"event": "depthUpdate", "raw_payload": "{\"e\": \"depthUpdate\", \"E\": 1773246391788, \"T\": 1773246391785, \"s\": \"BTCUSDT\", \"U\": 10089704444092, \"u\": 10089704449540, \"pu\": 10089704443921, \"b\": [[\"1000.00\", \"26.792\"], [\"5000.00\", \"101.418\"], [\"19867.10\", \"1.620\"], [\"19967.10\", \"0.510\"], [\"20067.10\", \"0.510\"], [\"20267.10\", \"0.360\"], [\"66817.60\", \"0.002\"], [\"66826.30\", \"0.007\"], [\"69663.40\", \"0.000\"], [\"69884.90\", \"3.720\"], [\"70133.00\", \"4.815\"], [\"70314.30\", \"0.709\"], [\"70316.70\", \"0.107\"], [\"70316.80\", \"0.008\"], [\"70325.00\", \"0.293\"], [\"70325.10\", \"0.029\"], [\"70339.40\", \"0.008\"], [\"70339.50\", \"0.002\"], [\"70340.10\", \"0.515\"], [\"70340.20\", \"0.002\"], [\"70356.50\", \"0.661\"], [\"70356.90\", \"0.011\"], [\"70358.30\", \"0.017\"], [\"70360.70\", \"0.204\"], [\"70367.10\", \"3.092\"]], \"a\": [[\"70367.20\", \"36.880\"], [\"70368.20\", \"0.000\"], [\"70368.30\", \"0.027\"], [\"70373.20\", \"0.010\"], [\"70374.20\", \"0.034\"], [\"70378.00\", \"0.005\"], [\"70379.40\", \"1.069\"], [\"70384.60\", \"0.000\"], [\"70385.60\", \"0.142\"], [\"70387.70\", \"0.559\"], [\"70389.70\", \"0.005\"], [\"70396.20\", \"0.005\"], [\"70403.80\", \"0.080\"], [\"70405.30\", \"0.084\"], [\"70410.20\", \"0.073\"], [\"70849.30\", \"3.720\"], [\"70877.20\", \"0.000\"], [\"71070.90\", \"1.454\"], [\"73901.60\", \"0.000\"], [\"74000.00\", \"186.225\"], [\"74184.00\", \"0.056\"]]}", "symbol": "BTCUSDT"}
