{"event": "depthUpdate", "raw_payload": "{\"e\": \"depthUpdate\", \"E\": 1773246391890, \"T\": 1773246391888, \"s\": \"BTCUSDT\", \"U\": 10089704449624, \"u\": 10089704455889, \"pu\": 10089704449540, \"b\": [[\"5000.00\", \"101.418\"], [\"19867.10\", \"1.490\"], [\"19967.10\", \"0.580\"], [\"20067.10\", \"0.420\"], [\"20267.10\", \"0.510\"], [\"63330.40\", \"0.016\"], [\"66826.30\", \"0.000\"], [\"66826.70\", \"0.005\"], [\"67552.40\", \"0.633\"], [\"69663.40\", \"0.000\"], [\"69776.00\", \"0.045\"], [\"69884.90\", \"0.000\"], [\"69885.60\", \"3.805\"], [\"70015.30\", \"0.044\"], [\"70015.40\", \"0.007\"], [\"70156.20\", \"0.002\"], [\"70174.40\", \"3.226\"], [\"70263.50\", \"0.081\"], [\"70290.50\", \"1.587\"], [\"70294.00\", \"0.789\"], [\"70294.50\", \"0.280\"], [\"70305.40\", \"0.987\"], [\"70316.80\", \"0.006\"], [\"70317.00\", \"0.010\"], [\"70319.90\", \"0.000\"], [\"70324.90\", \"2.229\"], [\"70325.00\", \"0.293\"], [\"70338.90\", \"0.108\"], [\"70340.10\", \"0.004\"], [\"70343.70\", \"0.526\"], [\"70349.50\", \"1.070\"], [\"70352.90\", \"0.066\"], [\"70353.00\", \"1.250\"], [\"70356.60\", \"0.404\"], [\"70357.20\", \"0.460\"], [\"70358.40\", \"0.000\"], [\"70360.80\", \"0.401\"], [\"70363.50\", \"0.202\"], [\"70367.10\", \"3.088\"]], \"a\": [[\"70368.20\", \"0.002\"], [\"70368.30\", \"0.025\"], [\"70369.70\", \"0.003\"], [\"70376.80\", \"0.085\"], [\"70377.20\", \"0.004\"], [\"70380.40\", \"0.000\"], [\"70395.30\", \"0.376\"], [\"70397.90\", \"0.004\"], [\"70403.80\", \"0.000\"], [\"70524.20\", \"0.123\"], [\"70531.70\", \"0.042\"], [\"70537.20\", \"0.123\"], [\"70638.20\", \"0.236\"], [\"70848.60\", \"3.720\"], [\"70849.30\", \"0.000\"], [\"71070.90\", \"1.454\"], [\"71428.70\", \"1.705\"], [\"71457.90\", \"0.362\"], [\"71563.40\", \"0.279\"], [\"73892.70\", \"0.000\"], [\"77403.90\", \"0.002\"], [\"89523.20\", \"0.000\"]]}", "symbol": "BTCUSDT"}
{"event": "depthUpdate", "raw_payload": "{\"e\": \"depthUpdate\", \"E\": 1773246391992, \"T\": 1773246391991, \"s\": \"BTCUSDT\", \"U\": 10089704456067, \"u\": 10089704461952, \"pu\": 10089704455889, \"b\": [[\"1000.00\", \"26.792\"], [\"5000.00\", \"101.398\"], [\"19867.10\", \"1.320\"], [\"19967.10\", \"0.660\"], [\"20067.10\", \"0.340\"], [\"20267.10\", \"0.680\"], [\"63330.40\", \"0.014\"], [\"66835.80\", \"0.000\"], [\"67552.50\", \"0.014\"], [\"69100.50\", \"0.643\"], [\"69663.40\", \"0.000\"], [\"70015.40\", \"0.000\"], [\"70133.00\", \"4.822\"], [\"70172.20\", \"0.007\"], [\"70293.60\", \"0.052\"], [\"70294.40\", \"0.076\"], [\"70296.10\", \"0.281\"], [\"70303.00\", \"1.107\"], [\"70307.80\", \"1.454\"], [\"70316.70\", \"0.109\"], [\"70317.00\", \"0.008\"], [\"70324.90\", \"2.229\"], [\"70325.00\", \"0.293\"], [\"70325.40\", \"0.914\"], [\"70349.30\", \"0.002\"], [\"70349.60\", \"1.125\"], [\"70355.50\", \"0.001\"], [\"70356.60\", \"0.006\"], [\"70357.30\", \"0.142\"]], \"a\": [[\"70368.20\", \"0.000\"], [\"70368.30\", \"0.002\"], [\"70396.60\", \"0.179\"], [\"70398.90\", \"0.010\"], [\"70630.80\", \"0.285\"], [\"71070.90\", \"1.454\"], [\"71347.40\", \"0.003\"], [\"71387.50\", \"0.842\"], [\"73894.70\", \"0.005\"], [\"73916.30\", \"0.000\"], [\"77403.90\", \"0.000\"]]}", "symbol": "BTCUSDT"}
{"event": "depthUpdate", "raw_payload": "{\"e\": \"depthUpdate\", \"E\": 1773246392094, \"T\": 1773246392093, \"s\": \"BTCUSDT\", \"U\": 10089704462031, \"u\": 10089704468241, \"pu\": 10089704461952, \"b\": [[\"1000.00\", \"26.792\"], [\"5000.00\", \"101.398\"], [\"19867.10\", \"1.150\"], [\"19967.10\", \"0.750\"], [\"20067.10\", \"0.250\"], [\"20267.10\", \"0.850\"], [\"56294.00\", \"0.000\"], [\"66838.10\", \"0.000\"], [\"68540.60\", \"0.002\"], [\"69389.00\", \"0.969\"], [\"69663.40\", \"0.002\"], [\"69885.60\", \"0.085\"], [\"70015.20\", \"0.000\"], [\"70064.50\", \"0.022\"], [\"70108.40\", \"0.000\"], [\"70162.40\", \"0.000\"], [\"70203.20\", \"0.121\"], [\"70231.10\", \"0.002\"], [\"70279.20\", \"0.071\"], [\"70279.40\", \"0.083\"], [\"70286.30\", \"0.126\"], [\"70286.40\", \"0.078\"], [\"70286.50\", \"0.002\"], [\"70289.70\", \"0.263\"], [\"70293.20\", \"0.091\"], [\"70293.30\", \"1.699\"], [\"70293.50\", \"0.070\"], [\"70293.60\", \"0.095\"], [\"70294.70\", \"0.133\"], [\"70305.40\", \"0.989\"], [\"70316.70\", \"0.107\"], [\"70316.80\", \"0.008\"], [\"70322.00\", \"0.004\"], [\"70329.00\", \"0.032\"], [\"70333.90\", \"0.003\"], [\"70336.00\", \"0.090\"], [\"70339.40\", \"0.010\"], [\"70339.50\", \"0.004\"], [\"70340.10\", \"0.002\"], [\"70340.20\", \"0.000\"], [\"70343.00\", \"0.577\"], [\"70343.60\", \"0.003\"], [\"70346.40\", \"0.071\"], [\"70349.90\", \"0.000\"], [\"70350.00\", \"0.008\"], [\"70350.20\", \"0.177\"], [\"70351.90\", \"0.015\"], [\"70352.20\", \"0.007\"], [\"70353.10\", \"0.009\"], [\"70356.50\", \"0.664\"], [\"70360.10\", \"0.099\"], [\"70365.90\", \"0.004\"], [\"70367.10\", \"3.090\"]], \"a\": [[\"70369.80\", \"0.012\"], [\"70379.90\", \"0.002\"], [\"70385.60\", \"0.000\"], [\"70386.40\", \"0.142\"], [\"70387.30\", \"0.070\"], [\"70387.80\", \"0.002\"], [\"70388.10\", \"0.000\"], [\"70389.60\", \"0.011\"], [\"70389.90\", \"0.007\"], [\"70390.00\", \"0.042\"], [\"70392.00\", \"0.392\"], [\"70398.90\", \"0.112\"], [\"70399.00\", \"0.002\"], [\"70401.80\", \"0.009\"], [\"70401.90\", \"1.082\"], [\"70402.50\", \"0.010\"], [\"70402.60\", \"0.147\"], [\"70405.30\", \"0.004\"], [\"70406.00\", \"1.080\"], [\"70408.80\", \"0.005\"], [\"70408.90\", \"0.004\"], [\"70409.50\", \"0.963\"], [\"70409.60\", \"0.002\"], [\"70413.00\", \"1.074\"], [\"70420.00\", \"1.262\"], [\"70423.50\", \"0.086\"], [\"70425.50\", \"0.000\"], [\"70455.30\", \"0.138\"], [\"70455.60\", \"0.000\"], [\"70462.30\", \"0.071\"], [\"70462.60\", \"0.002\"], [\"70469.40\", \"0.071\"], [\"70469.70\", \"0.085\"], [\"70509.10\", \"0.002\"], [\"70848.00\", \"3.722\"], [\"70848.60\", \"0.000\"], [\"70880.70\", \"0.004\"], [\"71050.00\", \"3.907\"], [\"71070.90\", \"1.454\"], [\"71107.50\", \"0.000\"], [\"71320.80\", \"0.000\"], [\"71425.80\", \"0.699\"], [\"89523.20\", \"0.000\"]]}", "symbol": "BTCUSDT"}
{"event": "depthUpdate", "raw_payload": "{\"e\": \"depthUpdate\", \"E\": 1773246392196, \"T\": 1773246392193, \"s\": \"BTCUSDT\", \"U\": 10089704468284, \"u\": 10089704476040, \"pu\": 10089704468241, \"b\": [[\"5000.00\", \"101.418\"], [\"19867.10\", \"0.980\"], [\"19967.10\", \"0.830\"], [\"20067.10\", \"0.170\"], [\"20267.10\", \"1.020\"], [\"66801.70\", \"0.000\"], [\"66841.90\", \"0.002\"], [\"66844.80\", \"0.000\"], [\"69051.20\", \"0.363\"], [\"69663.40\", \"0.000\"], [\"69888.40\", \"3.720\"], [\"70015.30\", \"0.044\"], [\"70172.70\", \"0.059\"], [\"70173.70\", \"0.550\"], [\"70179.80\", \"10.000\"], [\"70180.80\", \"0.713\"], [\"70180.90\", \"0.003\"], [\"70193.80\", \"0.002\"], [\"70194.80\", \"0.284\"], [\"70212.50\", \"0.084\"], [\"70242.20\", \"0.086\"], [\"70298.50\", \"0.003\"], [\"70310.80\", \"0.223\"], [\"70314.30\", \"0.927\"], [\"70316.70\", \"0.109\"], [\"70316.80\", \"0.006\"], [\"70326.60\", \"0.003\"], [\"70353.10\", \"0.007\"], [\"70356.20\", \"0.004\"], [\"70356.50\", \"0.661\"], [\"70357.90\", \"0.050\"], [\"70358.00\", \"0.000\"], [\"70358.80\", \"0.052\"], [\"70360.10\", \"0.097\"], [\"70366.00\", \"0.003\"], [\"70367.10\", \"3.130\"]], \"a\": [[\"70367.20\", \"36.875\"], [\"70368.20\", \"0.002\"], [\"70368.30\", \"0.025\"], [\"70374.10\", \"0.002\"], [\"70374.20\", \"0.031\"], [\"70376.80\", \"0.082\"], [\"70407.70\", \"0.008\"], [\"70435.90\", \"0.005\"], [\"70492.20\", \"2.003\"], [\"70519.00\", \"0.002\"], [\"70602.20\", \"2.960\"], [\"70628.80\", \"0.200\"], [\"70629.80\", \"0.000\"], [\"70632.60\", \"0.000\"], [\"70635.90\", \"0.200\"], [\"70636.90\", \"0.028\"], [\"70746.10\", \"0.331\"], [\"70747.70\", \"0.000\"], [\"70749.40\", \"0.000\"], [\"70845.80\", \"3.906\"], [\"70848.00\", \"0.002\"], [\"70938.60\", \"0.550\"], [\"70939.60\", \"0.000\"], [\"71070.80\", \"0.000\"], [\"71070.90\", \"1.454\"], [\"71093.40\", \"0.014\"], [\"71306.00\", \"0.009\"], [\"71518.70\", \"0.004\"], [\"71631.20\", \"0.000\"], [\"71731.30\", \"0.004\"], [\"73866.20\", \"0.000\"]]}", "symbol": "BTCUSDT"}
{"event": "depthUpdate", "raw_payload": "{\"e\": \"depthUpdate\", \"E\": 1773246392298, \"T\": 1773246392296, \"s\": \"BTCUSDT\", \"U\": 10089704476262, \"u\": 10089704481803, \"pu\": 10089704476040, \"b\": [[\"1000.00\", \"26.792\"], [\"5000.00\", \"101.418\"], [\"19867.10\", \"0.810\"], [\"19967.10\", \"0.920\"], [\"20067.10\", \"0.080\"], [\"20267.10\", \"1.190\"], [\"33000.00\", \"10.797\"], [\"56294.00\", \"0.000\"], [\"66834.30\", \"0.043\"], [\"66841.90\", \"0.000\"], [\"68197.50\", \"0.628\"], [\"68958.10\", \"0.002\"], [\"68959.70\", \"0.016\"], [\"69663.40\", \"0.000\"], [\"69911.10\", \"0.011\"], [\"70251.80\", \"0.000\"], [\"70270.40\", \"0.004\"], [\"70296.70\", \"1.006\"], [\"70338.90\", \"0.002\"], [\"70353.00\", \"1.356\"], [\"70367.10\", \"3.128\"]], \"a\": [[\"70368.30\", \"0.000\"], [\"70369.80\", \"0.012\"], [\"70371.60\", \"0.006\"], [\"70377.80\", \"0.003\"], [\"70439.60\", \"0.196\"], [\"71070.90\", \"1.454\"], [\"71707.00\", \"0.017\"], [\"89523.20\", \"0.000\"]]}", "symbol": "BTCUSDT"}
{"event": "depthUpdate", "raw_payload": "{\"e\": \"depthUpdate\", \"E\": 1773246392400, \"T\": 1773246392399, \"s\": \"BTCUSDT\", \"U\": 10089704481884, \"u\": 10089704488687, \"pu\": 10089704481803, \"b\": [[\"1000.00\", \"26.792\"], [\"5000.00\", \"101.398\"], [\"19867.10\", \"0.640\"], [\"19967.10\", \"1.000\"], [\"20067.10\", \"0.000\"], [\"20267.10\", \"1.360\"], [\"33000.00\", \"10.793\"], [\"66822.60\", \"0.007\"], [\"66829.10\", \"0.002\"], [\"69022.90\", \"0.729\"], [\"69663.40\", \"0.000\"], [\"69888.40\", \"0.000\"], [\"69889.10\", \"3.720\"], [\"70143.50\", \"0.000\"], [\"70172.70\", \"0.016\"], [\"70173.10\", \"0.000\"], [\"70173.40\", \"0.189\"], [\"70245.30\", \"0.000\"], [\"70324.90\", \"2.314\"], [\"70325.00\", \"0.208\"], [\"70347.00\", \"0.000\"], [\"70348.70\", \"0.071\"], [\"70351.00\", \"0.116\"], [\"70355.90\", \"0.081\"], [\"70361.40\", \"0.003\"], [\"70361.60\", \"0.400\"], [\"70366.10\", \"0.002\"], [\"70367.10\", \"3.234\"]], \"a\": [[\"70368.20\", \"0.000\"], [\"70368.30\", \"0.002\"], [\"70370.50\", \"0.023\"], [\"70371.50\", \"0.002\"], [\"70376.70\", \"0.192\"], [\"70404.80\", \"0.206\"], [\"70410.10\", \"0.073\"], [\"70410.20\", \"0.000\"], [\"70491.30\", \"0.000\"], [\"70760.90\", \"0.007\"], [\"70845.10\", \"3.720\"], [\"70845.80\", \"0.186\"], [\"71070.90\", \"1.454\"], [\"71500.70\", \"0.004\"]]}", "symbol": "BTCUSDT"}
{"event": "depthUpdate", "raw_payload": "{\"e\": \"depthUpdate\", \"E\": 1773246392502, \"T\": 1773246392501, \"s\": \"BTCUSDT\", \"U\": 10089704488786, \"u\": 10089704495497, \"pu\": 10089704488687, \"b\": [[\"5000.00\", \"101.418\"], [\"19867.10\", \"0.560\"], [\"19967.10\", \"0.910\"], [\"20267.10\", \"1.530\"], [\"66848.00\", \"0.004\"], [\"69126.10\", \"0.607\"], [\"69425.70\", \"0.000\"], [\"69634.60\", \"0.000\"], [\"69663.40\", \"0.000\"], [\"69795.10\", \"0.000\"], [\"69921.00\", \"0.004\"], [\"70015.30\", \"0.044\"], [\"70324.90\", \"2.229\"], [\"70325.10\", \"0.029\"], [\"70325.20\", \"0.191\"], [\"70325.50\", \"0.253\"], [\"70329.30\", \"0.000\"], [\"70333.30\", \"0.252\"], [\"70340.60\", \"0.080\"], [\"70342.40\", \"0.000\"], [\"70342.60\", \"0.379\"], [\"70345.90\", \"0.073\"], [\"70346.00\", \"0.856\"], [\"70355.90\", \"0.001\"], [\"70361.50\", \"0.003\"], [\"70361.70\", \"0.252\"]], \"a\": [[\"70369.80\", \"0.012\"], [\"70371.90\", \"0.024\"], [\"70398.00\", \"0.002\"], [\"70399.30\", \"1.078\"], [\"70428.30\", \"0.008\"], [\"70428.40\", \"0.332\"], [\"70636.00\", \"0.000\"], [\"70653.40\", \"0.008\"], [\"70816.50\", \"0.000\"], [\"70944.00\", \"0.012\"], [\"71070.90\", \"2.859\"], [\"73897.00\", \"0.162\"], [\"75256.80\", \"0.014\"], [\"89523.20\", \"0.000\"]]}", "symbol": "BTCUSDT"}
{"event": "depthUpdate", "raw_payload": "{\"e\": \"depthUpdate\", \"E\": 1773246392606, \"T\": 1773246392604, \"s\": \"BTCUSDT\", \"U\": 10089704495674, \"u\": 10089704500748, \"pu\": 10089704495497, \"b\": [[\"1000.00\", \"26.792\"], [\"5000.00\", \"101.398\"], [\"19867.10\", \"0.510\"], [\"19967.10\", \"0.830\"], [\"20167.10\", \"0.050\"], [\"20267.10\", \"1.610\"], [\"66845.30\", \"0.002\"], [\"68980.90\", \"1.228\"], [\"69135.70\", \"2.313\"], [\"69911.20\", \"0.009\"], [\"70133.00\", \"4.815\"], [\"70249.10\", \"0.011\"], [\"70297.10\", \"0.000\"], [\"70316.60\", \"0.007\"], [\"70316.70\", \"0.107\"], [\"70337.60\", \"0.037\"], [\"70340.60\", \"0.000\"], [\"70353.80\", \"0.082\"], [\"70366.50\", \"0.002\"]], \"a\": [[\"70386.40\", \"0.000\"], [\"70386.80\", \"0.047\"], [\"70387.20\", \"0.144\"], [\"70486.90\", \"0.035\"], [\"70487.40\", \"0.016\"], [\"70491.80\", \"0.383\"], [\"70524.00\", \"0.028\"], [\"70531.00\", \"0.190\"], [\"70538.00\", \"0.000\"], [\"70545.00\", \"13.633\"], [\"70548.70\", \"0.009\"], [\"70552.00\", \"0.005\"], [\"70555.70\", \"0.018\"], [\"70559.00\", \"0.125\"], [\"70562.70\", \"0.212\"], [\"70566.00\", \"0.124\"], [\"70569.70\", \"6.514\"], [\"70573.00\", \"0.007\"], [\"70576.70\", \"0.007\"], [\"70583.70\", \"0.007\"], [\"70590.70\", \"0.007\"], [\"70597.70\", \"0.007\"], [\"70602.20\", \"2.954\"], [\"70845.00\", \"0.006\"], [\"71070.90\", \"2.859\"], [\"71401.60\", \"2.586\"]]}", "symbol": "BTCUSDT"}
{"event": "depthUpdate", "raw_payload": "{\"e\": \"depthUpdate\", \"E\": 1773246392710, \"T\": 1773246392708, \"s\": \"BTCUSDT\", \"U\": 10089704500887, \"u\": 10089704505611, \"pu\": 10089704500748, \"b\": [[\"1000.00\", \"26.792\"], [\"5000.00\", \"101.418\"], [\"19867.10\", \"0.510\"], [\"19967.10\", \"0.740\"], [\"20167.10\", \"0.130\"], [\"20267.10\", \"1.620\"], [\"40000.00\", \"50.522\"], [\"66848.50\", \"0.027\"], [\"66848.70\", \"0.007\"], [\"68407.60\", \"0.007\"], [\"69126.20\", \"1.156\"], [\"69134.10\", \"0.007\"], [\"69514.50\", \"0.570\"], [\"69522.20\", \"0.000\"], [\"69533.10\", \"3.240\"], [\"69663.40\", \"0.000\"], [\"69795.20\", \"0.000\"], [\"69800.10\", \"0.771\"], [\"69911.20\", \"0.002\"], [\"69921.10\", \"0.000\"], [\"70133.20\", \"0.000\"], [\"70325.40\", \"0.999\"], [\"70325.50\", \"0.168\"], [\"70331.70\", \"0.250\"], [\"70333.30\", \"0.004\"], [\"70339.10\", \"0.018\"], [\"70348.70\", \"0.071\"], [\"70348.90\", \"0.214\"], [\"70351.30\", \"0.010\"], [\"70351.50\", \"0.002\"], [\"70352.90\", \"0.066\"], [\"70353.00\", \"0.896\"], [\"70353.10\", \"0.007\"], [\"70353.80\", \"0.082\"], [\"70354.40\", \"0.016\"], [\"70354.50\", \"0.058\"], [\"70354.60\", \"0.135\"], [\"70355.00\", \"0.280\"], [\"70355.40\", \"0.003\"], [\"70356.60\", \"0.006\"], [\"70356.70\", \"0.000\"], [\"70356.80\", \"0.000\"], [\"70358.70\", \"0.006\"], [\"70358.80\", \"0.005\"], [\"70360.00\", \"0.007\"], [\"70360.10\", \"0.000\"], [\"70366.90\", \"0.004\"]], \"a\": [[\"70369.80\", \"0.012\"], [\"70374.80\", \"0.002\"], [\"70383.80\", \"0.028\"], [\"70384.80\", \"0.032\"], [\"70393.70\", \"0.000\"], [\"70457.40\", \"0.089\"], [\"70507.80\", \"0.226\"], [\"70602.10\", \"0.761\"], [\"70845.00\", \"0.000\"], [\"71070.90\", \"2.859\"], [\"71331.20\", \"0.662\"], [\"71675.80\", \"0.000\"], [\"73890.90\", \"0.000\"], [\"89523.20\", \"0.000\"]]}", "symbol": "BTCUSDT"}
{"event": "depthUpdate", "raw_payload": "{\"e\": \"depthUpdate\", \"E\": 1773246392814, \"T\": 1773246392812, \"s\": \"BTCUSDT\", \"U\": 10089704505719, \"u\": 10089704513546, \"pu\": 10089704505611, \"b\": [[\"5000.00\", \"101.418\"], [\"19867.10\", \"0.520\"], [\"19967.10\", \"0.650\"], [\"20167.10\", \"0.220\"], [\"20267.10\", \"1.610\"], [\"40000.00\", \"50.271\"], [\"66822.60\", \"0.005\"], [\"69367.70\", \"0.000\"], [\"69374.80\", \"0.720\"], [\"69663.40\", \"0.000\"], [\"70015.30\", \"0.044\"], [\"70026.00\", \"32.258\"], [\"70026.30\", \"5.028\"], [\"70103.10\", \"26.251\"], [\"70316.10\", \"0.145\"], [\"70316.60\", \"0.005\"], [\"70325.40\", \"0.914\"], [\"70325.50\", \"0.253\"], [\"70348.70\", \"0.555\"], [\"70351.30\", \"0.038\"], [\"70351.50\", \"0.030\"], [\"70352.90\", \"0.097\"], [\"70353.10\", \"0.467\"], [\"70354.40\", \"0.037\"], [\"70354.50\", \"0.116\"], [\"70354.60\", \"0.192\"], [\"70355.00\", \"0.385\"], [\"70355.40\", \"0.046\"], [\"70356.60\", \"0.034\"], [\"70356.70\", \"0.090\"], [\"70358.70\", \"0.053\"], [\"70360.00\", \"0.104\"]], \"a\": [[\"70376.80\", \"0.011\"], [\"70379.10\", \"0.074\"], [\"70381.80\", \"0.000\"], [\"70382.20\", \"0.000\"], [\"70383.80\", \"0.000\"], [\"70384.80\", \"0.004\"], [\"70386.50\", \"0.000\"], [\"70391.00\", \"0.299\"], [\"70552.10\", \"1.186\"], [\"70602.10\", \"0.755\"], [\"70632.90\", \"26.130\"], [\"70710.50\", \"4.733\"], [\"70710.60\", \"30.944\"], [\"70710.70\", \"0.000\"], [\"71070.80\", \"0.006\"], [\"71070.90\", \"2.859\"], [\"73181.80\", \"0.012\"]]}", "symbol": "BTCUSDT"}
{"event": "depthUpdate", "raw_payload": "{\"e\": \"depthUpdate\", \"E\": 1773246392916, \"T\": 1773246392912, \"s\": \"BTCUSDT\", \"U\": 10089704513830, \"u\": 10089704520586, \"pu\": 10089704513546, \"b\": [[\"1000.00\", \"26.792\"], [\"5000.00\", \"101.418\"], [\"19867.10\", \"0.510\"], [\"19967.10\", \"0.570\"], [\"20167.10\", \"0.300\"], [\"20267.10\", \"1.620\"], [\"40000.00\", \"50.522\"], [\"63330.40\", \"0.016\"], [\"65051.80\", \"0.014\"], [\"66848.50\", \"0.025\"], [\"69663.40\", \"0.000\"], [\"69889.10\", \"0.000\"], [\"69889.90\", \"4.022\"], [\"70133.10\", \"0.007\"], [\"70298.80\", \"0.002\"], [\"70299.90\", \"0.049\"], [\"70314.30\", \"0.978\"], [\"70316.10\", \"0.143\"], [\"70316.40\", \"0.003\"], [\"70329.50\", \"0.002\"], [\"70339.10\", \"0.018\"], [\"70341.60\", \"0.030\"], [\"70344.20\", \"0.072\"], [\"70344.50\", \"0.710\"], [\"70345.90\", \"0.002\"], [\"70346.00\", \"0.217\"], [\"70346.40\", \"0.000\"], [\"70348.70\", \"0.151\"], [\"70351.30\", \"0.010\"], [\"70351.50\", \"0.002\"], [\"70351.90\", \"0.008\"], [\"70352.90\", \"0.066\"], [\"70353.10\", \"0.007\"], [\"70353.20\", \"0.007\"], [\"70353.80\", \"0.002\"], [\"70354.30\", \"0.360\"], [\"70354.40\", \"0.016\"], [\"70354.50\", \"0.058\"], [\"70354.60\", \"0.135\"], [\"70355.00\", \"0.280\"], [\"70355.40\", \"0.003\"], [\"70356.50\", \"0.664\"], [\"70356.60\", \"0.006\"], [\"70356.70\", \"0.000\"], [\"70356.90\", \"0.001\"], [\"70357.20\", \"0.001\"], [\"70358.30\", \"0.007\"], [\"70358.70\", \"0.006\"], [\"70358.80\", \"0.002\"], [\"70359.60\", \"0.008\"], [\"70360.00\", \"0.007\"], [\"70360.20\", \"0.006\"], [\"70360.80\", \"0.003\"], [\"70361.60\", \"0.002\"], [\"70361.70\", \"0.035\"], [\"70362.60\", \"0.016\"], [\"70367.10\", \"3.088\"]], \"a\": [[\"70367.20\", \"37.118\"], [\"70367.80\", \"0.043\"], [\"70367.90\", \"0.065\"], [\"70368.30\", \"0.000\"], [\"70369.70\", \"0.003\"], [\"70374.00\", \"0.003\"], [\"70374.30\", \"0.000\"], [\"70377.40\", \"0.016\"], [\"70377.80\", \"0.000\"], [\"70378.70\", \"0.000\"], [\"70379.10\", \"0.003\"], [\"70381.20\", \"0.005\"], [\"70381.30\", \"0.003\"], [\"70381.60\", \"0.472\"], [\"70382.90\", \"0.040\"], [\"70383.80\", \"0.028\"], [\"70384.80\", \"0.032\"], [\"70387.30\", \"0.050\"], [\"70388.60\", \"0.023\"], [\"70390.00\", \"0.002\"], [\"70391.40\", \"0.081\"], [\"70394.40\", \"0.002\"], [\"70398.90\", \"0.010\"], [\"70409.70\", \"0.013\"], [\"70443.60\", \"0.000\"], [\"70602.10\", \"0.761\"], [\"70622.90\", \"0.002\"], [\"70638.20\", \"0.234\"], [\"70844.30\", \"3.745\"], [\"70845.10\", \"0.000\"], [\"71070.80\", \"0.000\"], [\"71070.90\", \"2.859\"], [\"71296.40\", \"0.005\"], [\"71490.40\", \"0.699\"], [\"77403.90\", \"0.002\"], [\"89523.20\", \"0.000\"]]}", "symbol": "BTCUSDT"}
{"event": "depthUpdate", "raw_payload": "{\"e\": \"depthUpdate\", \"E\": 1773246393018, \"T\": 1773246393016, \"s\": \"BTCUSDT\", \"U\": 10089704520714, \"u\": 10089704525427, \"pu\": 10089704520586, \"b\": [[\"1000.00\", \"26.792\"], [\"5000.00\", \"101.418\"], [\"19867.10\", \"0.520\"], [\"19967.10\", \"0.480\"], [\"20167.10\", \"0.390\"], [\"20267.10\", \"1.610\"], [\"33000.00\", \"10.797\"], [\"56294.00\", \"0.000\"], [\"63330.40\", \"0.014\"], [\"69337.20\", \"0.880\"], [\"69346.80\", \"4.449\"], [\"69663.40\", \"0.000\"], [\"69800.10\", \"0.123\"], [\"70026.10\", \"1.909\"], [\"70104.80\", \"3.985\"], [\"70256.90\", \"0.000\"], [\"70296.10\", \"0.279\"], [\"70296.80\", \"0.469\"], [\"70297.40\", \"0.000\"], [\"70298.30\", \"0.011\"], [\"70325.40\", \"0.999\"], [\"70325.50\", \"0.168\"], [\"70342.20\", \"0.513\"], [\"70343.70\", \"0.015\"], [\"70346.20\", \"0.276\"], [\"70349.50\", \"1.072\"], [\"70349.60\", \"1.127\"], [\"70349.90\", \"0.002\"], [\"70351.50\", \"1.209\"], [\"70351.90\", \"0.006\"], [\"70352.00\", \"0.007\"], [\"70352.20\", \"0.005\"], [\"70352.30\", \"0.286\"], [\"70352.90\", \"0.064\"], [\"70353.20\", \"0.000\"], [\"70354.00\", \"0.000\"], [\"70354.30\", \"0.076\"], [\"70355.40\", \"0.145\"], [\"70356.40\", \"0.004\"], [\"70356.50\", \"0.664\"], [\"70356.60\", \"0.016\"], [\"70357.30\", \"0.000\"], [\"70357.50\", \"0.011\"], [\"70358.30\", \"0.017\"], [\"70359.60\", \"0.005\"], [\"70366.90\", \"0.002\"], [\"70367.10\", \"3.124\"]], \"a\": [[\"70367.20\", \"36.795\"], [\"70367.70\", \"0.002\"], [\"70367.80\", \"0.004\"], [\"70377.80\", \"0.003\"], [\"70381.80\", \"0.002\"], [\"70382.40\", \"0.081\"], [\"70384.70\", \"0.492\"], [\"70386.00\", \"0.000\"], [\"70387.20\", \"0.002\"], [\"70387.70\", \"0.561\"], [\"70388.00\", \"0.004\"], [\"70388.50\", \"0.015\"], [\"70389.60\", \"0.009\"], [\"70389.90\", \"0.005\"], [\"70391.40\", \"0.074\"], [\"70399.20\", \"0.855\"], [\"70399.40\", \"0.044\"], [\"70400.70\", \"0.002\"], [\"70410.10\", \"0.000\"], [\"70630.80\", \"4.157\"], [\"70710.50\", \"5.381\"], [\"70799.90\", \"22.014\"], [\"70887.80\", \"0.002\"], [\"71070.90\", \"2.859\"], [\"71279.60\", \"0.835\"], [\"71554.30\", \"0.000\"], [\"71660.90\", \"0.000\"], [\"73181.80\", \"0.014\"], [\"73889.80\", \"0.291\"], [\"73897.00\", \"0.160\"], [\"77403.90\", \"0.000\"]]}", "symbol": "BTCUSDT"}
{"event": "depthUpdate", "raw_payload": "{\"e\": \"depthUpdate\", \"E\": 1773246393122, \"T\": 1773246393120, \"s\": \"BTCUSDT\", \"U\": 10089704525590, \"u\": 10089704531832, \"pu\": 10089704525427, \"b\": [[\"5000.00\", \"101.418\"], [\"19867.10\", \"0.600\"], [\"19967.10\", \"0.400\"], [\"20167.10\", \"0.570\"], [\"20267.10\", \"1.430\"], [\"33000.00\", \"10.793\"], [\"56294.00\", \"0.000\"], [\"66835.00\", \"0.038\"], [\"66848.80\", \"0.000\"], [\"69663.40\", \"0.000\"], [\"69889.90\", \"0.302\"], [\"69890.70\", \"0.000\"], [\"70015.20\", \"0.000\"], [\"70015.30\", \"0.044\"], [\"70062.60\", \"0.002\"], [\"70064.50\", \"0.020\"], [\"70289.70\", \"0.481\"], [\"70303.00\", \"1.102\"], [\"70303.10\", \"0.005\"], [\"70310.80\", \"0.005\"], [\"70311.10\", \"0.056\"], [\"70311.20\", \"0.025\"], [\"70311.70\", \"0.175\"], [\"70316.10\", \"0.145\"], [\"70316.40\", \"0.001\"], [\"70319.20\", \"0.005\"], [\"70322.00\", \"0.004\"], [\"70325.40\", \"0.914\"], [\"70325.50\", \"0.168\"], [\"70325.60\", \"0.085\"], [\"70327.40\", \"0.006\"], [\"70329.00\", \"0.032\"], [\"70335.30\", \"0.006\"], [\"70335.40\", \"0.007\"], [\"70336.00\", \"0.090\"], [\"70343.00\", \"0.577\"], [\"70343.10\", \"0.079\"], [\"70344.50\", \"0.639\"], [\"70350.00\", \"0.008\"], [\"70353.20\", \"0.000\"], [\"70353.50\", \"0.612\"], [\"70356.50\", \"0.610\"], [\"70356.60\", \"0.006\"], [\"70357.50\", \"0.008\"], [\"70358.30\", \"0.007\"], [\"70359.80\", \"0.000\"], [\"70360.20\", \"0.006\"], [\"70360.50\", \"0.116\"], [\"70362.80\", \"0.015\"], [\"70365.70\", \"0.000\"], [\"70365.90\", \"0.002\"], [\"70366.00\", \"0.001\"], [\"70366.10\", \"0.000\"], [\"70366.50\", \"0.000\"], [\"70367.10\", \"3.122\"]], \"a\": [[\"70367.20\", \"37.117\"], [\"70369.80\", \"0.012\"], [\"70374.20\", \"0.003\"], [\"70377.80\", \"0.003\"], [\"70379.40\", \"1.071\"], [\"70379.90\", \"0.002\"], [\"70381.60\", \"0.578\"], [\"70392.00\", \"0.392\"], [\"70399.00\", \"0.002\"], [\"70406.00\", \"1.080\"], [\"70410.00\", \"0.086\"], [\"70413.00\", \"1.074\"], [\"70420.00\", \"1.262\"], [\"70423.50\", \"0.086\"], [\"70501.60\", \"0.011\"], [\"70508.80\", \"0.041\"], [\"70509.10\", \"0.000\"], [\"70742.60\", \"0.002\"], [\"70746.10\", \"0.329\"], [\"70843.50\", \"0.000\"], [\"70844.30\", \"0.025\"], [\"70880.80\", \"3.731\"], [\"71070.90\", \"2.859\"], [\"72018.40\", \"0.000\"], [\"73914.00\", \"0.100\"], [\"89523.20\", \"0.000\"]]}", "symbol": "BTCUSDT"}
{"event": "depthUpdate", "raw_payload": "{\"e\": \"depthUpdate\", \"E\": 1773246393224, \"T\": 1773246393220, \"s\": \"BTCUSDT\", \"U\": 10089704531982, \"u\": 10089704538737, \"pu\": 10089704531832, \"b\": [[\"1000.00\", \"26.792\"], [\"5000.00\", \"101.418\"], [\"19867.10\", \"0.690\"], [\"19967.10\", \"0.310\"], [\"20167.10\", \"0.730\"], [\"20267.10\", \"1.270\"], [\"67552.50\", \"0.016\"], [\"69225.10\", \"0.000\"], [\"69330.60\", \"18.570\"], [\"69346.80\", \"5.313\"], [\"69411.70\", \"0.000\"], [\"69663.40\", \"0.000\"], [\"69855.40\", \"0.000\"], [\"69858.40\", \"3.720\"], [\"69890.00\", \"0.205\"], [\"70104.90\", \"0.007\"], [\"70133.10\", \"0.000\"], [\"70242.20\", \"0.086\"], [\"70293.20\", \"0.309\"], [\"70298.50\", \"0.003\"], [\"70314.30\", \"0.760\"], [\"70316.00\", \"0.347\"], [\"70316.10\", \"0.143\"], [\"70326.60\", \"0.003\"], [\"70329.30\", \"0.248\"], [\"70330.70\", \"0.004\"], [\"70331.70\", \"0.002\"], [\"70338.90\", \"0.320\"], [\"70340.50\", \"0.572\"], [\"70340.60\", \"0.002\"], [\"70342.20\", \"0.002\"], [\"70342.40\", \"0.639\"], [\"70344.50\", \"0.000\"], [\"70346.20\", \"0.093\"], [\"70347.60\", \"0.080\"], [\"70348.70\", \"0.071\"], [\"70350.30\", \"0.011\"], [\"70351.80\", \"0.013\"], [\"70352.00\", \"0.000\"], [\"70353.00\", \"0.578\"], [\"70353.10\", \"0.000\"], [\"70356.50\", \"0.661\"], [\"70356.60\", \"0.671\"], [\"70357.70\", \"0.061\"], [\"70358.30\", \"0.007\"], [\"70360.60\", \"0.003\"], [\"70360.80\", \"0.132\"], [\"70361.90\", \"0.000\"], [\"70362.10\", \"0.006\"], [\"70363.50\", \"0.002\"], [\"70365.70\", \"0.002\"], [\"70367.10\", \"3.193\"]], \"a\": [[\"70367.20\", \"37.118\"], [\"70367.70\", \"0.004\"], [\"70367.80\", \"0.041\"], [\"70374.30\", \"0.003\"], [\"70377.70\", \"0.003\"], [\"70377.80\", \"0.000\"], [\"70378.40\", \"0.644\"], [\"70379.10\", \"0.000\"], [\"70379.80\", \"0.002\"], [\"70381.90\", \"0.000\"], [\"70386.60\", \"0.002\"], [\"70388.10\", \"0.511\"], [\"70389.70\", \"0.012\"], [\"70390.40\", \"0.001\"], [\"70390.60\", \"0.076\"], [\"70393.80\", \"0.188\"], [\"70394.20\", \"0.090\"], [\"70402.30\", \"0.069\"], [\"70407.70\", \"0.008\"], [\"70435.90\", \"0.005\"], [\"70492.20\", \"2.003\"], [\"70875.90\", \"3.720\"], [\"70878.80\", \"0.000\"], [\"70880.00\", \"3.420\"], [\"70880.80\", \"0.007\"], [\"71070.90\", \"2.859\"], [\"71093.50\", \"0.000\"], [\"71306.10\", \"0.047\"], [\"71352.30\", \"0.111\"], [\"71518.80\", \"0.002\"], [\"71731.40\", \"0.000\"], [\"73894.00\", \"0.002\"]]}", "symbol": "BTCUSDT"}
{"event": "depthUpdate", "raw_payload": "{\"e\": \"depthUpdate\", \"E\": 1773246393326, \"T\": 1773246393324, \"s\": \"BTCUSDT\", \"U\": 10089704538888, \"u\": 10089704543158, \"pu\": 10089704538737, \"b\": [[\"1000.00\", \"26.792\"], [\"5000.00\", \"101.418\"], [\"19867.10\", \"0.770\"], [\"19967.10\", \"0.230\"], [\"20167.10\", \"0.910\"], [\"20267.10\", \"1.090\"], [\"56294.00\", \"0.000\"], [\"66835.00\", \"0.036\"], [\"66837.60\", \"0.002\"], [\"68958.10\", \"0.004\"], [\"69365.40\", \"2.817\"], [\"70242.20\", \"0.086\"], [\"70247.90\", \"0.262\"], [\"70270.40\", \"0.002\"], [\"70279.00\", \"0.073\"], [\"70279.20\", \"0.000\"], [\"70286.10\", \"0.073\"], [\"70286.30\", \"0.055\"], [\"70293.10\", \"1.417\"], [\"70293.30\", \"1.628\"], [\"70298.50\", \"0.003\"], [\"70311.70\", \"0.075\"], [\"70316.00\", \"0.345\"], [\"70316.10\", \"0.145\"], [\"70326.60\", \"0.003\"], [\"70356.60\", \"0.016\"], [\"70357.80\", \"0.044\"], [\"70357.90\", \"0.008\"], [\"70358.30\", \"0.017\"], [\"70360.40\", \"0.657\"], [\"70360.50\", \"0.199\"], [\"70360.80\", \"0.034\"], [\"70365.90\", \"0.004\"], [\"70367.10\", \"3.195\"]], \"a\": [[\"70375.50\", \"0.003\"], [\"70379.80\", \"0.000\"], [\"70402.30\", \"0.005\"], [\"70407.70\", \"0.008\"], [\"70416.40\", \"0.249\"], [\"70435.90\", \"0.005\"], [\"70455.00\", \"0.073\"], [\"70455.30\", \"0.067\"], [\"70462.00\", \"0.080\"], [\"70462.30\", \"0.000\"], [\"70469.10\", \"0.152\"], [\"70469.40\", \"0.000\"], [\"70492.20\", \"2.003\"], [\"71070.90\", \"2.859\"], [\"71366.50\", \"0.351\"], [\"89523.20\", \"0.000\"]]}", "symbol": "BTCUSDT"}
{"event": "depthUpdate", "raw_payload": "{\"e\": \"depthUpdate\", \"E\": 1773246393428, \"T\": 1773246393424, \"s\": \"BTCUSDT\", \"U\": 10089704543266, \"u\": 10089704548936, \"pu\": 10089704543158, \"b\": [[\"5000.00\", \"101.418\"], [\"19867.10\", \"0.860\"], [\"19967.10\", \"0.140\"], [\"20167.10\", \"1.070\"], [\"20267.10\", \"0.930\"], [\"68959.80\", \"0.013\"], [\"69111.10\", \"0.317\"], [\"69346.80\", \"6.321\"], [\"69663.40\", \"0.000\"], [\"69858.40\", \"0.000\"], [\"70015.30\", \"0.044\"], [\"70104.90\", \"0.007\"], [\"70323.50\", \"0.000\"], [\"70360.70\", \"0.202\"], [\"70367.10\", \"3.193\"]], \"a\": [[\"70369.80\", \"0.012\"], [\"70377.10\", \"0.017\"], [\"70377.70\", \"0.000\"], [\"70378.40\", \"0.005\"], [\"70379.80\", \"0.639\"], [\"70390.60\", \"0.005\"], [\"70392.00\", \"0.463\"], [\"70399.50\", \"1.114\"], [\"70402.30\", \"0.033\"], [\"70414.30\", \"0.481\"], [\"70428.40\", \"0.204\"], [\"70428.50\", \"0.130\"], [\"70428.90\", \"0.029\"], [\"70432.70\", \"0.000\"], [\"70872.80\", \"3.720\"], [\"70875.90\", \"0.000\"], [\"71070.90\", \"2.859\"], [\"71457.90\", \"0.780\"], [\"71987.90\", \"0.654\"], [\"73893.80\", \"0.002\"]]}", "symbol": "BTCUSDT"}
{"event": "depthUpdate", "raw_payload": "{\"e\": \"depthUpdate\", \"E\": 1773246393530, \"T\": 1773246393529, \"s\": \"BTCUSDT\", \"U\": 10089704549058, \"u\": 10089704554523, \"pu\": 10089704548936, \"b\": [[\"1000.00\", \"26.942\"], [\"5000.00\", \"101.418\"], [\"19867.10\", \"0.940\"], [\"19967.10\", \"0.060\"], [\"20167.10\", \"1.250\"], [\"20267.10\", \"0.750\"], [\"66830.40\", \"0.002\"], [\"66837.60\", \"0.000\"], [\"69241.20\", \"1.009\"], [\"69346.80\", \"7.185\"], [\"69370.60\", \"1.222\"], [\"69376.80\", \"0.002\"], [\"69663.40\", \"0.000\"], [\"70242.20\", \"0.083\"], [\"70298.50\", \"0.000\"], [\"70314.30\", \"0.709\"], [\"70316.00\", \"0.347\"], [\"70316.10\", \"0.143\"], [\"70326.60\", \"0.000\"], [\"70366.00\", \"0.003\"], [\"70367.10\", \"3.191\"]], \"a\": [[\"70367.20\", \"36.793\"], [\"70367.70\", \"0.002\"], [\"70367.80\", \"0.004\"], [\"70368.30\", \"0.002\"], [\"70374.00\", \"0.000\"], [\"70374.60\", \"0.000\"], [\"70381.20\", \"0.003\"], [\"70381.70\", \"0.529\"], [\"70382.90\", \"0.000\"], [\"70384.70\", \"0.350\"], [\"70385.60\", \"0.142\"], [\"70387.10\", \"0.040\"], [\"70389.70\", \"0.005\"], [\"70391.40\", \"0.010\"], [\"70392.00\", \"0.392\"], [\"70393.10\", \"0.106\"], [\"70393.40\", \"0.071\"], [\"70398.90\", \"0.112\"], [\"70402.10\", \"0.347\"], [\"70402.30\", \"0.005\"], [\"70407.70\", \"0.005\"], [\"70435.90\", \"0.002\"], [\"70441.10\", \"0.000\"], [\"70492.20\", \"2.000\"], [\"70517.50\", \"0.010\"], [\"70524.50\", \"0.007\"], [\"70531.50\", \"0.086\"], [\"70538.50\", \"0.024\"], [\"70545.50\", \"0.007\"], [\"70548.70\", \"0.002\"], [\"70552.50\", \"0.007\"], [\"70555.70\", \"0.011\"], [\"70559.50\", \"0.007\"], [\"70562.70\", \"0.205\"], [\"70566.50\", \"0.015\"], [\"70569.70\", \"6.507\"], [\"70576.70\", \"0.000\"], [\"70583.70\", \"0.000\"], [\"70590.70\", \"0.000\"], [\"70597.70\", \"0.000\"], [\"70635.00\", \"0.008\"], [\"70653.40\", \"0.006\"], [\"70872.80\", \"0.000\"], [\"71070.90\", \"2.861\"], [\"71317.00\", \"0.002\"], [\"71370.70\", \"0.979\"], [\"71376.90\", \"0.118\"], [\"89523.20\", \"0.000\"]]}", "symbol": "BTCUSDT"}
{"event": "depthUpdate", "raw_payload": "{\"e\": \"depthUpdate\", \"E\": 1773246393632, \"T\": 1773246393630, \"s\": \"BTCUSDT\", \"U\": 10089704554564, \"u\": 10089704560757, \"pu\": 10089704554523, \"b\": [[\"1000.00\", \"26.792\"], [\"5000.00\", \"101.418\"], [\"19867.10\", \"0.970\"], [\"19967.10\", \"0.000\"], [\"20167.10\", \"1.410\"], [\"20267.10\", \"0.620\"], [\"66817.60\", \"0.000\"], [\"66821.40\", \"0.006\"], [\"66848.00\", \"0.004\"], [\"69663.40\", \"0.000\"], [\"69863.70\", \"3.720\"], [\"70242.20\", \"0.086\"], [\"70298.50\", \"0.003\"], [\"70305.20\", \"0.148\"], [\"70315.90\", \"0.105\"], [\"70316.00\", \"0.345\"], [\"70325.60\", \"0.000\"], [\"70325.70\", \"0.000\"], [\"70325.80\", \"0.087\"], [\"70326.60\", \"0.003\"], [\"70329.30\", \"0.000\"], [\"70333.30\", \"0.252\"], [\"70340.50\", \"0.061\"], [\"70342.40\", \"0.000\"], [\"70344.40\", \"0.513\"], [\"70345.90\", \"0.641\"], [\"70349.60\", \"1.125\"], [\"70349.90\", \"0.000\"], [\"70351.60\", \"0.076\"], [\"70351.90\", \"0.008\"], [\"70353.20\", \"0.000\"], [\"70355.40\", \"0.003\"], [\"70356.50\", \"0.446\"], [\"70356.60\", \"0.414\"], [\"70357.80\", \"0.186\"], [\"70358.20\", \"0.004\"], [\"70358.30\", \"0.064\"], [\"70360.20\", \"0.006\"], [\"70360.80\", \"0.003\"], [\"70362.60\", \"0.001\"], [\"70363.50\", \"0.202\"], [\"70363.60\", \"0.087\"], [\"70367.10\", \"3.305\"]], \"a\": [[\"70369.70\", \"0.003\"], [\"70374.20\", \"0.031\"], [\"70379.80\", \"0.000\"], [\"70381.50\", \"0.641\"], [\"70385.20\", \"0.052\"], [\"70385.70\", \"0.000\"], [\"70388.10\", \"0.000\"], [\"70388.50\", \"0.008\"], [\"70390.20\", \"0.513\"], [\"70390.40\", \"0.008\"], [\"70400.80\", \"0.002\"], [\"70407.70\", \"0.008\"], [\"70419.00\", \"0.101\"], [\"70426.00\", \"0.420\"], [\"70428.50\", \"0.002\"], [\"70428.60\", \"0.000\"], [\"70428.70\", \"0.131\"], [\"70428.90\", \"0.001\"], [\"70431.80\", \"0.143\"], [\"70432.70\", \"0.028\"], [\"70435.90\", \"0.005\"], [\"70483.00\", \"0.078\"], [\"70491.80\", \"0.381\"], [\"70492.20\", \"2.003\"], [\"70870.50\", \"3.724\"], [\"71070.90\", \"2.859\"], [\"71387.50\", \"1.821\"], [\"71456.50\", \"4.191\"]]}", "symbol": "BTCUSDT"}
{"event": "depthUpdate", "raw_payload": "{\"e\": \"depthUpdate\", \"E\": 1773246393734, \"T\": 1773246393733, \"s\": \"BTCUSDT\", \"U\": 10089704560885, \"u\": 10089704566578, \"pu\": 10089704560757, \"b\": [[\"5000.00\", \"101.418\"], [\"19867.10\", \"0.890\"], [\"20167.10\", \"1.590\"], [\"20267.10\", \"0.520\"], [\"33000.00\", \"10.797\"], [\"66848.70\", \"0.007\"], [\"66848.80\", \"0.002\"], [\"69663.40\", \"0.000\"], [\"69792.20\", \"46.947\"], [\"69863.70\", \"0.000\"], [\"69865.70\", \"0.028\"], [\"69918.00\", \"38.497\"], [\"70015.30\", \"0.044\"], [\"70235.10\", \"0.090\"], [\"70236.90\", \"0.084\"], [\"70281.50\", \"0.006\"], [\"70314.30\", \"0.760\"], [\"70315.60\", \"0.195\"], [\"70315.90\", \"0.103\"], [\"70325.70\", \"0.085\"], [\"70325.80\", \"0.002\"], [\"70325.90\", \"0.000\"], [\"70331.70\", \"0.250\"], [\"70333.30\", \"0.004\"], [\"70344.50\", \"0.639\"], [\"70345.90\", \"0.002\"], [\"70355.40\", \"0.145\"], [\"70356.60\", \"0.404\"], [\"70356.70\", \"0.000\"], [\"70357.80\", \"0.044\"], [\"70358.30\", \"0.054\"], [\"70360.50\", \"0.201\"], [\"70367.10\", \"3.188\"]], \"a\": [[\"70367.20\", \"37.118\"], [\"70367.70\", \"0.004\"], [\"70367.80\", \"0.041\"], [\"70374.10\", \"0.005\"], [\"70376.20\", \"0.012\"], [\"70376.50\", \"0.008\"], [\"70377.10\", \"0.014\"], [\"70398.90\", \"0.010\"], [\"70406.90\", \"0.000\"], [\"70409.90\", \"2.090\"], [\"70410.00\", \"0.013\"], [\"70428.70\", \"0.003\"], [\"70428.80\", \"0.179\"], [\"70441.10\", \"0.102\"], [\"70816.90\", \"38.365\"], [\"70866.60\", \"3.724\"], [\"70868.50\", \"0.000\"], [\"70870.50\", \"0.004\"], [\"70944.30\", \"47.817\"], [\"71070.90\", \"2.859\"], [\"71110.20\", \"0.000\"], [\"71365.80\", \"0.011\"], [\"71366.40\", \"0.837\"], [\"71471.30\", \"0.000\"], [\"73894.00\", \"0.000\"], [\"89523.20\", \"0.000\"]]}", "symbol": "BTCUSDT"}
{"event": "depthUpdate", "raw_payload": "{\"e\": \"depthUpdate\", \"E\": 1773246393838, \"T\": 1773246393836, \"s\": \"BTCUSDT\", \"U\": 10089704566737, \"u\": 10089704571774, \"pu\": 10089704566578, \"b\": [[\"1000.00\", \"26.792\"], [\"5000.00\", \"101.418\"], [\"19867.10\", \"0.800\"], [\"20067.10\", \"0.070\"], [\"20167.10\", \"1.620\"], [\"20267.10\", \"0.510\"], [\"33000.00\", \"10.793\"], [\"63330.40\", \"0.016\"], [\"66827.00\", \"0.022\"], [\"69663.40\", \"0.000\"], [\"70315.60\", \"0.193\"], [\"70315.80\", \"0.004\"], [\"70342.90\", \"1.579\"], [\"70344.40\", \"0.002\"], [\"70356.90\", \"0.011\"], [\"70357.90\", \"0.018\"], [\"70366.10\", \"0.002\"]], \"a\": [[\"70367.70\", \"0.002\"], [\"70367.80\", \"0.043\"], [\"70369.70\", \"0.003\"], [\"70376.60\", \"0.107\"], [\"70405.30\", \"0.084\"], [\"70428.90\", \"0.029\"], [\"70432.70\", \"0.000\"], [\"70480.00\", \"0.067\"], [\"70534.00\", \"0.123\"], [\"71070.90\", \"2.859\"], [\"71277.80\", \"0.007\"], [\"71692.40\", \"0.597\"], [\"73893.80\", \"0.000\"], [\"77403.90\", \"0.002\"]]}", "symbol": "BTCUSDT"}
{"event": "depthUpdate", "raw_payload": "{\"e\": \"depthUpdate\", \"E\": 1773246393940, \"T\": 1773246393939, \"s\": \"BTCUSDT\", \"U\": 10089704571880, \"u\": 10089704578125, \"pu\": 10089704571774, \"b\": [[\"5000.00\", \"101.418\"], [\"19867.10\", \"0.720\"], [\"20067.10\", \"0.160\"], [\"20167.10\", \"1.610\"], [\"20267.10\", \"0.510\"], [\"63330.40\", \"0.014\"], [\"64700.00\", \"2.451\"], [\"66820.40\", \"0.002\"], [\"69425.70\", \"63.768\"], [\"69533.10\", \"0.000\"], [\"69634.60\", \"55.256\"], [\"69663.40\", \"0.000\"], [\"69792.30\", \"3.242\"], [\"69869.20\", \"3.720\"], [\"70314.30\", \"0.709\"], [\"70315.80\", \"0.002\"], [\"70315.90\", \"0.105\"], [\"70325.50\", \"0.253\"], [\"70325.70\", \"0.000\"], [\"70336.70\", \"0.388\"], [\"70346.20\", \"0.276\"], [\"70357.70\", \"0.103\"], [\"70357.80\", \"0.002\"], [\"70366.50\", \"0.002\"], [\"70367.10\", \"3.190\"]], \"a\": [[\"70367.20\", \"36.793\"], [\"70367.70\", \"0.002\"], [\"70367.80\", \"0.004\"], [\"70381.40\", \"0.002\"], [\"70381.70\", \"0.527\"], [\"70382.60\", \"0.010\"], [\"70398.90\", \"0.112\"], [\"70602.10\", \"0.755\"], [\"70602.30\", \"0.006\"], [\"70617.10\", \"0.004\"], [\"70622.90\", \"0.000\"], [\"70708.90\", \"0.166\"], [\"70865.00\", \"3.746\"], [\"70866.60\", \"0.004\"], [\"70870.40\", \"0.000\"], [\"71070.90\", \"2.861\"], [\"71106.40\", \"52.992\"], [\"71319.70\", \"64.058\"], [\"73894.70\", \"0.003\"], [\"77403.90\", \"0.000\"], [\"89523.20\", \"0.000\"]]}", "symbol": "BTCUSDT"}
{"event": "depthUpdate", "raw_payload": "{\"e\": \"depthUpdate\", \"E\": 1773246394042, \"T\": 1773246394040, \"s\": \"BTCUSDT\", \"U\": 10089704578132, \"u\": 10089704583825, \"pu\": 10089704578125, \"b\": [[\"5000.00\", \"101.398\"], [\"19867.10\", \"0.630\"], [\"20067.10\", \"0.240\"], [\"20167.10\", \"1.620\"], [\"20267.10\", \"0.510\"], [\"40000.00\", \"50.271\"], [\"56294.00\", \"0.004\"], [\"66846.90\", \"0.002\"], [\"69663.40\", \"0.000\"], [\"69869.20\", \"0.000\"], [\"69870.70\", \"0.013\"], [\"70015.30\", \"0.044\"], [\"70062.70\", \"0.006\"], [\"70236.40\", \"0.653\"], [\"70289.70\", \"0.263\"], [\"70296.40\", \"0.004\"], [\"70296.70\", \"1.002\"], [\"70298.30\", \"0.009\"], [\"70322.00\", \"0.625\"], [\"70329.00\", \"0.653\"], [\"70336.00\", \"0.711\"], [\"70338.90\", \"0.002\"], [\"70343.00\", \"1.198\"], [\"70348.50\", \"0.501\"], [\"70350.00\", \"0.629\"], [\"70351.30\", \"0.038\"], [\"70351.50\", \"1.237\"], [\"70352.90\", \"0.095\"], [\"70353.00\", \"0.896\"], [\"70353.20\", \"0.000\"], [\"70353.30\", \"0.460\"], [\"70354.30\", \"0.097\"], [\"70354.40\", \"0.074\"], [\"70354.50\", \"0.115\"], [\"70354.90\", \"0.051\"], [\"70355.00\", \"0.337\"], [\"70355.30\", \"0.101\"], [\"70355.40\", \"0.003\"], [\"70356.50\", \"0.474\"], [\"70356.60\", \"0.494\"], [\"70357.80\", \"0.144\"], [\"70358.60\", \"0.053\"], [\"70359.90\", \"0.302\"], [\"70360.20\", \"0.006\"], [\"70361.70\", \"0.001\"], [\"70367.10\", \"3.336\"]], \"a\": [[\"70367.20\", \"36.791\"], [\"70369.70\", \"0.003\"], [\"70373.90\", \"0.001\"], [\"70374.00\", \"0.000\"], [\"70374.10\", \"0.002\"], [\"70374.30\", \"0.000\"], [\"70374.60\", \"0.002\"], [\"70379.30\", \"0.385\"], [\"70379.40\", \"1.069\"], [\"70379.90\", \"0.006\"], [\"70383.10\", \"0.030\"], [\"70383.80\", \"0.000\"], [\"70384.80\", \"0.004\"], [\"70387.10\", \"0.000\"], [\"70387.30\", \"0.040\"], [\"70388.60\", \"0.003\"], [\"70391.00\", \"0.339\"], [\"70392.00\", \"1.013\"], [\"70399.00\", \"0.623\"], [\"70405.30\", \"0.004\"], [\"70406.00\", \"1.701\"], [\"70413.00\", \"1.695\"], [\"70417.20\", \"0.000\"], [\"70417.80\", \"0.573\"], [\"70420.00\", \"1.883\"], [\"70427.60\", \"0.101\"], [\"70428.90\", \"0.001\"], [\"70430.30\", \"0.160\"], [\"70432.70\", \"0.028\"], [\"70436.70\", \"0.256\"], [\"70439.60\", \"0.192\"], [\"70505.70\", \"1.434\"], [\"70507.60\", \"0.438\"], [\"70507.70\", \"0.004\"], [\"70602.30\", \"0.000\"], [\"70862.20\", \"3.724\"], [\"70863.50\", \"0.000\"], [\"70865.00\", \"0.026\"], [\"71070.90\", \"2.859\"], [\"71277.70\", \"0.135\"], [\"71317.20\", \"1.886\"], [\"71387.50\", \"2.800\"], [\"71493.10\", \"1.675\"]]}", "symbol": "BTCUSDT"}
{"event": "depthUpdate", "raw_payload": "{\"e\": \"depthUpdate\", \"E\": 1773246394144, \"T\": 1773246394140, \"s\": \"BTCUSDT\", \"U\": 10089704583950, \"u\": 10089704590717, \"pu\": 10089704583825, \"b\": [[\"1000.00\", \"26.792\"], [\"5000.00\", \"101.418\"], [\"19867.10\", \"0.550\"], [\"20067.10\", \"0.330\"], [\"20167.10\", \"1.610\"], [\"20267.10\", \"0.510\"], [\"40000.00\", \"50.271\"], [\"56294.00\", \"0.000\"], [\"66820.80\", \"0.031\"], [\"70062.60\", \"0.000\"], [\"70242.20\", \"0.083\"], [\"70278.80\", \"0.071\"], [\"70279.00\", \"0.002\"], [\"70285.90\", \"0.071\"], [\"70286.10\", \"0.002\"], [\"70289.70\", \"0.263\"], [\"70292.90\", \"0.071\"], [\"70293.10\", \"1.346\"], [\"70298.50\", \"0.000\"], [\"70310.80\", \"0.223\"], [\"70315.90\", \"0.103\"], [\"70316.00\", \"0.347\"], [\"70322.00\", \"0.004\"], [\"70324.80\", \"0.786\"], [\"70325.10\", \"0.114\"], [\"70325.20\", \"0.191\"], [\"70325.30\", \"0.002\"], [\"70325.40\", \"0.914\"], [\"70325.50\", \"0.168\"], [\"70326.60\", \"0.000\"], [\"70328.80\", \"0.000\"], [\"70329.00\", \"0.032\"], [\"70335.40\", \"0.005\"], [\"70336.00\", \"0.090\"], [\"70343.00\", \"0.577\"], [\"70344.60\", \"0.002\"], [\"70347.60\", \"0.000\"], [\"70348.40\", \"0.484\"], [\"70348.50\", \"0.017\"], [\"70349.50\", \"1.074\"], [\"70349.80\", \"0.010\"], [\"70350.00\", \"0.008\"], [\"70350.30\", \"0.002\"], [\"70351.30\", \"0.038\"], [\"70351.50\", \"1.237\"], [\"70352.60\", \"0.186\"], [\"70352.90\", \"0.095\"], [\"70353.30\", \"0.460\"], [\"70353.40\", \"0.012\"], [\"70354.30\", \"0.097\"], [\"70354.40\", \"0.074\"], [\"70354.50\", \"0.115\"], [\"70354.90\", \"0.051\"], [\"70355.00\", \"0.337\"], [\"70355.10\", \"0.121\"], [\"70355.30\", \"0.101\"], [\"70355.60\", \"0.000\"], [\"70355.90\", \"0.081\"], [\"70356.50\", \"0.474\"], [\"70356.60\", \"0.494\"], [\"70356.70\", \"0.142\"], [\"70357.70\", \"0.100\"], [\"70357.80\", \"0.002\"], [\"70357.90\", \"0.021\"], [\"70358.60\", \"0.053\"], [\"70359.90\", \"0.302\"], [\"70360.30\", \"0.269\"], [\"70360.60\", \"0.001\"], [\"70362.00\", \"0.037\"], [\"70363.70\", \"0.014\"], [\"70367.10\", \"3.294\"]], \"a\": [[\"70367.20\", \"36.761\"], [\"70373.70\", \"0.003\"], [\"70379.90\", \"0.002\"], [\"70380.70\", \"0.000\"], [\"70383.10\", \"0.030\"], [\"70383.80\", \"0.000\"], [\"70384.80\", \"0.004\"], [\"70385.60\", \"0.000\"], [\"70386.60\", \"0.144\"], [\"70387.00\", \"0.133\"], [\"70391.00\", \"0.299\"], [\"70392.00\", \"0.392\"], [\"70397.60\", \"0.064\"], [\"70399.00\", \"0.002\"], [\"70402.20\", \"0.002\"], [\"70406.00\", \"1.080\"], [\"70407.70\", \"0.005\"], [\"70413.00\", \"1.074\"], [\"70415.90\", \"0.046\"], [\"70420.00\", \"1.262\"], [\"70423.50\", \"0.086\"], [\"70428.80\", \"0.051\"], [\"70428.90\", \"0.129\"], [\"70435.90\", \"0.002\"], [\"70443.30\", \"9.704\"], [\"70443.40\", \"0.008\"], [\"70454.80\", \"0.071\"], [\"70455.00\", \"0.002\"], [\"70461.80\", \"0.161\"], [\"70462.00\", \"0.009\"], [\"70468.90\", \"0.112\"], [\"70469.10\", \"0.081\"], [\"70492.20\", \"2.000\"], [\"70507.90\", \"0.038\"], [\"70508.80\", \"0.039\"], [\"70602.20\", \"2.960\"], [\"70742.60\", \"0.000\"], [\"70742.70\", \"0.002\"], [\"70862.20\", \"0.004\"], [\"71070.90\", \"2.859\"], [\"71235.10\", \"0.000\"], [\"71277.70\", \"0.129\"], [\"71484.40\", \"0.000\"], [\"73887.80\", \"0.010\"], [\"89523.20\", \"0.000\"]]}", "symbol": "BTCUSDT"}
{"event": "depthUpdate", "raw_payload": "{\"e\": \"depthUpdate\", \"E\": 1773246394246, \"T\": 1773246394245, \"s\": \"BTCUSDT\", \"U\": 10089704591016, \"u\": 10089704595880, \"pu\": 10089704590717, \"b\": [[\"5000.00\", \"101.418\"], [\"19867.10\", \"0.460\"], [\"20067.10\", \"0.440\"], [\"20167.10\", \"1.560\"], [\"20267.10\", \"0.540\"], [\"40000.00\", \"50.522\"], [\"66826.70\", \"0.003\"], [\"66846.90\", \"0.000\"], [\"69184.90\", \"0.291\"], [\"69663.40\", \"0.000\"], [\"70236.40\", \"0.652\"], [\"70293.20\", \"0.091\"], [\"70314.30\", \"0.927\"], [\"70325.10\", \"0.029\"], [\"70325.20\", \"0.276\"], [\"70325.30\", \"0.002\"], [\"70348.40\", \"0.000\"], [\"70351.30\", \"0.010\"], [\"70351.50\", \"1.209\"], [\"70352.90\", \"0.064\"], [\"70353.30\", \"0.000\"], [\"70354.30\", \"0.076\"], [\"70354.40\", \"0.016\"], [\"70354.50\", \"0.058\"], [\"70354.90\", \"0.003\"], [\"70355.00\", \"0.280\"], [\"70355.30\", \"0.058\"], [\"70356.50\", \"0.446\"], [\"70356.60\", \"0.404\"], [\"70358.60\", \"0.006\"], [\"70359.90\", \"0.205\"], [\"70366.90\", \"0.004\"]], \"a\": [[\"70369.70\", \"0.003\"], [\"70383.80\", \"0.028\"], [\"70384.80\", \"0.032\"], [\"70505.60\", \"1.949\"], [\"70505.70\", \"0.087\"], [\"70602.20\", \"2.954\"], [\"70678.10\", \"0.000\"], [\"70839.30\", \"0.000\"], [\"70880.80\", \"0.011\"], [\"70886.70\", \"0.000\"], [\"71070.80\", \"0.006\"], [\"71070.90\", \"2.859\"], [\"71093.50\", \"0.004\"], [\"71306.10\", \"0.051\"], [\"71518.80\", \"0.006\"], [\"71669.70\", \"0.002\"], [\"71731.40\", \"0.004\"]]}", "symbol": "BTCUSDT"}
{"event": "depthUpdate", "raw_payload": "{\"e\": \"depthUpdate\", \"E\": 1773246394348, \"T\": 1773246394347, \"s\": \"BTCUSDT\", \"U\": 10089704596085, \"u\": 10089704601321, \"pu\": 10089704595880, \"b\": [[\"5000.00\", \"101.398\"], [\"19867.10\", \"0.380\"], [\"20067.10\", \"0.610\"], [\"20167.10\", \"1.390\"], [\"20267.10\", \"0.620\"], [\"40000.00\", \"50.271\"], [\"56294.00\", \"0.000\"], [\"66827.00\", \"0.020\"], [\"68540.60\", \"0.000\"], [\"68893.00\", \"0.010\"], [\"68958.10\", \"0.002\"], [\"69245.40\", \"0.002\"], [\"69421.60\", \"0.015\"], [\"69663.40\", \"0.000\"], [\"69879.80\", \"3.720\"], [\"70015.30\", \"0.044\"], [\"70242.20\", \"0.086\"], [\"70247.90\", \"0.260\"], [\"70248.10\", \"0.002\"], [\"70278.70\", \"0.071\"], [\"70278.80\", \"0.000\"], [\"70285.80\", \"0.079\"], [\"70285.90\", \"0.000\"], [\"70289.70\", \"0.179\"], [\"70292.80\", \"0.073\"], [\"70292.90\", \"0.000\"], [\"70298.50\", \"0.003\"], [\"70315.80\", \"0.004\"], [\"70316.00\", \"0.345\"], [\"70326.60\", \"0.003\"], [\"70348.40\", \"0.484\"], [\"70348.60\", \"0.008\"], [\"70351.10\", \"0.011\"], [\"70351.30\", \"0.038\"], [\"70351.50\", \"0.030\"], [\"70352.80\", \"0.544\"], [\"70353.30\", \"0.460\"], [\"70354.30\", \"0.097\"], [\"70354.40\", \"0.074\"], [\"70354.50\", \"0.101\"], [\"70354.90\", \"0.017\"], [\"70355.20\", \"2.290\"], [\"70355.30\", \"0.101\"], [\"70355.90\", \"0.081\"], [\"70356.50\", \"0.706\"], [\"70356.60\", \"0.494\"], [\"70357.20\", \"0.347\"], [\"70357.90\", \"0.018\"], [\"70358.50\", \"0.050\"], [\"70358.70\", \"0.006\"], [\"70359.50\", \"0.000\"], [\"70359.80\", \"0.003\"], [\"70359.90\", \"0.302\"], [\"70360.80\", \"0.401\"], [\"70362.00\", \"0.003\"], [\"70367.00\", \"0.068\"], [\"70367.10\", \"3.393\"]], \"a\": [[\"70367.20\", \"35.980\"], [\"70376.50\", \"0.005\"], [\"70376.90\", \"0.004\"], [\"70377.80\", \"0.000\"], [\"70381.00\", \"0.003\"], [\"70381.40\", \"0.000\"], [\"70381.50\", \"0.002\"], [\"70381.60\", \"0.378\"], [\"70382.90\", \"0.639\"], [\"70383.80\", \"0.000\"], [\"70384.80\", \"0.004\"], [\"70387.70\", \"0.559\"], [\"70388.00\", \"0.002\"], [\"70389.50\", \"0.008\"], [\"70389.80\", \"0.010\"], [\"70393.40\", \"0.000\"], [\"70394.90\", \"0.071\"], [\"70407.70\", \"0.008\"], [\"70409.90\", \"2.017\"], [\"70415.90\", \"0.000\"], [\"70417.20\", \"0.046\"], [\"70435.90\", \"0.005\"], [\"70454.80\", \"0.071\"], [\"70461.80\", \"0.161\"], [\"70468.90\", \"0.112\"], [\"70492.20\", \"2.003\"], [\"70553.10\", \"0.198\"], [\"70602.10\", \"0.761\"], [\"70676.20\", \"0.058\"], [\"70833.30\", \"0.309\"], [\"70854.40\", \"3.722\"], [\"70995.10\", \"0.304\"], [\"71000.50\", \"0.039\"], [\"71070.80\", \"0.000\"], [\"71070.90\", \"2.859\"], [\"71156.90\", \"0.304\"], [\"71318.70\", \"0.304\"], [\"71683.10\", \"0.837\"], [\"73910.20\", \"0.002\"], [\"89523.20\", \"0.000\"]]}", "symbol": "BTCUSDT"}
{"event": "depthUpdate", "raw_payload": "{\"e\": \"depthUpdate\", \"E\": 1773246394450, \"T\": 1773246394449, \"s\": \"BTCUSDT\", \"U\": 10089704601334, \"u\": 10089704607376, \"pu\": 10089704601321, \"b\": [[\"1000.00\", \"26.792\"], [\"5000.00\", \"101.418\"], [\"19867.10\", \"0.290\"], [\"20067.10\", \"0.780\"], [\"20167.10\", \"1.220\"], [\"20267.10\", \"0.710\"], [\"33000.00\", \"10.797\"], [\"66820.90\", \"0.090\"], [\"68959.80\", \"0.016\"], [\"69376.60\", \"1.142\"], [\"69454.70\", \"0.719\"], [\"69663.40\", \"0.000\"], [\"69700.10\", \"0.122\"], [\"69879.80\", \"0.000\"], [\"69881.40\", \"3.720\"], [\"70025.20\", \"0.000\"], [\"70062.80\", \"0.007\"], [\"70104.90\", \"0.000\"], [\"70205.80\", \"0.082\"], [\"70263.60\", \"0.597\"], [\"70293.90\", \"0.000\"], [\"70315.80\", \"0.002\"], [\"70316.40\", \"0.003\"], [\"70325.20\", \"0.191\"], [\"70325.30\", \"0.087\"], [\"70336.30\", \"0.000\"], [\"70339.40\", \"0.010\"], [\"70339.50\", \"0.004\"], [\"70340.10\", \"0.002\"], [\"70340.20\", \"0.000\"], [\"70341.80\", \"0.052\"], [\"70342.20\", \"0.002\"], [\"70342.30\", \"0.055\"], [\"70342.90\", \"1.579\"], [\"70343.00\", \"0.577\"], [\"70343.10\", \"0.008\"], [\"70346.70\", \"0.413\"], [\"70349.50\", \"1.072\"], [\"70351.80\", \"0.006\"], [\"70353.20\", \"0.002\"], [\"70355.20\", \"2.297\"], [\"70356.50\", \"0.703\"], [\"70358.30\", \"0.047\"], [\"70359.80\", \"0.000\"], [\"70361.30\", \"0.401\"], [\"70361.50\", \"0.010\"], [\"70363.60\", \"0.189\"], [\"70367.10\", \"3.289\"]], \"a\": [[\"70369.70\", \"0.003\"], [\"70374.20\", \"0.003\"], [\"70377.80\", \"0.003\"], [\"70379.00\", \"0.004\"], [\"70381.40\", \"0.002\"], [\"70390.40\", \"0.001\"], [\"70391.40\", \"0.003\"], [\"70391.80\", \"0.007\"], [\"70393.70\", \"0.007\"], [\"70409.80\", \"0.076\"], [\"70426.70\", \"0.192\"], [\"70457.60\", \"0.000\"], [\"70522.80\", \"0.002\"], [\"70715.30\", \"0.000\"], [\"70852.80\", \"3.722\"], [\"70854.40\", \"0.002\"], [\"71032.10\", \"0.000\"], [\"71070.90\", \"2.859\"], [\"71774.50\", \"0.009\"], [\"73889.80\", \"0.289\"]]}", "symbol": "BTCUSDT"}
{"event": "depthUpdate", "raw_payload": "{\"e\": \"depthUpdate\", \"E\": 1773246394552, \"T\": 1773246394551, \"s\": \"BTCUSDT\", \"U\": 10089704607410, \"u\": 10089704633121, \"pu\": 10089704607376, \"b\": [[\"5000.00\", \"101.418\"], [\"19867.10\", \"0.210\"], [\"20067.10\", \"0.900\"], [\"20068.00\", \"0.010\"], [\"20068.30\", \"0.010\"], [\"20070.00\", \"0.010\"], [\"20070.40\", \"0.020\"], [\"20167.10\", \"1.050\"], [\"20267.10\", \"0.770\"], [\"20268.20\", \"0.010\"], [\"20270.00\", \"0.010\"], [\"33000.00\", \"10.793\"], [\"56294.00\", \"0.008\"], [\"56295.00\", \"0.116\"], [\"63330.40\", \"0.016\"], [\"63331.20\", \"0.002\"], [\"63340.70\", \"0.000\"], [\"63430.70\", \"0.002\"], [\"66820.40\", \"0.000\"], [\"68716.80\", \"0.000\"], [\"69069.20\", \"0.002\"], [\"69361.10\", \"0.000\"], [\"69361.20\", \"0.000\"], [\"69362.60\", \"0.004\"], [\"69363.20\", \"0.008\"], [\"69368.20\", \"0.002\"], [\"69370.00\", \"0.022\"], [\"69370.30\", \"1.587\"], [\"69370.40\", \"0.004\"], [\"69421.60\", \"0.013\"], [\"69543.80\", \"0.574\"], [\"69597.80\", \"0.002\"], [\"69663.40\", \"0.000\"], [\"69666.60\", \"0.278\"], [\"69837.50\", \"0.002\"], [\"69838.20\", \"0.000\"], [\"69881.40\", \"0.000\"], [\"69966.40\", \"0.000\"], [\"70017.60\", \"0.000\"], [\"70063.40\", \"0.014\"], [\"70067.60\", \"0.002\"], [\"70104.00\", \"0.002\"], [\"70106.50\", \"0.003\"], [\"70123.50\", \"0.000\"], [\"70126.90\", \"0.000\"], [\"70152.20\", \"0.002\"], [\"70170.20\", \"0.018\"], [\"70170.50\", \"0.000\"], [\"70172.40\", \"6.546\"], [\"70177.40\", \"0.011\"], [\"70179.30\", \"0.046\"], [\"70180.40\", \"0.000\"], [\"70184.30\", \"0.000\"], [\"70189.70\", \"0.080\"], [\"70191.20\", \"0.000\"], [\"70196.60\", \"23.268\"], [\"70197.80\", \"0.002\"], [\"70199.60\", \"0.000\"], [\"70202.40\", \"3.278\"], [\"70203.20\", \"0.001\"], [\"70204.90\", \"0.000\"], [\"70206.50\", \"0.119\"], [\"70207.50\", \"0.002\"], [\"70208.60\", \"0.003\"], [\"70223.20\", \"0.014\"], [\"70228.30\", \"0.000\"], [\"70228.60\", \"0.083\"], [\"70232.70\", \"0.045\"], [\"70234.50\", \"0.053\"], [\"70238.70\", \"0.048\"], [\"70238.90\", \"0.088\"], [\"70241.80\", \"0.082\"], [\"70242.70\", \"0.000\"], [\"70247.80\", \"0.000\"], [\"70250.40\", \"0.081\"], [\"70252.40\", \"0.014\"], [\"70254.30\", \"1.410\"], [\"70255.90\", \"0.002\"], [\"70259.10\", \"0.003\"], [\"70259.60\", \"0.000\"], [\"70260.00\", \"0.016\"], [\"70261.30\", \"0.002\"], [\"70261.50\", \"0.081\"], [\"70269.00\", \"0.004\"], [\"70270.10\", \"0.060\"], [\"70270.60\", \"0.125\"], [\"70271.40\", \"0.231\"], [\"70272.20\", \"0.014\"], [\"70272.30\", \"0.086\"], [\"70275.40\", \"0.014\"], [\"70275.60\", \"0.002\"], [\"70275.90\", \"0.007\"], [\"70276.00\", \"0.009\"], [\"70277.90\", \"6.305\"], [\"70278.00\", \"0.547\"], [\"70278.50\", \"0.000\"], [\"70279.70\", \"0.085\"], [\"70279.80\", \"0.002\"], [\"70280.00\", \"1.427\"], [\"70281.30\", \"0.085\"], [\"70283.10\", \"0.052\"], [\"70285.10\", \"0.000\"], [\"70285.70\", \"1.293\"], [\"70286.50\", \"0.084\"], [\"70287.00\", \"0.755\"], [\"70287.10\", \"2.102\"], [\"70287.70\", \"0.333\"], [\"70288.40\", \"0.039\"], [\"70288.70\", \"0.104\"], [\"70288.80\", \"0.465\"], [\"70289.50\", \"0.273\"], [\"70289.70\", \"0.025\"], [\"70290.20\", \"0.002\"], [\"70290.40\", \"0.484\"], [\"70291.20\", \"0.292\"], [\"70292.10\", \"0.002\"], [\"70292.20\", \"0.002\"], [\"70292.80\", \"0.091\"], [\"70293.20\", \"0.002\"], [\"70293.40\", \"0.097\"], [\"70293.60\", \"0.177\"], [\"70294.00\", \"0.838\"], [\"70294.60\", \"0.002\"], [\"70294.70\", \"0.215\"], [\"70295.80\", \"0.133\"], [\"70297.00\", \"0.005\"], [\"70297.90\", \"0.000\"], [\"70300.50\", \"1.094\"], [\"70301.30\", \"0.040\"], [\"70301.50\", \"0.000\"], [\"70304.10\", \"0.126\"], [\"70305.20\", \"0.007\"], [\"70307.30\", \"0.124\"], [\"70308.50\", \"0.116\"], [\"70308.80\", \"0.149\"], [\"70309.40\", \"1.062\"], [\"70310.80\", \"0.005\"], [\"70310.90\", \"0.023\"], [\"70311.70\", \"0.002\"], [\"70311.80\", \"0.010\"], [\"70311.90\", \"0.073\"], [\"70312.00\", \"0.066\"], [\"70312.10\", \"0.005\"], [\"70313.30\", \"0.002\"], [\"70313.40\", \"0.007\"], [\"70314.30\", \"0.709\"], [\"70315.90\", \"0.002\"], [\"70316.10\", \"0.002\"], [\"70316.40\", \"0.001\"], [\"70316.60\", \"0.002\"], [\"70316.70\", \"0.107\"], [\"70317.00\", \"0.008\"], [\"70317.20\", \"0.003\"], [\"70317.50\", \"0.202\"], [\"70317.90\", \"0.002\"], [\"70318.80\", \"0.010\"], [\"70319.60\", \"0.000\"], [\"70319.80\", \"0.552\"], [\"70320.70\", \"0.000\"], [\"70321.70\", \"0.002\"], [\"70322.20\", \"0.003\"], [\"70323.00\", \"0.004\"], [\"70323.70\", \"0.713\"], [\"70324.20\", \"0.005\"], [\"70324.60\", \"0.001\"], [\"70324.80\", \"0.005\"], [\"70324.90\", \"3.061\"], [\"70325.00\", \"0.361\"], [\"70325.10\", \"0.000\"], [\"70325.30\", \"0.002\"], [\"70325.60\", \"0.186\"], [\"70326.00\", \"0.073\"], [\"70326.30\", \"0.006\"], [\"70327.30\", \"0.085\"], [\"70327.70\", \"0.582\"], [\"70328.10\", \"0.214\"], [\"70328.50\", \"0.167\"], [\"70329.80\", \"0.006\"], [\"70330.50\", \"0.002\"], [\"70330.60\", \"0.388\"], [\"70330.70\", \"0.002\"], [\"70331.10\", \"0.000\"], [\"70331.70\", \"0.002\"], [\"70332.10\", \"0.288\"], [\"70332.50\", \"0.041\"], [\"70332.60\", \"0.066\"], [\"70333.20\", \"2.086\"], [\"70334.30\", \"0.003\"], [\"70334.90\", \"0.035\"], [\"70335.50\", \"0.046\"], [\"70335.70\", \"0.007\"], [\"70337.20\", \"0.000\"], [\"70337.30\", \"0.006\"], [\"70337.70\", \"0.004\"], [\"70338.00\", \"0.014\"], [\"70338.10\", \"0.000\"], [\"70338.70\", \"0.090\"], [\"70338.80\", \"0.002\"], [\"70338.90\", \"0.009\"], [\"70339.10\", \"0.266\"], [\"70339.30\", \"0.008\"], [\"70339.40\", \"0.017\"], [\"70339.50\", \"0.011\"], [\"70339.60\", \"0.772\"], [\"70339.80\", \"0.003\"], [\"70339.90\", \"0.000\"], [\"70340.10\", \"0.002\"], [\"70340.20\", \"0.000\"], [\"70340.40\", \"0.005\"], [\"70340.70\", \"0.045\"], [\"70340.80\", \"0.000\"], [\"70340.90\", \"0.013\"], [\"70341.50\", \"0.056\"], [\"70341.60\", \"0.029\"], [\"70341.80\", \"0.005\"], [\"70342.20\", \"0.000\"], [\"70342.30\", \"0.053\"], [\"70342.80\", \"0.000\"], [\"70342.90\", \"1.071\"], [\"70343.00\", \"0.575\"], [\"70343.60\", \"0.005\"], [\"70343.70\", \"0.007\"], [\"70344.20\", \"0.001\"], [\"70344.30\", \"0.004\"], [\"70344.50\", \"0.000\"], [\"70345.10\", \"0.002\"], [\"70345.30\", \"0.052\"], [\"70345.50\", \"0.114\"], [\"70345.90\", \"0.000\"], [\"70346.00\", \"0.217\"], [\"70346.10\", \"0.005\"], [\"70346.20\", \"0.195\"], [\"70346.40\", \"0.000\"], [\"70346.50\", \"0.002\"], [\"70346.60\", \"0.003\"], [\"70346.70\", \"0.342\"], [\"70346.80\", \"0.000\"], [\"70347.00\", \"0.000\"], [\"70347.10\", \"0.006\"], [\"70347.30\", \"0.240\"], [\"70347.40\", \"0.047\"], [\"70347.80\", \"0.071\"], [\"70348.00\", \"0.177\"], [\"70348.40\", \"0.000\"], [\"70348.50\", \"0.012\"], [\"70348.80\", \"0.002\"], [\"70348.90\", \"0.207\"], [\"70349.00\", \"0.002\"], [\"70349.10\", \"0.375\"], [\"70349.20\", \"0.003\"], [\"70349.30\", \"0.000\"], [\"70349.70\", \"0.003\"], [\"70349.80\", \"0.003\"], [\"70350.10\", \"0.003\"], [\"70350.20\", \"0.175\"], [\"70350.40\", \"0.000\"], [\"70350.70\", \"0.002\"], [\"70351.00\", \"0.045\"], [\"70351.10\", \"0.004\"], [\"70351.30\", \"0.010\"], [\"70351.40\", \"0.127\"], [\"70351.50\", \"0.002\"], [\"70351.60\", \"0.074\"], [\"70351.70\", \"0.003\"], [\"70351.90\", \"0.006\"], [\"70352.30\", \"0.002\"], [\"70352.40\", \"0.007\"], [\"70352.80\", \"0.513\"], [\"70352.90\", \"0.006\"], [\"70353.00\", \"0.705\"], [\"70353.10\", \"0.511\"], [\"70353.20\", \"0.000\"], [\"70353.30\", \"0.002\"], [\"70353.40\", \"0.005\"], [\"70353.50\", \"0.609\"], [\"70353.60\", \"1.261\"], [\"70353.90\", \"0.379\"], [\"70354.00\", \"0.007\"], [\"70354.30\", \"0.077\"], [\"70354.40\", \"0.087\"], [\"70354.50\", \"0.057\"], [\"70354.80\", \"0.000\"], [\"70354.90\", \"0.003\"], [\"70355.00\", \"0.280\"], [\"70355.10\", \"0.531\"], [\"70355.20\", \"1.129\"], [\"70355.30\", \"0.053\"], [\"70355.50\", \"0.001\"], [\"70355.80\", \"0.555\"], [\"70355.90\", \"0.080\"], [\"70356.20\", \"0.004\"], [\"70356.30\", \"0.208\"], [\"70356.40\", \"0.001\"], [\"70356.50\", \"0.675\"], [\"70356.60\", \"0.008\"], [\"70356.70\", \"0.000\"], [\"70356.90\", \"0.003\"], [\"70357.10\", \"0.000\"], [\"70357.20\", \"0.001\"], [\"70357.30\", \"0.511\"], [\"70357.40\", \"0.007\"], [\"70357.50\", \"0.005\"], [\"70357.70\", \"0.100\"], [\"70357.80\", \"0.000\"], [\"70357.90\", \"0.008\"], [\"70358.00\", \"0.002\"], [\"70358.20\", \"0.055\"], [\"70358.30\", \"0.000\"], [\"70358.50\", \"0.005\"], [\"70358.60\", \"0.010\"], [\"70358.80\", \"0.030\"], [\"70358.90\", \"0.023\"], [\"70359.00\", \"0.002\"], [\"70359.10\", \"0.004\"], [\"70359.20\", \"0.000\"], [\"70359.30\", \"0.000\"], [\"70359.40\", \"0.003\"], [\"70359.50\", \"0.028\"], [\"70359.60\", \"0.083\"], [\"70359.70\", \"0.002\"], [\"70359.80\", \"0.002\"], [\"70359.90\", \"0.209\"], [\"70360.00\", \"0.007\"], [\"70360.10\", \"0.460\"], [\"70360.20\", \"0.006\"], [\"70360.30\", \"0.036\"], [\"70360.40\", \"0.007\"], [\"70360.50\", \"0.541\"], [\"70360.60\", \"0.001\"], [\"70360.80\", \"1.213\"], [\"70360.90\", \"1.353\"], [\"70361.00\", \"0.146\"], [\"70361.10\", \"0.119\"], [\"70361.20\", \"0.002\"], [\"70361.30\", \"0.003\"], [\"70361.40\", \"0.000\"], [\"70361.50\", \"0.003\"], [\"70361.60\", \"0.004\"], [\"70361.80\", \"0.021\"], [\"70361.90\", \"0.058\"], [\"70362.00\", \"0.393\"], [\"70362.10\", \"0.059\"], [\"70362.30\", \"0.000\"], [\"70362.40\", \"0.113\"], [\"70362.50\", \"0.004\"], [\"70362.60\", \"0.001\"], [\"70362.80\", \"0.044\"], [\"70362.90\", \"0.000\"], [\"70363.00\", \"0.538\"], [\"70363.10\", \"0.006\"], [\"70363.40\", \"0.000\"], [\"70363.50\", \"0.203\"], [\"70363.60\", \"0.886\"], [\"70363.70\", \"0.142\"], [\"70363.80\", \"0.001\"], [\"70364.00\", \"0.037\"], [\"70364.10\", \"0.091\"], [\"70364.20\", \"0.002\"], [\"70364.70\", \"0.008\"], [\"70364.80\", \"0.001\"], [\"70365.00\", \"0.022\"], [\"70365.10\", \"0.011\"], [\"70365.50\", \"0.000\"], [\"70365.60\", \"0.005\"], [\"70365.70\", \"0.000\"], [\"70365.90\", \"0.002\"], [\"70366.00\", \"0.069\"], [\"70366.10\", \"0.000\"], [\"70366.40\", \"0.009\"], [\"70366.50\", \"0.007\"], [\"70366.70\", \"0.014\"], [\"70366.80\", \"0.000\"], [\"70366.90\", \"0.000\"], [\"70367.00\", \"0.008\"], [\"70367.10\", \"2.085\"], [\"70367.20\", \"1.520\"], [\"70367.30\", \"0.836\"], [\"70367.40\", \"0.097\"], [\"70367.50\", \"0.000\"], [\"70367.60\", \"0.004\"], [\"70367.70\", \"0.523\"], [\"70367.80\", \"0.765\"], [\"70367.90\", \"0.001\"], [\"70368.00\", \"0.003\"], [\"70368.10\", \"1.105\"], [\"70368.20\", \"0.016\"], [\"70368.30\", \"1.011\"], [\"70368.40\", \"0.185\"], [\"70368.50\", \"0.030\"], [\"70368.60\", \"0.257\"], [\"70368.70\", \"0.005\"], [\"70368.80\", \"0.179\"], [\"70368.90\", \"0.319\"], [\"70369.10\", \"0.000\"], [\"70369.20\", \"0.000\"], [\"70369.30\", \"0.418\"], [\"70369.60\", \"0.447\"], [\"70369.70\", \"0.526\"], [\"70369.80\", \"0.028\"], [\"70369.90\", \"0.001\"], [\"70370.00\", \"9.198\"], [\"70370.10\", \"2.336\"], [\"70370.20\", \"0.059\"], [\"70370.30\", \"0.313\"], [\"70370.40\", \"8.975\"], [\"70370.50\", \"4.263\"], [\"70370.80\", \"0.853\"], [\"70370.90\", \"1.540\"], [\"70371.00\", \"0.088\"], [\"70371.10\", \"3.671\"], [\"70371.20\", \"0.073\"], [\"70371.40\", \"0.073\"], [\"70372.00\", \"3.510\"], [\"70372.40\", \"3.959\"]], \"a\": [[\"70367.20\", \"0.000\"], [\"70367.30\", \"0.000\"], [\"70367.40\", \"0.000\"], [\"70367.50\", \"0.000\"], [\"70367.60\", \"0.000\"], [\"70367.70\", \"0.000\"], [\"70367.80\", \"0.000\"], [\"70367.90\", \"0.000\"], [\"70368.00\", \"0.000\"], [\"70368.10\", \"0.000\"], [\"70368.30\", \"0.000\"], [\"70368.40\", \"0.000\"], [\"70368.50\", \"0.000\"], [\"70368.60\", \"0.000\"], [\"70368.90\", \"0.000\"], [\"70369.00\", \"0.000\"], [\"70369.20\", \"0.000\"], [\"70369.30\", \"0.000\"], [\"70369.40\", \"0.000\"], [\"70369.70\", \"0.000\"], [\"70369.80\", \"0.000\"], [\"70369.90\", \"0.000\"], [\"70370.00\", \"0.000\"], [\"70370.10\", \"0.000\"], [\"70370.30\", \"0.000\"], [\"70370.40\", \"0.000\"], [\"70370.50\", \"0.000\"], [\"70370.60\", \"0.000\"], [\"70370.90\", \"0.000\"], [\"70371.00\", \"0.000\"], [\"70371.10\", \"0.000\"], [\"70371.20\", \"0.000\"], [\"70371.30\", \"0.000\"], [\"70371.50\", \"0.000\"], [\"70371.60\", \"0.000\"], [\"70371.70\", \"0.000\"], [\"70371.80\", \"0.000\"], [\"70371.90\", \"0.000\"], [\"70372.00\", \"0.000\"], [\"70372.10\", \"0.000\"], [\"70372.20\", \"0.000\"], [\"70372.30\", \"0.000\"], [\"70372.50\", \"0.000\"], [\"70372.80\", \"0.002\"], [\"70373.00\", \"0.006\"], [\"70373.20\", \"0.007\"], [\"70374.20\", \"0.000\"], [\"70374.30\", \"0.000\"], [\"70374.50\", \"0.002\"], [\"70374.60\", \"0.000\"], [\"70375.00\", \"0.001\"], [\"70375.10\", \"0.047\"], [\"70375.40\", \"0.003\"], [\"70375.60\", \"0.006\"], [\"70375.70\", \"0.002\"], [\"70376.20\", \"0.011\"], [\"70376.30\", \"0.001\"], [\"70376.60\", \"0.002\"], [\"70376.70\", \"0.003\"], [\"70376.80\", \"0.008\"], [\"70377.00\", \"0.002\"], [\"70377.10\", \"0.000\"], [\"70377.30\", \"0.006\"], [\"70377.40\", \"0.002\"], [\"70377.80\", \"0.000\"], [\"70378.50\", \"0.003\"], [\"70378.70\", \"0.003\"], [\"70378.90\", \"0.007\"], [\"70379.00\", \"0.001\"], [\"70379.30\", \"0.000\"], [\"70379.40\", \"0.003\"], [\"70379.50\", \"0.005\"], [\"70379.70\", \"0.000\"], [\"70379.90\", \"0.000\"], [\"70380.00\", \"0.011\"], [\"70380.10\", \"0.006\"], [\"70380.30\", \"0.000\"], [\"70380.40\", \"0.001\"], [\"70380.60\", \"0.005\"], [\"70380.70\", \"0.001\"], [\"70380.80\", \"0.002\"], [\"70380.90\", \"0.007\"], [\"70381.40\", \"0.000\"], [\"70381.50\", \"0.438\"], [\"70381.60\", \"0.002\"], [\"70381.70\", \"0.011\"], [\"70381.80\", \"0.000\"], [\"70382.20\", \"0.023\"], [\"70382.40\", \"0.006\"], [\"70382.60\", \"0.002\"], [\"70382.70\", \"0.001\"], [\"70382.80\", \"0.071\"], [\"70382.90\", \"0.062\"], [\"70383.10\", \"0.000\"], [\"70383.50\", \"0.036\"], [\"70383.90\", \"0.488\"], [\"70384.00\", \"0.008\"], [\"70384.20\", \"0.006\"], [\"70384.30\", \"0.000\"], [\"70384.40\", \"0.003\"], [\"70384.50\", \"0.002\"], [\"70384.70\", \"0.405\"], [\"70384.80\", \"0.002\"], [\"70384.90\", \"0.141\"], [\"70385.00\", \"0.271\"], [\"70385.10\", \"0.004\"], [\"70385.20\", \"0.005\"], [\"70385.40\", \"0.011\"], [\"70385.60\", \"0.000\"], [\"70386.10\", \"0.007\"], [\"70386.40\", \"0.102\"], [\"70386.60\", \"0.400\"], [\"70386.80\", \"0.445\"], [\"70386.90\", \"0.162\"], [\"70387.00\", \"0.096\"], [\"70387.10\", \"0.071\"], [\"70387.20\", \"0.005\"], [\"70387.30\", \"0.038\"], [\"70387.40\", \"0.099\"], [\"70387.50\", \"0.003\"], [\"70387.60\", \"0.036\"], [\"70387.70\", \"0.184\"], [\"70387.90\", \"0.006\"], [\"70388.20\", \"0.008\"], [\"70388.30\", \"0.400\"], [\"70388.40\", \"0.342\"], [\"70388.60\", \"0.003\"], [\"70388.70\", \"0.000\"], [\"70388.80\", \"0.159\"], [\"70389.00\", \"0.011\"], [\"70389.20\", \"0.001\"], [\"70389.40\", \"0.050\"], [\"70389.50\", \"0.006\"], [\"70389.60\", \"0.004\"], [\"70389.80\", \"0.001\"], [\"70389.90\", \"0.005\"], [\"70390.00\", \"0.000\"], [\"70390.20\", \"0.002\"], [\"70390.30\", \"0.000\"], [\"70390.40\", \"0.001\"], [\"70390.50\", \"0.401\"], [\"70390.60\", \"0.403\"], [\"70390.80\", \"0.541\"], [\"70390.90\", \"0.005\"], [\"70391.00\", \"0.005\"], [\"70391.20\", \"0.042\"], [\"70391.50\", \"0.000\"], [\"70391.80\", \"0.000\"], [\"70391.90\", \"0.007\"], [\"70392.00\", \"0.005\"], [\"70392.20\", \"0.007\"], [\"70392.30\", \"0.005\"], [\"70392.50\", \"0.070\"], [\"70392.60\", \"0.007\"], [\"70392.70\", \"0.373\"], [\"70392.90\", \"0.003\"], [\"70393.00\", \"0.698\"], [\"70393.10\", \"0.181\"], [\"70393.20\", \"0.002\"], [\"70393.40\", \"0.000\"], [\"70393.70\", \"0.000\"], [\"70393.80\", \"0.007\"], [\"70394.00\", \"0.205\"], [\"70394.20\", \"0.000\"], [\"70394.70\", \"1.066\"], [\"70394.80\", \"0.013\"], [\"70394.90\", \"0.000\"], [\"70395.00\", \"0.218\"], [\"70395.10\", \"0.088\"], [\"70395.20\", \"0.031\"], [\"70395.30\", \"0.002\"], [\"70395.50\", \"0.344\"], [\"70395.70\", \"0.000\"], [\"70396.00\", \"0.020\"], [\"70396.30\", \"0.002\"], [\"70396.60\", \"0.004\"], [\"70396.80\", \"0.003\"], [\"70397.00\", \"0.004\"], [\"70397.20\", \"0.000\"], [\"70397.40\", \"0.003\"], [\"70397.50\", \"0.928\"], [\"70397.60\", \"0.069\"], [\"70398.30\", \"0.375\"], [\"70398.40\", \"0.192\"], [\"70398.70\", \"0.000\"], [\"70398.90\", \"0.010\"], [\"70399.10\", \"0.512\"], [\"70399.20\", \"0.612\"], [\"70399.30\", \"0.009\"], [\"70399.40\", \"0.219\"], [\"70399.50\", \"0.020\"], [\"70399.90\", \"0.009\"], [\"70400.00\", \"2.036\"], [\"70400.40\", \"0.005\"], [\"70401.80\", \"0.000\"], [\"70401.90\", \"0.045\"], [\"70402.30\", \"0.005\"], [\"70402.50\", \"0.010\"], [\"70402.60\", \"0.006\"], [\"70402.80\", \"0.002\"], [\"70403.00\", \"0.431\"], [\"70403.20\", \"0.000\"], [\"70403.30\", \"0.228\"], [\"70403.90\", \"0.009\"], [\"70404.00\", \"0.395\"], [\"70404.50\", \"0.123\"], [\"70404.60\", \"0.016\"], [\"70404.70\", \"0.000\"], [\"70405.30\", \"0.004\"], [\"70405.40\", \"0.056\"], [\"70406.00\", \"1.082\"], [\"70406.10\", \"0.002\"], [\"70407.50\", \"0.002\"], [\"70408.50\", \"0.022\"], [\"70408.80\", \"0.003\"], [\"70408.90\", \"0.002\"], [\"70409.50\", \"0.963\"], [\"70409.60\", \"0.002\"], [\"70409.70\", \"0.000\"], [\"70409.80\", \"0.003\"], [\"70409.90\", \"2.017\"], [\"70410.00\", \"0.011\"], [\"70410.20\", \"0.000\"], [\"70410.30\", \"0.000\"], [\"70410.40\", \"0.082\"], [\"70410.90\", \"0.004\"], [\"70411.00\", \"0.002\"], [\"70411.80\", \"0.007\"], [\"70413.40\", \"0.344\"], [\"70413.50\", \"0.058\"], [\"70413.90\", \"0.018\"], [\"70414.60\", \"0.000\"], [\"70415.10\", \"0.584\"], [\"70415.40\", \"0.513\"], [\"70416.20\", \"0.002\"], [\"70417.00\", \"0.001\"], [\"70417.20\", \"0.000\"], [\"70417.70\", \"0.000\"], [\"70418.60\", \"0.003\"], [\"70420.00\", \"1.178\"], [\"70421.30\", \"0.001\"], [\"70421.90\", \"0.004\"], [\"70422.00\", \"2.826\"], [\"70422.70\", \"0.196\"], [\"70423.00\", \"0.019\"], [\"70423.10\", \"0.000\"], [\"70423.50\", \"0.002\"], [\"70424.60\", \"0.051\"], [\"70426.80\", \"0.193\"], [\"70427.00\", \"0.004\"], [\"70427.20\", \"2.237\"], [\"70427.80\", \"10.419\"], [\"70428.10\", \"0.164\"], [\"70428.50\", \"0.005\"], [\"70428.70\", \"0.003\"], [\"70428.80\", \"0.000\"], [\"70428.90\", \"0.001\"], [\"70429.40\", \"0.128\"], [\"70430.30\", \"0.080\"], [\"70431.30\", \"0.000\"], [\"70431.80\", \"0.049\"], [\"70432.50\", \"0.000\"], [\"70434.00\", \"0.008\"], [\"70434.50\", \"0.554\"], [\"70434.70\", \"0.243\"], [\"70436.10\", \"0.006\"], [\"70436.40\", \"0.082\"], [\"70436.80\", \"0.513\"], [\"70437.10\", \"0.000\"], [\"70437.20\", \"0.000\"], [\"70437.30\", \"0.241\"], [\"70437.50\", \"0.663\"], [\"70437.60\", \"1.004\"], [\"70437.90\", \"0.043\"], [\"70438.00\", \"0.000\"], [\"70438.70\", \"0.574\"], [\"70440.50\", \"0.131\"], [\"70441.10\", \"0.102\"], [\"70442.00\", \"0.600\"], [\"70442.20\", \"0.084\"], [\"70442.60\", \"0.081\"], [\"70442.90\", \"0.000\"], [\"70443.00\", \"0.004\"], [\"70443.20\", \"1.856\"], [\"70444.40\", \"0.053\"], [\"70444.60\", \"0.047\"], [\"70445.60\", \"0.001\"], [\"70446.20\", \"0.007\"], [\"70449.30\", \"0.002\"], [\"70449.80\", \"0.002\"], [\"70450.90\", \"0.004\"], [\"70451.00\", \"0.216\"], [\"70452.50\", \"0.170\"], [\"70452.70\", \"0.191\"], [\"70453.50\", \"0.000\"], [\"70457.70\", \"0.000\"], [\"70460.10\", \"0.000\"], [\"70460.20\", \"0.082\"], [\"70460.40\", \"1.070\"], [\"70460.60\", \"0.010\"], [\"70460.70\", \"0.007\"], [\"70463.10\", \"0.019\"], [\"70468.60\", \"0.056\"], [\"70470.40\", \"0.043\"], [\"70471.50\", \"0.348\"], [\"70471.80\", \"0.590\"], [\"70472.80\", \"0.151\"], [\"70473.60\", \"0.050\"], [\"70475.30\", \"0.002\"], [\"70479.40\", \"0.513\"], [\"70479.90\", \"0.176\"], [\"70480.50\", \"0.008\"], [\"70480.60\", \"3.608\"], [\"70481.20\", \"0.017\"], [\"70482.20\", \"0.000\"], [\"70484.90\", \"0.000\"], [\"70485.10\", \"0.332\"], [\"70486.60\", \"0.552\"], [\"70487.20\", \"0.031\"], [\"70488.50\", \"0.002\"], [\"70491.10\", \"0.447\"], [\"70498.70\", \"0.259\"], [\"70503.10\", \"0.273\"], [\"70504.90\", \"0.578\"], [\"70506.90\", \"0.025\"], [\"70510.30\", \"0.186\"], [\"70513.90\", \"0.207\"], [\"70517.50\", \"0.189\"], [\"70517.90\", \"0.000\"], [\"70518.90\", \"0.322\"], [\"70520.20\", \"0.007\"], [\"70520.70\", \"0.011\"], [\"70521.10\", \"0.186\"], [\"70524.50\", \"0.000\"], [\"70524.70\", \"0.186\"], [\"70527.20\", \"0.007\"], [\"70528.40\", \"8.267\"], [\"70528.50\", \"0.122\"], [\"70529.60\", \"0.000\"], [\"70531.50\", \"0.079\"], [\"70534.20\", \"0.127\"], [\"70537.40\", \"0.002\"], [\"70537.90\", \"0.000\"], [\"70538.50\", \"0.017\"], [\"70541.20\", \"6.516\"], [\"70545.40\", \"0.085\"], [\"70545.50\", \"0.000\"], [\"70546.00\", \"0.715\"], [\"70546.20\", \"0.082\"], [\"70547.00\", \"0.039\"], [\"70547.20\", \"1.634\"], [\"70547.60\", \"0.082\"], [\"70548.20\", \"0.011\"], [\"70550.20\", \"0.082\"], [\"70552.50\", \"0.000\"], [\"70554.80\", \"0.082\"], [\"70555.20\", \"1.149\"], [\"70559.50\", \"0.000\"], [\"70559.80\", \"0.084\"], [\"70560.50\", \"0.000\"], [\"70562.20\", \"0.007\"], [\"70564.60\", \"0.007\"], [\"70566.00\", \"0.043\"], [\"70566.50\", \"0.008\"], [\"70569.20\", \"0.017\"], [\"70570.80\", \"1.524\"], [\"70573.60\", \"10.003\"], [\"70576.80\", \"0.530\"], [\"70580.00\", \"0.007\"], [\"70602.10\", \"0.755\"], [\"70602.40\", \"0.031\"], [\"70635.00\", \"0.006\"], [\"70635.70\", \"0.002\"], [\"70667.40\", \"0.188\"], [\"70679.40\", \"1.015\"], [\"70679.50\", \"6.496\"], [\"70679.90\", \"0.000\"], [\"70852.80\", \"0.002\"], [\"70886.10\", \"0.000\"], [\"70895.00\", \"0.774\"], [\"70898.60\", \"0.003\"], [\"70898.70\", \"0.000\"], [\"71015.00\", \"0.002\"], [\"71050.20\", \"0.009\"], [\"71070.90\", \"2.859\"], [\"71074.10\", \"0.000\"], [\"71434.70\", \"0.000\"], [\"75940.80\", \"0.000\"], [\"76117.00\", \"0.050\"], [\"76293.20\", \"0.000\"], [\"76469.40\", \"0.000\"], [\"89523.20\", \"0.000\"]]}", "symbol": "BTCUSDT"}
{"event": "depthUpdate", "raw_payload": "{\"e\": \"depthUpdate\", \"E\": 1773246394654, \"T\": 1773246394653, \"s\": \"BTCUSDT\", \"U\": 10089704633142, \"u\": 10089704658903, \"pu\": 10089704633121, \"b\": [[\"5000.00\", \"101.418\"], [\"19867.10\", \"0.120\"], [\"20072.70\", \"0.040\"], [\"20072.80\", \"0.010\"], [\"20073.30\", \"0.070\"], [\"20074.80\", \"0.040\"], [\"20167.10\", \"0.890\"], [\"20270.40\", \"0.010\"], [\"20272.70\", \"0.020\"], [\"20273.30\", \"0.030\"], [\"20274.80\", \"0.030\"], [\"56294.00\", \"0.000\"], [\"56295.00\", \"0.000\"], [\"66830.40\", \"0.000\"], [\"68959.80\", \"0.010\"], [\"68965.10\", \"0.006\"], [\"69362.60\", \"0.000\"], [\"69363.20\", \"0.000\"], [\"69364.80\", \"0.287\"], [\"69365.90\", \"0.000\"], [\"69366.10\", \"0.722\"], [\"69367.10\", \"0.000\"], [\"69368.20\", \"0.000\"], [\"69370.00\", \"0.014\"], [\"69370.30\", \"1.585\"], [\"69370.40\", \"0.002\"], [\"69372.70\", \"0.030\"], [\"69372.90\", \"1.358\"], [\"69373.30\", \"0.034\"], [\"69374.80\", \"0.722\"], [\"69671.10\", \"0.000\"], [\"69881.50\", \"0.010\"], [\"69888.00\", \"1.739\"], [\"69900.00\", \"9.090\"], [\"69952.00\", \"0.000\"], [\"69952.10\", \"0.008\"], [\"69968.10\", \"0.125\"], [\"69987.60\", \"0.114\"], [\"69991.60\", \"0.008\"], [\"69997.70\", \"0.454\"], [\"69999.10\", \"0.175\"], [\"70003.30\", \"0.000\"], [\"70004.20\", \"0.002\"], [\"70015.30\", \"0.044\"], [\"70017.10\", \"0.000\"], [\"70050.90\", \"0.060\"], [\"70062.80\", \"0.000\"], [\"70063.50\", \"0.000\"], [\"70064.80\", \"0.037\"], [\"70071.30\", \"0.000\"], [\"70072.40\", \"0.032\"], [\"70083.10\", \"1.598\"], [\"70083.90\", \"0.616\"], [\"70110.10\", \"0.000\"], [\"70133.00\", \"4.822\"], [\"70153.20\", \"0.000\"], [\"70154.30\", \"0.067\"], [\"70156.50\", \"0.201\"], [\"70159.70\", \"0.013\"], [\"70166.10\", \"0.062\"], [\"70168.90\", \"0.208\"], [\"70172.40\", \"6.543\"], [\"70175.30\", \"0.000\"], [\"70177.40\", \"0.008\"], [\"70178.20\", \"0.265\"], [\"70180.90\", \"0.000\"], [\"70196.70\", \"0.058\"], [\"70197.60\", \"0.288\"], [\"70199.00\", \"0.000\"], [\"70204.60\", \"2.319\"], [\"70215.10\", \"0.126\"], [\"70221.60\", \"0.082\"], [\"70228.60\", \"0.000\"], [\"70228.70\", \"0.000\"], [\"70230.10\", \"0.345\"], [\"70232.10\", \"0.323\"], [\"70234.70\", \"0.000\"], [\"70238.70\", \"0.000\"], [\"70240.70\", \"0.000\"], [\"70244.60\", \"0.000\"], [\"70244.90\", \"1.066\"], [\"70245.50\", \"0.042\"], [\"70247.50\", \"0.061\"], [\"70248.00\", \"0.428\"], [\"70252.50\", \"0.010\"], [\"70254.60\", \"0.079\"], [\"70256.10\", \"0.088\"], [\"70257.80\", \"0.156\"], [\"70258.20\", \"0.001\"], [\"70258.90\", \"6.563\"], [\"70260.60\", \"0.628\"], [\"70262.50\", \"0.571\"], [\"70262.70\", \"0.128\"], [\"70263.00\", \"0.156\"], [\"70263.90\", \"0.780\"], [\"70264.10\", \"0.018\"], [\"70265.50\", \"0.009\"], [\"70268.80\", \"0.545\"], [\"70271.90\", \"0.006\"], [\"70272.20\", \"0.000\"], [\"70272.70\", \"0.108\"], [\"70273.80\", \"0.227\"], [\"70274.10\", \"0.000\"], [\"70274.20\", \"0.088\"], [\"70274.70\", \"0.000\"], [\"70275.40\", \"0.232\"], [\"70275.90\", \"0.000\"], [\"70276.00\", \"0.002\"], [\"70276.40\", \"0.000\"], [\"70278.90\", \"0.220\"], [\"70279.00\", \"0.364\"], [\"70279.10\", \"0.201\"], [\"70279.30\", \"0.004\"], [\"70281.80\", \"1.500\"], [\"70282.50\", \"0.053\"], [\"70284.20\", \"0.034\"], [\"70285.40\", \"0.016\"], [\"70287.00\", \"0.752\"], [\"70287.70\", \"0.409\"], [\"70288.30\", \"0.268\"], [\"70288.80\", \"0.621\"], [\"70288.90\", \"0.144\"], [\"70291.20\", \"0.114\"], [\"70292.80\", \"0.073\"], [\"70293.10\", \"1.345\"], [\"70294.20\", \"0.045\"], [\"70295.20\", \"0.021\"], [\"70295.80\", \"0.131\"], [\"70295.90\", \"1.002\"], [\"70296.80\", \"0.466\"], [\"70299.90\", \"0.000\"], [\"70300.00\", \"1.478\"], [\"70300.40\", \"0.007\"], [\"70300.50\", \"1.066\"], [\"70301.20\", \"3.605\"], [\"70302.80\", \"0.000\"], [\"70302.90\", \"0.021\"], [\"70303.10\", \"0.011\"], [\"70304.10\", \"0.106\"], [\"70304.90\", \"0.156\"], [\"70305.40\", \"0.003\"], [\"70305.50\", \"0.451\"], [\"70306.40\", \"0.000\"], [\"70306.50\", \"0.018\"], [\"70306.70\", \"0.029\"], [\"70307.20\", \"0.000\"], [\"70307.40\", \"0.002\"], [\"70307.80\", \"1.163\"], [\"70307.90\", \"0.171\"], [\"70310.00\", \"0.084\"], [\"70310.30\", \"0.008\"], [\"70310.50\", \"0.000\"], [\"70310.70\", \"0.581\"], [\"70310.90\", \"0.005\"], [\"70311.30\", \"0.750\"], [\"70311.40\", \"0.095\"], [\"70311.90\", \"0.000\"], [\"70312.20\", \"0.000\"], [\"70312.60\", \"0.000\"], [\"70312.70\", \"0.271\"], [\"70312.90\", \"1.128\"], [\"70313.00\", \"0.584\"], [\"70313.10\", \"0.228\"], [\"70313.50\", \"0.111\"], [\"70314.30\", \"0.437\"], [\"70314.80\", \"0.000\"], [\"70315.00\", \"0.002\"], [\"70315.10\", \"0.002\"], [\"70316.00\", \"0.342\"], [\"70316.10\", \"0.190\"], [\"70316.70\", \"0.007\"], [\"70317.00\", \"0.010\"], [\"70317.40\", \"1.071\"], [\"70317.50\", \"0.200\"], [\"70317.60\", \"0.516\"], [\"70317.70\", \"0.008\"], [\"70318.00\", \"0.043\"], [\"70318.30\", \"0.408\"], [\"70318.50\", \"0.720\"], [\"70318.80\", \"0.013\"], [\"70318.90\", \"0.237\"], [\"70319.10\", \"0.138\"], [\"70319.80\", \"0.583\"], [\"70320.10\", \"0.112\"], [\"70320.70\", \"0.223\"], [\"70320.80\", \"0.005\"], [\"70321.30\", \"0.035\"], [\"70321.50\", \"0.006\"], [\"70321.60\", \"0.006\"], [\"70321.70\", \"0.002\"], [\"70321.80\", \"0.493\"], [\"70321.90\", \"0.002\"], [\"70322.00\", \"0.006\"], [\"70322.20\", \"0.000\"], [\"70322.30\", \"0.692\"], [\"70322.40\", \"0.000\"], [\"70323.00\", \"0.008\"], [\"70323.10\", \"1.420\"], [\"70323.70\", \"0.002\"], [\"70324.00\", \"0.004\"], [\"70324.80\", \"0.019\"], [\"70324.90\", \"2.928\"], [\"70325.50\", \"0.168\"], [\"70325.60\", \"0.214\"], [\"70326.20\", \"0.000\"], [\"70327.30\", \"0.000\"], [\"70327.60\", \"0.000\"], [\"70327.70\", \"0.013\"], [\"70328.00\", \"0.006\"], [\"70328.10\", \"0.002\"], [\"70328.30\", \"0.005\"], [\"70328.50\", \"0.753\"], [\"70328.60\", \"0.529\"], [\"70328.70\", \"0.002\"], [\"70329.10\", \"0.366\"], [\"70329.30\", \"0.000\"], [\"70329.40\", \"0.000\"], [\"70329.80\", \"0.013\"], [\"70330.10\", \"1.084\"], [\"70330.20\", \"0.000\"], [\"70330.80\", \"0.280\"], [\"70330.90\", \"0.000\"], [\"70331.10\", \"0.000\"], [\"70331.30\", \"0.035\"], [\"70331.70\", \"0.000\"], [\"70332.10\", \"0.294\"], [\"70332.20\", \"0.009\"], [\"70332.40\", \"0.092\"], [\"70332.50\", \"0.822\"], [\"70332.60\", \"0.062\"], [\"70332.90\", \"0.003\"], [\"70333.00\", \"0.004\"], [\"70333.20\", \"2.075\"], [\"70334.00\", \"0.003\"], [\"70335.00\", \"0.008\"], [\"70335.20\", \"0.350\"], [\"70335.30\", \"0.002\"], [\"70335.70\", \"0.005\"], [\"70336.50\", \"0.004\"], [\"70336.70\", \"0.005\"], [\"70337.10\", \"1.066\"], [\"70337.80\", \"0.205\"], [\"70338.20\", \"0.000\"], [\"70338.30\", \"0.000\"], [\"70338.70\", \"0.006\"], [\"70338.80\", \"0.008\"], [\"70339.10\", \"0.018\"], [\"70339.40\", \"0.002\"], [\"70339.50\", \"0.002\"], [\"70339.60\", \"0.780\"], [\"70339.80\", \"0.033\"], [\"70340.10\", \"0.002\"], [\"70340.20\", \"0.000\"], [\"70340.30\", \"0.001\"], [\"70340.80\", \"0.004\"], [\"70340.90\", \"0.013\"], [\"70341.20\", \"0.017\"], [\"70341.50\", \"0.024\"], [\"70341.60\", \"0.027\"], [\"70341.70\", \"10.230\"], [\"70341.90\", \"0.534\"], [\"70342.20\", \"0.000\"], [\"70342.30\", \"0.243\"], [\"70342.40\", \"0.193\"], [\"70342.60\", \"0.379\"], [\"70342.90\", \"1.448\"], [\"70343.00\", \"2.101\"], [\"70343.20\", \"0.010\"], [\"70343.40\", \"0.000\"], [\"70343.50\", \"0.000\"], [\"70343.60\", \"0.003\"], [\"70343.70\", \"0.005\"], [\"70343.80\", \"0.002\"], [\"70344.30\", \"0.013\"], [\"70344.40\", \"0.195\"], [\"70344.60\", \"0.004\"], [\"70344.80\", \"0.251\"], [\"70344.90\", \"0.011\"], [\"70345.00\", \"0.209\"], [\"70345.10\", \"0.002\"], [\"70345.30\", \"0.000\"], [\"70345.60\", \"0.002\"], [\"70345.70\", \"0.002\"], [\"70345.80\", \"0.005\"], [\"70346.20\", \"0.442\"], [\"70346.40\", \"0.000\"], [\"70346.50\", \"0.002\"], [\"70347.10\", \"0.006\"], [\"70347.20\", \"0.030\"], [\"70347.30\", \"0.059\"], [\"70347.80\", \"0.002\"], [\"70347.90\", \"0.002\"], [\"70348.00\", \"0.006\"], [\"70348.10\", \"0.010\"], [\"70348.20\", \"0.369\"], [\"70348.30\", \"0.000\"], [\"70348.70\", \"0.231\"], [\"70349.00\", \"0.013\"], [\"70349.20\", \"0.001\"], [\"70349.40\", \"0.578\"], [\"70349.50\", \"1.070\"], [\"70350.00\", \"0.010\"], [\"70350.10\", \"0.010\"], [\"70350.20\", \"0.013\"], [\"70350.40\", \"0.007\"], [\"70351.00\", \"0.047\"], [\"70351.20\", \"0.005\"], [\"70351.30\", \"0.007\"], [\"70351.40\", \"0.037\"], [\"70351.50\", \"0.000\"], [\"70351.60\", \"0.074\"], [\"70351.70\", \"0.000\"], [\"70351.90\", \"0.008\"], [\"70352.10\", \"0.001\"], [\"70352.30\", \"0.052\"], [\"70352.40\", \"0.000\"], [\"70352.70\", \"0.314\"], [\"70353.00\", \"0.451\"], [\"70353.10\", \"0.466\"], [\"70353.50\", \"0.008\"], [\"70353.60\", \"0.624\"], [\"70353.70\", \"0.087\"], [\"70353.90\", \"0.201\"], [\"70354.00\", \"0.002\"], [\"70354.10\", \"0.038\"], [\"70354.40\", \"0.016\"], [\"70354.80\", \"0.002\"], [\"70355.00\", \"0.039\"], [\"70355.10\", \"0.551\"], [\"70355.20\", \"1.128\"], [\"70355.70\", \"0.008\"], [\"70355.80\", \"0.000\"], [\"70355.90\", \"0.000\"], [\"70356.10\", \"0.521\"], [\"70356.50\", \"0.624\"], [\"70357.40\", \"0.653\"], [\"70357.50\", \"0.010\"], [\"70357.60\", \"0.000\"], [\"70357.70\", \"0.042\"], [\"70358.00\", \"0.002\"], [\"70358.20\", \"0.033\"], [\"70358.50\", \"0.006\"], [\"70358.60\", \"0.074\"], [\"70358.70\", \"0.260\"], [\"70358.80\", \"0.002\"], [\"70358.90\", \"0.002\"], [\"70359.20\", \"0.115\"], [\"70359.40\", \"0.041\"], [\"70359.50\", \"0.040\"], [\"70359.60\", \"0.139\"], [\"70359.70\", \"0.000\"], [\"70359.80\", \"0.002\"], [\"70359.90\", \"0.263\"], [\"70360.00\", \"0.006\"], [\"70360.10\", \"0.000\"], [\"70360.30\", \"0.246\"], [\"70360.40\", \"0.009\"], [\"70360.50\", \"0.734\"], [\"70360.60\", \"0.487\"], [\"70360.70\", \"0.002\"], [\"70360.80\", \"0.008\"], [\"70360.90\", \"1.459\"], [\"70361.00\", \"0.513\"], [\"70361.10\", \"0.002\"], [\"70361.20\", \"0.002\"], [\"70361.30\", \"0.002\"], [\"70361.40\", \"0.000\"], [\"70361.50\", \"0.005\"], [\"70361.80\", \"0.002\"], [\"70361.90\", \"0.000\"], [\"70362.00\", \"0.336\"], [\"70362.10\", \"0.225\"], [\"70362.20\", \"0.011\"], [\"70362.40\", \"0.011\"], [\"70362.50\", \"0.105\"], [\"70362.70\", \"0.003\"], [\"70362.80\", \"0.001\"], [\"70363.00\", \"0.002\"], [\"70363.10\", \"0.006\"], [\"70363.30\", \"0.007\"], [\"70363.40\", \"0.000\"], [\"70363.60\", \"0.643\"], [\"70363.70\", \"1.207\"], [\"70363.80\", \"0.029\"], [\"70364.00\", \"0.009\"], [\"70364.10\", \"0.001\"], [\"70364.20\", \"0.002\"], [\"70364.30\", \"0.485\"], [\"70364.90\", \"0.000\"], [\"70365.00\", \"0.022\"], [\"70365.10\", \"0.040\"], [\"70365.20\", \"0.004\"], [\"70365.50\", \"0.001\"], [\"70365.60\", \"0.005\"], [\"70365.70\", \"0.000\"], [\"70365.80\", \"0.001\"], [\"70365.90\", \"0.261\"], [\"70366.00\", \"0.224\"], [\"70366.10\", \"0.000\"], [\"70366.20\", \"0.000\"], [\"70366.30\", \"0.000\"], [\"70366.40\", \"0.351\"], [\"70366.50\", \"0.001\"], [\"70366.60\", \"0.000\"], [\"70366.70\", \"0.014\"], [\"70367.00\", \"0.008\"], [\"70367.10\", \"1.267\"], [\"70367.20\", \"0.078\"], [\"70367.30\", \"0.450\"], [\"70367.40\", \"0.045\"], [\"70367.50\", \"0.187\"], [\"70367.70\", \"0.525\"], [\"70367.80\", \"0.494\"], [\"70367.90\", \"0.004\"], [\"70368.00\", \"0.026\"], [\"70368.10\", \"0.009\"], [\"70368.20\", \"0.016\"], [\"70368.30\", \"0.006\"], [\"70368.40\", \"0.001\"], [\"70368.50\", \"0.002\"], [\"70368.60\", \"0.000\"], [\"70368.70\", \"0.034\"], [\"70368.80\", \"0.000\"], [\"70368.90\", \"0.000\"], [\"70369.10\", \"0.001\"], [\"70369.20\", \"0.003\"], [\"70369.30\", \"0.000\"], [\"70369.50\", \"0.090\"], [\"70369.60\", \"0.001\"], [\"70369.70\", \"0.059\"], [\"70369.80\", \"0.000\"], [\"70369.90\", \"0.000\"], [\"70370.00\", \"0.462\"], [\"70370.10\", \"0.481\"], [\"70370.20\", \"0.000\"], [\"70370.30\", \"0.041\"], [\"70370.40\", \"0.308\"], [\"70370.50\", \"0.304\"], [\"70370.60\", \"0.459\"], [\"70370.70\", \"0.000\"], [\"70370.80\", \"0.000\"], [\"70370.90\", \"0.002\"], [\"70371.00\", \"0.002\"], [\"70371.10\", \"0.003\"], [\"70371.20\", \"0.002\"], [\"70371.30\", \"0.001\"], [\"70371.40\", \"0.047\"], [\"70371.50\", \"0.000\"], [\"70371.60\", \"0.002\"], [\"70371.70\", \"0.000\"], [\"70371.90\", \"0.002\"], [\"70372.00\", \"0.002\"], [\"70372.10\", \"0.097\"], [\"70372.20\", \"0.000\"], [\"70372.30\", \"0.000\"], [\"70372.40\", \"0.003\"], [\"70372.50\", \"0.000\"], [\"70372.60\", \"0.058\"], [\"70372.70\", \"0.301\"], [\"70372.80\", \"1.275\"], [\"70372.90\", \"0.344\"], [\"70373.00\", \"1.400\"], [\"70373.10\", \"0.003\"], [\"70373.20\", \"0.003\"], [\"70373.30\", \"0.022\"], [\"70373.40\", \"1.100\"], [\"70373.50\", \"0.852\"], [\"70374.00\", \"0.090\"], [\"70374.10\", \"0.002\"], [\"70374.60\", \"0.000\"], [\"70374.70\", \"0.130\"], [\"70374.80\", \"7.070\"], [\"70374.90\", \"3.285\"], [\"70375.00\", \"4.649\"], [\"70375.40\", \"2.628\"], [\"70375.50\", \"1.373\"], [\"70375.70\", \"0.610\"], [\"70376.10\", \"3.636\"]], \"a\": [[\"70372.70\", \"0.000\"], [\"70372.80\", \"0.000\"], [\"70372.90\", \"0.000\"], [\"70373.00\", \"0.000\"], [\"70373.20\", \"0.000\"], [\"70373.30\", \"0.000\"], [\"70373.40\", \"0.000\"], [\"70373.70\", \"0.000\"], [\"70373.80\", \"0.000\"], [\"70373.90\", \"0.000\"], [\"70374.10\", \"0.000\"], [\"70374.40\", \"0.000\"], [\"70374.50\", \"0.000\"], [\"70374.70\", \"0.000\"], [\"70374.80\", \"0.000\"], [\"70374.90\", \"0.000\"], [\"70375.00\", \"0.000\"], [\"70375.10\", \"0.000\"], [\"70375.40\", \"0.000\"], [\"70375.50\", \"0.000\"], [\"70375.60\", \"0.000\"], [\"70375.70\", \"0.000\"], [\"70375.80\", \"0.000\"], [\"70375.90\", \"0.000\"], [\"70376.10\", \"0.000\"], [\"70376.20\", \"0.009\"], [\"70376.30\", \"0.000\"], [\"70376.50\", \"0.002\"], [\"70377.30\", \"0.004\"], [\"70378.00\", \"0.001\"], [\"70378.10\", \"0.000\"], [\"70378.40\", \"0.004\"], [\"70378.60\", \"0.002\"], [\"70378.70\", \"0.000\"], [\"70378.80\", \"0.007\"], [\"70378.90\", \"0.003\"], [\"70379.00\", \"0.001\"], [\"70379.10\", \"0.000\"], [\"70379.50\", \"0.005\"], [\"70379.80\", \"0.039\"], [\"70380.00\", \"0.312\"], [\"70380.20\", \"0.000\"], [\"70380.40\", \"0.001\"], [\"70380.50\", \"0.096\"], [\"70380.70\", \"0.001\"], [\"70380.90\", \"0.007\"], [\"70381.00\", \"0.003\"], [\"70381.10\", \"0.000\"], [\"70381.40\", \"0.002\"], [\"70381.50\", \"0.002\"], [\"70381.70\", \"0.006\"], [\"70381.90\", \"0.000\"], [\"70382.00\", \"0.006\"], [\"70382.20\", \"0.002\"], [\"70382.40\", \"0.014\"], [\"70382.70\", \"0.016\"], [\"70382.80\", \"0.000\"], [\"70382.90\", \"0.002\"], [\"70383.20\", \"0.001\"], [\"70383.40\", \"0.002\"], [\"70383.50\", \"0.074\"], [\"70383.60\", \"0.007\"], [\"70383.70\", \"0.059\"], [\"70383.80\", \"0.436\"], [\"70383.90\", \"0.431\"], [\"70384.00\", \"0.005\"], [\"70384.10\", \"0.002\"], [\"70384.20\", \"0.006\"], [\"70384.30\", \"0.001\"], [\"70384.70\", \"0.004\"], [\"70384.80\", \"0.002\"], [\"70384.90\", \"0.428\"], [\"70385.00\", \"0.034\"], [\"70385.10\", \"0.005\"], [\"70385.20\", \"0.002\"], [\"70385.30\", \"0.008\"], [\"70385.40\", \"0.011\"], [\"70385.50\", \"0.000\"], [\"70385.60\", \"0.002\"], [\"70385.70\", \"0.003\"], [\"70385.90\", \"0.000\"], [\"70386.10\", \"0.006\"], [\"70386.30\", \"0.003\"], [\"70386.40\", \"0.000\"], [\"70386.60\", \"0.398\"], [\"70386.70\", \"0.004\"], [\"70386.80\", \"0.047\"], [\"70386.90\", \"0.000\"], [\"70387.00\", \"0.009\"], [\"70387.10\", \"0.000\"], [\"70387.20\", \"0.003\"], [\"70387.30\", \"0.002\"], [\"70387.40\", \"0.003\"], [\"70387.60\", \"0.000\"], [\"70387.70\", \"0.002\"], [\"70387.90\", \"0.004\"], [\"70388.10\", \"0.000\"], [\"70388.20\", \"0.008\"], [\"70388.30\", \"0.400\"], [\"70388.40\", \"0.000\"], [\"70388.80\", \"0.092\"], [\"70389.00\", \"0.009\"], [\"70389.10\", \"0.002\"], [\"70389.20\", \"0.003\"], [\"70389.40\", \"0.003\"], [\"70389.50\", \"0.004\"], [\"70389.70\", \"0.000\"], [\"70389.90\", \"0.000\"], [\"70390.00\", \"0.002\"], [\"70390.20\", \"0.029\"], [\"70390.30\", \"0.002\"], [\"70390.40\", \"0.001\"], [\"70390.50\", \"0.003\"], [\"70390.60\", \"0.005\"], [\"70390.70\", \"0.347\"], [\"70390.80\", \"0.000\"], [\"70391.00\", \"0.005\"], [\"70391.20\", \"0.040\"], [\"70391.30\", \"0.002\"], [\"70391.60\", \"0.039\"], [\"70391.70\", \"0.036\"], [\"70391.80\", \"0.000\"], [\"70391.90\", \"0.038\"], [\"70392.00\", \"0.041\"], [\"70392.10\", \"0.005\"], [\"70392.40\", \"0.009\"], [\"70392.50\", \"0.143\"], [\"70392.60\", \"1.073\"], [\"70392.70\", \"0.002\"], [\"70392.80\", \"0.324\"], [\"70393.00\", \"0.006\"], [\"70393.10\", \"0.000\"], [\"70393.50\", \"0.003\"], [\"70393.60\", \"0.002\"], [\"70394.10\", \"0.572\"], [\"70394.30\", \"0.052\"], [\"70394.60\", \"0.266\"], [\"70394.70\", \"0.000\"], [\"70394.80\", \"0.006\"], [\"70394.90\", \"0.003\"], [\"70395.00\", \"0.220\"], [\"70395.10\", \"0.116\"], [\"70395.20\", \"0.101\"], [\"70395.30\", \"0.641\"], [\"70395.40\", \"0.196\"], [\"70395.50\", \"0.002\"], [\"70396.30\", \"0.513\"], [\"70396.40\", \"0.345\"], [\"70396.80\", \"0.001\"], [\"70397.00\", \"0.002\"], [\"70397.20\", \"0.000\"], [\"70397.30\", \"0.000\"], [\"70397.40\", \"0.145\"], [\"70397.50\", \"0.672\"], [\"70397.60\", \"0.069\"], [\"70397.70\", \"0.002\"], [\"70397.80\", \"0.002\"], [\"70398.20\", \"0.284\"], [\"70398.30\", \"0.375\"], [\"70398.40\", \"0.006\"], [\"70398.60\", \"0.002\"], [\"70398.70\", \"0.699\"], [\"70398.80\", \"0.099\"], [\"70398.90\", \"0.005\"], [\"70399.00\", \"0.004\"], [\"70399.10\", \"0.001\"], [\"70399.30\", \"0.009\"], [\"70399.40\", \"0.044\"], [\"70399.50\", \"0.000\"], [\"70399.80\", \"0.002\"], [\"70399.90\", \"1.068\"], [\"70400.00\", \"2.073\"], [\"70400.10\", \"0.004\"], [\"70400.30\", \"0.184\"], [\"70401.00\", \"0.016\"], [\"70401.40\", \"0.018\"], [\"70401.50\", \"0.026\"], [\"70401.70\", \"0.002\"], [\"70401.80\", \"0.007\"], [\"70401.90\", \"0.011\"], [\"70402.00\", \"0.265\"], [\"70402.10\", \"0.005\"], [\"70402.30\", \"0.010\"], [\"70402.60\", \"0.005\"], [\"70402.80\", \"0.051\"], [\"70402.90\", \"0.002\"], [\"70403.00\", \"0.448\"], [\"70403.30\", \"0.213\"], [\"70403.40\", \"0.013\"], [\"70403.50\", \"0.017\"], [\"70403.70\", \"0.189\"], [\"70403.80\", \"0.342\"], [\"70403.90\", \"0.516\"], [\"70404.00\", \"0.386\"], [\"70404.10\", \"0.389\"], [\"70404.30\", \"0.002\"], [\"70404.50\", \"0.037\"], [\"70404.60\", \"0.013\"], [\"70404.70\", \"0.000\"], [\"70405.00\", \"0.027\"], [\"70405.40\", \"0.011\"], [\"70405.60\", \"0.220\"], [\"70405.90\", \"0.761\"], [\"70406.00\", \"0.004\"], [\"70406.10\", \"0.000\"], [\"70406.20\", \"0.007\"], [\"70406.70\", \"0.316\"], [\"70406.80\", \"0.004\"], [\"70407.20\", \"0.039\"], [\"70407.40\", \"0.002\"], [\"70407.50\", \"0.002\"], [\"70407.60\", \"0.015\"], [\"70407.70\", \"0.008\"], [\"70408.10\", \"0.000\"], [\"70408.20\", \"0.586\"], [\"70408.40\", \"0.374\"], [\"70408.50\", \"0.000\"], [\"70408.80\", \"0.012\"], [\"70408.90\", \"0.011\"], [\"70409.00\", \"0.025\"], [\"70409.10\", \"0.181\"], [\"70409.30\", \"0.003\"], [\"70409.40\", \"0.078\"], [\"70409.50\", \"0.782\"], [\"70409.60\", \"0.002\"], [\"70409.80\", \"0.005\"], [\"70409.90\", \"0.003\"], [\"70410.00\", \"0.011\"], [\"70410.10\", \"0.000\"], [\"70410.20\", \"0.073\"], [\"70410.30\", \"0.000\"], [\"70410.80\", \"0.030\"], [\"70410.90\", \"0.004\"], [\"70411.00\", \"0.002\"], [\"70411.10\", \"0.022\"], [\"70411.20\", \"0.073\"], [\"70411.50\", \"0.000\"], [\"70411.60\", \"0.002\"], [\"70411.70\", \"0.003\"], [\"70411.80\", \"0.009\"], [\"70411.90\", \"0.226\"], [\"70412.20\", \"0.002\"], [\"70412.30\", \"0.003\"], [\"70412.40\", \"0.003\"], [\"70412.50\", \"0.030\"], [\"70412.60\", \"0.007\"], [\"70412.80\", \"0.195\"], [\"70412.90\", \"0.087\"], [\"70413.00\", \"1.074\"], [\"70413.10\", \"0.002\"], [\"70413.30\", \"0.003\"], [\"70413.40\", \"0.396\"], [\"70413.50\", \"0.000\"], [\"70413.60\", \"0.042\"], [\"70413.70\", \"0.001\"], [\"70413.80\", \"0.000\"], [\"70413.90\", \"0.595\"], [\"70414.30\", \"0.000\"], [\"70414.40\", \"0.025\"], [\"70414.50\", \"0.000\"], [\"70414.70\", \"0.003\"], [\"70414.80\", \"0.006\"], [\"70414.90\", \"0.004\"], [\"70415.10\", \"0.642\"], [\"70415.20\", \"0.017\"], [\"70415.40\", \"0.516\"], [\"70415.50\", \"0.002\"], [\"70415.80\", \"0.000\"], [\"70415.90\", \"0.000\"], [\"70416.10\", \"0.005\"], [\"70416.50\", \"0.774\"], [\"70416.60\", \"0.008\"], [\"70416.80\", \"0.237\"], [\"70417.30\", \"0.023\"], [\"70417.60\", \"0.519\"], [\"70417.80\", \"0.003\"], [\"70418.30\", \"0.260\"], [\"70418.40\", \"0.223\"], [\"70418.50\", \"0.178\"], [\"70418.60\", \"0.219\"], [\"70418.90\", \"0.265\"], [\"70419.30\", \"0.002\"], [\"70419.50\", \"0.004\"], [\"70419.60\", \"1.069\"], [\"70420.00\", \"0.891\"], [\"70420.20\", \"0.005\"], [\"70420.40\", \"0.000\"], [\"70420.50\", \"0.000\"], [\"70421.00\", \"0.000\"], [\"70421.80\", \"0.030\"], [\"70421.90\", \"0.013\"], [\"70422.20\", \"0.003\"], [\"70422.70\", \"0.198\"], [\"70424.10\", \"0.098\"], [\"70424.50\", \"0.000\"], [\"70425.00\", \"0.037\"], [\"70425.40\", \"0.141\"], [\"70425.60\", \"0.187\"], [\"70425.70\", \"0.107\"], [\"70425.90\", \"0.527\"], [\"70426.00\", \"0.400\"], [\"70426.10\", \"0.194\"], [\"70426.90\", \"0.006\"], [\"70427.00\", \"0.004\"], [\"70427.10\", \"0.403\"], [\"70427.50\", \"0.041\"], [\"70427.60\", \"0.101\"], [\"70427.70\", \"0.000\"], [\"70427.80\", \"10.425\"], [\"70428.10\", \"0.091\"], [\"70428.90\", \"0.064\"], [\"70429.40\", \"0.000\"], [\"70429.50\", \"0.022\"], [\"70429.60\", \"0.033\"], [\"70429.70\", \"0.006\"], [\"70430.10\", \"0.049\"], [\"70430.20\", \"0.000\"], [\"70430.30\", \"0.000\"], [\"70431.80\", \"0.064\"], [\"70431.90\", \"0.000\"], [\"70432.40\", \"0.326\"], [\"70432.70\", \"0.188\"], [\"70433.10\", \"0.002\"], [\"70433.20\", \"0.000\"], [\"70433.50\", \"0.005\"], [\"70435.20\", \"0.002\"], [\"70435.50\", \"0.193\"], [\"70436.20\", \"0.002\"], [\"70436.40\", \"0.000\"], [\"70437.90\", \"0.000\"], [\"70440.10\", \"0.002\"], [\"70440.20\", \"0.010\"], [\"70440.50\", \"0.007\"], [\"70440.70\", \"0.000\"], [\"70441.10\", \"0.000\"], [\"70441.40\", \"0.256\"], [\"70441.60\", \"0.000\"], [\"70441.70\", \"0.004\"], [\"70442.10\", \"0.006\"], [\"70442.40\", \"0.095\"], [\"70442.70\", \"0.001\"], [\"70442.80\", \"0.115\"], [\"70442.90\", \"0.077\"], [\"70443.10\", \"0.005\"], [\"70443.60\", \"0.004\"], [\"70443.70\", \"0.003\"], [\"70444.00\", \"0.062\"], [\"70444.20\", \"1.127\"], [\"70444.60\", \"0.279\"], [\"70444.90\", \"6.348\"], [\"70445.10\", \"0.104\"], [\"70446.70\", \"0.001\"], [\"70446.90\", \"0.036\"], [\"70448.00\", \"0.128\"], [\"70448.10\", \"1.317\"], [\"70449.20\", \"0.624\"], [\"70449.50\", \"0.008\"], [\"70450.10\", \"0.001\"], [\"70450.20\", \"0.090\"], [\"70450.30\", \"0.084\"], [\"70450.80\", \"1.000\"], [\"70453.80\", \"0.279\"], [\"70454.30\", \"0.000\"], [\"70454.90\", \"0.000\"], [\"70458.50\", \"0.523\"], [\"70459.60\", \"0.226\"], [\"70459.90\", \"0.191\"], [\"70460.60\", \"0.003\"], [\"70460.70\", \"0.000\"], [\"70461.30\", \"0.007\"], [\"70463.40\", \"0.003\"], [\"70464.10\", \"2.006\"], [\"70464.60\", \"0.100\"], [\"70464.90\", \"2.074\"], [\"70466.00\", \"0.000\"], [\"70466.20\", \"0.004\"], [\"70467.20\", \"0.014\"], [\"70468.00\", \"1.201\"], [\"70470.60\", \"0.250\"], [\"70472.80\", \"0.153\"], [\"70473.20\", \"0.002\"], [\"70475.00\", \"0.378\"], [\"70477.60\", \"0.041\"], [\"70479.40\", \"0.511\"], [\"70480.70\", \"0.086\"], [\"70481.20\", \"0.003\"], [\"70481.60\", \"0.000\"], [\"70482.70\", \"0.049\"], [\"70483.00\", \"0.076\"], [\"70483.20\", \"0.344\"], [\"70484.30\", \"0.085\"], [\"70485.90\", \"0.003\"], [\"70486.40\", \"0.000\"], [\"70489.30\", \"0.004\"], [\"70489.90\", \"0.025\"], [\"70491.40\", \"10.446\"], [\"70492.90\", \"0.002\"], [\"70494.00\", \"0.195\"], [\"70494.40\", \"0.014\"], [\"70494.70\", \"1.397\"], [\"70494.80\", \"4.165\"], [\"70496.00\", \"0.000\"], [\"70498.70\", \"0.006\"], [\"70502.60\", \"1.318\"], [\"70508.70\", \"0.000\"], [\"70510.20\", \"0.087\"], [\"70511.00\", \"0.002\"], [\"70511.60\", \"0.382\"], [\"70512.60\", \"0.002\"], [\"70512.80\", \"0.000\"], [\"70512.90\", \"0.548\"], [\"70514.80\", \"0.003\"], [\"70515.00\", \"0.291\"], [\"70516.00\", \"0.002\"], [\"70517.70\", \"0.000\"], [\"70519.00\", \"0.000\"], [\"70520.00\", \"0.010\"], [\"70520.50\", \"0.005\"], [\"70521.00\", \"0.000\"], [\"70521.40\", \"0.000\"], [\"70523.10\", \"0.031\"], [\"70523.70\", \"0.095\"], [\"70524.60\", \"0.455\"], [\"70526.80\", \"0.128\"], [\"70526.90\", \"0.086\"], [\"70527.00\", \"0.115\"], [\"70529.70\", \"0.511\"], [\"70531.90\", \"0.081\"], [\"70532.80\", \"0.513\"], [\"70533.30\", \"0.035\"], [\"70534.70\", \"0.002\"], [\"70534.80\", \"0.000\"], [\"70538.90\", \"0.056\"], [\"70544.90\", \"0.000\"], [\"70545.30\", \"0.082\"], [\"70546.20\", \"0.164\"], [\"70547.60\", \"0.164\"], [\"70550.30\", \"0.046\"], [\"70550.40\", \"0.094\"], [\"70556.90\", \"0.092\"], [\"70557.10\", \"1.652\"], [\"70560.00\", \"0.269\"], [\"70560.90\", \"0.000\"], [\"70562.90\", \"0.003\"], [\"70564.40\", \"0.082\"], [\"70566.40\", \"0.003\"], [\"70566.90\", \"0.025\"], [\"70567.50\", \"0.036\"], [\"70567.80\", \"0.040\"], [\"70568.20\", \"0.036\"], [\"70568.40\", \"0.003\"], [\"70568.70\", \"0.036\"], [\"70570.10\", \"0.365\"], [\"70571.90\", \"0.003\"], [\"70573.00\", \"0.089\"], [\"70578.10\", \"0.002\"], [\"70578.50\", \"0.082\"], [\"70581.40\", \"0.086\"], [\"70584.70\", \"1.325\"], [\"70592.60\", \"4.413\"], [\"70592.70\", \"29.364\"], [\"70596.70\", \"0.063\"], [\"70597.70\", \"0.050\"], [\"70603.20\", \"0.272\"], [\"70610.50\", \"0.002\"], [\"70621.30\", \"0.002\"], [\"70637.20\", \"0.390\"], [\"70637.50\", \"0.002\"], [\"70656.20\", \"0.200\"], [\"70665.20\", \"1.138\"], [\"70668.20\", \"5.684\"], [\"70669.60\", \"0.190\"], [\"70670.60\", \"0.199\"], [\"70671.20\", \"4.306\"], [\"70738.80\", \"0.000\"], [\"70753.50\", \"0.022\"], [\"70753.60\", \"0.006\"], [\"70759.70\", \"0.028\"], [\"70784.30\", \"0.454\"], [\"70804.00\", \"0.000\"], [\"70839.10\", \"0.000\"], [\"70874.30\", \"1.190\"], [\"70909.50\", \"0.002\"], [\"70944.60\", \"0.048\"], [\"70979.80\", \"0.000\"], [\"71078.60\", \"0.281\"], [\"71200.10\", \"0.000\"], [\"71357.90\", \"0.490\"], [\"71717.60\", \"0.998\"], [\"73927.70\", \"0.022\"], [\"74817.10\", \"0.000\"], [\"75059.80\", \"0.000\"], [\"75236.00\", \"0.050\"], [\"75412.20\", \"0.000\"], [\"75588.40\", \"0.003\"], [\"75764.60\", \"0.000\"]]}", "symbol": "BTCUSDT"}
{"event": "depthUpdate", "raw_payload": "{\"e\": \"depthUpdate\", \"E\": 1773246394756, \"T\": 1773246394755, \"s\": \"BTCUSDT\", \"U\": 10089704659002, \"u\": 10089704705895, \"pu\": 10089704658903, \"b\": [[\"1000.00\", \"26.792\"], [\"5000.00\", \"101.418\"], [\"19867.10\", \"0.040\"], [\"20074.80\", \"0.050\"], [\"20076.10\", \"0.010\"], [\"20076.80\", \"0.020\"], [\"20079.10\", \"0.020\"], [\"20079.90\", \"0.010\"], [\"20080.00\", \"0.030\"], [\"20082.60\", \"0.020\"], [\"20083.10\", \"0.010\"], [\"20083.50\", \"0.010\"], [\"20084.20\", \"0.010\"], [\"20084.60\", \"0.010\"], [\"20086.20\", \"0.010\"], [\"20167.10\", \"0.720\"], [\"20276.10\", \"0.010\"], [\"20277.80\", \"0.010\"], [\"20279.10\", \"0.010\"], [\"20280.00\", \"0.010\"], [\"20280.70\", \"0.010\"], [\"20282.60\", \"0.010\"], [\"20283.50\", \"0.010\"], [\"20285.80\", \"0.010\"], [\"63330.40\", \"0.014\"], [\"66848.70\", \"0.005\"], [\"66849.70\", \"0.002\"], [\"66857.30\", \"0.002\"], [\"69069.20\", \"0.004\"], [\"69346.80\", \"8.049\"], [\"69366.10\", \"0.720\"], [\"69370.00\", \"0.002\"], [\"69370.40\", \"0.000\"], [\"69372.70\", \"0.010\"], [\"69373.30\", \"0.008\"], [\"69376.10\", \"0.002\"], [\"69376.40\", \"0.008\"], [\"69376.80\", \"0.016\"], [\"69380.00\", \"0.354\"], [\"69380.70\", \"0.018\"], [\"69382.60\", \"1.441\"], [\"69682.10\", \"0.006\"], [\"69977.40\", \"0.000\"], [\"69978.40\", \"0.000\"], [\"69979.80\", \"0.002\"], [\"69981.70\", \"2.026\"], [\"69995.50\", \"0.000\"], [\"69998.70\", \"0.006\"], [\"70062.90\", \"0.305\"], [\"70076.90\", \"0.172\"], [\"70077.30\", \"0.000\"], [\"70078.00\", \"0.000\"], [\"70080.20\", \"0.134\"], [\"70080.50\", \"0.007\"], [\"70091.30\", \"3.992\"], [\"70098.60\", \"0.008\"], [\"70113.70\", \"0.000\"], [\"70124.50\", \"5.259\"], [\"70125.60\", \"0.982\"], [\"70132.00\", \"0.000\"], [\"70133.00\", \"4.815\"], [\"70136.50\", \"0.000\"], [\"70140.30\", \"0.000\"], [\"70154.20\", \"0.000\"], [\"70157.40\", \"0.158\"], [\"70163.40\", \"0.000\"], [\"70166.10\", \"28.776\"], [\"70167.30\", \"0.000\"], [\"70168.00\", \"0.525\"], [\"70171.00\", \"0.001\"], [\"70174.10\", \"0.000\"], [\"70174.20\", \"0.000\"], [\"70174.30\", \"0.000\"], [\"70176.60\", \"0.895\"], [\"70177.10\", \"0.012\"], [\"70177.60\", \"1.797\"], [\"70178.50\", \"0.451\"], [\"70182.30\", \"0.018\"], [\"70183.40\", \"0.000\"], [\"70184.10\", \"0.028\"], [\"70185.90\", \"0.004\"], [\"70187.90\", \"0.043\"], [\"70189.70\", \"0.000\"], [\"70191.40\", \"0.000\"], [\"70193.20\", \"2.594\"], [\"70193.40\", \"0.000\"], [\"70206.50\", \"0.080\"], [\"70208.30\", \"19.315\"], [\"70209.90\", \"0.006\"], [\"70210.00\", \"0.549\"], [\"70230.10\", \"0.003\"], [\"70230.80\", \"0.511\"], [\"70232.10\", \"0.305\"], [\"70237.50\", \"0.447\"], [\"70238.00\", \"2.094\"], [\"70240.40\", \"0.000\"], [\"70242.00\", \"0.002\"], [\"70242.10\", \"2.008\"], [\"70242.20\", \"0.083\"], [\"70244.90\", \"0.000\"], [\"70248.00\", \"0.420\"], [\"70248.30\", \"0.040\"], [\"70248.50\", \"0.909\"], [\"70254.20\", \"0.000\"], [\"70255.10\", \"0.514\"], [\"70256.10\", \"0.345\"], [\"70256.70\", \"0.000\"], [\"70257.90\", \"0.004\"], [\"70258.00\", \"0.042\"], [\"70258.60\", \"0.000\"], [\"70258.80\", \"0.208\"], [\"70259.00\", \"2.364\"], [\"70259.10\", \"2.003\"], [\"70259.70\", \"0.002\"], [\"70260.70\", \"0.000\"], [\"70260.90\", \"0.004\"], [\"70262.50\", \"0.348\"], [\"70263.00\", \"0.154\"], [\"70263.80\", \"1.275\"], [\"70266.20\", \"0.011\"], [\"70268.60\", \"0.000\"], [\"70270.00\", \"2.061\"], [\"70272.10\", \"0.669\"], [\"70272.90\", \"0.193\"], [\"70273.00\", \"0.741\"], [\"70273.40\", \"0.517\"], [\"70274.20\", \"0.003\"], [\"70275.40\", \"0.022\"], [\"70275.80\", \"0.511\"], [\"70277.60\", \"0.002\"], [\"70277.90\", \"6.472\"], [\"70278.00\", \"0.523\"], [\"70278.70\", \"0.000\"], [\"70279.10\", \"0.200\"], [\"70279.30\", \"0.002\"], [\"70280.20\", \"0.006\"], [\"70281.00\", \"0.003\"], [\"70282.50\", \"0.039\"], [\"70282.70\", \"0.000\"], [\"70283.60\", \"0.071\"], [\"70284.10\", \"0.089\"], [\"70284.60\", \"0.000\"], [\"70285.80\", \"0.008\"], [\"70286.00\", \"4.125\"], [\"70286.20\", \"0.012\"], [\"70286.50\", \"0.084\"], [\"70287.00\", \"1.185\"], [\"70287.30\", \"2.207\"], [\"70287.40\", \"6.546\"], [\"70287.70\", \"0.166\"], [\"70288.30\", \"0.525\"], [\"70288.50\", \"0.000\"], [\"70289.70\", \"0.000\"], [\"70289.80\", \"0.009\"], [\"70289.90\", \"0.378\"], [\"70290.20\", \"0.002\"], [\"70290.40\", \"0.474\"], [\"70290.90\", \"0.228\"], [\"70291.00\", \"0.127\"], [\"70291.50\", \"0.004\"], [\"70292.60\", \"0.017\"], [\"70292.70\", \"0.051\"], [\"70292.80\", \"10.736\"], [\"70292.90\", \"4.063\"], [\"70293.40\", \"0.050\"], [\"70294.00\", \"0.792\"], [\"70295.20\", \"0.003\"], [\"70295.40\", \"0.020\"], [\"70295.60\", \"0.000\"], [\"70296.70\", \"0.000\"], [\"70296.80\", \"0.463\"], [\"70297.80\", \"0.002\"], [\"70298.10\", \"0.073\"], [\"70298.30\", \"0.002\"], [\"70298.40\", \"0.005\"], [\"70298.50\", \"0.000\"], [\"70300.20\", \"0.000\"], [\"70300.40\", \"0.000\"], [\"70301.70\", \"2.087\"], [\"70301.80\", \"0.538\"], [\"70301.90\", \"0.004\"], [\"70302.10\", \"6.533\"], [\"70302.30\", \"0.000\"], [\"70302.40\", \"0.002\"], [\"70302.50\", \"0.002\"], [\"70302.60\", \"0.002\"], [\"70303.00\", \"1.958\"], [\"70303.10\", \"0.005\"], [\"70303.50\", \"0.215\"], [\"70304.10\", \"0.006\"], [\"70304.20\", \"0.000\"], [\"70304.30\", \"0.554\"], [\"70304.40\", \"0.018\"], [\"70304.50\", \"0.006\"], [\"70304.60\", \"0.000\"], [\"70305.10\", \"0.079\"], [\"70305.50\", \"0.446\"], [\"70306.10\", \"0.192\"], [\"70306.50\", \"0.039\"], [\"70307.10\", \"0.010\"], [\"70307.60\", \"0.002\"], [\"70307.90\", \"0.090\"], [\"70308.20\", \"0.039\"], [\"70308.40\", \"0.000\"], [\"70308.60\", \"0.004\"], [\"70309.00\", \"0.000\"], [\"70309.20\", \"0.101\"], [\"70309.50\", \"0.000\"], [\"70310.10\", \"0.000\"], [\"70310.80\", \"0.050\"], [\"70311.10\", \"0.000\"], [\"70311.40\", \"0.144\"], [\"70311.50\", \"1.068\"], [\"70311.60\", \"0.003\"], [\"70312.20\", \"0.002\"], [\"70312.70\", \"0.043\"], [\"70312.90\", \"1.055\"], [\"70313.00\", \"0.514\"], [\"70313.10\", \"0.200\"], [\"70313.50\", \"0.000\"], [\"70314.20\", \"1.000\"], [\"70314.60\", \"0.000\"], [\"70315.40\", \"0.003\"], [\"70316.10\", \"0.090\"], [\"70316.30\", \"0.000\"], [\"70317.80\", \"0.002\"], [\"70318.00\", \"0.041\"], [\"70318.30\", \"0.002\"], [\"70318.50\", \"0.636\"], [\"70318.80\", \"0.010\"], [\"70319.80\", \"0.590\"], [\"70320.80\", \"0.146\"], [\"70321.10\", \"0.083\"], [\"70321.30\", \"0.125\"], [\"70321.70\", \"0.065\"], [\"70322.00\", \"0.004\"], [\"70322.10\", \"0.265\"], [\"70322.20\", \"0.000\"], [\"70322.30\", \"0.592\"], [\"70322.60\", \"0.000\"], [\"70322.80\", \"0.000\"], [\"70322.90\", \"0.085\"], [\"70323.20\", \"0.002\"], [\"70323.60\", \"0.004\"], [\"70323.90\", \"0.002\"], [\"70324.10\", \"0.007\"], [\"70324.20\", \"0.005\"], [\"70324.30\", \"0.000\"], [\"70324.40\", \"0.102\"], [\"70324.70\", \"0.040\"], [\"70324.80\", \"0.016\"], [\"70324.90\", \"1.962\"], [\"70325.00\", \"0.208\"], [\"70325.30\", \"0.002\"], [\"70325.50\", \"0.005\"], [\"70325.60\", \"0.214\"], [\"70325.80\", \"0.074\"], [\"70326.00\", \"0.000\"], [\"70326.10\", \"0.006\"], [\"70326.30\", \"0.003\"], [\"70326.60\", \"0.000\"], [\"70326.90\", \"0.015\"], [\"70327.00\", \"0.513\"], [\"70327.70\", \"0.000\"], [\"70327.90\", \"0.002\"], [\"70328.10\", \"0.002\"], [\"70328.20\", \"0.000\"], [\"70328.30\", \"0.002\"], [\"70328.50\", \"0.000\"], [\"70328.60\", \"0.373\"], [\"70329.00\", \"0.012\"], [\"70329.50\", \"0.004\"], [\"70330.00\", \"0.088\"], [\"70330.10\", \"1.069\"], [\"70330.50\", \"0.041\"], [\"70330.60\", \"0.002\"], [\"70330.80\", \"0.223\"], [\"70331.30\", \"0.038\"], [\"70331.40\", \"0.000\"], [\"70331.70\", \"0.713\"], [\"70332.10\", \"0.010\"], [\"70332.40\", \"0.089\"], [\"70332.50\", \"0.041\"], [\"70333.10\", \"0.014\"], [\"70333.20\", \"2.075\"], [\"70333.40\", \"0.004\"], [\"70334.00\", \"0.103\"], [\"70334.20\", \"0.040\"], [\"70334.50\", \"0.511\"], [\"70334.60\", \"0.560\"], [\"70334.90\", \"0.000\"], [\"70335.20\", \"0.350\"], [\"70335.60\", \"0.010\"], [\"70336.30\", \"0.085\"], [\"70336.60\", \"0.019\"], [\"70336.90\", \"0.027\"], [\"70337.00\", \"0.002\"], [\"70337.20\", \"0.000\"], [\"70337.60\", \"0.000\"], [\"70337.70\", \"0.084\"], [\"70337.80\", \"0.226\"], [\"70338.00\", \"0.969\"], [\"70338.30\", \"0.000\"], [\"70338.50\", \"0.711\"], [\"70338.70\", \"0.194\"], [\"70338.80\", \"0.002\"], [\"70338.90\", \"0.408\"], [\"70339.10\", \"0.000\"], [\"70339.60\", \"0.188\"], [\"70340.00\", \"0.015\"], [\"70340.20\", \"0.153\"], [\"70340.30\", \"0.001\"], [\"70340.80\", \"0.000\"], [\"70340.90\", \"0.007\"], [\"70341.00\", \"0.362\"], [\"70341.20\", \"0.003\"], [\"70341.50\", \"0.423\"], [\"70341.90\", \"0.511\"], [\"70342.00\", \"0.005\"], [\"70342.10\", \"0.256\"], [\"70342.20\", \"0.007\"], [\"70342.40\", \"0.235\"], [\"70342.60\", \"0.005\"], [\"70342.90\", \"1.068\"], [\"70343.10\", \"0.007\"], [\"70343.20\", \"0.004\"], [\"70343.30\", \"0.072\"], [\"70343.90\", \"0.569\"], [\"70344.30\", \"0.039\"], [\"70344.40\", \"0.186\"], [\"70344.80\", \"0.003\"], [\"70344.90\", \"0.049\"], [\"70345.00\", \"0.205\"], [\"70345.20\", \"0.000\"], [\"70345.70\", \"0.000\"], [\"70345.80\", \"0.003\"], [\"70346.00\", \"0.004\"], [\"70346.20\", \"0.442\"], [\"70346.30\", \"0.003\"], [\"70346.40\", \"0.000\"], [\"70346.50\", \"0.286\"], [\"70347.10\", \"0.006\"], [\"70347.20\", \"0.030\"], [\"70347.40\", \"0.054\"], [\"70347.50\", \"0.002\"], [\"70347.70\", \"0.012\"], [\"70347.80\", \"0.006\"], [\"70347.90\", \"0.584\"], [\"70348.00\", \"0.004\"], [\"70348.50\", \"0.000\"], [\"70348.60\", \"0.005\"], [\"70348.70\", \"0.610\"], [\"70349.20\", \"0.001\"], [\"70349.30\", \"0.002\"], [\"70349.70\", \"0.003\"], [\"70349.90\", \"0.000\"], [\"70350.00\", \"0.010\"], [\"70350.40\", \"0.000\"], [\"70350.60\", \"0.018\"], [\"70350.70\", \"0.002\"], [\"70350.80\", \"0.006\"], [\"70350.90\", \"0.001\"], [\"70351.00\", \"0.045\"], [\"70351.10\", \"0.010\"], [\"70351.30\", \"0.016\"], [\"70351.40\", \"0.045\"], [\"70351.60\", \"0.002\"], [\"70352.10\", \"0.000\"], [\"70352.20\", \"0.195\"], [\"70352.30\", \"0.000\"], [\"70352.60\", \"0.005\"], [\"70352.70\", \"0.202\"], [\"70352.80\", \"0.549\"], [\"70352.90\", \"0.013\"], [\"70353.00\", \"0.460\"], [\"70353.10\", \"0.488\"], [\"70353.40\", \"0.004\"], [\"70353.60\", \"0.521\"], [\"70353.70\", \"0.022\"], [\"70353.80\", \"0.188\"], [\"70353.90\", \"0.136\"], [\"70354.10\", \"0.020\"], [\"70354.20\", \"0.019\"], [\"70354.30\", \"0.019\"], [\"70354.50\", \"0.059\"], [\"70354.60\", \"0.135\"], [\"70354.80\", \"0.000\"], [\"70354.90\", \"0.002\"], [\"70355.00\", \"0.004\"], [\"70355.10\", \"0.549\"], [\"70355.20\", \"1.128\"], [\"70355.60\", \"0.000\"], [\"70355.70\", \"0.006\"], [\"70356.00\", \"0.003\"], [\"70356.10\", \"0.003\"], [\"70356.60\", \"0.254\"], [\"70356.90\", \"0.000\"], [\"70357.00\", \"0.005\"], [\"70357.40\", \"0.000\"], [\"70357.90\", \"0.010\"], [\"70358.20\", \"0.003\"], [\"70358.30\", \"0.000\"], [\"70358.50\", \"0.003\"], [\"70358.60\", \"0.003\"], [\"70358.70\", \"0.006\"], [\"70358.80\", \"0.002\"], [\"70358.90\", \"0.002\"], [\"70359.10\", \"0.001\"], [\"70359.20\", \"0.115\"], [\"70359.30\", \"0.000\"], [\"70359.50\", \"0.040\"], [\"70359.70\", \"0.071\"], [\"70359.80\", \"0.000\"], [\"70360.00\", \"0.013\"], [\"70360.30\", \"0.005\"], [\"70360.40\", \"0.002\"], [\"70360.50\", \"0.552\"], [\"70360.60\", \"0.000\"], [\"70360.70\", \"0.002\"], [\"70360.80\", \"0.009\"], [\"70360.90\", \"1.386\"], [\"70361.10\", \"0.116\"], [\"70361.20\", \"0.002\"], [\"70361.40\", \"0.000\"], [\"70361.50\", \"0.420\"], [\"70361.60\", \"0.002\"], [\"70361.70\", \"0.001\"], [\"70361.80\", \"0.000\"], [\"70361.90\", \"0.000\"], [\"70362.00\", \"0.370\"], [\"70362.10\", \"0.225\"], [\"70362.20\", \"0.004\"], [\"70362.30\", \"0.004\"], [\"70362.40\", \"0.011\"], [\"70362.50\", \"0.004\"], [\"70362.70\", \"0.005\"], [\"70362.80\", \"0.000\"], [\"70362.90\", \"0.018\"], [\"70363.00\", \"0.002\"], [\"70363.40\", \"0.000\"], [\"70363.50\", \"0.202\"], [\"70363.60\", \"0.604\"], [\"70363.70\", \"0.003\"], [\"70363.80\", \"0.512\"], [\"70363.90\", \"0.000\"], [\"70364.00\", \"0.180\"], [\"70364.10\", \"0.000\"], [\"70364.20\", \"0.002\"], [\"70364.30\", \"0.006\"], [\"70364.40\", \"0.487\"], [\"70364.60\", \"0.002\"], [\"70364.70\", \"0.012\"], [\"70364.80\", \"0.000\"], [\"70364.90\", \"0.052\"], [\"70365.00\", \"0.006\"], [\"70365.10\", \"0.009\"], [\"70365.20\", \"0.002\"], [\"70365.30\", \"0.002\"], [\"70365.40\", \"0.003\"], [\"70365.50\", \"0.007\"], [\"70365.60\", \"0.239\"], [\"70365.70\", \"0.000\"], [\"70365.80\", \"0.000\"], [\"70365.90\", \"0.027\"], [\"70366.00\", \"0.002\"], [\"70366.10\", \"0.091\"], [\"70366.60\", \"0.000\"], [\"70366.70\", \"0.002\"], [\"70366.80\", \"0.000\"], [\"70366.90\", \"0.000\"], [\"70367.00\", \"0.096\"], [\"70367.10\", \"0.140\"], [\"70367.20\", \"0.000\"], [\"70367.30\", \"0.234\"], [\"70367.40\", \"0.030\"], [\"70367.50\", \"0.513\"], [\"70367.60\", \"0.102\"], [\"70367.70\", \"0.224\"], [\"70367.80\", \"0.388\"], [\"70367.90\", \"0.003\"], [\"70368.00\", \"1.069\"], [\"70368.10\", \"0.008\"], [\"70368.20\", \"0.014\"], [\"70368.30\", \"0.006\"], [\"70368.40\", \"0.021\"], [\"70368.50\", \"0.002\"], [\"70368.60\", \"0.001\"], [\"70368.70\", \"0.005\"], [\"70368.80\", \"0.000\"], [\"70368.90\", \"0.000\"], [\"70369.00\", \"0.000\"], [\"70369.10\", \"0.001\"], [\"70369.20\", \"0.000\"], [\"70369.30\", \"0.002\"], [\"70369.50\", \"0.002\"], [\"70369.60\", \"0.000\"], [\"70369.70\", \"0.060\"], [\"70369.80\", \"0.002\"], [\"70369.90\", \"0.000\"], [\"70370.00\", \"0.260\"], [\"70370.10\", \"0.481\"], [\"70370.40\", \"0.304\"], [\"70370.50\", \"0.303\"], [\"70370.70\", \"0.000\"], [\"70370.80\", \"0.241\"], [\"70370.90\", \"0.003\"], [\"70371.00\", \"0.004\"], [\"70371.30\", \"0.064\"], [\"70371.40\", \"0.075\"], [\"70371.60\", \"0.003\"], [\"70371.70\", \"0.002\"], [\"70371.80\", \"0.766\"], [\"70371.90\", \"0.002\"], [\"70372.00\", \"0.009\"], [\"70372.10\", \"0.644\"], [\"70372.20\", \"0.001\"], [\"70372.30\", \"0.002\"], [\"70372.40\", \"0.005\"], [\"70372.50\", \"0.028\"], [\"70372.60\", \"0.004\"], [\"70372.70\", \"0.301\"], [\"70372.80\", \"0.177\"], [\"70372.90\", \"0.350\"], [\"70373.00\", \"0.303\"], [\"70373.20\", \"0.002\"], [\"70373.30\", \"0.005\"], [\"70373.40\", \"0.003\"], [\"70373.50\", \"0.000\"], [\"70373.60\", \"1.303\"], [\"70373.70\", \"0.582\"], [\"70373.80\", \"0.009\"], [\"70373.90\", \"0.001\"], [\"70374.10\", \"0.000\"], [\"70374.20\", \"0.001\"], [\"70374.50\", \"0.002\"], [\"70374.70\", \"0.003\"], [\"70374.80\", \"0.220\"], [\"70374.90\", \"0.000\"], [\"70375.00\", \"0.088\"], [\"70375.10\", \"0.000\"], [\"70375.20\", \"0.000\"], [\"70375.30\", \"0.181\"], [\"70375.40\", \"0.001\"], [\"70375.50\", \"0.048\"], [\"70375.60\", \"0.000\"], [\"70375.70\", \"0.034\"], [\"70375.80\", \"0.000\"], [\"70375.90\", \"0.080\"], [\"70376.00\", \"0.003\"], [\"70376.10\", \"0.499\"], [\"70376.20\", \"0.000\"], [\"70376.30\", \"0.003\"], [\"70376.40\", \"0.000\"], [\"70376.50\", \"0.521\"], [\"70376.60\", \"0.319\"], [\"70376.70\", \"0.006\"], [\"70376.80\", \"0.409\"], [\"70376.90\", \"0.319\"], [\"70377.00\", \"0.003\"], [\"70377.10\", \"0.400\"], [\"70377.20\", \"0.416\"], [\"70377.30\", \"0.005\"], [\"70377.40\", \"0.149\"], [\"70377.50\", \"0.000\"], [\"70377.70\", \"0.000\"], [\"70377.80\", \"0.201\"], [\"70377.90\", \"0.322\"], [\"70378.00\", \"0.392\"], [\"70378.10\", \"0.359\"], [\"70378.20\", \"0.413\"], [\"70378.30\", \"0.000\"], [\"70378.40\", \"0.002\"], [\"70378.50\", \"0.000\"], [\"70378.70\", \"0.001\"], [\"70378.80\", \"0.319\"], [\"70378.90\", \"0.256\"], [\"70379.00\", \"0.005\"], [\"70379.10\", \"0.016\"], [\"70379.20\", \"0.000\"], [\"70379.30\", \"0.319\"], [\"70379.40\", \"0.001\"], [\"70379.50\", \"0.000\"], [\"70379.60\", \"0.000\"], [\"70379.70\", \"0.002\"], [\"70379.80\", \"0.000\"], [\"70379.90\", \"0.095\"], [\"70380.00\", \"0.789\"], [\"70380.10\", \"1.104\"], [\"70380.20\", \"0.000\"], [\"70380.30\", \"0.001\"], [\"70380.40\", \"0.000\"], [\"70380.50\", \"0.002\"], [\"70380.60\", \"0.005\"], [\"70380.70\", \"0.830\"], [\"70380.80\", \"0.000\"], [\"70380.90\", \"0.000\"], [\"70381.00\", \"0.001\"], [\"70381.10\", \"0.000\"], [\"70381.20\", \"0.000\"], [\"70381.30\", \"0.000\"], [\"70381.40\", \"0.002\"], [\"70381.50\", \"0.001\"], [\"70381.60\", \"0.000\"], [\"70381.90\", \"0.000\"], [\"70382.00\", \"0.006\"], [\"70382.20\", \"0.003\"], [\"70382.30\", \"0.002\"], [\"70382.40\", \"0.328\"], [\"70382.50\", \"0.109\"], [\"70382.60\", \"0.453\"], [\"70382.70\", \"1.100\"], [\"70382.80\", \"0.000\"], [\"70382.90\", \"0.003\"], [\"70383.00\", \"0.000\"], [\"70383.10\", \"0.000\"], [\"70383.20\", \"0.001\"], [\"70383.30\", \"0.001\"], [\"70383.40\", \"0.001\"], [\"70383.50\", \"0.530\"], [\"70383.60\", \"0.226\"], [\"70383.70\", \"0.000\"], [\"70383.80\", \"0.127\"], [\"70383.90\", \"0.129\"], [\"70384.00\", \"0.127\"], [\"70384.10\", \"0.104\"], [\"70384.20\", \"0.000\"], [\"70384.30\", \"0.000\"], [\"70384.40\", \"0.000\"], [\"70384.50\", \"0.001\"], [\"70384.60\", \"2.306\"], [\"70384.70\", \"2.466\"], [\"70384.80\", \"0.003\"], [\"70384.90\", \"0.000\"], [\"70385.00\", \"0.000\"], [\"70385.10\", \"0.008\"], [\"70385.20\", \"0.008\"], [\"70385.30\", \"0.000\"], [\"70385.50\", \"0.135\"], [\"70385.60\", \"0.080\"], [\"70385.70\", \"0.001\"], [\"70385.80\", \"0.308\"], [\"70385.90\", \"0.461\"], [\"70386.00\", \"0.042\"], [\"70386.10\", \"0.001\"], [\"70386.20\", \"10.199\"], [\"70386.30\", \"0.007\"], [\"70386.40\", \"0.002\"], [\"70386.60\", \"0.000\"], [\"70386.70\", \"1.000\"], [\"70386.90\", \"0.000\"], [\"70387.10\", \"0.663\"], [\"70387.20\", \"0.846\"]], \"a\": [[\"70376.20\", \"0.000\"], [\"70376.50\", \"0.000\"], [\"70376.60\", \"0.000\"], [\"70376.70\", \"0.000\"], [\"70376.80\", \"0.000\"], [\"70376.90\", \"0.000\"], [\"70377.00\", \"0.000\"], [\"70377.20\", \"0.000\"], [\"70377.30\", \"0.000\"], [\"70377.40\", \"0.000\"], [\"70377.50\", \"0.000\"], [\"70377.90\", \"0.000\"], [\"70378.00\", \"0.000\"], [\"70378.20\", \"0.000\"], [\"70378.30\", \"0.000\"], [\"70378.40\", \"0.000\"], [\"70378.50\", \"0.000\"], [\"70378.60\", \"0.000\"], [\"70378.80\", \"0.000\"], [\"70378.90\", \"0.000\"], [\"70379.00\", \"0.000\"], [\"70379.40\", \"0.000\"], [\"70379.50\", \"0.000\"], [\"70379.60\", \"0.000\"], [\"70379.80\", \"0.000\"], [\"70380.00\", \"0.000\"], [\"70380.10\", \"0.000\"], [\"70380.40\", \"0.000\"], [\"70380.50\", \"0.000\"], [\"70380.60\", \"0.000\"], [\"70380.70\", \"0.000\"], [\"70380.80\", \"0.000\"], [\"70380.90\", \"0.000\"], [\"70381.00\", \"0.000\"], [\"70381.20\", \"0.000\"], [\"70381.30\", \"0.000\"], [\"70381.40\", \"0.000\"], [\"70381.50\", \"0.000\"], [\"70381.60\", \"0.000\"], [\"70381.70\", \"0.000\"], [\"70382.00\", \"0.000\"], [\"70382.10\", \"0.000\"], [\"70382.20\", \"0.000\"], [\"70382.30\", \"0.000\"], [\"70382.40\", \"0.000\"], [\"70382.50\", \"0.000\"], [\"70382.60\", \"0.000\"], [\"70382.70\", \"0.000\"], [\"70382.90\", \"0.000\"], [\"70383.00\", \"0.000\"], [\"70383.20\", \"0.000\"], [\"70383.40\", \"0.000\"], [\"70383.50\", \"0.000\"], [\"70383.60\", \"0.000\"], [\"70383.70\", \"0.000\"], [\"70383.80\", \"0.000\"], [\"70383.90\", \"0.000\"], [\"70384.00\", \"0.000\"], [\"70384.10\", \"0.000\"], [\"70384.20\", \"0.000\"], [\"70384.30\", \"0.000\"], [\"70384.40\", \"0.000\"], [\"70384.50\", \"0.000\"], [\"70384.60\", \"0.000\"], [\"70384.70\", \"0.000\"], [\"70384.80\", \"0.000\"], [\"70384.90\", \"0.000\"], [\"70385.00\", \"0.000\"], [\"70385.10\", \"0.000\"], [\"70385.20\", \"0.000\"], [\"70385.30\", \"0.000\"], [\"70385.40\", \"0.000\"], [\"70385.60\", \"0.000\"], [\"70385.70\", \"0.000\"], [\"70385.80\", \"0.000\"], [\"70386.00\", \"0.000\"], [\"70386.10\", \"0.000\"], [\"70386.30\", \"0.000\"], [\"70386.50\", \"0.000\"], [\"70386.60\", \"0.000\"], [\"70386.70\", \"0.000\"], [\"70386.80\", \"0.000\"], [\"70386.90\", \"0.000\"], [\"70387.00\", \"0.000\"], [\"70387.20\", \"0.000\"], [\"70387.30\", \"0.000\"], [\"70387.40\", \"0.000\"], [\"70387.50\", \"0.000\"], [\"70387.70\", \"0.003\"], [\"70387.80\", \"0.002\"], [\"70387.90\", \"0.002\"], [\"70388.00\", \"0.000\"], [\"70388.20\", \"0.006\"], [\"70388.30\", \"0.002\"], [\"70388.50\", \"0.005\"], [\"70388.70\", \"0.000\"], [\"70388.80\", \"0.003\"], [\"70389.00\", \"0.011\"], [\"70389.10\", \"0.000\"], [\"70389.20\", \"0.001\"], [\"70389.30\", \"0.000\"], [\"70389.50\", \"0.001\"], [\"70389.60\", \"0.002\"], [\"70389.80\", \"0.017\"], [\"70389.90\", \"0.049\"], [\"70390.10\", \"0.006\"], [\"70390.20\", \"0.002\"], [\"70390.30\", \"0.000\"], [\"70390.40\", \"0.001\"], [\"70390.50\", \"0.000\"], [\"70390.60\", \"0.005\"], [\"70390.70\", \"0.002\"], [\"70390.80\", \"0.000\"], [\"70390.90\", \"0.005\"], [\"70391.00\", \"0.045\"], [\"70391.20\", \"0.055\"], [\"70391.30\", \"0.006\"], [\"70391.40\", \"0.004\"], [\"70391.60\", \"0.003\"], [\"70391.70\", \"0.002\"], [\"70391.80\", \"0.001\"], [\"70391.90\", \"0.002\"], [\"70392.00\", \"0.005\"], [\"70392.20\", \"0.007\"], [\"70392.40\", \"0.008\"], [\"70392.50\", \"0.000\"], [\"70392.60\", \"0.005\"], [\"70392.70\", \"0.000\"], [\"70392.80\", \"0.167\"], [\"70393.00\", \"0.003\"], [\"70393.10\", \"0.000\"], [\"70393.20\", \"0.002\"], [\"70393.40\", \"0.004\"], [\"70393.80\", \"0.007\"], [\"70393.90\", \"0.008\"], [\"70394.00\", \"0.000\"], [\"70394.10\", \"0.002\"], [\"70394.30\", \"0.000\"], [\"70394.60\", \"0.001\"], [\"70394.70\", \"0.000\"], [\"70394.80\", \"0.003\"], [\"70394.90\", \"0.000\"], [\"70395.00\", \"0.007\"], [\"70395.10\", \"0.104\"], [\"70395.20\", \"0.002\"], [\"70395.30\", \"0.004\"], [\"70395.40\", \"0.009\"], [\"70395.80\", \"0.000\"], [\"70396.30\", \"0.514\"], [\"70396.40\", \"0.345\"], [\"70396.50\", \"0.002\"], [\"70396.60\", \"0.006\"], [\"70396.70\", \"0.000\"], [\"70396.90\", \"0.007\"], [\"70397.00\", \"0.002\"], [\"70397.10\", \"0.000\"], [\"70397.30\", \"0.000\"], [\"70397.40\", \"0.005\"], [\"70397.50\", \"0.004\"], [\"70397.60\", \"0.066\"], [\"70397.70\", \"0.002\"], [\"70398.00\", \"0.002\"], [\"70398.10\", \"0.065\"], [\"70398.20\", \"0.397\"], [\"70398.50\", \"0.002\"], [\"70398.60\", \"0.425\"], [\"70398.70\", \"0.511\"], [\"70398.80\", \"0.010\"], [\"70398.90\", \"0.003\"], [\"70399.10\", \"0.000\"], [\"70399.50\", \"0.003\"], [\"70399.70\", \"0.029\"], [\"70399.80\", \"0.004\"], [\"70400.00\", \"2.038\"], [\"70400.10\", \"0.000\"], [\"70400.20\", \"0.002\"], [\"70400.30\", \"0.218\"], [\"70400.50\", \"0.000\"], [\"70400.60\", \"0.002\"], [\"70400.90\", \"0.007\"], [\"70401.00\", \"0.007\"], [\"70401.30\", \"0.000\"], [\"70401.40\", \"0.004\"], [\"70401.70\", \"0.002\"], [\"70401.80\", \"0.000\"], [\"70402.00\", \"0.003\"], [\"70402.20\", \"0.060\"], [\"70402.30\", \"0.010\"], [\"70402.40\", \"0.002\"], [\"70402.50\", \"0.002\"], [\"70402.70\", \"0.266\"], [\"70402.80\", \"0.004\"], [\"70402.90\", \"0.003\"], [\"70403.00\", \"0.309\"], [\"70403.20\", \"0.000\"], [\"70403.40\", \"0.007\"], [\"70403.50\", \"0.007\"], [\"70403.60\", \"0.001\"], [\"70403.70\", \"0.005\"], [\"70403.90\", \"0.005\"], [\"70404.00\", \"0.000\"], [\"70404.10\", \"0.004\"], [\"70404.20\", \"0.002\"], [\"70404.50\", \"0.001\"], [\"70404.60\", \"0.000\"], [\"70404.70\", \"0.007\"], [\"70404.80\", \"0.296\"], [\"70405.00\", \"0.002\"], [\"70405.20\", \"0.123\"], [\"70405.30\", \"0.002\"], [\"70405.40\", \"0.002\"], [\"70405.50\", \"0.005\"], [\"70405.60\", \"0.025\"], [\"70405.70\", \"0.187\"], [\"70405.80\", \"0.004\"], [\"70405.90\", \"0.511\"], [\"70406.00\", \"0.004\"], [\"70406.50\", \"0.004\"], [\"70406.60\", \"0.002\"], [\"70406.70\", \"0.316\"], [\"70407.00\", \"0.006\"], [\"70407.20\", \"0.042\"], [\"70407.30\", \"0.002\"], [\"70407.40\", \"0.000\"], [\"70407.60\", \"0.003\"], [\"70407.70\", \"0.005\"], [\"70407.80\", \"0.010\"], [\"70408.00\", \"0.144\"], [\"70408.10\", \"0.000\"], [\"70408.30\", \"0.010\"], [\"70408.40\", \"0.560\"], [\"70408.60\", \"0.003\"], [\"70408.70\", \"0.002\"], [\"70408.80\", \"0.287\"], [\"70408.90\", \"0.049\"], [\"70409.00\", \"0.023\"], [\"70409.20\", \"0.901\"], [\"70409.30\", \"0.005\"], [\"70409.40\", \"0.012\"], [\"70409.70\", \"0.640\"], [\"70409.80\", \"0.003\"], [\"70409.90\", \"0.017\"], [\"70410.00\", \"0.017\"], [\"70410.10\", \"0.002\"], [\"70410.20\", \"0.000\"], [\"70410.30\", \"0.000\"], [\"70410.40\", \"0.000\"], [\"70410.50\", \"0.000\"], [\"70410.70\", \"0.013\"], [\"70410.90\", \"0.002\"], [\"70411.00\", \"0.003\"], [\"70411.10\", \"0.002\"], [\"70411.20\", \"0.002\"], [\"70411.40\", \"0.005\"], [\"70411.60\", \"0.003\"], [\"70411.70\", \"0.003\"], [\"70411.80\", \"0.014\"], [\"70411.90\", \"0.206\"], [\"70412.00\", \"0.002\"], [\"70412.30\", \"0.073\"], [\"70412.40\", \"0.003\"], [\"70412.60\", \"0.002\"], [\"70412.80\", \"0.198\"], [\"70413.00\", \"1.074\"], [\"70413.10\", \"0.002\"], [\"70413.20\", \"0.002\"], [\"70413.40\", \"0.344\"], [\"70413.50\", \"0.000\"], [\"70413.60\", \"0.002\"], [\"70413.70\", \"0.001\"], [\"70413.80\", \"0.000\"], [\"70413.90\", \"0.005\"], [\"70414.20\", \"0.023\"], [\"70414.30\", \"0.012\"], [\"70414.40\", \"0.025\"], [\"70414.50\", \"0.000\"], [\"70414.90\", \"0.002\"], [\"70415.00\", \"0.005\"], [\"70415.10\", \"0.593\"], [\"70415.40\", \"0.516\"], [\"70415.50\", \"0.002\"], [\"70415.70\", \"0.013\"], [\"70415.80\", \"0.009\"], [\"70415.90\", \"0.010\"], [\"70416.00\", \"0.238\"], [\"70416.10\", \"0.301\"], [\"70416.30\", \"0.002\"], [\"70416.50\", \"0.770\"], [\"70416.60\", \"0.006\"], [\"70416.70\", \"0.002\"], [\"70416.80\", \"0.226\"], [\"70416.90\", \"0.071\"], [\"70417.00\", \"0.004\"], [\"70417.10\", \"0.003\"], [\"70417.20\", \"0.002\"], [\"70417.30\", \"0.002\"], [\"70417.40\", \"0.012\"], [\"70417.50\", \"0.250\"], [\"70417.80\", \"0.514\"], [\"70417.90\", \"0.006\"], [\"70418.00\", \"0.381\"], [\"70418.10\", \"0.003\"], [\"70418.20\", \"0.008\"], [\"70418.30\", \"0.262\"], [\"70418.40\", \"0.243\"], [\"70418.50\", \"0.002\"], [\"70418.60\", \"0.219\"], [\"70418.70\", \"0.002\"], [\"70418.80\", \"0.000\"], [\"70418.90\", \"0.294\"], [\"70419.00\", \"0.171\"], [\"70419.30\", \"0.002\"], [\"70419.40\", \"0.111\"], [\"70419.80\", \"0.348\"], [\"70420.00\", \"0.893\"], [\"70420.20\", \"0.025\"], [\"70420.50\", \"0.013\"], [\"70420.60\", \"0.005\"], [\"70420.70\", \"0.025\"], [\"70420.80\", \"0.099\"], [\"70421.00\", \"0.002\"], [\"70421.10\", \"0.220\"], [\"70421.30\", \"0.001\"], [\"70421.40\", \"0.092\"], [\"70421.50\", \"0.000\"], [\"70421.90\", \"0.011\"], [\"70422.00\", \"2.846\"], [\"70422.40\", \"0.003\"], [\"70422.80\", \"0.002\"], [\"70422.90\", \"0.002\"], [\"70423.50\", \"0.004\"], [\"70423.70\", \"0.594\"], [\"70424.60\", \"0.000\"], [\"70425.00\", \"0.017\"], [\"70425.10\", \"0.092\"], [\"70425.50\", \"0.022\"], [\"70425.60\", \"0.102\"], [\"70425.90\", \"0.527\"], [\"70426.10\", \"0.199\"], [\"70426.20\", \"0.000\"], [\"70426.30\", \"0.004\"], [\"70426.40\", \"0.052\"], [\"70426.50\", \"0.087\"], [\"70426.60\", \"0.000\"], [\"70426.70\", \"0.315\"], [\"70426.80\", \"0.002\"], [\"70426.90\", \"0.004\"], [\"70427.00\", \"0.002\"], [\"70428.40\", \"0.002\"], [\"70428.90\", \"0.001\"], [\"70429.50\", \"0.002\"], [\"70429.80\", \"0.000\"], [\"70430.60\", \"2.759\"], [\"70430.90\", \"0.250\"], [\"70431.00\", \"0.002\"], [\"70431.50\", \"0.192\"], [\"70431.60\", \"0.001\"], [\"70431.80\", \"0.089\"], [\"70432.10\", \"1.513\"], [\"70432.40\", \"0.198\"], [\"70432.70\", \"0.188\"], [\"70433.50\", \"0.002\"], [\"70433.60\", \"0.081\"], [\"70433.90\", \"0.006\"], [\"70434.10\", \"0.005\"], [\"70434.20\", \"0.481\"], [\"70434.30\", \"0.000\"], [\"70434.70\", \"0.197\"], [\"70434.90\", \"0.384\"], [\"70435.00\", \"0.203\"], [\"70435.40\", \"0.000\"], [\"70435.60\", \"0.344\"], [\"70435.90\", \"0.000\"], [\"70436.50\", \"0.015\"], [\"70436.60\", \"0.006\"], [\"70436.70\", \"0.256\"], [\"70437.00\", \"0.002\"], [\"70437.20\", \"0.004\"], [\"70437.40\", \"0.002\"], [\"70437.50\", \"0.476\"], [\"70437.60\", \"0.002\"], [\"70437.80\", \"0.003\"], [\"70438.60\", \"0.131\"], [\"70439.40\", \"0.020\"], [\"70439.80\", \"0.070\"], [\"70440.50\", \"0.004\"], [\"70440.90\", \"0.230\"], [\"70441.20\", \"0.002\"], [\"70441.40\", \"0.307\"], [\"70442.00\", \"0.791\"], [\"70442.10\", \"0.004\"], [\"70442.60\", \"0.083\"], [\"70442.90\", \"0.000\"], [\"70443.10\", \"0.002\"], [\"70443.30\", \"0.105\"], [\"70443.40\", \"0.010\"], [\"70443.60\", \"0.003\"], [\"70444.10\", \"0.369\"], [\"70444.40\", \"0.004\"], [\"70444.60\", \"0.232\"], [\"70444.70\", \"0.198\"], [\"70445.30\", \"0.000\"], [\"70445.80\", \"0.566\"], [\"70447.20\", \"0.004\"], [\"70447.60\", \"0.038\"], [\"70447.80\", \"0.000\"], [\"70448.00\", \"0.115\"], [\"70448.20\", \"0.000\"], [\"70448.40\", \"0.004\"], [\"70449.10\", \"0.195\"], [\"70449.30\", \"0.048\"], [\"70449.50\", \"0.000\"], [\"70450.40\", \"0.000\"], [\"70450.60\", \"0.000\"], [\"70451.30\", \"0.342\"], [\"70451.50\", \"0.003\"], [\"70451.60\", \"0.000\"], [\"70451.90\", \"0.002\"], [\"70452.50\", \"0.000\"], [\"70453.10\", \"0.002\"], [\"70453.50\", \"0.004\"], [\"70453.80\", \"0.280\"], [\"70454.80\", \"0.000\"], [\"70455.10\", \"1.000\"], [\"70455.30\", \"0.068\"], [\"70455.70\", \"0.006\"], [\"70456.00\", \"0.087\"], [\"70456.10\", \"0.002\"], [\"70456.50\", \"0.049\"], [\"70456.60\", \"0.641\"], [\"70457.20\", \"0.000\"], [\"70457.30\", \"0.005\"], [\"70457.40\", \"0.090\"], [\"70457.50\", \"0.240\"], [\"70457.80\", \"0.007\"], [\"70458.40\", \"0.047\"], [\"70458.70\", \"0.001\"], [\"70458.90\", \"0.049\"], [\"70459.50\", \"0.000\"], [\"70459.60\", \"0.003\"], [\"70460.30\", \"0.008\"], [\"70461.30\", \"0.007\"], [\"70461.80\", \"0.090\"], [\"70462.00\", \"0.010\"], [\"70462.40\", \"0.049\"], [\"70462.50\", \"0.041\"], [\"70463.90\", \"0.089\"], [\"70464.10\", \"0.006\"], [\"70465.40\", \"0.514\"], [\"70465.70\", \"0.000\"], [\"70466.20\", \"0.002\"], [\"70467.20\", \"0.000\"], [\"70467.40\", \"0.071\"], [\"70467.50\", \"0.002\"], [\"70468.60\", \"0.099\"], [\"70468.90\", \"0.041\"], [\"70469.80\", \"0.257\"], [\"70470.50\", \"0.170\"], [\"70470.80\", \"1.502\"], [\"70471.00\", \"0.097\"], [\"70471.20\", \"0.101\"], [\"70471.50\", \"0.348\"], [\"70471.60\", \"0.000\"], [\"70473.40\", \"0.000\"], [\"70474.40\", \"0.156\"], [\"70474.80\", \"0.000\"], [\"70475.10\", \"7.890\"], [\"70475.60\", \"0.016\"], [\"70475.90\", \"0.201\"], [\"70478.30\", \"0.000\"], [\"70478.40\", \"0.002\"], [\"70479.00\", \"0.010\"], [\"70479.10\", \"0.081\"], [\"70479.90\", \"0.094\"], [\"70480.50\", \"0.002\"], [\"70480.70\", \"0.079\"], [\"70481.50\", \"0.347\"], [\"70481.70\", \"0.182\"], [\"70482.30\", \"0.000\"], [\"70483.90\", \"0.000\"], [\"70484.10\", \"0.003\"], [\"70484.80\", \"2.126\"], [\"70485.50\", \"0.080\"], [\"70490.50\", \"0.034\"], [\"70491.30\", \"0.006\"], [\"70492.20\", \"0.000\"], [\"70493.20\", \"0.002\"], [\"70493.50\", \"0.002\"], [\"70493.90\", \"0.000\"], [\"70495.30\", \"2.135\"], [\"70495.40\", \"0.000\"], [\"70495.60\", \"0.515\"], [\"70495.90\", \"0.272\"], [\"70497.70\", \"0.004\"], [\"70498.90\", \"0.094\"], [\"70499.20\", \"0.126\"], [\"70499.60\", \"0.233\"], [\"70499.80\", \"13.637\"], [\"70501.70\", \"0.090\"], [\"70501.80\", \"0.419\"], [\"70501.90\", \"0.252\"], [\"70502.60\", \"0.518\"], [\"70503.80\", \"0.000\"], [\"70504.70\", \"0.264\"], [\"70505.50\", \"0.000\"], [\"70505.80\", \"0.090\"], [\"70507.70\", \"0.002\"], [\"70508.20\", \"0.000\"], [\"70508.30\", \"0.134\"], [\"70510.50\", \"0.010\"], [\"70511.40\", \"1.296\"], [\"70511.80\", \"0.202\"], [\"70512.80\", \"2.000\"], [\"70513.10\", \"0.168\"], [\"70514.70\", \"0.000\"], [\"70516.80\", \"0.000\"], [\"70517.40\", \"10.057\"], [\"70518.30\", \"0.003\"], [\"70518.40\", \"0.081\"], [\"70518.90\", \"0.246\"], [\"70520.30\", \"0.000\"], [\"70521.70\", \"0.006\"], [\"70521.80\", \"0.000\"], [\"70522.60\", \"0.130\"], [\"70523.30\", \"23.172\"], [\"70523.80\", \"2.002\"], [\"70524.10\", \"0.002\"], [\"70524.20\", \"0.042\"], [\"70527.60\", \"0.018\"], [\"70527.70\", \"0.002\"], [\"70528.30\", \"0.225\"], [\"70528.40\", \"8.381\"], [\"70529.10\", \"0.003\"], [\"70529.90\", \"0.000\"], [\"70530.50\", \"5.284\"], [\"70530.80\", \"0.000\"], [\"70531.90\", \"0.267\"], [\"70532.20\", \"0.042\"], [\"70532.40\", \"2.587\"], [\"70532.60\", \"0.000\"], [\"70533.70\", \"0.003\"], [\"70534.40\", \"0.205\"], [\"70534.50\", \"0.194\"], [\"70534.90\", \"0.194\"], [\"70535.00\", \"10.083\"], [\"70535.60\", \"0.000\"], [\"70538.90\", \"0.017\"], [\"70539.20\", \"0.000\"], [\"70539.50\", \"0.225\"], [\"70540.00\", \"0.013\"], [\"70540.90\", \"0.511\"], [\"70541.80\", \"0.000\"], [\"70543.00\", \"0.082\"], [\"70545.40\", \"0.004\"], [\"70546.00\", \"0.633\"], [\"70546.50\", \"0.000\"], [\"70547.30\", \"0.004\"], [\"70547.80\", \"0.000\"], [\"70548.00\", \"0.002\"], [\"70549.40\", \"0.000\"], [\"70550.20\", \"0.121\"], [\"70556.70\", \"2.100\"], [\"70557.20\", \"0.000\"], [\"70557.40\", \"5.031\"], [\"70558.60\", \"0.163\"], [\"70558.70\", \"3.552\"], [\"70559.60\", \"13.218\"], [\"70561.00\", \"0.039\"], [\"70563.60\", \"1.677\"], [\"70566.80\", \"0.025\"], [\"70566.90\", \"0.107\"], [\"70568.00\", \"0.082\"], [\"70568.10\", \"0.025\"], [\"70569.20\", \"0.042\"], [\"70570.10\", \"0.366\"], [\"70573.00\", \"0.171\"], [\"70574.70\", \"0.003\"], [\"70578.20\", \"0.003\"], [\"70578.50\", \"0.164\"], [\"70582.30\", \"0.002\"], [\"70582.90\", \"0.436\"], [\"70588.00\", \"1.499\"], [\"70588.10\", \"0.193\"], [\"70588.30\", \"0.003\"], [\"70589.30\", \"0.002\"], [\"70589.60\", \"5.259\"], [\"70589.70\", \"34.963\"], [\"70591.40\", \"0.202\"], [\"70591.50\", \"0.000\"], [\"70592.00\", \"0.002\"], [\"70594.10\", \"0.143\"], [\"70595.40\", \"0.004\"], [\"70598.00\", \"0.125\"], [\"70598.50\", \"4.177\"], [\"70599.40\", \"0.000\"], [\"70602.40\", \"0.025\"], [\"70606.40\", \"0.004\"], [\"70609.10\", \"0.044\"], [\"70611.30\", \"0.000\"], [\"70612.50\", \"2.659\"], [\"70612.60\", \"10.000\"], [\"70614.10\", \"0.206\"], [\"70619.80\", \"1.695\"], [\"70620.30\", \"0.003\"], [\"70630.80\", \"8.990\"], [\"70632.00\", \"35.734\"], [\"70640.60\", \"2.688\"], [\"70643.60\", \"17.217\"], [\"70659.80\", \"0.200\"], [\"70663.40\", \"0.309\"], [\"70667.00\", \"0.200\"], [\"70670.60\", \"0.399\"], [\"70674.30\", \"0.190\"], [\"70676.20\", \"0.107\"], [\"70676.40\", \"0.382\"], [\"70680.50\", \"0.190\"], [\"70681.50\", \"0.193\"], [\"70681.90\", \"0.186\"], [\"70733.60\", \"0.002\"], [\"70750.80\", \"0.002\"], [\"70751.10\", \"0.002\"], [\"70757.90\", \"0.038\"], [\"70761.60\", \"0.025\"], [\"70767.90\", \"0.004\"], [\"70768.40\", \"0.002\"], [\"70768.80\", \"0.000\"], [\"70804.10\", \"0.112\"], [\"70950.00\", \"2.593\"], [\"71083.00\", \"0.003\"], [\"71089.80\", \"0.002\"], [\"71224.80\", \"0.000\"], [\"71264.00\", \"1.429\"], [\"71326.90\", \"0.000\"], [\"71330.00\", \"0.490\"], [\"71364.30\", \"0.971\"], [\"71367.00\", \"0.009\"], [\"71367.80\", \"2.637\"], [\"71368.00\", \"0.825\"], [\"71368.70\", \"0.000\"], [\"71368.80\", \"3.921\"], [\"71368.90\", \"0.419\"], [\"71403.10\", \"0.971\"], [\"71404.60\", \"4.855\"], [\"71405.30\", \"0.971\"], [\"71432.40\", \"0.000\"], [\"71439.20\", \"0.000\"], [\"71470.50\", \"1.944\"], [\"71474.30\", \"0.978\"], [\"71476.30\", \"0.970\"], [\"71502.70\", \"0.000\"], [\"71510.10\", \"0.969\"], [\"71540.20\", \"1.938\"], [\"74468.30\", \"0.000\"], [\"74642.70\", \"0.000\"]]}", "symbol": "BTCUSDT"}
{"event": "depthUpdate", "raw_payload": "{\"e\": \"depthUpdate\", \"E\": 1773246394858, \"T\": 1773246394857, \"s\": \"BTCUSDT\", \"U\": 10089704705902, \"u\": 10089704737125, \"pu\": 10089704705895, \"b\": [[\"5000.00\", \"101.418\"], [\"19867.10\", \"0.000\"], [\"20086.20\", \"0.020\"], [\"20087.40\", \"0.010\"], [\"20088.40\", \"0.010\"], [\"20088.90\", \"0.010\"], [\"20090.10\", \"0.010\"], [\"20090.80\", \"0.020\"], [\"20091.80\", \"0.110\"], [\"20167.10\", \"0.540\"], [\"20191.80\", \"0.050\"], [\"20285.80\", \"0.000\"], [\"20286.20\", \"0.000\"], [\"20288.40\", \"0.000\"], [\"20290.80\", \"0.000\"], [\"20291.50\", \"0.000\"], [\"40000.00\", \"50.522\"], [\"63352.60\", \"0.002\"], [\"66820.80\", \"0.029\"], [\"66831.30\", \"0.004\"], [\"66872.00\", \"0.022\"], [\"69372.90\", \"1.356\"], [\"69374.80\", \"0.720\"], [\"69376.10\", \"0.000\"], [\"69376.40\", \"0.006\"], [\"69376.80\", \"0.002\"], [\"69380.00\", \"0.352\"], [\"69380.70\", \"0.000\"], [\"69382.60\", \"1.439\"], [\"69388.40\", \"0.008\"], [\"69388.90\", \"0.022\"], [\"69390.80\", \"0.014\"], [\"69391.00\", \"0.006\"], [\"69391.80\", \"0.016\"], [\"69500.00\", \"89.275\"], [\"69597.80\", \"0.004\"], [\"69628.20\", \"0.000\"], [\"69682.10\", \"0.000\"], [\"69687.90\", \"1.136\"], [\"69699.90\", \"20.303\"], [\"69731.90\", \"0.003\"], [\"69775.00\", \"0.106\"], [\"69827.70\", \"3.720\"], [\"69911.10\", \"0.005\"], [\"70005.60\", \"0.000\"], [\"70017.30\", \"0.000\"], [\"70018.20\", \"0.000\"], [\"70026.10\", \"1.261\"], [\"70038.40\", \"0.021\"], [\"70038.50\", \"0.281\"], [\"70060.40\", \"0.000\"], [\"70061.80\", \"0.034\"], [\"70062.90\", \"0.010\"], [\"70070.00\", \"6.964\"], [\"70072.40\", \"1.067\"], [\"70084.00\", \"0.002\"], [\"70088.00\", \"0.045\"], [\"70099.70\", \"1.704\"], [\"70109.00\", \"0.648\"], [\"70117.30\", \"0.011\"], [\"70117.60\", \"0.019\"], [\"70118.00\", \"1.398\"], [\"70120.90\", \"0.000\"], [\"70133.00\", \"2.812\"], [\"70146.20\", \"0.000\"], [\"70150.60\", \"10.704\"], [\"70153.90\", \"1.818\"], [\"70159.50\", \"1.413\"], [\"70159.80\", \"0.000\"], [\"70160.20\", \"0.000\"], [\"70167.80\", \"6.339\"], [\"70171.40\", \"0.003\"], [\"70172.50\", \"0.000\"], [\"70174.40\", \"0.000\"], [\"70176.20\", \"0.018\"], [\"70177.60\", \"0.000\"], [\"70178.40\", \"35.407\"], [\"70178.50\", \"0.163\"], [\"70179.80\", \"0.000\"], [\"70179.90\", \"1.488\"], [\"70185.40\", \"0.020\"], [\"70186.90\", \"0.000\"], [\"70192.80\", \"7.800\"], [\"70193.70\", \"0.000\"], [\"70196.00\", \"2.607\"], [\"70196.70\", \"0.004\"], [\"70197.10\", \"1.243\"], [\"70198.50\", \"0.022\"], [\"70200.70\", \"0.000\"], [\"70202.00\", \"0.000\"], [\"70202.40\", \"0.000\"], [\"70202.70\", \"3.674\"], [\"70202.80\", \"0.086\"], [\"70204.00\", \"0.188\"], [\"70204.60\", \"2.373\"], [\"70205.50\", \"0.496\"], [\"70205.80\", \"0.000\"], [\"70207.40\", \"10.000\"], [\"70208.80\", \"0.053\"], [\"70209.20\", \"0.000\"], [\"70210.00\", \"4.872\"], [\"70210.80\", \"0.282\"], [\"70212.50\", \"0.004\"], [\"70213.60\", \"2.155\"], [\"70213.90\", \"0.085\"], [\"70231.50\", \"0.000\"], [\"70231.80\", \"0.045\"], [\"70232.10\", \"0.209\"], [\"70233.50\", \"0.000\"], [\"70234.00\", \"2.456\"], [\"70234.40\", \"0.039\"], [\"70235.00\", \"4.306\"], [\"70236.30\", \"0.084\"], [\"70237.50\", \"0.105\"], [\"70238.20\", \"0.083\"], [\"70248.80\", \"0.097\"], [\"70249.30\", \"0.262\"], [\"70250.90\", \"0.000\"], [\"70254.30\", \"0.344\"], [\"70255.50\", \"0.497\"], [\"70257.80\", \"0.042\"], [\"70258.90\", \"6.535\"], [\"70259.50\", \"0.159\"], [\"70262.50\", \"0.619\"], [\"70265.10\", \"0.079\"], [\"70267.20\", \"0.099\"], [\"70267.60\", \"0.414\"], [\"70267.90\", \"0.039\"], [\"70270.40\", \"0.000\"], [\"70274.30\", \"0.115\"], [\"70275.20\", \"0.082\"], [\"70275.30\", \"0.035\"], [\"70278.00\", \"0.599\"], [\"70279.00\", \"0.002\"], [\"70279.10\", \"0.000\"], [\"70279.70\", \"0.228\"], [\"70281.10\", \"1.328\"], [\"70283.10\", \"0.004\"], [\"70283.20\", \"0.004\"], [\"70284.70\", \"0.000\"], [\"70284.90\", \"1.330\"], [\"70286.00\", \"3.983\"], [\"70286.10\", \"0.090\"], [\"70287.70\", \"0.248\"], [\"70288.30\", \"0.474\"], [\"70290.90\", \"0.214\"], [\"70291.00\", \"0.071\"], [\"70291.50\", \"0.002\"], [\"70292.30\", \"0.363\"], [\"70292.80\", \"10.736\"], [\"70293.10\", \"1.203\"], [\"70293.50\", \"0.109\"], [\"70293.60\", \"0.170\"], [\"70294.00\", \"2.972\"], [\"70296.90\", \"1.099\"], [\"70297.10\", \"0.082\"], [\"70297.40\", \"0.082\"], [\"70297.70\", \"0.000\"], [\"70298.00\", \"0.118\"], [\"70298.20\", \"0.082\"], [\"70298.40\", \"0.007\"], [\"70298.50\", \"0.014\"], [\"70299.80\", \"0.000\"], [\"70300.10\", \"0.000\"], [\"70300.80\", \"0.082\"], [\"70303.50\", \"0.347\"], [\"70303.70\", \"0.248\"], [\"70303.80\", \"0.086\"], [\"70303.90\", \"0.055\"], [\"70304.10\", \"0.002\"], [\"70304.40\", \"0.000\"], [\"70304.50\", \"0.148\"], [\"70304.90\", \"0.002\"], [\"70306.20\", \"0.041\"], [\"70306.70\", \"0.000\"], [\"70307.90\", \"0.087\"], [\"70309.10\", \"0.200\"], [\"70309.40\", \"1.061\"], [\"70310.20\", \"0.000\"], [\"70310.50\", \"0.000\"], [\"70310.70\", \"0.723\"], [\"70310.80\", \"0.134\"], [\"70310.90\", \"0.004\"], [\"70311.60\", \"0.085\"], [\"70311.70\", \"0.106\"], [\"70313.00\", \"0.511\"], [\"70313.70\", \"0.003\"], [\"70314.90\", \"0.003\"], [\"70315.30\", \"0.539\"], [\"70316.00\", \"0.342\"], [\"70317.00\", \"0.010\"], [\"70317.50\", \"0.203\"], [\"70317.60\", \"0.512\"], [\"70318.00\", \"0.041\"], [\"70318.60\", \"0.003\"], [\"70318.70\", \"0.158\"], [\"70319.10\", \"0.179\"], [\"70319.50\", \"0.075\"], [\"70320.20\", \"0.077\"], [\"70320.70\", \"0.000\"], [\"70321.20\", \"0.124\"], [\"70321.30\", \"0.131\"], [\"70321.80\", \"0.514\"], [\"70322.00\", \"0.002\"], [\"70322.20\", \"0.020\"], [\"70322.90\", \"0.001\"], [\"70323.30\", \"0.078\"], [\"70324.80\", \"0.002\"], [\"70325.10\", \"0.000\"], [\"70325.30\", \"0.007\"], [\"70326.10\", \"0.004\"], [\"70326.30\", \"0.027\"], [\"70326.40\", \"0.194\"], [\"70326.60\", \"0.000\"], [\"70326.90\", \"0.000\"], [\"70328.40\", \"0.042\"], [\"70328.60\", \"1.052\"], [\"70328.70\", \"0.305\"], [\"70328.90\", \"0.007\"], [\"70329.00\", \"0.009\"], [\"70329.70\", \"0.006\"], [\"70329.80\", \"0.007\"], [\"70329.90\", \"0.084\"], [\"70330.00\", \"0.127\"], [\"70330.40\", \"0.382\"], [\"70331.20\", \"0.002\"], [\"70331.30\", \"0.002\"], [\"70331.50\", \"0.000\"], [\"70332.10\", \"0.004\"], [\"70332.20\", \"0.000\"], [\"70332.40\", \"0.939\"], [\"70332.90\", \"0.000\"], [\"70333.00\", \"0.000\"], [\"70333.60\", \"0.000\"], [\"70333.80\", \"0.063\"], [\"70333.90\", \"0.000\"], [\"70334.00\", \"0.103\"], [\"70334.10\", \"0.205\"], [\"70334.30\", \"0.000\"], [\"70334.40\", \"0.574\"], [\"70334.60\", \"0.560\"], [\"70335.00\", \"0.005\"], [\"70335.20\", \"0.344\"], [\"70335.50\", \"0.048\"], [\"70335.90\", \"0.010\"], [\"70336.10\", \"0.005\"], [\"70336.30\", \"0.000\"], [\"70336.60\", \"0.021\"], [\"70336.80\", \"0.515\"], [\"70336.90\", \"0.029\"], [\"70337.10\", \"1.068\"], [\"70337.30\", \"0.034\"], [\"70337.50\", \"0.016\"], [\"70337.70\", \"0.004\"], [\"70337.90\", \"0.000\"], [\"70338.10\", \"0.000\"], [\"70338.50\", \"0.000\"], [\"70338.60\", \"0.003\"], [\"70338.70\", \"0.194\"], [\"70338.80\", \"0.017\"], [\"70338.90\", \"0.408\"], [\"70339.00\", \"1.041\"], [\"70339.20\", \"0.036\"], [\"70339.80\", \"0.003\"], [\"70340.10\", \"0.002\"], [\"70340.50\", \"0.146\"], [\"70340.80\", \"0.024\"], [\"70341.80\", \"0.015\"], [\"70342.00\", \"0.005\"], [\"70342.40\", \"0.195\"], [\"70343.60\", \"0.003\"], [\"70343.90\", \"0.000\"], [\"70344.10\", \"0.040\"], [\"70345.30\", \"0.711\"], [\"70346.00\", \"0.004\"], [\"70346.10\", \"0.015\"], [\"70347.20\", \"0.001\"], [\"70347.40\", \"0.237\"], [\"70347.80\", \"0.006\"], [\"70348.10\", \"0.004\"], [\"70348.60\", \"0.005\"], [\"70348.70\", \"0.450\"], [\"70349.50\", \"1.851\"], [\"70350.00\", \"0.006\"], [\"70350.10\", \"0.042\"], [\"70350.20\", \"0.000\"], [\"70350.60\", \"0.010\"], [\"70350.80\", \"0.002\"], [\"70351.10\", \"0.004\"], [\"70351.30\", \"0.007\"], [\"70351.40\", \"0.000\"], [\"70351.90\", \"0.006\"], [\"70352.00\", \"0.009\"], [\"70352.10\", \"0.009\"], [\"70352.30\", \"0.007\"], [\"70352.40\", \"0.004\"], [\"70352.50\", \"0.000\"], [\"70352.80\", \"0.515\"], [\"70353.10\", \"0.490\"], [\"70353.50\", \"0.008\"], [\"70353.60\", \"0.550\"], [\"70353.70\", \"0.130\"], [\"70353.90\", \"0.100\"], [\"70354.20\", \"0.024\"], [\"70354.30\", \"0.019\"], [\"70354.40\", \"0.022\"], [\"70354.50\", \"0.064\"], [\"70354.60\", \"0.002\"], [\"70354.70\", \"0.010\"], [\"70355.00\", \"0.000\"], [\"70355.20\", \"1.121\"], [\"70355.30\", \"0.018\"], [\"70355.40\", \"0.004\"], [\"70355.60\", \"0.000\"], [\"70355.80\", \"0.000\"], [\"70355.90\", \"0.000\"], [\"70356.50\", \"0.395\"], [\"70356.60\", \"0.113\"], [\"70357.20\", \"0.000\"], [\"70357.40\", \"0.283\"], [\"70357.50\", \"0.005\"], [\"70357.90\", \"0.200\"], [\"70358.00\", \"0.003\"], [\"70359.00\", \"0.242\"], [\"70359.10\", \"0.000\"], [\"70359.30\", \"0.006\"], [\"70359.40\", \"0.039\"], [\"70359.60\", \"0.058\"], [\"70359.70\", \"0.000\"], [\"70360.00\", \"0.006\"], [\"70360.20\", \"0.199\"], [\"70360.30\", \"0.191\"], [\"70360.40\", \"0.000\"], [\"70360.50\", \"0.549\"], [\"70360.90\", \"1.101\"], [\"70361.10\", \"0.002\"], [\"70361.20\", \"0.000\"], [\"70361.30\", \"0.010\"], [\"70362.10\", \"0.192\"], [\"70362.20\", \"0.000\"], [\"70362.40\", \"0.008\"], [\"70362.50\", \"0.003\"], [\"70362.60\", \"0.002\"], [\"70362.70\", \"0.002\"], [\"70363.60\", \"0.602\"], [\"70363.90\", \"0.256\"], [\"70364.00\", \"0.009\"], [\"70364.40\", \"0.003\"], [\"70364.60\", \"0.000\"], [\"70364.70\", \"0.010\"], [\"70365.00\", \"0.004\"], [\"70365.50\", \"0.000\"], [\"70365.70\", \"0.000\"], [\"70365.80\", \"0.047\"], [\"70366.00\", \"0.002\"], [\"70366.10\", \"0.061\"], [\"70366.20\", \"0.000\"], [\"70366.40\", \"0.349\"], [\"70366.50\", \"0.001\"], [\"70366.60\", \"0.071\"], [\"70366.70\", \"0.000\"], [\"70366.80\", \"0.002\"], [\"70367.00\", \"0.093\"], [\"70367.10\", \"0.140\"], [\"70367.20\", \"0.000\"], [\"70367.30\", \"0.248\"], [\"70367.40\", \"0.002\"], [\"70367.50\", \"0.514\"], [\"70367.60\", \"0.074\"], [\"70367.70\", \"0.202\"], [\"70368.00\", \"1.069\"], [\"70368.10\", \"0.557\"], [\"70368.20\", \"0.005\"], [\"70368.40\", \"0.029\"], [\"70368.60\", \"0.001\"], [\"70368.70\", \"0.000\"], [\"70368.80\", \"0.000\"], [\"70368.90\", \"0.000\"], [\"70369.10\", \"0.055\"], [\"70369.20\", \"0.036\"], [\"70369.50\", \"0.000\"], [\"70369.60\", \"0.384\"], [\"70369.70\", \"0.001\"], [\"70369.80\", \"0.002\"], [\"70369.90\", \"0.000\"], [\"70370.00\", \"0.280\"], [\"70370.10\", \"0.181\"], [\"70370.20\", \"0.639\"], [\"70370.30\", \"0.041\"], [\"70370.40\", \"0.004\"], [\"70370.50\", \"0.003\"], [\"70370.60\", \"0.461\"], [\"70370.70\", \"0.080\"], [\"70370.80\", \"0.040\"], [\"70370.90\", \"0.010\"], [\"70371.10\", \"0.043\"], [\"70371.30\", \"0.049\"], [\"70371.40\", \"0.047\"], [\"70371.50\", \"0.035\"], [\"70371.70\", \"0.040\"], [\"70371.80\", \"0.000\"], [\"70371.90\", \"0.002\"], [\"70372.00\", \"0.002\"], [\"70372.10\", \"0.342\"], [\"70372.20\", \"0.001\"], [\"70372.50\", \"0.007\"], [\"70372.60\", \"0.002\"], [\"70372.70\", \"0.003\"], [\"70372.90\", \"0.048\"], [\"70373.00\", \"0.005\"], [\"70373.30\", \"0.009\"], [\"70373.60\", \"0.006\"], [\"70373.70\", \"1.066\"], [\"70373.80\", \"0.356\"], [\"70373.90\", \"0.110\"], [\"70374.10\", \"0.000\"], [\"70374.70\", \"0.003\"], [\"70374.80\", \"0.131\"], [\"70374.90\", \"0.002\"], [\"70375.00\", \"0.087\"], [\"70375.10\", \"0.007\"], [\"70375.50\", \"0.000\"], [\"70375.70\", \"0.000\"], [\"70376.00\", \"0.008\"], [\"70376.20\", \"0.241\"], [\"70376.30\", \"0.002\"], [\"70376.50\", \"0.003\"], [\"70376.60\", \"0.002\"], [\"70376.70\", \"1.214\"], [\"70376.80\", \"0.407\"], [\"70376.90\", \"0.321\"], [\"70377.00\", \"0.302\"], [\"70377.20\", \"0.319\"], [\"70377.30\", \"0.002\"], [\"70377.40\", \"0.003\"], [\"70377.50\", \"0.127\"], [\"70377.60\", \"0.007\"], [\"70377.70\", \"0.106\"], [\"70377.80\", \"0.210\"], [\"70378.00\", \"0.326\"], [\"70378.10\", \"0.324\"], [\"70378.20\", \"0.320\"], [\"70378.30\", \"0.342\"], [\"70378.50\", \"0.000\"], [\"70378.70\", \"0.003\"], [\"70378.80\", \"0.000\"], [\"70378.90\", \"0.002\"], [\"70379.00\", \"0.005\"], [\"70379.10\", \"0.001\"], [\"70379.20\", \"0.000\"], [\"70379.30\", \"0.000\"], [\"70379.40\", \"0.001\"], [\"70379.70\", \"0.002\"], [\"70379.80\", \"0.000\"], [\"70379.90\", \"0.081\"], [\"70380.00\", \"0.016\"], [\"70380.10\", \"0.004\"], [\"70380.20\", \"0.284\"], [\"70380.30\", \"0.005\"], [\"70380.40\", \"0.000\"], [\"70380.50\", \"0.002\"], [\"70380.60\", \"0.003\"], [\"70380.70\", \"0.038\"], [\"70380.80\", \"0.142\"], [\"70381.10\", \"0.000\"], [\"70381.20\", \"0.003\"], [\"70381.40\", \"0.002\"], [\"70381.80\", \"0.002\"], [\"70381.90\", \"0.202\"], [\"70382.10\", \"0.071\"], [\"70382.40\", \"0.017\"], [\"70382.50\", \"0.059\"], [\"70382.60\", \"0.003\"], [\"70382.70\", \"0.016\"], [\"70382.90\", \"0.007\"], [\"70383.00\", \"0.000\"], [\"70383.30\", \"0.002\"], [\"70383.50\", \"0.007\"], [\"70383.60\", \"0.000\"], [\"70383.70\", \"0.001\"], [\"70383.80\", \"0.000\"], [\"70383.90\", \"0.002\"], [\"70384.00\", \"0.000\"], [\"70384.10\", \"0.000\"], [\"70384.20\", \"0.001\"], [\"70384.40\", \"0.002\"], [\"70384.60\", \"1.144\"], [\"70384.70\", \"0.005\"], [\"70384.80\", \"0.255\"], [\"70384.90\", \"0.011\"], [\"70385.00\", \"0.270\"], [\"70385.10\", \"0.656\"], [\"70385.20\", \"0.000\"], [\"70385.30\", \"0.002\"], [\"70385.40\", \"0.001\"], [\"70385.50\", \"0.000\"], [\"70385.60\", \"0.000\"], [\"70385.70\", \"0.001\"], [\"70385.80\", \"0.002\"], [\"70385.90\", \"0.062\"], [\"70386.00\", \"0.000\"], [\"70386.20\", \"0.027\"], [\"70386.30\", \"0.004\"], [\"70386.40\", \"0.024\"], [\"70386.50\", \"0.000\"], [\"70386.60\", \"0.004\"], [\"70386.70\", \"0.000\"], [\"70386.80\", \"0.000\"], [\"70386.90\", \"0.002\"], [\"70387.00\", \"0.003\"], [\"70387.10\", \"0.001\"], [\"70387.20\", \"0.002\"], [\"70387.30\", \"0.002\"], [\"70387.40\", \"0.003\"], [\"70387.50\", \"0.000\"], [\"70387.60\", \"0.001\"], [\"70387.70\", \"0.000\"], [\"70387.80\", \"0.047\"], [\"70388.10\", \"0.003\"], [\"70388.20\", \"0.000\"], [\"70388.30\", \"0.001\"], [\"70388.40\", \"0.201\"], [\"70388.50\", \"1.100\"], [\"70388.60\", \"0.000\"], [\"70388.70\", \"0.003\"], [\"70388.80\", \"0.003\"], [\"70388.90\", \"0.047\"], [\"70389.00\", \"1.104\"], [\"70389.10\", \"0.005\"], [\"70389.20\", \"0.000\"], [\"70389.30\", \"0.002\"], [\"70389.40\", \"0.058\"], [\"70389.50\", \"0.000\"], [\"70389.60\", \"0.000\"], [\"70389.70\", \"0.005\"], [\"70389.80\", \"0.001\"], [\"70389.90\", \"0.002\"], [\"70390.00\", \"0.005\"], [\"70390.10\", \"0.003\"], [\"70390.20\", \"0.000\"], [\"70390.30\", \"0.000\"], [\"70390.50\", \"0.000\"], [\"70390.60\", \"0.001\"], [\"70390.70\", \"0.001\"], [\"70390.80\", \"0.000\"], [\"70390.90\", \"0.000\"], [\"70391.00\", \"1.002\"], [\"70391.10\", \"0.002\"], [\"70391.20\", \"0.000\"], [\"70391.30\", \"0.000\"], [\"70391.50\", \"0.000\"], [\"70391.60\", \"0.000\"], [\"70391.70\", \"0.001\"], [\"70391.80\", \"2.727\"]], \"a\": [[\"70387.70\", \"0.000\"], [\"70387.80\", \"0.000\"], [\"70387.90\", \"0.000\"], [\"70388.20\", \"0.000\"], [\"70388.30\", \"0.000\"], [\"70388.50\", \"0.000\"], [\"70388.60\", \"0.000\"], [\"70388.80\", \"0.000\"], [\"70389.00\", \"0.000\"], [\"70389.20\", \"0.000\"], [\"70389.40\", \"0.000\"], [\"70389.50\", \"0.000\"], [\"70389.60\", \"0.000\"], [\"70389.80\", \"0.000\"], [\"70389.90\", \"0.000\"], [\"70390.00\", \"0.000\"], [\"70390.10\", \"0.000\"], [\"70390.20\", \"0.000\"], [\"70390.40\", \"0.000\"], [\"70390.60\", \"0.000\"], [\"70390.70\", \"0.000\"], [\"70390.90\", \"0.000\"], [\"70391.00\", \"0.000\"], [\"70391.10\", \"0.000\"], [\"70391.20\", \"0.000\"], [\"70391.30\", \"0.000\"], [\"70391.40\", \"0.000\"], [\"70391.60\", \"0.000\"], [\"70391.70\", \"0.000\"], [\"70391.80\", \"0.000\"], [\"70391.90\", \"2.997\"], [\"70392.00\", \"0.003\"], [\"70392.10\", \"0.002\"], [\"70392.20\", \"0.001\"], [\"70392.30\", \"0.005\"], [\"70392.40\", \"0.004\"], [\"70392.70\", \"0.002\"], [\"70392.80\", \"0.026\"], [\"70392.90\", \"0.002\"], [\"70393.20\", \"0.002\"], [\"70393.40\", \"0.000\"], [\"70393.50\", \"0.002\"], [\"70393.90\", \"0.002\"], [\"70394.00\", \"0.001\"], [\"70394.10\", \"0.042\"], [\"70394.20\", \"0.000\"], [\"70395.00\", \"0.007\"], [\"70395.10\", \"0.002\"], [\"70395.30\", \"0.002\"], [\"70395.50\", \"0.055\"], [\"70395.80\", \"0.002\"], [\"70395.90\", \"0.285\"], [\"70396.20\", \"0.002\"], [\"70396.30\", \"0.018\"], [\"70396.60\", \"0.004\"], [\"70396.80\", \"0.040\"], [\"70396.90\", \"0.007\"], [\"70397.10\", \"0.002\"], [\"70397.20\", \"0.001\"], [\"70397.30\", \"0.005\"], [\"70397.40\", \"0.003\"], [\"70397.50\", \"0.007\"], [\"70397.70\", \"0.000\"], [\"70397.80\", \"0.003\"], [\"70398.10\", \"0.008\"], [\"70398.20\", \"0.000\"], [\"70398.30\", \"0.000\"], [\"70398.50\", \"0.258\"], [\"70398.60\", \"1.067\"], [\"70398.70\", \"0.000\"], [\"70398.80\", \"0.000\"], [\"70399.00\", \"0.008\"], [\"70399.10\", \"0.001\"], [\"70399.20\", \"0.400\"], [\"70399.40\", \"0.045\"], [\"70399.50\", \"0.000\"], [\"70399.60\", \"0.004\"], [\"70399.70\", \"0.006\"], [\"70399.80\", \"0.005\"], [\"70399.90\", \"0.002\"], [\"70400.00\", \"2.038\"], [\"70400.10\", \"0.000\"], [\"70400.20\", \"0.002\"], [\"70400.30\", \"0.003\"], [\"70400.40\", \"0.005\"], [\"70400.50\", \"0.074\"], [\"70400.80\", \"0.003\"], [\"70400.90\", \"0.005\"], [\"70401.10\", \"0.311\"], [\"70401.20\", \"0.003\"], [\"70401.30\", \"0.002\"], [\"70401.50\", \"0.024\"], [\"70401.70\", \"0.004\"], [\"70401.80\", \"0.001\"], [\"70401.90\", \"0.000\"], [\"70402.20\", \"0.002\"], [\"70402.30\", \"0.005\"], [\"70402.40\", \"0.007\"], [\"70402.50\", \"0.004\"], [\"70402.60\", \"0.041\"], [\"70402.70\", \"0.002\"], [\"70402.80\", \"0.008\"], [\"70402.90\", \"0.000\"], [\"70403.00\", \"0.296\"], [\"70403.30\", \"0.073\"], [\"70403.40\", \"0.003\"], [\"70403.50\", \"0.000\"], [\"70403.70\", \"0.516\"], [\"70403.90\", \"0.002\"], [\"70404.10\", \"0.000\"], [\"70404.20\", \"0.003\"], [\"70404.70\", \"0.000\"], [\"70404.80\", \"0.206\"], [\"70404.90\", \"0.039\"], [\"70405.00\", \"0.002\"], [\"70405.20\", \"0.153\"], [\"70405.60\", \"0.027\"], [\"70406.10\", \"0.003\"], [\"70406.70\", \"0.316\"], [\"70407.20\", \"0.003\"], [\"70407.40\", \"0.639\"], [\"70408.00\", \"0.002\"], [\"70408.10\", \"0.008\"], [\"70408.20\", \"0.006\"], [\"70408.30\", \"0.008\"], [\"70408.40\", \"0.379\"], [\"70408.50\", \"0.000\"], [\"70408.70\", \"0.004\"], [\"70408.80\", \"0.184\"], [\"70408.90\", \"0.002\"], [\"70409.00\", \"0.003\"], [\"70409.10\", \"0.175\"], [\"70409.20\", \"0.703\"], [\"70409.30\", \"0.003\"], [\"70409.40\", \"0.005\"], [\"70409.50\", \"0.787\"], [\"70409.70\", \"0.000\"], [\"70409.90\", \"0.003\"], [\"70410.00\", \"0.015\"], [\"70410.10\", \"0.000\"], [\"70410.40\", \"0.000\"], [\"70410.50\", \"0.090\"], [\"70410.70\", \"0.013\"], [\"70410.80\", \"0.030\"], [\"70411.00\", \"0.003\"], [\"70411.10\", \"0.075\"], [\"70411.40\", \"0.015\"], [\"70411.70\", \"0.009\"], [\"70411.80\", \"0.149\"], [\"70411.90\", \"0.208\"], [\"70412.10\", \"0.511\"], [\"70412.20\", \"0.004\"], [\"70412.30\", \"0.003\"], [\"70412.50\", \"0.007\"], [\"70412.90\", \"0.087\"], [\"70413.00\", \"1.076\"], [\"70413.10\", \"0.002\"], [\"70413.40\", \"0.342\"], [\"70413.50\", \"0.003\"], [\"70413.80\", \"0.007\"], [\"70413.90\", \"0.073\"], [\"70414.00\", \"0.201\"], [\"70414.20\", \"0.025\"], [\"70414.40\", \"0.072\"], [\"70414.70\", \"0.008\"], [\"70414.90\", \"0.289\"], [\"70415.00\", \"0.005\"], [\"70415.10\", \"0.595\"], [\"70415.30\", \"0.009\"], [\"70415.70\", \"0.115\"], [\"70415.80\", \"0.007\"], [\"70415.90\", \"0.008\"], [\"70416.00\", \"0.264\"], [\"70416.30\", \"0.274\"], [\"70416.40\", \"0.252\"], [\"70416.50\", \"0.873\"], [\"70416.60\", \"0.011\"], [\"70416.70\", \"0.002\"], [\"70416.90\", \"0.000\"], [\"70417.10\", \"0.074\"], [\"70417.20\", \"0.172\"], [\"70417.30\", \"0.000\"], [\"70417.50\", \"0.150\"], [\"70417.60\", \"0.737\"], [\"70417.90\", \"0.006\"], [\"70418.00\", \"0.390\"], [\"70418.10\", \"0.004\"], [\"70418.40\", \"0.223\"], [\"70418.50\", \"0.005\"], [\"70418.60\", \"0.139\"], [\"70418.70\", \"0.002\"], [\"70418.80\", \"0.003\"], [\"70418.90\", \"0.228\"], [\"70419.00\", \"0.101\"], [\"70419.30\", \"0.002\"], [\"70419.40\", \"0.111\"], [\"70419.50\", \"0.006\"], [\"70419.60\", \"1.069\"], [\"70419.80\", \"0.256\"], [\"70419.90\", \"0.515\"], [\"70420.00\", \"1.342\"], [\"70420.10\", \"0.206\"], [\"70420.20\", \"0.005\"], [\"70420.70\", \"0.015\"], [\"70420.80\", \"0.013\"], [\"70420.90\", \"0.000\"], [\"70421.10\", \"0.256\"], [\"70421.40\", \"1.907\"], [\"70421.50\", \"0.002\"], [\"70421.60\", \"0.061\"], [\"70421.70\", \"0.000\"], [\"70421.80\", \"0.000\"], [\"70421.90\", \"0.002\"], [\"70422.00\", \"2.826\"], [\"70422.10\", \"0.004\"], [\"70422.20\", \"0.005\"], [\"70422.40\", \"0.189\"], [\"70422.60\", \"0.070\"], [\"70422.80\", \"0.000\"], [\"70422.90\", \"0.000\"], [\"70423.50\", \"0.004\"], [\"70423.60\", \"0.212\"], [\"70423.90\", \"0.024\"], [\"70424.20\", \"0.000\"], [\"70424.30\", \"0.002\"], [\"70424.90\", \"0.000\"], [\"70425.00\", \"0.017\"], [\"70425.40\", \"0.142\"], [\"70425.50\", \"0.000\"], [\"70425.60\", \"0.000\"], [\"70425.70\", \"0.005\"], [\"70425.80\", \"1.068\"], [\"70425.90\", \"0.547\"], [\"70426.00\", \"0.508\"], [\"70426.30\", \"0.002\"], [\"70426.40\", \"0.000\"], [\"70426.70\", \"0.213\"], [\"70427.00\", \"0.002\"], [\"70427.10\", \"0.345\"], [\"70427.20\", \"2.288\"], [\"70427.40\", \"0.002\"], [\"70427.60\", \"0.001\"], [\"70427.70\", \"0.002\"], [\"70427.80\", \"10.427\"], [\"70428.70\", \"1.003\"], [\"70429.40\", \"0.005\"], [\"70429.50\", \"0.054\"], [\"70430.20\", \"0.000\"], [\"70430.50\", \"0.846\"], [\"70430.90\", \"0.189\"], [\"70431.00\", \"0.002\"], [\"70431.20\", \"0.000\"], [\"70431.60\", \"0.068\"], [\"70431.80\", \"0.047\"], [\"70432.10\", \"0.513\"], [\"70432.30\", \"0.002\"], [\"70432.70\", \"0.000\"], [\"70432.80\", \"0.028\"], [\"70433.60\", \"0.000\"], [\"70434.10\", \"0.121\"], [\"70434.20\", \"0.482\"], [\"70434.30\", \"0.029\"], [\"70434.50\", \"0.585\"], [\"70435.10\", \"0.002\"], [\"70435.90\", \"0.000\"], [\"70436.60\", \"0.026\"], [\"70437.10\", \"0.000\"], [\"70437.70\", \"0.008\"], [\"70438.00\", \"0.028\"], [\"70438.60\", \"0.003\"], [\"70438.80\", \"0.004\"], [\"70439.30\", \"0.515\"], [\"70439.70\", \"0.000\"], [\"70440.00\", \"0.071\"], [\"70440.20\", \"0.010\"], [\"70440.90\", \"0.210\"], [\"70441.30\", \"0.008\"], [\"70441.40\", \"0.256\"], [\"70441.50\", \"0.064\"], [\"70441.80\", \"0.421\"], [\"70441.90\", \"0.196\"], [\"70442.00\", \"0.600\"], [\"70442.60\", \"0.130\"], [\"70442.80\", \"0.115\"], [\"70443.20\", \"0.003\"], [\"70443.30\", \"0.130\"], [\"70443.40\", \"0.056\"], [\"70443.60\", \"0.033\"], [\"70443.80\", \"0.066\"], [\"70444.00\", \"0.006\"], [\"70444.20\", \"1.040\"], [\"70444.30\", \"0.002\"], [\"70444.50\", \"0.001\"], [\"70444.60\", \"0.062\"], [\"70444.70\", \"1.047\"], [\"70444.80\", \"2.286\"], [\"70444.90\", \"6.305\"], [\"70445.10\", \"0.089\"], [\"70445.20\", \"3.527\"], [\"70446.10\", \"0.004\"], [\"70447.40\", \"0.874\"], [\"70447.50\", \"0.002\"], [\"70447.90\", \"0.104\"], [\"70448.00\", \"0.079\"], [\"70448.30\", \"0.452\"], [\"70448.60\", \"0.004\"], [\"70449.30\", \"0.002\"], [\"70449.50\", \"0.020\"], [\"70450.40\", \"0.192\"], [\"70450.70\", \"0.000\"], [\"70451.10\", \"0.028\"], [\"70451.70\", \"0.139\"], [\"70451.80\", \"2.130\"], [\"70452.30\", \"0.043\"], [\"70453.00\", \"10.226\"], [\"70453.50\", \"0.000\"], [\"70453.80\", \"0.280\"], [\"70455.10\", \"1.083\"], [\"70455.20\", \"0.000\"], [\"70455.40\", \"0.085\"], [\"70455.50\", \"0.006\"], [\"70456.30\", \"0.206\"], [\"70456.70\", \"0.012\"], [\"70457.40\", \"0.090\"], [\"70457.60\", \"0.000\"], [\"70458.00\", \"0.021\"], [\"70458.40\", \"0.000\"], [\"70458.60\", \"0.201\"], [\"70458.70\", \"0.078\"], [\"70458.80\", \"0.011\"], [\"70458.90\", \"0.000\"], [\"70459.30\", \"0.237\"], [\"70460.00\", \"0.014\"], [\"70460.30\", \"0.005\"], [\"70461.30\", \"0.000\"], [\"70462.50\", \"0.097\"], [\"70462.70\", \"0.007\"], [\"70462.80\", \"0.207\"], [\"70463.00\", \"0.049\"], [\"70463.30\", \"0.154\"], [\"70464.30\", \"0.001\"], [\"70464.50\", \"0.142\"], [\"70464.60\", \"0.087\"], [\"70464.80\", \"0.003\"], [\"70465.50\", \"0.118\"], [\"70466.00\", \"0.047\"], [\"70466.10\", \"0.065\"], [\"70467.00\", \"0.521\"], [\"70467.10\", \"0.189\"], [\"70468.20\", \"0.514\"], [\"70468.30\", \"0.002\"], [\"70468.40\", \"0.005\"], [\"70470.10\", \"0.191\"], [\"70470.80\", \"1.644\"], [\"70471.40\", \"0.068\"], [\"70471.70\", \"0.309\"], [\"70472.10\", \"0.423\"], [\"70472.30\", \"0.085\"], [\"70472.50\", \"0.004\"], [\"70472.60\", \"2.828\"], [\"70472.70\", \"0.002\"], [\"70473.10\", \"0.081\"], [\"70473.70\", \"0.087\"], [\"70473.80\", \"0.041\"], [\"70474.00\", \"0.047\"], [\"70474.80\", \"0.007\"], [\"70475.60\", \"0.002\"], [\"70475.70\", \"0.088\"], [\"70476.50\", \"0.002\"], [\"70478.20\", \"0.039\"], [\"70478.40\", \"0.000\"], [\"70478.60\", \"0.142\"], [\"70479.00\", \"0.023\"], [\"70479.50\", \"0.545\"], [\"70479.70\", \"0.044\"], [\"70480.20\", \"0.044\"], [\"70480.60\", \"0.000\"], [\"70480.90\", \"0.130\"], [\"70482.30\", \"0.000\"], [\"70483.20\", \"0.358\"], [\"70483.30\", \"1.764\"], [\"70485.20\", \"0.002\"], [\"70485.90\", \"0.085\"], [\"70486.90\", \"0.009\"], [\"70489.90\", \"0.000\"], [\"70491.30\", \"0.000\"], [\"70492.00\", \"3.564\"], [\"70492.20\", \"1.324\"], [\"70494.40\", \"0.000\"], [\"70494.70\", \"2.061\"], [\"70494.90\", \"0.079\"], [\"70495.00\", \"1.332\"], [\"70496.10\", \"0.014\"], [\"70497.50\", \"0.006\"], [\"70498.30\", \"0.026\"], [\"70501.70\", \"0.244\"], [\"70502.40\", \"0.027\"], [\"70504.00\", \"0.087\"], [\"70506.10\", \"0.004\"], [\"70506.30\", \"0.205\"], [\"70507.50\", \"0.002\"], [\"70507.60\", \"0.624\"], [\"70510.20\", \"0.000\"], [\"70510.70\", \"1.906\"], [\"70512.60\", \"0.004\"], [\"70512.70\", \"6.528\"], [\"70514.50\", \"2.220\"], [\"70521.90\", \"0.000\"], [\"70522.60\", \"0.014\"], [\"70522.70\", \"0.000\"], [\"70522.90\", \"0.571\"], [\"70523.10\", \"0.003\"], [\"70523.30\", \"0.012\"], [\"70524.60\", \"0.093\"], [\"70525.50\", \"1.308\"], [\"70528.40\", \"0.197\"], [\"70528.60\", \"0.084\"], [\"70531.40\", \"0.005\"], [\"70531.50\", \"0.000\"], [\"70532.30\", \"0.050\"], [\"70533.40\", \"0.012\"], [\"70537.30\", \"0.000\"], [\"70537.90\", \"0.363\"], [\"70538.50\", \"0.045\"], [\"70539.40\", \"0.039\"], [\"70540.90\", \"0.550\"], [\"70541.90\", \"0.231\"], [\"70542.80\", \"0.046\"], [\"70543.90\", \"0.082\"], [\"70544.30\", \"8.184\"], [\"70547.20\", \"1.676\"], [\"70547.80\", \"0.102\"], [\"70547.90\", \"0.273\"], [\"70548.00\", \"0.084\"], [\"70549.80\", \"6.091\"], [\"70550.80\", \"0.082\"], [\"70551.30\", \"0.000\"], [\"70551.90\", \"0.310\"], [\"70555.00\", \"0.154\"], [\"70555.40\", \"0.041\"], [\"70556.20\", \"0.093\"], [\"70556.70\", \"3.840\"], [\"70557.10\", \"1.598\"], [\"70557.90\", \"0.039\"], [\"70558.80\", \"0.082\"], [\"70560.00\", \"3.743\"], [\"70560.40\", \"23.148\"], [\"70561.60\", \"0.082\"], [\"70561.90\", \"0.039\"], [\"70563.00\", \"0.082\"], [\"70565.10\", \"0.082\"], [\"70565.40\", \"0.088\"], [\"70566.40\", \"2.068\"], [\"70566.50\", \"0.090\"], [\"70567.00\", \"1.199\"], [\"70567.10\", \"0.049\"], [\"70568.20\", \"0.108\"], [\"70568.40\", \"0.085\"], [\"70569.00\", \"0.000\"], [\"70570.80\", \"0.036\"], [\"70571.50\", \"0.082\"], [\"70571.80\", \"0.082\"], [\"70573.60\", \"0.003\"], [\"70575.00\", \"0.082\"], [\"70575.40\", \"0.082\"], [\"70577.00\", \"0.054\"], [\"70577.30\", \"1.704\"], [\"70577.60\", \"0.000\"], [\"70577.70\", \"0.107\"], [\"70577.80\", \"0.192\"], [\"70578.30\", \"0.002\"], [\"70578.50\", \"0.200\"], [\"70579.90\", \"0.082\"], [\"70580.90\", \"0.011\"], [\"70581.10\", \"0.780\"], [\"70581.40\", \"0.084\"], [\"70583.40\", \"0.003\"], [\"70583.50\", \"1.812\"], [\"70584.90\", \"0.082\"], [\"70585.40\", \"0.082\"], [\"70586.90\", \"0.005\"], [\"70588.40\", \"10.005\"], [\"70589.00\", \"0.213\"], [\"70591.40\", \"0.205\"], [\"70592.20\", \"0.085\"], [\"70592.30\", \"0.001\"], [\"70597.50\", \"0.043\"], [\"70599.30\", \"0.000\"], [\"70600.50\", \"0.003\"], [\"70602.00\", \"0.008\"], [\"70603.90\", \"0.003\"], [\"70610.00\", \"0.193\"], [\"70610.30\", \"1.293\"], [\"70610.40\", \"8.082\"], [\"70610.60\", \"0.036\"], [\"70611.60\", \"0.000\"], [\"70612.40\", \"0.049\"], [\"70617.10\", \"0.002\"], [\"70622.80\", \"0.002\"], [\"70630.10\", \"0.311\"], [\"70630.90\", \"1.184\"], [\"70631.90\", \"0.170\"], [\"70664.90\", \"0.190\"], [\"70666.40\", \"0.193\"], [\"70672.70\", \"0.196\"], [\"70674.20\", \"0.200\"], [\"70685.90\", \"0.190\"], [\"70687.40\", \"0.390\"], [\"70693.90\", \"1.017\"], [\"70694.70\", \"6.498\"], [\"70700.40\", \"0.007\"], [\"70702.80\", \"0.000\"], [\"70735.80\", \"0.065\"], [\"70742.50\", \"0.141\"], [\"70753.00\", \"0.000\"], [\"70758.90\", \"0.042\"], [\"70759.70\", \"0.000\"], [\"70765.10\", \"0.002\"], [\"70778.30\", \"0.028\"], [\"70778.40\", \"0.168\"], [\"70816.80\", \"6.072\"], [\"70817.10\", \"0.000\"], [\"70955.60\", \"3.739\"], [\"70990.00\", \"0.594\"], [\"71017.40\", \"0.000\"], [\"71027.90\", \"0.000\"], [\"71033.40\", \"0.112\"], [\"71057.00\", \"0.766\"], [\"71071.10\", \"0.768\"], [\"71082.90\", \"0.049\"], [\"71084.10\", \"0.000\"], [\"71089.80\", \"0.000\"], [\"71095.80\", \"0.000\"], [\"71125.20\", \"0.766\"], [\"71129.80\", \"0.070\"], [\"71159.00\", \"0.000\"], [\"71190.70\", \"0.000\"], [\"71191.20\", \"0.004\"], [\"71196.50\", \"0.000\"], [\"71200.80\", \"0.703\"], [\"71228.90\", \"0.000\"], [\"71234.70\", \"1.390\"], [\"71235.40\", \"0.695\"], [\"71244.20\", \"0.002\"], [\"71261.00\", \"0.007\"], [\"71263.30\", \"0.000\"], [\"71264.50\", \"0.000\"], [\"71264.60\", \"0.000\"], [\"71266.50\", \"0.000\"], [\"71266.80\", \"0.000\"], [\"71266.90\", \"0.000\"], [\"71268.40\", \"1.403\"], [\"71301.10\", \"0.694\"], [\"71305.80\", \"0.696\"], [\"71306.40\", \"4.164\"], [\"71331.40\", \"0.000\"], [\"71337.20\", \"0.003\"], [\"71364.30\", \"0.000\"], [\"71365.00\", \"0.005\"], [\"71368.80\", \"0.003\"], [\"71370.40\", \"0.003\"], [\"71373.60\", \"0.000\"], [\"71373.70\", \"3.468\"], [\"71375.50\", \"1.388\"], [\"71376.00\", \"1.750\"], [\"71405.90\", \"0.971\"], [\"71406.00\", \"1.962\"], [\"71408.80\", \"1.947\"], [\"71408.90\", \"0.970\"], [\"71411.40\", \"1.940\"], [\"71411.90\", \"1.110\"], [\"71412.00\", \"1.080\"], [\"71434.60\", \"0.000\"], [\"71437.30\", \"0.000\"], [\"71437.40\", \"0.135\"], [\"71439.10\", \"0.002\"], [\"71439.90\", \"0.006\"], [\"71440.70\", \"0.000\"], [\"71442.40\", \"0.000\"], [\"71444.00\", \"2.307\"], [\"71444.10\", \"6.527\"], [\"71474.20\", \"0.000\"], [\"71474.30\", \"0.000\"], [\"71475.70\", \"1.940\"], [\"71476.40\", \"3.889\"], [\"71478.30\", \"1.940\"], [\"71479.20\", \"2.915\"], [\"71479.30\", \"1.942\"], [\"71481.00\", \"0.975\"], [\"71482.30\", \"0.973\"], [\"71482.40\", \"0.969\"], [\"71510.10\", \"1.938\"], [\"71511.00\", \"0.700\"], [\"71511.60\", \"0.969\"], [\"71774.50\", \"0.006\"], [\"73932.10\", \"0.002\"], [\"77255.80\", \"0.000\"], [\"77430.20\", \"0.000\"], [\"77431.10\", \"0.002\"], [\"89523.20\", \"0.000\"]]}", "symbol": "BTCUSDT"}
{"event": "depthUpdate", "raw_payload": "{\"e\": \"depthUpdate\", \"E\": 1773246394960, \"T\": 1773246394957, \"s\": \"BTCUSDT\", \"U\": 10089704737140, \"u\": 10089704746173, \"pu\": 10089704737125, \"b\": [[\"1000.00\", \"26.792\"], [\"5000.00\", \"101.398\"], [\"19991.80\", \"0.010\"], [\"20091.80\", \"0.260\"], [\"20167.10\", \"0.380\"], [\"20191.80\", \"0.130\"], [\"20274.80\", \"0.020\"], [\"20276.10\", \"0.000\"], [\"20277.80\", \"0.000\"], [\"20279.10\", \"0.000\"], [\"20280.00\", \"0.000\"], [\"20280.70\", \"0.000\"], [\"20282.60\", \"0.000\"], [\"20283.50\", \"0.000\"], [\"63352.60\", \"0.000\"], [\"66845.30\", \"0.000\"], [\"66872.00\", \"0.002\"], [\"69260.30\", \"13.023\"], [\"69296.00\", \"1.009\"], [\"69307.60\", \"0.002\"], [\"69328.90\", \"0.012\"], [\"69330.50\", \"3.487\"], [\"69356.80\", \"1.784\"], [\"69357.90\", \"1.999\"], [\"69687.90\", \"1.136\"], [\"69827.70\", \"0.000\"], [\"69831.40\", \"3.720\"], [\"70015.30\", \"0.044\"], [\"70108.90\", \"0.000\"], [\"70111.50\", \"3.802\"], [\"70114.60\", \"0.000\"], [\"70115.30\", \"1.040\"], [\"70140.90\", \"47.048\"], [\"70143.20\", \"8.757\"], [\"70146.10\", \"0.236\"], [\"70146.50\", \"0.000\"], [\"70148.30\", \"3.182\"], [\"70150.10\", \"0.684\"], [\"70161.50\", \"0.000\"], [\"70172.50\", \"1.049\"], [\"70178.50\", \"5.562\"], [\"70195.60\", \"0.189\"], [\"70195.80\", \"1.113\"], [\"70198.70\", \"0.040\"], [\"70208.90\", \"0.005\"], [\"70211.60\", \"0.000\"], [\"70233.00\", \"0.291\"], [\"70233.70\", \"0.058\"], [\"70234.80\", \"0.000\"], [\"70235.20\", \"0.043\"], [\"70238.00\", \"5.430\"], [\"70239.40\", \"0.000\"], [\"70239.50\", \"0.078\"], [\"70240.60\", \"1.293\"], [\"70241.70\", \"0.000\"], [\"70246.80\", \"0.014\"], [\"70248.80\", \"0.083\"], [\"70257.40\", \"0.002\"], [\"70259.00\", \"1.309\"], [\"70266.80\", \"0.003\"], [\"70272.00\", \"1.113\"], [\"70273.50\", \"0.038\"], [\"70273.60\", \"3.606\"], [\"70273.80\", \"0.000\"], [\"70276.90\", \"0.431\"], [\"70281.00\", \"0.000\"], [\"70284.60\", \"0.003\"], [\"70287.70\", \"0.172\"], [\"70288.20\", \"0.002\"], [\"70288.60\", \"0.264\"], [\"70288.90\", \"0.008\"], [\"70295.50\", \"0.513\"], [\"70296.40\", \"0.002\"], [\"70301.00\", \"0.573\"], [\"70301.30\", \"0.116\"], [\"70302.90\", \"0.003\"], [\"70303.80\", \"0.286\"], [\"70309.20\", \"0.094\"], [\"70315.30\", \"0.533\"], [\"70317.00\", \"0.013\"], [\"70318.90\", \"0.005\"], [\"70319.10\", \"0.043\"], [\"70321.50\", \"0.000\"], [\"70323.10\", \"1.423\"], [\"70324.40\", \"0.002\"], [\"70332.40\", \"0.937\"], [\"70334.00\", \"0.100\"], [\"70335.50\", \"0.046\"], [\"70335.70\", \"0.002\"], [\"70336.20\", \"0.002\"], [\"70336.30\", \"0.100\"], [\"70336.60\", \"0.018\"], [\"70337.30\", \"0.031\"], [\"70337.50\", \"0.018\"], [\"70337.70\", \"0.008\"], [\"70338.00\", \"0.966\"], [\"70340.50\", \"0.061\"], [\"70340.60\", \"0.087\"], [\"70346.00\", \"0.006\"], [\"70346.20\", \"0.274\"], [\"70347.30\", \"0.056\"], [\"70349.00\", \"0.002\"], [\"70349.60\", \"1.261\"], [\"70351.30\", \"0.010\"], [\"70352.00\", \"0.012\"], [\"70352.90\", \"0.006\"], [\"70353.60\", \"0.460\"], [\"70354.40\", \"0.016\"], [\"70354.50\", \"0.057\"], [\"70354.70\", \"0.003\"], [\"70355.20\", \"1.085\"], [\"70359.50\", \"0.000\"], [\"70359.60\", \"0.022\"], [\"70360.20\", \"0.203\"], [\"70360.50\", \"0.651\"], [\"70361.30\", \"0.012\"], [\"70361.40\", \"0.380\"], [\"70367.10\", \"0.138\"], [\"70369.80\", \"0.005\"], [\"70369.90\", \"0.080\"], [\"70370.70\", \"0.511\"], [\"70370.80\", \"0.000\"], [\"70371.90\", \"0.073\"], [\"70372.80\", \"0.220\"], [\"70373.00\", \"0.041\"], [\"70373.10\", \"0.039\"], [\"70373.90\", \"0.112\"], [\"70374.70\", \"0.003\"], [\"70374.90\", \"0.004\"], [\"70375.00\", \"0.087\"], [\"70375.30\", \"0.183\"], [\"70376.10\", \"0.496\"], [\"70376.20\", \"0.248\"], [\"70376.40\", \"0.000\"], [\"70376.60\", \"0.000\"], [\"70376.70\", \"1.212\"], [\"70376.80\", \"0.088\"], [\"70376.90\", \"0.000\"], [\"70377.10\", \"0.081\"], [\"70377.20\", \"0.000\"], [\"70377.50\", \"0.411\"], [\"70377.60\", \"0.407\"], [\"70377.70\", \"0.447\"], [\"70377.90\", \"0.003\"], [\"70378.00\", \"0.007\"], [\"70378.10\", \"0.005\"], [\"70378.20\", \"0.003\"], [\"70378.30\", \"0.342\"], [\"70379.20\", \"0.040\"], [\"70380.20\", \"0.000\"], [\"70380.90\", \"0.105\"], [\"70381.20\", \"0.000\"], [\"70381.50\", \"0.003\"], [\"70381.70\", \"0.003\"], [\"70382.10\", \"0.000\"], [\"70382.70\", \"0.019\"], [\"70383.60\", \"0.003\"], [\"70383.80\", \"0.003\"], [\"70384.50\", \"0.004\"], [\"70384.60\", \"1.126\"], [\"70384.70\", \"0.224\"], [\"70384.90\", \"0.014\"], [\"70385.10\", \"0.001\"], [\"70385.20\", \"0.003\"], [\"70386.20\", \"0.006\"], [\"70386.40\", \"0.000\"], [\"70386.80\", \"0.002\"], [\"70388.40\", \"0.177\"], [\"70389.10\", \"0.660\"], [\"70389.70\", \"0.002\"], [\"70390.80\", \"0.000\"], [\"70391.80\", \"3.116\"]], \"a\": [[\"70391.90\", \"3.231\"], [\"70393.60\", \"0.021\"], [\"70394.00\", \"0.004\"], [\"70396.30\", \"0.003\"], [\"70397.90\", \"0.043\"], [\"70398.70\", \"0.002\"], [\"70399.10\", \"0.512\"], [\"70399.70\", \"0.009\"], [\"70400.30\", \"0.074\"], [\"70401.30\", \"0.513\"], [\"70402.50\", \"0.007\"], [\"70402.60\", \"0.005\"], [\"70403.20\", \"0.003\"], [\"70404.70\", \"0.025\"], [\"70405.20\", \"0.155\"], [\"70405.70\", \"0.223\"], [\"70406.00\", \"0.004\"], [\"70406.10\", \"0.072\"], [\"70406.40\", \"0.039\"], [\"70406.50\", \"0.040\"], [\"70406.70\", \"0.319\"], [\"70407.40\", \"0.700\"], [\"70407.60\", \"0.001\"], [\"70408.40\", \"0.004\"], [\"70408.70\", \"0.002\"], [\"70408.80\", \"0.234\"], [\"70409.00\", \"0.145\"], [\"70409.40\", \"0.380\"], [\"70409.50\", \"0.784\"], [\"70409.60\", \"0.002\"], [\"70410.30\", \"0.071\"], [\"70410.60\", \"0.006\"], [\"70411.80\", \"0.007\"], [\"70411.90\", \"0.206\"], [\"70412.30\", \"0.003\"], [\"70412.40\", \"0.003\"], [\"70412.50\", \"0.009\"], [\"70412.60\", \"0.004\"], [\"70413.30\", \"0.006\"], [\"70413.50\", \"0.000\"], [\"70414.20\", \"0.023\"], [\"70414.50\", \"0.000\"], [\"70414.60\", \"0.070\"], [\"70414.90\", \"0.291\"], [\"70416.60\", \"0.046\"], [\"70417.10\", \"0.003\"], [\"70417.20\", \"0.102\"], [\"70417.90\", \"0.000\"], [\"70418.20\", \"0.002\"], [\"70418.40\", \"0.195\"], [\"70419.00\", \"0.006\"], [\"70419.10\", \"0.000\"], [\"70419.90\", \"0.585\"], [\"70420.00\", \"1.081\"], [\"70420.20\", \"0.003\"], [\"70420.60\", \"0.007\"], [\"70420.70\", \"0.006\"], [\"70420.80\", \"0.004\"], [\"70420.90\", \"0.003\"], [\"70421.40\", \"0.008\"], [\"70421.60\", \"0.064\"], [\"70422.00\", \"2.828\"], [\"70422.10\", \"0.002\"], [\"70422.20\", \"0.000\"], [\"70422.30\", \"0.003\"], [\"70422.60\", \"0.000\"], [\"70422.80\", \"0.009\"], [\"70422.90\", \"0.009\"], [\"70423.50\", \"0.008\"], [\"70424.20\", \"0.000\"], [\"70424.30\", \"0.002\"], [\"70424.90\", \"0.002\"], [\"70425.00\", \"0.019\"], [\"70426.50\", \"0.002\"], [\"70427.20\", \"2.204\"], [\"70427.40\", \"1.002\"], [\"70427.50\", \"0.008\"], [\"70427.70\", \"0.000\"], [\"70427.80\", \"10.419\"], [\"70428.70\", \"0.003\"], [\"70429.00\", \"0.002\"], [\"70429.10\", \"0.511\"], [\"70429.20\", \"0.002\"], [\"70429.80\", \"0.002\"], [\"70429.90\", \"0.006\"], [\"70430.10\", \"0.052\"], [\"70430.60\", \"2.875\"], [\"70432.40\", \"0.201\"], [\"70432.80\", \"0.324\"], [\"70433.10\", \"0.030\"], [\"70438.60\", \"0.053\"], [\"70439.90\", \"0.033\"], [\"70440.80\", \"0.006\"], [\"70442.40\", \"0.022\"], [\"70442.60\", \"0.002\"], [\"70442.80\", \"0.243\"], [\"70444.10\", \"0.374\"], [\"70444.30\", \"0.030\"], [\"70444.60\", \"0.000\"], [\"70445.00\", \"0.024\"], [\"70448.60\", \"0.032\"], [\"70451.10\", \"0.000\"], [\"70452.00\", \"0.652\"], [\"70452.10\", \"0.032\"], [\"70452.30\", \"0.000\"], [\"70453.80\", \"0.282\"], [\"70455.00\", \"0.492\"], [\"70455.30\", \"0.007\"], [\"70456.20\", \"0.002\"], [\"70457.10\", \"0.460\"], [\"70458.70\", \"0.001\"], [\"70460.60\", \"0.006\"], [\"70460.90\", \"0.082\"], [\"70461.70\", \"0.081\"], [\"70465.50\", \"0.082\"], [\"70468.00\", \"1.066\"], [\"70469.00\", \"1.012\"], [\"70472.40\", \"0.084\"], [\"70477.20\", \"0.079\"], [\"70477.30\", \"0.002\"], [\"70479.20\", \"0.012\"], [\"70481.60\", \"0.133\"], [\"70487.40\", \"0.002\"], [\"70488.30\", \"0.055\"], [\"70490.50\", \"0.000\"], [\"70492.00\", \"0.000\"], [\"70495.30\", \"2.059\"], [\"70500.70\", \"0.008\"], [\"70501.80\", \"0.917\"], [\"70501.90\", \"0.286\"], [\"70503.40\", \"3.576\"], [\"70505.80\", \"0.099\"], [\"70507.70\", \"0.000\"], [\"70508.00\", \"0.075\"], [\"70509.20\", \"0.000\"], [\"70516.90\", \"0.090\"], [\"70521.90\", \"1.276\"], [\"70522.60\", \"0.002\"], [\"70523.70\", \"0.093\"], [\"70527.60\", \"0.000\"], [\"70531.60\", \"0.003\"], [\"70532.40\", \"1.867\"], [\"70534.90\", \"0.212\"], [\"70547.50\", \"0.078\"], [\"70549.70\", \"1.490\"], [\"70549.90\", \"0.000\"], [\"70570.80\", \"0.081\"], [\"70602.00\", \"0.002\"], [\"70610.40\", \"8.082\"], [\"70618.80\", \"0.384\"], [\"70621.30\", \"0.040\"], [\"70624.90\", \"0.002\"], [\"70630.80\", \"5.770\"], [\"70632.90\", \"0.000\"], [\"70633.20\", \"0.002\"], [\"70708.90\", \"0.079\"], [\"70710.50\", \"0.764\"], [\"70710.60\", \"0.006\"], [\"70816.80\", \"0.346\"], [\"70816.90\", \"0.000\"], [\"70944.30\", \"0.000\"], [\"70952.30\", \"3.738\"], [\"70955.60\", \"0.019\"], [\"71106.40\", \"0.000\"], [\"71268.10\", \"0.000\"], [\"71271.00\", \"0.000\"], [\"71306.40\", \"5.552\"], [\"71384.20\", \"0.003\"], [\"71391.50\", \"4.863\"], [\"71444.10\", \"5.557\"], [\"71482.40\", \"1.938\"], [\"71532.20\", \"0.975\"], [\"73931.70\", \"0.002\"], [\"77431.10\", \"0.000\"]]}", "symbol": "BTCUSDT"}
{"event": "depthUpdate", "raw_payload": "{\"e\": \"depthUpdate\", \"E\": 1773246395062, \"T\": 1773246395060, \"s\": \"BTCUSDT\", \"U\": 10089704746434, \"u\": 10089704755637, \"pu\": 10089704746173, \"b\": [[\"1000.00\", \"26.792\"], [\"5000.00\", \"101.418\"], [\"19991.80\", \"0.090\"], [\"20091.80\", \"0.270\"], [\"20167.10\", \"0.290\"], [\"20191.80\", \"0.220\"], [\"20270.00\", \"0.000\"], [\"20270.40\", \"0.000\"], [\"20272.70\", \"0.000\"], [\"20273.30\", \"0.000\"], [\"20274.80\", \"0.000\"], [\"56294.00\", \"0.000\"], [\"67576.20\", \"0.002\"], [\"68970.60\", \"0.723\"], [\"69154.70\", \"0.000\"], [\"69251.50\", \"0.000\"], [\"69296.00\", \"2.009\"], [\"69330.60\", \"17.570\"], [\"69366.40\", \"1.855\"], [\"69417.10\", \"0.288\"], [\"69574.80\", \"2.394\"], [\"69624.50\", \"1.422\"], [\"69673.30\", \"2.137\"], [\"69687.90\", \"1.136\"], [\"69723.10\", \"0.735\"], [\"69831.40\", \"0.000\"], [\"70062.70\", \"0.004\"], [\"70125.70\", \"0.000\"], [\"70169.00\", \"0.149\"], [\"70204.60\", \"2.319\"], [\"70208.40\", \"0.128\"], [\"70215.10\", \"0.000\"], [\"70230.30\", \"0.215\"], [\"70232.70\", \"0.002\"], [\"70234.40\", \"0.004\"], [\"70246.80\", \"0.000\"], [\"70251.00\", \"0.014\"], [\"70254.50\", \"0.000\"], [\"70276.50\", \"0.002\"], [\"70281.60\", \"0.217\"], [\"70291.00\", \"0.000\"], [\"70296.70\", \"0.093\"], [\"70297.70\", \"0.071\"], [\"70298.10\", \"0.002\"], [\"70301.70\", \"2.089\"], [\"70301.80\", \"0.513\"], [\"70303.80\", \"0.202\"], [\"70304.50\", \"0.146\"], [\"70304.80\", \"0.074\"], [\"70305.10\", \"0.008\"], [\"70307.30\", \"0.208\"], [\"70311.50\", \"1.066\"], [\"70311.80\", \"0.081\"], [\"70313.20\", \"0.025\"], [\"70318.50\", \"0.634\"], [\"70320.80\", \"0.046\"], [\"70331.00\", \"0.007\"], [\"70333.80\", \"0.163\"], [\"70334.00\", \"0.000\"], [\"70336.60\", \"0.002\"], [\"70339.20\", \"0.004\"], [\"70339.50\", \"0.102\"], [\"70340.60\", \"0.002\"], [\"70340.90\", \"0.007\"], [\"70341.20\", \"0.088\"], [\"70343.00\", \"2.723\"], [\"70343.30\", \"0.093\"], [\"70344.30\", \"0.062\"], [\"70350.00\", \"0.628\"], [\"70350.40\", \"0.017\"], [\"70351.40\", \"0.011\"], [\"70353.60\", \"0.420\"], [\"70353.90\", \"0.053\"], [\"70357.00\", \"0.627\"], [\"70357.50\", \"0.022\"], [\"70359.40\", \"0.003\"], [\"70361.50\", \"0.377\"], [\"70362.60\", \"0.000\"], [\"70364.00\", \"0.631\"], [\"70364.60\", \"0.024\"], [\"70367.30\", \"0.333\"], [\"70372.90\", \"0.559\"], [\"70374.70\", \"0.006\"], [\"70375.40\", \"0.004\"], [\"70376.70\", \"1.273\"], [\"70377.40\", \"0.046\"], [\"70377.80\", \"0.245\"], [\"70377.90\", \"0.003\"], [\"70378.50\", \"0.002\"], [\"70378.90\", \"0.005\"], [\"70379.60\", \"0.003\"], [\"70384.70\", \"0.226\"], [\"70384.90\", \"0.014\"], [\"70385.90\", \"0.003\"], [\"70386.30\", \"0.002\"], [\"70388.40\", \"0.179\"], [\"70388.50\", \"1.100\"], [\"70391.10\", \"0.000\"], [\"70391.60\", \"0.062\"], [\"70391.70\", \"0.003\"]], \"a\": [[\"70391.90\", \"3.226\"], [\"70392.70\", \"0.000\"], [\"70392.80\", \"0.000\"], [\"70393.50\", \"0.004\"], [\"70394.40\", \"0.004\"], [\"70394.60\", \"0.002\"], [\"70404.60\", \"0.000\"], [\"70405.00\", \"0.027\"], [\"70405.40\", \"0.027\"], [\"70406.00\", \"0.626\"], [\"70406.10\", \"0.097\"], [\"70406.80\", \"0.000\"], [\"70408.70\", \"0.060\"], [\"70413.00\", \"1.698\"], [\"70413.30\", \"0.007\"], [\"70414.20\", \"0.014\"], [\"70414.60\", \"0.000\"], [\"70416.30\", \"0.344\"], [\"70417.40\", \"0.377\"], [\"70420.00\", \"1.703\"], [\"70421.90\", \"0.004\"], [\"70422.70\", \"0.196\"], [\"70422.80\", \"0.000\"], [\"70422.90\", \"0.000\"], [\"70423.00\", \"0.022\"], [\"70423.50\", \"0.026\"], [\"70423.60\", \"0.221\"], [\"70423.70\", \"0.597\"], [\"70424.40\", \"0.202\"], [\"70425.10\", \"0.095\"], [\"70425.90\", \"0.527\"], [\"70426.00\", \"0.480\"], [\"70427.00\", \"0.644\"], [\"70430.50\", \"0.868\"], [\"70430.60\", \"2.895\"], [\"70434.00\", \"0.630\"], [\"70434.10\", \"0.143\"], [\"70437.60\", \"0.023\"], [\"70444.30\", \"0.002\"], [\"70444.70\", \"1.066\"], [\"70446.40\", \"0.004\"], [\"70447.40\", \"0.849\"], [\"70447.60\", \"0.002\"], [\"70449.20\", \"0.574\"], [\"70449.80\", \"0.000\"], [\"70451.20\", \"0.000\"], [\"70451.80\", \"2.155\"], [\"70452.00\", \"0.680\"], [\"70452.10\", \"0.063\"], [\"70455.80\", \"0.000\"], [\"70467.40\", \"0.000\"], [\"70474.20\", \"0.115\"], [\"70474.40\", \"0.085\"], [\"70481.20\", \"0.074\"], [\"70481.50\", \"0.276\"], [\"70487.90\", \"0.101\"], [\"70488.30\", \"0.112\"], [\"70507.30\", \"0.091\"], [\"70512.50\", \"0.000\"], [\"70558.40\", \"0.002\"], [\"70566.80\", \"0.000\"], [\"70568.70\", \"0.000\"], [\"70583.40\", \"0.194\"], [\"70589.70\", \"34.944\"], [\"70601.40\", \"0.019\"], [\"70603.50\", \"0.006\"], [\"70632.10\", \"0.006\"], [\"70634.00\", \"0.004\"], [\"70635.70\", \"0.004\"], [\"70650.40\", \"0.060\"], [\"70694.20\", \"0.223\"], [\"70717.70\", \"0.004\"], [\"70949.30\", \"3.752\"], [\"70952.30\", \"0.018\"], [\"70981.50\", \"0.003\"], [\"71070.40\", \"0.004\"], [\"71095.80\", \"0.000\"], [\"71100.00\", \"19.811\"], [\"71468.10\", \"0.000\"], [\"71792.40\", \"0.066\"], [\"71834.90\", \"0.140\"], [\"73920.00\", \"0.302\"], [\"89523.20\", \"0.000\"]]}", "symbol": "BTCUSDT"}
{"event": "depthUpdate", "raw_payload": "{\"e\": \"depthUpdate\", \"E\": 1773246395164, \"T\": 1773246395163, \"s\": \"BTCUSDT\", \"U\": 10089704755847, \"u\": 10089704765484, \"pu\": 10089704755637, \"b\": [[\"5000.00\", \"101.418\"], [\"19991.80\", \"0.180\"], [\"20084.60\", \"0.000\"], [\"20086.20\", \"0.010\"], [\"20088.40\", \"0.000\"], [\"20090.10\", \"0.000\"], [\"20090.80\", \"0.010\"], [\"20091.80\", \"0.310\"], [\"20167.10\", \"0.210\"], [\"20191.80\", \"0.300\"], [\"20267.10\", \"0.700\"], [\"20268.20\", \"0.000\"], [\"33000.00\", \"10.797\"], [\"56313.00\", \"0.000\"], [\"69191.00\", \"0.000\"], [\"69230.30\", \"1.001\"], [\"69331.70\", \"6.819\"], [\"69371.10\", \"0.999\"], [\"69687.90\", \"1.136\"], [\"69841.80\", \"3.720\"], [\"70013.00\", \"0.089\"], [\"70039.50\", \"0.002\"], [\"70039.80\", \"0.002\"], [\"70068.70\", \"0.195\"], [\"70074.80\", \"0.000\"], [\"70076.90\", \"0.112\"], [\"70146.30\", \"0.004\"], [\"70167.50\", \"0.000\"], [\"70178.50\", \"5.724\"], [\"70213.90\", \"0.087\"], [\"70220.30\", \"0.000\"], [\"70233.00\", \"0.248\"], [\"70233.80\", \"0.040\"], [\"70266.20\", \"0.009\"], [\"70273.40\", \"0.515\"], [\"70276.10\", \"0.000\"], [\"70278.90\", \"0.002\"], [\"70291.80\", \"0.000\"], [\"70303.50\", \"0.246\"], [\"70303.70\", \"0.147\"], [\"70303.80\", \"0.504\"], [\"70326.70\", \"0.000\"], [\"70332.00\", \"2.048\"], [\"70335.20\", \"0.346\"], [\"70337.50\", \"0.016\"], [\"70338.60\", \"0.005\"], [\"70338.70\", \"0.191\"], [\"70339.30\", \"0.005\"], [\"70339.80\", \"0.000\"], [\"70343.00\", \"2.101\"], [\"70345.60\", \"1.952\"], [\"70346.20\", \"0.562\"], [\"70350.00\", \"0.006\"], [\"70350.60\", \"0.008\"], [\"70351.90\", \"0.004\"], [\"70353.30\", \"0.000\"], [\"70353.60\", \"0.373\"], [\"70353.70\", \"0.016\"], [\"70355.90\", \"0.080\"], [\"70356.30\", \"0.210\"], [\"70357.00\", \"0.005\"], [\"70359.20\", \"0.072\"], [\"70362.00\", \"0.335\"], [\"70363.30\", \"0.009\"], [\"70364.00\", \"0.009\"], [\"70365.80\", \"0.000\"], [\"70366.10\", \"0.036\"], [\"70367.30\", \"0.248\"], [\"70367.40\", \"0.004\"], [\"70368.00\", \"1.074\"], [\"70369.10\", \"0.058\"], [\"70369.40\", \"0.071\"], [\"70369.80\", \"0.008\"], [\"70369.90\", \"0.000\"], [\"70370.10\", \"0.183\"], [\"70370.40\", \"0.006\"], [\"70370.80\", \"0.007\"], [\"70371.90\", \"0.005\"], [\"70372.00\", \"0.004\"], [\"70372.20\", \"0.008\"], [\"70372.30\", \"0.004\"], [\"70372.90\", \"0.559\"], [\"70373.00\", \"1.248\"], [\"70373.30\", \"0.007\"], [\"70373.60\", \"0.003\"], [\"70373.90\", \"0.110\"], [\"70374.00\", \"0.093\"], [\"70374.10\", \"0.000\"], [\"70374.60\", \"0.007\"], [\"70374.80\", \"0.415\"], [\"70374.90\", \"0.002\"], [\"70375.00\", \"0.007\"], [\"70375.10\", \"0.000\"], [\"70375.30\", \"0.181\"], [\"70375.90\", \"0.000\"], [\"70376.00\", \"0.003\"], [\"70376.10\", \"0.416\"], [\"70376.20\", \"0.246\"], [\"70376.40\", \"0.177\"], [\"70376.70\", \"0.113\"], [\"70376.80\", \"0.044\"], [\"70376.90\", \"0.142\"], [\"70377.10\", \"0.083\"], [\"70377.40\", \"0.082\"], [\"70377.50\", \"0.181\"], [\"70377.80\", \"0.238\"], [\"70377.90\", \"0.003\"], [\"70378.00\", \"0.004\"], [\"70378.40\", \"0.116\"], [\"70379.30\", \"0.007\"], [\"70380.00\", \"0.018\"], [\"70380.70\", \"0.038\"], [\"70380.80\", \"0.000\"], [\"70382.10\", \"0.000\"], [\"70382.40\", \"0.002\"], [\"70382.80\", \"0.047\"], [\"70383.10\", \"0.003\"], [\"70383.50\", \"0.000\"], [\"70384.60\", \"0.000\"], [\"70384.70\", \"0.006\"], [\"70384.90\", \"0.009\"], [\"70385.10\", \"0.656\"], [\"70387.80\", \"0.000\"], [\"70388.50\", \"0.000\"], [\"70388.60\", \"0.002\"], [\"70389.00\", \"0.004\"], [\"70389.10\", \"0.005\"], [\"70391.60\", \"0.061\"], [\"70391.70\", \"0.003\"], [\"70391.80\", \"1.483\"]], \"a\": [[\"70391.90\", \"3.673\"], [\"70392.30\", \"0.002\"], [\"70392.40\", \"0.002\"], [\"70393.40\", \"0.002\"], [\"70393.50\", \"0.027\"], [\"70393.80\", \"0.005\"], [\"70395.10\", \"0.000\"], [\"70396.50\", \"0.000\"], [\"70396.60\", \"0.018\"], [\"70397.90\", \"0.041\"], [\"70398.40\", \"0.406\"], [\"70398.50\", \"0.658\"], [\"70398.90\", \"0.031\"], [\"70399.30\", \"0.007\"], [\"70400.70\", \"0.000\"], [\"70402.10\", \"0.003\"], [\"70403.00\", \"0.466\"], [\"70404.40\", \"0.016\"], [\"70405.30\", \"0.038\"], [\"70405.60\", \"1.093\"], [\"70405.70\", \"0.294\"], [\"70406.00\", \"0.004\"], [\"70406.30\", \"0.108\"], [\"70406.40\", \"0.217\"], [\"70407.50\", \"0.004\"], [\"70407.80\", \"0.057\"], [\"70408.10\", \"0.001\"], [\"70408.50\", \"0.043\"], [\"70409.00\", \"0.003\"], [\"70409.70\", \"0.002\"], [\"70409.90\", \"0.005\"], [\"70410.30\", \"0.000\"], [\"70410.60\", \"0.004\"], [\"70411.30\", \"0.007\"], [\"70412.00\", \"0.029\"], [\"70412.50\", \"0.007\"], [\"70412.60\", \"0.002\"], [\"70413.00\", \"1.178\"], [\"70413.10\", \"0.004\"], [\"70414.80\", \"0.126\"], [\"70415.30\", \"0.002\"], [\"70416.50\", \"0.771\"], [\"70417.50\", \"0.143\"], [\"70419.70\", \"0.198\"], [\"70420.00\", \"1.081\"], [\"70420.60\", \"0.047\"], [\"70423.70\", \"0.649\"], [\"70425.80\", \"1.071\"], [\"70426.50\", \"0.005\"], [\"70427.00\", \"0.002\"], [\"70427.20\", \"2.207\"], [\"70427.90\", \"0.003\"], [\"70429.50\", \"0.002\"], [\"70431.80\", \"0.054\"], [\"70432.20\", \"1.116\"], [\"70434.00\", \"0.008\"], [\"70443.40\", \"0.010\"], [\"70446.30\", \"0.002\"], [\"70446.60\", \"0.002\"], [\"70447.30\", \"0.005\"], [\"70448.00\", \"0.043\"], [\"70448.10\", \"1.256\"], [\"70448.30\", \"0.416\"], [\"70455.90\", \"0.089\"], [\"70458.00\", \"0.019\"], [\"70462.10\", \"0.781\"], [\"70463.20\", \"0.002\"], [\"70464.60\", \"0.089\"], [\"70464.90\", \"2.082\"], [\"70466.20\", \"0.010\"], [\"70472.90\", \"0.002\"], [\"70473.60\", \"0.047\"], [\"70474.00\", \"0.000\"], [\"70475.00\", \"0.348\"], [\"70479.50\", \"0.685\"], [\"70480.40\", \"0.209\"], [\"70484.50\", \"0.289\"], [\"70485.10\", \"0.330\"], [\"70487.90\", \"0.087\"], [\"70488.30\", \"0.126\"], [\"70490.40\", \"0.002\"], [\"70495.00\", \"1.362\"], [\"70497.40\", \"0.010\"], [\"70503.30\", \"0.011\"], [\"70507.90\", \"0.036\"], [\"70511.60\", \"0.482\"], [\"70528.10\", \"0.000\"], [\"70531.30\", \"0.002\"], [\"70532.60\", \"0.002\"], [\"70545.90\", \"0.200\"], [\"70569.00\", \"0.036\"], [\"70579.60\", \"0.002\"], [\"70585.40\", \"0.000\"], [\"70590.50\", \"0.002\"], [\"70592.20\", \"0.003\"], [\"70625.10\", \"0.004\"], [\"70627.10\", \"0.012\"], [\"70628.10\", \"0.002\"], [\"70667.40\", \"2.202\"], [\"70710.50\", \"0.116\"], [\"70742.70\", \"0.000\"], [\"70799.90\", \"19.422\"], [\"70836.70\", \"0.002\"], [\"70887.80\", \"3.242\"], [\"70941.90\", \"3.720\"], [\"70949.30\", \"0.032\"], [\"71095.80\", \"0.000\"], [\"71342.10\", \"1.121\"], [\"71412.50\", \"1.681\"], [\"71500.00\", \"286.415\"], [\"71553.30\", \"0.982\"], [\"73929.30\", \"0.002\"]]}", "symbol": "BTCUSDT"}
{"event": "depthUpdate", "raw_payload": "{\"e\": \"depthUpdate\", \"E\": 1773246395266, \"T\": 1773246395265, \"s\": \"BTCUSDT\", \"U\": 10089704765524, \"u\": 10089704774651, \"pu\": 10089704765484, \"b\": [[\"1000.00\", \"26.792\"], [\"5000.00\", \"101.418\"], [\"19991.80\", \"0.260\"], [\"20074.80\", \"0.040\"], [\"20076.10\", \"0.000\"], [\"20076.80\", \"0.010\"], [\"20079.10\", \"0.010\"], [\"20080.00\", \"0.010\"], [\"20082.60\", \"0.010\"], [\"20083.50\", \"0.000\"], [\"20091.80\", \"0.400\"], [\"20167.10\", \"0.120\"], [\"20191.80\", \"0.390\"], [\"20267.10\", \"0.610\"], [\"33000.00\", \"10.793\"], [\"66872.20\", \"0.002\"], [\"68893.00\", \"0.012\"], [\"69260.30\", \"12.022\"], [\"69262.00\", \"0.000\"], [\"69300.70\", \"2.000\"], [\"69330.60\", \"16.570\"], [\"69331.70\", \"5.811\"], [\"69332.40\", \"0.527\"], [\"69371.10\", \"3.996\"], [\"69687.90\", \"1.136\"], [\"70039.80\", \"0.002\"], [\"70068.70\", \"0.004\"], [\"70074.10\", \"0.000\"], [\"70121.00\", \"0.041\"], [\"70129.80\", \"0.007\"], [\"70161.50\", \"10.120\"], [\"70178.90\", \"0.000\"], [\"70179.90\", \"0.609\"], [\"70228.00\", \"6.047\"], [\"70230.00\", \"1.968\"], [\"70233.40\", \"0.090\"], [\"70299.70\", \"0.000\"], [\"70321.40\", \"0.205\"], [\"70324.40\", \"0.313\"], [\"70338.00\", \"0.968\"], [\"70338.60\", \"0.003\"], [\"70340.40\", \"0.002\"], [\"70340.70\", \"0.042\"], [\"70341.10\", \"0.085\"], [\"70341.20\", \"0.000\"], [\"70341.50\", \"0.420\"], [\"70344.30\", \"0.062\"], [\"70348.80\", \"0.000\"], [\"70349.60\", \"1.362\"], [\"70350.10\", \"0.002\"], [\"70350.30\", \"0.000\"], [\"70351.50\", \"0.040\"], [\"70353.90\", \"0.006\"], [\"70355.30\", \"0.266\"], [\"70355.60\", \"0.002\"], [\"70355.90\", \"0.000\"], [\"70357.40\", \"0.035\"], [\"70359.00\", \"0.002\"], [\"70366.10\", \"0.000\"], [\"70366.30\", \"0.003\"], [\"70367.00\", \"0.096\"], [\"70368.10\", \"0.514\"], [\"70368.70\", \"0.639\"], [\"70369.10\", \"0.004\"], [\"70369.20\", \"0.000\"], [\"70369.80\", \"0.088\"], [\"70369.90\", \"0.002\"], [\"70370.20\", \"0.002\"], [\"70370.60\", \"0.641\"], [\"70371.10\", \"0.003\"], [\"70371.40\", \"0.000\"], [\"70372.00\", \"0.002\"], [\"70372.30\", \"0.286\"], [\"70372.80\", \"0.180\"], [\"70374.80\", \"0.131\"], [\"70375.40\", \"0.146\"], [\"70376.40\", \"0.263\"], [\"70376.60\", \"0.036\"], [\"70376.70\", \"0.160\"], [\"70376.80\", \"0.120\"], [\"70376.90\", \"0.000\"], [\"70377.00\", \"0.304\"], [\"70377.10\", \"0.141\"], [\"70377.90\", \"0.010\"], [\"70378.00\", \"0.007\"], [\"70378.10\", \"0.040\"], [\"70379.00\", \"0.002\"], [\"70379.30\", \"0.000\"], [\"70389.10\", \"0.003\"], [\"70391.50\", \"0.059\"], [\"70391.60\", \"0.004\"], [\"70391.70\", \"0.001\"], [\"70391.80\", \"1.487\"]], \"a\": [[\"70393.80\", \"0.003\"], [\"70394.50\", \"0.005\"], [\"70395.20\", \"0.000\"], [\"70396.60\", \"0.016\"], [\"70398.00\", \"0.000\"], [\"70399.40\", \"0.043\"], [\"70400.80\", \"0.001\"], [\"70402.20\", \"0.000\"], [\"70404.30\", \"0.144\"], [\"70405.80\", \"0.006\"], [\"70406.40\", \"0.075\"], [\"70407.40\", \"0.984\"], [\"70407.50\", \"0.002\"], [\"70407.70\", \"0.007\"], [\"70408.00\", \"0.004\"], [\"70408.70\", \"0.107\"], [\"70409.70\", \"0.000\"], [\"70409.90\", \"0.003\"], [\"70413.20\", \"0.513\"], [\"70414.40\", \"0.025\"], [\"70414.90\", \"0.008\"], [\"70417.50\", \"0.145\"], [\"70417.80\", \"0.003\"], [\"70418.90\", \"0.226\"], [\"70425.90\", \"0.525\"], [\"70428.60\", \"0.003\"], [\"70428.70\", \"0.016\"], [\"70429.30\", \"0.005\"], [\"70442.50\", \"0.128\"], [\"70442.80\", \"0.115\"], [\"70446.90\", \"0.000\"], [\"70448.00\", \"0.007\"], [\"70449.30\", \"0.000\"], [\"70467.80\", \"0.098\"], [\"70568.70\", \"0.036\"], [\"70880.70\", \"0.000\"], [\"71095.80\", \"0.000\"], [\"71306.00\", \"0.005\"], [\"73910.20\", \"0.000\"], [\"73924.90\", \"0.052\"], [\"89523.20\", \"0.000\"]]}", "symbol": "BTCUSDT"}
{"event": "depthUpdate", "raw_payload": "{\"e\": \"depthUpdate\", \"E\": 1773246395368, \"T\": 1773246395364, \"s\": \"BTCUSDT\", \"U\": 10089704774832, \"u\": 10089704781120, \"pu\": 10089704774651, \"b\": [[\"1000.00\", \"26.792\"], [\"5000.00\", \"101.418\"], [\"19991.80\", \"0.350\"], [\"20070.00\", \"0.000\"], [\"20070.40\", \"0.010\"], [\"20072.70\", \"0.020\"], [\"20073.30\", \"0.030\"], [\"20074.80\", \"0.030\"], [\"20091.80\", \"0.480\"], [\"20167.10\", \"0.040\"], [\"20191.80\", \"0.470\"], [\"20267.10\", \"0.530\"], [\"68984.00\", \"0.003\"], [\"68985.60\", \"0.002\"], [\"69189.90\", \"0.000\"], [\"69230.30\", \"2.002\"], [\"69258.20\", \"0.649\"], [\"69260.30\", \"10.020\"], [\"69300.70\", \"5.000\"], [\"69328.50\", \"4.204\"], [\"69330.60\", \"14.856\"], [\"69331.70\", \"4.803\"], [\"69371.10\", \"7.707\"], [\"69401.00\", \"2.147\"], [\"69441.50\", \"2.139\"], [\"69471.30\", \"2.852\"], [\"69511.90\", \"0.733\"], [\"69687.90\", \"1.136\"], [\"69841.80\", \"0.000\"], [\"69843.80\", \"3.730\"], [\"70001.80\", \"0.000\"], [\"70076.90\", \"0.083\"], [\"70087.60\", \"0.192\"], [\"70090.90\", \"0.140\"], [\"70119.30\", \"9.430\"], [\"70122.50\", \"2.412\"], [\"70133.00\", \"1.404\"], [\"70164.00\", \"1.750\"], [\"70193.20\", \"2.558\"], [\"70235.20\", \"0.043\"], [\"70248.10\", \"0.000\"], [\"70249.40\", \"0.055\"], [\"70272.00\", \"0.012\"], [\"70293.30\", \"1.626\"], [\"70297.20\", \"0.002\"], [\"70298.20\", \"0.124\"], [\"70301.20\", \"0.003\"], [\"70303.90\", \"0.004\"], [\"70312.10\", \"0.002\"], [\"70312.90\", \"1.004\"], [\"70319.80\", \"0.593\"], [\"70321.30\", \"0.133\"], [\"70337.80\", \"0.228\"], [\"70338.00\", \"0.966\"], [\"70340.60\", \"0.000\"], [\"70341.10\", \"0.000\"], [\"70341.30\", \"0.085\"], [\"70341.50\", \"0.399\"], [\"70342.00\", \"0.002\"], [\"70342.60\", \"0.002\"], [\"70343.70\", \"0.007\"], [\"70345.50\", \"0.111\"], [\"70345.60\", \"1.955\"], [\"70347.40\", \"0.240\"], [\"70349.60\", \"1.413\"], [\"70352.00\", \"0.003\"], [\"70352.10\", \"0.000\"], [\"70353.70\", \"0.034\"], [\"70354.40\", \"0.019\"], [\"70359.20\", \"0.029\"], [\"70359.70\", \"0.009\"], [\"70359.80\", \"0.009\"], [\"70359.90\", \"0.205\"], [\"70360.50\", \"0.549\"], [\"70361.10\", \"0.008\"], [\"70362.00\", \"0.337\"], [\"70366.60\", \"0.000\"], [\"70369.50\", \"0.071\"], [\"70371.70\", \"0.004\"], [\"70373.10\", \"0.003\"], [\"70373.80\", \"0.503\"], [\"70374.20\", \"0.052\"], [\"70377.10\", \"0.061\"], [\"70377.90\", \"0.410\"], [\"70378.50\", \"0.402\"], [\"70379.40\", \"0.401\"], [\"70384.90\", \"0.006\"], [\"70385.10\", \"0.658\"], [\"70385.20\", \"0.005\"], [\"70391.10\", \"0.002\"], [\"70391.80\", \"2.097\"]], \"a\": [[\"70391.90\", \"3.434\"], [\"70398.40\", \"0.006\"], [\"70398.50\", \"0.258\"], [\"70401.60\", \"0.009\"], [\"70412.00\", \"0.009\"], [\"70415.80\", \"0.000\"], [\"70415.90\", \"0.008\"], [\"70416.90\", \"0.070\"], [\"70417.10\", \"0.010\"], [\"70419.90\", \"0.515\"], [\"70424.50\", \"0.020\"], [\"70430.00\", \"0.018\"], [\"70430.70\", \"0.007\"], [\"70431.40\", \"0.757\"], [\"70432.10\", \"0.516\"], [\"70435.20\", \"1.875\"], [\"70449.00\", \"0.003\"], [\"70451.40\", \"0.513\"], [\"70457.50\", \"0.237\"], [\"70487.90\", \"0.101\"], [\"70488.30\", \"0.112\"], [\"70492.60\", \"0.000\"], [\"70498.90\", \"0.092\"], [\"70508.40\", \"0.018\"], [\"70511.60\", \"0.382\"], [\"70520.50\", \"0.003\"], [\"70540.50\", \"0.004\"], [\"70561.50\", \"0.002\"], [\"70564.80\", \"0.002\"], [\"70566.80\", \"0.025\"], [\"70597.50\", \"0.000\"], [\"70650.40\", \"0.002\"], [\"70651.00\", \"17.864\"], [\"70728.70\", \"21.905\"], [\"70834.80\", \"26.248\"], [\"70939.80\", \"3.720\"], [\"70941.90\", \"0.000\"], [\"70962.30\", \"30.428\"], [\"71093.40\", \"0.010\"], [\"71095.80\", \"0.000\"], [\"71133.40\", \"0.841\"], [\"71319.70\", \"0.000\"], [\"71482.90\", \"0.978\"], [\"71518.70\", \"0.000\"], [\"71731.30\", \"0.000\"], [\"71774.50\", \"0.003\"], [\"71799.70\", \"0.003\"], [\"73932.60\", \"0.002\"]]}", "symbol": "BTCUSDT"}
{"event": "depthUpdate", "raw_payload": "{\"e\": \"depthUpdate\", \"E\": 1773246395470, \"T\": 1773246395468, \"s\": \"BTCUSDT\", \"U\": 10089704781368, \"u\": 10089704789025, \"pu\": 10089704781120, \"b\": [[\"5000.00\", \"101.418\"], [\"19991.80\", \"0.480\"], [\"20067.10\", \"0.830\"], [\"20068.00\", \"0.000\"], [\"20091.80\", \"0.470\"], [\"20167.10\", \"0.000\"], [\"20191.80\", \"0.560\"], [\"20267.10\", \"0.440\"], [\"69260.30\", \"9.019\"], [\"69300.70\", \"6.000\"], [\"69421.60\", \"0.015\"], [\"69574.80\", \"1.683\"], [\"69611.90\", \"0.000\"], [\"69624.50\", \"2.133\"], [\"69652.70\", \"3.091\"], [\"69673.30\", \"1.427\"], [\"69687.90\", \"1.136\"], [\"69723.10\", \"1.445\"], [\"69776.00\", \"0.000\"], [\"69809.50\", \"0.150\"], [\"69843.80\", \"0.010\"], [\"69845.70\", \"0.000\"], [\"69847.30\", \"3.720\"], [\"70026.10\", \"1.909\"], [\"70062.90\", \"0.003\"], [\"70109.00\", \"0.000\"], [\"70157.80\", \"0.007\"], [\"70193.10\", \"0.005\"], [\"70203.00\", \"0.227\"], [\"70233.70\", \"0.101\"], [\"70251.00\", \"0.000\"], [\"70251.30\", \"0.016\"], [\"70312.50\", \"0.050\"], [\"70315.00\", \"0.046\"], [\"70317.30\", \"0.046\"], [\"70337.80\", \"0.226\"], [\"70338.00\", \"0.968\"], [\"70341.30\", \"0.000\"], [\"70341.50\", \"0.399\"], [\"70341.80\", \"0.015\"], [\"70342.10\", \"0.341\"], [\"70352.70\", \"0.200\"], [\"70352.80\", \"0.513\"], [\"70353.00\", \"0.478\"], [\"70360.90\", \"1.066\"], [\"70361.10\", \"0.010\"], [\"70361.20\", \"0.002\"], [\"70361.80\", \"0.006\"], [\"70362.00\", \"0.343\"], [\"70367.70\", \"0.002\"], [\"70373.00\", \"1.212\"], [\"70374.20\", \"0.001\"], [\"70380.40\", \"0.003\"], [\"70380.70\", \"0.438\"], [\"70380.90\", \"0.213\"], [\"70388.60\", \"0.000\"], [\"70391.10\", \"0.004\"], [\"70391.50\", \"0.000\"], [\"70391.60\", \"0.002\"], [\"70391.80\", \"1.928\"]], \"a\": [[\"70391.90\", \"3.672\"], [\"70394.50\", \"0.005\"], [\"70404.80\", \"0.248\"], [\"70427.90\", \"0.033\"], [\"70432.30\", \"0.025\"], [\"70432.80\", \"0.327\"], [\"70433.50\", \"0.005\"], [\"70434.20\", \"0.485\"], [\"70434.90\", \"0.387\"], [\"70442.50\", \"0.000\"], [\"70443.00\", \"0.002\"], [\"70443.20\", \"0.131\"], [\"70445.50\", \"0.253\"], [\"70458.70\", \"0.003\"], [\"70459.60\", \"0.081\"], [\"70474.10\", \"0.006\"], [\"70487.90\", \"0.087\"], [\"70488.30\", \"0.112\"], [\"70488.70\", \"0.202\"], [\"70488.90\", \"0.000\"], [\"70557.00\", \"0.002\"], [\"70562.20\", \"0.009\"], [\"70597.50\", \"0.043\"], [\"70612.40\", \"0.002\"], [\"70647.50\", \"4.654\"], [\"70728.60\", \"3.366\"], [\"70729.10\", \"0.000\"], [\"70870.20\", \"0.007\"], [\"70905.60\", \"0.004\"], [\"70925.00\", \"0.158\"], [\"70936.30\", \"3.723\"], [\"70938.00\", \"0.407\"], [\"70939.80\", \"0.000\"], [\"71095.80\", \"0.000\"], [\"73917.50\", \"0.002\"], [\"89523.20\", \"0.000\"]]}", "symbol": "BTCUSDT"}
