{"event": "depthUpdate", "raw_payload": "{\"e\": \"depthUpdate\", \"E\": 1773246398440, \"T\": 1773246398439, \"s\": \"BTCUSDT\", \"U\": 10089705114889, \"u\": 10089705140291, \"pu\": 10089705114691, \"b\": [[\"5000.00\", \"101.418\"], [\"19865.90\", \"0.030\"], [\"19887.30\", \"0.340\"], [\"19966.40\", \"0.010\"], [\"19967.10\", \"0.070\"], [\"19987.30\", \"0.250\"], [\"20087.30\", \"0.000\"], [\"20265.90\", \"0.060\"], [\"20266.40\", \"0.020\"], [\"20267.00\", \"0.020\"], [\"20267.10\", \"0.140\"], [\"66837.10\", \"0.031\"], [\"66846.10\", \"0.006\"], [\"68680.00\", \"0.351\"], [\"69340.10\", \"0.000\"], [\"69346.90\", \"0.864\"], [\"69662.20\", \"0.002\"], [\"69663.40\", \"0.000\"], [\"69678.50\", \"0.002\"], [\"69808.60\", \"3.722\"], [\"70061.80\", \"0.000\"], [\"70062.70\", \"6.558\"], [\"70062.80\", \"1.018\"], [\"70069.30\", \"0.376\"], [\"70070.10\", \"0.194\"], [\"70080.20\", \"1.046\"], [\"70135.10\", \"0.002\"], [\"70135.80\", \"0.002\"], [\"70136.60\", \"0.083\"], [\"70136.90\", \"0.000\"], [\"70137.30\", \"0.000\"], [\"70137.70\", \"0.000\"], [\"70138.10\", \"0.081\"], [\"70198.80\", \"13.068\"], [\"70256.20\", \"0.105\"], [\"70258.20\", \"0.015\"], [\"70258.30\", \"0.043\"], [\"70259.00\", \"1.315\"], [\"70260.70\", \"6.781\"], [\"70262.30\", \"0.188\"], [\"70262.50\", \"1.805\"], [\"70267.60\", \"0.388\"], [\"70273.00\", \"0.744\"], [\"70276.30\", \"0.115\"], [\"70277.60\", \"0.002\"], [\"70283.20\", \"0.146\"], [\"70283.90\", \"0.020\"], [\"70287.40\", \"0.013\"], [\"70287.60\", \"0.000\"], [\"70288.30\", \"0.256\"], [\"70288.60\", \"0.040\"], [\"70290.50\", \"0.624\"], [\"70291.40\", \"0.039\"], [\"70293.70\", \"0.122\"], [\"70294.10\", \"0.050\"], [\"70294.30\", \"0.219\"], [\"70294.70\", \"0.082\"], [\"70296.00\", \"0.006\"], [\"70296.60\", \"0.055\"], [\"70296.70\", \"0.187\"], [\"70297.40\", \"0.030\"], [\"70297.80\", \"0.031\"], [\"70298.00\", \"0.043\"], [\"70298.60\", \"3.617\"], [\"70298.70\", \"0.514\"], [\"70299.10\", \"0.000\"], [\"70299.60\", \"0.002\"], [\"70299.90\", \"0.000\"], [\"70301.00\", \"1.122\"], [\"70304.30\", \"0.617\"], [\"70308.10\", \"0.004\"], [\"70308.60\", \"0.004\"], [\"70308.90\", \"0.540\"], [\"70310.10\", \"0.074\"], [\"70310.90\", \"0.009\"], [\"70315.30\", \"0.515\"], [\"70315.50\", \"0.005\"], [\"70315.60\", \"0.195\"], [\"70315.70\", \"0.391\"], [\"70315.90\", \"0.046\"], [\"70316.00\", \"0.342\"], [\"70316.10\", \"0.090\"], [\"70318.60\", \"0.000\"], [\"70320.60\", \"0.713\"], [\"70320.80\", \"0.002\"], [\"70321.40\", \"0.236\"], [\"70322.30\", \"2.494\"], [\"70323.30\", \"0.220\"], [\"70323.50\", \"0.002\"], [\"70323.60\", \"0.002\"], [\"70323.70\", \"0.002\"], [\"70324.40\", \"0.571\"], [\"70324.70\", \"0.157\"], [\"70324.80\", \"0.000\"], [\"70325.40\", \"0.931\"], [\"70325.80\", \"0.002\"], [\"70326.30\", \"0.003\"], [\"70326.80\", \"0.000\"], [\"70327.50\", \"0.017\"], [\"70327.60\", \"0.003\"], [\"70328.30\", \"0.005\"], [\"70328.70\", \"0.188\"], [\"70328.90\", \"0.002\"], [\"70329.10\", \"0.345\"], [\"70329.20\", \"0.512\"], [\"70330.00\", \"0.092\"], [\"70331.00\", \"0.008\"], [\"70331.90\", \"0.090\"], [\"70332.40\", \"0.107\"], [\"70333.00\", \"0.582\"], [\"70333.30\", \"0.007\"], [\"70333.40\", \"0.384\"], [\"70334.00\", \"0.004\"], [\"70335.00\", \"0.012\"], [\"70336.10\", \"0.003\"], [\"70336.30\", \"0.001\"], [\"70336.40\", \"0.000\"], [\"70336.50\", \"0.006\"], [\"70336.70\", \"0.002\"], [\"70336.90\", \"0.003\"], [\"70337.20\", \"0.000\"], [\"70337.30\", \"0.021\"], [\"70337.40\", \"0.339\"], [\"70337.50\", \"0.001\"], [\"70337.70\", \"0.011\"], [\"70337.80\", \"0.205\"], [\"70337.90\", \"0.080\"], [\"70338.00\", \"0.034\"], [\"70338.10\", \"0.000\"], [\"70338.70\", \"0.196\"], [\"70338.80\", \"0.008\"], [\"70338.90\", \"0.031\"], [\"70339.40\", \"0.005\"], [\"70339.50\", \"0.002\"], [\"70339.80\", \"0.005\"], [\"70340.10\", \"0.005\"], [\"70340.20\", \"0.003\"], [\"70340.70\", \"0.000\"], [\"70341.30\", \"0.000\"], [\"70341.80\", \"0.514\"], [\"70342.00\", \"0.005\"], [\"70342.20\", \"0.005\"], [\"70342.30\", \"0.245\"], [\"70342.90\", \"0.377\"], [\"70343.00\", \"2.105\"], [\"70343.60\", \"0.107\"], [\"70343.70\", \"0.003\"], [\"70344.00\", \"0.104\"], [\"70344.10\", \"0.007\"], [\"70344.20\", \"0.001\"], [\"70345.50\", \"0.007\"], [\"70345.80\", \"0.073\"], [\"70347.20\", \"0.001\"], [\"70347.30\", \"0.111\"], [\"70347.90\", \"0.007\"], [\"70348.00\", \"0.020\"], [\"70348.10\", \"0.004\"], [\"70348.50\", \"0.183\"], [\"70349.10\", \"0.011\"], [\"70349.90\", \"0.293\"], [\"70350.00\", \"0.689\"], [\"70350.10\", \"1.068\"], [\"70351.40\", \"0.263\"], [\"70351.60\", \"0.039\"], [\"70351.70\", \"0.116\"], [\"70351.80\", \"0.134\"], [\"70352.00\", \"0.090\"], [\"70352.10\", \"0.061\"], [\"70352.40\", \"0.079\"], [\"70352.50\", \"0.054\"], [\"70352.70\", \"0.440\"], [\"70352.80\", \"0.379\"], [\"70353.00\", \"0.692\"], [\"70353.50\", \"0.122\"], [\"70353.60\", \"0.000\"], [\"70353.70\", \"0.001\"], [\"70355.10\", \"0.003\"], [\"70355.30\", \"0.005\"], [\"70355.80\", \"0.001\"], [\"70355.90\", \"0.000\"], [\"70356.20\", \"0.034\"], [\"70356.40\", \"0.001\"], [\"70356.50\", \"0.012\"], [\"70356.70\", \"0.123\"], [\"70356.80\", \"0.001\"], [\"70356.90\", \"0.000\"], [\"70357.00\", \"0.007\"], [\"70357.20\", \"0.000\"], [\"70357.30\", \"0.001\"], [\"70357.40\", \"0.000\"], [\"70358.00\", \"0.003\"], [\"70358.10\", \"0.001\"], [\"70358.40\", \"0.000\"], [\"70358.50\", \"0.005\"], [\"70358.90\", \"0.002\"], [\"70359.00\", \"0.000\"], [\"70359.90\", \"0.006\"], [\"70360.10\", \"0.006\"], [\"70360.60\", \"0.000\"], [\"70361.70\", \"1.001\"], [\"70361.80\", \"0.006\"], [\"70362.90\", \"0.000\"], [\"70363.10\", \"0.005\"], [\"70364.40\", \"0.000\"], [\"70364.70\", \"0.007\"], [\"70365.00\", \"0.000\"], [\"70365.20\", \"0.002\"], [\"70365.40\", \"0.000\"], [\"70365.50\", \"0.000\"], [\"70365.80\", \"0.002\"], [\"70365.90\", \"0.371\"], [\"70366.00\", \"0.000\"], [\"70366.40\", \"0.000\"], [\"70366.50\", \"0.000\"], [\"70367.00\", \"0.000\"], [\"70367.10\", \"0.000\"]], \"a\": [[\"70366.00\", \"11.805\"], [\"70366.10\", \"0.001\"], [\"70366.30\", \"0.000\"], [\"70366.40\", \"0.002\"], [\"70366.50\", \"0.004\"], [\"70366.60\", \"0.000\"], [\"70366.70\", \"0.002\"], [\"70366.90\", \"0.000\"], [\"70367.00\", \"0.210\"], [\"70367.10\", \"0.008\"], [\"70367.20\", \"0.006\"], [\"70367.50\", \"0.002\"], [\"70367.80\", \"0.005\"], [\"70368.10\", \"0.000\"], [\"70368.20\", \"0.000\"], [\"70368.40\", \"0.004\"], [\"70368.50\", \"0.000\"], [\"70368.70\", \"0.000\"], [\"70369.90\", \"0.804\"], [\"70370.00\", \"0.802\"], [\"70370.10\", \"0.800\"], [\"70370.20\", \"1.311\"], [\"70370.40\", \"0.000\"], [\"70370.50\", \"0.139\"], [\"70370.90\", \"0.041\"], [\"70371.20\", \"0.023\"], [\"70371.50\", \"0.004\"], [\"70371.70\", \"0.008\"], [\"70371.80\", \"0.005\"], [\"70372.20\", \"0.001\"], [\"70372.80\", \"0.021\"], [\"70373.00\", \"0.247\"], [\"70373.20\", \"0.342\"], [\"70373.50\", \"0.003\"], [\"70373.60\", \"0.024\"], [\"70373.80\", \"0.004\"], [\"70373.90\", \"0.004\"], [\"70374.00\", \"0.003\"], [\"70374.10\", \"0.641\"], [\"70374.20\", \"0.003\"], [\"70374.60\", \"0.000\"], [\"70374.70\", \"0.003\"], [\"70374.80\", \"0.000\"], [\"70374.90\", \"0.000\"], [\"70375.20\", \"0.387\"], [\"70375.40\", \"0.004\"], [\"70375.50\", \"0.204\"], [\"70375.70\", \"0.000\"], [\"70375.80\", \"0.023\"], [\"70376.00\", \"0.061\"], [\"70376.40\", \"0.296\"], [\"70376.50\", \"0.030\"], [\"70376.60\", \"0.060\"], [\"70376.70\", \"0.045\"], [\"70376.80\", \"0.192\"], [\"70377.00\", \"0.092\"], [\"70377.10\", \"0.004\"], [\"70377.20\", \"0.000\"], [\"70377.40\", \"0.001\"], [\"70377.50\", \"0.513\"], [\"70377.60\", \"0.002\"], [\"70377.70\", \"0.007\"], [\"70377.80\", \"0.007\"], [\"70377.90\", \"0.106\"], [\"70378.00\", \"0.051\"], [\"70378.10\", \"0.093\"], [\"70378.20\", \"0.002\"], [\"70378.30\", \"0.000\"], [\"70378.40\", \"0.157\"], [\"70378.50\", \"0.018\"], [\"70378.80\", \"0.000\"], [\"70379.00\", \"0.343\"], [\"70379.20\", \"0.062\"], [\"70379.40\", \"0.030\"], [\"70379.50\", \"0.001\"], [\"70379.60\", \"0.257\"], [\"70379.70\", \"0.723\"], [\"70379.80\", \"0.002\"], [\"70379.90\", \"0.014\"], [\"70380.00\", \"0.047\"], [\"70380.10\", \"0.003\"], [\"70380.50\", \"0.003\"], [\"70381.00\", \"0.079\"], [\"70381.30\", \"0.003\"], [\"70381.40\", \"0.005\"], [\"70381.50\", \"0.443\"], [\"70381.60\", \"0.004\"], [\"70381.70\", \"0.097\"], [\"70381.80\", \"0.002\"], [\"70382.00\", \"1.070\"], [\"70382.10\", \"0.000\"], [\"70382.70\", \"0.036\"], [\"70382.80\", \"0.513\"], [\"70382.90\", \"0.061\"], [\"70383.00\", \"0.083\"], [\"70383.20\", \"0.000\"], [\"70383.60\", \"0.007\"], [\"70383.80\", \"0.043\"], [\"70384.10\", \"0.004\"], [\"70384.60\", \"0.025\"], [\"70384.70\", \"0.003\"], [\"70384.80\", \"0.008\"], [\"70384.90\", \"0.396\"], [\"70385.00\", \"0.346\"], [\"70386.40\", \"0.048\"], [\"70386.70\", \"0.000\"], [\"70387.00\", \"0.211\"], [\"70387.10\", \"0.133\"], [\"70387.40\", \"0.377\"], [\"70387.60\", \"0.258\"], [\"70387.70\", \"0.000\"], [\"70388.20\", \"0.001\"], [\"70388.30\", \"0.000\"], [\"70388.40\", \"0.003\"], [\"70390.20\", \"1.004\"], [\"70390.30\", \"0.003\"], [\"70390.70\", \"0.007\"], [\"70391.40\", \"0.002\"], [\"70391.80\", \"0.001\"], [\"70391.90\", \"0.007\"], [\"70392.00\", \"0.004\"], [\"70392.30\", \"0.005\"], [\"70392.90\", \"0.002\"], [\"70394.80\", \"0.195\"], [\"70394.90\", \"0.064\"], [\"70395.10\", \"0.001\"], [\"70396.40\", \"0.952\"], [\"70397.20\", \"0.041\"], [\"70397.40\", \"0.050\"], [\"70397.60\", \"0.072\"], [\"70397.80\", \"0.002\"], [\"70398.30\", \"0.002\"], [\"70398.90\", \"0.012\"], [\"70399.10\", \"0.200\"], [\"70399.20\", \"0.653\"], [\"70399.50\", \"0.000\"], [\"70402.00\", \"0.188\"], [\"70402.10\", \"0.516\"], [\"70402.20\", \"0.070\"], [\"70402.80\", \"0.642\"], [\"70404.60\", \"0.000\"], [\"70404.70\", \"0.762\"], [\"70405.40\", \"0.015\"], [\"70405.50\", \"0.002\"], [\"70406.20\", \"0.002\"], [\"70407.20\", \"0.005\"], [\"70407.40\", \"0.000\"], [\"70407.70\", \"0.042\"], [\"70408.20\", \"0.024\"], [\"70410.40\", \"0.190\"], [\"70411.70\", \"0.089\"], [\"70414.40\", \"0.015\"], [\"70414.60\", \"0.033\"], [\"70415.30\", \"0.002\"], [\"70415.70\", \"0.051\"], [\"70416.10\", \"0.298\"], [\"70416.40\", \"0.251\"], [\"70417.00\", \"0.003\"], [\"70417.40\", \"0.000\"], [\"70417.50\", \"0.143\"], [\"70417.70\", \"0.000\"], [\"70418.10\", \"0.000\"], [\"70418.50\", \"0.004\"], [\"70418.70\", \"0.062\"], [\"70418.80\", \"0.093\"], [\"70419.00\", \"0.006\"], [\"70419.30\", \"0.002\"], [\"70420.00\", \"1.190\"], [\"70420.60\", \"0.005\"], [\"70421.20\", \"0.028\"], [\"70421.80\", \"0.461\"], [\"70422.20\", \"0.000\"], [\"70422.30\", \"0.000\"], [\"70422.40\", \"0.003\"], [\"70422.50\", \"0.000\"], [\"70422.70\", \"0.194\"], [\"70422.80\", \"0.002\"], [\"70422.90\", \"0.002\"], [\"70423.40\", \"2.093\"], [\"70424.90\", \"0.142\"], [\"70425.00\", \"0.128\"], [\"70426.10\", \"0.192\"], [\"70426.40\", \"0.024\"], [\"70426.90\", \"0.004\"], [\"70427.00\", \"0.002\"], [\"70427.40\", \"0.002\"], [\"70428.40\", \"0.002\"], [\"70429.60\", \"0.033\"], [\"70430.40\", \"0.192\"], [\"70432.80\", \"0.296\"], [\"70433.80\", \"0.036\"], [\"70433.90\", \"0.003\"], [\"70437.50\", \"0.715\"], [\"70437.60\", \"0.023\"], [\"70438.00\", \"0.000\"], [\"70439.40\", \"0.002\"], [\"70440.70\", \"0.052\"], [\"70441.10\", \"0.056\"], [\"70441.50\", \"0.003\"], [\"70442.90\", \"0.043\"], [\"70445.60\", \"0.000\"], [\"70447.00\", \"0.003\"], [\"70449.30\", \"0.000\"], [\"70457.50\", \"0.192\"], [\"70465.80\", \"0.206\"], [\"70475.00\", \"0.354\"], [\"70475.10\", \"7.973\"], [\"70481.40\", \"0.002\"], [\"70483.40\", \"0.203\"], [\"70484.60\", \"0.125\"], [\"70489.10\", \"0.044\"], [\"70489.30\", \"0.002\"], [\"70494.80\", \"4.163\"], [\"70495.00\", \"0.008\"], [\"70495.90\", \"0.316\"], [\"70497.40\", \"0.177\"], [\"70499.20\", \"0.003\"], [\"70503.60\", \"0.359\"], [\"70506.30\", \"0.088\"], [\"70506.70\", \"0.573\"], [\"70513.10\", \"0.000\"], [\"70525.20\", \"0.000\"], [\"70526.10\", \"0.000\"], [\"70526.20\", \"0.262\"], [\"70541.90\", \"0.189\"], [\"70554.50\", \"1.240\"], [\"70565.40\", \"0.009\"], [\"70568.90\", \"0.010\"], [\"70580.10\", \"0.018\"], [\"70582.30\", \"0.000\"], [\"70583.90\", \"0.006\"], [\"70585.30\", \"0.002\"], [\"70587.70\", \"0.378\"], [\"70589.30\", \"0.000\"], [\"70635.70\", \"0.000\"], [\"70667.40\", \"2.016\"], [\"70733.60\", \"0.004\"], [\"70884.80\", \"0.004\"], [\"70924.60\", \"3.722\"], [\"70925.40\", \"0.019\"], [\"71069.70\", \"0.004\"], [\"71070.20\", \"0.000\"], [\"71070.80\", \"0.000\"], [\"71070.90\", \"2.859\"], [\"71097.40\", \"0.004\"], [\"71310.10\", \"0.844\"], [\"71366.00\", \"0.332\"], [\"71366.50\", \"0.367\"], [\"71366.60\", \"1.393\"], [\"71367.00\", \"0.019\"], [\"71367.10\", \"2.778\"], [\"71367.20\", \"0.000\"], [\"71368.40\", \"0.852\"], [\"71368.60\", \"1.488\"], [\"71369.90\", \"0.232\"], [\"71370.20\", \"3.696\"], [\"71370.50\", \"0.005\"], [\"71371.30\", \"0.010\"], [\"71522.70\", \"0.018\"], [\"71735.40\", \"0.006\"], [\"71764.50\", \"0.278\"], [\"100000.00\", \"15.236\"]]}", "symbol": "BTCUSDT"}
{"event": "depthUpdate", "raw_payload": "{\"e\": \"depthUpdate\", \"E\": 1773246398542, \"T\": 1773246398541, \"s\": \"BTCUSDT\", \"U\": 10089705140317, \"u\": 10089705155351, \"pu\": 10089705140291, \"b\": [[\"5000.00\", \"101.418\"], [\"19861.60\", \"0.040\"], [\"19865.90\", \"0.080\"], [\"19887.30\", \"0.170\"], [\"19987.30\", \"0.160\"], [\"20261.60\", \"0.080\"], [\"20261.70\", \"0.010\"], [\"20265.90\", \"0.140\"], [\"66826.60\", \"0.005\"], [\"66846.10\", \"0.004\"], [\"67551.30\", \"0.002\"], [\"69376.80\", \"0.000\"], [\"69434.00\", \"0.287\"], [\"69642.90\", \"0.000\"], [\"69658.00\", \"0.697\"], [\"69662.20\", \"0.000\"], [\"69808.60\", \"0.002\"], [\"69810.10\", \"0.000\"], [\"69837.20\", \"0.005\"], [\"69932.30\", \"0.005\"], [\"69936.00\", \"0.005\"], [\"69983.80\", \"0.000\"], [\"70027.50\", \"0.005\"], [\"70033.30\", \"0.000\"], [\"70040.60\", \"0.000\"], [\"70065.20\", \"0.570\"], [\"70079.20\", \"0.000\"], [\"70080.90\", \"0.202\"], [\"70117.80\", \"0.042\"], [\"70122.70\", \"0.004\"], [\"70128.80\", \"0.002\"], [\"70134.20\", \"0.002\"], [\"70135.80\", \"0.000\"], [\"70135.90\", \"0.000\"], [\"70138.00\", \"1.420\"], [\"70149.80\", \"0.001\"], [\"70160.90\", \"0.908\"], [\"70167.30\", \"0.005\"], [\"70172.70\", \"0.019\"], [\"70174.30\", \"0.002\"], [\"70174.60\", \"0.007\"], [\"70185.60\", \"0.003\"], [\"70186.80\", \"0.039\"], [\"70190.80\", \"0.039\"], [\"70195.80\", \"0.001\"], [\"70199.00\", \"0.082\"], [\"70201.10\", \"0.123\"], [\"70206.20\", \"0.083\"], [\"70206.60\", \"0.039\"], [\"70208.40\", \"4.784\"], [\"70214.50\", \"0.084\"], [\"70216.80\", \"1.515\"], [\"70217.90\", \"0.043\"], [\"70220.80\", \"0.448\"], [\"70224.30\", \"0.442\"], [\"70227.70\", \"0.084\"], [\"70231.50\", \"0.082\"], [\"70238.00\", \"2.094\"], [\"70240.40\", \"0.256\"], [\"70242.50\", \"0.123\"], [\"70242.70\", \"0.000\"], [\"70246.20\", \"0.002\"], [\"70247.10\", \"0.080\"], [\"70247.30\", \"0.384\"], [\"70248.30\", \"0.042\"], [\"70256.10\", \"0.131\"], [\"70261.30\", \"0.170\"], [\"70262.70\", \"0.000\"], [\"70263.00\", \"0.122\"], [\"70263.20\", \"1.417\"], [\"70268.30\", \"0.002\"], [\"70270.00\", \"2.051\"], [\"70270.60\", \"0.002\"], [\"70273.00\", \"0.741\"], [\"70273.90\", \"1.067\"], [\"70275.20\", \"0.082\"], [\"70275.50\", \"0.367\"], [\"70276.60\", \"0.209\"], [\"70277.20\", \"0.002\"], [\"70277.90\", \"6.305\"], [\"70278.00\", \"0.517\"], [\"70279.40\", \"0.083\"], [\"70281.80\", \"1.518\"], [\"70282.90\", \"0.002\"], [\"70283.90\", \"0.002\"], [\"70285.80\", \"0.008\"], [\"70287.20\", \"0.055\"], [\"70287.50\", \"0.053\"], [\"70289.60\", \"0.000\"], [\"70289.90\", \"0.454\"], [\"70290.30\", \"0.002\"], [\"70291.70\", \"0.049\"], [\"70292.70\", \"0.000\"], [\"70292.80\", \"10.739\"], [\"70293.50\", \"0.002\"], [\"70293.70\", \"0.043\"], [\"70294.10\", \"0.003\"], [\"70294.40\", \"0.135\"], [\"70294.80\", \"0.448\"], [\"70295.00\", \"0.055\"], [\"70295.40\", \"0.016\"], [\"70296.00\", \"0.006\"], [\"70296.70\", \"0.051\"], [\"70296.80\", \"0.463\"], [\"70297.20\", \"0.002\"], [\"70298.00\", \"0.000\"], [\"70298.20\", \"0.042\"], [\"70298.40\", \"0.005\"], [\"70298.60\", \"3.620\"], [\"70298.70\", \"0.511\"], [\"70300.80\", \"0.000\"], [\"70301.80\", \"0.645\"], [\"70301.90\", \"0.140\"], [\"70302.40\", \"0.087\"], [\"70302.50\", \"0.002\"], [\"70304.00\", \"0.062\"], [\"70304.30\", \"0.641\"], [\"70304.50\", \"0.007\"], [\"70304.90\", \"0.086\"], [\"70306.50\", \"0.015\"], [\"70306.70\", \"0.004\"], [\"70307.10\", \"0.012\"], [\"70307.20\", \"0.002\"], [\"70308.00\", \"0.132\"], [\"70308.20\", \"0.000\"], [\"70308.60\", \"0.002\"], [\"70310.70\", \"0.581\"], [\"70311.60\", \"0.002\"], [\"70312.00\", \"0.068\"], [\"70312.10\", \"0.002\"], [\"70312.40\", \"0.033\"], [\"70312.50\", \"0.006\"], [\"70312.90\", \"1.007\"], [\"70313.70\", \"0.005\"], [\"70314.20\", \"0.011\"], [\"70314.40\", \"0.000\"], [\"70315.00\", \"0.002\"], [\"70315.20\", \"0.575\"], [\"70315.30\", \"1.226\"], [\"70315.60\", \"0.191\"], [\"70317.30\", \"0.002\"], [\"70318.00\", \"0.041\"], [\"70318.50\", \"0.636\"], [\"70319.40\", \"0.974\"], [\"70320.60\", \"0.002\"], [\"70321.90\", \"0.009\"], [\"70323.30\", \"0.008\"], [\"70323.60\", \"0.000\"], [\"70324.00\", \"0.011\"], [\"70324.40\", \"0.002\"], [\"70324.90\", \"0.006\"], [\"70325.30\", \"0.016\"], [\"70325.60\", \"0.189\"], [\"70326.10\", \"0.007\"], [\"70326.50\", \"0.008\"], [\"70326.80\", \"0.003\"], [\"70327.30\", \"0.071\"], [\"70328.40\", \"0.002\"], [\"70328.60\", \"0.231\"], [\"70329.00\", \"0.013\"], [\"70329.50\", \"0.004\"], [\"70329.80\", \"0.024\"], [\"70330.30\", \"0.005\"], [\"70330.60\", \"0.000\"], [\"70330.80\", \"0.193\"], [\"70331.70\", \"0.122\"], [\"70332.00\", \"2.167\"], [\"70332.40\", \"0.087\"], [\"70332.50\", \"0.002\"], [\"70332.60\", \"0.082\"], [\"70332.90\", \"0.000\"], [\"70333.00\", \"0.511\"], [\"70333.10\", \"0.003\"], [\"70333.20\", \"0.003\"], [\"70333.30\", \"0.005\"], [\"70333.50\", \"0.318\"], [\"70333.80\", \"0.002\"], [\"70334.00\", \"0.000\"], [\"70334.30\", \"0.000\"], [\"70334.40\", \"0.577\"], [\"70334.50\", \"0.520\"], [\"70334.60\", \"0.593\"], [\"70335.20\", \"0.348\"], [\"70335.30\", \"0.002\"], [\"70335.50\", \"0.001\"], [\"70335.90\", \"0.006\"], [\"70336.00\", \"0.092\"], [\"70336.60\", \"0.000\"], [\"70336.70\", \"0.002\"], [\"70336.80\", \"0.006\"], [\"70337.00\", \"0.012\"], [\"70337.20\", \"0.513\"], [\"70337.30\", \"0.010\"], [\"70337.40\", \"0.012\"], [\"70337.70\", \"0.009\"], [\"70338.00\", \"0.034\"], [\"70338.10\", \"0.001\"], [\"70338.30\", \"0.007\"], [\"70338.60\", \"0.010\"], [\"70338.70\", \"0.196\"], [\"70338.80\", \"0.008\"], [\"70339.00\", \"0.000\"], [\"70339.20\", \"0.428\"], [\"70339.40\", \"0.005\"], [\"70339.60\", \"0.188\"], [\"70339.70\", \"1.209\"], [\"70340.10\", \"0.005\"], [\"70340.20\", \"0.003\"], [\"70340.80\", \"0.005\"], [\"70340.90\", \"0.003\"], [\"70341.50\", \"0.003\"], [\"70341.60\", \"0.009\"], [\"70341.70\", \"10.230\"], [\"70341.80\", \"0.798\"], [\"70342.10\", \"0.000\"], [\"70342.20\", \"0.003\"], [\"70342.30\", \"0.053\"], [\"70342.40\", \"0.007\"], [\"70342.60\", \"0.007\"], [\"70343.30\", \"0.004\"], [\"70343.50\", \"0.359\"], [\"70343.60\", \"0.003\"], [\"70343.70\", \"0.145\"], [\"70343.80\", \"0.004\"], [\"70344.00\", \"0.104\"], [\"70344.30\", \"0.105\"], [\"70344.40\", \"0.000\"], [\"70344.50\", \"0.000\"], [\"70344.60\", \"0.574\"], [\"70344.80\", \"0.139\"], [\"70345.20\", \"0.001\"], [\"70345.50\", \"0.014\"], [\"70345.60\", \"0.087\"], [\"70345.80\", \"0.038\"], [\"70346.20\", \"0.554\"], [\"70346.30\", \"0.003\"], [\"70346.40\", \"0.004\"], [\"70346.80\", \"0.000\"], [\"70346.90\", \"0.345\"], [\"70347.40\", \"0.033\"], [\"70347.50\", \"0.002\"], [\"70347.60\", \"0.503\"], [\"70347.80\", \"0.270\"], [\"70348.00\", \"0.013\"], [\"70348.30\", \"0.000\"], [\"70348.50\", \"0.181\"], [\"70348.80\", \"0.001\"], [\"70349.30\", \"0.002\"], [\"70349.40\", \"0.010\"], [\"70349.50\", \"0.006\"], [\"70349.90\", \"0.003\"], [\"70350.00\", \"0.471\"], [\"70350.10\", \"0.002\"], [\"70350.20\", \"0.302\"], [\"70350.40\", \"0.020\"], [\"70350.60\", \"0.000\"], [\"70350.70\", \"0.002\"], [\"70350.80\", \"0.004\"], [\"70351.00\", \"0.054\"], [\"70351.20\", \"0.007\"], [\"70351.40\", \"0.263\"], [\"70351.80\", \"0.170\"], [\"70351.90\", \"0.006\"], [\"70352.00\", \"0.106\"], [\"70352.30\", \"0.006\"], [\"70352.70\", \"0.417\"], [\"70352.80\", \"0.037\"], [\"70353.00\", \"0.034\"], [\"70353.20\", \"0.000\"], [\"70353.30\", \"0.411\"], [\"70353.50\", \"0.008\"], [\"70354.30\", \"0.000\"], [\"70354.50\", \"0.004\"], [\"70354.80\", \"0.049\"], [\"70355.30\", \"0.002\"], [\"70355.40\", \"0.004\"], [\"70355.90\", \"0.000\"], [\"70356.00\", \"0.006\"], [\"70356.20\", \"0.004\"], [\"70356.30\", \"0.008\"], [\"70356.50\", \"0.014\"], [\"70356.70\", \"0.003\"], [\"70356.80\", \"0.001\"], [\"70358.10\", \"0.000\"], [\"70358.80\", \"0.004\"], [\"70358.90\", \"0.002\"], [\"70359.30\", \"0.000\"], [\"70360.10\", \"0.004\"], [\"70360.20\", \"0.003\"], [\"70360.30\", \"0.002\"], [\"70360.50\", \"0.003\"], [\"70360.80\", \"0.003\"], [\"70360.90\", \"1.000\"], [\"70361.00\", \"0.004\"], [\"70361.10\", \"0.002\"], [\"70361.20\", \"0.002\"], [\"70361.40\", \"0.000\"], [\"70361.50\", \"0.001\"], [\"70361.60\", \"1.555\"], [\"70361.70\", \"0.000\"], [\"70361.80\", \"0.000\"], [\"70361.90\", \"0.000\"], [\"70362.00\", \"0.000\"], [\"70362.10\", \"0.000\"], [\"70362.20\", \"0.000\"], [\"70362.30\", \"0.000\"], [\"70362.40\", \"0.000\"], [\"70362.50\", \"0.000\"], [\"70363.00\", \"0.000\"], [\"70363.10\", \"0.000\"], [\"70363.20\", \"0.000\"], [\"70363.30\", \"0.000\"], [\"70363.50\", \"0.000\"], [\"70363.60\", \"0.000\"], [\"70364.00\", \"0.000\"], [\"70364.10\", \"0.000\"], [\"70364.20\", \"0.000\"], [\"70364.30\", \"0.000\"], [\"70364.70\", \"0.000\"], [\"70365.10\", \"0.000\"], [\"70365.20\", \"0.000\"], [\"70365.60\", \"0.000\"], [\"70365.80\", \"0.000\"], [\"70365.90\", \"0.000\"]], \"a\": [[\"70361.70\", \"7.888\"], [\"70361.80\", \"0.025\"], [\"70361.90\", \"0.001\"], [\"70362.00\", \"0.003\"], [\"70362.10\", \"0.000\"], [\"70362.20\", \"0.000\"], [\"70362.30\", \"0.000\"], [\"70362.40\", \"0.002\"], [\"70362.50\", \"0.000\"], [\"70362.60\", \"0.000\"], [\"70362.80\", \"0.000\"], [\"70362.90\", \"0.000\"], [\"70363.00\", \"0.000\"], [\"70363.10\", \"0.000\"], [\"70363.20\", \"0.000\"], [\"70363.30\", \"0.002\"], [\"70363.40\", \"0.000\"], [\"70363.50\", \"0.005\"], [\"70363.60\", \"0.000\"], [\"70363.70\", \"0.000\"], [\"70364.10\", \"0.003\"], [\"70364.20\", \"0.000\"], [\"70364.30\", \"0.001\"], [\"70364.40\", \"0.000\"], [\"70364.60\", \"0.000\"], [\"70364.80\", \"0.000\"], [\"70365.00\", \"0.002\"], [\"70365.10\", \"0.002\"], [\"70365.20\", \"0.102\"], [\"70365.30\", \"0.014\"], [\"70365.40\", \"0.004\"], [\"70365.70\", \"0.000\"], [\"70365.90\", \"1.442\"], [\"70366.00\", \"0.860\"], [\"70366.10\", \"0.003\"], [\"70366.50\", \"0.004\"], [\"70366.60\", \"0.041\"], [\"70366.90\", \"0.003\"], [\"70367.00\", \"0.210\"], [\"70367.20\", \"0.004\"], [\"70367.60\", \"0.061\"], [\"70368.00\", \"0.001\"], [\"70368.50\", \"0.003\"], [\"70368.70\", \"0.003\"], [\"70368.90\", \"0.002\"], [\"70369.10\", \"0.021\"], [\"70369.20\", \"0.000\"], [\"70369.50\", \"0.003\"], [\"70369.90\", \"1.095\"], [\"70370.20\", \"1.314\"], [\"70370.30\", \"0.001\"], [\"70370.90\", \"0.003\"], [\"70371.00\", \"0.004\"], [\"70371.10\", \"0.126\"], [\"70371.20\", \"0.004\"], [\"70371.30\", \"0.000\"], [\"70371.40\", \"0.019\"], [\"70371.50\", \"0.005\"], [\"70371.70\", \"0.005\"], [\"70371.90\", \"0.008\"], [\"70372.00\", \"0.005\"], [\"70372.20\", \"0.003\"], [\"70372.30\", \"0.144\"], [\"70372.40\", \"0.014\"], [\"70372.80\", \"0.002\"], [\"70372.90\", \"0.189\"], [\"70373.10\", \"0.511\"], [\"70373.30\", \"0.003\"], [\"70373.40\", \"0.022\"], [\"70373.50\", \"0.000\"], [\"70373.60\", \"0.046\"], [\"70373.70\", \"0.017\"], [\"70374.00\", \"0.037\"], [\"70374.10\", \"0.672\"], [\"70374.20\", \"0.136\"], [\"70374.40\", \"0.047\"], [\"70374.50\", \"0.004\"], [\"70374.70\", \"0.017\"], [\"70374.90\", \"0.028\"], [\"70375.00\", \"0.005\"], [\"70375.20\", \"0.391\"], [\"70375.30\", \"0.539\"], [\"70375.40\", \"0.005\"], [\"70375.60\", \"0.050\"], [\"70375.70\", \"0.095\"], [\"70375.80\", \"0.002\"], [\"70376.00\", \"0.004\"], [\"70376.40\", \"0.262\"], [\"70376.50\", \"0.006\"], [\"70376.60\", \"0.002\"], [\"70376.70\", \"0.002\"], [\"70376.90\", \"0.066\"], [\"70377.00\", \"0.003\"], [\"70377.10\", \"0.003\"], [\"70377.30\", \"0.003\"], [\"70377.70\", \"0.000\"], [\"70377.80\", \"0.007\"], [\"70377.90\", \"0.004\"], [\"70378.00\", \"0.004\"], [\"70378.10\", \"0.002\"], [\"70378.40\", \"0.000\"], [\"70378.50\", \"0.004\"], [\"70379.10\", \"0.097\"], [\"70379.20\", \"0.003\"], [\"70379.30\", \"0.004\"], [\"70379.40\", \"0.000\"], [\"70379.50\", \"0.003\"], [\"70379.60\", \"0.162\"], [\"70379.90\", \"0.014\"], [\"70380.00\", \"0.045\"], [\"70380.10\", \"0.005\"], [\"70380.40\", \"0.188\"], [\"70380.70\", \"0.072\"], [\"70381.00\", \"0.040\"], [\"70381.40\", \"0.002\"], [\"70381.70\", \"0.040\"], [\"70382.40\", \"0.256\"], [\"70382.70\", \"0.038\"], [\"70382.80\", \"0.515\"], [\"70382.90\", \"0.042\"], [\"70383.00\", \"0.154\"], [\"70383.60\", \"0.005\"], [\"70384.10\", \"0.006\"], [\"70384.50\", \"0.008\"], [\"70385.00\", \"0.348\"], [\"70385.20\", \"0.557\"], [\"70386.00\", \"0.049\"], [\"70386.30\", \"1.003\"], [\"70387.10\", \"0.131\"], [\"70387.20\", \"0.052\"], [\"70387.30\", \"0.008\"], [\"70387.60\", \"0.222\"], [\"70388.70\", \"0.000\"], [\"70389.00\", \"0.004\"], [\"70389.20\", \"0.002\"], [\"70389.40\", \"0.003\"], [\"70389.50\", \"0.001\"], [\"70390.20\", \"0.002\"], [\"70390.60\", \"0.001\"], [\"70390.80\", \"0.003\"], [\"70391.10\", \"0.005\"], [\"70392.00\", \"0.084\"], [\"70392.10\", \"0.765\"], [\"70392.40\", \"0.412\"], [\"70393.30\", \"0.027\"], [\"70393.70\", \"0.004\"], [\"70393.90\", \"0.022\"], [\"70394.00\", \"0.000\"], [\"70394.20\", \"0.004\"], [\"70394.40\", \"0.009\"], [\"70394.60\", \"0.202\"], [\"70394.80\", \"0.192\"], [\"70395.00\", \"0.004\"], [\"70395.10\", \"0.003\"], [\"70396.30\", \"0.001\"], [\"70396.40\", \"0.766\"], [\"70396.80\", \"0.011\"], [\"70396.90\", \"0.074\"], [\"70397.00\", \"0.002\"], [\"70397.20\", \"0.001\"], [\"70397.40\", \"0.008\"], [\"70397.50\", \"0.550\"], [\"70397.60\", \"0.072\"], [\"70398.90\", \"0.005\"], [\"70399.00\", \"0.002\"], [\"70400.70\", \"0.000\"], [\"70400.90\", \"0.765\"], [\"70401.00\", \"0.241\"], [\"70402.20\", \"0.008\"], [\"70403.90\", \"0.023\"], [\"70404.50\", \"0.000\"], [\"70404.80\", \"0.407\"], [\"70404.90\", \"0.002\"], [\"70408.40\", \"0.004\"], [\"70408.80\", \"0.002\"], [\"70408.90\", \"0.077\"], [\"70409.10\", \"1.580\"], [\"70409.20\", \"0.186\"], [\"70410.50\", \"0.082\"], [\"70411.60\", \"0.022\"], [\"70411.70\", \"0.007\"], [\"70412.80\", \"0.271\"], [\"70413.00\", \"0.009\"], [\"70413.30\", \"0.000\"], [\"70413.90\", \"0.000\"], [\"70414.20\", \"0.005\"], [\"70414.50\", \"0.057\"], [\"70414.60\", \"0.115\"], [\"70414.70\", \"0.000\"], [\"70415.40\", \"0.002\"], [\"70415.70\", \"0.002\"], [\"70416.70\", \"0.085\"], [\"70418.80\", \"0.009\"], [\"70420.40\", \"0.082\"], [\"70420.50\", \"0.000\"], [\"70420.70\", \"0.128\"], [\"70421.20\", \"0.000\"], [\"70421.50\", \"0.280\"], [\"70421.80\", \"0.333\"], [\"70423.20\", \"0.035\"], [\"70423.30\", \"0.521\"], [\"70424.00\", \"0.006\"], [\"70424.20\", \"0.000\"], [\"70425.00\", \"0.212\"], [\"70425.30\", \"0.006\"], [\"70425.90\", \"0.527\"], [\"70427.90\", \"0.000\"], [\"70428.50\", \"0.086\"], [\"70429.30\", \"0.032\"], [\"70430.30\", \"0.056\"], [\"70431.30\", \"0.003\"], [\"70432.10\", \"0.516\"], [\"70435.60\", \"0.342\"], [\"70436.60\", \"0.049\"], [\"70439.20\", \"0.006\"], [\"70439.60\", \"0.000\"], [\"70439.90\", \"0.000\"], [\"70440.70\", \"0.049\"], [\"70441.00\", \"0.033\"], [\"70441.50\", \"0.002\"], [\"70444.30\", \"0.138\"], [\"70444.40\", \"0.262\"], [\"70444.70\", \"0.353\"], [\"70448.00\", \"0.007\"], [\"70448.10\", \"1.252\"], [\"70453.00\", \"10.246\"], [\"70455.20\", \"0.073\"], [\"70455.60\", \"0.039\"], [\"70458.70\", \"0.002\"], [\"70460.80\", \"0.082\"], [\"70462.10\", \"0.781\"], [\"70465.20\", \"0.084\"], [\"70472.30\", \"0.092\"], [\"70479.00\", \"0.010\"], [\"70485.10\", \"0.228\"], [\"70485.50\", \"0.002\"], [\"70487.20\", \"0.029\"], [\"70488.50\", \"0.000\"], [\"70491.10\", \"0.447\"], [\"70491.20\", \"0.002\"], [\"70503.10\", \"0.086\"], [\"70503.60\", \"0.363\"], [\"70511.10\", \"0.033\"], [\"70511.30\", \"0.126\"], [\"70512.20\", \"0.129\"], [\"70515.00\", \"0.000\"], [\"70523.70\", \"0.318\"], [\"70526.80\", \"0.061\"], [\"70527.00\", \"0.081\"], [\"70528.40\", \"0.083\"], [\"70528.90\", \"0.128\"], [\"70531.00\", \"0.557\"], [\"70536.70\", \"0.000\"], [\"70539.50\", \"0.000\"], [\"70540.90\", \"0.511\"], [\"70541.40\", \"0.009\"], [\"70546.40\", \"0.007\"], [\"70553.40\", \"0.007\"], [\"70556.20\", \"0.002\"], [\"70557.10\", \"1.598\"], [\"70558.80\", \"0.000\"], [\"70560.40\", \"23.155\"], [\"70564.40\", \"0.000\"], [\"70565.10\", \"0.000\"], [\"70565.40\", \"0.006\"], [\"70567.40\", \"0.009\"], [\"70573.00\", \"0.089\"], [\"70574.40\", \"0.009\"], [\"70575.40\", \"0.000\"], [\"70575.50\", \"0.000\"], [\"70576.80\", \"0.447\"], [\"70577.40\", \"0.018\"], [\"70577.70\", \"0.065\"], [\"70579.10\", \"0.000\"], [\"70580.00\", \"0.006\"], [\"70580.10\", \"0.000\"], [\"70581.40\", \"0.009\"], [\"70582.40\", \"0.127\"], [\"70582.60\", \"10.305\"], [\"70584.70\", \"1.324\"], [\"70588.40\", \"0.012\"], [\"70591.70\", \"0.381\"], [\"70595.40\", \"0.010\"], [\"70597.50\", \"0.043\"], [\"70597.70\", \"0.000\"], [\"70598.00\", \"0.000\"], [\"70598.70\", \"0.000\"], [\"70598.80\", \"0.005\"], [\"70603.70\", \"0.019\"], [\"70605.70\", \"0.002\"], [\"70609.90\", \"0.030\"], [\"70612.60\", \"0.000\"], [\"70612.70\", \"0.000\"], [\"70619.70\", \"0.002\"], [\"70626.70\", \"0.000\"], [\"70632.10\", \"0.004\"], [\"70646.00\", \"0.002\"], [\"70651.00\", \"4.878\"], [\"70651.60\", \"0.201\"], [\"70662.40\", \"0.198\"], [\"70693.90\", \"0.060\"], [\"70713.60\", \"0.000\"], [\"70728.70\", \"0.002\"], [\"70747.00\", \"2.002\"], [\"70789.10\", \"0.005\"], [\"70842.40\", \"0.006\"], [\"70924.60\", \"0.002\"], [\"70937.80\", \"0.000\"], [\"71065.30\", \"0.000\"], [\"71069.70\", \"0.002\"], [\"71118.30\", \"0.004\"], [\"71331.00\", \"0.004\"], [\"71361.70\", \"0.281\"], [\"71361.80\", \"0.040\"], [\"71366.60\", \"1.391\"], [\"71367.00\", \"0.009\"], [\"71367.10\", \"2.776\"], [\"71376.90\", \"0.116\"], [\"73919.30\", \"0.111\"], [\"89523.20\", \"0.000\"], [\"100000.00\", \"15.236\"]]}", "symbol": "BTCUSDT"}
{"event": "depthUpdate", "raw_payload": "{\"e\": \"depthUpdate\", \"E\": 1773246398644, \"T\": 1773246398640, \"s\": \"BTCUSDT\", \"U\": 10089705155362, \"u\": 10089705163518, \"pu\": 10089705155351, \"b\": [[\"1000.00\", \"26.792\"], [\"5000.00\", \"101.418\"], [\"19861.60\", \"0.120\"], [\"19887.30\", \"0.080\"], [\"19987.30\", \"0.080\"], [\"20161.60\", \"0.080\"], [\"20261.60\", \"0.170\"], [\"20287.30\", \"0.070\"], [\"33000.00\", \"10.797\"], [\"66847.00\", \"0.003\"], [\"67835.80\", \"0.002\"], [\"69369.00\", \"1.203\"], [\"69511.20\", \"0.000\"], [\"69517.30\", \"0.642\"], [\"69658.00\", \"0.697\"], [\"70041.80\", \"0.363\"], [\"70064.80\", \"0.002\"], [\"70065.30\", \"0.116\"], [\"70115.50\", \"9.915\"], [\"70118.00\", \"2.414\"], [\"70128.90\", \"0.312\"], [\"70134.20\", \"0.038\"], [\"70135.80\", \"0.043\"], [\"70135.90\", \"0.043\"], [\"70138.00\", \"1.455\"], [\"70138.10\", \"0.074\"], [\"70150.60\", \"0.000\"], [\"70153.90\", \"0.311\"], [\"70157.70\", \"6.350\"], [\"70159.50\", \"2.180\"], [\"70167.30\", \"0.002\"], [\"70192.80\", \"0.003\"], [\"70196.00\", \"1.636\"], [\"70199.20\", \"0.191\"], [\"70199.90\", \"4.320\"], [\"70213.90\", \"0.045\"], [\"70235.00\", \"0.095\"], [\"70238.80\", \"0.268\"], [\"70240.60\", \"0.833\"], [\"70250.70\", \"0.115\"], [\"70250.80\", \"3.605\"], [\"70251.80\", \"0.006\"], [\"70256.10\", \"0.082\"], [\"70256.60\", \"1.329\"], [\"70259.00\", \"1.309\"], [\"70259.10\", \"0.003\"], [\"70262.10\", \"0.008\"], [\"70262.20\", \"0.000\"], [\"70266.00\", \"0.894\"], [\"70271.30\", \"0.225\"], [\"70282.30\", \"0.027\"], [\"70282.80\", \"0.521\"], [\"70285.40\", \"0.142\"], [\"70289.90\", \"0.378\"], [\"70293.70\", \"0.018\"], [\"70294.60\", \"0.000\"], [\"70294.80\", \"0.531\"], [\"70295.00\", \"0.005\"], [\"70295.70\", \"0.007\"], [\"70296.60\", \"0.004\"], [\"70296.70\", \"0.000\"], [\"70296.90\", \"0.263\"], [\"70297.60\", \"0.002\"], [\"70300.30\", \"0.002\"], [\"70302.20\", \"0.851\"], [\"70304.00\", \"0.000\"], [\"70304.10\", \"0.853\"], [\"70304.40\", \"0.784\"], [\"70308.90\", \"0.547\"], [\"70311.50\", \"1.068\"], [\"70311.60\", \"0.074\"], [\"70312.00\", \"0.066\"], [\"70315.60\", \"0.211\"], [\"70316.20\", \"0.015\"], [\"70317.10\", \"0.085\"], [\"70318.20\", \"0.405\"], [\"70320.20\", \"0.000\"], [\"70321.00\", \"0.289\"], [\"70322.60\", \"0.035\"], [\"70323.50\", \"0.005\"], [\"70324.20\", \"0.008\"], [\"70324.50\", \"0.516\"], [\"70327.30\", \"0.000\"], [\"70327.50\", \"0.002\"], [\"70329.60\", \"0.004\"], [\"70330.00\", \"0.096\"], [\"70331.10\", \"0.071\"], [\"70332.40\", \"0.096\"], [\"70332.50\", \"0.011\"], [\"70332.60\", \"0.097\"], [\"70333.10\", \"0.003\"], [\"70333.20\", \"0.003\"], [\"70333.80\", \"0.004\"], [\"70333.90\", \"0.005\"], [\"70334.50\", \"0.511\"], [\"70334.60\", \"0.000\"], [\"70334.80\", \"0.750\"], [\"70335.20\", \"0.348\"], [\"70335.30\", \"0.002\"], [\"70335.70\", \"0.005\"], [\"70335.80\", \"0.234\"], [\"70335.90\", \"0.004\"], [\"70336.00\", \"0.103\"], [\"70337.30\", \"0.012\"], [\"70337.40\", \"0.014\"], [\"70337.90\", \"0.139\"], [\"70338.00\", \"0.034\"], [\"70338.10\", \"0.078\"], [\"70338.70\", \"0.194\"], [\"70338.80\", \"0.006\"], [\"70340.10\", \"0.025\"], [\"70341.00\", \"0.342\"], [\"70343.50\", \"0.287\"], [\"70343.90\", \"0.002\"], [\"70344.00\", \"0.208\"], [\"70344.10\", \"0.011\"], [\"70344.40\", \"0.003\"], [\"70344.80\", \"0.003\"], [\"70345.20\", \"0.115\"], [\"70345.80\", \"0.017\"], [\"70346.30\", \"0.046\"], [\"70346.50\", \"0.252\"], [\"70346.60\", \"0.045\"], [\"70346.70\", \"0.037\"], [\"70346.90\", \"0.347\"], [\"70347.30\", \"0.154\"], [\"70347.60\", \"0.376\"], [\"70347.70\", \"0.093\"], [\"70347.90\", \"0.000\"], [\"70348.00\", \"0.005\"], [\"70348.90\", \"0.205\"], [\"70349.10\", \"0.009\"], [\"70350.30\", \"0.003\"], [\"70351.10\", \"0.006\"], [\"70351.40\", \"0.000\"], [\"70351.50\", \"0.655\"], [\"70351.60\", \"0.003\"], [\"70351.70\", \"0.008\"], [\"70351.80\", \"0.011\"], [\"70352.10\", \"0.003\"], [\"70352.40\", \"0.000\"], [\"70352.50\", \"0.000\"], [\"70352.80\", \"0.002\"], [\"70353.10\", \"0.002\"], [\"70353.30\", \"0.003\"], [\"70353.40\", \"0.003\"], [\"70354.00\", \"0.003\"], [\"70354.20\", \"0.009\"], [\"70354.80\", \"0.070\"], [\"70355.00\", \"0.046\"], [\"70355.40\", \"0.003\"], [\"70356.10\", \"0.003\"], [\"70356.50\", \"0.011\"], [\"70356.70\", \"0.002\"], [\"70357.00\", \"0.016\"], [\"70358.50\", \"0.002\"], [\"70358.70\", \"0.006\"], [\"70360.10\", \"0.000\"], [\"70361.60\", \"1.581\"]], \"a\": [[\"70361.70\", \"6.901\"], [\"70361.80\", \"0.027\"], [\"70361.90\", \"0.058\"], [\"70362.00\", \"0.000\"], [\"70364.60\", \"0.002\"], [\"70364.70\", \"0.019\"], [\"70364.90\", \"0.003\"], [\"70365.10\", \"0.000\"], [\"70365.20\", \"0.099\"], [\"70365.50\", \"0.003\"], [\"70365.80\", \"0.003\"], [\"70365.90\", \"1.444\"], [\"70366.00\", \"0.812\"], [\"70366.10\", \"0.001\"], [\"70366.40\", \"0.007\"], [\"70366.50\", \"0.005\"], [\"70366.60\", \"0.039\"], [\"70367.00\", \"0.002\"], [\"70367.10\", \"0.000\"], [\"70367.20\", \"0.001\"], [\"70367.80\", \"0.008\"], [\"70369.70\", \"0.740\"], [\"70369.80\", \"1.070\"], [\"70369.90\", \"0.806\"], [\"70370.30\", \"0.001\"], [\"70371.40\", \"0.090\"], [\"70372.20\", \"0.007\"], [\"70372.50\", \"0.008\"], [\"70373.00\", \"0.245\"], [\"70376.10\", \"0.004\"], [\"70377.20\", \"0.003\"], [\"70378.70\", \"0.025\"], [\"70378.90\", \"0.250\"], [\"70379.10\", \"0.122\"], [\"70379.50\", \"0.028\"], [\"70379.60\", \"0.002\"], [\"70379.70\", \"0.759\"], [\"70380.50\", \"0.039\"], [\"70381.40\", \"0.250\"], [\"70382.40\", \"0.231\"], [\"70382.70\", \"0.157\"], [\"70382.80\", \"0.723\"], [\"70382.90\", \"0.033\"], [\"70383.10\", \"0.002\"], [\"70383.90\", \"0.002\"], [\"70384.90\", \"0.148\"], [\"70385.00\", \"0.592\"], [\"70385.10\", \"0.025\"], [\"70387.00\", \"0.209\"], [\"70387.10\", \"0.070\"], [\"70387.40\", \"0.383\"], [\"70389.60\", \"0.404\"], [\"70392.00\", \"0.638\"], [\"70392.10\", \"1.137\"], [\"70392.40\", \"0.004\"], [\"70393.30\", \"0.042\"], [\"70395.20\", \"0.003\"], [\"70395.40\", \"0.089\"], [\"70396.40\", \"0.764\"], [\"70396.80\", \"0.045\"], [\"70397.10\", \"0.000\"], [\"70397.50\", \"0.514\"], [\"70400.30\", \"0.023\"], [\"70402.20\", \"0.003\"], [\"70406.30\", \"0.023\"], [\"70408.80\", \"0.075\"], [\"70408.90\", \"0.004\"], [\"70409.70\", \"0.270\"], [\"70410.70\", \"0.010\"], [\"70411.40\", \"0.002\"], [\"70411.60\", \"0.002\"], [\"70411.70\", \"0.488\"], [\"70411.80\", \"0.002\"], [\"70412.30\", \"0.350\"], [\"70413.10\", \"0.060\"], [\"70413.20\", \"0.511\"], [\"70413.30\", \"0.141\"], [\"70414.50\", \"0.057\"], [\"70415.90\", \"0.581\"], [\"70417.20\", \"0.849\"], [\"70417.30\", \"0.000\"], [\"70417.50\", \"0.002\"], [\"70419.10\", \"0.849\"], [\"70420.00\", \"1.318\"], [\"70420.10\", \"0.221\"], [\"70420.40\", \"0.082\"], [\"70420.50\", \"0.020\"], [\"70420.70\", \"0.000\"], [\"70421.20\", \"0.028\"], [\"70422.10\", \"0.002\"], [\"70422.60\", \"0.100\"], [\"70425.80\", \"1.068\"], [\"70427.10\", \"0.345\"], [\"70427.20\", \"2.682\"], [\"70429.80\", \"0.000\"], [\"70432.10\", \"0.519\"], [\"70435.50\", \"0.001\"], [\"70438.50\", \"0.100\"], [\"70439.10\", \"0.084\"], [\"70439.20\", \"0.003\"], [\"70440.20\", \"0.152\"], [\"70442.60\", \"0.232\"], [\"70444.20\", \"0.511\"], [\"70447.20\", \"0.146\"], [\"70452.20\", \"0.000\"], [\"70453.50\", \"0.000\"], [\"70454.30\", \"0.142\"], [\"70455.30\", \"0.000\"], [\"70456.40\", \"0.002\"], [\"70459.20\", \"0.102\"], [\"70461.60\", \"0.511\"], [\"70466.30\", \"0.108\"], [\"70466.60\", \"1.450\"], [\"70472.50\", \"0.029\"], [\"70480.20\", \"0.121\"], [\"70483.80\", \"0.000\"], [\"70493.10\", \"0.003\"], [\"70495.60\", \"1.058\"], [\"70499.80\", \"13.983\"], [\"70512.90\", \"0.007\"], [\"70516.00\", \"0.024\"], [\"70524.80\", \"0.052\"], [\"70526.10\", \"0.025\"], [\"70526.40\", \"0.002\"], [\"70532.90\", \"0.000\"], [\"70533.30\", \"0.013\"], [\"70534.00\", \"0.176\"], [\"70541.20\", \"6.567\"], [\"70559.70\", \"0.000\"], [\"70561.80\", \"0.000\"], [\"70562.90\", \"0.000\"], [\"70581.10\", \"2.240\"], [\"70585.90\", \"0.003\"], [\"70597.70\", \"0.050\"], [\"70602.10\", \"1.500\"], [\"70603.40\", \"4.289\"], [\"70603.80\", \"0.233\"], [\"70612.50\", \"1.166\"], [\"70656.80\", \"10.000\"], [\"70701.60\", \"0.000\"], [\"70905.60\", \"0.004\"], [\"71065.30\", \"0.000\"], [\"71369.10\", \"0.606\"], [\"71543.80\", \"0.004\"], [\"73919.30\", \"0.109\"]]}", "symbol": "BTCUSDT"}
{"event": "depthUpdate", "raw_payload": "{\"e\": \"depthUpdate\", \"E\": 1773246398746, \"T\": 1773246398745, \"s\": \"BTCUSDT\", \"U\": 10089705163737, \"u\": 10089705172046, \"pu\": 10089705163518, \"b\": [[\"5000.00\", \"101.418\"], [\"19861.60\", \"0.210\"], [\"19885.40\", \"0.000\"], [\"19887.30\", \"0.000\"], [\"19985.40\", \"0.000\"], [\"19987.30\", \"0.000\"], [\"20161.60\", \"0.160\"], [\"20261.60\", \"0.260\"], [\"20287.20\", \"0.000\"], [\"20287.30\", \"0.000\"], [\"33000.00\", \"10.793\"], [\"66848.70\", \"0.005\"], [\"68364.40\", \"0.004\"], [\"69341.40\", \"2.006\"], [\"69418.10\", \"29.549\"], [\"69627.00\", \"23.584\"], [\"69658.00\", \"0.697\"], [\"69787.50\", \"19.936\"], [\"69810.50\", \"0.000\"], [\"69811.70\", \"3.730\"], [\"69913.30\", \"16.994\"], [\"70018.40\", \"14.099\"], [\"70080.20\", \"1.093\"], [\"70095.50\", \"11.620\"], [\"70135.10\", \"0.027\"], [\"70135.60\", \"0.000\"], [\"70137.70\", \"0.054\"], [\"70141.10\", \"0.009\"], [\"70215.20\", \"0.239\"], [\"70246.60\", \"0.618\"], [\"70263.90\", \"0.247\"], [\"70265.70\", \"0.044\"], [\"70269.90\", \"0.044\"], [\"70273.40\", \"0.559\"], [\"70273.60\", \"0.119\"], [\"70276.20\", \"0.052\"], [\"70279.50\", \"0.069\"], [\"70286.50\", \"0.002\"], [\"70287.20\", \"0.058\"], [\"70293.30\", \"1.628\"], [\"70294.10\", \"0.000\"], [\"70294.40\", \"0.018\"], [\"70294.80\", \"0.344\"], [\"70299.10\", \"0.028\"], [\"70301.80\", \"0.541\"], [\"70302.60\", \"0.004\"], [\"70310.30\", \"0.016\"], [\"70311.40\", \"0.094\"], [\"70311.50\", \"1.066\"], [\"70312.00\", \"0.066\"], [\"70314.20\", \"0.004\"], [\"70315.60\", \"0.231\"], [\"70318.00\", \"0.048\"], [\"70318.50\", \"0.651\"], [\"70319.10\", \"0.011\"], [\"70320.10\", \"0.137\"], [\"70320.60\", \"0.017\"], [\"70320.70\", \"0.003\"], [\"70320.80\", \"0.020\"], [\"70321.40\", \"0.239\"], [\"70321.90\", \"0.002\"], [\"70322.10\", \"0.238\"], [\"70322.80\", \"0.003\"], [\"70324.00\", \"0.004\"], [\"70325.00\", \"0.412\"], [\"70331.70\", \"0.181\"], [\"70334.30\", \"0.001\"], [\"70334.80\", \"0.670\"], [\"70337.80\", \"0.225\"], [\"70344.00\", \"0.395\"], [\"70346.30\", \"0.223\"], [\"70346.60\", \"0.070\"], [\"70346.70\", \"0.120\"], [\"70347.30\", \"0.043\"], [\"70347.40\", \"0.103\"], [\"70347.50\", \"0.115\"], [\"70350.80\", \"0.004\"], [\"70354.50\", \"0.006\"], [\"70356.30\", \"0.005\"], [\"70356.50\", \"0.006\"], [\"70358.60\", \"0.006\"], [\"70358.70\", \"0.007\"], [\"70360.80\", \"0.005\"], [\"70361.50\", \"0.000\"], [\"70361.60\", \"0.896\"]], \"a\": [[\"70361.70\", \"7.061\"], [\"70366.30\", \"0.003\"], [\"70366.90\", \"0.006\"], [\"70368.70\", \"0.066\"], [\"70369.00\", \"0.006\"], [\"70369.90\", \"0.808\"], [\"70370.10\", \"0.802\"], [\"70371.40\", \"0.075\"], [\"70372.50\", \"0.006\"], [\"70378.40\", \"0.036\"], [\"70379.10\", \"0.229\"], [\"70379.40\", \"0.036\"], [\"70379.50\", \"0.136\"], [\"70380.00\", \"0.050\"], [\"70380.20\", \"0.025\"], [\"70380.80\", \"0.120\"], [\"70381.00\", \"0.087\"], [\"70381.60\", \"0.047\"], [\"70383.00\", \"0.083\"], [\"70383.50\", \"0.001\"], [\"70383.60\", \"0.007\"], [\"70384.20\", \"0.001\"], [\"70384.90\", \"0.040\"], [\"70387.20\", \"0.002\"], [\"70387.60\", \"0.186\"], [\"70396.90\", \"0.005\"], [\"70401.30\", \"0.000\"], [\"70404.30\", \"1.883\"], [\"70409.30\", \"0.000\"], [\"70410.00\", \"0.008\"], [\"70413.10\", \"0.201\"], [\"70413.30\", \"0.000\"], [\"70414.50\", \"0.159\"], [\"70420.00\", \"1.318\"], [\"70420.10\", \"0.221\"], [\"70420.20\", \"0.000\"], [\"70421.20\", \"0.028\"], [\"70440.90\", \"1.203\"], [\"70453.80\", \"0.413\"], [\"70466.70\", \"0.000\"], [\"70468.90\", \"0.105\"], [\"70475.00\", \"0.348\"], [\"70525.20\", \"0.036\"], [\"70532.90\", \"0.036\"], [\"70554.40\", \"0.036\"], [\"70578.00\", \"0.019\"], [\"70603.70\", \"0.000\"], [\"70654.90\", \"1.754\"], [\"70700.00\", \"19.240\"], [\"70911.50\", \"3.724\"], [\"70912.80\", \"0.000\"], [\"71065.30\", \"0.000\"], [\"71253.00\", \"2.389\"], [\"73918.40\", \"0.000\"], [\"89523.20\", \"0.000\"]]}", "symbol": "BTCUSDT"}
{"event": "depthUpdate", "raw_payload": "{\"e\": \"depthUpdate\", \"E\": 1773246398848, \"T\": 1773246398847, \"s\": \"BTCUSDT\", \"U\": 10089705172168, \"u\": 10089705179684, \"pu\": 10089705172046, \"b\": [[\"5000.00\", \"101.398\"], [\"19861.60\", \"0.290\"], [\"19885.20\", \"0.140\"], [\"19985.20\", \"0.280\"], [\"20161.60\", \"0.250\"], [\"20261.60\", \"0.340\"], [\"20285.20\", \"0.400\"], [\"63325.40\", \"0.013\"], [\"69533.10\", \"3.240\"], [\"69658.00\", \"0.697\"], [\"69800.10\", \"0.771\"], [\"69811.70\", \"0.010\"], [\"69936.10\", \"0.072\"], [\"70014.10\", \"0.000\"], [\"70020.10\", \"2.182\"], [\"70040.70\", \"0.009\"], [\"70097.50\", \"1.845\"], [\"70129.00\", \"0.000\"], [\"70136.60\", \"0.126\"], [\"70137.00\", \"0.022\"], [\"70137.70\", \"0.089\"], [\"70255.00\", \"0.014\"], [\"70258.20\", \"0.001\"], [\"70288.00\", \"0.012\"], [\"70294.80\", \"0.635\"], [\"70301.30\", \"0.111\"], [\"70311.40\", \"0.092\"], [\"70311.60\", \"0.004\"], [\"70315.00\", \"0.004\"], [\"70317.90\", \"0.005\"], [\"70318.60\", \"0.003\"], [\"70319.30\", \"0.003\"], [\"70319.40\", \"0.762\"], [\"70319.50\", \"0.102\"], [\"70320.00\", \"0.047\"], [\"70329.60\", \"0.002\"], [\"70333.50\", \"0.530\"], [\"70337.80\", \"0.205\"], [\"70340.50\", \"0.066\"], [\"70343.60\", \"0.075\"], [\"70344.00\", \"0.208\"], [\"70346.30\", \"0.266\"], [\"70346.70\", \"0.207\"], [\"70347.40\", \"0.123\"], [\"70347.80\", \"0.247\"], [\"70348.10\", \"0.039\"], [\"70351.00\", \"0.057\"], [\"70353.30\", \"0.000\"], [\"70354.80\", \"0.094\"], [\"70358.60\", \"0.004\"], [\"70361.60\", \"0.550\"]], \"a\": [[\"70361.70\", \"7.555\"], [\"70365.80\", \"0.321\"], [\"70366.10\", \"0.001\"], [\"70371.20\", \"0.007\"], [\"70372.00\", \"0.002\"], [\"70374.90\", \"0.030\"], [\"70382.70\", \"0.121\"], [\"70383.00\", \"0.047\"], [\"70383.80\", \"0.007\"], [\"70384.60\", \"0.000\"], [\"70387.10\", \"0.012\"], [\"70399.80\", \"0.004\"], [\"70412.90\", \"0.165\"], [\"70413.10\", \"0.060\"], [\"70417.30\", \"0.000\"], [\"70421.20\", \"0.000\"], [\"70435.60\", \"0.426\"], [\"70437.90\", \"0.042\"], [\"70439.10\", \"0.000\"], [\"70442.00\", \"0.600\"], [\"70450.60\", \"0.301\"], [\"70454.40\", \"0.052\"], [\"70597.50\", \"0.000\"], [\"70910.10\", \"3.720\"], [\"70911.50\", \"0.004\"], [\"71065.30\", \"0.002\"], [\"71689.60\", \"1.046\"], [\"71717.20\", \"0.000\"], [\"71795.80\", \"0.000\"], [\"73915.00\", \"0.002\"], [\"73918.90\", \"0.002\"], [\"77397.90\", \"0.002\"]]}", "symbol": "BTCUSDT"}
{"event": "depthUpdate", "raw_payload": "{\"e\": \"depthUpdate\", \"E\": 1773246398950, \"T\": 1773246398949, \"s\": \"BTCUSDT\", \"U\": 10089705179692, \"u\": 10089705186698, \"pu\": 10089705179684, \"b\": [[\"1000.00\", \"26.792\"], [\"5000.00\", \"101.418\"], [\"19861.60\", \"0.380\"], [\"19885.20\", \"0.050\"], [\"19985.20\", \"0.190\"], [\"20161.60\", \"0.330\"], [\"20261.60\", \"0.430\"], [\"20285.20\", \"0.320\"], [\"63325.40\", \"0.011\"], [\"64700.00\", \"2.604\"], [\"66843.50\", \"0.003\"], [\"69658.00\", \"0.697\"], [\"69731.90\", \"0.019\"], [\"69737.30\", \"0.000\"], [\"69813.80\", \"3.720\"], [\"70080.20\", \"1.046\"], [\"70128.90\", \"0.276\"], [\"70135.10\", \"0.002\"], [\"70135.80\", \"0.002\"], [\"70136.60\", \"0.086\"], [\"70137.30\", \"0.000\"], [\"70137.70\", \"0.035\"], [\"70156.50\", \"0.201\"], [\"70160.70\", \"1.924\"], [\"70167.30\", \"0.038\"], [\"70236.00\", \"0.062\"], [\"70259.80\", \"0.000\"], [\"70271.20\", \"0.003\"], [\"70290.90\", \"0.257\"], [\"70295.00\", \"0.002\"], [\"70304.00\", \"0.005\"], [\"70306.40\", \"0.003\"], [\"70311.60\", \"0.002\"], [\"70311.70\", \"0.004\"], [\"70312.00\", \"0.088\"], [\"70315.10\", \"0.005\"], [\"70315.80\", \"0.003\"], [\"70316.50\", \"0.007\"], [\"70317.20\", \"0.006\"], [\"70319.10\", \"0.033\"], [\"70320.30\", \"0.256\"], [\"70320.50\", \"0.000\"], [\"70322.20\", \"0.004\"], [\"70323.20\", \"0.007\"], [\"70325.30\", \"0.011\"], [\"70327.40\", \"0.048\"], [\"70328.20\", \"0.054\"], [\"70328.80\", \"0.000\"], [\"70330.20\", \"0.002\"], [\"70330.90\", \"0.003\"], [\"70331.10\", \"0.000\"], [\"70334.60\", \"0.005\"], [\"70335.30\", \"0.073\"], [\"70335.90\", \"0.075\"], [\"70337.10\", \"1.073\"], [\"70338.10\", \"0.007\"], [\"70338.50\", \"0.214\"], [\"70338.60\", \"0.003\"], [\"70340.20\", \"0.287\"], [\"70340.30\", \"0.008\"], [\"70340.60\", \"0.007\"], [\"70341.10\", \"0.007\"], [\"70341.60\", \"0.005\"], [\"70342.40\", \"0.000\"], [\"70342.60\", \"0.000\"], [\"70342.90\", \"0.382\"], [\"70343.10\", \"0.085\"], [\"70344.00\", \"0.208\"], [\"70345.00\", \"0.212\"], [\"70345.60\", \"0.007\"], [\"70346.60\", \"0.068\"], [\"70347.00\", \"0.058\"], [\"70347.40\", \"0.103\"], [\"70347.70\", \"0.095\"], [\"70347.80\", \"0.006\"], [\"70348.60\", \"0.006\"], [\"70349.90\", \"0.008\"], [\"70351.60\", \"0.006\"], [\"70354.80\", \"0.335\"], [\"70356.60\", \"3.183\"], [\"70358.60\", \"0.006\"], [\"70361.60\", \"0.553\"]], \"a\": [[\"70361.70\", \"7.127\"], [\"70365.10\", \"0.002\"], [\"70366.70\", \"0.005\"], [\"70369.90\", \"0.806\"], [\"70370.60\", \"0.005\"], [\"70371.50\", \"0.007\"], [\"70371.70\", \"0.008\"], [\"70374.40\", \"0.045\"], [\"70376.00\", \"0.011\"], [\"70376.50\", \"0.290\"], [\"70376.70\", \"0.005\"], [\"70376.90\", \"0.059\"], [\"70378.30\", \"0.007\"], [\"70379.30\", \"0.011\"], [\"70383.00\", \"0.011\"], [\"70383.60\", \"0.078\"], [\"70383.80\", \"0.000\"], [\"70384.40\", \"0.071\"], [\"70384.90\", \"0.004\"], [\"70385.20\", \"0.514\"], [\"70386.20\", \"0.007\"], [\"70386.40\", \"0.001\"], [\"70386.90\", \"0.007\"], [\"70387.10\", \"0.005\"], [\"70387.40\", \"0.381\"], [\"70388.60\", \"0.000\"], [\"70389.80\", \"0.000\"], [\"70390.70\", \"0.000\"], [\"70391.60\", \"0.001\"], [\"70392.20\", \"0.004\"], [\"70392.40\", \"0.001\"], [\"70395.20\", \"0.000\"], [\"70400.80\", \"0.002\"], [\"70401.90\", \"0.000\"], [\"70407.30\", \"0.000\"], [\"70415.80\", \"0.004\"], [\"70421.20\", \"0.028\"], [\"70432.50\", \"0.004\"], [\"70434.10\", \"0.121\"], [\"70440.30\", \"0.059\"], [\"70441.00\", \"0.029\"], [\"70449.50\", \"0.002\"], [\"70467.60\", \"0.100\"], [\"70472.80\", \"0.151\"], [\"70477.90\", \"0.379\"], [\"70510.80\", \"0.006\"], [\"70622.40\", \"0.002\"], [\"70737.20\", \"0.035\"], [\"70909.40\", \"3.725\"], [\"70910.10\", \"0.000\"], [\"71065.30\", \"0.000\"], [\"73886.20\", \"0.002\"], [\"73908.10\", \"0.002\"], [\"77397.90\", \"0.000\"], [\"89523.20\", \"0.000\"]]}", "symbol": "BTCUSDT"}
{"event": "depthUpdate", "raw_payload": "{\"e\": \"depthUpdate\", \"E\": 1773246399052, \"T\": 1773246399050, \"s\": \"BTCUSDT\", \"U\": 10089705186701, \"u\": 10089705195143, \"pu\": 10089705186698, \"b\": [[\"5000.00\", \"101.398\"], [\"19861.60\", \"0.460\"], [\"19885.20\", \"0.000\"], [\"19985.20\", \"0.110\"], [\"20161.60\", \"0.450\"], [\"20261.60\", \"0.480\"], [\"20285.20\", \"0.200\"], [\"56310.00\", \"100.003\"], [\"64700.00\", \"2.451\"], [\"68250.80\", \"0.006\"], [\"69371.60\", \"0.000\"], [\"69658.00\", \"0.697\"], [\"69813.10\", \"3.720\"], [\"69813.80\", \"0.000\"], [\"69906.20\", \"0.008\"], [\"69911.60\", \"0.357\"], [\"70081.00\", \"0.004\"], [\"70086.40\", \"0.007\"], [\"70134.20\", \"0.002\"], [\"70135.90\", \"0.000\"], [\"70138.00\", \"1.420\"], [\"70196.90\", \"0.049\"], [\"70204.70\", \"0.002\"], [\"70224.20\", \"1.356\"], [\"70255.30\", \"0.082\"], [\"70256.20\", \"0.107\"], [\"70261.60\", \"0.000\"], [\"70280.60\", \"0.000\"], [\"70284.20\", \"0.036\"], [\"70289.60\", \"0.076\"], [\"70294.70\", \"0.130\"], [\"70294.80\", \"0.395\"], [\"70298.40\", \"0.011\"], [\"70301.90\", \"0.004\"], [\"70303.70\", \"0.069\"], [\"70311.70\", \"0.002\"], [\"70311.80\", \"0.012\"], [\"70312.30\", \"0.001\"], [\"70313.00\", \"0.514\"], [\"70313.30\", \"0.004\"], [\"70313.70\", \"0.008\"], [\"70314.40\", \"0.003\"], [\"70315.00\", \"0.626\"], [\"70322.00\", \"0.626\"], [\"70327.40\", \"0.046\"], [\"70329.00\", \"0.635\"], [\"70336.00\", \"0.725\"], [\"70336.10\", \"0.009\"], [\"70337.00\", \"0.018\"], [\"70337.10\", \"1.079\"], [\"70343.00\", \"2.727\"], [\"70344.00\", \"0.548\"], [\"70346.70\", \"0.171\"], [\"70347.60\", \"0.376\"], [\"70351.00\", \"0.057\"], [\"70352.60\", \"0.005\"], [\"70353.70\", \"0.004\"], [\"70354.60\", \"0.002\"], [\"70354.90\", \"0.004\"], [\"70357.00\", \"0.020\"], [\"70361.30\", \"0.004\"], [\"70361.60\", \"0.434\"]], \"a\": [[\"70361.70\", \"7.099\"], [\"70361.90\", \"0.062\"], [\"70366.00\", \"0.812\"], [\"70368.10\", \"0.002\"], [\"70368.70\", \"0.066\"], [\"70371.20\", \"0.004\"], [\"70372.30\", \"0.147\"], [\"70374.40\", \"0.049\"], [\"70375.70\", \"0.095\"], [\"70379.30\", \"0.013\"], [\"70381.70\", \"0.043\"], [\"70382.70\", \"0.060\"], [\"70392.00\", \"1.260\"], [\"70399.00\", \"0.624\"], [\"70401.90\", \"0.030\"], [\"70406.00\", \"0.626\"], [\"70413.00\", \"0.631\"], [\"70416.90\", \"0.003\"], [\"70417.00\", \"0.001\"], [\"70452.20\", \"0.003\"], [\"70465.20\", \"0.166\"], [\"70467.10\", \"0.191\"], [\"70472.70\", \"0.000\"], [\"70484.80\", \"0.126\"], [\"70487.50\", \"0.141\"], [\"70494.50\", \"1.162\"], [\"70518.90\", \"0.188\"], [\"70520.30\", \"0.000\"], [\"70526.20\", \"0.201\"], [\"70596.70\", \"0.002\"], [\"70597.50\", \"0.043\"], [\"70643.30\", \"0.129\"], [\"70648.90\", \"0.000\"], [\"70819.90\", \"0.012\"], [\"70825.50\", \"0.000\"], [\"70909.40\", \"0.005\"], [\"70910.10\", \"3.720\"], [\"70996.90\", \"0.016\"], [\"71002.60\", \"0.062\"], [\"71065.30\", \"0.000\"], [\"71303.60\", \"1.113\"], [\"71341.90\", \"0.004\"], [\"71709.30\", \"0.136\"], [\"72478.20\", \"0.000\"], [\"73887.10\", \"0.002\"]]}", "symbol": "BTCUSDT"}
{"event": "depthUpdate", "raw_payload": "{\"e\": \"depthUpdate\", \"E\": 1773246399154, \"T\": 1773246399153, \"s\": \"BTCUSDT\", \"U\": 10089705195298, \"u\": 10089705225726, \"pu\": 10089705195143, \"b\": [[\"5000.00\", \"101.418\"], [\"19856.60\", \"0.050\"], [\"19857.90\", \"0.010\"], [\"19861.60\", \"0.490\"], [\"19985.20\", \"0.020\"], [\"20156.60\", \"0.110\"], [\"20157.90\", \"0.010\"], [\"20159.60\", \"0.010\"], [\"20161.60\", \"0.490\"], [\"20285.20\", \"0.030\"], [\"66830.00\", \"0.532\"], [\"66848.80\", \"0.000\"], [\"69658.00\", \"0.697\"], [\"69813.10\", \"0.000\"], [\"69981.50\", \"0.002\"], [\"69984.70\", \"0.002\"], [\"70009.80\", \"0.002\"], [\"70060.10\", \"10.000\"], [\"70060.30\", \"0.190\"], [\"70060.60\", \"0.187\"], [\"70061.00\", \"0.194\"], [\"70066.10\", \"0.000\"], [\"70073.70\", \"0.214\"], [\"70076.90\", \"0.132\"], [\"70077.30\", \"0.202\"], [\"70084.90\", \"0.000\"], [\"70109.00\", \"34.149\"], [\"70111.50\", \"7.896\"], [\"70120.90\", \"0.002\"], [\"70122.80\", \"0.000\"], [\"70140.90\", \"0.000\"], [\"70143.20\", \"1.687\"], [\"70146.00\", \"0.512\"], [\"70164.20\", \"0.113\"], [\"70167.70\", \"0.194\"], [\"70168.40\", \"10.000\"], [\"70172.50\", \"0.000\"], [\"70174.60\", \"2.565\"], [\"70174.70\", \"1.681\"], [\"70180.30\", \"0.039\"], [\"70182.70\", \"0.210\"], [\"70184.30\", \"0.039\"], [\"70187.10\", \"0.082\"], [\"70193.20\", \"0.000\"], [\"70195.10\", \"0.053\"], [\"70197.90\", \"0.160\"], [\"70198.80\", \"13.150\"], [\"70199.30\", \"5.966\"], [\"70200.90\", \"0.082\"], [\"70202.70\", \"1.736\"], [\"70204.10\", \"0.082\"], [\"70204.40\", \"0.082\"], [\"70205.70\", \"0.002\"], [\"70206.40\", \"0.039\"], [\"70209.10\", \"0.207\"], [\"70212.80\", \"0.050\"], [\"70213.70\", \"0.039\"], [\"70213.80\", \"0.043\"], [\"70214.40\", \"0.513\"], [\"70215.90\", \"0.259\"], [\"70216.30\", \"0.273\"], [\"70217.90\", \"0.125\"], [\"70220.40\", \"0.042\"], [\"70220.60\", \"0.755\"], [\"70221.60\", \"0.084\"], [\"70223.70\", \"0.716\"], [\"70224.10\", \"0.082\"], [\"70227.00\", \"0.566\"], [\"70236.30\", \"0.082\"], [\"70238.90\", \"0.088\"], [\"70242.00\", \"0.004\"], [\"70243.10\", \"0.128\"], [\"70244.10\", \"0.385\"], [\"70245.50\", \"0.042\"], [\"70247.20\", \"0.016\"], [\"70249.20\", \"0.143\"], [\"70250.90\", \"0.006\"], [\"70251.80\", \"0.000\"], [\"70252.40\", \"0.012\"], [\"70253.00\", \"4.153\"], [\"70255.50\", \"1.028\"], [\"70255.90\", \"0.185\"], [\"70256.80\", \"0.637\"], [\"70259.00\", \"1.312\"], [\"70259.10\", \"1.069\"], [\"70259.50\", \"0.159\"], [\"70261.30\", \"0.170\"], [\"70262.50\", \"1.791\"], [\"70262.60\", \"0.712\"], [\"70263.20\", \"1.419\"], [\"70264.20\", \"0.002\"], [\"70264.70\", \"0.173\"], [\"70264.90\", \"1.068\"], [\"70265.30\", \"0.023\"], [\"70265.70\", \"0.058\"], [\"70266.00\", \"0.891\"], [\"70266.40\", \"1.311\"], [\"70267.40\", \"0.282\"], [\"70268.30\", \"0.001\"], [\"70270.60\", \"0.448\"], [\"70270.90\", \"0.002\"], [\"70271.60\", \"0.230\"], [\"70272.30\", \"0.004\"], [\"70274.80\", \"0.000\"], [\"70275.20\", \"0.000\"], [\"70277.00\", \"0.100\"], [\"70277.90\", \"6.348\"], [\"70278.10\", \"0.018\"], [\"70279.20\", \"0.071\"], [\"70279.40\", \"0.081\"], [\"70279.50\", \"0.044\"], [\"70279.70\", \"0.003\"], [\"70281.30\", \"0.003\"], [\"70281.60\", \"0.217\"], [\"70281.80\", \"1.500\"], [\"70282.50\", \"0.000\"], [\"70284.10\", \"0.002\"], [\"70285.20\", \"0.000\"], [\"70285.30\", \"0.004\"], [\"70286.00\", \"5.486\"], [\"70286.10\", \"0.005\"], [\"70286.20\", \"0.081\"], [\"70286.30\", \"0.016\"], [\"70286.60\", \"0.039\"], [\"70287.20\", \"0.055\"], [\"70287.40\", \"0.011\"], [\"70288.20\", \"0.004\"], [\"70288.30\", \"0.217\"], [\"70288.40\", \"0.000\"], [\"70288.60\", \"0.001\"], [\"70288.80\", \"0.465\"], [\"70289.60\", \"0.000\"], [\"70289.80\", \"0.094\"], [\"70289.90\", \"0.121\"], [\"70290.10\", \"0.157\"], [\"70290.30\", \"0.002\"], [\"70290.40\", \"0.421\"], [\"70290.60\", \"0.092\"], [\"70290.90\", \"0.214\"], [\"70291.20\", \"0.032\"], [\"70291.70\", \"0.049\"], [\"70292.60\", \"0.069\"], [\"70292.80\", \"10.756\"], [\"70292.90\", \"0.005\"], [\"70293.30\", \"1.846\"], [\"70293.40\", \"0.023\"], [\"70293.60\", \"0.002\"], [\"70294.00\", \"2.927\"], [\"70294.70\", \"0.000\"], [\"70295.00\", \"0.106\"], [\"70295.20\", \"0.079\"], [\"70295.80\", \"0.049\"], [\"70296.30\", \"0.189\"], [\"70296.50\", \"0.207\"], [\"70296.90\", \"0.260\"], [\"70298.20\", \"0.000\"], [\"70299.30\", \"0.084\"], [\"70299.70\", \"0.004\"], [\"70300.30\", \"0.138\"], [\"70300.70\", \"0.000\"], [\"70300.80\", \"0.002\"], [\"70301.30\", \"0.072\"], [\"70301.70\", \"0.587\"], [\"70302.20\", \"0.892\"], [\"70303.00\", \"0.346\"], [\"70303.30\", \"0.136\"], [\"70303.60\", \"0.005\"], [\"70303.70\", \"0.008\"], [\"70304.20\", \"0.000\"], [\"70304.30\", \"0.557\"], [\"70304.90\", \"0.002\"], [\"70305.00\", \"0.000\"], [\"70305.30\", \"0.313\"], [\"70305.50\", \"0.000\"], [\"70306.70\", \"0.000\"], [\"70306.80\", \"0.000\"], [\"70306.90\", \"0.000\"], [\"70307.00\", \"0.003\"], [\"70307.30\", \"0.134\"], [\"70307.60\", \"0.002\"], [\"70308.00\", \"0.102\"], [\"70308.30\", \"0.142\"], [\"70308.40\", \"0.000\"], [\"70308.50\", \"0.118\"], [\"70308.80\", \"0.110\"], [\"70309.00\", \"0.001\"], [\"70309.10\", \"0.200\"], [\"70309.40\", \"0.000\"], [\"70309.70\", \"0.000\"], [\"70310.10\", \"0.785\"], [\"70310.20\", \"0.014\"], [\"70310.30\", \"0.009\"], [\"70310.40\", \"0.004\"], [\"70311.20\", \"0.015\"], [\"70311.40\", \"0.092\"], [\"70311.50\", \"1.071\"], [\"70311.80\", \"0.010\"], [\"70312.00\", \"0.088\"], [\"70312.20\", \"0.005\"], [\"70312.40\", \"0.005\"], [\"70313.10\", \"0.448\"], [\"70313.70\", \"0.006\"], [\"70313.90\", \"0.000\"], [\"70314.10\", \"0.002\"], [\"70314.40\", \"0.005\"], [\"70314.80\", \"0.000\"], [\"70315.00\", \"0.004\"], [\"70315.20\", \"1.144\"], [\"70315.30\", \"0.515\"], [\"70315.60\", \"0.241\"], [\"70315.90\", \"0.022\"], [\"70316.10\", \"0.090\"], [\"70316.80\", \"0.008\"], [\"70317.00\", \"0.034\"], [\"70317.40\", \"1.073\"], [\"70318.60\", \"0.007\"], [\"70319.00\", \"0.000\"], [\"70319.40\", \"0.193\"], [\"70319.70\", \"0.016\"], [\"70319.80\", \"0.511\"], [\"70320.30\", \"0.296\"], [\"70321.00\", \"0.041\"], [\"70321.40\", \"0.317\"], [\"70321.90\", \"0.056\"], [\"70322.00\", \"0.004\"], [\"70322.10\", \"0.240\"], [\"70322.20\", \"0.007\"], [\"70322.30\", \"1.983\"], [\"70322.70\", \"0.591\"], [\"70323.40\", \"0.007\"], [\"70323.50\", \"0.003\"], [\"70323.80\", \"0.511\"], [\"70324.10\", \"0.019\"], [\"70324.20\", \"0.046\"], [\"70324.30\", \"0.030\"], [\"70324.50\", \"0.005\"], [\"70324.70\", \"0.147\"], [\"70325.00\", \"0.416\"], [\"70325.10\", \"0.110\"], [\"70325.40\", \"0.933\"], [\"70325.50\", \"0.516\"], [\"70325.60\", \"0.189\"], [\"70325.70\", \"0.035\"], [\"70326.20\", \"0.006\"], [\"70326.30\", \"0.404\"], [\"70326.60\", \"0.071\"], [\"70327.00\", \"0.002\"], [\"70327.30\", \"0.639\"], [\"70327.40\", \"0.006\"], [\"70327.50\", \"0.513\"], [\"70328.10\", \"0.002\"], [\"70328.20\", \"0.002\"], [\"70328.30\", \"0.006\"], [\"70328.40\", \"0.532\"], [\"70328.50\", \"0.111\"], [\"70328.80\", \"0.000\"], [\"70328.90\", \"0.082\"], [\"70329.00\", \"0.018\"], [\"70329.10\", \"0.003\"], [\"70329.20\", \"0.001\"], [\"70329.30\", \"1.153\"], [\"70329.40\", \"0.003\"], [\"70329.50\", \"0.002\"], [\"70329.60\", \"0.002\"], [\"70329.70\", \"0.006\"], [\"70329.80\", \"0.000\"], [\"70329.90\", \"0.073\"], [\"70330.00\", \"0.098\"], [\"70330.10\", \"0.003\"], [\"70330.30\", \"0.008\"], [\"70330.40\", \"0.382\"], [\"70330.50\", \"0.067\"], [\"70331.00\", \"0.221\"], [\"70331.10\", \"0.000\"], [\"70331.20\", \"0.040\"], [\"70331.30\", \"0.096\"], [\"70331.40\", \"0.000\"], [\"70331.60\", \"0.006\"], [\"70331.70\", \"0.252\"], [\"70331.80\", \"0.002\"], [\"70331.90\", \"0.092\"], [\"70332.00\", \"0.003\"], [\"70332.20\", \"0.344\"], [\"70332.30\", \"0.008\"], [\"70332.40\", \"0.087\"], [\"70332.50\", \"0.002\"], [\"70332.60\", \"0.062\"], [\"70332.70\", \"0.004\"], [\"70332.90\", \"0.511\"], [\"70333.00\", \"0.018\"], [\"70333.10\", \"0.005\"], [\"70333.20\", \"0.005\"], [\"70333.50\", \"0.000\"], [\"70333.80\", \"0.002\"], [\"70333.90\", \"0.003\"], [\"70334.20\", \"0.007\"], [\"70334.50\", \"0.000\"], [\"70334.60\", \"0.005\"], [\"70334.70\", \"0.000\"], [\"70334.80\", \"0.472\"], [\"70335.00\", \"1.078\"], [\"70335.10\", \"1.212\"], [\"70335.20\", \"0.004\"], [\"70335.30\", \"0.002\"], [\"70335.40\", \"0.005\"], [\"70335.90\", \"0.306\"], [\"70336.00\", \"0.022\"], [\"70336.30\", \"0.015\"], [\"70336.40\", \"0.014\"], [\"70336.60\", \"0.003\"], [\"70336.70\", \"0.002\"], [\"70336.90\", \"0.006\"], [\"70337.00\", \"0.016\"], [\"70337.10\", \"0.290\"], [\"70337.20\", \"0.000\"], [\"70337.30\", \"0.003\"], [\"70337.40\", \"0.009\"], [\"70337.60\", \"0.011\"], [\"70337.90\", \"0.000\"], [\"70338.00\", \"0.008\"], [\"70338.10\", \"0.007\"], [\"70338.20\", \"0.342\"], [\"70338.30\", \"0.000\"], [\"70338.40\", \"0.007\"], [\"70338.50\", \"0.000\"], [\"70338.60\", \"0.005\"], [\"70338.70\", \"0.004\"], [\"70338.80\", \"0.002\"], [\"70339.00\", \"0.319\"], [\"70339.10\", \"0.000\"], [\"70339.60\", \"0.002\"], [\"70339.70\", \"0.001\"], [\"70339.80\", \"0.186\"], [\"70340.10\", \"0.005\"], [\"70340.20\", \"0.000\"], [\"70340.30\", \"0.001\"], [\"70340.50\", \"0.063\"], [\"70340.60\", \"0.000\"], [\"70340.90\", \"0.191\"], [\"70341.00\", \"0.000\"], [\"70341.10\", \"0.000\"], [\"70341.30\", \"0.000\"], [\"70341.50\", \"0.003\"], [\"70341.60\", \"0.007\"], [\"70341.80\", \"0.289\"], [\"70342.00\", \"0.082\"], [\"70342.20\", \"0.005\"], [\"70342.30\", \"0.122\"], [\"70342.50\", \"0.110\"], [\"70342.60\", \"0.000\"], [\"70342.70\", \"0.107\"], [\"70342.80\", \"0.268\"], [\"70343.00\", \"2.103\"], [\"70343.10\", \"0.003\"], [\"70343.20\", \"0.022\"], [\"70343.30\", \"0.094\"], [\"70343.40\", \"0.010\"], [\"70343.60\", \"0.189\"], [\"70343.70\", \"0.003\"], [\"70343.80\", \"0.005\"], [\"70343.90\", \"0.000\"], [\"70344.00\", \"0.078\"], [\"70344.30\", \"0.209\"], [\"70344.50\", \"0.005\"], [\"70344.70\", \"0.655\"], [\"70344.80\", \"0.004\"], [\"70344.90\", \"0.005\"], [\"70345.00\", \"0.209\"], [\"70345.10\", \"0.000\"], [\"70345.20\", \"0.001\"], [\"70345.30\", \"0.021\"], [\"70345.50\", \"0.004\"], [\"70345.60\", \"0.005\"], [\"70345.70\", \"0.000\"], [\"70345.80\", \"0.003\"], [\"70345.90\", \"0.010\"], [\"70346.00\", \"0.005\"], [\"70346.10\", \"0.006\"], [\"70346.20\", \"0.274\"], [\"70346.30\", \"0.003\"], [\"70346.40\", \"0.002\"], [\"70346.50\", \"0.002\"], [\"70346.60\", \"0.007\"], [\"70346.70\", \"0.000\"], [\"70346.90\", \"0.006\"], [\"70347.00\", \"0.000\"], [\"70347.10\", \"0.006\"], [\"70347.30\", \"0.015\"], [\"70347.40\", \"0.000\"], [\"70347.50\", \"0.004\"], [\"70347.60\", \"0.374\"], [\"70347.70\", \"0.013\"], [\"70347.80\", \"0.055\"], [\"70348.10\", \"0.025\"], [\"70348.20\", \"0.370\"], [\"70348.30\", \"0.000\"], [\"70348.50\", \"0.000\"], [\"70348.60\", \"0.027\"], [\"70348.70\", \"0.003\"], [\"70348.90\", \"0.000\"], [\"70349.10\", \"0.000\"], [\"70349.30\", \"0.000\"], [\"70349.60\", \"0.000\"], [\"70349.90\", \"0.003\"], [\"70350.00\", \"0.021\"], [\"70350.20\", \"0.000\"], [\"70350.50\", \"0.003\"], [\"70350.90\", \"0.022\"], [\"70351.00\", \"0.000\"], [\"70351.10\", \"0.002\"], [\"70351.20\", \"0.008\"], [\"70351.50\", \"0.000\"], [\"70351.70\", \"0.005\"], [\"70352.00\", \"0.001\"], [\"70352.10\", \"0.000\"], [\"70352.20\", \"0.003\"], [\"70352.30\", \"0.003\"], [\"70352.60\", \"0.003\"], [\"70352.70\", \"0.002\"], [\"70352.80\", \"0.004\"], [\"70353.00\", \"0.034\"], [\"70353.70\", \"0.024\"], [\"70354.30\", \"0.004\"], [\"70354.40\", \"1.003\"], [\"70354.50\", \"0.004\"], [\"70354.80\", \"0.000\"], [\"70355.00\", \"0.004\"], [\"70355.10\", \"0.003\"], [\"70355.50\", \"0.000\"], [\"70355.60\", \"0.000\"], [\"70355.70\", \"0.002\"], [\"70355.80\", \"0.000\"], [\"70356.00\", \"0.002\"], [\"70356.20\", \"0.002\"], [\"70356.30\", \"0.002\"], [\"70356.40\", \"0.000\"], [\"70356.50\", \"0.024\"], [\"70356.60\", \"3.195\"], [\"70356.70\", \"0.000\"], [\"70356.80\", \"0.000\"], [\"70357.00\", \"0.000\"], [\"70357.30\", \"0.000\"], [\"70357.50\", \"0.000\"], [\"70357.90\", \"0.000\"], [\"70358.00\", \"0.000\"], [\"70358.20\", \"0.000\"], [\"70358.50\", \"0.000\"], [\"70358.60\", \"0.000\"], [\"70358.70\", \"0.000\"], [\"70358.80\", \"0.000\"], [\"70358.90\", \"0.000\"], [\"70359.40\", \"0.000\"], [\"70359.50\", \"0.000\"], [\"70359.60\", \"0.000\"], [\"70359.80\", \"0.000\"], [\"70359.90\", \"0.000\"], [\"70360.00\", \"0.000\"], [\"70360.20\", \"0.000\"], [\"70360.30\", \"0.000\"], [\"70360.50\", \"0.000\"], [\"70360.80\", \"0.000\"], [\"70360.90\", \"0.000\"], [\"70361.00\", \"0.000\"], [\"70361.10\", \"0.000\"], [\"70361.20\", \"0.000\"], [\"70361.30\", \"0.000\"], [\"70361.60\", \"0.000\"]], \"a\": [[\"70356.70\", \"11.347\"], [\"70356.80\", \"0.005\"], [\"70356.90\", \"0.002\"], [\"70357.10\", \"0.000\"], [\"70357.20\", \"0.004\"], [\"70357.40\", \"0.000\"], [\"70357.50\", \"1.587\"], [\"70357.60\", \"0.001\"], [\"70357.70\", \"0.000\"], [\"70357.80\", \"0.000\"], [\"70357.90\", \"0.422\"], [\"70358.00\", \"0.001\"], [\"70358.10\", \"0.001\"], [\"70358.20\", \"0.002\"], [\"70358.30\", \"0.000\"], [\"70358.50\", \"0.005\"], [\"70358.60\", \"0.002\"], [\"70358.70\", \"0.042\"], [\"70358.80\", \"0.000\"], [\"70358.90\", \"0.000\"], [\"70359.00\", \"0.000\"], [\"70359.10\", \"0.003\"], [\"70359.20\", \"0.001\"], [\"70359.30\", \"0.000\"], [\"70359.50\", \"0.000\"], [\"70359.60\", \"0.000\"], [\"70359.70\", \"0.002\"], [\"70359.80\", \"0.003\"], [\"70359.90\", \"0.001\"], [\"70360.00\", \"0.397\"], [\"70360.10\", \"0.000\"], [\"70360.20\", \"0.002\"], [\"70360.30\", \"0.005\"], [\"70360.40\", \"0.003\"], [\"70360.50\", \"0.001\"], [\"70360.60\", \"0.000\"], [\"70360.90\", \"0.000\"], [\"70361.00\", \"0.000\"], [\"70361.10\", \"0.533\"], [\"70361.20\", \"0.002\"], [\"70361.30\", \"0.006\"], [\"70361.40\", \"0.811\"], [\"70361.50\", \"0.001\"], [\"70361.60\", \"1.131\"], [\"70361.70\", \"0.948\"], [\"70361.80\", \"0.822\"], [\"70361.90\", \"0.178\"], [\"70362.20\", \"0.001\"], [\"70362.50\", \"0.002\"], [\"70362.70\", \"0.001\"], [\"70362.90\", \"0.039\"], [\"70363.20\", \"0.003\"], [\"70363.30\", \"0.004\"], [\"70363.70\", \"0.004\"], [\"70364.00\", \"0.004\"], [\"70364.20\", \"0.000\"], [\"70364.40\", \"0.000\"], [\"70364.60\", \"0.002\"], [\"70364.70\", \"0.001\"], [\"70364.80\", \"0.003\"], [\"70364.90\", \"0.005\"], [\"70365.00\", \"0.016\"], [\"70365.10\", \"0.002\"], [\"70365.20\", \"0.204\"], [\"70365.30\", \"0.011\"], [\"70365.40\", \"0.069\"], [\"70365.60\", \"0.075\"], [\"70365.70\", \"0.515\"], [\"70365.80\", \"0.600\"], [\"70365.90\", \"1.442\"], [\"70366.00\", \"0.811\"], [\"70366.10\", \"0.819\"], [\"70366.40\", \"0.028\"], [\"70366.60\", \"0.639\"], [\"70366.90\", \"0.034\"], [\"70367.00\", \"0.000\"], [\"70367.10\", \"0.118\"], [\"70367.20\", \"0.175\"], [\"70367.30\", \"0.004\"], [\"70367.40\", \"0.007\"], [\"70367.50\", \"0.032\"], [\"70367.70\", \"0.001\"], [\"70367.80\", \"0.005\"], [\"70368.00\", \"0.512\"], [\"70368.10\", \"0.002\"], [\"70368.20\", \"0.057\"], [\"70368.30\", \"0.003\"], [\"70368.50\", \"0.000\"], [\"70368.60\", \"0.018\"], [\"70368.70\", \"0.003\"], [\"70368.80\", \"0.001\"], [\"70368.90\", \"0.002\"], [\"70369.10\", \"0.000\"], [\"70369.20\", \"0.000\"], [\"70369.30\", \"0.192\"], [\"70369.40\", \"0.000\"], [\"70369.60\", \"0.003\"], [\"70369.70\", \"0.380\"], [\"70369.80\", \"1.068\"], [\"70370.00\", \"0.002\"], [\"70370.10\", \"0.000\"], [\"70370.20\", \"0.571\"], [\"70370.30\", \"0.000\"], [\"70370.40\", \"0.047\"], [\"70370.60\", \"0.005\"], [\"70370.70\", \"0.002\"], [\"70370.80\", \"0.004\"], [\"70370.90\", \"0.003\"], [\"70371.10\", \"0.005\"], [\"70371.20\", \"0.003\"], [\"70371.40\", \"0.006\"], [\"70371.50\", \"0.004\"], [\"70371.70\", \"0.006\"], [\"70371.80\", \"0.008\"], [\"70371.90\", \"0.001\"], [\"70372.00\", \"0.099\"], [\"70372.20\", \"0.006\"], [\"70372.30\", \"0.002\"], [\"70372.50\", \"0.005\"], [\"70372.70\", \"0.007\"], [\"70372.90\", \"0.700\"], [\"70373.00\", \"0.148\"], [\"70373.10\", \"0.511\"], [\"70373.30\", \"0.003\"], [\"70373.40\", \"0.011\"], [\"70373.60\", \"0.003\"], [\"70373.70\", \"0.003\"], [\"70373.90\", \"0.004\"], [\"70374.00\", \"0.002\"], [\"70374.10\", \"0.002\"], [\"70374.20\", \"0.003\"], [\"70374.30\", \"0.089\"], [\"70374.40\", \"0.002\"], [\"70374.50\", \"0.002\"], [\"70374.70\", \"0.003\"], [\"70374.80\", \"0.007\"], [\"70374.90\", \"0.044\"], [\"70375.10\", \"0.248\"], [\"70375.20\", \"0.388\"], [\"70375.30\", \"0.511\"], [\"70375.40\", \"0.003\"], [\"70375.50\", \"0.275\"], [\"70375.60\", \"0.003\"], [\"70375.70\", \"0.005\"], [\"70376.00\", \"0.004\"], [\"70376.40\", \"0.261\"], [\"70376.50\", \"0.286\"], [\"70376.70\", \"0.005\"], [\"70376.90\", \"0.002\"], [\"70377.00\", \"0.039\"], [\"70377.30\", \"0.039\"], [\"70377.40\", \"0.001\"], [\"70377.80\", \"0.009\"], [\"70378.10\", \"0.000\"], [\"70378.30\", \"0.000\"], [\"70378.70\", \"0.025\"], [\"70379.00\", \"0.345\"], [\"70379.10\", \"1.346\"], [\"70379.30\", \"0.009\"], [\"70379.90\", \"0.008\"], [\"70380.10\", \"0.056\"], [\"70380.30\", \"0.071\"], [\"70380.50\", \"0.036\"], [\"70380.70\", \"0.072\"], [\"70380.90\", \"0.000\"], [\"70381.30\", \"0.121\"], [\"70381.40\", \"0.002\"], [\"70382.20\", \"0.007\"], [\"70382.50\", \"0.534\"], [\"70382.60\", \"0.007\"], [\"70382.80\", \"0.210\"], [\"70383.00\", \"0.001\"], [\"70383.60\", \"0.007\"], [\"70384.10\", \"0.006\"], [\"70384.40\", \"0.000\"], [\"70384.90\", \"0.006\"], [\"70385.00\", \"0.590\"], [\"70385.50\", \"0.000\"], [\"70385.60\", \"0.005\"], [\"70385.80\", \"0.052\"], [\"70386.00\", \"0.009\"], [\"70386.20\", \"0.000\"], [\"70386.30\", \"0.003\"], [\"70386.40\", \"0.235\"], [\"70386.60\", \"0.002\"], [\"70386.90\", \"0.000\"], [\"70387.00\", \"0.399\"], [\"70387.10\", \"0.197\"], [\"70387.20\", \"0.000\"], [\"70387.50\", \"0.090\"], [\"70387.90\", \"0.003\"], [\"70388.00\", \"0.306\"], [\"70388.10\", \"0.002\"], [\"70388.20\", \"0.036\"], [\"70388.40\", \"0.197\"], [\"70389.10\", \"0.003\"], [\"70389.50\", \"0.000\"], [\"70389.60\", \"0.394\"], [\"70390.00\", \"0.002\"], [\"70390.20\", \"0.005\"], [\"70390.70\", \"0.003\"], [\"70391.20\", \"0.258\"], [\"70391.40\", \"0.002\"], [\"70391.60\", \"0.000\"], [\"70391.70\", \"0.000\"], [\"70391.80\", \"0.000\"], [\"70391.90\", \"0.593\"], [\"70392.00\", \"0.638\"], [\"70392.10\", \"0.763\"], [\"70392.20\", \"0.002\"], [\"70392.80\", \"0.000\"], [\"70393.30\", \"0.038\"], [\"70393.70\", \"0.000\"], [\"70393.90\", \"0.022\"], [\"70394.10\", \"0.000\"], [\"70394.50\", \"0.005\"], [\"70394.80\", \"0.189\"], [\"70394.90\", \"0.029\"], [\"70395.10\", \"0.000\"], [\"70395.30\", \"0.777\"], [\"70395.50\", \"0.587\"], [\"70396.50\", \"0.005\"], [\"70398.90\", \"0.005\"], [\"70399.00\", \"0.002\"], [\"70399.30\", \"0.007\"], [\"70399.40\", \"0.083\"], [\"70399.80\", \"0.002\"], [\"70399.90\", \"0.552\"], [\"70400.00\", \"2.034\"], [\"70400.20\", \"0.113\"], [\"70400.50\", \"0.000\"], [\"70400.60\", \"0.002\"], [\"70400.80\", \"0.000\"], [\"70401.00\", \"0.007\"], [\"70401.50\", \"0.026\"], [\"70401.80\", \"0.028\"], [\"70401.90\", \"0.000\"], [\"70402.20\", \"0.000\"], [\"70402.40\", \"0.048\"], [\"70402.80\", \"0.913\"], [\"70402.90\", \"1.148\"], [\"70403.00\", \"0.003\"], [\"70403.50\", \"0.000\"], [\"70403.60\", \"0.082\"], [\"70404.10\", \"0.000\"], [\"70404.20\", \"0.477\"], [\"70404.30\", \"1.886\"], [\"70404.70\", \"0.807\"], [\"70404.80\", \"0.394\"], [\"70405.00\", \"0.124\"], [\"70405.20\", \"0.191\"], [\"70405.30\", \"0.012\"], [\"70405.40\", \"0.002\"], [\"70405.50\", \"0.006\"], [\"70405.60\", \"0.211\"], [\"70406.00\", \"0.013\"], [\"70406.30\", \"0.000\"], [\"70406.50\", \"0.001\"], [\"70406.90\", \"0.552\"], [\"70407.20\", \"0.002\"], [\"70407.80\", \"0.163\"], [\"70407.90\", \"0.193\"], [\"70408.40\", \"0.077\"], [\"70408.50\", \"0.000\"], [\"70408.60\", \"0.000\"], [\"70408.80\", \"0.002\"], [\"70409.40\", \"0.082\"], [\"70409.60\", \"0.089\"], [\"70409.80\", \"0.197\"], [\"70410.30\", \"0.082\"], [\"70410.60\", \"0.086\"], [\"70411.00\", \"0.003\"], [\"70411.30\", \"0.031\"], [\"70411.70\", \"0.590\"], [\"70412.90\", \"0.024\"], [\"70413.00\", \"0.089\"], [\"70413.40\", \"0.742\"], [\"70414.20\", \"0.007\"], [\"70414.50\", \"0.137\"], [\"70414.70\", \"0.000\"], [\"70415.50\", \"0.084\"], [\"70415.90\", \"0.535\"], [\"70416.50\", \"0.566\"], [\"70417.30\", \"0.128\"], [\"70417.60\", \"0.007\"], [\"70417.80\", \"0.575\"], [\"70418.20\", \"0.002\"], [\"70418.40\", \"0.224\"], [\"70418.70\", \"0.033\"], [\"70418.80\", \"0.000\"], [\"70419.30\", \"0.002\"], [\"70420.00\", \"1.188\"], [\"70420.50\", \"0.000\"], [\"70421.20\", \"0.000\"], [\"70421.50\", \"0.178\"], [\"70421.80\", \"0.142\"], [\"70422.60\", \"0.000\"], [\"70423.40\", \"2.069\"], [\"70423.50\", \"0.086\"], [\"70425.00\", \"0.017\"], [\"70425.20\", \"0.002\"], [\"70425.50\", \"0.018\"], [\"70425.70\", \"0.000\"], [\"70425.80\", \"1.141\"], [\"70425.90\", \"0.532\"], [\"70426.20\", \"0.000\"], [\"70426.40\", \"0.000\"], [\"70427.10\", \"0.534\"], [\"70427.50\", \"0.244\"], [\"70428.20\", \"0.000\"], [\"70428.50\", \"0.002\"], [\"70429.00\", \"0.000\"], [\"70430.30\", \"0.000\"], [\"70430.50\", \"0.846\"], [\"70431.20\", \"0.014\"], [\"70431.70\", \"0.080\"], [\"70431.80\", \"0.002\"], [\"70432.10\", \"0.565\"], [\"70433.80\", \"0.000\"], [\"70434.00\", \"0.021\"], [\"70434.10\", \"0.005\"], [\"70435.60\", \"0.342\"], [\"70437.50\", \"1.643\"], [\"70437.60\", \"0.002\"], [\"70438.10\", \"0.000\"], [\"70439.20\", \"0.000\"], [\"70440.10\", \"6.521\"], [\"70440.40\", \"0.000\"], [\"70440.50\", \"0.004\"], [\"70440.70\", \"0.000\"], [\"70441.90\", \"0.208\"], [\"70442.10\", \"0.009\"], [\"70442.40\", \"0.212\"], [\"70442.60\", \"0.000\"], [\"70442.90\", \"0.111\"], [\"70443.70\", \"0.300\"], [\"70444.10\", \"0.429\"], [\"70444.60\", \"0.293\"], [\"70444.70\", \"0.334\"], [\"70445.60\", \"0.039\"], [\"70447.60\", \"0.015\"], [\"70448.20\", \"0.071\"], [\"70448.70\", \"0.000\"], [\"70449.20\", \"0.674\"], [\"70450.10\", \"0.003\"], [\"70450.20\", \"0.020\"], [\"70451.60\", \"0.000\"], [\"70452.00\", \"0.082\"], [\"70455.20\", \"0.071\"], [\"70455.90\", \"0.125\"], [\"70456.10\", \"0.016\"], [\"70456.60\", \"0.645\"], [\"70456.90\", \"0.000\"], [\"70457.20\", \"0.000\"], [\"70457.60\", \"0.100\"], [\"70458.00\", \"0.019\"], [\"70459.20\", \"0.002\"], [\"70459.50\", \"0.000\"], [\"70459.60\", \"0.003\"], [\"70461.90\", \"0.082\"], [\"70462.20\", \"0.006\"], [\"70463.10\", \"0.008\"], [\"70463.20\", \"7.034\"], [\"70464.90\", \"2.189\"], [\"70466.40\", \"0.242\"], [\"70467.10\", \"0.273\"], [\"70467.60\", \"0.000\"], [\"70468.50\", \"0.386\"], [\"70471.40\", \"0.000\"], [\"70480.90\", \"0.127\"], [\"70481.40\", \"0.000\"], [\"70483.00\", \"0.113\"], [\"70483.10\", \"1.147\"], [\"70483.70\", \"0.046\"], [\"70490.20\", \"0.200\"], [\"70490.40\", \"0.000\"], [\"70495.50\", \"0.006\"], [\"70497.00\", \"4.994\"], [\"70499.50\", \"0.615\"], [\"70499.70\", \"0.020\"], [\"70508.20\", \"0.458\"], [\"70512.20\", \"0.111\"], [\"70514.80\", \"0.003\"], [\"70522.60\", \"0.002\"], [\"70524.60\", \"0.007\"], [\"70530.50\", \"10.836\"], [\"70536.10\", \"0.002\"], [\"70537.20\", \"0.081\"], [\"70538.80\", \"1.598\"], [\"70539.30\", \"0.000\"], [\"70539.40\", \"0.000\"], [\"70539.60\", \"3.554\"], [\"70542.40\", \"0.191\"], [\"70544.50\", \"0.000\"], [\"70545.20\", \"0.000\"], [\"70547.60\", \"0.000\"], [\"70550.20\", \"0.039\"], [\"70550.30\", \"0.005\"], [\"70550.40\", \"0.012\"], [\"70554.70\", \"0.000\"], [\"70554.80\", \"0.000\"], [\"70555.40\", \"0.000\"], [\"70556.90\", \"0.053\"], [\"70557.10\", \"0.000\"], [\"70557.40\", \"0.000\"], [\"70557.90\", \"0.000\"], [\"70558.70\", \"0.000\"], [\"70559.80\", \"0.002\"], [\"70561.60\", \"0.000\"], [\"70562.10\", \"0.016\"], [\"70567.00\", \"1.117\"], [\"70570.80\", \"0.036\"], [\"70571.50\", \"0.000\"], [\"70573.00\", \"0.007\"], [\"70573.10\", \"0.000\"], [\"70574.60\", \"0.018\"], [\"70577.40\", \"0.000\"], [\"70578.00\", \"8.801\"], [\"70610.40\", \"0.006\"], [\"70622.30\", \"0.006\"], [\"70624.90\", \"0.000\"], [\"70657.60\", \"0.194\"], [\"70661.60\", \"0.990\"], [\"70664.60\", \"0.004\"], [\"70667.00\", \"0.000\"], [\"70676.20\", \"0.058\"], [\"70676.40\", \"0.003\"], [\"70681.10\", \"0.027\"], [\"70681.50\", \"0.000\"], [\"70717.80\", \"0.035\"], [\"70727.50\", \"0.005\"], [\"70736.80\", \"0.002\"], [\"70737.10\", \"0.000\"], [\"70743.90\", \"0.000\"], [\"70747.60\", \"0.047\"], [\"70754.40\", \"0.007\"], [\"70783.70\", \"0.000\"], [\"70910.00\", \"0.766\"], [\"70910.10\", \"0.000\"], [\"71060.30\", \"0.000\"], [\"71061.60\", \"0.000\"], [\"71065.30\", \"0.000\"], [\"71356.70\", \"0.016\"], [\"71361.70\", \"0.285\"], [\"71366.00\", \"0.328\"], [\"71366.50\", \"0.353\"], [\"71367.10\", \"2.774\"], [\"71768.90\", \"0.030\"], [\"73898.10\", \"0.002\"], [\"89523.20\", \"0.000\"], [\"100000.00\", \"15.279\"]]}", "symbol": "BTCUSDT"}
{"event": "depthUpdate", "raw_payload": "{\"e\": \"depthUpdate\", \"E\": 1773246399256, \"T\": 1773246399254, \"s\": \"BTCUSDT\", \"U\": 10089705225805, \"u\": 10089705240348, \"pu\": 10089705225726, \"b\": [[\"1000.00\", \"26.792\"], [\"5000.00\", \"101.418\"], [\"19856.60\", \"0.130\"], [\"19982.30\", \"0.030\"], [\"19983.30\", \"0.000\"], [\"19985.20\", \"0.000\"], [\"20156.60\", \"0.280\"], [\"20282.30\", \"0.050\"], [\"20283.30\", \"0.000\"], [\"20285.10\", \"0.000\"], [\"20285.20\", \"0.000\"], [\"66832.50\", \"0.002\"], [\"67659.70\", \"0.002\"], [\"68188.20\", \"0.632\"], [\"69168.00\", \"1.449\"], [\"69336.80\", \"0.866\"], [\"69653.00\", \"0.000\"], [\"69798.00\", \"3.720\"], [\"70062.80\", \"2.466\"], [\"70087.20\", \"0.237\"], [\"70099.80\", \"0.048\"], [\"70128.90\", \"0.312\"], [\"70135.10\", \"0.027\"], [\"70135.80\", \"0.045\"], [\"70136.00\", \"0.900\"], [\"70137.30\", \"0.058\"], [\"70138.00\", \"1.455\"], [\"70169.00\", \"1.623\"], [\"70185.10\", \"0.732\"], [\"70195.20\", \"6.050\"], [\"70196.10\", \"0.041\"], [\"70200.00\", \"1.523\"], [\"70211.60\", \"0.000\"], [\"70212.40\", \"0.084\"], [\"70213.50\", \"0.376\"], [\"70231.70\", \"0.003\"], [\"70239.50\", \"0.192\"], [\"70241.20\", \"0.028\"], [\"70244.80\", \"2.011\"], [\"70247.90\", \"0.163\"], [\"70249.00\", \"0.002\"], [\"70249.90\", \"0.000\"], [\"70251.50\", \"0.000\"], [\"70255.50\", \"1.255\"], [\"70255.90\", \"0.072\"], [\"70256.20\", \"0.081\"], [\"70257.10\", \"0.155\"], [\"70259.50\", \"0.117\"], [\"70263.30\", \"0.367\"], [\"70263.70\", \"0.071\"], [\"70263.80\", \"0.204\"], [\"70267.80\", \"0.033\"], [\"70270.60\", \"0.590\"], [\"70270.70\", \"0.078\"], [\"70271.60\", \"0.003\"], [\"70272.10\", \"0.669\"], [\"70275.50\", \"0.000\"], [\"70277.80\", \"0.274\"], [\"70279.20\", \"0.000\"], [\"70281.70\", \"0.103\"], [\"70283.20\", \"0.004\"], [\"70284.50\", \"0.000\"], [\"70286.20\", \"0.094\"], [\"70286.30\", \"0.072\"], [\"70287.30\", \"0.238\"], [\"70288.00\", \"0.015\"], [\"70289.60\", \"0.000\"], [\"70289.70\", \"0.007\"], [\"70294.80\", \"0.344\"], [\"70295.00\", \"0.002\"], [\"70295.70\", \"0.000\"], [\"70296.30\", \"0.002\"], [\"70296.80\", \"0.463\"], [\"70298.60\", \"3.620\"], [\"70300.10\", \"0.000\"], [\"70300.30\", \"0.002\"], [\"70301.40\", \"0.345\"], [\"70301.50\", \"0.014\"], [\"70302.10\", \"0.106\"], [\"70302.70\", \"0.015\"], [\"70303.30\", \"0.139\"], [\"70305.80\", \"0.020\"], [\"70305.90\", \"0.251\"], [\"70306.10\", \"0.192\"], [\"70306.20\", \"0.004\"], [\"70306.60\", \"0.019\"], [\"70307.30\", \"0.137\"], [\"70308.00\", \"0.105\"], [\"70308.50\", \"0.116\"], [\"70308.70\", \"0.009\"], [\"70309.40\", \"0.003\"], [\"70310.10\", \"0.788\"], [\"70310.80\", \"0.006\"], [\"70312.20\", \"0.007\"], [\"70312.30\", \"0.008\"], [\"70313.20\", \"0.000\"], [\"70313.40\", \"0.004\"], [\"70314.00\", \"0.002\"], [\"70314.40\", \"0.012\"], [\"70314.60\", \"0.000\"], [\"70315.50\", \"0.002\"], [\"70315.90\", \"0.002\"], [\"70316.10\", \"0.093\"], [\"70318.00\", \"0.041\"], [\"70319.70\", \"0.002\"], [\"70320.10\", \"0.130\"], [\"70321.00\", \"0.000\"], [\"70321.30\", \"0.102\"], [\"70322.00\", \"10.228\"], [\"70324.70\", \"0.227\"], [\"70324.90\", \"0.063\"], [\"70325.00\", \"0.260\"], [\"70325.10\", \"0.309\"], [\"70325.40\", \"2.323\"], [\"70325.80\", \"0.073\"], [\"70326.00\", \"0.001\"], [\"70326.10\", \"0.016\"], [\"70326.20\", \"0.015\"], [\"70326.30\", \"0.384\"], [\"70326.80\", \"0.003\"], [\"70326.90\", \"0.000\"], [\"70327.10\", \"0.000\"], [\"70327.40\", \"0.006\"], [\"70327.50\", \"0.515\"], [\"70327.60\", \"0.012\"], [\"70328.20\", \"0.002\"], [\"70328.30\", \"0.006\"], [\"70328.90\", \"0.002\"], [\"70329.00\", \"0.009\"], [\"70329.60\", \"0.002\"], [\"70329.70\", \"0.006\"], [\"70330.10\", \"0.005\"], [\"70330.30\", \"0.008\"], [\"70330.40\", \"0.384\"], [\"70330.90\", \"0.010\"], [\"70331.00\", \"0.221\"], [\"70331.10\", \"0.000\"], [\"70331.90\", \"0.009\"], [\"70332.00\", \"0.017\"], [\"70332.10\", \"0.007\"], [\"70332.20\", \"0.342\"], [\"70332.40\", \"0.087\"], [\"70332.50\", \"0.002\"], [\"70333.10\", \"0.287\"], [\"70333.20\", \"0.003\"], [\"70333.50\", \"0.007\"], [\"70334.20\", \"0.000\"], [\"70334.40\", \"0.597\"], [\"70334.80\", \"0.020\"], [\"70335.10\", \"1.214\"], [\"70335.20\", \"0.800\"], [\"70335.30\", \"0.074\"], [\"70335.50\", \"0.342\"], [\"70335.90\", \"0.004\"], [\"70336.80\", \"0.000\"], [\"70337.10\", \"0.006\"], [\"70337.20\", \"0.142\"], [\"70337.40\", \"0.002\"], [\"70337.90\", \"0.002\"], [\"70338.40\", \"0.000\"], [\"70339.00\", \"0.312\"], [\"70339.10\", \"0.004\"], [\"70339.20\", \"0.009\"], [\"70339.30\", \"0.012\"], [\"70339.90\", \"0.002\"], [\"70340.10\", \"0.007\"], [\"70340.30\", \"0.001\"], [\"70340.50\", \"0.106\"], [\"70340.80\", \"0.102\"], [\"70340.90\", \"0.220\"], [\"70341.20\", \"0.059\"], [\"70341.50\", \"0.046\"], [\"70341.60\", \"0.005\"], [\"70341.70\", \"0.005\"], [\"70341.90\", \"0.035\"], [\"70342.00\", \"0.091\"], [\"70342.50\", \"0.089\"], [\"70343.00\", \"0.392\"], [\"70343.20\", \"0.022\"], [\"70343.60\", \"0.117\"], [\"70343.80\", \"0.003\"], [\"70344.30\", \"0.004\"], [\"70344.70\", \"0.957\"], [\"70345.20\", \"0.287\"], [\"70345.30\", \"0.000\"], [\"70346.00\", \"0.002\"], [\"70348.10\", \"0.004\"], [\"70348.20\", \"0.001\"], [\"70349.70\", \"0.004\"], [\"70350.30\", \"0.006\"], [\"70350.50\", \"0.003\"], [\"70350.70\", \"0.002\"], [\"70350.80\", \"0.002\"], [\"70350.90\", \"0.001\"], [\"70351.30\", \"0.002\"], [\"70351.70\", \"0.000\"], [\"70351.80\", \"0.006\"], [\"70352.70\", \"0.000\"], [\"70353.70\", \"0.003\"], [\"70354.30\", \"0.002\"], [\"70354.40\", \"0.003\"], [\"70354.50\", \"0.004\"], [\"70355.80\", \"1.000\"], [\"70355.90\", \"0.004\"], [\"70356.50\", \"0.003\"], [\"70356.60\", \"3.200\"]], \"a\": [[\"70356.70\", \"9.089\"], [\"70356.80\", \"0.003\"], [\"70356.90\", \"0.000\"], [\"70357.20\", \"0.002\"], [\"70357.40\", \"0.002\"], [\"70357.50\", \"0.140\"], [\"70357.60\", \"0.000\"], [\"70359.30\", \"0.020\"], [\"70359.40\", \"0.003\"], [\"70360.20\", \"0.005\"], [\"70360.30\", \"0.002\"], [\"70361.40\", \"0.470\"], [\"70361.50\", \"0.001\"], [\"70361.70\", \"0.945\"], [\"70361.80\", \"0.824\"], [\"70362.00\", \"0.002\"], [\"70362.60\", \"0.003\"], [\"70364.40\", \"0.000\"], [\"70364.90\", \"0.008\"], [\"70365.90\", \"1.444\"], [\"70366.00\", \"0.882\"], [\"70366.10\", \"0.817\"], [\"70367.20\", \"0.179\"], [\"70367.30\", \"0.001\"], [\"70367.60\", \"0.000\"], [\"70369.80\", \"1.070\"], [\"70369.90\", \"0.804\"], [\"70370.20\", \"0.514\"], [\"70370.40\", \"0.051\"], [\"70370.50\", \"0.137\"], [\"70370.70\", \"0.003\"], [\"70372.70\", \"0.150\"], [\"70372.80\", \"0.253\"], [\"70372.90\", \"0.229\"], [\"70373.00\", \"0.027\"], [\"70374.10\", \"0.057\"], [\"70374.20\", \"0.514\"], [\"70375.00\", \"0.148\"], [\"70375.20\", \"0.384\"], [\"70375.50\", \"0.277\"], [\"70375.70\", \"0.003\"], [\"70376.70\", \"0.063\"], [\"70377.20\", \"0.108\"], [\"70378.70\", \"0.311\"], [\"70378.90\", \"0.498\"], [\"70379.50\", \"0.197\"], [\"70379.80\", \"0.004\"], [\"70380.30\", \"0.000\"], [\"70380.40\", \"0.245\"], [\"70380.70\", \"0.036\"], [\"70381.30\", \"0.127\"], [\"70381.70\", \"0.005\"], [\"70382.40\", \"0.302\"], [\"70382.90\", \"0.003\"], [\"70385.10\", \"0.030\"], [\"70386.00\", \"0.020\"], [\"70387.10\", \"0.569\"], [\"70388.00\", \"0.191\"], [\"70389.00\", \"0.002\"], [\"70393.00\", \"0.006\"], [\"70393.10\", \"0.071\"], [\"70393.90\", \"0.035\"], [\"70394.20\", \"0.019\"], [\"70394.30\", \"0.000\"], [\"70397.20\", \"0.004\"], [\"70397.40\", \"0.003\"], [\"70398.80\", \"0.000\"], [\"70401.00\", \"0.014\"], [\"70403.10\", \"0.004\"], [\"70404.40\", \"0.006\"], [\"70405.10\", \"0.042\"], [\"70405.80\", \"0.001\"], [\"70405.90\", \"0.941\"], [\"70407.80\", \"0.141\"], [\"70408.20\", \"0.072\"], [\"70409.20\", \"0.189\"], [\"70411.00\", \"0.000\"], [\"70412.30\", \"0.344\"], [\"70413.50\", \"0.028\"], [\"70413.60\", \"0.000\"], [\"70416.70\", \"0.082\"], [\"70417.00\", \"0.034\"], [\"70417.30\", \"0.100\"], [\"70421.00\", \"0.006\"], [\"70421.70\", \"0.015\"], [\"70425.40\", \"0.006\"], [\"70428.10\", \"0.134\"], [\"70430.40\", \"0.000\"], [\"70432.90\", \"0.004\"], [\"70433.50\", \"0.002\"], [\"70435.20\", \"0.157\"], [\"70441.50\", \"0.073\"], [\"70442.90\", \"0.068\"], [\"70444.60\", \"0.191\"], [\"70448.20\", \"0.000\"], [\"70448.50\", \"0.090\"], [\"70450.00\", \"0.766\"], [\"70455.20\", \"0.000\"], [\"70455.60\", \"0.110\"], [\"70462.10\", \"1.642\"], [\"70462.30\", \"0.000\"], [\"70463.10\", \"0.014\"], [\"70466.60\", \"1.550\"], [\"70468.90\", \"0.099\"], [\"70476.80\", \"0.011\"], [\"70479.90\", \"0.119\"], [\"70481.70\", \"0.085\"], [\"70492.80\", \"0.088\"], [\"70496.00\", \"10.000\"], [\"70501.80\", \"1.518\"], [\"70504.00\", \"4.501\"], [\"70505.40\", \"0.231\"], [\"70505.80\", \"0.090\"], [\"70512.30\", \"0.002\"], [\"70513.50\", \"0.000\"], [\"70518.60\", \"0.367\"], [\"70520.50\", \"0.064\"], [\"70521.40\", \"0.000\"], [\"70521.60\", \"0.000\"], [\"70523.00\", \"0.053\"], [\"70530.50\", \"5.552\"], [\"70531.00\", \"0.190\"], [\"70534.00\", \"0.134\"], [\"70549.70\", \"1.490\"], [\"70551.00\", \"0.002\"], [\"70551.50\", \"1.642\"], [\"70556.70\", \"2.100\"], [\"70577.70\", \"1.369\"], [\"70583.50\", \"0.002\"], [\"70604.50\", \"10.000\"], [\"70609.30\", \"0.361\"], [\"70610.30\", \"0.002\"], [\"70643.60\", \"7.217\"], [\"70701.80\", \"0.061\"], [\"70718.90\", \"0.121\"], [\"70735.80\", \"0.004\"], [\"70752.80\", \"0.023\"], [\"70752.90\", \"0.000\"], [\"70915.20\", \"3.720\"], [\"71060.30\", \"0.000\"], [\"73898.10\", \"0.000\"], [\"75259.30\", \"0.014\"]]}", "symbol": "BTCUSDT"}
{"event": "depthUpdate", "raw_payload": "{\"e\": \"depthUpdate\", \"E\": 1773246399358, \"T\": 1773246399356, \"s\": \"BTCUSDT\", \"U\": 10089705240544, \"u\": 10089705247240, \"pu\": 10089705240348, \"b\": [[\"5000.00\", \"101.418\"], [\"19856.60\", \"0.220\"], [\"19970.40\", \"0.110\"], [\"19971.00\", \"0.000\"], [\"19972.40\", \"0.000\"], [\"19974.20\", \"0.000\"], [\"19979.90\", \"0.000\"], [\"19982.30\", \"0.000\"], [\"20156.60\", \"0.450\"], [\"20270.40\", \"0.210\"], [\"20270.50\", \"0.000\"], [\"20271.00\", \"0.000\"], [\"20272.30\", \"0.000\"], [\"20273.80\", \"0.000\"], [\"20274.20\", \"0.000\"], [\"20282.00\", \"0.000\"], [\"20282.30\", \"0.000\"], [\"33000.00\", \"10.797\"], [\"56310.00\", \"100.003\"], [\"66856.30\", \"0.000\"], [\"68947.50\", \"0.002\"], [\"68949.50\", \"0.006\"], [\"69653.00\", \"0.000\"], [\"69795.90\", \"0.006\"], [\"69798.00\", \"0.000\"], [\"70080.20\", \"1.093\"], [\"70099.80\", \"0.012\"], [\"70122.90\", \"0.051\"], [\"70129.00\", \"0.036\"], [\"70135.60\", \"0.047\"], [\"70135.90\", \"0.007\"], [\"70136.60\", \"0.126\"], [\"70137.70\", \"0.054\"], [\"70141.10\", \"0.002\"], [\"70156.60\", \"0.036\"], [\"70174.40\", \"0.005\"], [\"70191.20\", \"0.007\"], [\"70199.70\", \"0.044\"], [\"70210.30\", \"0.171\"], [\"70227.50\", \"0.002\"], [\"70231.70\", \"0.005\"], [\"70241.30\", \"0.019\"], [\"70246.00\", \"0.113\"], [\"70255.00\", \"0.000\"], [\"70258.20\", \"0.003\"], [\"70263.20\", \"1.461\"], [\"70265.90\", \"0.000\"], [\"70267.50\", \"0.000\"], [\"70269.70\", \"0.008\"], [\"70281.70\", \"0.003\"], [\"70286.20\", \"0.010\"], [\"70286.90\", \"0.090\"], [\"70288.60\", \"0.029\"], [\"70291.30\", \"0.029\"], [\"70293.70\", \"0.042\"], [\"70294.80\", \"0.368\"], [\"70300.30\", \"0.053\"], [\"70301.40\", \"0.261\"], [\"70302.10\", \"0.002\"], [\"70302.40\", \"0.005\"], [\"70305.80\", \"0.000\"], [\"70305.90\", \"0.248\"], [\"70313.10\", \"0.200\"], [\"70314.70\", \"0.002\"], [\"70315.90\", \"0.022\"], [\"70316.30\", \"0.004\"], [\"70318.60\", \"0.255\"], [\"70322.00\", \"10.231\"], [\"70322.30\", \"0.081\"], [\"70322.60\", \"0.033\"], [\"70323.80\", \"0.512\"], [\"70324.90\", \"0.012\"], [\"70325.40\", \"2.327\"], [\"70325.50\", \"0.513\"], [\"70325.60\", \"0.190\"], [\"70326.50\", \"0.010\"], [\"70326.60\", \"0.000\"], [\"70327.30\", \"0.000\"], [\"70328.70\", \"0.506\"], [\"70330.20\", \"0.073\"], [\"70331.40\", \"0.639\"], [\"70331.80\", \"0.395\"], [\"70335.10\", \"1.725\"], [\"70335.50\", \"0.477\"], [\"70340.50\", \"0.236\"], [\"70340.60\", \"0.047\"], [\"70340.90\", \"0.303\"], [\"70341.00\", \"1.066\"], [\"70341.60\", \"0.095\"], [\"70343.20\", \"0.022\"], [\"70344.00\", \"0.005\"], [\"70346.00\", \"0.004\"], [\"70348.70\", \"0.045\"], [\"70352.80\", \"0.002\"], [\"70354.90\", \"0.002\"], [\"70356.60\", \"4.061\"]], \"a\": [[\"70356.70\", \"6.971\"], [\"70360.20\", \"0.002\"], [\"70361.80\", \"0.822\"], [\"70362.00\", \"0.000\"], [\"70363.80\", \"0.002\"], [\"70364.10\", \"0.003\"], [\"70364.40\", \"0.000\"], [\"70365.30\", \"0.011\"], [\"70365.60\", \"0.073\"], [\"70366.00\", \"0.886\"], [\"70366.60\", \"0.000\"], [\"70367.30\", \"0.001\"], [\"70368.10\", \"0.641\"], [\"70369.00\", \"0.008\"], [\"70370.40\", \"0.047\"], [\"70370.70\", \"0.006\"], [\"70372.60\", \"0.004\"], [\"70373.40\", \"0.047\"], [\"70374.10\", \"0.093\"], [\"70374.20\", \"0.003\"], [\"70374.40\", \"0.146\"], [\"70375.10\", \"0.000\"], [\"70375.20\", \"0.544\"], [\"70375.90\", \"0.050\"], [\"70376.40\", \"0.772\"], [\"70376.60\", \"0.045\"], [\"70377.40\", \"0.249\"], [\"70379.10\", \"1.250\"], [\"70379.50\", \"0.161\"], [\"70380.20\", \"0.000\"], [\"70380.60\", \"0.076\"], [\"70381.00\", \"0.051\"], [\"70382.80\", \"0.208\"], [\"70387.70\", \"0.080\"], [\"70391.80\", \"0.001\"], [\"70392.80\", \"0.002\"], [\"70393.10\", \"0.000\"], [\"70393.90\", \"0.035\"], [\"70395.40\", \"0.009\"], [\"70402.40\", \"0.072\"], [\"70403.30\", \"0.167\"], [\"70405.90\", \"0.969\"], [\"70409.40\", \"0.113\"], [\"70409.60\", \"0.089\"], [\"70411.10\", \"0.096\"], [\"70413.50\", \"0.000\"], [\"70421.30\", \"0.095\"], [\"70423.40\", \"2.093\"], [\"70427.10\", \"0.725\"], [\"70440.20\", \"0.173\"], [\"70466.60\", \"1.450\"], [\"70494.70\", \"3.396\"], [\"70511.40\", \"1.302\"], [\"70518.50\", \"0.189\"], [\"70518.90\", \"0.087\"], [\"70521.80\", \"0.094\"], [\"70541.20\", \"6.509\"], [\"70542.40\", \"0.000\"], [\"70574.90\", \"0.019\"], [\"70578.00\", \"8.782\"], [\"70602.10\", \"2.895\"], [\"70640.60\", \"1.196\"], [\"70669.60\", \"0.000\"], [\"70672.70\", \"0.147\"], [\"70674.30\", \"0.000\"], [\"70718.00\", \"0.078\"], [\"70915.20\", \"0.000\"], [\"70917.30\", \"0.000\"], [\"70922.60\", \"0.000\"], [\"71060.30\", \"0.000\"], [\"73666.00\", \"5.661\"], [\"73909.40\", \"0.002\"], [\"89523.20\", \"0.000\"]]}", "symbol": "BTCUSDT"}
{"event": "depthUpdate", "raw_payload": "{\"e\": \"depthUpdate\", \"E\": 1773246399460, \"T\": 1773246399458, \"s\": \"BTCUSDT\", \"U\": 10089705247369, \"u\": 10089705253407, \"pu\": 10089705247240, \"b\": [[\"1000.00\", \"26.942\"], [\"5000.00\", \"101.418\"], [\"19856.60\", \"0.300\"], [\"19970.40\", \"0.030\"], [\"20156.60\", \"0.620\"], [\"20270.40\", \"0.040\"], [\"33000.00\", \"10.793\"], [\"68407.20\", \"0.007\"], [\"68413.20\", \"0.000\"], [\"68691.30\", \"0.000\"], [\"68969.40\", \"0.006\"], [\"69247.50\", \"0.000\"], [\"69525.60\", \"0.575\"], [\"69653.00\", \"0.000\"], [\"70009.80\", \"0.002\"], [\"70066.10\", \"0.040\"], [\"70080.20\", \"1.046\"], [\"70111.40\", \"0.162\"], [\"70125.50\", \"0.542\"], [\"70128.90\", \"0.276\"], [\"70135.10\", \"0.002\"], [\"70135.80\", \"0.002\"], [\"70136.60\", \"0.086\"], [\"70137.00\", \"0.069\"], [\"70137.30\", \"0.000\"], [\"70137.70\", \"0.000\"], [\"70141.00\", \"0.000\"], [\"70156.60\", \"0.000\"], [\"70234.60\", \"0.005\"], [\"70286.20\", \"0.094\"], [\"70300.30\", \"0.138\"], [\"70306.20\", \"0.002\"], [\"70306.60\", \"0.021\"], [\"70308.90\", \"0.567\"], [\"70312.00\", \"0.066\"], [\"70315.60\", \"0.201\"], [\"70315.90\", \"0.002\"], [\"70316.10\", \"0.341\"], [\"70316.50\", \"0.013\"], [\"70318.60\", \"0.007\"], [\"70319.10\", \"0.002\"], [\"70322.60\", \"0.002\"], [\"70322.70\", \"0.597\"], [\"70323.20\", \"0.111\"], [\"70325.30\", \"0.002\"], [\"70325.40\", \"2.336\"], [\"70325.50\", \"0.522\"], [\"70325.80\", \"0.002\"], [\"70326.10\", \"0.007\"], [\"70326.20\", \"0.006\"], [\"70329.50\", \"0.073\"], [\"70329.70\", \"0.645\"], [\"70330.10\", \"0.003\"], [\"70330.40\", \"0.382\"], [\"70331.40\", \"0.000\"], [\"70332.20\", \"0.344\"], [\"70332.40\", \"0.089\"], [\"70333.90\", \"0.031\"], [\"70334.20\", \"0.028\"], [\"70336.90\", \"0.003\"], [\"70337.20\", \"0.145\"], [\"70340.50\", \"0.279\"], [\"70340.90\", \"0.390\"], [\"70342.00\", \"0.082\"], [\"70342.80\", \"0.244\"], [\"70344.70\", \"0.960\"], [\"70346.00\", \"0.008\"], [\"70349.80\", \"0.027\"], [\"70356.60\", \"3.212\"]], \"a\": [[\"70356.70\", \"6.995\"], [\"70356.80\", \"0.001\"], [\"70357.50\", \"0.135\"], [\"70358.50\", \"0.007\"], [\"70359.10\", \"0.145\"], [\"70360.00\", \"0.397\"], [\"70360.40\", \"0.006\"], [\"70360.50\", \"0.003\"], [\"70361.30\", \"0.008\"], [\"70361.60\", \"1.102\"], [\"70361.70\", \"0.943\"], [\"70363.70\", \"0.064\"], [\"70364.30\", \"0.003\"], [\"70364.40\", \"0.000\"], [\"70364.60\", \"0.000\"], [\"70365.00\", \"0.002\"], [\"70365.30\", \"0.011\"], [\"70365.40\", \"0.004\"], [\"70365.60\", \"0.000\"], [\"70365.80\", \"0.557\"], [\"70366.10\", \"0.803\"], [\"70366.40\", \"0.007\"], [\"70366.90\", \"0.006\"], [\"70367.10\", \"0.000\"], [\"70367.20\", \"0.147\"], [\"70367.30\", \"0.001\"], [\"70367.50\", \"0.004\"], [\"70367.80\", \"0.019\"], [\"70368.20\", \"0.000\"], [\"70372.00\", \"0.002\"], [\"70372.70\", \"0.175\"], [\"70373.70\", \"0.039\"], [\"70374.10\", \"0.129\"], [\"70375.50\", \"0.206\"], [\"70377.70\", \"0.071\"], [\"70378.40\", \"0.000\"], [\"70379.10\", \"1.214\"], [\"70379.50\", \"0.125\"], [\"70382.70\", \"0.002\"], [\"70393.90\", \"0.015\"], [\"70396.80\", \"0.065\"], [\"70409.00\", \"0.008\"], [\"70410.00\", \"0.014\"], [\"70411.70\", \"0.570\"], [\"70413.50\", \"0.028\"], [\"70413.70\", \"0.021\"], [\"70462.20\", \"0.047\"], [\"70468.90\", \"0.058\"], [\"70473.20\", \"0.000\"], [\"70486.00\", \"0.044\"], [\"70525.20\", \"0.000\"], [\"70526.20\", \"0.165\"], [\"70552.30\", \"0.028\"], [\"70554.40\", \"0.000\"], [\"70713.50\", \"0.071\"], [\"70905.60\", \"0.000\"], [\"71060.30\", \"0.000\"], [\"71118.30\", \"0.000\"], [\"71331.00\", \"0.000\"], [\"71543.80\", \"0.000\"], [\"73932.60\", \"0.000\"], [\"100000.00\", \"15.487\"]]}", "symbol": "BTCUSDT"}
{"event": "depthUpdate", "raw_payload": "{\"e\": \"depthUpdate\", \"E\": 1773246399562, \"T\": 1773246399560, \"s\": \"BTCUSDT\", \"U\": 10089705253484, \"u\": 10089705259264, \"pu\": 10089705253407, \"b\": [[\"1000.00\", \"26.792\"], [\"5000.00\", \"101.418\"], [\"19856.60\", \"0.390\"], [\"19967.10\", \"0.020\"], [\"19968.20\", \"0.000\"], [\"19970.40\", \"0.000\"], [\"20156.60\", \"0.790\"], [\"20267.10\", \"0.030\"], [\"20268.50\", \"0.000\"], [\"20269.80\", \"0.000\"], [\"20270.40\", \"0.000\"], [\"56285.00\", \"0.035\"], [\"66826.60\", \"0.003\"], [\"66872.20\", \"0.002\"], [\"66872.30\", \"0.004\"], [\"68949.70\", \"0.009\"], [\"68959.80\", \"0.007\"], [\"69160.70\", \"0.399\"], [\"69653.00\", \"0.000\"], [\"69793.90\", \"0.000\"], [\"69810.30\", \"0.000\"], [\"69811.30\", \"3.720\"], [\"70100.60\", \"0.393\"], [\"70129.50\", \"6.583\"], [\"70136.00\", \"0.857\"], [\"70138.00\", \"1.420\"], [\"70240.00\", \"0.270\"], [\"70246.60\", \"0.620\"], [\"70248.00\", \"0.422\"], [\"70263.20\", \"1.463\"], [\"70286.20\", \"0.010\"], [\"70294.50\", \"0.244\"], [\"70300.30\", \"0.002\"], [\"70307.70\", \"4.698\"], [\"70308.90\", \"0.547\"], [\"70314.30\", \"0.437\"], [\"70316.00\", \"0.362\"], [\"70324.90\", \"0.148\"], [\"70327.10\", \"0.002\"], [\"70338.90\", \"0.040\"], [\"70342.60\", \"0.002\"], [\"70342.80\", \"0.003\"], [\"70344.70\", \"0.305\"], [\"70346.00\", \"0.011\"], [\"70349.60\", \"0.000\"], [\"70349.80\", \"0.268\"], [\"70349.90\", \"0.658\"], [\"70356.40\", \"0.002\"], [\"70356.60\", \"3.214\"]], \"a\": [[\"70356.70\", \"5.646\"], [\"70357.50\", \"0.135\"], [\"70358.60\", \"0.000\"], [\"70359.90\", \"0.003\"], [\"70361.70\", \"0.915\"], [\"70364.40\", \"0.000\"], [\"70365.50\", \"0.003\"], [\"70367.30\", \"0.001\"], [\"70372.60\", \"0.147\"], [\"70373.40\", \"0.072\"], [\"70374.40\", \"0.182\"], [\"70374.90\", \"0.187\"], [\"70376.40\", \"0.261\"], [\"70376.70\", \"0.113\"], [\"70378.60\", \"0.511\"], [\"70379.40\", \"0.000\"], [\"70379.50\", \"0.089\"], [\"70379.70\", \"0.723\"], [\"70380.50\", \"0.000\"], [\"70380.70\", \"0.000\"], [\"70381.00\", \"0.004\"], [\"70381.60\", \"0.004\"], [\"70385.30\", \"0.345\"], [\"70385.90\", \"0.191\"], [\"70408.30\", \"0.081\"], [\"70408.40\", \"0.004\"], [\"70416.50\", \"0.668\"], [\"70445.60\", \"0.041\"], [\"70456.60\", \"0.641\"], [\"70498.10\", \"0.007\"], [\"70503.10\", \"0.084\"], [\"70505.10\", \"0.088\"], [\"70512.10\", \"0.007\"], [\"70519.10\", \"0.007\"], [\"70526.10\", \"0.032\"], [\"70533.10\", \"0.009\"], [\"70540.10\", \"0.007\"], [\"70541.20\", \"6.567\"], [\"70546.40\", \"0.000\"], [\"70547.10\", \"0.007\"], [\"70553.40\", \"0.000\"], [\"70560.40\", \"23.148\"], [\"70567.40\", \"0.002\"], [\"70574.40\", \"0.002\"], [\"70581.40\", \"0.002\"], [\"70588.40\", \"0.005\"], [\"70595.40\", \"0.003\"], [\"70617.60\", \"0.002\"], [\"70646.00\", \"0.000\"], [\"70902.00\", \"3.821\"], [\"70903.00\", \"0.048\"], [\"71060.30\", \"0.000\"], [\"71384.40\", \"0.700\"], [\"71756.50\", \"0.004\"], [\"71774.50\", \"0.000\"], [\"73222.00\", \"0.360\"], [\"73884.70\", \"0.002\"], [\"89523.20\", \"0.000\"]]}", "symbol": "BTCUSDT"}
{"event": "depthUpdate", "raw_payload": "{\"e\": \"depthUpdate\", \"E\": 1773246399664, \"T\": 1773246399660, \"s\": \"BTCUSDT\", \"U\": 10089705259336, \"u\": 10089705264709, \"pu\": 10089705259264, \"b\": [[\"5000.00\", \"101.418\"], [\"19856.60\", \"0.420\"], [\"19865.90\", \"0.030\"], [\"19966.40\", \"0.000\"], [\"19967.10\", \"0.000\"], [\"20156.60\", \"0.960\"], [\"20256.60\", \"0.050\"], [\"20265.90\", \"0.040\"], [\"20266.40\", \"0.000\"], [\"20267.00\", \"0.000\"], [\"20267.10\", \"0.000\"], [\"65051.30\", \"0.014\"], [\"66836.80\", \"0.002\"], [\"67542.40\", \"0.002\"], [\"68949.50\", \"0.009\"], [\"68965.10\", \"0.003\"], [\"69322.50\", \"1.886\"], [\"69653.00\", \"0.000\"], [\"69811.30\", \"0.000\"], [\"70066.10\", \"0.000\"], [\"70072.60\", \"2.014\"], [\"70122.90\", \"0.004\"], [\"70136.60\", \"0.043\"], [\"70156.60\", \"0.036\"], [\"70199.20\", \"0.189\"], [\"70203.80\", \"0.354\"], [\"70270.40\", \"0.002\"], [\"70277.90\", \"6.305\"], [\"70288.90\", \"0.057\"], [\"70289.40\", \"0.000\"], [\"70289.70\", \"0.010\"], [\"70290.30\", \"0.045\"], [\"70297.10\", \"0.004\"], [\"70306.60\", \"0.019\"], [\"70307.20\", \"0.004\"], [\"70312.90\", \"1.027\"], [\"70316.00\", \"0.342\"], [\"70329.50\", \"0.002\"], [\"70333.10\", \"0.358\"], [\"70340.40\", \"0.006\"], [\"70340.80\", \"0.104\"], [\"70343.20\", \"0.022\"], [\"70346.00\", \"0.004\"], [\"70349.40\", \"0.212\"], [\"70350.00\", \"0.023\"], [\"70356.60\", \"3.946\"]], \"a\": [[\"70356.70\", \"5.026\"], [\"70359.10\", \"0.003\"], [\"70360.20\", \"0.002\"], [\"70361.00\", \"0.002\"], [\"70361.90\", \"0.003\"], [\"70364.30\", \"0.001\"], [\"70364.40\", \"0.000\"], [\"70366.50\", \"0.007\"], [\"70367.30\", \"0.001\"], [\"70368.10\", \"0.002\"], [\"70368.70\", \"0.178\"], [\"70370.10\", \"0.639\"], [\"70378.70\", \"0.286\"], [\"70379.50\", \"0.064\"], [\"70380.00\", \"0.052\"], [\"70380.60\", \"0.005\"], [\"70382.60\", \"0.078\"], [\"70382.80\", \"0.158\"], [\"70391.90\", \"0.596\"], [\"70397.70\", \"0.002\"], [\"70406.80\", \"0.048\"], [\"70408.20\", \"0.024\"], [\"70413.00\", \"0.005\"], [\"70414.00\", \"0.201\"], [\"70434.10\", \"0.089\"], [\"70436.70\", \"0.200\"], [\"70438.20\", \"0.004\"], [\"70451.40\", \"0.511\"], [\"70503.30\", \"0.009\"], [\"70525.20\", \"0.036\"], [\"70526.20\", \"0.201\"], [\"70551.90\", \"0.357\"], [\"70554.40\", \"0.036\"], [\"70622.30\", \"0.000\"], [\"70713.40\", \"0.006\"], [\"70902.00\", \"0.101\"], [\"70903.40\", \"0.000\"], [\"71060.30\", \"0.000\"], [\"71321.30\", \"0.490\"], [\"73887.10\", \"0.000\"]]}", "symbol": "BTCUSDT"}
{"event": "depthUpdate", "raw_payload": "{\"e\": \"depthUpdate\", \"E\": 1773246399766, \"T\": 1773246399765, \"s\": \"BTCUSDT\", \"U\": 10089705264848, \"u\": 10089705269790, \"pu\": 10089705264709, \"b\": [[\"1000.00\", \"26.792\"], [\"5000.00\", \"101.418\"], [\"19861.60\", \"0.430\"], [\"19865.90\", \"0.000\"], [\"20056.60\", \"0.010\"], [\"20156.60\", \"1.120\"], [\"20161.60\", \"0.480\"], [\"20256.60\", \"0.140\"], [\"20261.60\", \"0.370\"], [\"20261.70\", \"0.000\"], [\"20265.90\", \"0.000\"], [\"66837.40\", \"0.002\"], [\"66848.70\", \"0.007\"], [\"67483.50\", \"0.008\"], [\"69041.10\", \"0.362\"], [\"69160.70\", \"0.615\"], [\"69653.00\", \"0.000\"], [\"70007.10\", \"1.137\"], [\"70075.10\", \"0.224\"], [\"70110.20\", \"0.000\"], [\"70135.60\", \"0.000\"], [\"70267.80\", \"0.033\"], [\"70284.40\", \"0.269\"], [\"70298.40\", \"0.073\"], [\"70324.70\", \"0.147\"], [\"70327.30\", \"0.035\"], [\"70329.30\", \"1.233\"], [\"70333.60\", \"0.020\"], [\"70335.10\", \"1.846\"], [\"70340.90\", \"0.392\"], [\"70345.90\", \"0.010\"], [\"70346.00\", \"0.007\"], [\"70350.10\", \"0.288\"], [\"70355.20\", \"0.002\"], [\"70356.60\", \"3.540\"]], \"a\": [[\"70356.70\", \"5.827\"], [\"70360.40\", \"0.003\"], [\"70364.20\", \"0.002\"], [\"70364.30\", \"0.001\"], [\"70364.40\", \"0.000\"], [\"70365.50\", \"0.575\"], [\"70367.10\", \"0.003\"], [\"70367.30\", \"0.001\"], [\"70372.60\", \"0.147\"], [\"70374.90\", \"0.187\"], [\"70380.80\", \"0.000\"], [\"70392.50\", \"0.168\"], [\"70393.40\", \"0.000\"], [\"70419.70\", \"0.257\"], [\"70430.60\", \"2.959\"], [\"70432.80\", \"0.000\"], [\"70434.10\", \"0.005\"], [\"70479.00\", \"0.103\"], [\"70488.30\", \"0.055\"], [\"70488.40\", \"0.003\"], [\"70591.60\", \"0.006\"], [\"70713.40\", \"0.000\"], [\"70748.60\", \"0.056\"], [\"70778.30\", \"0.000\"], [\"70778.40\", \"0.140\"], [\"71060.30\", \"0.000\"], [\"71613.10\", \"0.026\"], [\"73915.00\", \"0.000\"], [\"89523.20\", \"0.000\"]]}", "symbol": "BTCUSDT"}
